
#######################################################################
# +-----------------------------------------------------------------+ #
# |                            BO4 object                           | #
# +-----------------------------------------------------------------+ #
#######################################################################

Author: NLBlackEagle

Description: No description given

SettingsMode: WriteWithoutComments


#######################################################################
# +-----------------------------------------------------------------+ #
# |                          Main settings                          | #
# +-----------------------------------------------------------------+ #
#######################################################################

FixedRotation: 

Frequency: 0

SpawnHeight: highestBlock

UseCenterForHighestBlock: true

##############################
# Height Limits for the BO4. #
##############################

MinHeight: 0

MaxHeight: 255

InheritBO3: 

InheritBO3Rotation: NORTH

OverrideChildSettings: true

OverrideParentHeight: true

CanOverride: true

BranchFrequency: 0

BranchFrequencyGroup: 

MustBeBelowOther: false

MustBeInside: 

CannotBeInside: 

ReplacesBO3: 

MustBeInsideWorldBorders: false

CanSpawnOnWater: true

SpawnOnWaterOnly: false

SpawnUnderWater: false

SpawnAtWaterLevel: false

HeightOffset: -5

RemoveAir: true

ReplaceAbove: 

ReplaceBelow: SMOOTH_BRICK:0

ReplaceWithBiomeBlocks: false

ReplaceWithSurfaceBlock: GRASS

ReplaceWithGroundBlock: DIRT

ReplaceWithStoneBlock: STONE

SmoothRadius: 0

SmoothHeightOffset: 0

SmoothStartTop: false

SmoothStartWood: false

SmoothingSurfaceBlock: 

SmoothingGroundBlock: 

BO3Group: 

IsSpawnPoint: false

DoReplaceBlocks: true


#######################################################################
# +-----------------------------------------------------------------+ #
# |                              Blocks                             | #
# +-----------------------------------------------------------------+ #
#######################################################################

RandomBlock(-8,0,1,SMOOTH_BRICK:0,40,SMOOTH_BRICK:1,30,SMOOTH_BRICK:2,30,SMOOTH_STAIRS:0,15,SMOOTH_STAIRS:1,15,SMOOTH_STAIRS:2,15,SMOOTH_STAIRS:3,15,STEP:5,15,STEP:13,15,COBBLE_WALL:0,10,COBBLESTONE_STAIRS:0,10,STEP:3,10,COBBLE_WALL:1,20,COBBLESTONE_STAIRS:2,20,COBBLESTONE_STAIRS:3,20,MOSSY_COBBLESTONE:0,60,COBBLESTONE_STAIRS:1,20,STEP:11,20,COBBLESTONE:0,100)
RandomBlock(-8,0,2,SMOOTH_BRICK:0,40,SMOOTH_BRICK:1,30,SMOOTH_BRICK:2,30,SMOOTH_STAIRS:0,15,SMOOTH_STAIRS:1,15,SMOOTH_STAIRS:2,15,SMOOTH_STAIRS:3,15,STEP:5,15,STEP:13,15,COBBLE_WALL:0,10,COBBLESTONE_STAIRS:0,10,STEP:3,10,COBBLE_WALL:1,20,COBBLESTONE_STAIRS:2,20,COBBLESTONE_STAIRS:3,20,MOSSY_COBBLESTONE:0,60,COBBLESTONE_STAIRS:1,20,STEP:11,20,COBBLESTONE:0,100)
RandomBlock(-8,0,3,SMOOTH_BRICK:0,40,SMOOTH_BRICK:1,30,SMOOTH_BRICK:2,30,SMOOTH_STAIRS:0,15,SMOOTH_STAIRS:1,15,SMOOTH_STAIRS:2,15,SMOOTH_STAIRS:3,15,STEP:5,15,STEP:13,15,COBBLE_WALL:0,10,COBBLESTONE_STAIRS:0,10,STEP:3,10,COBBLE_WALL:1,20,COBBLESTONE_STAIRS:2,20,COBBLESTONE_STAIRS:3,20,MOSSY_COBBLESTONE:0,60,COBBLESTONE_STAIRS:1,20,STEP:11,20,COBBLESTONE:0,100)
RandomBlock(-8,0,4,SMOOTH_BRICK:0,40,SMOOTH_BRICK:1,30,SMOOTH_BRICK:2,30,SMOOTH_STAIRS:0,15,SMOOTH_STAIRS:1,15,SMOOTH_STAIRS:2,15,SMOOTH_STAIRS:3,15,STEP:5,15,STEP:13,15,COBBLE_WALL:0,10,COBBLESTONE_STAIRS:0,10,STEP:3,10,COBBLE_WALL:1,20,COBBLESTONE_STAIRS:2,20,COBBLESTONE_STAIRS:3,20,MOSSY_COBBLESTONE:0,60,COBBLESTONE_STAIRS:1,20,STEP:11,20,COBBLESTONE:0,100)
RandomBlock(-8,0,5,SMOOTH_BRICK:0,40,SMOOTH_BRICK:1,30,SMOOTH_BRICK:2,30,SMOOTH_STAIRS:0,15,SMOOTH_STAIRS:1,15,SMOOTH_STAIRS:2,15,SMOOTH_STAIRS:3,15,STEP:5,15,STEP:13,15,COBBLE_WALL:0,10,COBBLESTONE_STAIRS:0,10,STEP:3,10,COBBLE_WALL:1,20,COBBLESTONE_STAIRS:2,20,COBBLESTONE_STAIRS:3,20,MOSSY_COBBLESTONE:0,60,COBBLESTONE_STAIRS:1,20,STEP:11,20,COBBLESTONE:0,100)
RandomBlock(-8,0,6,SMOOTH_BRICK:0,40,SMOOTH_BRICK:1,30,SMOOTH_BRICK:2,30,SMOOTH_STAIRS:0,15,SMOOTH_STAIRS:1,15,SMOOTH_STAIRS:2,15,SMOOTH_STAIRS:3,15,STEP:5,15,STEP:13,15,COBBLE_WALL:0,10,COBBLESTONE_STAIRS:0,10,STEP:3,10,COBBLE_WALL:1,20,COBBLESTONE_STAIRS:2,20,COBBLESTONE_STAIRS:3,20,MOSSY_COBBLESTONE:0,60,COBBLESTONE_STAIRS:1,20,STEP:11,20,COBBLESTONE:0,100)
RandomBlock(-8,0,7,SMOOTH_BRICK:0,40,SMOOTH_BRICK:1,30,SMOOTH_BRICK:2,30,SMOOTH_STAIRS:0,15,SMOOTH_STAIRS:1,15,SMOOTH_STAIRS:2,15,SMOOTH_STAIRS:3,15,STEP:5,15,STEP:13,15,COBBLE_WALL:0,10,COBBLESTONE_STAIRS:0,10,STEP:3,10,COBBLE_WALL:1,20,COBBLESTONE_STAIRS:2,20,COBBLESTONE_STAIRS:3,20,MOSSY_COBBLESTONE:0,60,COBBLESTONE_STAIRS:1,20,STEP:11,20,COBBLESTONE:0,100)
RandomBlock(-8,1,1,SMOOTH_BRICK:0,40,SMOOTH_BRICK:1,30,SMOOTH_BRICK:2,30,SMOOTH_STAIRS:0,15,SMOOTH_STAIRS:1,15,SMOOTH_STAIRS:2,15,SMOOTH_STAIRS:3,15,STEP:5,15,STEP:13,15,COBBLE_WALL:0,10,COBBLESTONE_STAIRS:0,10,STEP:3,10,COBBLE_WALL:1,20,COBBLESTONE_STAIRS:2,20,COBBLESTONE_STAIRS:3,20,MOSSY_COBBLESTONE:0,60,COBBLESTONE_STAIRS:1,20,STEP:11,20,COBBLESTONE:0,100)
RandomBlock(-8,1,2,SMOOTH_BRICK:0,40,SMOOTH_BRICK:1,30,SMOOTH_BRICK:2,30,SMOOTH_STAIRS:0,15,SMOOTH_STAIRS:1,15,SMOOTH_STAIRS:2,15,SMOOTH_STAIRS:3,15,STEP:5,15,STEP:13,15,COBBLE_WALL:0,10,COBBLESTONE_STAIRS:0,10,STEP:3,10,COBBLE_WALL:1,20,COBBLESTONE_STAIRS:2,20,COBBLESTONE_STAIRS:3,20,MOSSY_COBBLESTONE:0,60,COBBLESTONE_STAIRS:1,20,STEP:11,20,COBBLESTONE:0,100)
RandomBlock(-8,1,3,SMOOTH_BRICK:0,40,SMOOTH_BRICK:1,30,SMOOTH_BRICK:2,30,SMOOTH_STAIRS:0,15,SMOOTH_STAIRS:1,15,SMOOTH_STAIRS:2,15,SMOOTH_STAIRS:3,15,STEP:5,15,STEP:13,15,COBBLE_WALL:0,10,COBBLESTONE_STAIRS:0,10,STEP:3,10,COBBLE_WALL:1,20,COBBLESTONE_STAIRS:2,20,COBBLESTONE_STAIRS:3,20,MOSSY_COBBLESTONE:0,60,COBBLESTONE_STAIRS:1,20,STEP:11,20,COBBLESTONE:0,100)
RandomBlock(-8,1,4,SMOOTH_BRICK:0,40,SMOOTH_BRICK:1,30,SMOOTH_BRICK:2,30,SMOOTH_STAIRS:0,15,SMOOTH_STAIRS:1,15,SMOOTH_STAIRS:2,15,SMOOTH_STAIRS:3,15,STEP:5,15,STEP:13,15,COBBLE_WALL:0,10,COBBLESTONE_STAIRS:0,10,STEP:3,10,COBBLE_WALL:1,20,COBBLESTONE_STAIRS:2,20,COBBLESTONE_STAIRS:3,20,MOSSY_COBBLESTONE:0,60,COBBLESTONE_STAIRS:1,20,STEP:11,20,COBBLESTONE:0,100)
RandomBlock(-8,1,5,SMOOTH_BRICK:0,40,SMOOTH_BRICK:1,30,SMOOTH_BRICK:2,30,SMOOTH_STAIRS:0,15,SMOOTH_STAIRS:1,15,SMOOTH_STAIRS:2,15,SMOOTH_STAIRS:3,15,STEP:5,15,STEP:13,15,COBBLE_WALL:0,10,COBBLESTONE_STAIRS:0,10,STEP:3,10,COBBLE_WALL:1,20,COBBLESTONE_STAIRS:2,20,COBBLESTONE_STAIRS:3,20,MOSSY_COBBLESTONE:0,60,COBBLESTONE_STAIRS:1,20,STEP:11,20,COBBLESTONE:0,100)
RandomBlock(-8,1,6,SMOOTH_BRICK:0,40,SMOOTH_BRICK:1,30,SMOOTH_BRICK:2,30,SMOOTH_STAIRS:0,15,SMOOTH_STAIRS:1,15,SMOOTH_STAIRS:2,15,SMOOTH_STAIRS:3,15,STEP:5,15,STEP:13,15,COBBLE_WALL:0,10,COBBLESTONE_STAIRS:0,10,STEP:3,10,COBBLE_WALL:1,20,COBBLESTONE_STAIRS:2,20,COBBLESTONE_STAIRS:3,20,MOSSY_COBBLESTONE:0,60,COBBLESTONE_STAIRS:1,20,STEP:11,20,COBBLESTONE:0,100)
RandomBlock(-8,1,7,SMOOTH_BRICK:0,40,SMOOTH_BRICK:1,30,SMOOTH_BRICK:2,30,SMOOTH_STAIRS:0,15,SMOOTH_STAIRS:1,15,SMOOTH_STAIRS:2,15,SMOOTH_STAIRS:3,15,STEP:5,15,STEP:13,15,COBBLE_WALL:0,10,COBBLESTONE_STAIRS:0,10,STEP:3,10,COBBLE_WALL:1,20,COBBLESTONE_STAIRS:2,20,COBBLESTONE_STAIRS:3,20,MOSSY_COBBLESTONE:0,60,COBBLESTONE_STAIRS:1,20,STEP:11,20,COBBLESTONE:0,100)
RandomBlock(-8,2,1,SMOOTH_BRICK:0,40,SMOOTH_BRICK:1,30,SMOOTH_BRICK:2,30,SMOOTH_STAIRS:0,15,SMOOTH_STAIRS:1,15,SMOOTH_STAIRS:2,15,SMOOTH_STAIRS:3,15,STEP:5,15,STEP:13,15,COBBLE_WALL:0,10,COBBLESTONE_STAIRS:0,10,STEP:3,10,COBBLE_WALL:1,20,COBBLESTONE_STAIRS:2,20,COBBLESTONE_STAIRS:3,20,MOSSY_COBBLESTONE:0,60,COBBLESTONE_STAIRS:1,20,STEP:11,20,COBBLESTONE:0,100)
RandomBlock(-8,2,2,SMOOTH_BRICK:0,40,SMOOTH_BRICK:1,30,SMOOTH_BRICK:2,30,SMOOTH_STAIRS:0,15,SMOOTH_STAIRS:1,15,SMOOTH_STAIRS:2,15,SMOOTH_STAIRS:3,15,STEP:5,15,STEP:13,15,COBBLE_WALL:0,10,COBBLESTONE_STAIRS:0,10,STEP:3,10,COBBLE_WALL:1,20,COBBLESTONE_STAIRS:2,20,COBBLESTONE_STAIRS:3,20,MOSSY_COBBLESTONE:0,60,COBBLESTONE_STAIRS:1,20,STEP:11,20,COBBLESTONE:0,100)
RandomBlock(-8,2,3,SMOOTH_BRICK:0,40,SMOOTH_BRICK:1,30,SMOOTH_BRICK:2,30,SMOOTH_STAIRS:0,15,SMOOTH_STAIRS:1,15,SMOOTH_STAIRS:2,15,SMOOTH_STAIRS:3,15,STEP:5,15,STEP:13,15,COBBLE_WALL:0,10,COBBLESTONE_STAIRS:0,10,STEP:3,10,COBBLE_WALL:1,20,COBBLESTONE_STAIRS:2,20,COBBLESTONE_STAIRS:3,20,MOSSY_COBBLESTONE:0,60,COBBLESTONE_STAIRS:1,20,STEP:11,20,COBBLESTONE:0,100)
RandomBlock(-8,2,4,SMOOTH_BRICK:0,40,SMOOTH_BRICK:1,30,SMOOTH_BRICK:2,30,SMOOTH_STAIRS:0,15,SMOOTH_STAIRS:1,15,SMOOTH_STAIRS:2,15,SMOOTH_STAIRS:3,15,STEP:5,15,STEP:13,15,COBBLE_WALL:0,10,COBBLESTONE_STAIRS:0,10,STEP:3,10,COBBLE_WALL:1,20,COBBLESTONE_STAIRS:2,20,COBBLESTONE_STAIRS:3,20,MOSSY_COBBLESTONE:0,60,COBBLESTONE_STAIRS:1,20,STEP:11,20,COBBLESTONE:0,100)
RandomBlock(-8,2,5,SMOOTH_BRICK:0,40,SMOOTH_BRICK:1,30,SMOOTH_BRICK:2,30,SMOOTH_STAIRS:0,15,SMOOTH_STAIRS:1,15,SMOOTH_STAIRS:2,15,SMOOTH_STAIRS:3,15,STEP:5,15,STEP:13,15,COBBLE_WALL:0,10,COBBLESTONE_STAIRS:0,10,STEP:3,10,COBBLE_WALL:1,20,COBBLESTONE_STAIRS:2,20,COBBLESTONE_STAIRS:3,20,MOSSY_COBBLESTONE:0,60,COBBLESTONE_STAIRS:1,20,STEP:11,20,COBBLESTONE:0,100)
RandomBlock(-8,2,6,SMOOTH_BRICK:0,40,SMOOTH_BRICK:1,30,SMOOTH_BRICK:2,30,SMOOTH_STAIRS:0,15,SMOOTH_STAIRS:1,15,SMOOTH_STAIRS:2,15,SMOOTH_STAIRS:3,15,STEP:5,15,STEP:13,15,COBBLE_WALL:0,10,COBBLESTONE_STAIRS:0,10,STEP:3,10,COBBLE_WALL:1,20,COBBLESTONE_STAIRS:2,20,COBBLESTONE_STAIRS:3,20,MOSSY_COBBLESTONE:0,60,COBBLESTONE_STAIRS:1,20,STEP:11,20,COBBLESTONE:0,100)
RandomBlock(-8,2,7,SMOOTH_BRICK:0,40,SMOOTH_BRICK:1,30,SMOOTH_BRICK:2,30,SMOOTH_STAIRS:0,15,SMOOTH_STAIRS:1,15,SMOOTH_STAIRS:2,15,SMOOTH_STAIRS:3,15,STEP:5,15,STEP:13,15,COBBLE_WALL:0,10,COBBLESTONE_STAIRS:0,10,STEP:3,10,COBBLE_WALL:1,20,COBBLESTONE_STAIRS:2,20,COBBLESTONE_STAIRS:3,20,MOSSY_COBBLESTONE:0,60,COBBLESTONE_STAIRS:1,20,STEP:11,20,COBBLESTONE:0,100)
RandomBlock(-8,3,1,SMOOTH_BRICK:0,40,SMOOTH_BRICK:1,30,SMOOTH_BRICK:2,30,SMOOTH_STAIRS:0,15,SMOOTH_STAIRS:1,15,SMOOTH_STAIRS:2,15,SMOOTH_STAIRS:3,15,STEP:5,15,STEP:13,15,COBBLE_WALL:0,10,COBBLESTONE_STAIRS:0,10,STEP:3,10,COBBLE_WALL:1,20,COBBLESTONE_STAIRS:2,20,COBBLESTONE_STAIRS:3,20,MOSSY_COBBLESTONE:0,60,COBBLESTONE_STAIRS:1,20,STEP:11,20,COBBLESTONE:0,100)
RandomBlock(-8,3,2,SMOOTH_BRICK:0,40,SMOOTH_BRICK:1,30,SMOOTH_BRICK:2,30,SMOOTH_STAIRS:0,15,SMOOTH_STAIRS:1,15,SMOOTH_STAIRS:2,15,SMOOTH_STAIRS:3,15,STEP:5,15,STEP:13,15,COBBLE_WALL:0,10,COBBLESTONE_STAIRS:0,10,STEP:3,10,COBBLE_WALL:1,20,COBBLESTONE_STAIRS:2,20,COBBLESTONE_STAIRS:3,20,MOSSY_COBBLESTONE:0,60,COBBLESTONE_STAIRS:1,20,STEP:11,20,COBBLESTONE:0,100)
RandomBlock(-8,3,3,SMOOTH_BRICK:0,40,SMOOTH_BRICK:1,30,SMOOTH_BRICK:2,30,SMOOTH_STAIRS:0,15,SMOOTH_STAIRS:1,15,SMOOTH_STAIRS:2,15,SMOOTH_STAIRS:3,15,STEP:5,15,STEP:13,15,COBBLE_WALL:0,10,COBBLESTONE_STAIRS:0,10,STEP:3,10,COBBLE_WALL:1,20,COBBLESTONE_STAIRS:2,20,COBBLESTONE_STAIRS:3,20,MOSSY_COBBLESTONE:0,60,COBBLESTONE_STAIRS:1,20,STEP:11,20,COBBLESTONE:0,100)
RandomBlock(-8,3,4,SMOOTH_BRICK:0,40,SMOOTH_BRICK:1,30,SMOOTH_BRICK:2,30,SMOOTH_STAIRS:0,15,SMOOTH_STAIRS:1,15,SMOOTH_STAIRS:2,15,SMOOTH_STAIRS:3,15,STEP:5,15,STEP:13,15,COBBLE_WALL:0,10,COBBLESTONE_STAIRS:0,10,STEP:3,10,COBBLE_WALL:1,20,COBBLESTONE_STAIRS:2,20,COBBLESTONE_STAIRS:3,20,MOSSY_COBBLESTONE:0,60,COBBLESTONE_STAIRS:1,20,STEP:11,20,COBBLESTONE:0,100)
RandomBlock(-8,3,5,SMOOTH_BRICK:0,40,SMOOTH_BRICK:1,30,SMOOTH_BRICK:2,30,SMOOTH_STAIRS:0,15,SMOOTH_STAIRS:1,15,SMOOTH_STAIRS:2,15,SMOOTH_STAIRS:3,15,STEP:5,15,STEP:13,15,COBBLE_WALL:0,10,COBBLESTONE_STAIRS:0,10,STEP:3,10,COBBLE_WALL:1,20,COBBLESTONE_STAIRS:2,20,COBBLESTONE_STAIRS:3,20,MOSSY_COBBLESTONE:0,60,COBBLESTONE_STAIRS:1,20,STEP:11,20,COBBLESTONE:0,100)
RandomBlock(-8,3,6,SMOOTH_BRICK:0,40,SMOOTH_BRICK:1,30,SMOOTH_BRICK:2,30,SMOOTH_STAIRS:0,15,SMOOTH_STAIRS:1,15,SMOOTH_STAIRS:2,15,SMOOTH_STAIRS:3,15,STEP:5,15,STEP:13,15,COBBLE_WALL:0,10,COBBLESTONE_STAIRS:0,10,STEP:3,10,COBBLE_WALL:1,20,COBBLESTONE_STAIRS:2,20,COBBLESTONE_STAIRS:3,20,MOSSY_COBBLESTONE:0,60,COBBLESTONE_STAIRS:1,20,STEP:11,20,COBBLESTONE:0,100)
RandomBlock(-8,3,7,SMOOTH_BRICK:0,40,SMOOTH_BRICK:1,30,SMOOTH_BRICK:2,30,SMOOTH_STAIRS:0,15,SMOOTH_STAIRS:1,15,SMOOTH_STAIRS:2,15,SMOOTH_STAIRS:3,15,STEP:5,15,STEP:13,15,COBBLE_WALL:0,10,COBBLESTONE_STAIRS:0,10,STEP:3,10,COBBLE_WALL:1,20,COBBLESTONE_STAIRS:2,20,COBBLESTONE_STAIRS:3,20,MOSSY_COBBLESTONE:0,60,COBBLESTONE_STAIRS:1,20,STEP:11,20,COBBLESTONE:0,100)
RandomBlock(-8,4,1,SMOOTH_BRICK:0,40,SMOOTH_BRICK:1,30,SMOOTH_BRICK:2,30,SMOOTH_STAIRS:0,15,SMOOTH_STAIRS:1,15,SMOOTH_STAIRS:2,15,SMOOTH_STAIRS:3,15,STEP:5,15,STEP:13,15,COBBLE_WALL:0,10,COBBLESTONE_STAIRS:0,10,STEP:3,10,COBBLE_WALL:1,20,COBBLESTONE_STAIRS:2,20,COBBLESTONE_STAIRS:3,20,MOSSY_COBBLESTONE:0,60,COBBLESTONE_STAIRS:1,20,STEP:11,20,COBBLESTONE:0,100)
RandomBlock(-8,4,2,SMOOTH_BRICK:0,40,SMOOTH_BRICK:1,30,SMOOTH_BRICK:2,30,SMOOTH_STAIRS:0,15,SMOOTH_STAIRS:1,15,SMOOTH_STAIRS:2,15,SMOOTH_STAIRS:3,15,STEP:5,15,STEP:13,15,COBBLE_WALL:0,10,COBBLESTONE_STAIRS:0,10,STEP:3,10,COBBLE_WALL:1,20,COBBLESTONE_STAIRS:2,20,COBBLESTONE_STAIRS:3,20,MOSSY_COBBLESTONE:0,60,COBBLESTONE_STAIRS:1,20,STEP:11,20,COBBLESTONE:0,100)
RandomBlock(-8,4,3,SMOOTH_BRICK:0,40,SMOOTH_BRICK:1,30,SMOOTH_BRICK:2,30,SMOOTH_STAIRS:0,15,SMOOTH_STAIRS:1,15,SMOOTH_STAIRS:2,15,SMOOTH_STAIRS:3,15,STEP:5,15,STEP:13,15,COBBLE_WALL:0,10,COBBLESTONE_STAIRS:0,10,STEP:3,10,COBBLE_WALL:1,20,COBBLESTONE_STAIRS:2,20,COBBLESTONE_STAIRS:3,20,MOSSY_COBBLESTONE:0,60,COBBLESTONE_STAIRS:1,20,STEP:11,20,COBBLESTONE:0,100)
RandomBlock(-8,4,4,SMOOTH_BRICK:0,40,SMOOTH_BRICK:1,30,SMOOTH_BRICK:2,30,SMOOTH_STAIRS:0,15,SMOOTH_STAIRS:1,15,SMOOTH_STAIRS:2,15,SMOOTH_STAIRS:3,15,STEP:5,15,STEP:13,15,COBBLE_WALL:0,10,COBBLESTONE_STAIRS:0,10,STEP:3,10,COBBLE_WALL:1,20,COBBLESTONE_STAIRS:2,20,COBBLESTONE_STAIRS:3,20,MOSSY_COBBLESTONE:0,60,COBBLESTONE_STAIRS:1,20,STEP:11,20,COBBLESTONE:0,100)
RandomBlock(-8,4,5,SMOOTH_BRICK:0,40,SMOOTH_BRICK:1,30,SMOOTH_BRICK:2,30,SMOOTH_STAIRS:0,15,SMOOTH_STAIRS:1,15,SMOOTH_STAIRS:2,15,SMOOTH_STAIRS:3,15,STEP:5,15,STEP:13,15,COBBLE_WALL:0,10,COBBLESTONE_STAIRS:0,10,STEP:3,10,COBBLE_WALL:1,20,COBBLESTONE_STAIRS:2,20,COBBLESTONE_STAIRS:3,20,MOSSY_COBBLESTONE:0,60,COBBLESTONE_STAIRS:1,20,STEP:11,20,COBBLESTONE:0,100)
RandomBlock(-8,4,6,SMOOTH_BRICK:0,40,SMOOTH_BRICK:1,30,SMOOTH_BRICK:2,30,SMOOTH_STAIRS:0,15,SMOOTH_STAIRS:1,15,SMOOTH_STAIRS:2,15,SMOOTH_STAIRS:3,15,STEP:5,15,STEP:13,15,COBBLE_WALL:0,10,COBBLESTONE_STAIRS:0,10,STEP:3,10,COBBLE_WALL:1,20,COBBLESTONE_STAIRS:2,20,COBBLESTONE_STAIRS:3,20,MOSSY_COBBLESTONE:0,60,COBBLESTONE_STAIRS:1,20,STEP:11,20,COBBLESTONE:0,100)
RandomBlock(-8,4,7,SMOOTH_BRICK:0,40,SMOOTH_BRICK:1,30,SMOOTH_BRICK:2,30,SMOOTH_STAIRS:0,15,SMOOTH_STAIRS:1,15,SMOOTH_STAIRS:2,15,SMOOTH_STAIRS:3,15,STEP:5,15,STEP:13,15,COBBLE_WALL:0,10,COBBLESTONE_STAIRS:0,10,STEP:3,10,COBBLE_WALL:1,20,COBBLESTONE_STAIRS:2,20,COBBLESTONE_STAIRS:3,20,MOSSY_COBBLESTONE:0,60,COBBLESTONE_STAIRS:1,20,STEP:11,20,COBBLESTONE:0,100)
RandomBlock(-8,5,1,quark:limestone:1,30,quark:limestone_wall,10,quark:limestone,100)
RandomBlock(-8,5,2,quark:limestone:1,30,quark:limestone_wall,10,quark:limestone,100)
RandomBlock(-8,5,3,quark:limestone:1,30,quark:limestone_wall,10,quark:limestone,100)
RandomBlock(-8,5,4,quark:limestone:1,30,quark:limestone_wall,10,quark:limestone,100)
RandomBlock(-8,5,5,quark:limestone:1,30,quark:limestone_wall,10,quark:limestone,100)
RandomBlock(-8,5,6,quark:limestone:1,30,quark:limestone_wall,10,quark:limestone,100)
RandomBlock(-8,5,7,quark:limestone:1,30,quark:limestone_wall,10,quark:limestone,100)
RandomBlock(-8,6,1,quark:limestone:1,30,quark:limestone_wall,10,quark:limestone,100)
RandomBlock(-8,6,2,quark:limestone:1,30,quark:limestone_wall,10,quark:limestone,100)
RandomBlock(-8,6,3,quark:limestone:1,30,quark:limestone_wall,10,quark:limestone,100)
RandomBlock(-8,6,4,quark:limestone:1,30,quark:limestone_wall,10,quark:limestone,100)
RandomBlock(-8,6,5,quark:limestone:1,30,quark:limestone_wall,10,quark:limestone,100)
RandomBlock(-8,6,6,quark:limestone:1,30,quark:limestone_wall,10,quark:limestone,100)
RandomBlock(-8,6,7,quark:limestone:1,30,quark:limestone_wall,10,quark:limestone,100)
RandomBlock(-8,7,1,quark:limestone:1,30,quark:limestone_wall,10,quark:limestone,100)
RandomBlock(-8,7,2,quark:limestone:1,30,quark:limestone_wall,10,quark:limestone,100)
RandomBlock(-8,7,3,quark:limestone:1,30,quark:limestone_wall,10,quark:limestone,100)
RandomBlock(-8,7,4,quark:limestone:1,30,quark:limestone_wall,10,quark:limestone,100)
RandomBlock(-8,7,5,quark:limestone:1,30,quark:limestone_wall,10,quark:limestone,100)
RandomBlock(-8,7,6,quark:limestone:1,30,quark:limestone_wall,10,quark:limestone,100)
RandomBlock(-8,7,7,quark:limestone:1,30,quark:limestone_wall,10,quark:limestone,100)
Block(-8,8,1,inspirations:redstone_barrel)
Block(-8,8,4,inspirations:redstone_barrel)
Block(-8,8,7,inspirations:redstone_barrel)
Block(-8,9,1,inspirations:redstone_barrel)
Block(-8,9,4,inspirations:redstone_barrel)
Block(-8,9,7,inspirations:redstone_barrel)
RandomBlock(-8,10,1,quark:limestone:1,30,quark:limestone_wall,10,quark:limestone,100)
RandomBlock(-8,10,2,quark:limestone:1,30,quark:limestone_wall,10,quark:limestone,100)
RandomBlock(-8,10,3,quark:limestone:1,30,quark:limestone_wall,10,quark:limestone,100)
RandomBlock(-8,10,4,quark:limestone:1,30,quark:limestone_wall,10,quark:limestone,100)
RandomBlock(-8,10,5,quark:limestone:1,30,quark:limestone_wall,10,quark:limestone,100)
RandomBlock(-8,10,6,quark:limestone:1,30,quark:limestone_wall,10,quark:limestone,100)
RandomBlock(-8,10,7,quark:limestone:1,30,quark:limestone_wall,10,quark:limestone,100)
RandomBlock(-8,11,1,quark:limestone:1,30,quark:limestone_wall,10,quark:limestone,100)
RandomBlock(-8,11,2,quark:limestone:1,30,quark:limestone_wall,10,quark:limestone,100)
RandomBlock(-8,11,3,quark:limestone:1,30,quark:limestone_wall,10,quark:limestone,100)
RandomBlock(-8,11,4,quark:limestone:1,30,quark:limestone_wall,10,quark:limestone,100)
RandomBlock(-8,11,5,quark:limestone:1,30,quark:limestone_wall,10,quark:limestone,100)
RandomBlock(-8,11,6,quark:limestone:1,30,quark:limestone_wall,10,quark:limestone,100)
RandomBlock(-8,11,7,quark:limestone:1,30,quark:limestone_wall,10,quark:limestone,100)
Block(-8,12,4,quark:iron_plate:1)
Block(-8,12,6,VINE:8)
Block(-8,12,7,VINE:8)
Block(-8,13,4,quark:iron_plate:1)
Block(-8,13,6,VINE:8)
Block(-8,13,7,VINE:8)
RandomBlock(-7,0,-1,SMOOTH_BRICK:0,40,SMOOTH_BRICK:1,30,SMOOTH_BRICK:2,30,SMOOTH_STAIRS:0,15,SMOOTH_STAIRS:1,15,SMOOTH_STAIRS:2,15,SMOOTH_STAIRS:3,15,STEP:5,15,STEP:13,15,COBBLE_WALL:0,10,COBBLESTONE_STAIRS:0,10,STEP:3,10,COBBLE_WALL:1,20,COBBLESTONE_STAIRS:2,20,COBBLESTONE_STAIRS:3,20,MOSSY_COBBLESTONE:0,60,COBBLESTONE_STAIRS:1,20,STEP:11,20,COBBLESTONE:0,100)
RandomBlock(-7,0,0,SMOOTH_BRICK:0,40,SMOOTH_BRICK:1,30,SMOOTH_BRICK:2,30,SMOOTH_STAIRS:0,15,SMOOTH_STAIRS:1,15,SMOOTH_STAIRS:2,15,SMOOTH_STAIRS:3,15,STEP:5,15,STEP:13,15,COBBLE_WALL:0,10,COBBLESTONE_STAIRS:0,10,STEP:3,10,COBBLE_WALL:1,20,COBBLESTONE_STAIRS:2,20,COBBLESTONE_STAIRS:3,20,MOSSY_COBBLESTONE:0,60,COBBLESTONE_STAIRS:1,20,STEP:11,20,COBBLESTONE:0,100)
RandomBlock(-7,0,1,SMOOTH_BRICK:0,40,SMOOTH_BRICK:1,30,SMOOTH_BRICK:2,30,SMOOTH_STAIRS:0,15,SMOOTH_STAIRS:1,15,SMOOTH_STAIRS:2,15,SMOOTH_STAIRS:3,15,STEP:5,15,STEP:13,15,COBBLE_WALL:0,10,COBBLESTONE_STAIRS:0,10,STEP:3,10,COBBLE_WALL:1,20,COBBLESTONE_STAIRS:2,20,COBBLESTONE_STAIRS:3,20,MOSSY_COBBLESTONE:0,60,COBBLESTONE_STAIRS:1,20,STEP:11,20,COBBLESTONE:0,100)
RandomBlock(-7,0,2,SMOOTH_BRICK:0,40,SMOOTH_BRICK:1,30,SMOOTH_BRICK:2,30,SMOOTH_STAIRS:0,15,SMOOTH_STAIRS:1,15,SMOOTH_STAIRS:2,15,SMOOTH_STAIRS:3,15,STEP:5,15,STEP:13,15,COBBLE_WALL:0,10,COBBLESTONE_STAIRS:0,10,STEP:3,10,COBBLE_WALL:1,20,COBBLESTONE_STAIRS:2,20,COBBLESTONE_STAIRS:3,20,MOSSY_COBBLESTONE:0,60,COBBLESTONE_STAIRS:1,20,STEP:11,20,COBBLESTONE:0,100)
RandomBlock(-7,0,3,SMOOTH_BRICK:0,40,SMOOTH_BRICK:1,30,SMOOTH_BRICK:2,30,SMOOTH_STAIRS:0,15,SMOOTH_STAIRS:1,15,SMOOTH_STAIRS:2,15,SMOOTH_STAIRS:3,15,STEP:5,15,STEP:13,15,COBBLE_WALL:0,10,COBBLESTONE_STAIRS:0,10,STEP:3,10,COBBLE_WALL:1,20,COBBLESTONE_STAIRS:2,20,COBBLESTONE_STAIRS:3,20,MOSSY_COBBLESTONE:0,60,COBBLESTONE_STAIRS:1,20,STEP:11,20,COBBLESTONE:0,100)
RandomBlock(-7,0,4,SMOOTH_BRICK:0,40,SMOOTH_BRICK:1,30,SMOOTH_BRICK:2,30,SMOOTH_STAIRS:0,15,SMOOTH_STAIRS:1,15,SMOOTH_STAIRS:2,15,SMOOTH_STAIRS:3,15,STEP:5,15,STEP:13,15,COBBLE_WALL:0,10,COBBLESTONE_STAIRS:0,10,STEP:3,10,COBBLE_WALL:1,20,COBBLESTONE_STAIRS:2,20,COBBLESTONE_STAIRS:3,20,MOSSY_COBBLESTONE:0,60,COBBLESTONE_STAIRS:1,20,STEP:11,20,COBBLESTONE:0,100)
RandomBlock(-7,0,5,SMOOTH_BRICK:0,40,SMOOTH_BRICK:1,30,SMOOTH_BRICK:2,30,SMOOTH_STAIRS:0,15,SMOOTH_STAIRS:1,15,SMOOTH_STAIRS:2,15,SMOOTH_STAIRS:3,15,STEP:5,15,STEP:13,15,COBBLE_WALL:0,10,COBBLESTONE_STAIRS:0,10,STEP:3,10,COBBLE_WALL:1,20,COBBLESTONE_STAIRS:2,20,COBBLESTONE_STAIRS:3,20,MOSSY_COBBLESTONE:0,60,COBBLESTONE_STAIRS:1,20,STEP:11,20,COBBLESTONE:0,100)
RandomBlock(-7,0,6,SMOOTH_BRICK:0,40,SMOOTH_BRICK:1,30,SMOOTH_BRICK:2,30,SMOOTH_STAIRS:0,15,SMOOTH_STAIRS:1,15,SMOOTH_STAIRS:2,15,SMOOTH_STAIRS:3,15,STEP:5,15,STEP:13,15,COBBLE_WALL:0,10,COBBLESTONE_STAIRS:0,10,STEP:3,10,COBBLE_WALL:1,20,COBBLESTONE_STAIRS:2,20,COBBLESTONE_STAIRS:3,20,MOSSY_COBBLESTONE:0,60,COBBLESTONE_STAIRS:1,20,STEP:11,20,COBBLESTONE:0,100)
RandomBlock(-7,0,7,SMOOTH_BRICK:0,40,SMOOTH_BRICK:1,30,SMOOTH_BRICK:2,30,SMOOTH_STAIRS:0,15,SMOOTH_STAIRS:1,15,SMOOTH_STAIRS:2,15,SMOOTH_STAIRS:3,15,STEP:5,15,STEP:13,15,COBBLE_WALL:0,10,COBBLESTONE_STAIRS:0,10,STEP:3,10,COBBLE_WALL:1,20,COBBLESTONE_STAIRS:2,20,COBBLESTONE_STAIRS:3,20,MOSSY_COBBLESTONE:0,60,COBBLESTONE_STAIRS:1,20,STEP:11,20,COBBLESTONE:0,100)
RandomBlock(-7,0,8,SMOOTH_BRICK:0,40,SMOOTH_BRICK:1,30,SMOOTH_BRICK:2,30,SMOOTH_STAIRS:0,15,SMOOTH_STAIRS:1,15,SMOOTH_STAIRS:2,15,SMOOTH_STAIRS:3,15,STEP:5,15,STEP:13,15,COBBLE_WALL:0,10,COBBLESTONE_STAIRS:0,10,STEP:3,10,COBBLE_WALL:1,20,COBBLESTONE_STAIRS:2,20,COBBLESTONE_STAIRS:3,20,MOSSY_COBBLESTONE:0,60,COBBLESTONE_STAIRS:1,20,STEP:11,20,COBBLESTONE:0,100)
RandomBlock(-7,1,-1,SMOOTH_BRICK:0,40,SMOOTH_BRICK:1,30,SMOOTH_BRICK:2,30,SMOOTH_STAIRS:0,15,SMOOTH_STAIRS:1,15,SMOOTH_STAIRS:2,15,SMOOTH_STAIRS:3,15,STEP:5,15,STEP:13,15,COBBLE_WALL:0,10,COBBLESTONE_STAIRS:0,10,STEP:3,10,COBBLE_WALL:1,20,COBBLESTONE_STAIRS:2,20,COBBLESTONE_STAIRS:3,20,MOSSY_COBBLESTONE:0,60,COBBLESTONE_STAIRS:1,20,STEP:11,20,COBBLESTONE:0,100)
RandomBlock(-7,1,0,SMOOTH_BRICK:0,40,SMOOTH_BRICK:1,30,SMOOTH_BRICK:2,30,SMOOTH_STAIRS:0,15,SMOOTH_STAIRS:1,15,SMOOTH_STAIRS:2,15,SMOOTH_STAIRS:3,15,STEP:5,15,STEP:13,15,COBBLE_WALL:0,10,COBBLESTONE_STAIRS:0,10,STEP:3,10,COBBLE_WALL:1,20,COBBLESTONE_STAIRS:2,20,COBBLESTONE_STAIRS:3,20,MOSSY_COBBLESTONE:0,60,COBBLESTONE_STAIRS:1,20,STEP:11,20,COBBLESTONE:0,100)
RandomBlock(-7,1,1,SMOOTH_BRICK:0,40,SMOOTH_BRICK:1,30,SMOOTH_BRICK:2,30,SMOOTH_STAIRS:0,15,SMOOTH_STAIRS:1,15,SMOOTH_STAIRS:2,15,SMOOTH_STAIRS:3,15,STEP:5,15,STEP:13,15,COBBLE_WALL:0,10,COBBLESTONE_STAIRS:0,10,STEP:3,10,COBBLE_WALL:1,20,COBBLESTONE_STAIRS:2,20,COBBLESTONE_STAIRS:3,20,MOSSY_COBBLESTONE:0,60,COBBLESTONE_STAIRS:1,20,STEP:11,20,COBBLESTONE:0,100)
RandomBlock(-7,1,2,SMOOTH_BRICK:0,40,SMOOTH_BRICK:1,30,SMOOTH_BRICK:2,30,SMOOTH_STAIRS:0,15,SMOOTH_STAIRS:1,15,SMOOTH_STAIRS:2,15,SMOOTH_STAIRS:3,15,STEP:5,15,STEP:13,15,COBBLE_WALL:0,10,COBBLESTONE_STAIRS:0,10,STEP:3,10,COBBLE_WALL:1,20,COBBLESTONE_STAIRS:2,20,COBBLESTONE_STAIRS:3,20,MOSSY_COBBLESTONE:0,60,COBBLESTONE_STAIRS:1,20,STEP:11,20,COBBLESTONE:0,100)
RandomBlock(-7,1,3,SMOOTH_BRICK:0,40,SMOOTH_BRICK:1,30,SMOOTH_BRICK:2,30,SMOOTH_STAIRS:0,15,SMOOTH_STAIRS:1,15,SMOOTH_STAIRS:2,15,SMOOTH_STAIRS:3,15,STEP:5,15,STEP:13,15,COBBLE_WALL:0,10,COBBLESTONE_STAIRS:0,10,STEP:3,10,COBBLE_WALL:1,20,COBBLESTONE_STAIRS:2,20,COBBLESTONE_STAIRS:3,20,MOSSY_COBBLESTONE:0,60,COBBLESTONE_STAIRS:1,20,STEP:11,20,COBBLESTONE:0,100)
RandomBlock(-7,1,4,SMOOTH_BRICK:0,40,SMOOTH_BRICK:1,30,SMOOTH_BRICK:2,30,SMOOTH_STAIRS:0,15,SMOOTH_STAIRS:1,15,SMOOTH_STAIRS:2,15,SMOOTH_STAIRS:3,15,STEP:5,15,STEP:13,15,COBBLE_WALL:0,10,COBBLESTONE_STAIRS:0,10,STEP:3,10,COBBLE_WALL:1,20,COBBLESTONE_STAIRS:2,20,COBBLESTONE_STAIRS:3,20,MOSSY_COBBLESTONE:0,60,COBBLESTONE_STAIRS:1,20,STEP:11,20,COBBLESTONE:0,100)
RandomBlock(-7,1,5,SMOOTH_BRICK:0,40,SMOOTH_BRICK:1,30,SMOOTH_BRICK:2,30,SMOOTH_STAIRS:0,15,SMOOTH_STAIRS:1,15,SMOOTH_STAIRS:2,15,SMOOTH_STAIRS:3,15,STEP:5,15,STEP:13,15,COBBLE_WALL:0,10,COBBLESTONE_STAIRS:0,10,STEP:3,10,COBBLE_WALL:1,20,COBBLESTONE_STAIRS:2,20,COBBLESTONE_STAIRS:3,20,MOSSY_COBBLESTONE:0,60,COBBLESTONE_STAIRS:1,20,STEP:11,20,COBBLESTONE:0,100)
RandomBlock(-7,1,6,SMOOTH_BRICK:0,40,SMOOTH_BRICK:1,30,SMOOTH_BRICK:2,30,SMOOTH_STAIRS:0,15,SMOOTH_STAIRS:1,15,SMOOTH_STAIRS:2,15,SMOOTH_STAIRS:3,15,STEP:5,15,STEP:13,15,COBBLE_WALL:0,10,COBBLESTONE_STAIRS:0,10,STEP:3,10,COBBLE_WALL:1,20,COBBLESTONE_STAIRS:2,20,COBBLESTONE_STAIRS:3,20,MOSSY_COBBLESTONE:0,60,COBBLESTONE_STAIRS:1,20,STEP:11,20,COBBLESTONE:0,100)
RandomBlock(-7,1,7,SMOOTH_BRICK:0,40,SMOOTH_BRICK:1,30,SMOOTH_BRICK:2,30,SMOOTH_STAIRS:0,15,SMOOTH_STAIRS:1,15,SMOOTH_STAIRS:2,15,SMOOTH_STAIRS:3,15,STEP:5,15,STEP:13,15,COBBLE_WALL:0,10,COBBLESTONE_STAIRS:0,10,STEP:3,10,COBBLE_WALL:1,20,COBBLESTONE_STAIRS:2,20,COBBLESTONE_STAIRS:3,20,MOSSY_COBBLESTONE:0,60,COBBLESTONE_STAIRS:1,20,STEP:11,20,COBBLESTONE:0,100)
RandomBlock(-7,1,8,SMOOTH_BRICK:0,40,SMOOTH_BRICK:1,30,SMOOTH_BRICK:2,30,SMOOTH_STAIRS:0,15,SMOOTH_STAIRS:1,15,SMOOTH_STAIRS:2,15,SMOOTH_STAIRS:3,15,STEP:5,15,STEP:13,15,COBBLE_WALL:0,10,COBBLESTONE_STAIRS:0,10,STEP:3,10,COBBLE_WALL:1,20,COBBLESTONE_STAIRS:2,20,COBBLESTONE_STAIRS:3,20,MOSSY_COBBLESTONE:0,60,COBBLESTONE_STAIRS:1,20,STEP:11,20,COBBLESTONE:0,100)
RandomBlock(-7,2,-1,SMOOTH_BRICK:0,40,SMOOTH_BRICK:1,30,SMOOTH_BRICK:2,30,SMOOTH_STAIRS:0,15,SMOOTH_STAIRS:1,15,SMOOTH_STAIRS:2,15,SMOOTH_STAIRS:3,15,STEP:5,15,STEP:13,15,COBBLE_WALL:0,10,COBBLESTONE_STAIRS:0,10,STEP:3,10,COBBLE_WALL:1,20,COBBLESTONE_STAIRS:2,20,COBBLESTONE_STAIRS:3,20,MOSSY_COBBLESTONE:0,60,COBBLESTONE_STAIRS:1,20,STEP:11,20,COBBLESTONE:0,100)
RandomBlock(-7,2,0,SMOOTH_BRICK:0,40,SMOOTH_BRICK:1,30,SMOOTH_BRICK:2,30,SMOOTH_STAIRS:0,15,SMOOTH_STAIRS:1,15,SMOOTH_STAIRS:2,15,SMOOTH_STAIRS:3,15,STEP:5,15,STEP:13,15,COBBLE_WALL:0,10,COBBLESTONE_STAIRS:0,10,STEP:3,10,COBBLE_WALL:1,20,COBBLESTONE_STAIRS:2,20,COBBLESTONE_STAIRS:3,20,MOSSY_COBBLESTONE:0,60,COBBLESTONE_STAIRS:1,20,STEP:11,20,COBBLESTONE:0,100)
RandomBlock(-7,2,1,SMOOTH_BRICK:0,40,SMOOTH_BRICK:1,30,SMOOTH_BRICK:2,30,SMOOTH_STAIRS:0,15,SMOOTH_STAIRS:1,15,SMOOTH_STAIRS:2,15,SMOOTH_STAIRS:3,15,STEP:5,15,STEP:13,15,COBBLE_WALL:0,10,COBBLESTONE_STAIRS:0,10,STEP:3,10,COBBLE_WALL:1,20,COBBLESTONE_STAIRS:2,20,COBBLESTONE_STAIRS:3,20,MOSSY_COBBLESTONE:0,60,COBBLESTONE_STAIRS:1,20,STEP:11,20,COBBLESTONE:0,100)
RandomBlock(-7,2,2,SMOOTH_BRICK:0,40,SMOOTH_BRICK:1,30,SMOOTH_BRICK:2,30,SMOOTH_STAIRS:0,15,SMOOTH_STAIRS:1,15,SMOOTH_STAIRS:2,15,SMOOTH_STAIRS:3,15,STEP:5,15,STEP:13,15,COBBLE_WALL:0,10,COBBLESTONE_STAIRS:0,10,STEP:3,10,COBBLE_WALL:1,20,COBBLESTONE_STAIRS:2,20,COBBLESTONE_STAIRS:3,20,MOSSY_COBBLESTONE:0,60,COBBLESTONE_STAIRS:1,20,STEP:11,20,COBBLESTONE:0,100)
RandomBlock(-7,2,3,SMOOTH_BRICK:0,40,SMOOTH_BRICK:1,30,SMOOTH_BRICK:2,30,SMOOTH_STAIRS:0,15,SMOOTH_STAIRS:1,15,SMOOTH_STAIRS:2,15,SMOOTH_STAIRS:3,15,STEP:5,15,STEP:13,15,COBBLE_WALL:0,10,COBBLESTONE_STAIRS:0,10,STEP:3,10,COBBLE_WALL:1,20,COBBLESTONE_STAIRS:2,20,COBBLESTONE_STAIRS:3,20,MOSSY_COBBLESTONE:0,60,COBBLESTONE_STAIRS:1,20,STEP:11,20,COBBLESTONE:0,100)
RandomBlock(-7,2,4,SMOOTH_BRICK:0,40,SMOOTH_BRICK:1,30,SMOOTH_BRICK:2,30,SMOOTH_STAIRS:0,15,SMOOTH_STAIRS:1,15,SMOOTH_STAIRS:2,15,SMOOTH_STAIRS:3,15,STEP:5,15,STEP:13,15,COBBLE_WALL:0,10,COBBLESTONE_STAIRS:0,10,STEP:3,10,COBBLE_WALL:1,20,COBBLESTONE_STAIRS:2,20,COBBLESTONE_STAIRS:3,20,MOSSY_COBBLESTONE:0,60,COBBLESTONE_STAIRS:1,20,STEP:11,20,COBBLESTONE:0,100)
RandomBlock(-7,2,5,SMOOTH_BRICK:0,40,SMOOTH_BRICK:1,30,SMOOTH_BRICK:2,30,SMOOTH_STAIRS:0,15,SMOOTH_STAIRS:1,15,SMOOTH_STAIRS:2,15,SMOOTH_STAIRS:3,15,STEP:5,15,STEP:13,15,COBBLE_WALL:0,10,COBBLESTONE_STAIRS:0,10,STEP:3,10,COBBLE_WALL:1,20,COBBLESTONE_STAIRS:2,20,COBBLESTONE_STAIRS:3,20,MOSSY_COBBLESTONE:0,60,COBBLESTONE_STAIRS:1,20,STEP:11,20,COBBLESTONE:0,100)
RandomBlock(-7,2,6,SMOOTH_BRICK:0,40,SMOOTH_BRICK:1,30,SMOOTH_BRICK:2,30,SMOOTH_STAIRS:0,15,SMOOTH_STAIRS:1,15,SMOOTH_STAIRS:2,15,SMOOTH_STAIRS:3,15,STEP:5,15,STEP:13,15,COBBLE_WALL:0,10,COBBLESTONE_STAIRS:0,10,STEP:3,10,COBBLE_WALL:1,20,COBBLESTONE_STAIRS:2,20,COBBLESTONE_STAIRS:3,20,MOSSY_COBBLESTONE:0,60,COBBLESTONE_STAIRS:1,20,STEP:11,20,COBBLESTONE:0,100)
RandomBlock(-7,2,7,SMOOTH_BRICK:0,40,SMOOTH_BRICK:1,30,SMOOTH_BRICK:2,30,SMOOTH_STAIRS:0,15,SMOOTH_STAIRS:1,15,SMOOTH_STAIRS:2,15,SMOOTH_STAIRS:3,15,STEP:5,15,STEP:13,15,COBBLE_WALL:0,10,COBBLESTONE_STAIRS:0,10,STEP:3,10,COBBLE_WALL:1,20,COBBLESTONE_STAIRS:2,20,COBBLESTONE_STAIRS:3,20,MOSSY_COBBLESTONE:0,60,COBBLESTONE_STAIRS:1,20,STEP:11,20,COBBLESTONE:0,100)
RandomBlock(-7,2,8,SMOOTH_BRICK:0,40,SMOOTH_BRICK:1,30,SMOOTH_BRICK:2,30,SMOOTH_STAIRS:0,15,SMOOTH_STAIRS:1,15,SMOOTH_STAIRS:2,15,SMOOTH_STAIRS:3,15,STEP:5,15,STEP:13,15,COBBLE_WALL:0,10,COBBLESTONE_STAIRS:0,10,STEP:3,10,COBBLE_WALL:1,20,COBBLESTONE_STAIRS:2,20,COBBLESTONE_STAIRS:3,20,MOSSY_COBBLESTONE:0,60,COBBLESTONE_STAIRS:1,20,STEP:11,20,COBBLESTONE:0,100)
RandomBlock(-7,3,-1,SMOOTH_BRICK:0,40,SMOOTH_BRICK:1,30,SMOOTH_BRICK:2,30,SMOOTH_STAIRS:0,15,SMOOTH_STAIRS:1,15,SMOOTH_STAIRS:2,15,SMOOTH_STAIRS:3,15,STEP:5,15,STEP:13,15,COBBLE_WALL:0,10,COBBLESTONE_STAIRS:0,10,STEP:3,10,COBBLE_WALL:1,20,COBBLESTONE_STAIRS:2,20,COBBLESTONE_STAIRS:3,20,MOSSY_COBBLESTONE:0,60,COBBLESTONE_STAIRS:1,20,STEP:11,20,COBBLESTONE:0,100)
RandomBlock(-7,3,0,SMOOTH_BRICK:0,40,SMOOTH_BRICK:1,30,SMOOTH_BRICK:2,30,SMOOTH_STAIRS:0,15,SMOOTH_STAIRS:1,15,SMOOTH_STAIRS:2,15,SMOOTH_STAIRS:3,15,STEP:5,15,STEP:13,15,COBBLE_WALL:0,10,COBBLESTONE_STAIRS:0,10,STEP:3,10,COBBLE_WALL:1,20,COBBLESTONE_STAIRS:2,20,COBBLESTONE_STAIRS:3,20,MOSSY_COBBLESTONE:0,60,COBBLESTONE_STAIRS:1,20,STEP:11,20,COBBLESTONE:0,100)
RandomBlock(-7,3,1,SMOOTH_BRICK:0,40,SMOOTH_BRICK:1,30,SMOOTH_BRICK:2,30,SMOOTH_STAIRS:0,15,SMOOTH_STAIRS:1,15,SMOOTH_STAIRS:2,15,SMOOTH_STAIRS:3,15,STEP:5,15,STEP:13,15,COBBLE_WALL:0,10,COBBLESTONE_STAIRS:0,10,STEP:3,10,COBBLE_WALL:1,20,COBBLESTONE_STAIRS:2,20,COBBLESTONE_STAIRS:3,20,MOSSY_COBBLESTONE:0,60,COBBLESTONE_STAIRS:1,20,STEP:11,20,COBBLESTONE:0,100)
RandomBlock(-7,3,2,SMOOTH_BRICK:0,40,SMOOTH_BRICK:1,30,SMOOTH_BRICK:2,30,SMOOTH_STAIRS:0,15,SMOOTH_STAIRS:1,15,SMOOTH_STAIRS:2,15,SMOOTH_STAIRS:3,15,STEP:5,15,STEP:13,15,COBBLE_WALL:0,10,COBBLESTONE_STAIRS:0,10,STEP:3,10,COBBLE_WALL:1,20,COBBLESTONE_STAIRS:2,20,COBBLESTONE_STAIRS:3,20,MOSSY_COBBLESTONE:0,60,COBBLESTONE_STAIRS:1,20,STEP:11,20,COBBLESTONE:0,100)
RandomBlock(-7,3,3,SMOOTH_BRICK:0,40,SMOOTH_BRICK:1,30,SMOOTH_BRICK:2,30,SMOOTH_STAIRS:0,15,SMOOTH_STAIRS:1,15,SMOOTH_STAIRS:2,15,SMOOTH_STAIRS:3,15,STEP:5,15,STEP:13,15,COBBLE_WALL:0,10,COBBLESTONE_STAIRS:0,10,STEP:3,10,COBBLE_WALL:1,20,COBBLESTONE_STAIRS:2,20,COBBLESTONE_STAIRS:3,20,MOSSY_COBBLESTONE:0,60,COBBLESTONE_STAIRS:1,20,STEP:11,20,COBBLESTONE:0,100)
RandomBlock(-7,3,4,SMOOTH_BRICK:0,40,SMOOTH_BRICK:1,30,SMOOTH_BRICK:2,30,SMOOTH_STAIRS:0,15,SMOOTH_STAIRS:1,15,SMOOTH_STAIRS:2,15,SMOOTH_STAIRS:3,15,STEP:5,15,STEP:13,15,COBBLE_WALL:0,10,COBBLESTONE_STAIRS:0,10,STEP:3,10,COBBLE_WALL:1,20,COBBLESTONE_STAIRS:2,20,COBBLESTONE_STAIRS:3,20,MOSSY_COBBLESTONE:0,60,COBBLESTONE_STAIRS:1,20,STEP:11,20,COBBLESTONE:0,100)
RandomBlock(-7,3,5,SMOOTH_BRICK:0,40,SMOOTH_BRICK:1,30,SMOOTH_BRICK:2,30,SMOOTH_STAIRS:0,15,SMOOTH_STAIRS:1,15,SMOOTH_STAIRS:2,15,SMOOTH_STAIRS:3,15,STEP:5,15,STEP:13,15,COBBLE_WALL:0,10,COBBLESTONE_STAIRS:0,10,STEP:3,10,COBBLE_WALL:1,20,COBBLESTONE_STAIRS:2,20,COBBLESTONE_STAIRS:3,20,MOSSY_COBBLESTONE:0,60,COBBLESTONE_STAIRS:1,20,STEP:11,20,COBBLESTONE:0,100)
RandomBlock(-7,3,6,SMOOTH_BRICK:0,40,SMOOTH_BRICK:1,30,SMOOTH_BRICK:2,30,SMOOTH_STAIRS:0,15,SMOOTH_STAIRS:1,15,SMOOTH_STAIRS:2,15,SMOOTH_STAIRS:3,15,STEP:5,15,STEP:13,15,COBBLE_WALL:0,10,COBBLESTONE_STAIRS:0,10,STEP:3,10,COBBLE_WALL:1,20,COBBLESTONE_STAIRS:2,20,COBBLESTONE_STAIRS:3,20,MOSSY_COBBLESTONE:0,60,COBBLESTONE_STAIRS:1,20,STEP:11,20,COBBLESTONE:0,100)
RandomBlock(-7,3,7,SMOOTH_BRICK:0,40,SMOOTH_BRICK:1,30,SMOOTH_BRICK:2,30,SMOOTH_STAIRS:0,15,SMOOTH_STAIRS:1,15,SMOOTH_STAIRS:2,15,SMOOTH_STAIRS:3,15,STEP:5,15,STEP:13,15,COBBLE_WALL:0,10,COBBLESTONE_STAIRS:0,10,STEP:3,10,COBBLE_WALL:1,20,COBBLESTONE_STAIRS:2,20,COBBLESTONE_STAIRS:3,20,MOSSY_COBBLESTONE:0,60,COBBLESTONE_STAIRS:1,20,STEP:11,20,COBBLESTONE:0,100)
RandomBlock(-7,3,8,SMOOTH_BRICK:0,40,SMOOTH_BRICK:1,30,SMOOTH_BRICK:2,30,SMOOTH_STAIRS:0,15,SMOOTH_STAIRS:1,15,SMOOTH_STAIRS:2,15,SMOOTH_STAIRS:3,15,STEP:5,15,STEP:13,15,COBBLE_WALL:0,10,COBBLESTONE_STAIRS:0,10,STEP:3,10,COBBLE_WALL:1,20,COBBLESTONE_STAIRS:2,20,COBBLESTONE_STAIRS:3,20,MOSSY_COBBLESTONE:0,60,COBBLESTONE_STAIRS:1,20,STEP:11,20,COBBLESTONE:0,100)
RandomBlock(-7,4,-1,SMOOTH_BRICK:0,40,SMOOTH_BRICK:1,30,SMOOTH_BRICK:2,30,SMOOTH_STAIRS:0,15,SMOOTH_STAIRS:1,15,SMOOTH_STAIRS:2,15,SMOOTH_STAIRS:3,15,STEP:5,15,STEP:13,15,COBBLE_WALL:0,10,COBBLESTONE_STAIRS:0,10,STEP:3,10,COBBLE_WALL:1,20,COBBLESTONE_STAIRS:2,20,COBBLESTONE_STAIRS:3,20,MOSSY_COBBLESTONE:0,60,COBBLESTONE_STAIRS:1,20,STEP:11,20,COBBLESTONE:0,100)
RandomBlock(-7,4,0,SMOOTH_BRICK:0,40,SMOOTH_BRICK:1,30,SMOOTH_BRICK:2,30,SMOOTH_STAIRS:0,15,SMOOTH_STAIRS:1,15,SMOOTH_STAIRS:2,15,SMOOTH_STAIRS:3,15,STEP:5,15,STEP:13,15,COBBLE_WALL:0,10,COBBLESTONE_STAIRS:0,10,STEP:3,10,COBBLE_WALL:1,20,COBBLESTONE_STAIRS:2,20,COBBLESTONE_STAIRS:3,20,MOSSY_COBBLESTONE:0,60,COBBLESTONE_STAIRS:1,20,STEP:11,20,COBBLESTONE:0,100)
RandomBlock(-7,4,1,SMOOTH_BRICK:0,40,SMOOTH_BRICK:1,30,SMOOTH_BRICK:2,30,SMOOTH_STAIRS:0,15,SMOOTH_STAIRS:1,15,SMOOTH_STAIRS:2,15,SMOOTH_STAIRS:3,15,STEP:5,15,STEP:13,15,COBBLE_WALL:0,10,COBBLESTONE_STAIRS:0,10,STEP:3,10,COBBLE_WALL:1,20,COBBLESTONE_STAIRS:2,20,COBBLESTONE_STAIRS:3,20,MOSSY_COBBLESTONE:0,60,COBBLESTONE_STAIRS:1,20,STEP:11,20,COBBLESTONE:0,100)
RandomBlock(-7,4,2,SMOOTH_BRICK:0,40,SMOOTH_BRICK:1,30,SMOOTH_BRICK:2,30,SMOOTH_STAIRS:0,15,SMOOTH_STAIRS:1,15,SMOOTH_STAIRS:2,15,SMOOTH_STAIRS:3,15,STEP:5,15,STEP:13,15,COBBLE_WALL:0,10,COBBLESTONE_STAIRS:0,10,STEP:3,10,COBBLE_WALL:1,20,COBBLESTONE_STAIRS:2,20,COBBLESTONE_STAIRS:3,20,MOSSY_COBBLESTONE:0,60,COBBLESTONE_STAIRS:1,20,STEP:11,20,COBBLESTONE:0,100)
RandomBlock(-7,4,3,SMOOTH_BRICK:0,40,SMOOTH_BRICK:1,30,SMOOTH_BRICK:2,30,SMOOTH_STAIRS:0,15,SMOOTH_STAIRS:1,15,SMOOTH_STAIRS:2,15,SMOOTH_STAIRS:3,15,STEP:5,15,STEP:13,15,COBBLE_WALL:0,10,COBBLESTONE_STAIRS:0,10,STEP:3,10,COBBLE_WALL:1,20,COBBLESTONE_STAIRS:2,20,COBBLESTONE_STAIRS:3,20,MOSSY_COBBLESTONE:0,60,COBBLESTONE_STAIRS:1,20,STEP:11,20,COBBLESTONE:0,100)
RandomBlock(-7,4,4,SMOOTH_BRICK:0,40,SMOOTH_BRICK:1,30,SMOOTH_BRICK:2,30,SMOOTH_STAIRS:0,15,SMOOTH_STAIRS:1,15,SMOOTH_STAIRS:2,15,SMOOTH_STAIRS:3,15,STEP:5,15,STEP:13,15,COBBLE_WALL:0,10,COBBLESTONE_STAIRS:0,10,STEP:3,10,COBBLE_WALL:1,20,COBBLESTONE_STAIRS:2,20,COBBLESTONE_STAIRS:3,20,MOSSY_COBBLESTONE:0,60,COBBLESTONE_STAIRS:1,20,STEP:11,20,COBBLESTONE:0,100)
RandomBlock(-7,4,5,SMOOTH_BRICK:0,40,SMOOTH_BRICK:1,30,SMOOTH_BRICK:2,30,SMOOTH_STAIRS:0,15,SMOOTH_STAIRS:1,15,SMOOTH_STAIRS:2,15,SMOOTH_STAIRS:3,15,STEP:5,15,STEP:13,15,COBBLE_WALL:0,10,COBBLESTONE_STAIRS:0,10,STEP:3,10,COBBLE_WALL:1,20,COBBLESTONE_STAIRS:2,20,COBBLESTONE_STAIRS:3,20,MOSSY_COBBLESTONE:0,60,COBBLESTONE_STAIRS:1,20,STEP:11,20,COBBLESTONE:0,100)
RandomBlock(-7,4,6,SMOOTH_BRICK:0,40,SMOOTH_BRICK:1,30,SMOOTH_BRICK:2,30,SMOOTH_STAIRS:0,15,SMOOTH_STAIRS:1,15,SMOOTH_STAIRS:2,15,SMOOTH_STAIRS:3,15,STEP:5,15,STEP:13,15,COBBLE_WALL:0,10,COBBLESTONE_STAIRS:0,10,STEP:3,10,COBBLE_WALL:1,20,COBBLESTONE_STAIRS:2,20,COBBLESTONE_STAIRS:3,20,MOSSY_COBBLESTONE:0,60,COBBLESTONE_STAIRS:1,20,STEP:11,20,COBBLESTONE:0,100)
RandomBlock(-7,4,7,SMOOTH_BRICK:0,40,SMOOTH_BRICK:1,30,SMOOTH_BRICK:2,30,SMOOTH_STAIRS:0,15,SMOOTH_STAIRS:1,15,SMOOTH_STAIRS:2,15,SMOOTH_STAIRS:3,15,STEP:5,15,STEP:13,15,COBBLE_WALL:0,10,COBBLESTONE_STAIRS:0,10,STEP:3,10,COBBLE_WALL:1,20,COBBLESTONE_STAIRS:2,20,COBBLESTONE_STAIRS:3,20,MOSSY_COBBLESTONE:0,60,COBBLESTONE_STAIRS:1,20,STEP:11,20,COBBLESTONE:0,100)
RandomBlock(-7,4,8,SMOOTH_BRICK:0,40,SMOOTH_BRICK:1,30,SMOOTH_BRICK:2,30,SMOOTH_STAIRS:0,15,SMOOTH_STAIRS:1,15,SMOOTH_STAIRS:2,15,SMOOTH_STAIRS:3,15,STEP:5,15,STEP:13,15,COBBLE_WALL:0,10,COBBLESTONE_STAIRS:0,10,STEP:3,10,COBBLE_WALL:1,20,COBBLESTONE_STAIRS:2,20,COBBLESTONE_STAIRS:3,20,MOSSY_COBBLESTONE:0,60,COBBLESTONE_STAIRS:1,20,STEP:11,20,COBBLESTONE:0,100)
RandomBlock(-7,5,-1,quark:limestone:1,30,quark:limestone_wall,10,quark:limestone,100)
RandomBlock(-7,5,0,quark:limestone:1,30,quark:limestone_wall,10,quark:limestone,100)
RandomBlock(-7,5,1,SMOOTH_BRICK:0,40,SMOOTH_BRICK:1,30,SMOOTH_BRICK:2,30,SMOOTH_STAIRS:0,15,SMOOTH_STAIRS:1,15,SMOOTH_STAIRS:2,15,SMOOTH_STAIRS:3,15,STEP:5,15,STEP:13,15,COBBLE_WALL:0,10,COBBLESTONE_STAIRS:0,10,STEP:3,10,COBBLE_WALL:1,20,COBBLESTONE_STAIRS:2,20,COBBLESTONE_STAIRS:3,20,MOSSY_COBBLESTONE:0,60,COBBLESTONE_STAIRS:1,20,STEP:11,20,COBBLESTONE:0,100)
RandomBlock(-7,5,2,SMOOTH_BRICK:0,40,SMOOTH_BRICK:1,30,SMOOTH_BRICK:2,30,SMOOTH_STAIRS:0,15,SMOOTH_STAIRS:1,15,SMOOTH_STAIRS:2,15,SMOOTH_STAIRS:3,15,STEP:5,15,STEP:13,15,COBBLE_WALL:0,10,COBBLESTONE_STAIRS:0,10,STEP:3,10,COBBLE_WALL:1,20,COBBLESTONE_STAIRS:2,20,COBBLESTONE_STAIRS:3,20,MOSSY_COBBLESTONE:0,60,COBBLESTONE_STAIRS:1,20,STEP:11,20,COBBLESTONE:0,100)
RandomBlock(-7,5,3,SMOOTH_BRICK:0,40,SMOOTH_BRICK:1,30,SMOOTH_BRICK:2,30,SMOOTH_STAIRS:0,15,SMOOTH_STAIRS:1,15,SMOOTH_STAIRS:2,15,SMOOTH_STAIRS:3,15,STEP:5,15,STEP:13,15,COBBLE_WALL:0,10,COBBLESTONE_STAIRS:0,10,STEP:3,10,COBBLE_WALL:1,20,COBBLESTONE_STAIRS:2,20,COBBLESTONE_STAIRS:3,20,MOSSY_COBBLESTONE:0,60,COBBLESTONE_STAIRS:1,20,STEP:11,20,COBBLESTONE:0,100)
RandomBlock(-7,5,4,SMOOTH_BRICK:0,40,SMOOTH_BRICK:1,30,SMOOTH_BRICK:2,30,SMOOTH_STAIRS:0,15,SMOOTH_STAIRS:1,15,SMOOTH_STAIRS:2,15,SMOOTH_STAIRS:3,15,STEP:5,15,STEP:13,15,COBBLE_WALL:0,10,COBBLESTONE_STAIRS:0,10,STEP:3,10,COBBLE_WALL:1,20,COBBLESTONE_STAIRS:2,20,COBBLESTONE_STAIRS:3,20,MOSSY_COBBLESTONE:0,60,COBBLESTONE_STAIRS:1,20,STEP:11,20,COBBLESTONE:0,100)
RandomBlock(-7,5,5,SMOOTH_BRICK:0,40,SMOOTH_BRICK:1,30,SMOOTH_BRICK:2,30,SMOOTH_STAIRS:0,15,SMOOTH_STAIRS:1,15,SMOOTH_STAIRS:2,15,SMOOTH_STAIRS:3,15,STEP:5,15,STEP:13,15,COBBLE_WALL:0,10,COBBLESTONE_STAIRS:0,10,STEP:3,10,COBBLE_WALL:1,20,COBBLESTONE_STAIRS:2,20,COBBLESTONE_STAIRS:3,20,MOSSY_COBBLESTONE:0,60,COBBLESTONE_STAIRS:1,20,STEP:11,20,COBBLESTONE:0,100)
RandomBlock(-7,5,6,SMOOTH_BRICK:0,40,SMOOTH_BRICK:1,30,SMOOTH_BRICK:2,30,SMOOTH_STAIRS:0,15,SMOOTH_STAIRS:1,15,SMOOTH_STAIRS:2,15,SMOOTH_STAIRS:3,15,STEP:5,15,STEP:13,15,COBBLE_WALL:0,10,COBBLESTONE_STAIRS:0,10,STEP:3,10,COBBLE_WALL:1,20,COBBLESTONE_STAIRS:2,20,COBBLESTONE_STAIRS:3,20,MOSSY_COBBLESTONE:0,60,COBBLESTONE_STAIRS:1,20,STEP:11,20,COBBLESTONE:0,100)
RandomBlock(-7,5,7,SMOOTH_BRICK:0,40,SMOOTH_BRICK:1,30,SMOOTH_BRICK:2,30,SMOOTH_STAIRS:0,15,SMOOTH_STAIRS:1,15,SMOOTH_STAIRS:2,15,SMOOTH_STAIRS:3,15,STEP:5,15,STEP:13,15,COBBLE_WALL:0,10,COBBLESTONE_STAIRS:0,10,STEP:3,10,COBBLE_WALL:1,20,COBBLESTONE_STAIRS:2,20,COBBLESTONE_STAIRS:3,20,MOSSY_COBBLESTONE:0,60,COBBLESTONE_STAIRS:1,20,STEP:11,20,COBBLESTONE:0,100)
RandomBlock(-7,5,8,quark:limestone:1,30,quark:limestone_wall,10,quark:limestone,100)
RandomBlock(-7,6,-1,quark:limestone:1,30,quark:limestone_wall,10,quark:limestone,100)
RandomBlock(-7,6,0,quark:limestone:1,30,quark:limestone_wall,10,quark:limestone,100)
RandomBlock(-7,6,1,SMOOTH_BRICK:0,40,SMOOTH_BRICK:1,30,SMOOTH_BRICK:2,30,SMOOTH_STAIRS:0,15,SMOOTH_STAIRS:1,15,SMOOTH_STAIRS:2,15,SMOOTH_STAIRS:3,15,STEP:5,15,STEP:13,15,COBBLE_WALL:0,10,COBBLESTONE_STAIRS:0,10,STEP:3,10,COBBLE_WALL:1,20,COBBLESTONE_STAIRS:2,20,COBBLESTONE_STAIRS:3,20,MOSSY_COBBLESTONE:0,60,COBBLESTONE_STAIRS:1,20,STEP:11,20,COBBLESTONE:0,100)
RandomBlock(-7,6,2,SMOOTH_BRICK:0,40,SMOOTH_BRICK:1,30,SMOOTH_BRICK:2,30,SMOOTH_STAIRS:0,15,SMOOTH_STAIRS:1,15,SMOOTH_STAIRS:2,15,SMOOTH_STAIRS:3,15,STEP:5,15,STEP:13,15,COBBLE_WALL:0,10,COBBLESTONE_STAIRS:0,10,STEP:3,10,COBBLE_WALL:1,20,COBBLESTONE_STAIRS:2,20,COBBLESTONE_STAIRS:3,20,MOSSY_COBBLESTONE:0,60,COBBLESTONE_STAIRS:1,20,STEP:11,20,COBBLESTONE:0,100)
RandomBlock(-7,6,3,SMOOTH_BRICK:0,40,SMOOTH_BRICK:1,30,SMOOTH_BRICK:2,30,SMOOTH_STAIRS:0,15,SMOOTH_STAIRS:1,15,SMOOTH_STAIRS:2,15,SMOOTH_STAIRS:3,15,STEP:5,15,STEP:13,15,COBBLE_WALL:0,10,COBBLESTONE_STAIRS:0,10,STEP:3,10,COBBLE_WALL:1,20,COBBLESTONE_STAIRS:2,20,COBBLESTONE_STAIRS:3,20,MOSSY_COBBLESTONE:0,60,COBBLESTONE_STAIRS:1,20,STEP:11,20,COBBLESTONE:0,100)
RandomBlock(-7,6,4,SMOOTH_BRICK:0,40,SMOOTH_BRICK:1,30,SMOOTH_BRICK:2,30,SMOOTH_STAIRS:0,15,SMOOTH_STAIRS:1,15,SMOOTH_STAIRS:2,15,SMOOTH_STAIRS:3,15,STEP:5,15,STEP:13,15,COBBLE_WALL:0,10,COBBLESTONE_STAIRS:0,10,STEP:3,10,COBBLE_WALL:1,20,COBBLESTONE_STAIRS:2,20,COBBLESTONE_STAIRS:3,20,MOSSY_COBBLESTONE:0,60,COBBLESTONE_STAIRS:1,20,STEP:11,20,COBBLESTONE:0,100)
RandomBlock(-7,6,5,SMOOTH_BRICK:0,40,SMOOTH_BRICK:1,30,SMOOTH_BRICK:2,30,SMOOTH_STAIRS:0,15,SMOOTH_STAIRS:1,15,SMOOTH_STAIRS:2,15,SMOOTH_STAIRS:3,15,STEP:5,15,STEP:13,15,COBBLE_WALL:0,10,COBBLESTONE_STAIRS:0,10,STEP:3,10,COBBLE_WALL:1,20,COBBLESTONE_STAIRS:2,20,COBBLESTONE_STAIRS:3,20,MOSSY_COBBLESTONE:0,60,COBBLESTONE_STAIRS:1,20,STEP:11,20,COBBLESTONE:0,100)
RandomBlock(-7,6,6,SMOOTH_BRICK:0,40,SMOOTH_BRICK:1,30,SMOOTH_BRICK:2,30,SMOOTH_STAIRS:0,15,SMOOTH_STAIRS:1,15,SMOOTH_STAIRS:2,15,SMOOTH_STAIRS:3,15,STEP:5,15,STEP:13,15,COBBLE_WALL:0,10,COBBLESTONE_STAIRS:0,10,STEP:3,10,COBBLE_WALL:1,20,COBBLESTONE_STAIRS:2,20,COBBLESTONE_STAIRS:3,20,MOSSY_COBBLESTONE:0,60,COBBLESTONE_STAIRS:1,20,STEP:11,20,COBBLESTONE:0,100)
RandomBlock(-7,6,7,SMOOTH_BRICK:0,40,SMOOTH_BRICK:1,30,SMOOTH_BRICK:2,30,SMOOTH_STAIRS:0,15,SMOOTH_STAIRS:1,15,SMOOTH_STAIRS:2,15,SMOOTH_STAIRS:3,15,STEP:5,15,STEP:13,15,COBBLE_WALL:0,10,COBBLESTONE_STAIRS:0,10,STEP:3,10,COBBLE_WALL:1,20,COBBLESTONE_STAIRS:2,20,COBBLESTONE_STAIRS:3,20,MOSSY_COBBLESTONE:0,60,COBBLESTONE_STAIRS:1,20,STEP:11,20,COBBLESTONE:0,100)
RandomBlock(-7,6,8,quark:limestone:1,30,quark:limestone_wall,10,quark:limestone,100)
RandomBlock(-7,7,-1,quark:limestone:1,30,quark:limestone_wall,10,quark:limestone,100)
RandomBlock(-7,7,0,quark:limestone:1,30,quark:limestone_wall,10,quark:limestone,100)
RandomBlock(-7,7,1,SMOOTH_BRICK:0,40,SMOOTH_BRICK:1,30,SMOOTH_BRICK:2,30,SMOOTH_STAIRS:0,15,SMOOTH_STAIRS:1,15,SMOOTH_STAIRS:2,15,SMOOTH_STAIRS:3,15,STEP:5,15,STEP:13,15,COBBLE_WALL:0,10,COBBLESTONE_STAIRS:0,10,STEP:3,10,COBBLE_WALL:1,20,COBBLESTONE_STAIRS:2,20,COBBLESTONE_STAIRS:3,20,MOSSY_COBBLESTONE:0,60,COBBLESTONE_STAIRS:1,20,STEP:11,20,COBBLESTONE:0,100)
RandomBlock(-7,7,2,SMOOTH_BRICK:0,40,SMOOTH_BRICK:1,30,SMOOTH_BRICK:2,30,SMOOTH_STAIRS:0,15,SMOOTH_STAIRS:1,15,SMOOTH_STAIRS:2,15,SMOOTH_STAIRS:3,15,STEP:5,15,STEP:13,15,COBBLE_WALL:0,10,COBBLESTONE_STAIRS:0,10,STEP:3,10,COBBLE_WALL:1,20,COBBLESTONE_STAIRS:2,20,COBBLESTONE_STAIRS:3,20,MOSSY_COBBLESTONE:0,60,COBBLESTONE_STAIRS:1,20,STEP:11,20,COBBLESTONE:0,100)
RandomBlock(-7,7,3,SMOOTH_BRICK:0,40,SMOOTH_BRICK:1,30,SMOOTH_BRICK:2,30,SMOOTH_STAIRS:0,15,SMOOTH_STAIRS:1,15,SMOOTH_STAIRS:2,15,SMOOTH_STAIRS:3,15,STEP:5,15,STEP:13,15,COBBLE_WALL:0,10,COBBLESTONE_STAIRS:0,10,STEP:3,10,COBBLE_WALL:1,20,COBBLESTONE_STAIRS:2,20,COBBLESTONE_STAIRS:3,20,MOSSY_COBBLESTONE:0,60,COBBLESTONE_STAIRS:1,20,STEP:11,20,COBBLESTONE:0,100)
Block(-7,7,4,quark:iron_plate)
RandomBlock(-7,7,5,SMOOTH_BRICK:0,40,SMOOTH_BRICK:1,30,SMOOTH_BRICK:2,30,SMOOTH_STAIRS:0,15,SMOOTH_STAIRS:1,15,SMOOTH_STAIRS:2,15,SMOOTH_STAIRS:3,15,STEP:5,15,STEP:13,15,COBBLE_WALL:0,10,COBBLESTONE_STAIRS:0,10,STEP:3,10,COBBLE_WALL:1,20,COBBLESTONE_STAIRS:2,20,COBBLESTONE_STAIRS:3,20,MOSSY_COBBLESTONE:0,60,COBBLESTONE_STAIRS:1,20,STEP:11,20,COBBLESTONE:0,100)
RandomBlock(-7,7,6,SMOOTH_BRICK:0,40,SMOOTH_BRICK:1,30,SMOOTH_BRICK:2,30,SMOOTH_STAIRS:0,15,SMOOTH_STAIRS:1,15,SMOOTH_STAIRS:2,15,SMOOTH_STAIRS:3,15,STEP:5,15,STEP:13,15,COBBLE_WALL:0,10,COBBLESTONE_STAIRS:0,10,STEP:3,10,COBBLE_WALL:1,20,COBBLESTONE_STAIRS:2,20,COBBLESTONE_STAIRS:3,20,MOSSY_COBBLESTONE:0,60,COBBLESTONE_STAIRS:1,20,STEP:11,20,COBBLESTONE:0,100)
RandomBlock(-7,7,7,SMOOTH_BRICK:0,40,SMOOTH_BRICK:1,30,SMOOTH_BRICK:2,30,SMOOTH_STAIRS:0,15,SMOOTH_STAIRS:1,15,SMOOTH_STAIRS:2,15,SMOOTH_STAIRS:3,15,STEP:5,15,STEP:13,15,COBBLE_WALL:0,10,COBBLESTONE_STAIRS:0,10,STEP:3,10,COBBLE_WALL:1,20,COBBLESTONE_STAIRS:2,20,COBBLESTONE_STAIRS:3,20,MOSSY_COBBLESTONE:0,60,COBBLESTONE_STAIRS:1,20,STEP:11,20,COBBLESTONE:0,100)
RandomBlock(-7,7,8,quark:limestone:1,30,quark:limestone_wall,10,quark:limestone,100)
Block(-7,8,-1,inspirations:redstone_barrel)
RandomBlock(-7,8,1,rustic:iron_lattice:0,30,rustic:iron_lattice,100)
RandomBlock(-7,8,2,rustic:iron_lattice:0,30,rustic:iron_lattice,100)
RandomBlock(-7,8,3,rustic:iron_lattice:0,30,rustic:iron_lattice,100)
Block(-7,8,4,quark:iron_plate)
RandomBlock(-7,8,5,rustic:iron_lattice:0,30,rustic:iron_lattice,100)
RandomBlock(-7,8,6,rustic:iron_lattice:0,30,rustic:iron_lattice,100)
RandomBlock(-7,8,7,rustic:iron_lattice:0,30,rustic:iron_lattice,100)
Block(-7,9,-1,inspirations:redstone_barrel)
RandomBlock(-7,9,1,rustic:iron_lattice:0,30,rustic:iron_lattice,100)
RandomBlock(-7,9,2,rustic:iron_lattice:0,30,rustic:iron_lattice,100)
RandomBlock(-7,9,3,rustic:iron_lattice:0,30,rustic:iron_lattice,100)
RandomBlock(-7,9,4,rustic:iron_lattice:0,30,rustic:iron_lattice,100)
RandomBlock(-7,9,5,rustic:iron_lattice:0,30,rustic:iron_lattice,100)
RandomBlock(-7,9,6,rustic:iron_lattice:0,30,rustic:iron_lattice,100)
RandomBlock(-7,9,7,rustic:iron_lattice:0,30,rustic:iron_lattice,100)
RandomBlock(-7,10,-1,quark:limestone:1,30,quark:limestone_wall,10,quark:limestone,100)
RandomBlock(-7,10,0,quark:limestone:1,30,quark:limestone_wall,10,quark:limestone,100)
RandomBlock(-7,10,1,rustic:iron_lattice:0,30,rustic:iron_lattice,100)
RandomBlock(-7,10,2,rustic:iron_lattice:0,30,rustic:iron_lattice,100)
RandomBlock(-7,10,3,rustic:iron_lattice:0,30,rustic:iron_lattice,100)
RandomBlock(-7,10,4,rustic:iron_lattice:0,30,rustic:iron_lattice,100)
RandomBlock(-7,10,5,rustic:iron_lattice:0,30,rustic:iron_lattice,100)
RandomBlock(-7,10,6,rustic:iron_lattice:0,30,rustic:iron_lattice,100)
RandomBlock(-7,10,7,rustic:iron_lattice:0,30,rustic:iron_lattice,100)
RandomBlock(-7,10,8,quark:limestone:1,30,quark:limestone_wall,10,quark:limestone,100)
RandomBlock(-7,11,-1,quark:limestone:1,30,quark:limestone_wall,10,quark:limestone,100)
RandomBlock(-7,11,0,quark:limestone:1,30,quark:limestone_wall,10,quark:limestone,100)
RandomBlock(-7,11,8,quark:limestone:1,30,quark:limestone_wall,10,quark:limestone,100)
Block(-7,12,0,quark:iron_plate:1)
RandomBlock(-7,12,1,quark:limestone:1,30,quark:limestone_wall,10,quark:limestone,100)
RandomBlock(-7,12,2,quark:limestone:1,30,quark:limestone_wall,10,quark:limestone,100)
RandomBlock(-7,12,3,quark:limestone:1,30,quark:limestone_wall,10,quark:limestone,100)
RandomBlock(-7,12,4,quark:limestone:1,30,quark:limestone_wall,10,quark:limestone,100)
RandomBlock(-7,12,5,quark:limestone:1,30,quark:limestone_wall,10,quark:limestone,100)
RandomBlock(-7,12,6,quark:limestone:1,30,quark:limestone_wall,10,quark:limestone,100)
RandomBlock(-7,12,7,quark:limestone:1,30,quark:limestone_wall,10,quark:limestone,100)
Block(-7,12,8,quark:iron_plate:1)
Block(-7,13,0,quark:iron_plate:1)
RandomBlock(-7,13,1,quark:limestone:1,30,quark:limestone_wall,10,quark:limestone,100)
RandomBlock(-7,13,2,quark:limestone:1,30,quark:limestone_wall,10,quark:limestone,100)
RandomBlock(-7,13,3,quark:limestone:1,30,quark:limestone_wall,10,quark:limestone,100)
RandomBlock(-7,13,4,quark:limestone:1,30,quark:limestone_wall,10,quark:limestone,100)
RandomBlock(-7,13,5,quark:limestone:1,30,quark:limestone_wall,10,quark:limestone,100)
RandomBlock(-7,13,6,quark:limestone:1,30,quark:limestone_wall,10,quark:limestone,100)
RandomBlock(-7,13,7,quark:limestone:1,30,quark:limestone_wall,10,quark:limestone,100)
Block(-7,13,8,quark:iron_plate:1)
Block(-7,14,2,VINE:8)
Block(-7,14,3,VINE:8)
Block(-7,14,4,quark:iron_plate:1)
Block(-7,15,2,VINE:8)
Block(-7,15,3,VINE:8)
Block(-7,15,4,quark:iron_plate:1)
RandomBlock(-6,0,-3,SMOOTH_BRICK:0,40,SMOOTH_BRICK:1,30,SMOOTH_BRICK:2,30,SMOOTH_STAIRS:0,15,SMOOTH_STAIRS:1,15,SMOOTH_STAIRS:2,15,SMOOTH_STAIRS:3,15,STEP:5,15,STEP:13,15,COBBLE_WALL:0,10,COBBLESTONE_STAIRS:0,10,STEP:3,10,COBBLE_WALL:1,20,COBBLESTONE_STAIRS:2,20,COBBLESTONE_STAIRS:3,20,MOSSY_COBBLESTONE:0,60,COBBLESTONE_STAIRS:1,20,STEP:11,20,COBBLESTONE:0,100)
RandomBlock(-6,0,-2,SMOOTH_BRICK:0,40,SMOOTH_BRICK:1,30,SMOOTH_BRICK:2,30,SMOOTH_STAIRS:0,15,SMOOTH_STAIRS:1,15,SMOOTH_STAIRS:2,15,SMOOTH_STAIRS:3,15,STEP:5,15,STEP:13,15,COBBLE_WALL:0,10,COBBLESTONE_STAIRS:0,10,STEP:3,10,COBBLE_WALL:1,20,COBBLESTONE_STAIRS:2,20,COBBLESTONE_STAIRS:3,20,MOSSY_COBBLESTONE:0,60,COBBLESTONE_STAIRS:1,20,STEP:11,20,COBBLESTONE:0,100)
RandomBlock(-6,0,-1,SMOOTH_BRICK:0,40,SMOOTH_BRICK:1,30,SMOOTH_BRICK:2,30,SMOOTH_STAIRS:0,15,SMOOTH_STAIRS:1,15,SMOOTH_STAIRS:2,15,SMOOTH_STAIRS:3,15,STEP:5,15,STEP:13,15,COBBLE_WALL:0,10,COBBLESTONE_STAIRS:0,10,STEP:3,10,COBBLE_WALL:1,20,COBBLESTONE_STAIRS:2,20,COBBLESTONE_STAIRS:3,20,MOSSY_COBBLESTONE:0,60,COBBLESTONE_STAIRS:1,20,STEP:11,20,COBBLESTONE:0,100)
RandomBlock(-6,0,0,SMOOTH_BRICK:0,40,SMOOTH_BRICK:1,30,SMOOTH_BRICK:2,30,SMOOTH_STAIRS:0,15,SMOOTH_STAIRS:1,15,SMOOTH_STAIRS:2,15,SMOOTH_STAIRS:3,15,STEP:5,15,STEP:13,15,COBBLE_WALL:0,10,COBBLESTONE_STAIRS:0,10,STEP:3,10,COBBLE_WALL:1,20,COBBLESTONE_STAIRS:2,20,COBBLESTONE_STAIRS:3,20,MOSSY_COBBLESTONE:0,60,COBBLESTONE_STAIRS:1,20,STEP:11,20,COBBLESTONE:0,100)
RandomBlock(-6,0,1,SMOOTH_BRICK:0,40,SMOOTH_BRICK:1,30,SMOOTH_BRICK:2,30,SMOOTH_STAIRS:0,15,SMOOTH_STAIRS:1,15,SMOOTH_STAIRS:2,15,SMOOTH_STAIRS:3,15,STEP:5,15,STEP:13,15,COBBLE_WALL:0,10,COBBLESTONE_STAIRS:0,10,STEP:3,10,COBBLE_WALL:1,20,COBBLESTONE_STAIRS:2,20,COBBLESTONE_STAIRS:3,20,MOSSY_COBBLESTONE:0,60,COBBLESTONE_STAIRS:1,20,STEP:11,20,COBBLESTONE:0,100)
RandomBlock(-6,0,2,SMOOTH_BRICK:0,40,SMOOTH_BRICK:1,30,SMOOTH_BRICK:2,30,SMOOTH_STAIRS:0,15,SMOOTH_STAIRS:1,15,SMOOTH_STAIRS:2,15,SMOOTH_STAIRS:3,15,STEP:5,15,STEP:13,15,COBBLE_WALL:0,10,COBBLESTONE_STAIRS:0,10,STEP:3,10,COBBLE_WALL:1,20,COBBLESTONE_STAIRS:2,20,COBBLESTONE_STAIRS:3,20,MOSSY_COBBLESTONE:0,60,COBBLESTONE_STAIRS:1,20,STEP:11,20,COBBLESTONE:0,100)
RandomBlock(-6,0,3,SMOOTH_BRICK:0,40,SMOOTH_BRICK:1,30,SMOOTH_BRICK:2,30,SMOOTH_STAIRS:0,15,SMOOTH_STAIRS:1,15,SMOOTH_STAIRS:2,15,SMOOTH_STAIRS:3,15,STEP:5,15,STEP:13,15,COBBLE_WALL:0,10,COBBLESTONE_STAIRS:0,10,STEP:3,10,COBBLE_WALL:1,20,COBBLESTONE_STAIRS:2,20,COBBLESTONE_STAIRS:3,20,MOSSY_COBBLESTONE:0,60,COBBLESTONE_STAIRS:1,20,STEP:11,20,COBBLESTONE:0,100)
RandomBlock(-6,0,4,SMOOTH_BRICK:0,40,SMOOTH_BRICK:1,30,SMOOTH_BRICK:2,30,SMOOTH_STAIRS:0,15,SMOOTH_STAIRS:1,15,SMOOTH_STAIRS:2,15,SMOOTH_STAIRS:3,15,STEP:5,15,STEP:13,15,COBBLE_WALL:0,10,COBBLESTONE_STAIRS:0,10,STEP:3,10,COBBLE_WALL:1,20,COBBLESTONE_STAIRS:2,20,COBBLESTONE_STAIRS:3,20,MOSSY_COBBLESTONE:0,60,COBBLESTONE_STAIRS:1,20,STEP:11,20,COBBLESTONE:0,100)
RandomBlock(-6,0,5,SMOOTH_BRICK:0,40,SMOOTH_BRICK:1,30,SMOOTH_BRICK:2,30,SMOOTH_STAIRS:0,15,SMOOTH_STAIRS:1,15,SMOOTH_STAIRS:2,15,SMOOTH_STAIRS:3,15,STEP:5,15,STEP:13,15,COBBLE_WALL:0,10,COBBLESTONE_STAIRS:0,10,STEP:3,10,COBBLE_WALL:1,20,COBBLESTONE_STAIRS:2,20,COBBLESTONE_STAIRS:3,20,MOSSY_COBBLESTONE:0,60,COBBLESTONE_STAIRS:1,20,STEP:11,20,COBBLESTONE:0,100)
RandomBlock(-6,0,6,SMOOTH_BRICK:0,40,SMOOTH_BRICK:1,30,SMOOTH_BRICK:2,30,SMOOTH_STAIRS:0,15,SMOOTH_STAIRS:1,15,SMOOTH_STAIRS:2,15,SMOOTH_STAIRS:3,15,STEP:5,15,STEP:13,15,COBBLE_WALL:0,10,COBBLESTONE_STAIRS:0,10,STEP:3,10,COBBLE_WALL:1,20,COBBLESTONE_STAIRS:2,20,COBBLESTONE_STAIRS:3,20,MOSSY_COBBLESTONE:0,60,COBBLESTONE_STAIRS:1,20,STEP:11,20,COBBLESTONE:0,100)
RandomBlock(-6,0,7,SMOOTH_BRICK:0,40,SMOOTH_BRICK:1,30,SMOOTH_BRICK:2,30,SMOOTH_STAIRS:0,15,SMOOTH_STAIRS:1,15,SMOOTH_STAIRS:2,15,SMOOTH_STAIRS:3,15,STEP:5,15,STEP:13,15,COBBLE_WALL:0,10,COBBLESTONE_STAIRS:0,10,STEP:3,10,COBBLE_WALL:1,20,COBBLESTONE_STAIRS:2,20,COBBLESTONE_STAIRS:3,20,MOSSY_COBBLESTONE:0,60,COBBLESTONE_STAIRS:1,20,STEP:11,20,COBBLESTONE:0,100)
RandomBlock(-6,0,8,SMOOTH_BRICK:0,40,SMOOTH_BRICK:1,30,SMOOTH_BRICK:2,30,SMOOTH_STAIRS:0,15,SMOOTH_STAIRS:1,15,SMOOTH_STAIRS:2,15,SMOOTH_STAIRS:3,15,STEP:5,15,STEP:13,15,COBBLE_WALL:0,10,COBBLESTONE_STAIRS:0,10,STEP:3,10,COBBLE_WALL:1,20,COBBLESTONE_STAIRS:2,20,COBBLESTONE_STAIRS:3,20,MOSSY_COBBLESTONE:0,60,COBBLESTONE_STAIRS:1,20,STEP:11,20,COBBLESTONE:0,100)
RandomBlock(-6,1,-3,SMOOTH_BRICK:0,40,SMOOTH_BRICK:1,30,SMOOTH_BRICK:2,30,SMOOTH_STAIRS:0,15,SMOOTH_STAIRS:1,15,SMOOTH_STAIRS:2,15,SMOOTH_STAIRS:3,15,STEP:5,15,STEP:13,15,COBBLE_WALL:0,10,COBBLESTONE_STAIRS:0,10,STEP:3,10,COBBLE_WALL:1,20,COBBLESTONE_STAIRS:2,20,COBBLESTONE_STAIRS:3,20,MOSSY_COBBLESTONE:0,60,COBBLESTONE_STAIRS:1,20,STEP:11,20,COBBLESTONE:0,100)
RandomBlock(-6,1,-2,SMOOTH_BRICK:0,40,SMOOTH_BRICK:1,30,SMOOTH_BRICK:2,30,SMOOTH_STAIRS:0,15,SMOOTH_STAIRS:1,15,SMOOTH_STAIRS:2,15,SMOOTH_STAIRS:3,15,STEP:5,15,STEP:13,15,COBBLE_WALL:0,10,COBBLESTONE_STAIRS:0,10,STEP:3,10,COBBLE_WALL:1,20,COBBLESTONE_STAIRS:2,20,COBBLESTONE_STAIRS:3,20,MOSSY_COBBLESTONE:0,60,COBBLESTONE_STAIRS:1,20,STEP:11,20,COBBLESTONE:0,100)
RandomBlock(-6,1,-1,SMOOTH_BRICK:0,40,SMOOTH_BRICK:1,30,SMOOTH_BRICK:2,30,SMOOTH_STAIRS:0,15,SMOOTH_STAIRS:1,15,SMOOTH_STAIRS:2,15,SMOOTH_STAIRS:3,15,STEP:5,15,STEP:13,15,COBBLE_WALL:0,10,COBBLESTONE_STAIRS:0,10,STEP:3,10,COBBLE_WALL:1,20,COBBLESTONE_STAIRS:2,20,COBBLESTONE_STAIRS:3,20,MOSSY_COBBLESTONE:0,60,COBBLESTONE_STAIRS:1,20,STEP:11,20,COBBLESTONE:0,100)
RandomBlock(-6,1,0,SMOOTH_BRICK:0,40,SMOOTH_BRICK:1,30,SMOOTH_BRICK:2,30,SMOOTH_STAIRS:0,15,SMOOTH_STAIRS:1,15,SMOOTH_STAIRS:2,15,SMOOTH_STAIRS:3,15,STEP:5,15,STEP:13,15,COBBLE_WALL:0,10,COBBLESTONE_STAIRS:0,10,STEP:3,10,COBBLE_WALL:1,20,COBBLESTONE_STAIRS:2,20,COBBLESTONE_STAIRS:3,20,MOSSY_COBBLESTONE:0,60,COBBLESTONE_STAIRS:1,20,STEP:11,20,COBBLESTONE:0,100)
RandomBlock(-6,1,1,SMOOTH_BRICK:0,40,SMOOTH_BRICK:1,30,SMOOTH_BRICK:2,30,SMOOTH_STAIRS:0,15,SMOOTH_STAIRS:1,15,SMOOTH_STAIRS:2,15,SMOOTH_STAIRS:3,15,STEP:5,15,STEP:13,15,COBBLE_WALL:0,10,COBBLESTONE_STAIRS:0,10,STEP:3,10,COBBLE_WALL:1,20,COBBLESTONE_STAIRS:2,20,COBBLESTONE_STAIRS:3,20,MOSSY_COBBLESTONE:0,60,COBBLESTONE_STAIRS:1,20,STEP:11,20,COBBLESTONE:0,100)
RandomBlock(-6,1,2,SMOOTH_BRICK:0,40,SMOOTH_BRICK:1,30,SMOOTH_BRICK:2,30,SMOOTH_STAIRS:0,15,SMOOTH_STAIRS:1,15,SMOOTH_STAIRS:2,15,SMOOTH_STAIRS:3,15,STEP:5,15,STEP:13,15,COBBLE_WALL:0,10,COBBLESTONE_STAIRS:0,10,STEP:3,10,COBBLE_WALL:1,20,COBBLESTONE_STAIRS:2,20,COBBLESTONE_STAIRS:3,20,MOSSY_COBBLESTONE:0,60,COBBLESTONE_STAIRS:1,20,STEP:11,20,COBBLESTONE:0,100)
RandomBlock(-6,1,3,SMOOTH_BRICK:0,40,SMOOTH_BRICK:1,30,SMOOTH_BRICK:2,30,SMOOTH_STAIRS:0,15,SMOOTH_STAIRS:1,15,SMOOTH_STAIRS:2,15,SMOOTH_STAIRS:3,15,STEP:5,15,STEP:13,15,COBBLE_WALL:0,10,COBBLESTONE_STAIRS:0,10,STEP:3,10,COBBLE_WALL:1,20,COBBLESTONE_STAIRS:2,20,COBBLESTONE_STAIRS:3,20,MOSSY_COBBLESTONE:0,60,COBBLESTONE_STAIRS:1,20,STEP:11,20,COBBLESTONE:0,100)
RandomBlock(-6,1,4,SMOOTH_BRICK:0,40,SMOOTH_BRICK:1,30,SMOOTH_BRICK:2,30,SMOOTH_STAIRS:0,15,SMOOTH_STAIRS:1,15,SMOOTH_STAIRS:2,15,SMOOTH_STAIRS:3,15,STEP:5,15,STEP:13,15,COBBLE_WALL:0,10,COBBLESTONE_STAIRS:0,10,STEP:3,10,COBBLE_WALL:1,20,COBBLESTONE_STAIRS:2,20,COBBLESTONE_STAIRS:3,20,MOSSY_COBBLESTONE:0,60,COBBLESTONE_STAIRS:1,20,STEP:11,20,COBBLESTONE:0,100)
RandomBlock(-6,1,5,SMOOTH_BRICK:0,40,SMOOTH_BRICK:1,30,SMOOTH_BRICK:2,30,SMOOTH_STAIRS:0,15,SMOOTH_STAIRS:1,15,SMOOTH_STAIRS:2,15,SMOOTH_STAIRS:3,15,STEP:5,15,STEP:13,15,COBBLE_WALL:0,10,COBBLESTONE_STAIRS:0,10,STEP:3,10,COBBLE_WALL:1,20,COBBLESTONE_STAIRS:2,20,COBBLESTONE_STAIRS:3,20,MOSSY_COBBLESTONE:0,60,COBBLESTONE_STAIRS:1,20,STEP:11,20,COBBLESTONE:0,100)
RandomBlock(-6,1,6,SMOOTH_BRICK:0,40,SMOOTH_BRICK:1,30,SMOOTH_BRICK:2,30,SMOOTH_STAIRS:0,15,SMOOTH_STAIRS:1,15,SMOOTH_STAIRS:2,15,SMOOTH_STAIRS:3,15,STEP:5,15,STEP:13,15,COBBLE_WALL:0,10,COBBLESTONE_STAIRS:0,10,STEP:3,10,COBBLE_WALL:1,20,COBBLESTONE_STAIRS:2,20,COBBLESTONE_STAIRS:3,20,MOSSY_COBBLESTONE:0,60,COBBLESTONE_STAIRS:1,20,STEP:11,20,COBBLESTONE:0,100)
RandomBlock(-6,1,7,SMOOTH_BRICK:0,40,SMOOTH_BRICK:1,30,SMOOTH_BRICK:2,30,SMOOTH_STAIRS:0,15,SMOOTH_STAIRS:1,15,SMOOTH_STAIRS:2,15,SMOOTH_STAIRS:3,15,STEP:5,15,STEP:13,15,COBBLE_WALL:0,10,COBBLESTONE_STAIRS:0,10,STEP:3,10,COBBLE_WALL:1,20,COBBLESTONE_STAIRS:2,20,COBBLESTONE_STAIRS:3,20,MOSSY_COBBLESTONE:0,60,COBBLESTONE_STAIRS:1,20,STEP:11,20,COBBLESTONE:0,100)
RandomBlock(-6,1,8,SMOOTH_BRICK:0,40,SMOOTH_BRICK:1,30,SMOOTH_BRICK:2,30,SMOOTH_STAIRS:0,15,SMOOTH_STAIRS:1,15,SMOOTH_STAIRS:2,15,SMOOTH_STAIRS:3,15,STEP:5,15,STEP:13,15,COBBLE_WALL:0,10,COBBLESTONE_STAIRS:0,10,STEP:3,10,COBBLE_WALL:1,20,COBBLESTONE_STAIRS:2,20,COBBLESTONE_STAIRS:3,20,MOSSY_COBBLESTONE:0,60,COBBLESTONE_STAIRS:1,20,STEP:11,20,COBBLESTONE:0,100)
RandomBlock(-6,2,-3,SMOOTH_BRICK:0,40,SMOOTH_BRICK:1,30,SMOOTH_BRICK:2,30,SMOOTH_STAIRS:0,15,SMOOTH_STAIRS:1,15,SMOOTH_STAIRS:2,15,SMOOTH_STAIRS:3,15,STEP:5,15,STEP:13,15,COBBLE_WALL:0,10,COBBLESTONE_STAIRS:0,10,STEP:3,10,COBBLE_WALL:1,20,COBBLESTONE_STAIRS:2,20,COBBLESTONE_STAIRS:3,20,MOSSY_COBBLESTONE:0,60,COBBLESTONE_STAIRS:1,20,STEP:11,20,COBBLESTONE:0,100)
RandomBlock(-6,2,-2,SMOOTH_BRICK:0,40,SMOOTH_BRICK:1,30,SMOOTH_BRICK:2,30,SMOOTH_STAIRS:0,15,SMOOTH_STAIRS:1,15,SMOOTH_STAIRS:2,15,SMOOTH_STAIRS:3,15,STEP:5,15,STEP:13,15,COBBLE_WALL:0,10,COBBLESTONE_STAIRS:0,10,STEP:3,10,COBBLE_WALL:1,20,COBBLESTONE_STAIRS:2,20,COBBLESTONE_STAIRS:3,20,MOSSY_COBBLESTONE:0,60,COBBLESTONE_STAIRS:1,20,STEP:11,20,COBBLESTONE:0,100)
RandomBlock(-6,2,-1,SMOOTH_BRICK:0,40,SMOOTH_BRICK:1,30,SMOOTH_BRICK:2,30,SMOOTH_STAIRS:0,15,SMOOTH_STAIRS:1,15,SMOOTH_STAIRS:2,15,SMOOTH_STAIRS:3,15,STEP:5,15,STEP:13,15,COBBLE_WALL:0,10,COBBLESTONE_STAIRS:0,10,STEP:3,10,COBBLE_WALL:1,20,COBBLESTONE_STAIRS:2,20,COBBLESTONE_STAIRS:3,20,MOSSY_COBBLESTONE:0,60,COBBLESTONE_STAIRS:1,20,STEP:11,20,COBBLESTONE:0,100)
RandomBlock(-6,2,0,SMOOTH_BRICK:0,40,SMOOTH_BRICK:1,30,SMOOTH_BRICK:2,30,SMOOTH_STAIRS:0,15,SMOOTH_STAIRS:1,15,SMOOTH_STAIRS:2,15,SMOOTH_STAIRS:3,15,STEP:5,15,STEP:13,15,COBBLE_WALL:0,10,COBBLESTONE_STAIRS:0,10,STEP:3,10,COBBLE_WALL:1,20,COBBLESTONE_STAIRS:2,20,COBBLESTONE_STAIRS:3,20,MOSSY_COBBLESTONE:0,60,COBBLESTONE_STAIRS:1,20,STEP:11,20,COBBLESTONE:0,100)
RandomBlock(-6,2,1,SMOOTH_BRICK:0,40,SMOOTH_BRICK:1,30,SMOOTH_BRICK:2,30,SMOOTH_STAIRS:0,15,SMOOTH_STAIRS:1,15,SMOOTH_STAIRS:2,15,SMOOTH_STAIRS:3,15,STEP:5,15,STEP:13,15,COBBLE_WALL:0,10,COBBLESTONE_STAIRS:0,10,STEP:3,10,COBBLE_WALL:1,20,COBBLESTONE_STAIRS:2,20,COBBLESTONE_STAIRS:3,20,MOSSY_COBBLESTONE:0,60,COBBLESTONE_STAIRS:1,20,STEP:11,20,COBBLESTONE:0,100)
RandomBlock(-6,2,2,SMOOTH_BRICK:0,40,SMOOTH_BRICK:1,30,SMOOTH_BRICK:2,30,SMOOTH_STAIRS:0,15,SMOOTH_STAIRS:1,15,SMOOTH_STAIRS:2,15,SMOOTH_STAIRS:3,15,STEP:5,15,STEP:13,15,COBBLE_WALL:0,10,COBBLESTONE_STAIRS:0,10,STEP:3,10,COBBLE_WALL:1,20,COBBLESTONE_STAIRS:2,20,COBBLESTONE_STAIRS:3,20,MOSSY_COBBLESTONE:0,60,COBBLESTONE_STAIRS:1,20,STEP:11,20,COBBLESTONE:0,100)
RandomBlock(-6,2,3,SMOOTH_BRICK:0,40,SMOOTH_BRICK:1,30,SMOOTH_BRICK:2,30,SMOOTH_STAIRS:0,15,SMOOTH_STAIRS:1,15,SMOOTH_STAIRS:2,15,SMOOTH_STAIRS:3,15,STEP:5,15,STEP:13,15,COBBLE_WALL:0,10,COBBLESTONE_STAIRS:0,10,STEP:3,10,COBBLE_WALL:1,20,COBBLESTONE_STAIRS:2,20,COBBLESTONE_STAIRS:3,20,MOSSY_COBBLESTONE:0,60,COBBLESTONE_STAIRS:1,20,STEP:11,20,COBBLESTONE:0,100)
RandomBlock(-6,2,4,SMOOTH_BRICK:0,40,SMOOTH_BRICK:1,30,SMOOTH_BRICK:2,30,SMOOTH_STAIRS:0,15,SMOOTH_STAIRS:1,15,SMOOTH_STAIRS:2,15,SMOOTH_STAIRS:3,15,STEP:5,15,STEP:13,15,COBBLE_WALL:0,10,COBBLESTONE_STAIRS:0,10,STEP:3,10,COBBLE_WALL:1,20,COBBLESTONE_STAIRS:2,20,COBBLESTONE_STAIRS:3,20,MOSSY_COBBLESTONE:0,60,COBBLESTONE_STAIRS:1,20,STEP:11,20,COBBLESTONE:0,100)
RandomBlock(-6,2,5,SMOOTH_BRICK:0,40,SMOOTH_BRICK:1,30,SMOOTH_BRICK:2,30,SMOOTH_STAIRS:0,15,SMOOTH_STAIRS:1,15,SMOOTH_STAIRS:2,15,SMOOTH_STAIRS:3,15,STEP:5,15,STEP:13,15,COBBLE_WALL:0,10,COBBLESTONE_STAIRS:0,10,STEP:3,10,COBBLE_WALL:1,20,COBBLESTONE_STAIRS:2,20,COBBLESTONE_STAIRS:3,20,MOSSY_COBBLESTONE:0,60,COBBLESTONE_STAIRS:1,20,STEP:11,20,COBBLESTONE:0,100)
RandomBlock(-6,2,6,SMOOTH_BRICK:0,40,SMOOTH_BRICK:1,30,SMOOTH_BRICK:2,30,SMOOTH_STAIRS:0,15,SMOOTH_STAIRS:1,15,SMOOTH_STAIRS:2,15,SMOOTH_STAIRS:3,15,STEP:5,15,STEP:13,15,COBBLE_WALL:0,10,COBBLESTONE_STAIRS:0,10,STEP:3,10,COBBLE_WALL:1,20,COBBLESTONE_STAIRS:2,20,COBBLESTONE_STAIRS:3,20,MOSSY_COBBLESTONE:0,60,COBBLESTONE_STAIRS:1,20,STEP:11,20,COBBLESTONE:0,100)
RandomBlock(-6,2,7,SMOOTH_BRICK:0,40,SMOOTH_BRICK:1,30,SMOOTH_BRICK:2,30,SMOOTH_STAIRS:0,15,SMOOTH_STAIRS:1,15,SMOOTH_STAIRS:2,15,SMOOTH_STAIRS:3,15,STEP:5,15,STEP:13,15,COBBLE_WALL:0,10,COBBLESTONE_STAIRS:0,10,STEP:3,10,COBBLE_WALL:1,20,COBBLESTONE_STAIRS:2,20,COBBLESTONE_STAIRS:3,20,MOSSY_COBBLESTONE:0,60,COBBLESTONE_STAIRS:1,20,STEP:11,20,COBBLESTONE:0,100)
RandomBlock(-6,2,8,SMOOTH_BRICK:0,40,SMOOTH_BRICK:1,30,SMOOTH_BRICK:2,30,SMOOTH_STAIRS:0,15,SMOOTH_STAIRS:1,15,SMOOTH_STAIRS:2,15,SMOOTH_STAIRS:3,15,STEP:5,15,STEP:13,15,COBBLE_WALL:0,10,COBBLESTONE_STAIRS:0,10,STEP:3,10,COBBLE_WALL:1,20,COBBLESTONE_STAIRS:2,20,COBBLESTONE_STAIRS:3,20,MOSSY_COBBLESTONE:0,60,COBBLESTONE_STAIRS:1,20,STEP:11,20,COBBLESTONE:0,100)
RandomBlock(-6,3,-3,SMOOTH_BRICK:0,40,SMOOTH_BRICK:1,30,SMOOTH_BRICK:2,30,SMOOTH_STAIRS:0,15,SMOOTH_STAIRS:1,15,SMOOTH_STAIRS:2,15,SMOOTH_STAIRS:3,15,STEP:5,15,STEP:13,15,COBBLE_WALL:0,10,COBBLESTONE_STAIRS:0,10,STEP:3,10,COBBLE_WALL:1,20,COBBLESTONE_STAIRS:2,20,COBBLESTONE_STAIRS:3,20,MOSSY_COBBLESTONE:0,60,COBBLESTONE_STAIRS:1,20,STEP:11,20,COBBLESTONE:0,100)
RandomBlock(-6,3,-2,SMOOTH_BRICK:0,40,SMOOTH_BRICK:1,30,SMOOTH_BRICK:2,30,SMOOTH_STAIRS:0,15,SMOOTH_STAIRS:1,15,SMOOTH_STAIRS:2,15,SMOOTH_STAIRS:3,15,STEP:5,15,STEP:13,15,COBBLE_WALL:0,10,COBBLESTONE_STAIRS:0,10,STEP:3,10,COBBLE_WALL:1,20,COBBLESTONE_STAIRS:2,20,COBBLESTONE_STAIRS:3,20,MOSSY_COBBLESTONE:0,60,COBBLESTONE_STAIRS:1,20,STEP:11,20,COBBLESTONE:0,100)
RandomBlock(-6,3,-1,SMOOTH_BRICK:0,40,SMOOTH_BRICK:1,30,SMOOTH_BRICK:2,30,SMOOTH_STAIRS:0,15,SMOOTH_STAIRS:1,15,SMOOTH_STAIRS:2,15,SMOOTH_STAIRS:3,15,STEP:5,15,STEP:13,15,COBBLE_WALL:0,10,COBBLESTONE_STAIRS:0,10,STEP:3,10,COBBLE_WALL:1,20,COBBLESTONE_STAIRS:2,20,COBBLESTONE_STAIRS:3,20,MOSSY_COBBLESTONE:0,60,COBBLESTONE_STAIRS:1,20,STEP:11,20,COBBLESTONE:0,100)
RandomBlock(-6,3,0,SMOOTH_BRICK:0,40,SMOOTH_BRICK:1,30,SMOOTH_BRICK:2,30,SMOOTH_STAIRS:0,15,SMOOTH_STAIRS:1,15,SMOOTH_STAIRS:2,15,SMOOTH_STAIRS:3,15,STEP:5,15,STEP:13,15,COBBLE_WALL:0,10,COBBLESTONE_STAIRS:0,10,STEP:3,10,COBBLE_WALL:1,20,COBBLESTONE_STAIRS:2,20,COBBLESTONE_STAIRS:3,20,MOSSY_COBBLESTONE:0,60,COBBLESTONE_STAIRS:1,20,STEP:11,20,COBBLESTONE:0,100)
RandomBlock(-6,3,1,SMOOTH_BRICK:0,40,SMOOTH_BRICK:1,30,SMOOTH_BRICK:2,30,SMOOTH_STAIRS:0,15,SMOOTH_STAIRS:1,15,SMOOTH_STAIRS:2,15,SMOOTH_STAIRS:3,15,STEP:5,15,STEP:13,15,COBBLE_WALL:0,10,COBBLESTONE_STAIRS:0,10,STEP:3,10,COBBLE_WALL:1,20,COBBLESTONE_STAIRS:2,20,COBBLESTONE_STAIRS:3,20,MOSSY_COBBLESTONE:0,60,COBBLESTONE_STAIRS:1,20,STEP:11,20,COBBLESTONE:0,100)
RandomBlock(-6,3,2,SMOOTH_BRICK:0,40,SMOOTH_BRICK:1,30,SMOOTH_BRICK:2,30,SMOOTH_STAIRS:0,15,SMOOTH_STAIRS:1,15,SMOOTH_STAIRS:2,15,SMOOTH_STAIRS:3,15,STEP:5,15,STEP:13,15,COBBLE_WALL:0,10,COBBLESTONE_STAIRS:0,10,STEP:3,10,COBBLE_WALL:1,20,COBBLESTONE_STAIRS:2,20,COBBLESTONE_STAIRS:3,20,MOSSY_COBBLESTONE:0,60,COBBLESTONE_STAIRS:1,20,STEP:11,20,COBBLESTONE:0,100)
RandomBlock(-6,3,3,SMOOTH_BRICK:0,40,SMOOTH_BRICK:1,30,SMOOTH_BRICK:2,30,SMOOTH_STAIRS:0,15,SMOOTH_STAIRS:1,15,SMOOTH_STAIRS:2,15,SMOOTH_STAIRS:3,15,STEP:5,15,STEP:13,15,COBBLE_WALL:0,10,COBBLESTONE_STAIRS:0,10,STEP:3,10,COBBLE_WALL:1,20,COBBLESTONE_STAIRS:2,20,COBBLESTONE_STAIRS:3,20,MOSSY_COBBLESTONE:0,60,COBBLESTONE_STAIRS:1,20,STEP:11,20,COBBLESTONE:0,100)
RandomBlock(-6,3,4,SMOOTH_BRICK:0,40,SMOOTH_BRICK:1,30,SMOOTH_BRICK:2,30,SMOOTH_STAIRS:0,15,SMOOTH_STAIRS:1,15,SMOOTH_STAIRS:2,15,SMOOTH_STAIRS:3,15,STEP:5,15,STEP:13,15,COBBLE_WALL:0,10,COBBLESTONE_STAIRS:0,10,STEP:3,10,COBBLE_WALL:1,20,COBBLESTONE_STAIRS:2,20,COBBLESTONE_STAIRS:3,20,MOSSY_COBBLESTONE:0,60,COBBLESTONE_STAIRS:1,20,STEP:11,20,COBBLESTONE:0,100)
RandomBlock(-6,3,5,SMOOTH_BRICK:0,40,SMOOTH_BRICK:1,30,SMOOTH_BRICK:2,30,SMOOTH_STAIRS:0,15,SMOOTH_STAIRS:1,15,SMOOTH_STAIRS:2,15,SMOOTH_STAIRS:3,15,STEP:5,15,STEP:13,15,COBBLE_WALL:0,10,COBBLESTONE_STAIRS:0,10,STEP:3,10,COBBLE_WALL:1,20,COBBLESTONE_STAIRS:2,20,COBBLESTONE_STAIRS:3,20,MOSSY_COBBLESTONE:0,60,COBBLESTONE_STAIRS:1,20,STEP:11,20,COBBLESTONE:0,100)
RandomBlock(-6,3,6,SMOOTH_BRICK:0,40,SMOOTH_BRICK:1,30,SMOOTH_BRICK:2,30,SMOOTH_STAIRS:0,15,SMOOTH_STAIRS:1,15,SMOOTH_STAIRS:2,15,SMOOTH_STAIRS:3,15,STEP:5,15,STEP:13,15,COBBLE_WALL:0,10,COBBLESTONE_STAIRS:0,10,STEP:3,10,COBBLE_WALL:1,20,COBBLESTONE_STAIRS:2,20,COBBLESTONE_STAIRS:3,20,MOSSY_COBBLESTONE:0,60,COBBLESTONE_STAIRS:1,20,STEP:11,20,COBBLESTONE:0,100)
RandomBlock(-6,3,7,SMOOTH_BRICK:0,40,SMOOTH_BRICK:1,30,SMOOTH_BRICK:2,30,SMOOTH_STAIRS:0,15,SMOOTH_STAIRS:1,15,SMOOTH_STAIRS:2,15,SMOOTH_STAIRS:3,15,STEP:5,15,STEP:13,15,COBBLE_WALL:0,10,COBBLESTONE_STAIRS:0,10,STEP:3,10,COBBLE_WALL:1,20,COBBLESTONE_STAIRS:2,20,COBBLESTONE_STAIRS:3,20,MOSSY_COBBLESTONE:0,60,COBBLESTONE_STAIRS:1,20,STEP:11,20,COBBLESTONE:0,100)
RandomBlock(-6,3,8,SMOOTH_BRICK:0,40,SMOOTH_BRICK:1,30,SMOOTH_BRICK:2,30,SMOOTH_STAIRS:0,15,SMOOTH_STAIRS:1,15,SMOOTH_STAIRS:2,15,SMOOTH_STAIRS:3,15,STEP:5,15,STEP:13,15,COBBLE_WALL:0,10,COBBLESTONE_STAIRS:0,10,STEP:3,10,COBBLE_WALL:1,20,COBBLESTONE_STAIRS:2,20,COBBLESTONE_STAIRS:3,20,MOSSY_COBBLESTONE:0,60,COBBLESTONE_STAIRS:1,20,STEP:11,20,COBBLESTONE:0,100)
RandomBlock(-6,4,-3,SMOOTH_BRICK:0,40,SMOOTH_BRICK:1,30,SMOOTH_BRICK:2,30,SMOOTH_STAIRS:0,15,SMOOTH_STAIRS:1,15,SMOOTH_STAIRS:2,15,SMOOTH_STAIRS:3,15,STEP:5,15,STEP:13,15,COBBLE_WALL:0,10,COBBLESTONE_STAIRS:0,10,STEP:3,10,COBBLE_WALL:1,20,COBBLESTONE_STAIRS:2,20,COBBLESTONE_STAIRS:3,20,MOSSY_COBBLESTONE:0,60,COBBLESTONE_STAIRS:1,20,STEP:11,20,COBBLESTONE:0,100)
RandomBlock(-6,4,-2,SMOOTH_BRICK:0,40,SMOOTH_BRICK:1,30,SMOOTH_BRICK:2,30,SMOOTH_STAIRS:0,15,SMOOTH_STAIRS:1,15,SMOOTH_STAIRS:2,15,SMOOTH_STAIRS:3,15,STEP:5,15,STEP:13,15,COBBLE_WALL:0,10,COBBLESTONE_STAIRS:0,10,STEP:3,10,COBBLE_WALL:1,20,COBBLESTONE_STAIRS:2,20,COBBLESTONE_STAIRS:3,20,MOSSY_COBBLESTONE:0,60,COBBLESTONE_STAIRS:1,20,STEP:11,20,COBBLESTONE:0,100)
RandomBlock(-6,4,-1,SMOOTH_BRICK:0,40,SMOOTH_BRICK:1,30,SMOOTH_BRICK:2,30,SMOOTH_STAIRS:0,15,SMOOTH_STAIRS:1,15,SMOOTH_STAIRS:2,15,SMOOTH_STAIRS:3,15,STEP:5,15,STEP:13,15,COBBLE_WALL:0,10,COBBLESTONE_STAIRS:0,10,STEP:3,10,COBBLE_WALL:1,20,COBBLESTONE_STAIRS:2,20,COBBLESTONE_STAIRS:3,20,MOSSY_COBBLESTONE:0,60,COBBLESTONE_STAIRS:1,20,STEP:11,20,COBBLESTONE:0,100)
RandomBlock(-6,4,0,SMOOTH_BRICK:0,40,SMOOTH_BRICK:1,30,SMOOTH_BRICK:2,30,SMOOTH_STAIRS:0,15,SMOOTH_STAIRS:1,15,SMOOTH_STAIRS:2,15,SMOOTH_STAIRS:3,15,STEP:5,15,STEP:13,15,COBBLE_WALL:0,10,COBBLESTONE_STAIRS:0,10,STEP:3,10,COBBLE_WALL:1,20,COBBLESTONE_STAIRS:2,20,COBBLESTONE_STAIRS:3,20,MOSSY_COBBLESTONE:0,60,COBBLESTONE_STAIRS:1,20,STEP:11,20,COBBLESTONE:0,100)
RandomBlock(-6,4,1,SMOOTH_BRICK:0,40,SMOOTH_BRICK:1,30,SMOOTH_BRICK:2,30,SMOOTH_STAIRS:0,15,SMOOTH_STAIRS:1,15,SMOOTH_STAIRS:2,15,SMOOTH_STAIRS:3,15,STEP:5,15,STEP:13,15,COBBLE_WALL:0,10,COBBLESTONE_STAIRS:0,10,STEP:3,10,COBBLE_WALL:1,20,COBBLESTONE_STAIRS:2,20,COBBLESTONE_STAIRS:3,20,MOSSY_COBBLESTONE:0,60,COBBLESTONE_STAIRS:1,20,STEP:11,20,COBBLESTONE:0,100)
RandomBlock(-6,4,2,SMOOTH_BRICK:0,40,SMOOTH_BRICK:1,30,SMOOTH_BRICK:2,30,SMOOTH_STAIRS:0,15,SMOOTH_STAIRS:1,15,SMOOTH_STAIRS:2,15,SMOOTH_STAIRS:3,15,STEP:5,15,STEP:13,15,COBBLE_WALL:0,10,COBBLESTONE_STAIRS:0,10,STEP:3,10,COBBLE_WALL:1,20,COBBLESTONE_STAIRS:2,20,COBBLESTONE_STAIRS:3,20,MOSSY_COBBLESTONE:0,60,COBBLESTONE_STAIRS:1,20,STEP:11,20,COBBLESTONE:0,100)
RandomBlock(-6,4,3,SMOOTH_BRICK:0,40,SMOOTH_BRICK:1,30,SMOOTH_BRICK:2,30,SMOOTH_STAIRS:0,15,SMOOTH_STAIRS:1,15,SMOOTH_STAIRS:2,15,SMOOTH_STAIRS:3,15,STEP:5,15,STEP:13,15,COBBLE_WALL:0,10,COBBLESTONE_STAIRS:0,10,STEP:3,10,COBBLE_WALL:1,20,COBBLESTONE_STAIRS:2,20,COBBLESTONE_STAIRS:3,20,MOSSY_COBBLESTONE:0,60,COBBLESTONE_STAIRS:1,20,STEP:11,20,COBBLESTONE:0,100)
RandomBlock(-6,4,4,SMOOTH_BRICK:0,40,SMOOTH_BRICK:1,30,SMOOTH_BRICK:2,30,SMOOTH_STAIRS:0,15,SMOOTH_STAIRS:1,15,SMOOTH_STAIRS:2,15,SMOOTH_STAIRS:3,15,STEP:5,15,STEP:13,15,COBBLE_WALL:0,10,COBBLESTONE_STAIRS:0,10,STEP:3,10,COBBLE_WALL:1,20,COBBLESTONE_STAIRS:2,20,COBBLESTONE_STAIRS:3,20,MOSSY_COBBLESTONE:0,60,COBBLESTONE_STAIRS:1,20,STEP:11,20,COBBLESTONE:0,100)
RandomBlock(-6,4,5,SMOOTH_BRICK:0,40,SMOOTH_BRICK:1,30,SMOOTH_BRICK:2,30,SMOOTH_STAIRS:0,15,SMOOTH_STAIRS:1,15,SMOOTH_STAIRS:2,15,SMOOTH_STAIRS:3,15,STEP:5,15,STEP:13,15,COBBLE_WALL:0,10,COBBLESTONE_STAIRS:0,10,STEP:3,10,COBBLE_WALL:1,20,COBBLESTONE_STAIRS:2,20,COBBLESTONE_STAIRS:3,20,MOSSY_COBBLESTONE:0,60,COBBLESTONE_STAIRS:1,20,STEP:11,20,COBBLESTONE:0,100)
RandomBlock(-6,4,6,SMOOTH_BRICK:0,40,SMOOTH_BRICK:1,30,SMOOTH_BRICK:2,30,SMOOTH_STAIRS:0,15,SMOOTH_STAIRS:1,15,SMOOTH_STAIRS:2,15,SMOOTH_STAIRS:3,15,STEP:5,15,STEP:13,15,COBBLE_WALL:0,10,COBBLESTONE_STAIRS:0,10,STEP:3,10,COBBLE_WALL:1,20,COBBLESTONE_STAIRS:2,20,COBBLESTONE_STAIRS:3,20,MOSSY_COBBLESTONE:0,60,COBBLESTONE_STAIRS:1,20,STEP:11,20,COBBLESTONE:0,100)
RandomBlock(-6,4,7,SMOOTH_BRICK:0,40,SMOOTH_BRICK:1,30,SMOOTH_BRICK:2,30,SMOOTH_STAIRS:0,15,SMOOTH_STAIRS:1,15,SMOOTH_STAIRS:2,15,SMOOTH_STAIRS:3,15,STEP:5,15,STEP:13,15,COBBLE_WALL:0,10,COBBLESTONE_STAIRS:0,10,STEP:3,10,COBBLE_WALL:1,20,COBBLESTONE_STAIRS:2,20,COBBLESTONE_STAIRS:3,20,MOSSY_COBBLESTONE:0,60,COBBLESTONE_STAIRS:1,20,STEP:11,20,COBBLESTONE:0,100)
RandomBlock(-6,4,8,SMOOTH_BRICK:0,40,SMOOTH_BRICK:1,30,SMOOTH_BRICK:2,30,SMOOTH_STAIRS:0,15,SMOOTH_STAIRS:1,15,SMOOTH_STAIRS:2,15,SMOOTH_STAIRS:3,15,STEP:5,15,STEP:13,15,COBBLE_WALL:0,10,COBBLESTONE_STAIRS:0,10,STEP:3,10,COBBLE_WALL:1,20,COBBLESTONE_STAIRS:2,20,COBBLESTONE_STAIRS:3,20,MOSSY_COBBLESTONE:0,60,COBBLESTONE_STAIRS:1,20,STEP:11,20,COBBLESTONE:0,100)
RandomBlock(-6,5,-3,quark:limestone:1,30,quark:limestone_wall,10,quark:limestone,100)
RandomBlock(-6,5,-2,quark:limestone:1,30,quark:limestone_wall,10,quark:limestone,100)
RandomBlock(-6,5,-1,SMOOTH_BRICK:0,40,SMOOTH_BRICK:1,30,SMOOTH_BRICK:2,30,SMOOTH_STAIRS:0,15,SMOOTH_STAIRS:1,15,SMOOTH_STAIRS:2,15,SMOOTH_STAIRS:3,15,STEP:5,15,STEP:13,15,COBBLE_WALL:0,10,COBBLESTONE_STAIRS:0,10,STEP:3,10,COBBLE_WALL:1,20,COBBLESTONE_STAIRS:2,20,COBBLESTONE_STAIRS:3,20,MOSSY_COBBLESTONE:0,60,COBBLESTONE_STAIRS:1,20,STEP:11,20,COBBLESTONE:0,100)
RandomBlock(-6,5,0,SMOOTH_BRICK:0,40,SMOOTH_BRICK:1,30,SMOOTH_BRICK:2,30,SMOOTH_STAIRS:0,15,SMOOTH_STAIRS:1,15,SMOOTH_STAIRS:2,15,SMOOTH_STAIRS:3,15,STEP:5,15,STEP:13,15,COBBLE_WALL:0,10,COBBLESTONE_STAIRS:0,10,STEP:3,10,COBBLE_WALL:1,20,COBBLESTONE_STAIRS:2,20,COBBLESTONE_STAIRS:3,20,MOSSY_COBBLESTONE:0,60,COBBLESTONE_STAIRS:1,20,STEP:11,20,COBBLESTONE:0,100)
RandomBlock(-6,5,1,SMOOTH_BRICK:0,40,SMOOTH_BRICK:1,30,SMOOTH_BRICK:2,30,SMOOTH_STAIRS:0,15,SMOOTH_STAIRS:1,15,SMOOTH_STAIRS:2,15,SMOOTH_STAIRS:3,15,STEP:5,15,STEP:13,15,COBBLE_WALL:0,10,COBBLESTONE_STAIRS:0,10,STEP:3,10,COBBLE_WALL:1,20,COBBLESTONE_STAIRS:2,20,COBBLESTONE_STAIRS:3,20,MOSSY_COBBLESTONE:0,60,COBBLESTONE_STAIRS:1,20,STEP:11,20,COBBLESTONE:0,100)
RandomBlock(-6,5,2,SMOOTH_BRICK:0,40,SMOOTH_BRICK:1,30,SMOOTH_BRICK:2,30,SMOOTH_STAIRS:0,15,SMOOTH_STAIRS:1,15,SMOOTH_STAIRS:2,15,SMOOTH_STAIRS:3,15,STEP:5,15,STEP:13,15,COBBLE_WALL:0,10,COBBLESTONE_STAIRS:0,10,STEP:3,10,COBBLE_WALL:1,20,COBBLESTONE_STAIRS:2,20,COBBLESTONE_STAIRS:3,20,MOSSY_COBBLESTONE:0,60,COBBLESTONE_STAIRS:1,20,STEP:11,20,COBBLESTONE:0,100)
RandomBlock(-6,5,3,SMOOTH_BRICK:0,40,SMOOTH_BRICK:1,30,SMOOTH_BRICK:2,30,SMOOTH_STAIRS:0,15,SMOOTH_STAIRS:1,15,SMOOTH_STAIRS:2,15,SMOOTH_STAIRS:3,15,STEP:5,15,STEP:13,15,COBBLE_WALL:0,10,COBBLESTONE_STAIRS:0,10,STEP:3,10,COBBLE_WALL:1,20,COBBLESTONE_STAIRS:2,20,COBBLESTONE_STAIRS:3,20,MOSSY_COBBLESTONE:0,60,COBBLESTONE_STAIRS:1,20,STEP:11,20,COBBLESTONE:0,100)
RandomBlock(-6,5,4,SMOOTH_BRICK:0,40,SMOOTH_BRICK:1,30,SMOOTH_BRICK:2,30,SMOOTH_STAIRS:0,15,SMOOTH_STAIRS:1,15,SMOOTH_STAIRS:2,15,SMOOTH_STAIRS:3,15,STEP:5,15,STEP:13,15,COBBLE_WALL:0,10,COBBLESTONE_STAIRS:0,10,STEP:3,10,COBBLE_WALL:1,20,COBBLESTONE_STAIRS:2,20,COBBLESTONE_STAIRS:3,20,MOSSY_COBBLESTONE:0,60,COBBLESTONE_STAIRS:1,20,STEP:11,20,COBBLESTONE:0,100)
RandomBlock(-6,5,5,SMOOTH_BRICK:0,40,SMOOTH_BRICK:1,30,SMOOTH_BRICK:2,30,SMOOTH_STAIRS:0,15,SMOOTH_STAIRS:1,15,SMOOTH_STAIRS:2,15,SMOOTH_STAIRS:3,15,STEP:5,15,STEP:13,15,COBBLE_WALL:0,10,COBBLESTONE_STAIRS:0,10,STEP:3,10,COBBLE_WALL:1,20,COBBLESTONE_STAIRS:2,20,COBBLESTONE_STAIRS:3,20,MOSSY_COBBLESTONE:0,60,COBBLESTONE_STAIRS:1,20,STEP:11,20,COBBLESTONE:0,100)
RandomBlock(-6,5,6,SMOOTH_BRICK:0,40,SMOOTH_BRICK:1,30,SMOOTH_BRICK:2,30,SMOOTH_STAIRS:0,15,SMOOTH_STAIRS:1,15,SMOOTH_STAIRS:2,15,SMOOTH_STAIRS:3,15,STEP:5,15,STEP:13,15,COBBLE_WALL:0,10,COBBLESTONE_STAIRS:0,10,STEP:3,10,COBBLE_WALL:1,20,COBBLESTONE_STAIRS:2,20,COBBLESTONE_STAIRS:3,20,MOSSY_COBBLESTONE:0,60,COBBLESTONE_STAIRS:1,20,STEP:11,20,COBBLESTONE:0,100)
RandomBlock(-6,5,7,SMOOTH_BRICK:0,40,SMOOTH_BRICK:1,30,SMOOTH_BRICK:2,30,SMOOTH_STAIRS:0,15,SMOOTH_STAIRS:1,15,SMOOTH_STAIRS:2,15,SMOOTH_STAIRS:3,15,STEP:5,15,STEP:13,15,COBBLE_WALL:0,10,COBBLESTONE_STAIRS:0,10,STEP:3,10,COBBLE_WALL:1,20,COBBLESTONE_STAIRS:2,20,COBBLESTONE_STAIRS:3,20,MOSSY_COBBLESTONE:0,60,COBBLESTONE_STAIRS:1,20,STEP:11,20,COBBLESTONE:0,100)
RandomBlock(-6,5,8,SMOOTH_BRICK:0,40,SMOOTH_BRICK:1,30,SMOOTH_BRICK:2,30,SMOOTH_STAIRS:0,15,SMOOTH_STAIRS:1,15,SMOOTH_STAIRS:2,15,SMOOTH_STAIRS:3,15,STEP:5,15,STEP:13,15,COBBLE_WALL:0,10,COBBLESTONE_STAIRS:0,10,STEP:3,10,COBBLE_WALL:1,20,COBBLESTONE_STAIRS:2,20,COBBLESTONE_STAIRS:3,20,MOSSY_COBBLESTONE:0,60,COBBLESTONE_STAIRS:1,20,STEP:11,20,COBBLESTONE:0,100)
RandomBlock(-6,6,-3,quark:limestone:1,30,quark:limestone_wall,10,quark:limestone,100)
RandomBlock(-6,6,-2,quark:limestone:1,30,quark:limestone_wall,10,quark:limestone,100)
RandomBlock(-6,6,-1,SMOOTH_BRICK:0,40,SMOOTH_BRICK:1,30,SMOOTH_BRICK:2,30,SMOOTH_STAIRS:0,15,SMOOTH_STAIRS:1,15,SMOOTH_STAIRS:2,15,SMOOTH_STAIRS:3,15,STEP:5,15,STEP:13,15,COBBLE_WALL:0,10,COBBLESTONE_STAIRS:0,10,STEP:3,10,COBBLE_WALL:1,20,COBBLESTONE_STAIRS:2,20,COBBLESTONE_STAIRS:3,20,MOSSY_COBBLESTONE:0,60,COBBLESTONE_STAIRS:1,20,STEP:11,20,COBBLESTONE:0,100)
RandomBlock(-6,6,0,SMOOTH_BRICK:0,40,SMOOTH_BRICK:1,30,SMOOTH_BRICK:2,30,SMOOTH_STAIRS:0,15,SMOOTH_STAIRS:1,15,SMOOTH_STAIRS:2,15,SMOOTH_STAIRS:3,15,STEP:5,15,STEP:13,15,COBBLE_WALL:0,10,COBBLESTONE_STAIRS:0,10,STEP:3,10,COBBLE_WALL:1,20,COBBLESTONE_STAIRS:2,20,COBBLESTONE_STAIRS:3,20,MOSSY_COBBLESTONE:0,60,COBBLESTONE_STAIRS:1,20,STEP:11,20,COBBLESTONE:0,100)
RandomBlock(-6,6,1,SMOOTH_BRICK:0,40,SMOOTH_BRICK:1,30,SMOOTH_BRICK:2,30,SMOOTH_STAIRS:0,15,SMOOTH_STAIRS:1,15,SMOOTH_STAIRS:2,15,SMOOTH_STAIRS:3,15,STEP:5,15,STEP:13,15,COBBLE_WALL:0,10,COBBLESTONE_STAIRS:0,10,STEP:3,10,COBBLE_WALL:1,20,COBBLESTONE_STAIRS:2,20,COBBLESTONE_STAIRS:3,20,MOSSY_COBBLESTONE:0,60,COBBLESTONE_STAIRS:1,20,STEP:11,20,COBBLESTONE:0,100)
RandomBlock(-6,6,2,SMOOTH_BRICK:0,40,SMOOTH_BRICK:1,30,SMOOTH_BRICK:2,30,SMOOTH_STAIRS:0,15,SMOOTH_STAIRS:1,15,SMOOTH_STAIRS:2,15,SMOOTH_STAIRS:3,15,STEP:5,15,STEP:13,15,COBBLE_WALL:0,10,COBBLESTONE_STAIRS:0,10,STEP:3,10,COBBLE_WALL:1,20,COBBLESTONE_STAIRS:2,20,COBBLESTONE_STAIRS:3,20,MOSSY_COBBLESTONE:0,60,COBBLESTONE_STAIRS:1,20,STEP:11,20,COBBLESTONE:0,100)
RandomBlock(-6,6,3,SMOOTH_BRICK:0,40,SMOOTH_BRICK:1,30,SMOOTH_BRICK:2,30,SMOOTH_STAIRS:0,15,SMOOTH_STAIRS:1,15,SMOOTH_STAIRS:2,15,SMOOTH_STAIRS:3,15,STEP:5,15,STEP:13,15,COBBLE_WALL:0,10,COBBLESTONE_STAIRS:0,10,STEP:3,10,COBBLE_WALL:1,20,COBBLESTONE_STAIRS:2,20,COBBLESTONE_STAIRS:3,20,MOSSY_COBBLESTONE:0,60,COBBLESTONE_STAIRS:1,20,STEP:11,20,COBBLESTONE:0,100)
RandomBlock(-6,6,4,SMOOTH_BRICK:0,40,SMOOTH_BRICK:1,30,SMOOTH_BRICK:2,30,SMOOTH_STAIRS:0,15,SMOOTH_STAIRS:1,15,SMOOTH_STAIRS:2,15,SMOOTH_STAIRS:3,15,STEP:5,15,STEP:13,15,COBBLE_WALL:0,10,COBBLESTONE_STAIRS:0,10,STEP:3,10,COBBLE_WALL:1,20,COBBLESTONE_STAIRS:2,20,COBBLESTONE_STAIRS:3,20,MOSSY_COBBLESTONE:0,60,COBBLESTONE_STAIRS:1,20,STEP:11,20,COBBLESTONE:0,100)
RandomBlock(-6,6,5,SMOOTH_BRICK:0,40,SMOOTH_BRICK:1,30,SMOOTH_BRICK:2,30,SMOOTH_STAIRS:0,15,SMOOTH_STAIRS:1,15,SMOOTH_STAIRS:2,15,SMOOTH_STAIRS:3,15,STEP:5,15,STEP:13,15,COBBLE_WALL:0,10,COBBLESTONE_STAIRS:0,10,STEP:3,10,COBBLE_WALL:1,20,COBBLESTONE_STAIRS:2,20,COBBLESTONE_STAIRS:3,20,MOSSY_COBBLESTONE:0,60,COBBLESTONE_STAIRS:1,20,STEP:11,20,COBBLESTONE:0,100)
RandomBlock(-6,6,6,SMOOTH_BRICK:0,40,SMOOTH_BRICK:1,30,SMOOTH_BRICK:2,30,SMOOTH_STAIRS:0,15,SMOOTH_STAIRS:1,15,SMOOTH_STAIRS:2,15,SMOOTH_STAIRS:3,15,STEP:5,15,STEP:13,15,COBBLE_WALL:0,10,COBBLESTONE_STAIRS:0,10,STEP:3,10,COBBLE_WALL:1,20,COBBLESTONE_STAIRS:2,20,COBBLESTONE_STAIRS:3,20,MOSSY_COBBLESTONE:0,60,COBBLESTONE_STAIRS:1,20,STEP:11,20,COBBLESTONE:0,100)
RandomBlock(-6,6,7,SMOOTH_BRICK:0,40,SMOOTH_BRICK:1,30,SMOOTH_BRICK:2,30,SMOOTH_STAIRS:0,15,SMOOTH_STAIRS:1,15,SMOOTH_STAIRS:2,15,SMOOTH_STAIRS:3,15,STEP:5,15,STEP:13,15,COBBLE_WALL:0,10,COBBLESTONE_STAIRS:0,10,STEP:3,10,COBBLE_WALL:1,20,COBBLESTONE_STAIRS:2,20,COBBLESTONE_STAIRS:3,20,MOSSY_COBBLESTONE:0,60,COBBLESTONE_STAIRS:1,20,STEP:11,20,COBBLESTONE:0,100)
RandomBlock(-6,6,8,SMOOTH_BRICK:0,40,SMOOTH_BRICK:1,30,SMOOTH_BRICK:2,30,SMOOTH_STAIRS:0,15,SMOOTH_STAIRS:1,15,SMOOTH_STAIRS:2,15,SMOOTH_STAIRS:3,15,STEP:5,15,STEP:13,15,COBBLE_WALL:0,10,COBBLESTONE_STAIRS:0,10,STEP:3,10,COBBLE_WALL:1,20,COBBLESTONE_STAIRS:2,20,COBBLESTONE_STAIRS:3,20,MOSSY_COBBLESTONE:0,60,COBBLESTONE_STAIRS:1,20,STEP:11,20,COBBLESTONE:0,100)
RandomBlock(-6,7,-3,quark:limestone:1,30,quark:limestone_wall,10,quark:limestone,100)
RandomBlock(-6,7,-2,quark:limestone:1,30,quark:limestone_wall,10,quark:limestone,100)
RandomBlock(-6,7,-1,SMOOTH_BRICK:0,40,SMOOTH_BRICK:1,30,SMOOTH_BRICK:2,30,SMOOTH_STAIRS:0,15,SMOOTH_STAIRS:1,15,SMOOTH_STAIRS:2,15,SMOOTH_STAIRS:3,15,STEP:5,15,STEP:13,15,COBBLE_WALL:0,10,COBBLESTONE_STAIRS:0,10,STEP:3,10,COBBLE_WALL:1,20,COBBLESTONE_STAIRS:2,20,COBBLESTONE_STAIRS:3,20,MOSSY_COBBLESTONE:0,60,COBBLESTONE_STAIRS:1,20,STEP:11,20,COBBLESTONE:0,100)
RandomBlock(-6,7,0,SMOOTH_BRICK:0,40,SMOOTH_BRICK:1,30,SMOOTH_BRICK:2,30,SMOOTH_STAIRS:0,15,SMOOTH_STAIRS:1,15,SMOOTH_STAIRS:2,15,SMOOTH_STAIRS:3,15,STEP:5,15,STEP:13,15,COBBLE_WALL:0,10,COBBLESTONE_STAIRS:0,10,STEP:3,10,COBBLE_WALL:1,20,COBBLESTONE_STAIRS:2,20,COBBLESTONE_STAIRS:3,20,MOSSY_COBBLESTONE:0,60,COBBLESTONE_STAIRS:1,20,STEP:11,20,COBBLESTONE:0,100)
RandomBlock(-6,7,1,SMOOTH_BRICK:0,40,SMOOTH_BRICK:1,30,SMOOTH_BRICK:2,30,SMOOTH_STAIRS:0,15,SMOOTH_STAIRS:1,15,SMOOTH_STAIRS:2,15,SMOOTH_STAIRS:3,15,STEP:5,15,STEP:13,15,COBBLE_WALL:0,10,COBBLESTONE_STAIRS:0,10,STEP:3,10,COBBLE_WALL:1,20,COBBLESTONE_STAIRS:2,20,COBBLESTONE_STAIRS:3,20,MOSSY_COBBLESTONE:0,60,COBBLESTONE_STAIRS:1,20,STEP:11,20,COBBLESTONE:0,100)
RandomBlock(-6,7,2,SMOOTH_BRICK:0,40,SMOOTH_BRICK:1,30,SMOOTH_BRICK:2,30,SMOOTH_STAIRS:0,15,SMOOTH_STAIRS:1,15,SMOOTH_STAIRS:2,15,SMOOTH_STAIRS:3,15,STEP:5,15,STEP:13,15,COBBLE_WALL:0,10,COBBLESTONE_STAIRS:0,10,STEP:3,10,COBBLE_WALL:1,20,COBBLESTONE_STAIRS:2,20,COBBLESTONE_STAIRS:3,20,MOSSY_COBBLESTONE:0,60,COBBLESTONE_STAIRS:1,20,STEP:11,20,COBBLESTONE:0,100)
RandomBlock(-6,7,3,SMOOTH_BRICK:0,40,SMOOTH_BRICK:1,30,SMOOTH_BRICK:2,30,SMOOTH_STAIRS:0,15,SMOOTH_STAIRS:1,15,SMOOTH_STAIRS:2,15,SMOOTH_STAIRS:3,15,STEP:5,15,STEP:13,15,COBBLE_WALL:0,10,COBBLESTONE_STAIRS:0,10,STEP:3,10,COBBLE_WALL:1,20,COBBLESTONE_STAIRS:2,20,COBBLESTONE_STAIRS:3,20,MOSSY_COBBLESTONE:0,60,COBBLESTONE_STAIRS:1,20,STEP:11,20,COBBLESTONE:0,100)
RandomBlock(-6,7,4,SMOOTH_BRICK:0,40,SMOOTH_BRICK:1,30,SMOOTH_BRICK:2,30,SMOOTH_STAIRS:0,15,SMOOTH_STAIRS:1,15,SMOOTH_STAIRS:2,15,SMOOTH_STAIRS:3,15,STEP:5,15,STEP:13,15,COBBLE_WALL:0,10,COBBLESTONE_STAIRS:0,10,STEP:3,10,COBBLE_WALL:1,20,COBBLESTONE_STAIRS:2,20,COBBLESTONE_STAIRS:3,20,MOSSY_COBBLESTONE:0,60,COBBLESTONE_STAIRS:1,20,STEP:11,20,COBBLESTONE:0,100)
RandomBlock(-6,7,5,SMOOTH_BRICK:0,40,SMOOTH_BRICK:1,30,SMOOTH_BRICK:2,30,SMOOTH_STAIRS:0,15,SMOOTH_STAIRS:1,15,SMOOTH_STAIRS:2,15,SMOOTH_STAIRS:3,15,STEP:5,15,STEP:13,15,COBBLE_WALL:0,10,COBBLESTONE_STAIRS:0,10,STEP:3,10,COBBLE_WALL:1,20,COBBLESTONE_STAIRS:2,20,COBBLESTONE_STAIRS:3,20,MOSSY_COBBLESTONE:0,60,COBBLESTONE_STAIRS:1,20,STEP:11,20,COBBLESTONE:0,100)
RandomBlock(-6,7,6,SMOOTH_BRICK:0,40,SMOOTH_BRICK:1,30,SMOOTH_BRICK:2,30,SMOOTH_STAIRS:0,15,SMOOTH_STAIRS:1,15,SMOOTH_STAIRS:2,15,SMOOTH_STAIRS:3,15,STEP:5,15,STEP:13,15,COBBLE_WALL:0,10,COBBLESTONE_STAIRS:0,10,STEP:3,10,COBBLE_WALL:1,20,COBBLESTONE_STAIRS:2,20,COBBLESTONE_STAIRS:3,20,MOSSY_COBBLESTONE:0,60,COBBLESTONE_STAIRS:1,20,STEP:11,20,COBBLESTONE:0,100)
RandomBlock(-6,7,7,SMOOTH_BRICK:0,40,SMOOTH_BRICK:1,30,SMOOTH_BRICK:2,30,SMOOTH_STAIRS:0,15,SMOOTH_STAIRS:1,15,SMOOTH_STAIRS:2,15,SMOOTH_STAIRS:3,15,STEP:5,15,STEP:13,15,COBBLE_WALL:0,10,COBBLESTONE_STAIRS:0,10,STEP:3,10,COBBLE_WALL:1,20,COBBLESTONE_STAIRS:2,20,COBBLESTONE_STAIRS:3,20,MOSSY_COBBLESTONE:0,60,COBBLESTONE_STAIRS:1,20,STEP:11,20,COBBLESTONE:0,100)
RandomBlock(-6,7,8,SMOOTH_BRICK:0,40,SMOOTH_BRICK:1,30,SMOOTH_BRICK:2,30,SMOOTH_STAIRS:0,15,SMOOTH_STAIRS:1,15,SMOOTH_STAIRS:2,15,SMOOTH_STAIRS:3,15,STEP:5,15,STEP:13,15,COBBLE_WALL:0,10,COBBLESTONE_STAIRS:0,10,STEP:3,10,COBBLE_WALL:1,20,COBBLESTONE_STAIRS:2,20,COBBLESTONE_STAIRS:3,20,MOSSY_COBBLESTONE:0,60,COBBLESTONE_STAIRS:1,20,STEP:11,20,COBBLESTONE:0,100)
Block(-6,8,-3,inspirations:redstone_barrel)
RandomBlock(-6,8,-1,rustic:iron_lattice:0,30,rustic:iron_lattice,100)
RandomBlock(-6,8,0,rustic:iron_lattice:0,30,rustic:iron_lattice,100)
RandomBlock(-6,8,1,rustic:iron_lattice:0,30,rustic:iron_lattice,100)
Block(-6,8,4,quark:iron_plate)
RandomBlock(-6,8,7,rustic:iron_lattice:0,30,rustic:iron_lattice,100)
RandomBlock(-6,8,8,rustic:iron_lattice:0,30,rustic:iron_lattice,100)
Block(-6,9,-3,inspirations:redstone_barrel)
RandomBlock(-6,9,-1,rustic:iron_lattice:0,30,rustic:iron_lattice,100)
RandomBlock(-6,9,0,rustic:iron_lattice:0,30,rustic:iron_lattice,100)
RandomBlock(-6,9,1,rustic:iron_lattice:0,30,rustic:iron_lattice,100)
RandomBlock(-6,9,7,rustic:iron_lattice:0,30,rustic:iron_lattice,100)
RandomBlock(-6,9,8,rustic:iron_lattice:0,30,rustic:iron_lattice,100)
RandomBlock(-6,10,-3,quark:limestone:1,30,quark:limestone_wall,10,quark:limestone,100)
RandomBlock(-6,10,-2,quark:limestone:1,30,quark:limestone_wall,10,quark:limestone,100)
RandomBlock(-6,10,-1,rustic:iron_lattice:0,30,rustic:iron_lattice,100)
RandomBlock(-6,10,0,rustic:iron_lattice:0,30,rustic:iron_lattice,100)
RandomBlock(-6,10,1,rustic:iron_lattice:0,30,rustic:iron_lattice,100)
RandomBlock(-6,10,7,rustic:iron_lattice:0,30,rustic:iron_lattice,100)
RandomBlock(-6,10,8,rustic:iron_lattice:0,30,rustic:iron_lattice,100)
RandomBlock(-6,11,-3,quark:limestone:1,30,quark:limestone_wall,10,quark:limestone,100)
RandomBlock(-6,11,-2,quark:limestone:1,30,quark:limestone_wall,10,quark:limestone,100)
Block(-6,11,0,VINE:2)
Block(-6,11,1,VINE:6)
Block(-6,11,7,VINE:2)
RandomBlock(-6,12,-1,quark:limestone:1,30,quark:limestone_wall,10,quark:limestone,100)
RandomBlock(-6,12,0,quark:limestone:1,30,quark:limestone_wall,10,quark:limestone,100)
Block(-6,12,1,VINE:6)
Block(-6,12,7,VINE:2)
RandomBlock(-6,12,8,quark:limestone:1,30,quark:limestone_wall,10,quark:limestone,100)
RandomBlock(-6,13,-1,quark:limestone:1,30,quark:limestone_wall,10,quark:limestone,100)
RandomBlock(-6,13,0,quark:limestone:1,30,quark:limestone_wall,10,quark:limestone,100)
Block(-6,13,1,VINE:6)
Block(-6,13,7,VINE:2)
RandomBlock(-6,13,8,quark:limestone:1,30,quark:limestone_wall,10,quark:limestone,100)
Block(-6,14,-1,VINE:1)
Block(-6,14,0,quark:iron_plate:1)
RandomBlock(-6,14,1,quark:limestone:1,30,quark:limestone_wall,10,quark:limestone,100)
RandomBlock(-6,14,2,quark:limestone:1,30,quark:limestone_wall,10,quark:limestone,100)
RandomBlock(-6,14,3,quark:limestone:1,30,quark:limestone_wall,10,quark:limestone,100)
RandomBlock(-6,14,4,quark:limestone:1,30,quark:limestone_wall,10,quark:limestone,100)
RandomBlock(-6,14,5,quark:limestone:1,30,quark:limestone_wall,10,quark:limestone,100)
RandomBlock(-6,14,6,quark:limestone:1,30,quark:limestone_wall,10,quark:limestone,100)
RandomBlock(-6,14,7,quark:limestone:1,30,quark:limestone_wall,10,quark:limestone,100)
Block(-6,14,8,quark:iron_plate:1)
Block(-6,15,0,quark:iron_plate:1)
RandomBlock(-6,15,1,quark:limestone:1,30,quark:limestone_wall,10,quark:limestone,100)
RandomBlock(-6,15,2,quark:limestone:1,30,quark:limestone_wall,10,quark:limestone,100)
RandomBlock(-6,15,3,quark:limestone:1,30,quark:limestone_wall,10,quark:limestone,100)
RandomBlock(-6,15,4,quark:limestone:1,30,quark:limestone_wall,10,quark:limestone,100)
RandomBlock(-6,15,5,quark:limestone:1,30,quark:limestone_wall,10,quark:limestone,100)
RandomBlock(-6,15,6,quark:limestone:1,30,quark:limestone_wall,10,quark:limestone,100)
RandomBlock(-6,15,7,quark:limestone:1,30,quark:limestone_wall,10,quark:limestone,100)
Block(-6,15,8,quark:iron_plate:1)
Block(-6,16,4,quark:iron_plate:1)
Block(-6,16,6,VINE:8)
Block(-6,17,6,VINE:8)
Block(-6,18,6,VINE:8)
RandomBlock(-5,0,-4,SMOOTH_BRICK:0,40,SMOOTH_BRICK:1,30,SMOOTH_BRICK:2,30,SMOOTH_STAIRS:0,15,SMOOTH_STAIRS:1,15,SMOOTH_STAIRS:2,15,SMOOTH_STAIRS:3,15,STEP:5,15,STEP:13,15,COBBLE_WALL:0,10,COBBLESTONE_STAIRS:0,10,STEP:3,10,COBBLE_WALL:1,20,COBBLESTONE_STAIRS:2,20,COBBLESTONE_STAIRS:3,20,MOSSY_COBBLESTONE:0,60,COBBLESTONE_STAIRS:1,20,STEP:11,20,COBBLESTONE:0,100)
RandomBlock(-5,0,-3,SMOOTH_BRICK:0,40,SMOOTH_BRICK:1,30,SMOOTH_BRICK:2,30,SMOOTH_STAIRS:0,15,SMOOTH_STAIRS:1,15,SMOOTH_STAIRS:2,15,SMOOTH_STAIRS:3,15,STEP:5,15,STEP:13,15,COBBLE_WALL:0,10,COBBLESTONE_STAIRS:0,10,STEP:3,10,COBBLE_WALL:1,20,COBBLESTONE_STAIRS:2,20,COBBLESTONE_STAIRS:3,20,MOSSY_COBBLESTONE:0,60,COBBLESTONE_STAIRS:1,20,STEP:11,20,COBBLESTONE:0,100)
RandomBlock(-5,0,-2,SMOOTH_BRICK:0,40,SMOOTH_BRICK:1,30,SMOOTH_BRICK:2,30,SMOOTH_STAIRS:0,15,SMOOTH_STAIRS:1,15,SMOOTH_STAIRS:2,15,SMOOTH_STAIRS:3,15,STEP:5,15,STEP:13,15,COBBLE_WALL:0,10,COBBLESTONE_STAIRS:0,10,STEP:3,10,COBBLE_WALL:1,20,COBBLESTONE_STAIRS:2,20,COBBLESTONE_STAIRS:3,20,MOSSY_COBBLESTONE:0,60,COBBLESTONE_STAIRS:1,20,STEP:11,20,COBBLESTONE:0,100)
RandomBlock(-5,0,-1,SMOOTH_BRICK:0,40,SMOOTH_BRICK:1,30,SMOOTH_BRICK:2,30,SMOOTH_STAIRS:0,15,SMOOTH_STAIRS:1,15,SMOOTH_STAIRS:2,15,SMOOTH_STAIRS:3,15,STEP:5,15,STEP:13,15,COBBLE_WALL:0,10,COBBLESTONE_STAIRS:0,10,STEP:3,10,COBBLE_WALL:1,20,COBBLESTONE_STAIRS:2,20,COBBLESTONE_STAIRS:3,20,MOSSY_COBBLESTONE:0,60,COBBLESTONE_STAIRS:1,20,STEP:11,20,COBBLESTONE:0,100)
RandomBlock(-5,0,0,SMOOTH_BRICK:0,40,SMOOTH_BRICK:1,30,SMOOTH_BRICK:2,30,SMOOTH_STAIRS:0,15,SMOOTH_STAIRS:1,15,SMOOTH_STAIRS:2,15,SMOOTH_STAIRS:3,15,STEP:5,15,STEP:13,15,COBBLE_WALL:0,10,COBBLESTONE_STAIRS:0,10,STEP:3,10,COBBLE_WALL:1,20,COBBLESTONE_STAIRS:2,20,COBBLESTONE_STAIRS:3,20,MOSSY_COBBLESTONE:0,60,COBBLESTONE_STAIRS:1,20,STEP:11,20,COBBLESTONE:0,100)
RandomBlock(-5,0,1,SMOOTH_BRICK:0,40,SMOOTH_BRICK:1,30,SMOOTH_BRICK:2,30,SMOOTH_STAIRS:0,15,SMOOTH_STAIRS:1,15,SMOOTH_STAIRS:2,15,SMOOTH_STAIRS:3,15,STEP:5,15,STEP:13,15,COBBLE_WALL:0,10,COBBLESTONE_STAIRS:0,10,STEP:3,10,COBBLE_WALL:1,20,COBBLESTONE_STAIRS:2,20,COBBLESTONE_STAIRS:3,20,MOSSY_COBBLESTONE:0,60,COBBLESTONE_STAIRS:1,20,STEP:11,20,COBBLESTONE:0,100)
RandomBlock(-5,0,2,SMOOTH_BRICK:0,40,SMOOTH_BRICK:1,30,SMOOTH_BRICK:2,30,SMOOTH_STAIRS:0,15,SMOOTH_STAIRS:1,15,SMOOTH_STAIRS:2,15,SMOOTH_STAIRS:3,15,STEP:5,15,STEP:13,15,COBBLE_WALL:0,10,COBBLESTONE_STAIRS:0,10,STEP:3,10,COBBLE_WALL:1,20,COBBLESTONE_STAIRS:2,20,COBBLESTONE_STAIRS:3,20,MOSSY_COBBLESTONE:0,60,COBBLESTONE_STAIRS:1,20,STEP:11,20,COBBLESTONE:0,100)
RandomBlock(-5,0,3,SMOOTH_BRICK:0,40,SMOOTH_BRICK:1,30,SMOOTH_BRICK:2,30,SMOOTH_STAIRS:0,15,SMOOTH_STAIRS:1,15,SMOOTH_STAIRS:2,15,SMOOTH_STAIRS:3,15,STEP:5,15,STEP:13,15,COBBLE_WALL:0,10,COBBLESTONE_STAIRS:0,10,STEP:3,10,COBBLE_WALL:1,20,COBBLESTONE_STAIRS:2,20,COBBLESTONE_STAIRS:3,20,MOSSY_COBBLESTONE:0,60,COBBLESTONE_STAIRS:1,20,STEP:11,20,COBBLESTONE:0,100)
RandomBlock(-5,0,4,SMOOTH_BRICK:0,40,SMOOTH_BRICK:1,30,SMOOTH_BRICK:2,30,SMOOTH_STAIRS:0,15,SMOOTH_STAIRS:1,15,SMOOTH_STAIRS:2,15,SMOOTH_STAIRS:3,15,STEP:5,15,STEP:13,15,COBBLE_WALL:0,10,COBBLESTONE_STAIRS:0,10,STEP:3,10,COBBLE_WALL:1,20,COBBLESTONE_STAIRS:2,20,COBBLESTONE_STAIRS:3,20,MOSSY_COBBLESTONE:0,60,COBBLESTONE_STAIRS:1,20,STEP:11,20,COBBLESTONE:0,100)
RandomBlock(-5,0,5,SMOOTH_BRICK:0,40,SMOOTH_BRICK:1,30,SMOOTH_BRICK:2,30,SMOOTH_STAIRS:0,15,SMOOTH_STAIRS:1,15,SMOOTH_STAIRS:2,15,SMOOTH_STAIRS:3,15,STEP:5,15,STEP:13,15,COBBLE_WALL:0,10,COBBLESTONE_STAIRS:0,10,STEP:3,10,COBBLE_WALL:1,20,COBBLESTONE_STAIRS:2,20,COBBLESTONE_STAIRS:3,20,MOSSY_COBBLESTONE:0,60,COBBLESTONE_STAIRS:1,20,STEP:11,20,COBBLESTONE:0,100)
RandomBlock(-5,0,6,SMOOTH_BRICK:0,40,SMOOTH_BRICK:1,30,SMOOTH_BRICK:2,30,SMOOTH_STAIRS:0,15,SMOOTH_STAIRS:1,15,SMOOTH_STAIRS:2,15,SMOOTH_STAIRS:3,15,STEP:5,15,STEP:13,15,COBBLE_WALL:0,10,COBBLESTONE_STAIRS:0,10,STEP:3,10,COBBLE_WALL:1,20,COBBLESTONE_STAIRS:2,20,COBBLESTONE_STAIRS:3,20,MOSSY_COBBLESTONE:0,60,COBBLESTONE_STAIRS:1,20,STEP:11,20,COBBLESTONE:0,100)
RandomBlock(-5,0,7,SMOOTH_BRICK:0,40,SMOOTH_BRICK:1,30,SMOOTH_BRICK:2,30,SMOOTH_STAIRS:0,15,SMOOTH_STAIRS:1,15,SMOOTH_STAIRS:2,15,SMOOTH_STAIRS:3,15,STEP:5,15,STEP:13,15,COBBLE_WALL:0,10,COBBLESTONE_STAIRS:0,10,STEP:3,10,COBBLE_WALL:1,20,COBBLESTONE_STAIRS:2,20,COBBLESTONE_STAIRS:3,20,MOSSY_COBBLESTONE:0,60,COBBLESTONE_STAIRS:1,20,STEP:11,20,COBBLESTONE:0,100)
RandomBlock(-5,0,8,SMOOTH_BRICK:0,40,SMOOTH_BRICK:1,30,SMOOTH_BRICK:2,30,SMOOTH_STAIRS:0,15,SMOOTH_STAIRS:1,15,SMOOTH_STAIRS:2,15,SMOOTH_STAIRS:3,15,STEP:5,15,STEP:13,15,COBBLE_WALL:0,10,COBBLESTONE_STAIRS:0,10,STEP:3,10,COBBLE_WALL:1,20,COBBLESTONE_STAIRS:2,20,COBBLESTONE_STAIRS:3,20,MOSSY_COBBLESTONE:0,60,COBBLESTONE_STAIRS:1,20,STEP:11,20,COBBLESTONE:0,100)
RandomBlock(-5,1,-4,SMOOTH_BRICK:0,40,SMOOTH_BRICK:1,30,SMOOTH_BRICK:2,30,SMOOTH_STAIRS:0,15,SMOOTH_STAIRS:1,15,SMOOTH_STAIRS:2,15,SMOOTH_STAIRS:3,15,STEP:5,15,STEP:13,15,COBBLE_WALL:0,10,COBBLESTONE_STAIRS:0,10,STEP:3,10,COBBLE_WALL:1,20,COBBLESTONE_STAIRS:2,20,COBBLESTONE_STAIRS:3,20,MOSSY_COBBLESTONE:0,60,COBBLESTONE_STAIRS:1,20,STEP:11,20,COBBLESTONE:0,100)
RandomBlock(-5,1,-3,SMOOTH_BRICK:0,40,SMOOTH_BRICK:1,30,SMOOTH_BRICK:2,30,SMOOTH_STAIRS:0,15,SMOOTH_STAIRS:1,15,SMOOTH_STAIRS:2,15,SMOOTH_STAIRS:3,15,STEP:5,15,STEP:13,15,COBBLE_WALL:0,10,COBBLESTONE_STAIRS:0,10,STEP:3,10,COBBLE_WALL:1,20,COBBLESTONE_STAIRS:2,20,COBBLESTONE_STAIRS:3,20,MOSSY_COBBLESTONE:0,60,COBBLESTONE_STAIRS:1,20,STEP:11,20,COBBLESTONE:0,100)
RandomBlock(-5,1,-2,SMOOTH_BRICK:0,40,SMOOTH_BRICK:1,30,SMOOTH_BRICK:2,30,SMOOTH_STAIRS:0,15,SMOOTH_STAIRS:1,15,SMOOTH_STAIRS:2,15,SMOOTH_STAIRS:3,15,STEP:5,15,STEP:13,15,COBBLE_WALL:0,10,COBBLESTONE_STAIRS:0,10,STEP:3,10,COBBLE_WALL:1,20,COBBLESTONE_STAIRS:2,20,COBBLESTONE_STAIRS:3,20,MOSSY_COBBLESTONE:0,60,COBBLESTONE_STAIRS:1,20,STEP:11,20,COBBLESTONE:0,100)
RandomBlock(-5,1,-1,SMOOTH_BRICK:0,40,SMOOTH_BRICK:1,30,SMOOTH_BRICK:2,30,SMOOTH_STAIRS:0,15,SMOOTH_STAIRS:1,15,SMOOTH_STAIRS:2,15,SMOOTH_STAIRS:3,15,STEP:5,15,STEP:13,15,COBBLE_WALL:0,10,COBBLESTONE_STAIRS:0,10,STEP:3,10,COBBLE_WALL:1,20,COBBLESTONE_STAIRS:2,20,COBBLESTONE_STAIRS:3,20,MOSSY_COBBLESTONE:0,60,COBBLESTONE_STAIRS:1,20,STEP:11,20,COBBLESTONE:0,100)
RandomBlock(-5,1,0,SMOOTH_BRICK:0,40,SMOOTH_BRICK:1,30,SMOOTH_BRICK:2,30,SMOOTH_STAIRS:0,15,SMOOTH_STAIRS:1,15,SMOOTH_STAIRS:2,15,SMOOTH_STAIRS:3,15,STEP:5,15,STEP:13,15,COBBLE_WALL:0,10,COBBLESTONE_STAIRS:0,10,STEP:3,10,COBBLE_WALL:1,20,COBBLESTONE_STAIRS:2,20,COBBLESTONE_STAIRS:3,20,MOSSY_COBBLESTONE:0,60,COBBLESTONE_STAIRS:1,20,STEP:11,20,COBBLESTONE:0,100)
RandomBlock(-5,1,1,SMOOTH_BRICK:0,40,SMOOTH_BRICK:1,30,SMOOTH_BRICK:2,30,SMOOTH_STAIRS:0,15,SMOOTH_STAIRS:1,15,SMOOTH_STAIRS:2,15,SMOOTH_STAIRS:3,15,STEP:5,15,STEP:13,15,COBBLE_WALL:0,10,COBBLESTONE_STAIRS:0,10,STEP:3,10,COBBLE_WALL:1,20,COBBLESTONE_STAIRS:2,20,COBBLESTONE_STAIRS:3,20,MOSSY_COBBLESTONE:0,60,COBBLESTONE_STAIRS:1,20,STEP:11,20,COBBLESTONE:0,100)
RandomBlock(-5,1,2,SMOOTH_BRICK:0,40,SMOOTH_BRICK:1,30,SMOOTH_BRICK:2,30,SMOOTH_STAIRS:0,15,SMOOTH_STAIRS:1,15,SMOOTH_STAIRS:2,15,SMOOTH_STAIRS:3,15,STEP:5,15,STEP:13,15,COBBLE_WALL:0,10,COBBLESTONE_STAIRS:0,10,STEP:3,10,COBBLE_WALL:1,20,COBBLESTONE_STAIRS:2,20,COBBLESTONE_STAIRS:3,20,MOSSY_COBBLESTONE:0,60,COBBLESTONE_STAIRS:1,20,STEP:11,20,COBBLESTONE:0,100)
RandomBlock(-5,1,3,SMOOTH_BRICK:0,40,SMOOTH_BRICK:1,30,SMOOTH_BRICK:2,30,SMOOTH_STAIRS:0,15,SMOOTH_STAIRS:1,15,SMOOTH_STAIRS:2,15,SMOOTH_STAIRS:3,15,STEP:5,15,STEP:13,15,COBBLE_WALL:0,10,COBBLESTONE_STAIRS:0,10,STEP:3,10,COBBLE_WALL:1,20,COBBLESTONE_STAIRS:2,20,COBBLESTONE_STAIRS:3,20,MOSSY_COBBLESTONE:0,60,COBBLESTONE_STAIRS:1,20,STEP:11,20,COBBLESTONE:0,100)
RandomBlock(-5,1,4,SMOOTH_BRICK:0,40,SMOOTH_BRICK:1,30,SMOOTH_BRICK:2,30,SMOOTH_STAIRS:0,15,SMOOTH_STAIRS:1,15,SMOOTH_STAIRS:2,15,SMOOTH_STAIRS:3,15,STEP:5,15,STEP:13,15,COBBLE_WALL:0,10,COBBLESTONE_STAIRS:0,10,STEP:3,10,COBBLE_WALL:1,20,COBBLESTONE_STAIRS:2,20,COBBLESTONE_STAIRS:3,20,MOSSY_COBBLESTONE:0,60,COBBLESTONE_STAIRS:1,20,STEP:11,20,COBBLESTONE:0,100)
RandomBlock(-5,1,5,SMOOTH_BRICK:0,40,SMOOTH_BRICK:1,30,SMOOTH_BRICK:2,30,SMOOTH_STAIRS:0,15,SMOOTH_STAIRS:1,15,SMOOTH_STAIRS:2,15,SMOOTH_STAIRS:3,15,STEP:5,15,STEP:13,15,COBBLE_WALL:0,10,COBBLESTONE_STAIRS:0,10,STEP:3,10,COBBLE_WALL:1,20,COBBLESTONE_STAIRS:2,20,COBBLESTONE_STAIRS:3,20,MOSSY_COBBLESTONE:0,60,COBBLESTONE_STAIRS:1,20,STEP:11,20,COBBLESTONE:0,100)
RandomBlock(-5,1,6,SMOOTH_BRICK:0,40,SMOOTH_BRICK:1,30,SMOOTH_BRICK:2,30,SMOOTH_STAIRS:0,15,SMOOTH_STAIRS:1,15,SMOOTH_STAIRS:2,15,SMOOTH_STAIRS:3,15,STEP:5,15,STEP:13,15,COBBLE_WALL:0,10,COBBLESTONE_STAIRS:0,10,STEP:3,10,COBBLE_WALL:1,20,COBBLESTONE_STAIRS:2,20,COBBLESTONE_STAIRS:3,20,MOSSY_COBBLESTONE:0,60,COBBLESTONE_STAIRS:1,20,STEP:11,20,COBBLESTONE:0,100)
RandomBlock(-5,1,7,SMOOTH_BRICK:0,40,SMOOTH_BRICK:1,30,SMOOTH_BRICK:2,30,SMOOTH_STAIRS:0,15,SMOOTH_STAIRS:1,15,SMOOTH_STAIRS:2,15,SMOOTH_STAIRS:3,15,STEP:5,15,STEP:13,15,COBBLE_WALL:0,10,COBBLESTONE_STAIRS:0,10,STEP:3,10,COBBLE_WALL:1,20,COBBLESTONE_STAIRS:2,20,COBBLESTONE_STAIRS:3,20,MOSSY_COBBLESTONE:0,60,COBBLESTONE_STAIRS:1,20,STEP:11,20,COBBLESTONE:0,100)
RandomBlock(-5,1,8,SMOOTH_BRICK:0,40,SMOOTH_BRICK:1,30,SMOOTH_BRICK:2,30,SMOOTH_STAIRS:0,15,SMOOTH_STAIRS:1,15,SMOOTH_STAIRS:2,15,SMOOTH_STAIRS:3,15,STEP:5,15,STEP:13,15,COBBLE_WALL:0,10,COBBLESTONE_STAIRS:0,10,STEP:3,10,COBBLE_WALL:1,20,COBBLESTONE_STAIRS:2,20,COBBLESTONE_STAIRS:3,20,MOSSY_COBBLESTONE:0,60,COBBLESTONE_STAIRS:1,20,STEP:11,20,COBBLESTONE:0,100)
RandomBlock(-5,2,-4,SMOOTH_BRICK:0,40,SMOOTH_BRICK:1,30,SMOOTH_BRICK:2,30,SMOOTH_STAIRS:0,15,SMOOTH_STAIRS:1,15,SMOOTH_STAIRS:2,15,SMOOTH_STAIRS:3,15,STEP:5,15,STEP:13,15,COBBLE_WALL:0,10,COBBLESTONE_STAIRS:0,10,STEP:3,10,COBBLE_WALL:1,20,COBBLESTONE_STAIRS:2,20,COBBLESTONE_STAIRS:3,20,MOSSY_COBBLESTONE:0,60,COBBLESTONE_STAIRS:1,20,STEP:11,20,COBBLESTONE:0,100)
RandomBlock(-5,2,-3,SMOOTH_BRICK:0,40,SMOOTH_BRICK:1,30,SMOOTH_BRICK:2,30,SMOOTH_STAIRS:0,15,SMOOTH_STAIRS:1,15,SMOOTH_STAIRS:2,15,SMOOTH_STAIRS:3,15,STEP:5,15,STEP:13,15,COBBLE_WALL:0,10,COBBLESTONE_STAIRS:0,10,STEP:3,10,COBBLE_WALL:1,20,COBBLESTONE_STAIRS:2,20,COBBLESTONE_STAIRS:3,20,MOSSY_COBBLESTONE:0,60,COBBLESTONE_STAIRS:1,20,STEP:11,20,COBBLESTONE:0,100)
RandomBlock(-5,2,-2,SMOOTH_BRICK:0,40,SMOOTH_BRICK:1,30,SMOOTH_BRICK:2,30,SMOOTH_STAIRS:0,15,SMOOTH_STAIRS:1,15,SMOOTH_STAIRS:2,15,SMOOTH_STAIRS:3,15,STEP:5,15,STEP:13,15,COBBLE_WALL:0,10,COBBLESTONE_STAIRS:0,10,STEP:3,10,COBBLE_WALL:1,20,COBBLESTONE_STAIRS:2,20,COBBLESTONE_STAIRS:3,20,MOSSY_COBBLESTONE:0,60,COBBLESTONE_STAIRS:1,20,STEP:11,20,COBBLESTONE:0,100)
RandomBlock(-5,2,-1,SMOOTH_BRICK:0,40,SMOOTH_BRICK:1,30,SMOOTH_BRICK:2,30,SMOOTH_STAIRS:0,15,SMOOTH_STAIRS:1,15,SMOOTH_STAIRS:2,15,SMOOTH_STAIRS:3,15,STEP:5,15,STEP:13,15,COBBLE_WALL:0,10,COBBLESTONE_STAIRS:0,10,STEP:3,10,COBBLE_WALL:1,20,COBBLESTONE_STAIRS:2,20,COBBLESTONE_STAIRS:3,20,MOSSY_COBBLESTONE:0,60,COBBLESTONE_STAIRS:1,20,STEP:11,20,COBBLESTONE:0,100)
RandomBlock(-5,2,0,SMOOTH_BRICK:0,40,SMOOTH_BRICK:1,30,SMOOTH_BRICK:2,30,SMOOTH_STAIRS:0,15,SMOOTH_STAIRS:1,15,SMOOTH_STAIRS:2,15,SMOOTH_STAIRS:3,15,STEP:5,15,STEP:13,15,COBBLE_WALL:0,10,COBBLESTONE_STAIRS:0,10,STEP:3,10,COBBLE_WALL:1,20,COBBLESTONE_STAIRS:2,20,COBBLESTONE_STAIRS:3,20,MOSSY_COBBLESTONE:0,60,COBBLESTONE_STAIRS:1,20,STEP:11,20,COBBLESTONE:0,100)
RandomBlock(-5,2,1,SMOOTH_BRICK:0,40,SMOOTH_BRICK:1,30,SMOOTH_BRICK:2,30,SMOOTH_STAIRS:0,15,SMOOTH_STAIRS:1,15,SMOOTH_STAIRS:2,15,SMOOTH_STAIRS:3,15,STEP:5,15,STEP:13,15,COBBLE_WALL:0,10,COBBLESTONE_STAIRS:0,10,STEP:3,10,COBBLE_WALL:1,20,COBBLESTONE_STAIRS:2,20,COBBLESTONE_STAIRS:3,20,MOSSY_COBBLESTONE:0,60,COBBLESTONE_STAIRS:1,20,STEP:11,20,COBBLESTONE:0,100)
RandomBlock(-5,2,2,SMOOTH_BRICK:0,40,SMOOTH_BRICK:1,30,SMOOTH_BRICK:2,30,SMOOTH_STAIRS:0,15,SMOOTH_STAIRS:1,15,SMOOTH_STAIRS:2,15,SMOOTH_STAIRS:3,15,STEP:5,15,STEP:13,15,COBBLE_WALL:0,10,COBBLESTONE_STAIRS:0,10,STEP:3,10,COBBLE_WALL:1,20,COBBLESTONE_STAIRS:2,20,COBBLESTONE_STAIRS:3,20,MOSSY_COBBLESTONE:0,60,COBBLESTONE_STAIRS:1,20,STEP:11,20,COBBLESTONE:0,100)
RandomBlock(-5,2,3,SMOOTH_BRICK:0,40,SMOOTH_BRICK:1,30,SMOOTH_BRICK:2,30,SMOOTH_STAIRS:0,15,SMOOTH_STAIRS:1,15,SMOOTH_STAIRS:2,15,SMOOTH_STAIRS:3,15,STEP:5,15,STEP:13,15,COBBLE_WALL:0,10,COBBLESTONE_STAIRS:0,10,STEP:3,10,COBBLE_WALL:1,20,COBBLESTONE_STAIRS:2,20,COBBLESTONE_STAIRS:3,20,MOSSY_COBBLESTONE:0,60,COBBLESTONE_STAIRS:1,20,STEP:11,20,COBBLESTONE:0,100)
RandomBlock(-5,2,4,SMOOTH_BRICK:0,40,SMOOTH_BRICK:1,30,SMOOTH_BRICK:2,30,SMOOTH_STAIRS:0,15,SMOOTH_STAIRS:1,15,SMOOTH_STAIRS:2,15,SMOOTH_STAIRS:3,15,STEP:5,15,STEP:13,15,COBBLE_WALL:0,10,COBBLESTONE_STAIRS:0,10,STEP:3,10,COBBLE_WALL:1,20,COBBLESTONE_STAIRS:2,20,COBBLESTONE_STAIRS:3,20,MOSSY_COBBLESTONE:0,60,COBBLESTONE_STAIRS:1,20,STEP:11,20,COBBLESTONE:0,100)
RandomBlock(-5,2,5,SMOOTH_BRICK:0,40,SMOOTH_BRICK:1,30,SMOOTH_BRICK:2,30,SMOOTH_STAIRS:0,15,SMOOTH_STAIRS:1,15,SMOOTH_STAIRS:2,15,SMOOTH_STAIRS:3,15,STEP:5,15,STEP:13,15,COBBLE_WALL:0,10,COBBLESTONE_STAIRS:0,10,STEP:3,10,COBBLE_WALL:1,20,COBBLESTONE_STAIRS:2,20,COBBLESTONE_STAIRS:3,20,MOSSY_COBBLESTONE:0,60,COBBLESTONE_STAIRS:1,20,STEP:11,20,COBBLESTONE:0,100)
RandomBlock(-5,2,6,SMOOTH_BRICK:0,40,SMOOTH_BRICK:1,30,SMOOTH_BRICK:2,30,SMOOTH_STAIRS:0,15,SMOOTH_STAIRS:1,15,SMOOTH_STAIRS:2,15,SMOOTH_STAIRS:3,15,STEP:5,15,STEP:13,15,COBBLE_WALL:0,10,COBBLESTONE_STAIRS:0,10,STEP:3,10,COBBLE_WALL:1,20,COBBLESTONE_STAIRS:2,20,COBBLESTONE_STAIRS:3,20,MOSSY_COBBLESTONE:0,60,COBBLESTONE_STAIRS:1,20,STEP:11,20,COBBLESTONE:0,100)
RandomBlock(-5,2,7,SMOOTH_BRICK:0,40,SMOOTH_BRICK:1,30,SMOOTH_BRICK:2,30,SMOOTH_STAIRS:0,15,SMOOTH_STAIRS:1,15,SMOOTH_STAIRS:2,15,SMOOTH_STAIRS:3,15,STEP:5,15,STEP:13,15,COBBLE_WALL:0,10,COBBLESTONE_STAIRS:0,10,STEP:3,10,COBBLE_WALL:1,20,COBBLESTONE_STAIRS:2,20,COBBLESTONE_STAIRS:3,20,MOSSY_COBBLESTONE:0,60,COBBLESTONE_STAIRS:1,20,STEP:11,20,COBBLESTONE:0,100)
RandomBlock(-5,2,8,SMOOTH_BRICK:0,40,SMOOTH_BRICK:1,30,SMOOTH_BRICK:2,30,SMOOTH_STAIRS:0,15,SMOOTH_STAIRS:1,15,SMOOTH_STAIRS:2,15,SMOOTH_STAIRS:3,15,STEP:5,15,STEP:13,15,COBBLE_WALL:0,10,COBBLESTONE_STAIRS:0,10,STEP:3,10,COBBLE_WALL:1,20,COBBLESTONE_STAIRS:2,20,COBBLESTONE_STAIRS:3,20,MOSSY_COBBLESTONE:0,60,COBBLESTONE_STAIRS:1,20,STEP:11,20,COBBLESTONE:0,100)
RandomBlock(-5,3,-4,SMOOTH_BRICK:0,40,SMOOTH_BRICK:1,30,SMOOTH_BRICK:2,30,SMOOTH_STAIRS:0,15,SMOOTH_STAIRS:1,15,SMOOTH_STAIRS:2,15,SMOOTH_STAIRS:3,15,STEP:5,15,STEP:13,15,COBBLE_WALL:0,10,COBBLESTONE_STAIRS:0,10,STEP:3,10,COBBLE_WALL:1,20,COBBLESTONE_STAIRS:2,20,COBBLESTONE_STAIRS:3,20,MOSSY_COBBLESTONE:0,60,COBBLESTONE_STAIRS:1,20,STEP:11,20,COBBLESTONE:0,100)
RandomBlock(-5,3,-3,SMOOTH_BRICK:0,40,SMOOTH_BRICK:1,30,SMOOTH_BRICK:2,30,SMOOTH_STAIRS:0,15,SMOOTH_STAIRS:1,15,SMOOTH_STAIRS:2,15,SMOOTH_STAIRS:3,15,STEP:5,15,STEP:13,15,COBBLE_WALL:0,10,COBBLESTONE_STAIRS:0,10,STEP:3,10,COBBLE_WALL:1,20,COBBLESTONE_STAIRS:2,20,COBBLESTONE_STAIRS:3,20,MOSSY_COBBLESTONE:0,60,COBBLESTONE_STAIRS:1,20,STEP:11,20,COBBLESTONE:0,100)
