
#######################################################################
# +-----------------------------------------------------------------+ #
# |                            BO3 object                           | #
# +-----------------------------------------------------------------+ #
#######################################################################

Author: NLBlackEagle

Description: No description given

Version: 3

SettingsMode: WriteWithoutComments


#######################################################################
# +-----------------------------------------------------------------+ #
# |                          Main settings                          | #
# +-----------------------------------------------------------------+ #
#######################################################################

Tree: true

Frequency: 1

Rarity: 100.0

RotateRandomly: true

SpawnHeight: randomY

SpawnHeightOffset: 0

SpawnHeightVariance: 0

##############################
# Height Limits for the BO3. #
##############################

MinHeight: 60

MaxHeight: 70

######################
# Extrusion settings #
######################

ExtrudeMode: None

ExtrudeThroughBlocks: AIR

MaxBranchDepth: 10

ExcludedBiomes: All


#######################################################################
# +-----------------------------------------------------------------+ #
# |                      Source block settings                      | #
# +-----------------------------------------------------------------+ #
#######################################################################

SourceBlocks: AIR

MaxPercentageOutsideSourceBlock: 100

OutsideSourceBlock: placeAnyway

DoReplaceBlocks: true

IsOTGPlus: false


#######################################################################
# +-----------------------------------------------------------------+ #
# |                              Blocks                             | #
# +-----------------------------------------------------------------+ #
#######################################################################

Block(-3,0,0,quark:world_stone_carved:3)
Block(-3,1,0,lycanitesmobs:ashenstonepillar)
Block(-3,2,0,quark:world_stone_carved:3)
Block(-3,3,0,lycanitesmobs:ashenstone_stairs:0)
Block(-2,0,-1,srparasites:parasiterubbledense:1)
Block(-2,0,0,quark:basalt:1)
Block(-2,0,1,srparasites:parasiterubbledense:1)
Block(-2,1,-1,srparasites:infestedbush)
Block(-2,1,1,srparasites:infestedbush:3)
Block(-2,2,1,srparasites:infestedbush:3)
Block(-2,3,0,quark:world_stone_carved:3)
Block(-2,4,0,lycanitesmobs:ashenstone_stairs:0)
Block(-1,0,-2,srparasites:parasiterubbledense:1)
Block(-1,0,-1,srparasites:parasiterubbledense:1)
Block(-1,0,0,quark:world_stone_carved:3)
Block(-1,0,1,srparasites:parasiterubbledense:1)
Block(-1,0,2,srparasites:parasiterubbledense:1)
Block(-1,0,3,srparasites:parasiterubbledense:1)
Block(-1,1,-2,srparasites:tunnel)
Block(-1,1,-1,srparasites:infestedbush:3)
Block(-1,1,0,lycanitesmobs:ashenstonepillar)
Block(-1,1,2,srparasites:tunnel)
Block(-1,1,3,srparasites:infestedbush:2)
Block(-1,2,-1,srparasites:infestedbush:3)
Block(-1,2,0,lycanitesmobs:ashenstonepillar)
Block(-1,3,-1,srparasites:infestedbush:3)
Block(-1,3,0,lycanitesmobs:ashenstonepillar)
Block(-1,4,-1,srparasites:infestedbush:3)
Block(-1,4,0,lycanitesmobs:ashenstonepillar)
Block(-1,5,-1,srparasites:infestedbush:3)
Block(-1,5,0,lycanitesmobs:ashenstonepillar)
Block(-1,6,0,lycanitesmobs:ashenstonepillar)
Block(-1,7,0,quark:world_stone_carved:3)
Block(0,0,-3,srparasites:parasiterubbledense:1)
Block(0,0,-2,srparasites:parasiterubbledense:1)
Block(0,0,-1,srparasites:parasiterubbledense:1)
Block(0,0,0,quark:basalt:1)
Block(0,0,1,srparasites:parasiterubbledense:1)
Block(0,0,2,srparasites:parasiterubbledense:1)
Block(0,1,-3,srparasites:infestedbush:3)
Block(0,1,0,AIR:0)
Block(0,2,-3,srparasites:infestedbush:3)
Block(0,2,0,AIR:0)
Block(0,3,0,AIR:0)
Block(0,4,0,AIR:0)
Block(0,5,0,AIR:0)
Block(0,6,0,AIR:0)
Block(0,7,0,quark:basalt:1)
Block(1,0,-2,srparasites:parasiterubbledense:1)
Block(1,0,-1,srparasites:parasiterubbledense:1)
Block(1,0,0,quark:basalt:1)
Block(1,0,1,srparasites:parasiterubbledense:1)
Block(1,0,2,srparasites:parasiterubbledense:1)
Block(1,1,0,AIR:0)
Block(1,1,2,srparasites:tunnel)
Block(1,2,0,AIR:0)
Block(1,3,0,AIR:0)
Block(1,4,0,AIR:0)
Block(1,5,0,AIR:0)
Block(1,6,0,AIR:0)
Block(1,7,0,quark:basalt:1)
Block(2,0,-2,srparasites:parasiterubbledense:1)
Block(2,0,-1,srparasites:parasiterubbledense:1)
Block(2,0,0,quark:world_stone_carved:3)
Block(2,0,1,srparasites:parasiterubbledense:1)
Block(2,1,-2,srparasites:infestedbush:3)
Block(2,1,-1,srparasites:tunnel)
Block(2,1,0,lycanitesmobs:ashenstonepillar)
Block(2,1,1,srparasites:parasiterubbledense:1)
Block(2,2,0,lycanitesmobs:ashenstonepillar)
Block(2,2,1,srparasites:infestedbush:3)
Block(2,3,0,lycanitesmobs:ashenstonepillar)
Block(2,3,1,srparasites:infestedbush:3)
Block(2,4,0,lycanitesmobs:ashenstonepillar)
Block(2,4,1,srparasites:infestedbush:3)
Block(2,5,0,lycanitesmobs:ashenstonepillar)
Block(2,5,1,srparasites:infestedbush:3)
Block(2,6,0,lycanitesmobs:ashenstonepillar)
Block(2,7,0,quark:world_stone_carved:3)
Block(3,0,-1,srparasites:parasiterubbledense:1)
Block(3,0,0,quark:basalt:1)
Block(3,0,1,srparasites:parasiterubbledense:1)
Block(3,1,-1,srparasites:infestedbush:3)
Block(3,4,0,quark:world_stone_carved:3)
Block(3,5,0,lycanitesmobs:ashenstone_stairs:1)
Block(4,0,0,quark:world_stone_carved:3)
Block(4,1,0,lycanitesmobs:ashenstonepillar)
Block(4,2,0,lycanitesmobs:ashenstonepillar)
Block(4,3,0,quark:world_stone_carved:3)
Block(4,4,0,lycanitesmobs:ashenstone_stairs:1)

#######################################################################
# +-----------------------------------------------------------------+ #
# |                            BO3 checks                           | #
# +-----------------------------------------------------------------+ #
#######################################################################

BlockCheck(0,0,0,AIR)
BlockCheck(-2,-1,-1,Solid)
BlockCheck(-2,-1,1,Solid)
BlockCheck(-1,-1,-2,Solid)
BlockCheck(-1,-1,3,Solid)
BlockCheck(0,-1,-3,Solid)
BlockCheck(1,-1,2,Solid)
BlockCheck(2,-1,-2,Solid)
BlockCheck(3,-1,1,Solid)
BlockCheck(4,-1,0,Solid)

#######################################################################
# +-----------------------------------------------------------------+ #
# |                             Branches                            | #
# +-----------------------------------------------------------------+ #
#######################################################################


#######################################################################
# +-----------------------------------------------------------------+ #
# |                             Entities                            | #
# +-----------------------------------------------------------------+ #
#######################################################################


#######################################################################
# +-----------------------------------------------------------------+ #
# |                            Particles                            | #
# +-----------------------------------------------------------------+ #
#######################################################################


#######################################################################
# +-----------------------------------------------------------------+ #
# |                             Spawners                            | #
# +-----------------------------------------------------------------+ #
#######################################################################


#######################################################################
# +-----------------------------------------------------------------+ #
# |                             ModData                             | #
# +-----------------------------------------------------------------+ #
#######################################################################

