
#######################################################################
# +-----------------------------------------------------------------+ #
# |                            BO4 object                           | #
# +-----------------------------------------------------------------+ #
#######################################################################

Author: NLBlackEagle

Description: No description given

SettingsMode: WriteDisable


#######################################################################
# +-----------------------------------------------------------------+ #
# |                          Main settings                          | #
# +-----------------------------------------------------------------+ #
#######################################################################

Frequency: 0

SpawnHeight: highestBlock

UseCenterForHighestBlock: true

##############################
# Height Limits for the BO4. #
##############################

MinHeight: 0

MaxHeight: 255

InheritBO3: 

InheritBO3Rotation: NORTH

OverrideChildSettings: true

OverrideParentHeight: false

CanOverride: true

BranchFrequency: 0

BranchFrequencyGroup: 

MustBeBelowOther: false

MustBeInside: 

CannotBeInside: 

ReplacesBO3: L4-M-CrossC0R0, L4-M-CrossC0R1, L4-M-CrossC0R2, L4-M-CrossC0R3, L4-M-CrossC1R0, L4-M-CrossC1R1, L4-M-CrossC1R2, L4-M-CrossC1R3, L4-M-CrossC2R0, L4-M-CrossC2R1, L4-M-CrossC2R2, L4-M-CrossC2R3, L4-M-CrossC3R0, L4-M-CrossC3R1, L4-M-CrossC3R2, L4-M-CrossC3R3, L4-M-Straigth-START_01-C0R0, L4-M-Straigth-START_01-C0R1, L4-M-Straigth-START_01-C1R0, L4-M-Straigth-START_01-C1R1, L4-M-Straigth-START_01-C2R0, L4-M-Straigth-START_01-C2R1, L4-M-Straigth-START_01-C3R0, L4-M-Straigth-START_01-C3R1, L4-M-Straigth-3CC0R0, L4-M-Straigth-3CC0R1, L4-M-Straigth-3CC0R2, L4-M-Straigth-3CC1R0, L4-M-Straigth-3CC1R1, L4-M-Straigth-3CC1R2, L4-M-Straigth-3CC2R0, L4-M-Straigth-3CC2R1, L4-M-Straigth-3CC2R2, L4-M-Straigth-3CC3R0, L4-M-Straigth-3CC3R1, L4-M-Straigth-3CC3R2, L4-M-Cross, skyscraper_2x2_01, skyscraper_2x2_02, skyscraper_2x2_03, skyscraper_2x2_04, skyscraper_2x2_05, skyscraper_3x3_01, skyscraper_3x3_02, skyscraper_3x3_03, L3-M-Straigth-2CC0R0, L3-M-Straigth-2CC0R1, L3-M-Straigth-2CC1R0, L3-M-Straigth-2CC1R1, L3-M-Straigth-2CC2R0, L3-M-Straigth-2CC2R1, L3-M-Straigth-2CC3R0, L3-M-Straigth-2CC3R1, L3-M-Straigth-3CC0R0, L3-M-Straigth-3CC0R1, L3-M-Straigth-3CC0R2, L3-M-Straigth-3CC1R0, L3-M-Straigth-3CC1R1, L3-M-Straigth-3CC1R2, L3-M-Straigth-3CC2R0, L3-M-Straigth-3CC2R1, L3-M-Straigth-3CC2R2, L3-M-Straigth-3CC3R0, L3-M-Straigth-3CC3R1, L3-M-Straigth-3CC3R2L4-M-CrossC0R0, L4-M-CrossC0R1, L4-M-CrossC0R2, L4-M-CrossC0R3, L4-M-CrossC1R0, L4-M-CrossC1R1, L4-M-CrossC1R2, L4-M-CrossC1R3, L4-M-CrossC2R0, L4-M-CrossC2R1, L4-M-CrossC2R2, L4-M-CrossC2R3, L4-M-CrossC3R0, L4-M-CrossC3R1, L4-M-CrossC3R2, L4-M-CrossC3R3, L4-M-Straigth-START_01-C0R0, L4-M-Straigth-START_01-C0R1, L4-M-Straigth-START_01-C1R0, L4-M-Straigth-START_01-C1R1, L4-M-Straigth-START_01-C2R0, L4-M-Straigth-START_01-C2R1, L4-M-Straigth-START_01-C3R0, L4-M-Straigth-START_01-C3R1, L4-M-Straigth-3CC0R0, L4-M-Straigth-3CC0R1, L4-M-Straigth-3CC0R2, L4-M-Straigth-3CC1R0, L4-M-Straigth-3CC1R1, L4-M-Straigth-3CC1R2, L4-M-Straigth-3CC2R0, L4-M-Straigth-3CC2R1, L4-M-Straigth-3CC2R2, L4-M-Straigth-3CC3R0, L4-M-Straigth-3CC3R1, L4-M-Straigth-3CC3R2, L4-M-Cross, skyscraper_2x2_01, skyscraper_2x2_02, skyscraper_2x2_03, skyscraper_2x2_04, skyscraper_2x2_05, skyscraper_3x3_01, skyscraper_3x3_02, skyscraper_3x3_03

MustBeInsideWorldBorders: false

CanSpawnOnWater: true

SpawnOnWaterOnly: false

SpawnUnderWater: false

SpawnAtWaterLevel: false

HeightOffset: 0

RemoveAir: false

ReplaceAbove: 

ReplaceBelow: 

ReplaceWithBiomeBlocks: true

ReplaceWithSurfaceBlock: GRASS

ReplaceWithGroundBlock: DIRT

ReplaceWithStoneBlock: STONE

SmoothRadius: 0

SmoothHeightOffset: 0

SmoothStartTop: false

SmoothStartWood: false

SmoothingSurfaceBlock: 

SmoothingGroundBlock: 

BO3Group: 

IsSpawnPoint: false

DoReplaceBlocks: true


#######################################################################
# +-----------------------------------------------------------------+ #
# |                              Blocks                             | #
# +-----------------------------------------------------------------+ #
#######################################################################

Block(-8,0,-7,CONCRETE:7)
Block(-8,0,-6,CONCRETE:7)
Block(-8,0,-5,CONCRETE:7)
Block(-8,0,-4,CONCRETE:7)
Block(-8,0,-3,CONCRETE:7)
Block(-8,0,-2,CONCRETE:7)
Block(-8,0,-1,CONCRETE:7)
Block(-8,0,0,CONCRETE:7)
Block(-8,0,1,CONCRETE:7)
Block(-8,0,2,CONCRETE:7)
Block(-8,0,3,CONCRETE:7)
Block(-8,0,4,CONCRETE:7)
Block(-8,0,5,CONCRETE:7)
Block(-8,0,6,CONCRETE:7)
Block(-8,0,7,CONCRETE:7)
Block(-8,0,8,CONCRETE:7)
Block(-8,1,-7,CONCRETE:7)
Block(-8,1,-6,CONCRETE:7)
Block(-8,1,-5,CONCRETE:7)
Block(-8,1,-4,CONCRETE:7)
Block(-8,1,-3,CONCRETE:7)
Block(-8,1,-2,CONCRETE:7)
Block(-8,1,-1,CONCRETE:7)
Block(-8,1,0,CONCRETE:7)
Block(-8,1,1,CONCRETE:7)
Block(-8,1,2,CONCRETE:7)
Block(-8,1,3,CONCRETE:7)
Block(-8,1,4,CONCRETE:7)
Block(-8,1,5,CONCRETE:7)
Block(-8,1,6,CONCRETE:7)
Block(-8,1,7,CONCRETE:7)
Block(-8,1,8,CONCRETE:7)
Block(-8,2,-7,CONCRETE:7)
Block(-8,2,-6,CONCRETE:7)
Block(-8,2,-5,CONCRETE:7)
Block(-8,2,-4,CONCRETE:7)
Block(-8,2,-3,CONCRETE:7)
Block(-8,2,-2,CONCRETE:7)
Block(-8,2,-1,CONCRETE:7)
Block(-8,2,0,CONCRETE:7)
Block(-8,2,1,CONCRETE:7)
Block(-8,2,2,CONCRETE:7)
Block(-8,2,3,CONCRETE:7)
Block(-8,2,4,CONCRETE:7)
Block(-8,2,5,CONCRETE:7)
Block(-8,2,6,CONCRETE:7)
Block(-8,2,7,CONCRETE:7)
Block(-8,2,8,CONCRETE:7)
Block(-8,3,-7,CONCRETE:7)
Block(-8,3,-6,CONCRETE:7)
Block(-8,3,-5,CONCRETE:7)
Block(-8,3,-4,CONCRETE:7)
Block(-8,3,-3,CONCRETE:7)
Block(-8,3,-2,CONCRETE:7)
Block(-8,3,-1,CONCRETE:7)
Block(-8,3,0,CONCRETE:7)
Block(-8,3,1,CONCRETE:7)
Block(-8,3,2,CONCRETE:7)
Block(-8,3,3,CONCRETE:7)
Block(-8,3,4,CONCRETE:7)
Block(-8,3,5,CONCRETE:7)
Block(-8,3,6,CONCRETE:7)
Block(-8,3,7,CONCRETE:7)
Block(-8,3,8,CONCRETE:7)
Block(-8,4,-7,CONCRETE:7)
Block(-8,4,-6,CONCRETE:7)
Block(-8,4,-5,CONCRETE:7)
Block(-8,4,-4,CONCRETE:7)
Block(-8,4,-3,CONCRETE:7)
Block(-8,4,-2,CONCRETE:7)
Block(-8,4,-1,CONCRETE:7)
Block(-8,4,0,CONCRETE:7)
Block(-8,4,1,CONCRETE:7)
Block(-8,4,2,CONCRETE:7)
Block(-8,4,3,CONCRETE:7)
Block(-8,4,4,CONCRETE:7)
Block(-8,4,5,CONCRETE:7)
Block(-8,4,6,CONCRETE:7)
Block(-8,4,7,CONCRETE:7)
Block(-8,4,8,CONCRETE:7)
Block(-8,5,-7,CONCRETE:7)
Block(-8,5,-6,CONCRETE:7)
Block(-8,5,-5,CONCRETE:7)
Block(-8,5,-4,CONCRETE:7)
Block(-8,5,-3,CONCRETE:7)
Block(-8,5,-2,CONCRETE:7)
Block(-8,5,-1,CONCRETE:7)
Block(-8,5,0,CONCRETE:7)
Block(-8,5,1,CONCRETE:7)
Block(-8,5,2,CONCRETE:7)
Block(-8,5,3,CONCRETE:7)
Block(-8,5,4,CONCRETE:7)
Block(-8,5,5,CONCRETE:7)
Block(-8,5,6,CONCRETE:7)
Block(-8,5,7,CONCRETE:7)
Block(-8,5,8,CONCRETE:7)
Block(-8,6,-7,CONCRETE:7)
Block(-8,6,-6,CONCRETE:7)
Block(-8,6,-5,CONCRETE:7)
Block(-8,6,-4,CONCRETE:7)
Block(-8,6,-3,CONCRETE:7)
Block(-8,6,-2,CONCRETE:7)
Block(-8,6,-1,CONCRETE:7)
Block(-8,6,0,CONCRETE:7)
Block(-8,6,1,CONCRETE:7)
Block(-8,6,2,CONCRETE:7)
Block(-8,6,3,CONCRETE:7)
Block(-8,6,4,CONCRETE:7)
Block(-8,6,5,CONCRETE:7)
Block(-8,6,6,CONCRETE:7)
Block(-8,6,7,CONCRETE:7)
Block(-8,6,8,CONCRETE:7)
Block(-8,7,-7,CONCRETE:7)
Block(-8,7,-6,CONCRETE:7)
Block(-8,7,-5,CONCRETE:7)
Block(-8,7,-4,CONCRETE:7)
Block(-8,7,-3,CONCRETE:7)
Block(-8,7,-2,CONCRETE:7)
Block(-8,7,-1,CONCRETE:7)
Block(-8,7,0,CONCRETE:7)
Block(-8,7,1,CONCRETE:7)
Block(-8,7,2,CONCRETE:7)
Block(-8,7,3,CONCRETE:7)
Block(-8,7,4,CONCRETE:7)
Block(-8,7,5,CONCRETE:7)
Block(-8,7,6,CONCRETE:7)
Block(-8,7,7,CONCRETE:7)
Block(-8,7,8,CONCRETE:7)
Block(-8,8,-7,CONCRETE:7)
Block(-8,8,-6,CONCRETE:7)
Block(-8,8,-5,CONCRETE:7)
Block(-8,8,-4,CONCRETE:7)
Block(-8,8,-3,CONCRETE:7)
Block(-8,8,-2,CONCRETE:7)
Block(-8,8,-1,CONCRETE:7)
Block(-8,8,0,CONCRETE:7)
Block(-8,8,1,CONCRETE:7)
Block(-8,8,2,CONCRETE:7)
Block(-8,8,3,CONCRETE:7)
Block(-8,8,4,CONCRETE:7)
Block(-8,8,5,CONCRETE:7)
Block(-8,8,6,CONCRETE:7)
Block(-8,8,7,CONCRETE:7)
Block(-8,8,8,CONCRETE:7)
Block(-8,9,-7,CONCRETE:7)
Block(-8,9,-6,CONCRETE:7)
Block(-8,9,-5,CONCRETE:7)
Block(-8,9,-4,CONCRETE:7)
Block(-8,9,-3,CONCRETE:7)
Block(-8,9,-2,CONCRETE:7)
Block(-8,9,-1,CONCRETE:7)
Block(-8,9,0,CONCRETE:7)
Block(-8,9,1,CONCRETE:7)
Block(-8,9,2,CONCRETE:7)
Block(-8,9,3,CONCRETE:7)
Block(-8,9,4,CONCRETE:7)
Block(-8,9,5,CONCRETE:7)
Block(-8,9,6,CONCRETE:7)
Block(-8,9,7,CONCRETE:7)
Block(-8,9,8,CONCRETE:7)
Block(-8,10,-7,CONCRETE:7)
Block(-8,10,-6,CONCRETE:7)
Block(-8,10,-5,CONCRETE:7)
Block(-8,10,-4,CONCRETE:7)
Block(-8,10,-3,CONCRETE:7)
Block(-8,10,-2,CONCRETE:7)
Block(-8,10,-1,CONCRETE:7)
Block(-8,10,0,CONCRETE:7)
Block(-8,10,1,CONCRETE:7)
Block(-8,10,2,CONCRETE:7)
Block(-8,10,3,CONCRETE:7)
Block(-8,10,4,CONCRETE:7)
Block(-8,10,5,CONCRETE:7)
Block(-8,10,6,CONCRETE:7)
Block(-8,10,7,CONCRETE:7)
Block(-8,10,8,CONCRETE:7)
Block(-8,11,-7,CONCRETE:7)
Block(-8,11,-6,CONCRETE:7)
Block(-8,11,-5,CONCRETE:7)
Block(-8,11,-4,CONCRETE:7)
Block(-8,11,-3,CONCRETE:7)
Block(-8,11,-2,CONCRETE:7)
Block(-8,11,-1,CONCRETE:7)
Block(-8,11,0,CONCRETE:7)
Block(-8,11,1,CONCRETE:7)
Block(-8,11,2,CONCRETE:7)
Block(-8,11,3,CONCRETE:7)
Block(-8,11,4,CONCRETE:7)
Block(-8,11,5,CONCRETE:7)
Block(-8,11,6,CONCRETE:7)
Block(-8,11,7,CONCRETE:7)
Block(-8,11,8,CONCRETE:7)
Block(-8,12,-7,CONCRETE:7)
Block(-8,12,-6,CONCRETE:7)
Block(-8,12,-5,CONCRETE:7)
Block(-8,12,-4,CONCRETE:7)
Block(-8,12,-3,CONCRETE:7)
Block(-8,12,-2,CONCRETE:7)
Block(-8,12,-1,CONCRETE:7)
Block(-8,12,0,CONCRETE:7)
Block(-8,12,1,CONCRETE:7)
Block(-8,12,2,CONCRETE:7)
Block(-8,12,3,CONCRETE:7)
Block(-8,12,4,CONCRETE:7)
Block(-8,12,5,CONCRETE:7)
Block(-8,12,6,CONCRETE:7)
Block(-8,12,7,CONCRETE:7)
Block(-8,12,8,CONCRETE:7)
Block(-8,13,-7,CONCRETE:7)
Block(-8,13,-6,CONCRETE:7)
Block(-8,13,-5,CONCRETE:7)
Block(-8,13,-4,CONCRETE:7)
Block(-8,13,-3,CONCRETE:7)
Block(-8,13,-2,CONCRETE:7)
Block(-8,13,-1,CONCRETE:7)
Block(-8,13,0,CONCRETE:7)
Block(-8,13,1,CONCRETE:7)
Block(-8,13,2,CONCRETE:7)
Block(-8,13,3,CONCRETE:7)
Block(-8,13,4,CONCRETE:7)
Block(-8,13,5,CONCRETE:7)
Block(-8,13,6,CONCRETE:7)
Block(-8,13,7,CONCRETE:7)
Block(-8,13,8,CONCRETE:7)
Block(-8,14,-7,CONCRETE:7)
Block(-8,14,-6,CONCRETE:7)
Block(-8,14,-5,CONCRETE:7)
Block(-8,14,-4,CONCRETE:7)
Block(-8,14,-3,CONCRETE:7)
Block(-8,14,-2,CONCRETE:7)
Block(-8,14,-1,CONCRETE:7)
Block(-8,14,0,CONCRETE:7)
Block(-8,14,1,CONCRETE:7)
Block(-8,14,2,CONCRETE:7)
Block(-8,14,3,CONCRETE:7)
Block(-8,14,4,CONCRETE:7)
Block(-8,14,5,CONCRETE:7)
Block(-8,14,6,CONCRETE:7)
Block(-8,14,7,CONCRETE:7)
Block(-8,14,8,CONCRETE:7)
Block(-8,15,-7,CONCRETE:7)
Block(-8,15,-6,CONCRETE:7)
Block(-8,15,-5,CONCRETE:7)
Block(-8,15,-4,CONCRETE:7)
Block(-8,15,-3,CONCRETE:7)
Block(-8,15,-2,CONCRETE:7)
Block(-8,15,-1,CONCRETE:7)
Block(-8,15,0,CONCRETE:7)
Block(-8,15,1,CONCRETE:7)
Block(-8,15,2,CONCRETE:7)
Block(-8,15,3,CONCRETE:7)
Block(-8,15,4,CONCRETE:7)
Block(-8,15,5,CONCRETE:7)
Block(-8,15,6,CONCRETE:7)
Block(-8,15,7,CONCRETE:7)
Block(-8,15,8,CONCRETE:7)
Block(-8,16,-7,CONCRETE:7)
Block(-8,16,-6,CONCRETE:7)
Block(-8,16,-5,CONCRETE:7)
Block(-8,16,-4,CONCRETE:7)
Block(-8,16,-3,CONCRETE:7)
Block(-8,16,-2,CONCRETE:7)
Block(-8,16,-1,CONCRETE:7)
Block(-8,16,0,CONCRETE:7)
Block(-8,16,1,CONCRETE:7)
Block(-8,16,2,CONCRETE:7)
Block(-8,16,3,CONCRETE:7)
Block(-8,16,4,CONCRETE:7)
Block(-8,16,5,CONCRETE:7)
Block(-8,16,6,CONCRETE:7)
Block(-8,16,7,CONCRETE:7)
Block(-8,16,8,CONCRETE:7)
Block(-8,17,-7,DOUBLE_STEP:0)
Block(-8,17,-6,DOUBLE_STEP:0)
Block(-8,17,-5,DOUBLE_STEP:0)
Block(-8,17,-4,DOUBLE_STEP:0)
Block(-8,17,-3,DOUBLE_STEP:0)
Block(-8,17,-2,DOUBLE_STEP:0)
Block(-8,17,-1,DOUBLE_STEP:0)
Block(-8,17,0,DOUBLE_STEP:0)
Block(-8,17,1,DOUBLE_STEP:0)
Block(-8,17,2,DOUBLE_STEP:0)
Block(-8,17,3,DOUBLE_STEP:0)
Block(-8,17,4,DOUBLE_STEP:0)
Block(-8,17,5,DOUBLE_STEP:0)
Block(-8,17,6,DOUBLE_STEP:0)
Block(-8,17,7,DOUBLE_STEP:0)
Block(-8,17,8,DOUBLE_STEP:0)
Block(-8,21,2,SMOOTH_STAIRS:6)
Block(-8,21,3,SMOOTH_STAIRS:4)
Block(-8,21,4,SMOOTH_STAIRS:4)
Block(-8,21,5,SMOOTH_STAIRS:4)
Block(-8,21,6,SMOOTH_STAIRS:4)
Block(-8,21,7,SMOOTH_STAIRS:7)
Block(-8,22,2,IRON_FENCE:0)
Block(-8,22,3,IRON_FENCE:0)
Block(-8,22,4,IRON_FENCE:0)
Block(-8,22,5,IRON_FENCE:0)
Block(-8,22,6,IRON_FENCE:0)
Block(-8,22,7,IRON_FENCE:0)
Block(-8,25,2,SMOOTH_STAIRS:6)
Block(-8,25,3,SMOOTH_STAIRS:4)
Block(-8,25,4,SMOOTH_STAIRS:4)
Block(-8,25,5,SMOOTH_STAIRS:4)
Block(-8,25,6,SMOOTH_STAIRS:4)
Block(-8,25,7,SMOOTH_STAIRS:7)
Block(-8,26,2,IRON_FENCE:0)
Block(-8,26,3,IRON_FENCE:0)
Block(-8,26,4,IRON_FENCE:0)
Block(-8,26,5,IRON_FENCE:0)
Block(-8,26,6,IRON_FENCE:0)
Block(-8,26,7,IRON_FENCE:0)
Block(-8,29,2,SMOOTH_STAIRS:6)
Block(-8,29,3,SMOOTH_STAIRS:4)
Block(-8,29,4,SMOOTH_STAIRS:4)
Block(-8,29,5,SMOOTH_STAIRS:4)
Block(-8,29,6,SMOOTH_STAIRS:4)
Block(-8,29,7,SMOOTH_STAIRS:7)
Block(-8,30,2,IRON_FENCE:0)
Block(-8,30,3,IRON_FENCE:0)
Block(-8,30,4,IRON_FENCE:0)
Block(-8,30,5,IRON_FENCE:0)
Block(-8,30,6,IRON_FENCE:0)
Block(-8,30,7,IRON_FENCE:0)
Block(-8,33,2,SMOOTH_STAIRS:6)
Block(-8,33,3,SMOOTH_STAIRS:4)
Block(-8,33,4,SMOOTH_STAIRS:4)
Block(-8,33,5,SMOOTH_STAIRS:4)
Block(-8,33,6,SMOOTH_STAIRS:4)
Block(-8,33,7,SMOOTH_STAIRS:7)
Block(-8,34,2,IRON_FENCE:0)
Block(-8,34,3,IRON_FENCE:0)
Block(-8,34,4,IRON_FENCE:0)
Block(-8,34,5,IRON_FENCE:0)
Block(-8,34,6,IRON_FENCE:0)
Block(-8,34,7,IRON_FENCE:0)
Block(-8,37,2,SMOOTH_STAIRS:6)
Block(-8,37,3,SMOOTH_STAIRS:4)
Block(-8,37,4,SMOOTH_STAIRS:4)
Block(-8,37,5,SMOOTH_STAIRS:4)
Block(-8,37,6,SMOOTH_STAIRS:4)
Block(-8,37,7,SMOOTH_STAIRS:7)
Block(-8,38,2,IRON_FENCE:0)
Block(-8,38,3,IRON_FENCE:0)
Block(-8,38,4,IRON_FENCE:0)
Block(-8,38,5,IRON_FENCE:0)
Block(-8,38,6,IRON_FENCE:0)
Block(-8,38,7,IRON_FENCE:0)
Block(-8,41,2,SMOOTH_STAIRS:6)
Block(-8,41,3,SMOOTH_STAIRS:4)
Block(-8,41,4,SMOOTH_STAIRS:4)
Block(-8,41,5,SMOOTH_STAIRS:4)
Block(-8,41,6,SMOOTH_STAIRS:4)
Block(-8,41,7,SMOOTH_STAIRS:7)
Block(-8,42,2,IRON_FENCE:0)
Block(-8,42,3,IRON_FENCE:0)
Block(-8,42,4,IRON_FENCE:0)
Block(-8,42,5,IRON_FENCE:0)
Block(-8,42,6,IRON_FENCE:0)
Block(-8,42,7,IRON_FENCE:0)
Block(-8,45,2,SMOOTH_STAIRS:6)
Block(-8,45,3,SMOOTH_STAIRS:4)
Block(-8,45,4,SMOOTH_STAIRS:4)
Block(-8,45,5,SMOOTH_STAIRS:4)
Block(-8,45,6,SMOOTH_STAIRS:4)
Block(-8,45,7,SMOOTH_STAIRS:7)
Block(-8,46,2,IRON_FENCE:0)
Block(-8,46,3,IRON_FENCE:0)
Block(-8,46,4,IRON_FENCE:0)
Block(-8,46,5,IRON_FENCE:0)
Block(-8,46,6,IRON_FENCE:0)
Block(-8,46,7,IRON_FENCE:0)
Block(-8,49,2,SMOOTH_STAIRS:6)
Block(-8,49,3,SMOOTH_STAIRS:4)
Block(-8,49,4,SMOOTH_STAIRS:4)
Block(-8,49,5,SMOOTH_STAIRS:4)
Block(-8,49,6,SMOOTH_STAIRS:4)
Block(-8,49,7,SMOOTH_STAIRS:7)
Block(-8,50,2,IRON_FENCE:0)
Block(-8,50,3,IRON_FENCE:0)
Block(-8,50,4,IRON_FENCE:0)
Block(-8,50,5,IRON_FENCE:0)
Block(-8,50,6,IRON_FENCE:0)
Block(-8,50,7,IRON_FENCE:0)
Block(-8,53,2,SMOOTH_STAIRS:6)
Block(-8,53,3,SMOOTH_STAIRS:4)
Block(-8,53,4,SMOOTH_STAIRS:4)
Block(-8,53,5,SMOOTH_STAIRS:4)
Block(-8,53,6,SMOOTH_STAIRS:4)
Block(-8,53,7,SMOOTH_STAIRS:7)
Block(-8,54,2,IRON_FENCE:0)
Block(-8,54,3,IRON_FENCE:0)
Block(-8,54,4,IRON_FENCE:0)
Block(-8,54,5,IRON_FENCE:0)
Block(-8,54,6,IRON_FENCE:0)
Block(-8,54,7,IRON_FENCE:0)
Block(-8,57,2,SMOOTH_STAIRS:6)
Block(-8,57,3,SMOOTH_STAIRS:4)
Block(-8,57,4,SMOOTH_STAIRS:4)
Block(-8,57,5,SMOOTH_STAIRS:4)
Block(-8,57,6,SMOOTH_STAIRS:4)
Block(-8,57,7,SMOOTH_STAIRS:7)
Block(-8,58,2,IRON_FENCE:0)
Block(-8,58,3,IRON_FENCE:0)
Block(-8,58,4,IRON_FENCE:0)
Block(-8,58,5,IRON_FENCE:0)
Block(-8,58,6,IRON_FENCE:0)
Block(-8,58,7,IRON_FENCE:0)
Block(-8,61,2,SMOOTH_STAIRS:6)
Block(-8,61,3,SMOOTH_STAIRS:4)
Block(-8,61,4,SMOOTH_STAIRS:4)
Block(-8,61,5,SMOOTH_STAIRS:4)
Block(-8,61,6,SMOOTH_STAIRS:4)
Block(-8,61,7,SMOOTH_STAIRS:7)
Block(-8,62,2,IRON_FENCE:0)
Block(-8,62,3,IRON_FENCE:0)
Block(-8,62,4,IRON_FENCE:0)
Block(-8,62,5,IRON_FENCE:0)
Block(-8,62,6,IRON_FENCE:0)
Block(-8,62,7,IRON_FENCE:0)
Block(-8,65,2,SMOOTH_STAIRS:6)
Block(-8,65,3,SMOOTH_STAIRS:4)
Block(-8,65,4,SMOOTH_STAIRS:4)
Block(-8,65,5,SMOOTH_STAIRS:4)
Block(-8,65,6,SMOOTH_STAIRS:4)
Block(-8,65,7,SMOOTH_STAIRS:7)
Block(-8,66,2,IRON_FENCE:0)
Block(-8,66,3,IRON_FENCE:0)
Block(-8,66,4,IRON_FENCE:0)
Block(-8,66,5,IRON_FENCE:0)
Block(-8,66,6,IRON_FENCE:0)
Block(-8,66,7,IRON_FENCE:0)
Block(-8,69,2,SMOOTH_STAIRS:6)
Block(-8,69,3,SMOOTH_STAIRS:4)
Block(-8,69,4,SMOOTH_STAIRS:4)
Block(-8,69,5,SMOOTH_STAIRS:4)
Block(-8,69,6,SMOOTH_STAIRS:4)
Block(-8,69,7,SMOOTH_STAIRS:7)
Block(-8,70,2,IRON_FENCE:0)
Block(-8,70,3,IRON_FENCE:0)
Block(-8,70,4,IRON_FENCE:0)
Block(-8,70,5,IRON_FENCE:0)
Block(-8,70,6,IRON_FENCE:0)
Block(-8,70,7,IRON_FENCE:0)
Block(-8,73,2,SMOOTH_STAIRS:6)
Block(-8,73,3,SMOOTH_STAIRS:4)
Block(-8,73,4,SMOOTH_STAIRS:4)
Block(-8,73,5,SMOOTH_STAIRS:4)
Block(-8,73,6,SMOOTH_STAIRS:4)
Block(-8,73,7,SMOOTH_STAIRS:7)
Block(-8,74,2,IRON_FENCE:0)
Block(-8,74,3,IRON_FENCE:0)
Block(-8,74,4,IRON_FENCE:0)
Block(-8,74,5,IRON_FENCE:0)
Block(-8,74,6,IRON_FENCE:0)
Block(-8,74,7,IRON_FENCE:0)
Block(-8,77,2,SMOOTH_STAIRS:6)
Block(-8,77,3,SMOOTH_STAIRS:4)
Block(-8,77,4,SMOOTH_STAIRS:4)
Block(-8,77,5,SMOOTH_STAIRS:4)
Block(-8,77,6,SMOOTH_STAIRS:4)
Block(-8,77,7,SMOOTH_STAIRS:7)
Block(-8,78,2,IRON_FENCE:0)
Block(-8,78,3,IRON_FENCE:0)
Block(-8,78,4,IRON_FENCE:0)
Block(-8,78,5,IRON_FENCE:0)
Block(-8,78,6,IRON_FENCE:0)
Block(-8,78,7,IRON_FENCE:0)
Block(-8,81,2,SMOOTH_STAIRS:6)
Block(-8,81,3,SMOOTH_STAIRS:4)
Block(-8,81,4,SMOOTH_STAIRS:4)
Block(-8,81,5,SMOOTH_STAIRS:4)
Block(-8,81,6,SMOOTH_STAIRS:4)
Block(-8,81,7,SMOOTH_STAIRS:7)
Block(-8,82,2,IRON_FENCE:0)
Block(-8,82,3,IRON_FENCE:0)
Block(-8,82,4,IRON_FENCE:0)
Block(-8,82,5,IRON_FENCE:0)
Block(-8,82,6,IRON_FENCE:0)
Block(-8,82,7,IRON_FENCE:0)
Block(-8,85,2,SMOOTH_STAIRS:6)
Block(-8,85,3,SMOOTH_STAIRS:4)
Block(-8,85,4,SMOOTH_STAIRS:4)
Block(-8,85,5,SMOOTH_STAIRS:4)
Block(-8,85,6,SMOOTH_STAIRS:4)
Block(-8,85,7,SMOOTH_STAIRS:7)
Block(-8,86,2,IRON_FENCE:0)
Block(-8,86,3,IRON_FENCE:0)
Block(-8,86,4,IRON_FENCE:0)
Block(-8,86,5,IRON_FENCE:0)
Block(-8,86,6,IRON_FENCE:0)
Block(-8,86,7,IRON_FENCE:0)
Block(-7,0,-7,CONCRETE:7)
Block(-7,0,-6,CONCRETE:7)
Block(-7,0,-5,CONCRETE:7)
Block(-7,0,-4,CONCRETE:7)
Block(-7,0,-3,CONCRETE:7)
Block(-7,0,-2,CONCRETE:7)
Block(-7,0,-1,CONCRETE:7)
Block(-7,0,0,CONCRETE:7)
Block(-7,0,1,CONCRETE:7)
Block(-7,0,2,CONCRETE:7)
Block(-7,0,3,CONCRETE:7)
Block(-7,0,4,CONCRETE:7)
Block(-7,0,5,CONCRETE:7)
Block(-7,0,6,CONCRETE:7)
Block(-7,0,7,CONCRETE:7)
Block(-7,0,8,CONCRETE:7)
Block(-7,1,-7,CONCRETE:7)
Block(-7,1,-6,CONCRETE:7)
Block(-7,1,-5,CONCRETE:7)
Block(-7,1,-4,CONCRETE:7)
Block(-7,1,-3,CONCRETE:7)
Block(-7,1,-2,CONCRETE:7)
Block(-7,1,-1,CONCRETE:7)
Block(-7,1,0,CONCRETE:7)
Block(-7,1,1,CONCRETE:7)
Block(-7,1,2,CONCRETE:7)
Block(-7,1,3,CONCRETE:7)
Block(-7,1,4,CONCRETE:7)
Block(-7,1,5,CONCRETE:7)
Block(-7,1,6,CONCRETE:7)
Block(-7,1,7,CONCRETE:7)
Block(-7,1,8,CONCRETE:7)
Block(-7,2,-7,CONCRETE:7)
Block(-7,2,-6,CONCRETE:7)
Block(-7,2,-5,CONCRETE:7)
Block(-7,2,-4,CONCRETE:7)
Block(-7,2,-3,CONCRETE:7)
Block(-7,2,-2,CONCRETE:7)
Block(-7,2,-1,CONCRETE:7)
Block(-7,2,0,CONCRETE:7)
Block(-7,2,1,CONCRETE:7)
Block(-7,2,2,CONCRETE:7)
Block(-7,2,3,CONCRETE:7)
Block(-7,2,4,CONCRETE:7)
Block(-7,2,5,CONCRETE:7)
Block(-7,2,6,CONCRETE:7)
Block(-7,2,7,CONCRETE:7)
Block(-7,2,8,CONCRETE:7)
Block(-7,3,-7,CONCRETE:7)
Block(-7,3,-6,CONCRETE:7)
Block(-7,3,-5,CONCRETE:7)
Block(-7,3,-4,CONCRETE:7)
Block(-7,3,-3,CONCRETE:7)
Block(-7,3,-2,CONCRETE:7)
Block(-7,3,-1,CONCRETE:7)
Block(-7,3,0,CONCRETE:7)
Block(-7,3,1,CONCRETE:7)
Block(-7,3,2,CONCRETE:7)
Block(-7,3,3,CONCRETE:7)
Block(-7,3,4,CONCRETE:7)
Block(-7,3,5,CONCRETE:7)
Block(-7,3,6,CONCRETE:7)
Block(-7,3,7,CONCRETE:7)
Block(-7,3,8,CONCRETE:7)
Block(-7,4,-7,CONCRETE:7)
Block(-7,4,-6,CONCRETE:7)
Block(-7,4,-5,CONCRETE:7)
Block(-7,4,-4,CONCRETE:7)
Block(-7,4,-3,CONCRETE:7)
Block(-7,4,-2,CONCRETE:7)
Block(-7,4,-1,CONCRETE:7)
Block(-7,4,0,CONCRETE:7)
Block(-7,4,1,CONCRETE:7)
Block(-7,4,2,CONCRETE:7)
Block(-7,4,3,CONCRETE:7)
Block(-7,4,4,CONCRETE:7)
Block(-7,4,5,CONCRETE:7)
Block(-7,4,6,CONCRETE:7)
Block(-7,4,7,CONCRETE:7)
Block(-7,4,8,CONCRETE:7)
Block(-7,5,-7,CONCRETE:7)
Block(-7,5,-6,CONCRETE:7)
Block(-7,5,-5,CONCRETE:7)
Block(-7,5,-4,CONCRETE:7)
Block(-7,5,-3,CONCRETE:7)
Block(-7,5,-2,CONCRETE:7)
Block(-7,5,-1,CONCRETE:7)
Block(-7,5,0,CONCRETE:7)
Block(-7,5,1,CONCRETE:7)
Block(-7,5,2,CONCRETE:7)
Block(-7,5,3,CONCRETE:7)
Block(-7,5,4,CONCRETE:7)
Block(-7,5,5,CONCRETE:7)
Block(-7,5,6,CONCRETE:7)
Block(-7,5,7,CONCRETE:7)
Block(-7,5,8,CONCRETE:7)
Block(-7,6,-7,CONCRETE:7)
Block(-7,6,-6,CONCRETE:7)
Block(-7,6,-5,CONCRETE:7)
Block(-7,6,-4,CONCRETE:7)
Block(-7,6,-3,CONCRETE:7)
Block(-7,6,-2,CONCRETE:7)
Block(-7,6,-1,CONCRETE:7)
Block(-7,6,0,CONCRETE:7)
Block(-7,6,1,CONCRETE:7)
Block(-7,6,2,CONCRETE:7)
Block(-7,6,3,CONCRETE:7)
Block(-7,6,4,CONCRETE:7)
Block(-7,6,5,CONCRETE:7)
Block(-7,6,6,CONCRETE:7)
Block(-7,6,7,CONCRETE:7)
Block(-7,6,8,CONCRETE:7)
Block(-7,7,-7,CONCRETE:7)
Block(-7,7,-6,CONCRETE:7)
Block(-7,7,-5,CONCRETE:7)
Block(-7,7,-4,CONCRETE:7)
Block(-7,7,-3,CONCRETE:7)
Block(-7,7,-2,CONCRETE:7)
Block(-7,7,-1,CONCRETE:7)
Block(-7,7,0,CONCRETE:7)
Block(-7,7,1,CONCRETE:7)
Block(-7,7,2,CONCRETE:7)
Block(-7,7,3,CONCRETE:7)
Block(-7,7,4,CONCRETE:7)
Block(-7,7,5,CONCRETE:7)
Block(-7,7,6,CONCRETE:7)
Block(-7,7,7,CONCRETE:7)
Block(-7,7,8,CONCRETE:7)
Block(-7,8,-7,CONCRETE:7)
Block(-7,8,-6,CONCRETE:7)
Block(-7,8,-5,CONCRETE:7)
Block(-7,8,-4,CONCRETE:7)
Block(-7,8,-3,CONCRETE:7)
Block(-7,8,-2,CONCRETE:7)
Block(-7,8,-1,CONCRETE:7)
Block(-7,8,0,CONCRETE:7)
Block(-7,8,1,CONCRETE:7)
Block(-7,8,2,CONCRETE:7)
Block(-7,8,3,CONCRETE:7)
Block(-7,8,4,CONCRETE:7)
Block(-7,8,5,CONCRETE:7)
Block(-7,8,6,CONCRETE:7)
Block(-7,8,7,CONCRETE:7)
Block(-7,8,8,CONCRETE:7)
Block(-7,9,-7,CONCRETE:7)
Block(-7,9,-6,CONCRETE:7)
Block(-7,9,-5,CONCRETE:7)
Block(-7,9,-4,CONCRETE:7)
Block(-7,9,-3,CONCRETE:7)
Block(-7,9,-2,CONCRETE:7)
Block(-7,9,-1,CONCRETE:7)
Block(-7,9,0,CONCRETE:7)
Block(-7,9,1,CONCRETE:7)
Block(-7,9,2,CONCRETE:7)
Block(-7,9,3,CONCRETE:7)
Block(-7,9,4,CONCRETE:7)
Block(-7,9,5,CONCRETE:7)
Block(-7,9,6,CONCRETE:7)
Block(-7,9,7,CONCRETE:7)
Block(-7,9,8,CONCRETE:7)
Block(-7,10,-7,CONCRETE:7)
Block(-7,10,-6,CONCRETE:7)
Block(-7,10,-5,CONCRETE:7)
Block(-7,10,-4,CONCRETE:7)
Block(-7,10,-3,CONCRETE:7)
Block(-7,10,-2,CONCRETE:7)
Block(-7,10,-1,CONCRETE:7)
Block(-7,10,0,CONCRETE:7)
Block(-7,10,1,CONCRETE:7)
Block(-7,10,2,CONCRETE:7)
Block(-7,10,3,CONCRETE:7)
Block(-7,10,4,CONCRETE:7)
Block(-7,10,5,CONCRETE:7)
Block(-7,10,6,CONCRETE:7)
Block(-7,10,7,CONCRETE:7)
Block(-7,10,8,CONCRETE:7)
Block(-7,11,-7,CONCRETE:7)
Block(-7,11,-6,CONCRETE:7)
Block(-7,11,-5,CONCRETE:7)
Block(-7,11,-4,CONCRETE:7)
Block(-7,11,-3,CONCRETE:7)
Block(-7,11,-2,CONCRETE:7)
Block(-7,11,-1,CONCRETE:7)
Block(-7,11,0,CONCRETE:7)
Block(-7,11,1,CONCRETE:7)
Block(-7,11,2,CONCRETE:7)
Block(-7,11,3,CONCRETE:7)
Block(-7,11,4,CONCRETE:7)
Block(-7,11,5,CONCRETE:7)
Block(-7,11,6,CONCRETE:7)
Block(-7,11,7,CONCRETE:7)
Block(-7,11,8,CONCRETE:7)
Block(-7,12,-7,CONCRETE:7)
Block(-7,12,-6,CONCRETE:7)
Block(-7,12,-5,CONCRETE:7)
Block(-7,12,-4,CONCRETE:7)
Block(-7,12,-3,CONCRETE:7)
Block(-7,12,-2,CONCRETE:7)
Block(-7,12,-1,CONCRETE:7)
Block(-7,12,0,CONCRETE:7)
Block(-7,12,1,CONCRETE:7)
Block(-7,12,2,CONCRETE:7)
Block(-7,12,3,CONCRETE:7)
Block(-7,12,4,CONCRETE:7)
Block(-7,12,5,CONCRETE:7)
Block(-7,12,6,CONCRETE:7)
Block(-7,12,7,CONCRETE:7)
Block(-7,12,8,CONCRETE:7)
Block(-7,13,-7,CONCRETE:7)
Block(-7,13,-6,CONCRETE:7)
Block(-7,13,-5,CONCRETE:7)
Block(-7,13,-4,CONCRETE:7)
Block(-7,13,-3,CONCRETE:7)
Block(-7,13,-2,CONCRETE:7)
Block(-7,13,-1,CONCRETE:7)
Block(-7,13,0,CONCRETE:7)
Block(-7,13,1,CONCRETE:7)
Block(-7,13,2,CONCRETE:7)
Block(-7,13,3,CONCRETE:7)
Block(-7,13,4,CONCRETE:7)
Block(-7,13,5,CONCRETE:7)
Block(-7,13,6,CONCRETE:7)
Block(-7,13,7,CONCRETE:7)
Block(-7,13,8,CONCRETE:7)
Block(-7,14,-7,CONCRETE:7)
Block(-7,14,-6,CONCRETE:7)
Block(-7,14,-5,CONCRETE:7)
Block(-7,14,-4,CONCRETE:7)
Block(-7,14,-3,CONCRETE:7)
Block(-7,14,-2,CONCRETE:7)
Block(-7,14,-1,CONCRETE:7)
Block(-7,14,0,CONCRETE:7)
Block(-7,14,1,CONCRETE:7)
Block(-7,14,2,CONCRETE:7)
Block(-7,14,3,IRON_DOOR_BLOCK:2)
Block(-7,14,4,AIR:0)
Block(-7,14,5,BOOKSHELF:0)
Block(-7,14,6,CONCRETE:7)
Block(-7,14,7,BOOKSHELF:0)
Block(-7,14,8,BOOKSHELF:0)
Block(-7,15,-7,CONCRETE:7)
Block(-7,15,-6,CONCRETE:7)
Block(-7,15,-5,CONCRETE:7)
Block(-7,15,-4,CONCRETE:7)
Block(-7,15,-3,CONCRETE:7)
Block(-7,15,-2,CONCRETE:7)
Block(-7,15,-1,CONCRETE:7)
Block(-7,15,0,CONCRETE:7)
Block(-7,15,1,CONCRETE:7)
Block(-7,15,2,CONCRETE:7)
Block(-7,15,3,IRON_DOOR_BLOCK:9)
Block(-7,15,4,AIR:0)
Block(-7,15,5,BOOKSHELF:0)
Block(-7,15,6,CONCRETE:7)
Block(-7,15,7,BOOKSHELF:0)
Block(-7,15,8,BOOKSHELF:0)
Block(-7,16,-7,CONCRETE:7)
Block(-7,16,-6,CONCRETE:7)
Block(-7,16,-5,CONCRETE:7)
Block(-7,16,-4,CONCRETE:7)
Block(-7,16,-3,CONCRETE:7)
Block(-7,16,-2,CONCRETE:7)
Block(-7,16,-1,CONCRETE:7)
Block(-7,16,0,CONCRETE:7)
Block(-7,16,1,CONCRETE:7)
Block(-7,16,2,CONCRETE:7)
Block(-7,16,3,STEP:8)
Block(-7,16,4,STEP:8)
Block(-7,16,5,STEP:8)
Block(-7,16,6,CONCRETE:7)
Block(-7,16,7,STEP:8)
Block(-7,16,8,STEP:8)
Block(-7,17,-7,DOUBLE_STEP:0)
Block(-7,17,-6,SMOOTH_BRICK:0)
Block(-7,17,-5,STAINED_CLAY:9)
Block(-7,17,-4,STAINED_CLAY:9)
Block(-7,17,-3,SMOOTH_BRICK:0)
Block(-7,17,-2,SMOOTH_BRICK:0)
Block(-7,17,-1,CONCRETE:7)
Block(-7,17,0,CONCRETE:7)
Block(-7,17,1,CONCRETE:7)
Block(-7,17,2,CONCRETE:7)
Block(-7,17,3,CONCRETE:7)
Block(-7,17,4,CONCRETE:7)
Block(-7,17,5,CONCRETE:7)
Block(-7,17,6,CONCRETE:7)
Block(-7,17,7,CONCRETE:7)
Block(-7,17,8,CONCRETE:7)
Block(-7,18,-6,COBBLE_WALL:0)
Block(-7,18,-4,COBBLE_WALL:0)
Block(-7,18,-2,COBBLE_WALL:0)
Block(-7,18,0,CONCRETE:7)
Block(-7,18,1,CONCRETE:7)
Block(-7,18,2,CONCRETE:7)
Block(-7,18,3,CONCRETE:7)
Block(-7,18,4,CONCRETE:7)
Block(-7,18,5,CONCRETE:7)
Block(-7,18,6,CONCRETE:7)
Block(-7,18,7,CONCRETE:7)
Block(-7,18,8,CONCRETE:7)
Block(-7,19,0,CONCRETE:7)
Block(-7,19,1,CONCRETE:7)
Block(-7,19,2,STAINED_GLASS_PANE:15)
Block(-7,19,3,CONCRETE:7)
Block(-7,19,4,STAINED_GLASS_PANE:15)
Block(-7,19,5,STAINED_GLASS_PANE:15)
Block(-7,19,6,CONCRETE:7)
Block(-7,19,7,STAINED_GLASS_PANE:15)
Block(-7,19,8,CONCRETE:7)
Block(-7,20,0,CONCRETE:7)
Block(-7,20,1,CONCRETE:7)
Block(-7,20,2,STAINED_GLASS_PANE:15)
Block(-7,20,3,CONCRETE:7)
Block(-7,20,4,STAINED_GLASS_PANE:15)
Block(-7,20,5,STAINED_GLASS_PANE:15)
Block(-7,20,6,CONCRETE:7)
Block(-7,20,7,STAINED_GLASS_PANE:15)
Block(-7,20,8,CONCRETE:7)
Block(-7,21,0,CONCRETE:7)
Block(-7,21,1,CONCRETE:7)
Block(-7,21,2,CONCRETE:7)
Block(-7,21,3,CONCRETE:7)
Block(-7,21,4,CONCRETE:7)
Block(-7,21,5,CONCRETE:7)
Block(-7,21,6,CONCRETE:7)
Block(-7,21,7,CONCRETE:7)
Block(-7,21,8,CONCRETE:7)
Block(-7,22,0,CONCRETE:7)
Block(-7,22,1,CONCRETE:7)
Block(-7,22,2,CONCRETE:7)
Block(-7,22,3,CONCRETE:7)
Block(-7,22,4,CONCRETE:7)
Block(-7,22,5,CONCRETE:7)
Block(-7,22,6,CONCRETE:7)
Block(-7,22,7,CONCRETE:7)
Block(-7,22,8,CONCRETE:7)
Block(-7,23,0,CONCRETE:7)
Block(-7,23,1,CONCRETE:7)
Block(-7,23,2,STAINED_GLASS_PANE:15)
Block(-7,23,3,CONCRETE:7)
Block(-7,23,4,STAINED_GLASS_PANE:15)
Block(-7,23,5,STAINED_GLASS_PANE:15)
Block(-7,23,6,CONCRETE:7)
Block(-7,23,7,STAINED_GLASS_PANE:15)
Block(-7,23,8,CONCRETE:7)
Block(-7,24,0,CONCRETE:7)
Block(-7,24,1,CONCRETE:7)
Block(-7,24,2,STAINED_GLASS_PANE:15)
Block(-7,24,3,CONCRETE:7)
Block(-7,24,4,STAINED_GLASS_PANE:15)
Block(-7,24,5,STAINED_GLASS_PANE:15)
Block(-7,24,6,CONCRETE:7)
Block(-7,24,7,STAINED_GLASS_PANE:15)
Block(-7,24,8,CONCRETE:7)
Block(-7,25,0,CONCRETE:7)
Block(-7,25,1,CONCRETE:7)
Block(-7,25,2,CONCRETE:7)
Block(-7,25,3,CONCRETE:7)
Block(-7,25,4,CONCRETE:7)
Block(-7,25,5,CONCRETE:7)
Block(-7,25,6,CONCRETE:7)
Block(-7,25,7,CONCRETE:7)
Block(-7,25,8,CONCRETE:7)
Block(-7,26,0,CONCRETE:7)
Block(-7,26,1,CONCRETE:7)
Block(-7,26,2,CONCRETE:7)
Block(-7,26,3,CONCRETE:7)
Block(-7,26,4,CONCRETE:7)
Block(-7,26,5,CONCRETE:7)
Block(-7,26,6,CONCRETE:7)
Block(-7,26,7,CONCRETE:7)
Block(-7,26,8,CONCRETE:7)
Block(-7,27,0,CONCRETE:7)
Block(-7,27,1,CONCRETE:7)
Block(-7,27,2,STAINED_GLASS_PANE:15)
Block(-7,27,3,CONCRETE:7)
Block(-7,27,4,STAINED_GLASS_PANE:15)
Block(-7,27,5,STAINED_GLASS_PANE:15)
Block(-7,27,6,CONCRETE:7)
Block(-7,27,7,STAINED_GLASS_PANE:15)
Block(-7,27,8,CONCRETE:7)
Block(-7,28,0,CONCRETE:7)
Block(-7,28,1,CONCRETE:7)
Block(-7,28,2,STAINED_GLASS_PANE:15)
Block(-7,28,3,CONCRETE:7)
Block(-7,28,4,STAINED_GLASS_PANE:15)
Block(-7,28,5,STAINED_GLASS_PANE:15)
Block(-7,28,6,CONCRETE:7)
Block(-7,28,7,STAINED_GLASS_PANE:15)
Block(-7,28,8,CONCRETE:7)
Block(-7,29,0,CONCRETE:7)
Block(-7,29,1,CONCRETE:7)
Block(-7,29,2,CONCRETE:7)
Block(-7,29,3,CONCRETE:7)
Block(-7,29,4,CONCRETE:7)
Block(-7,29,5,CONCRETE:7)
Block(-7,29,6,CONCRETE:7)
Block(-7,29,7,CONCRETE:7)
Block(-7,29,8,CONCRETE:7)
Block(-7,30,0,CONCRETE:7)
Block(-7,30,1,CONCRETE:7)
Block(-7,30,2,CONCRETE:7)
Block(-7,30,3,CONCRETE:7)
Block(-7,30,4,CONCRETE:7)
Block(-7,30,5,CONCRETE:7)
Block(-7,30,6,CONCRETE:7)
Block(-7,30,7,CONCRETE:7)
Block(-7,30,8,CONCRETE:7)
Block(-7,31,0,CONCRETE:7)
Block(-7,31,1,CONCRETE:7)
Block(-7,31,2,STAINED_GLASS_PANE:15)
Block(-7,31,3,CONCRETE:7)
Block(-7,31,4,STAINED_GLASS_PANE:15)
Block(-7,31,5,STAINED_GLASS_PANE:15)
Block(-7,31,6,CONCRETE:7)
Block(-7,31,7,STAINED_GLASS_PANE:15)
Block(-7,31,8,CONCRETE:7)
Block(-7,32,0,CONCRETE:7)
Block(-7,32,1,CONCRETE:7)
Block(-7,32,2,STAINED_GLASS_PANE:15)
Block(-7,32,3,CONCRETE:7)
Block(-7,32,4,STAINED_GLASS_PANE:15)
Block(-7,32,5,STAINED_GLASS_PANE:15)
Block(-7,32,6,CONCRETE:7)
Block(-7,32,7,STAINED_GLASS_PANE:15)
Block(-7,32,8,CONCRETE:7)
Block(-7,33,0,CONCRETE:7)
Block(-7,33,1,CONCRETE:7)
Block(-7,33,2,CONCRETE:7)
Block(-7,33,3,CONCRETE:7)
Block(-7,33,4,CONCRETE:7)
Block(-7,33,5,CONCRETE:7)
Block(-7,33,6,CONCRETE:7)
Block(-7,33,7,CONCRETE:7)
Block(-7,33,8,CONCRETE:7)
Block(-7,34,0,CONCRETE:7)
Block(-7,34,1,CONCRETE:7)
Block(-7,34,2,CONCRETE:7)
Block(-7,34,3,CONCRETE:7)
Block(-7,34,4,CONCRETE:7)
Block(-7,34,5,CONCRETE:7)
Block(-7,34,6,CONCRETE:7)
Block(-7,34,7,CONCRETE:7)
Block(-7,34,8,CONCRETE:7)
Block(-7,35,0,CONCRETE:7)
Block(-7,35,1,CONCRETE:7)
Block(-7,35,2,STAINED_GLASS_PANE:15)
Block(-7,35,3,CONCRETE:7)
Block(-7,35,4,STAINED_GLASS_PANE:15)
Block(-7,35,5,STAINED_GLASS_PANE:15)
Block(-7,35,6,CONCRETE:7)
Block(-7,35,7,STAINED_GLASS_PANE:15)
Block(-7,35,8,CONCRETE:7)
Block(-7,36,0,CONCRETE:7)
Block(-7,36,1,CONCRETE:7)
Block(-7,36,2,STAINED_GLASS_PANE:15)
Block(-7,36,3,CONCRETE:7)
Block(-7,36,4,STAINED_GLASS_PANE:15)
Block(-7,36,5,STAINED_GLASS_PANE:15)
Block(-7,36,6,CONCRETE:7)
Block(-7,36,7,STAINED_GLASS_PANE:15)
Block(-7,36,8,CONCRETE:7)
Block(-7,37,0,CONCRETE:7)
Block(-7,37,1,CONCRETE:7)
Block(-7,37,2,CONCRETE:7)
Block(-7,37,3,CONCRETE:7)
Block(-7,37,4,CONCRETE:7)
Block(-7,37,5,CONCRETE:7)
Block(-7,37,6,CONCRETE:7)
Block(-7,37,7,CONCRETE:7)
Block(-7,37,8,CONCRETE:7)
Block(-7,38,0,CONCRETE:8)
Block(-7,38,1,CONCRETE:8)
Block(-7,38,2,CONCRETE:8)
Block(-7,38,3,CONCRETE:8)
Block(-7,38,4,CONCRETE:8)
Block(-7,38,5,CONCRETE:8)
Block(-7,38,6,CONCRETE:8)
Block(-7,38,7,CONCRETE:8)
Block(-7,38,8,CONCRETE:8)
Block(-7,39,0,CONCRETE:8)
Block(-7,39,1,CONCRETE:8)
Block(-7,39,2,STAINED_GLASS_PANE:15)
Block(-7,39,3,CONCRETE:8)
Block(-7,39,4,STAINED_GLASS_PANE:15)
Block(-7,39,5,STAINED_GLASS_PANE:15)
Block(-7,39,6,CONCRETE:8)
Block(-7,39,7,STAINED_GLASS_PANE:15)
Block(-7,39,8,CONCRETE:8)
Block(-7,40,0,CONCRETE:8)
Block(-7,40,1,CONCRETE:8)
Block(-7,40,2,STAINED_GLASS_PANE:15)
Block(-7,40,3,CONCRETE:8)
Block(-7,40,4,STAINED_GLASS_PANE:15)
Block(-7,40,5,STAINED_GLASS_PANE:15)
Block(-7,40,6,CONCRETE:8)
Block(-7,40,7,STAINED_GLASS_PANE:15)
Block(-7,40,8,CONCRETE:8)
Block(-7,41,0,CONCRETE:8)
Block(-7,41,1,CONCRETE:8)
Block(-7,41,2,CONCRETE:8)
Block(-7,41,3,CONCRETE:8)
Block(-7,41,4,CONCRETE:8)
Block(-7,41,5,CONCRETE:8)
Block(-7,41,6,CONCRETE:8)
Block(-7,41,7,CONCRETE:8)
Block(-7,41,8,CONCRETE:8)
Block(-7,42,0,CONCRETE:8)
Block(-7,42,1,CONCRETE:8)
Block(-7,42,2,CONCRETE:8)
Block(-7,42,3,CONCRETE:8)
Block(-7,42,4,CONCRETE:8)
Block(-7,42,5,CONCRETE:8)
Block(-7,42,6,CONCRETE:8)
Block(-7,42,7,CONCRETE:8)
Block(-7,42,8,CONCRETE:8)
Block(-7,43,0,CONCRETE:8)
Block(-7,43,1,CONCRETE:8)
Block(-7,43,2,STAINED_GLASS_PANE:15)
Block(-7,43,3,CONCRETE:8)
Block(-7,43,4,STAINED_GLASS_PANE:15)
Block(-7,43,5,STAINED_GLASS_PANE:15)
Block(-7,43,6,CONCRETE:8)
Block(-7,43,7,STAINED_GLASS_PANE:15)
Block(-7,43,8,CONCRETE:8)
Block(-7,44,0,CONCRETE:8)
Block(-7,44,1,CONCRETE:8)
Block(-7,44,2,STAINED_GLASS_PANE:15)
Block(-7,44,3,CONCRETE:8)
Block(-7,44,4,STAINED_GLASS_PANE:15)
Block(-7,44,5,STAINED_GLASS_PANE:15)
Block(-7,44,6,CONCRETE:8)
Block(-7,44,7,STAINED_GLASS_PANE:15)
Block(-7,44,8,CONCRETE:8)
Block(-7,45,0,CONCRETE:8)
Block(-7,45,1,CONCRETE:8)
Block(-7,45,2,CONCRETE:8)
Block(-7,45,3,CONCRETE:8)
Block(-7,45,4,CONCRETE:8)
Block(-7,45,5,CONCRETE:8)
Block(-7,45,6,CONCRETE:8)
Block(-7,45,7,CONCRETE:8)
Block(-7,45,8,CONCRETE:8)
Block(-7,46,0,CONCRETE:8)
Block(-7,46,1,CONCRETE:8)
Block(-7,46,2,CONCRETE:8)
Block(-7,46,3,CONCRETE:8)
Block(-7,46,4,CONCRETE:8)
Block(-7,46,5,CONCRETE:8)
Block(-7,46,6,CONCRETE:8)
Block(-7,46,7,CONCRETE:8)
Block(-7,46,8,CONCRETE:8)
Block(-7,47,0,CONCRETE:8)
Block(-7,47,1,CONCRETE:8)
Block(-7,47,2,STAINED_GLASS_PANE:15)
Block(-7,47,3,CONCRETE:8)
Block(-7,47,4,STAINED_GLASS_PANE:15)
Block(-7,47,5,STAINED_GLASS_PANE:15)
Block(-7,47,6,CONCRETE:8)
Block(-7,47,7,STAINED_GLASS_PANE:15)
Block(-7,47,8,CONCRETE:8)
Block(-7,48,0,CONCRETE:8)
Block(-7,48,1,CONCRETE:8)
Block(-7,48,2,STAINED_GLASS_PANE:15)
Block(-7,48,3,CONCRETE:8)
Block(-7,48,4,STAINED_GLASS_PANE:15)
Block(-7,48,5,STAINED_GLASS_PANE:15)
Block(-7,48,6,CONCRETE:8)
Block(-7,48,7,STAINED_GLASS_PANE:15)
Block(-7,48,8,CONCRETE:8)
Block(-7,49,0,CONCRETE:7)
Block(-7,49,1,CONCRETE:7)
Block(-7,49,2,CONCRETE:7)
Block(-7,49,3,CONCRETE:7)
Block(-7,49,4,CONCRETE:7)
Block(-7,49,5,CONCRETE:7)
Block(-7,49,6,CONCRETE:7)
Block(-7,49,7,CONCRETE:7)
Block(-7,49,8,CONCRETE:7)
Block(-7,50,0,CONCRETE:8)
Block(-7,50,1,CONCRETE:8)
Block(-7,50,2,CONCRETE:8)
Block(-7,50,3,CONCRETE:8)
Block(-7,50,4,CONCRETE:8)
Block(-7,50,5,CONCRETE:8)
Block(-7,50,6,CONCRETE:8)
Block(-7,50,7,CONCRETE:8)
Block(-7,50,8,CONCRETE:8)
Block(-7,51,0,CONCRETE:8)
Block(-7,51,1,CONCRETE:8)
Block(-7,51,2,STAINED_GLASS_PANE:15)
Block(-7,51,3,CONCRETE:8)
Block(-7,51,4,STAINED_GLASS_PANE:15)
Block(-7,51,5,STAINED_GLASS_PANE:15)
Block(-7,51,6,CONCRETE:8)
Block(-7,51,7,STAINED_GLASS_PANE:15)
Block(-7,51,8,CONCRETE:8)
Block(-7,52,0,CONCRETE:8)
Block(-7,52,1,CONCRETE:8)
Block(-7,52,2,STAINED_GLASS_PANE:15)
Block(-7,52,3,CONCRETE:8)
Block(-7,52,4,STAINED_GLASS_PANE:15)
Block(-7,52,5,STAINED_GLASS_PANE:15)
Block(-7,52,6,CONCRETE:8)
Block(-7,52,7,STAINED_GLASS_PANE:15)
Block(-7,52,8,CONCRETE:8)
Block(-7,53,0,CONCRETE:7)
Block(-7,53,1,CONCRETE:7)
Block(-7,53,2,CONCRETE:7)
Block(-7,53,3,CONCRETE:7)
Block(-7,53,4,CONCRETE:7)
Block(-7,53,5,CONCRETE:7)
Block(-7,53,6,CONCRETE:7)
Block(-7,53,7,CONCRETE:7)
Block(-7,53,8,CONCRETE:7)
Block(-7,54,0,CONCRETE:8)
Block(-7,54,1,CONCRETE:8)
Block(-7,54,2,CONCRETE:8)
Block(-7,54,3,CONCRETE:8)
Block(-7,54,4,CONCRETE:8)
Block(-7,54,5,CONCRETE:8)
Block(-7,54,6,CONCRETE:8)
Block(-7,54,7,CONCRETE:8)
Block(-7,54,8,CONCRETE:8)
Block(-7,55,0,CONCRETE:8)
Block(-7,55,1,CONCRETE:8)
Block(-7,55,2,STAINED_GLASS_PANE:15)
Block(-7,55,3,CONCRETE:8)
Block(-7,55,4,STAINED_GLASS_PANE:15)
Block(-7,55,5,STAINED_GLASS_PANE:15)
Block(-7,55,6,CONCRETE:8)
Block(-7,55,7,STAINED_GLASS_PANE:15)
Block(-7,55,8,CONCRETE:8)
Block(-7,56,0,CONCRETE:8)
Block(-7,56,1,CONCRETE:8)
Block(-7,56,2,STAINED_GLASS_PANE:15)
Block(-7,56,3,CONCRETE:8)
Block(-7,56,4,STAINED_GLASS_PANE:15)
Block(-7,56,5,STAINED_GLASS_PANE:15)
Block(-7,56,6,CONCRETE:8)
Block(-7,56,7,STAINED_GLASS_PANE:15)
Block(-7,56,8,CONCRETE:8)
Block(-7,57,0,CONCRETE:8)
Block(-7,57,1,CONCRETE:8)
Block(-7,57,2,CONCRETE:8)
Block(-7,57,3,CONCRETE:8)
Block(-7,57,4,CONCRETE:8)
Block(-7,57,5,CONCRETE:8)
Block(-7,57,6,CONCRETE:8)
Block(-7,57,7,CONCRETE:8)
Block(-7,57,8,CONCRETE:8)
Block(-7,58,0,CONCRETE:8)
Block(-7,58,1,CONCRETE:8)
Block(-7,58,2,CONCRETE:8)
Block(-7,58,3,CONCRETE:8)
Block(-7,58,4,CONCRETE:8)
Block(-7,58,5,CONCRETE:8)
Block(-7,58,6,CONCRETE:8)
Block(-7,58,7,CONCRETE:8)
Block(-7,58,8,CONCRETE:8)
Block(-7,59,0,CONCRETE:8)
Block(-7,59,1,CONCRETE:8)
Block(-7,59,2,STAINED_GLASS_PANE:15)
Block(-7,59,3,CONCRETE:8)
Block(-7,59,4,STAINED_GLASS_PANE:15)
Block(-7,59,5,STAINED_GLASS_PANE:15)
Block(-7,59,6,CONCRETE:8)
Block(-7,59,7,STAINED_GLASS_PANE:15)
Block(-7,59,8,CONCRETE:8)
Block(-7,60,0,CONCRETE:8)
Block(-7,60,1,CONCRETE:8)
Block(-7,60,2,STAINED_GLASS_PANE:15)
Block(-7,60,3,CONCRETE:8)
Block(-7,60,4,STAINED_GLASS_PANE:15)
Block(-7,60,5,STAINED_GLASS_PANE:15)
Block(-7,60,6,CONCRETE:8)
Block(-7,60,7,STAINED_GLASS_PANE:15)
Block(-7,60,8,CONCRETE:8)
Block(-7,61,0,CONCRETE:8)
Block(-7,61,1,CONCRETE:8)
Block(-7,61,2,CONCRETE:8)
Block(-7,61,3,CONCRETE:8)
Block(-7,61,4,CONCRETE:8)
Block(-7,61,5,CONCRETE:8)
Block(-7,61,6,CONCRETE:8)
Block(-7,61,7,CONCRETE:8)
Block(-7,61,8,CONCRETE:8)
Block(-7,62,0,CONCRETE:8)
Block(-7,62,1,CONCRETE:8)
Block(-7,62,2,CONCRETE:8)
Block(-7,62,3,CONCRETE:8)
Block(-7,62,4,CONCRETE:8)
Block(-7,62,5,CONCRETE:8)
Block(-7,62,6,CONCRETE:8)
Block(-7,62,7,CONCRETE:8)
Block(-7,62,8,CONCRETE:8)
Block(-7,63,0,CONCRETE:8)
Block(-7,63,1,CONCRETE:8)
Block(-7,63,2,STAINED_GLASS_PANE:15)
Block(-7,63,3,CONCRETE:8)
Block(-7,63,4,STAINED_GLASS_PANE:15)
Block(-7,63,5,STAINED_GLASS_PANE:15)
Block(-7,63,6,CONCRETE:8)
Block(-7,63,7,STAINED_GLASS_PANE:15)
Block(-7,63,8,CONCRETE:8)
Block(-7,64,0,CONCRETE:8)
Block(-7,64,1,CONCRETE:8)
Block(-7,64,2,STAINED_GLASS_PANE:15)
Block(-7,64,3,CONCRETE:8)
Block(-7,64,4,STAINED_GLASS_PANE:15)
Block(-7,64,5,STAINED_GLASS_PANE:15)
Block(-7,64,6,CONCRETE:8)
Block(-7,64,7,STAINED_GLASS_PANE:15)
Block(-7,64,8,CONCRETE:8)
Block(-7,65,0,CONCRETE:8)
Block(-7,65,1,CONCRETE:8)
Block(-7,65,2,CONCRETE:8)
Block(-7,65,3,CONCRETE:8)
Block(-7,65,4,CONCRETE:8)
Block(-7,65,5,CONCRETE:8)
Block(-7,65,6,CONCRETE:8)
Block(-7,65,7,CONCRETE:8)
Block(-7,65,8,CONCRETE:8)
Block(-7,66,0,CONCRETE:8)
Block(-7,66,1,CONCRETE:8)
Block(-7,66,2,CONCRETE:8)
Block(-7,66,3,CONCRETE:8)
Block(-7,66,4,CONCRETE:8)
Block(-7,66,5,CONCRETE:8)
Block(-7,66,6,CONCRETE:8)
Block(-7,66,7,CONCRETE:8)
Block(-7,66,8,CONCRETE:8)
Block(-7,67,0,CONCRETE:8)
Block(-7,67,1,CONCRETE:8)
Block(-7,67,2,STAINED_GLASS_PANE:15)
Block(-7,67,3,CONCRETE:8)
Block(-7,67,4,STAINED_GLASS_PANE:15)
Block(-7,67,5,STAINED_GLASS_PANE:15)
Block(-7,67,6,CONCRETE:8)
Block(-7,67,7,STAINED_GLASS_PANE:15)
Block(-7,67,8,CONCRETE:8)
Block(-7,68,0,CONCRETE:8)
Block(-7,68,1,CONCRETE:8)
Block(-7,68,2,STAINED_GLASS_PANE:15)
Block(-7,68,3,CONCRETE:8)
Block(-7,68,4,STAINED_GLASS_PANE:15)
Block(-7,68,5,STAINED_GLASS_PANE:15)
Block(-7,68,6,CONCRETE:8)
Block(-7,68,7,STAINED_GLASS_PANE:15)
Block(-7,68,8,CONCRETE:8)
Block(-7,69,0,CONCRETE:8)
Block(-7,69,1,CONCRETE:8)
Block(-7,69,2,CONCRETE:8)
Block(-7,69,3,CONCRETE:8)
Block(-7,69,4,CONCRETE:8)
Block(-7,69,5,CONCRETE:8)
Block(-7,69,6,CONCRETE:8)
Block(-7,69,7,CONCRETE:8)
Block(-7,69,8,CONCRETE:8)
Block(-7,70,0,CONCRETE:8)
Block(-7,70,1,CONCRETE:8)
Block(-7,70,2,CONCRETE:8)
Block(-7,70,3,CONCRETE:8)
Block(-7,70,4,CONCRETE:8)
Block(-7,70,5,CONCRETE:8)
Block(-7,70,6,CONCRETE:8)
Block(-7,70,7,CONCRETE:8)
Block(-7,70,8,CONCRETE:8)
Block(-7,71,0,CONCRETE:8)
Block(-7,71,1,CONCRETE:8)
Block(-7,71,2,STAINED_GLASS_PANE:15)
Block(-7,71,3,CONCRETE:8)
Block(-7,71,4,STAINED_GLASS_PANE:15)
Block(-7,71,5,STAINED_GLASS_PANE:15)
Block(-7,71,6,CONCRETE:8)
Block(-7,71,7,STAINED_GLASS_PANE:15)
Block(-7,71,8,CONCRETE:8)
Block(-7,72,0,CONCRETE:8)
Block(-7,72,1,CONCRETE:8)
Block(-7,72,2,STAINED_GLASS_PANE:15)
Block(-7,72,3,CONCRETE:8)
Block(-7,72,4,STAINED_GLASS_PANE:15)
Block(-7,72,5,STAINED_GLASS_PANE:15)
Block(-7,72,6,CONCRETE:8)
Block(-7,72,7,STAINED_GLASS_PANE:15)
Block(-7,72,8,CONCRETE:8)
Block(-7,73,0,CONCRETE:8)
Block(-7,73,1,CONCRETE:8)
Block(-7,73,2,CONCRETE:8)
Block(-7,73,3,CONCRETE:8)
Block(-7,73,4,CONCRETE:8)
Block(-7,73,5,CONCRETE:8)
Block(-7,73,6,CONCRETE:8)
Block(-7,73,7,CONCRETE:8)
Block(-7,73,8,CONCRETE:8)
Block(-7,74,0,CONCRETE:8)
Block(-7,74,1,CONCRETE:8)
Block(-7,74,2,CONCRETE:8)
Block(-7,74,3,CONCRETE:8)
Block(-7,74,4,CONCRETE:8)
Block(-7,74,5,CONCRETE:8)
Block(-7,74,6,CONCRETE:8)
Block(-7,74,7,CONCRETE:8)
Block(-7,74,8,CONCRETE:8)
Block(-7,75,0,CONCRETE:8)
Block(-7,75,1,CONCRETE:8)
Block(-7,75,2,STAINED_GLASS_PANE:15)
Block(-7,75,3,CONCRETE:8)
Block(-7,75,4,STAINED_GLASS_PANE:15)
Block(-7,75,5,STAINED_GLASS_PANE:15)
Block(-7,75,6,CONCRETE:8)
Block(-7,75,7,STAINED_GLASS_PANE:15)
Block(-7,75,8,CONCRETE:8)
Block(-7,76,0,CONCRETE:8)
Block(-7,76,1,CONCRETE:8)
Block(-7,76,2,STAINED_GLASS_PANE:15)
Block(-7,76,3,CONCRETE:8)
Block(-7,76,4,STAINED_GLASS_PANE:15)
Block(-7,76,5,STAINED_GLASS_PANE:15)
Block(-7,76,6,CONCRETE:8)
Block(-7,76,7,STAINED_GLASS_PANE:15)
Block(-7,76,8,CONCRETE:8)
Block(-7,77,0,CONCRETE:8)
Block(-7,77,1,CONCRETE:8)
Block(-7,77,2,CONCRETE:8)
Block(-7,77,3,CONCRETE:8)
Block(-7,77,4,CONCRETE:8)
Block(-7,77,5,CONCRETE:8)
Block(-7,77,6,CONCRETE:8)
Block(-7,77,7,CONCRETE:8)
Block(-7,77,8,CONCRETE:8)
Block(-7,78,0,CONCRETE:8)
Block(-7,78,1,CONCRETE:8)
Block(-7,78,2,CONCRETE:8)
Block(-7,78,3,CONCRETE:8)
Block(-7,78,4,CONCRETE:8)
Block(-7,78,5,CONCRETE:8)
Block(-7,78,6,CONCRETE:8)
Block(-7,78,7,CONCRETE:8)
Block(-7,78,8,CONCRETE:8)
Block(-7,79,0,CONCRETE:8)
Block(-7,79,1,CONCRETE:8)
Block(-7,79,2,STAINED_GLASS_PANE:15)
Block(-7,79,3,CONCRETE:8)
Block(-7,79,4,STAINED_GLASS_PANE:15)
Block(-7,79,5,STAINED_GLASS_PANE:15)
Block(-7,79,6,CONCRETE:8)
Block(-7,79,7,STAINED_GLASS_PANE:15)
Block(-7,79,8,CONCRETE:8)
Block(-7,80,0,CONCRETE:8)
Block(-7,80,1,CONCRETE:8)
Block(-7,80,2,STAINED_GLASS_PANE:15)
Block(-7,80,3,CONCRETE:8)
Block(-7,80,4,STAINED_GLASS_PANE:15)
Block(-7,80,5,STAINED_GLASS_PANE:15)
Block(-7,80,6,CONCRETE:8)
Block(-7,80,7,STAINED_GLASS_PANE:15)
Block(-7,80,8,CONCRETE:8)
Block(-7,81,0,CONCRETE:7)
Block(-7,81,1,CONCRETE:7)
Block(-7,81,2,CONCRETE:7)
Block(-7,81,3,CONCRETE:7)
Block(-7,81,4,CONCRETE:7)
Block(-7,81,5,CONCRETE:7)
Block(-7,81,6,CONCRETE:7)
Block(-7,81,7,CONCRETE:7)
Block(-7,81,8,CONCRETE:7)
Block(-7,82,0,CONCRETE:8)
Block(-7,82,1,CONCRETE:8)
Block(-7,82,2,CONCRETE:8)
Block(-7,82,3,CONCRETE:8)
Block(-7,82,4,CONCRETE:8)
Block(-7,82,5,CONCRETE:8)
Block(-7,82,6,CONCRETE:8)
Block(-7,82,7,CONCRETE:8)
Block(-7,82,8,CONCRETE:8)
Block(-7,83,0,CONCRETE:8)
Block(-7,83,1,CONCRETE:8)
Block(-7,83,2,STAINED_GLASS_PANE:15)
Block(-7,83,3,CONCRETE:8)
Block(-7,83,4,STAINED_GLASS_PANE:15)
Block(-7,83,5,STAINED_GLASS_PANE:15)
Block(-7,83,6,CONCRETE:8)
Block(-7,83,7,STAINED_GLASS_PANE:15)
Block(-7,83,8,CONCRETE:8)
Block(-7,84,0,CONCRETE:8)
Block(-7,84,1,CONCRETE:8)
Block(-7,84,2,STAINED_GLASS_PANE:15)
Block(-7,84,3,CONCRETE:8)
Block(-7,84,4,STAINED_GLASS_PANE:15)
Block(-7,84,5,STAINED_GLASS_PANE:15)
Block(-7,84,6,CONCRETE:8)
Block(-7,84,7,STAINED_GLASS_PANE:15)
Block(-7,84,8,CONCRETE:8)
Block(-7,85,0,CONCRETE:8)
Block(-7,85,1,CONCRETE:8)
Block(-7,85,2,CONCRETE:8)
Block(-7,85,3,CONCRETE:8)
Block(-7,85,4,CONCRETE:8)
Block(-7,85,5,CONCRETE:8)
Block(-7,85,6,CONCRETE:8)
Block(-7,85,7,CONCRETE:8)
Block(-7,85,8,CONCRETE:8)
Block(-7,86,0,CONCRETE:8)
Block(-7,86,1,CONCRETE:8)
Block(-7,86,2,CONCRETE:8)
Block(-7,86,3,CONCRETE:8)
Block(-7,86,4,CONCRETE:8)
Block(-7,86,5,CONCRETE:8)
Block(-7,86,6,CONCRETE:8)
Block(-7,86,7,CONCRETE:8)
Block(-7,86,8,CONCRETE:8)
Block(-7,87,0,CONCRETE:8)
Block(-7,87,1,CONCRETE:8)
Block(-7,87,2,STAINED_GLASS_PANE:15)
Block(-7,87,3,CONCRETE:8)
Block(-7,87,4,STAINED_GLASS_PANE:15)
Block(-7,87,5,STAINED_GLASS_PANE:15)
Block(-7,87,6,CONCRETE:8)
Block(-7,87,7,STAINED_GLASS_PANE:15)
Block(-7,87,8,CONCRETE:8)
Block(-7,88,0,CONCRETE:8)
Block(-7,88,1,CONCRETE:8)
Block(-7,88,2,STAINED_GLASS_PANE:15)
Block(-7,88,3,CONCRETE:8)
Block(-7,88,4,STAINED_GLASS_PANE:15)
Block(-7,88,5,STAINED_GLASS_PANE:15)
Block(-7,88,6,CONCRETE:8)
Block(-7,88,7,STAINED_GLASS_PANE:15)
Block(-7,88,8,CONCRETE:8)
Block(-7,89,0,CONCRETE:8)
Block(-7,89,1,CONCRETE:8)
Block(-7,89,2,CONCRETE:8)
Block(-7,89,3,CONCRETE:8)
Block(-7,89,4,CONCRETE:8)
Block(-7,89,5,CONCRETE:8)
Block(-7,89,6,CONCRETE:8)
Block(-7,89,7,CONCRETE:8)
Block(-7,89,8,CONCRETE:8)
Block(-7,90,0,CONCRETE:7)
Block(-7,90,1,IRON_FENCE:0)
Block(-7,90,2,IRON_FENCE:0)
Block(-7,90,3,IRON_FENCE:0)
Block(-7,90,4,IRON_FENCE:0)
Block(-7,90,5,IRON_FENCE:0)
Block(-7,90,6,IRON_FENCE:0)
Block(-7,90,7,IRON_FENCE:0)
Block(-7,90,8,IRON_FENCE:0)
Block(-6,0,-7,CONCRETE:7)
Block(-6,0,-6,CONCRETE:7)
Block(-6,0,-5,CONCRETE:7)
Block(-6,0,-4,CONCRETE:7)
Block(-6,0,-3,CONCRETE:7)
Block(-6,0,-2,CONCRETE:7)
Block(-6,0,-1,CONCRETE:7)
Block(-6,0,0,CONCRETE:7)
Block(-6,0,1,CONCRETE:7)
Block(-6,0,2,CONCRETE:7)
Block(-6,0,3,CONCRETE:7)
Block(-6,0,4,CONCRETE:7)
Block(-6,0,5,CONCRETE:7)
Block(-6,0,6,CONCRETE:7)
Block(-6,0,7,CONCRETE:7)
Block(-6,0,8,CONCRETE:7)
Block(-6,1,-7,CONCRETE:7)
Block(-6,1,-6,CONCRETE:7)
Block(-6,1,-5,CONCRETE:7)
Block(-6,1,-4,CONCRETE:7)
Block(-6,1,-3,CONCRETE:7)
Block(-6,1,-2,CONCRETE:7)
Block(-6,1,-1,CONCRETE:7)
Block(-6,1,0,CONCRETE:7)
Block(-6,1,1,CONCRETE:7)
Block(-6,1,2,CONCRETE:7)
Block(-6,1,3,CONCRETE:7)
Block(-6,1,4,CONCRETE:7)
Block(-6,1,5,CONCRETE:7)
Block(-6,1,6,CONCRETE:7)
Block(-6,1,7,CONCRETE:7)
Block(-6,1,8,CONCRETE:7)
Block(-6,2,-7,CONCRETE:7)
Block(-6,2,-6,CONCRETE:7)
Block(-6,2,-5,CONCRETE:7)
Block(-6,2,-4,CONCRETE:7)
Block(-6,2,-3,CONCRETE:7)
Block(-6,2,-2,CONCRETE:7)
Block(-6,2,-1,CONCRETE:7)
Block(-6,2,0,CONCRETE:7)
Block(-6,2,1,CONCRETE:7)
Block(-6,2,2,CONCRETE:7)
Block(-6,2,3,CONCRETE:7)
Block(-6,2,4,CONCRETE:7)
Block(-6,2,5,CONCRETE:7)
Block(-6,2,6,CONCRETE:7)
Block(-6,2,7,CONCRETE:7)
Block(-6,2,8,CONCRETE:7)
Block(-6,3,-7,CONCRETE:7)
Block(-6,3,-6,CONCRETE:7)
Block(-6,3,-5,CONCRETE:7)
Block(-6,3,-4,CONCRETE:7)
Block(-6,3,-3,CONCRETE:7)
Block(-6,3,-2,CONCRETE:7)
Block(-6,3,-1,CONCRETE:7)
Block(-6,3,0,CONCRETE:7)
Block(-6,3,1,CONCRETE:7)
Block(-6,3,2,CONCRETE:7)
Block(-6,3,3,CONCRETE:7)
Block(-6,3,4,CONCRETE:7)
Block(-6,3,5,CONCRETE:7)
Block(-6,3,6,CONCRETE:7)
Block(-6,3,7,CONCRETE:7)
Block(-6,3,8,CONCRETE:7)
Block(-6,4,-7,CONCRETE:7)
Block(-6,4,-6,CONCRETE:7)
Block(-6,4,-5,CONCRETE:7)
Block(-6,4,-4,CONCRETE:7)
Block(-6,4,-3,CONCRETE:7)
Block(-6,4,-2,CONCRETE:7)
Block(-6,4,-1,CONCRETE:7)
Block(-6,4,0,CONCRETE:7)
Block(-6,4,1,CONCRETE:7)
Block(-6,4,2,CONCRETE:7)
Block(-6,4,3,CONCRETE:7)
Block(-6,4,4,CONCRETE:7)
Block(-6,4,5,CONCRETE:7)
Block(-6,4,6,CONCRETE:7)
Block(-6,4,7,CONCRETE:7)
Block(-6,4,8,CONCRETE:7)
Block(-6,5,-7,CONCRETE:7)
Block(-6,5,-6,CONCRETE:7)
Block(-6,5,-5,CONCRETE:7)
Block(-6,5,-4,CONCRETE:7)
Block(-6,5,-3,CONCRETE:7)
Block(-6,5,-2,CONCRETE:7)
Block(-6,5,-1,CONCRETE:7)
Block(-6,5,0,CONCRETE:7)
Block(-6,5,1,CONCRETE:7)
Block(-6,5,2,CONCRETE:7)
Block(-6,5,3,CONCRETE:7)
Block(-6,5,4,CONCRETE:7)
Block(-6,5,5,CONCRETE:7)
Block(-6,5,6,CONCRETE:7)
Block(-6,5,7,CONCRETE:7)
Block(-6,5,8,CONCRETE:7)
Block(-6,6,-7,CONCRETE:7)
Block(-6,6,-6,CONCRETE:7)
Block(-6,6,-5,CONCRETE:7)
Block(-6,6,-4,CONCRETE:7)
Block(-6,6,-3,CONCRETE:7)
Block(-6,6,-2,CONCRETE:7)
Block(-6,6,-1,CONCRETE:7)
Block(-6,6,0,CONCRETE:7)
Block(-6,6,1,CONCRETE:7)
Block(-6,6,2,CONCRETE:7)
Block(-6,6,3,CONCRETE:7)
Block(-6,6,4,CONCRETE:7)
Block(-6,6,5,CONCRETE:7)
Block(-6,6,6,CONCRETE:7)
Block(-6,6,7,CONCRETE:7)
Block(-6,6,8,CONCRETE:7)
Block(-6,7,-7,CONCRETE:7)
Block(-6,7,-6,CONCRETE:7)
Block(-6,7,-5,CONCRETE:7)
Block(-6,7,-4,CONCRETE:7)
Block(-6,7,-3,CONCRETE:7)
Block(-6,7,-2,CONCRETE:7)
Block(-6,7,-1,CONCRETE:7)
Block(-6,7,0,CONCRETE:7)
Block(-6,7,1,CONCRETE:7)
Block(-6,7,2,CONCRETE:7)
Block(-6,7,3,CONCRETE:7)
Block(-6,7,4,CONCRETE:7)
Block(-6,7,5,CONCRETE:7)
Block(-6,7,6,CONCRETE:7)
Block(-6,7,7,CONCRETE:7)
Block(-6,7,8,CONCRETE:7)
Block(-6,8,-7,CONCRETE:7)
Block(-6,8,-6,CONCRETE:7)
Block(-6,8,-5,CONCRETE:7)
Block(-6,8,-4,CONCRETE:7)
Block(-6,8,-3,CONCRETE:7)
Block(-6,8,-2,CONCRETE:7)
Block(-6,8,-1,CONCRETE:7)
Block(-6,8,0,CONCRETE:7)
Block(-6,8,1,CONCRETE:7)
Block(-6,8,2,CONCRETE:7)
Block(-6,8,3,CONCRETE:7)
Block(-6,8,4,CONCRETE:7)
Block(-6,8,5,CONCRETE:7)
Block(-6,8,6,CONCRETE:7)
Block(-6,8,7,CONCRETE:7)
Block(-6,8,8,CONCRETE:7)
Block(-6,9,-7,CONCRETE:7)
Block(-6,9,-6,CONCRETE:7)
Block(-6,9,-5,CONCRETE:7)
Block(-6,9,-4,CONCRETE:7)
Block(-6,9,-3,CONCRETE:7)
Block(-6,9,-2,CONCRETE:7)
Block(-6,9,-1,CONCRETE:7)
Block(-6,9,0,CONCRETE:7)
Block(-6,9,1,CONCRETE:7)
Block(-6,9,2,CONCRETE:7)
Block(-6,9,3,CONCRETE:7)
Block(-6,9,4,CONCRETE:7)
Block(-6,9,5,CONCRETE:7)
Block(-6,9,6,CONCRETE:7)
Block(-6,9,7,CONCRETE:7)
Block(-6,9,8,CONCRETE:7)
Block(-6,10,-7,CONCRETE:7)
Block(-6,10,-6,CONCRETE:7)
Block(-6,10,-5,CONCRETE:7)
Block(-6,10,-4,CONCRETE:7)
Block(-6,10,-3,CONCRETE:7)
Block(-6,10,-2,CONCRETE:7)
Block(-6,10,-1,CONCRETE:7)
Block(-6,10,0,CONCRETE:7)
Block(-6,10,1,CONCRETE:7)
Block(-6,10,2,CONCRETE:7)
Block(-6,10,3,CONCRETE:7)
Block(-6,10,4,CONCRETE:7)
Block(-6,10,5,CONCRETE:7)
Block(-6,10,6,CONCRETE:7)
Block(-6,10,7,CONCRETE:7)
Block(-6,10,8,CONCRETE:7)
Block(-6,11,-7,CONCRETE:7)
Block(-6,11,-6,CONCRETE:7)
Block(-6,11,-5,CONCRETE:7)
Block(-6,11,-4,CONCRETE:7)
Block(-6,11,-3,CONCRETE:7)
Block(-6,11,-2,CONCRETE:7)
Block(-6,11,-1,CONCRETE:7)
Block(-6,11,0,CONCRETE:7)
Block(-6,11,1,CONCRETE:7)
Block(-6,11,2,CONCRETE:7)
Block(-6,11,3,CONCRETE:7)
Block(-6,11,4,CONCRETE:7)
Block(-6,11,5,CONCRETE:7)
Block(-6,11,6,CONCRETE:7)
Block(-6,11,7,CONCRETE:7)
Block(-6,11,8,CONCRETE:7)
Block(-6,12,-7,CONCRETE:7)
Block(-6,12,-6,CONCRETE:7)
Block(-6,12,-5,CONCRETE:7)
Block(-6,12,-4,CONCRETE:7)
Block(-6,12,-3,CONCRETE:7)
Block(-6,12,-2,CONCRETE:7)
Block(-6,12,-1,CONCRETE:7)
Block(-6,12,0,CONCRETE:7)
Block(-6,12,1,CONCRETE:7)
Block(-6,12,2,CONCRETE:7)
Block(-6,12,3,CONCRETE:7)
Block(-6,12,4,CONCRETE:7)
Block(-6,12,5,CONCRETE:7)
Block(-6,12,6,CONCRETE:7)
Block(-6,12,7,CONCRETE:7)
Block(-6,12,8,CONCRETE:7)
Block(-6,13,-7,CONCRETE:7)
Block(-6,13,-6,CONCRETE:7)
Block(-6,13,-5,CONCRETE:7)
Block(-6,13,-4,CONCRETE:7)
Block(-6,13,-3,CONCRETE:7)
Block(-6,13,-2,CONCRETE:7)
Block(-6,13,-1,CONCRETE:7)
Block(-6,13,0,CONCRETE:7)
Block(-6,13,1,CONCRETE:7)
Block(-6,13,2,CONCRETE:7)
Block(-6,13,3,CONCRETE:7)
Block(-6,13,4,CONCRETE:7)
Block(-6,13,5,CONCRETE:7)
Block(-6,13,6,CONCRETE:7)
Block(-6,13,7,CONCRETE:7)
Block(-6,13,8,CONCRETE:7)
Block(-6,14,-7,CONCRETE:7)
Block(-6,14,-6,CONCRETE:7)
Block(-6,14,-5,CONCRETE:7)
Block(-6,14,-4,CONCRETE:7)
Block(-6,14,-3,CONCRETE:7)
Block(-6,14,-2,CONCRETE:7)
Block(-6,14,-1,CONCRETE:7)
Block(-6,14,0,CONCRETE:7)
Block(-6,14,1,CONCRETE:7)
Block(-6,14,2,CONCRETE:7)
RandomBlock(-6,14,3,AIR,90,IRON_TRAPDOOR:9,100)
Block(-6,14,4,AIR:0)
Block(-6,14,5,BOOKSHELF:0)
Block(-6,14,6,CONCRETE:7)
Block(-6,14,7,AIR:0)
Block(-6,14,8,AIR:0)
Block(-6,15,-7,CONCRETE:7)
Block(-6,15,-6,CONCRETE:7)
Block(-6,15,-5,CONCRETE:7)
Block(-6,15,-4,CONCRETE:7)
Block(-6,15,-3,CONCRETE:7)
Block(-6,15,-2,CONCRETE:7)
Block(-6,15,-1,CONCRETE:7)
Block(-6,15,0,CONCRETE:7)
Block(-6,15,1,CONCRETE:7)
Block(-6,15,2,CONCRETE:7)
RandomBlock(-6,15,3,AIR,90,IRON_TRAPDOOR:9,100)
Block(-6,15,4,AIR:0)
Block(-6,15,5,BOOKSHELF:0)
Block(-6,15,6,CONCRETE:7)
RandomBlock(-6,15,7,AIR,90,IRON_TRAPDOOR:11,100)
RandomBlock(-6,15,8,AIR,90,IRON_TRAPDOOR:11,100)
Block(-6,16,-7,CONCRETE:7)
Block(-6,16,-6,CONCRETE:7)
Block(-6,16,-5,CONCRETE:7)
Block(-6,16,-4,CONCRETE:7)
Block(-6,16,-3,CONCRETE:7)
Block(-6,16,-2,CONCRETE:7)
Block(-6,16,-1,CONCRETE:7)
Block(-6,16,0,CONCRETE:7)
Block(-6,16,1,CONCRETE:7)
Block(-6,16,2,CONCRETE:7)
Block(-6,16,3,STEP:8)
Block(-6,16,4,STEP:8)
Block(-6,16,5,STEP:8)
Block(-6,16,6,CONCRETE:7)
Block(-6,16,7,STEP:8)
Block(-6,16,8,STEP:8)
Block(-6,17,-7,DOUBLE_STEP:0)
Block(-6,17,-6,CONCRETE:7)
Block(-6,17,-5,SMOOTH_BRICK:0)
Block(-6,17,-4,SMOOTH_BRICK:0)
Block(-6,17,-3,SMOOTH_BRICK:0)
Block(-6,17,-2,SMOOTH_BRICK:2)
Block(-6,17,-1,CONCRETE:7)
Block(-6,17,0,CONCRETE:7)
Block(-6,17,1,CONCRETE:7)
Block(-6,17,2,CONCRETE:7)
Block(-6,17,3,CONCRETE:7)
Block(-6,17,4,CONCRETE:7)
Block(-6,17,5,CONCRETE:7)
Block(-6,17,6,CONCRETE:7)
Block(-6,17,7,CONCRETE:7)
Block(-6,17,8,CONCRETE:7)
Block(-6,18,0,CONCRETE:7)
Block(-6,18,1,CARPET:3)
Block(-6,18,2,CARPET:3)
RandomBlock(-6,18,3,AIR,90,WALL_SIGN:2,../AllScraperData/skyscraper_2x2_05/2-signC0R0.nbt,100)
RandomBlock(-6,18,4,minecraft:wooden_slab:5,95,BED_BLOCK:0,../AllScraperData/skyscraper_2x2_05/3-bedC0R0.nbt,100)
RandomBlock(-6,18,5,minecraft:wooden_slab:5,95,BED_BLOCK:8,../AllScraperData/skyscraper_2x2_05/4-bedC0R0.nbt,100)
Block(-6,18,6,CONCRETE:7)
RandomBlock(-6,18,7,AIR,95,STANDING_BANNER:14,../AllScraperData/skyscraper_2x2_05/5-bannerC0R0.nbt,100)
Block(-6,18,8,DARK_OAK_STAIRS:2)
Block(-6,19,0,CONCRETE:7)
Block(-6,19,6,CONCRETE:7)
RandomBlock(-6,19,7,AIR,90,IRON_TRAPDOOR:1,100)
RandomBlock(-6,19,8,AIR,95,WALL_BANNER:2,../AllScraperData/skyscraper_2x2_05/9-bannerC0R0.nbt,100)
Block(-6,20,0,CONCRETE:7)
RandomBlock(-6,20,2,AIR,95,WALL_BANNER:5,../AllScraperData/skyscraper_2x2_05/10-bannerC0R0.nbt,100)
RandomBlock(-6,20,4,AIR,95,WALL_BANNER:5,../AllScraperData/skyscraper_2x2_05/11-bannerC0R0.nbt,100)
RandomBlock(-6,20,5,AIR,95,WALL_BANNER:5,../AllScraperData/skyscraper_2x2_05/12-bannerC0R0.nbt,100)
Block(-6,20,6,CONCRETE:7)
RandomBlock(-6,20,7,AIR,95,WALL_BANNER:5,../AllScraperData/skyscraper_2x2_05/13-bannerC0R0.nbt,100)
Block(-6,21,0,CONCRETE:7)
Block(-6,21,1,STEP:8)
Block(-6,21,2,STEP:8)
Block(-6,21,3,STEP:8)
Block(-6,21,4,STEP:8)
Block(-6,21,5,STEP:8)
Block(-6,21,6,CONCRETE:7)
Block(-6,21,7,STEP:8)
Block(-6,21,8,STEP:8)
Block(-6,22,0,CONCRETE:7)
Block(-6,22,1,CARPET:10)
Block(-6,22,2,CARPET:10)
RandomBlock(-6,22,3,AIR,90,WALL_SIGN:2,../AllScraperData/skyscraper_2x2_05/16-signC0R0.nbt,100)
RandomBlock(-6,22,4,minecraft:wooden_slab:5,95,BED_BLOCK:0,../AllScraperData/skyscraper_2x2_05/17-bedC0R0.nbt,100)
RandomBlock(-6,22,5,minecraft:wooden_slab:5,95,BED_BLOCK:8,../AllScraperData/skyscraper_2x2_05/18-bedC0R0.nbt,100)
Block(-6,22,6,CONCRETE:7)
RandomBlock(-6,22,7,minecraft:wooden_slab:5,95,BED_BLOCK:10,../AllScraperData/skyscraper_2x2_05/19-bedC0R0.nbt,100)
RandomBlock(-6,22,8,minecraft:wooden_slab:5,95,BED_BLOCK:2,../AllScraperData/skyscraper_2x2_05/20-bedC0R0.nbt,100)
Block(-6,23,0,CONCRETE:7)
Block(-6,23,6,CONCRETE:7)
Block(-6,24,0,CONCRETE:7)
RandomBlock(-6,24,2,AIR,95,WALL_BANNER:5,../AllScraperData/skyscraper_2x2_05/23-bannerC0R0.nbt,100)
RandomBlock(-6,24,4,AIR,95,WALL_BANNER:5,../AllScraperData/skyscraper_2x2_05/24-bannerC0R0.nbt,100)
RandomBlock(-6,24,5,AIR,95,WALL_BANNER:5,../AllScraperData/skyscraper_2x2_05/25-bannerC0R0.nbt,100)
Block(-6,24,6,CONCRETE:7)
RandomBlock(-6,24,7,AIR,95,WALL_BANNER:5,../AllScraperData/skyscraper_2x2_05/26-bannerC0R0.nbt,100)
Block(-6,25,0,CONCRETE:7)
Block(-6,25,1,STEP:8)
Block(-6,25,2,STEP:8)
Block(-6,25,3,STEP:8)
Block(-6,25,4,STEP:8)
Block(-6,25,5,STEP:8)
Block(-6,25,6,CONCRETE:7)
Block(-6,25,7,STEP:8)
Block(-6,25,8,STEP:8)
Block(-6,26,0,CONCRETE:7)
Block(-6,26,1,CARPET:10)
Block(-6,26,2,CARPET:10)
RandomBlock(-6,26,3,AIR,90,WALL_SIGN:2,../AllScraperData/skyscraper_2x2_05/29-signC0R0.nbt,100)
RandomBlock(-6,26,4,minecraft:wooden_slab:5,95,BED_BLOCK:0,../AllScraperData/skyscraper_2x2_05/30-bedC0R0.nbt,100)
RandomBlock(-6,26,5,minecraft:wooden_slab:5,95,BED_BLOCK:8,../AllScraperData/skyscraper_2x2_05/31-bedC0R0.nbt,100)
Block(-6,26,6,CONCRETE:7)
RandomBlock(-6,26,7,minecraft:wooden_slab:5,95,BED_BLOCK:10,../AllScraperData/skyscraper_2x2_05/32-bedC0R0.nbt,100)
RandomBlock(-6,26,8,minecraft:wooden_slab:5,95,BED_BLOCK:2,../AllScraperData/skyscraper_2x2_05/33-bedC0R0.nbt,100)
Block(-6,27,0,CONCRETE:7)
Block(-6,27,6,CONCRETE:7)
Block(-6,28,0,CONCRETE:7)
RandomBlock(-6,28,2,AIR,95,WALL_BANNER:5,../AllScraperData/skyscraper_2x2_05/36-bannerC0R0.nbt,100)
RandomBlock(-6,28,4,AIR,95,WALL_BANNER:5,../AllScraperData/skyscraper_2x2_05/37-bannerC0R0.nbt,100)
RandomBlock(-6,28,5,AIR,95,WALL_BANNER:5,../AllScraperData/skyscraper_2x2_05/38-bannerC0R0.nbt,100)
Block(-6,28,6,CONCRETE:7)
RandomBlock(-6,28,7,AIR,95,WALL_BANNER:5,../AllScraperData/skyscraper_2x2_05/39-bannerC0R0.nbt,100)
Block(-6,29,0,CONCRETE:7)
Block(-6,29,1,STEP:8)
Block(-6,29,2,STEP:8)
Block(-6,29,3,STEP:8)
Block(-6,29,4,STEP:8)
Block(-6,29,5,STEP:8)
Block(-6,29,6,CONCRETE:7)
Block(-6,29,7,STEP:8)
Block(-6,29,8,STEP:8)
Block(-6,30,0,CONCRETE:7)
Block(-6,30,1,CARPET:10)
Block(-6,30,2,CARPET:10)
RandomBlock(-6,30,3,AIR,90,WALL_SIGN:2,../AllScraperData/skyscraper_2x2_05/42-signC0R0.nbt,100)
RandomBlock(-6,30,4,minecraft:wooden_slab:5,95,BED_BLOCK:0,../AllScraperData/skyscraper_2x2_05/43-bedC0R0.nbt,100)
RandomBlock(-6,30,5,minecraft:wooden_slab:5,95,BED_BLOCK:8,../AllScraperData/skyscraper_2x2_05/44-bedC0R0.nbt,100)
Block(-6,30,6,CONCRETE:7)
RandomBlock(-6,30,7,minecraft:wooden_slab:5,95,BED_BLOCK:10,../AllScraperData/skyscraper_2x2_05/45-bedC0R0.nbt,100)
RandomBlock(-6,30,8,minecraft:wooden_slab:5,95,BED_BLOCK:2,../AllScraperData/skyscraper_2x2_05/46-bedC0R0.nbt,100)
Block(-6,31,0,CONCRETE:7)
Block(-6,31,6,CONCRETE:7)
Block(-6,32,0,CONCRETE:7)
RandomBlock(-6,32,2,AIR,95,WALL_BANNER:5,../AllScraperData/skyscraper_2x2_05/49-bannerC0R0.nbt,100)
RandomBlock(-6,32,4,AIR,95,WALL_BANNER:5,../AllScraperData/skyscraper_2x2_05/50-bannerC0R0.nbt,100)
RandomBlock(-6,32,5,AIR,95,WALL_BANNER:5,../AllScraperData/skyscraper_2x2_05/51-bannerC0R0.nbt,100)
Block(-6,32,6,CONCRETE:7)
RandomBlock(-6,32,7,AIR,95,WALL_BANNER:5,../AllScraperData/skyscraper_2x2_05/52-bannerC0R0.nbt,100)
Block(-6,33,0,CONCRETE:7)
Block(-6,33,1,STEP:8)
Block(-6,33,2,STEP:8)
Block(-6,33,3,STEP:8)
Block(-6,33,4,STEP:8)
Block(-6,33,5,STEP:8)
Block(-6,33,6,CONCRETE:7)
Block(-6,33,7,STEP:8)
Block(-6,33,8,STEP:8)
Block(-6,34,0,CONCRETE:7)
Block(-6,34,1,CARPET:10)
Block(-6,34,2,CARPET:10)
RandomBlock(-6,34,3,AIR,90,WALL_SIGN:2,../AllScraperData/skyscraper_2x2_05/55-signC0R0.nbt,100)
RandomBlock(-6,34,4,minecraft:wooden_slab:5,95,BED_BLOCK:0,../AllScraperData/skyscraper_2x2_05/56-bedC0R0.nbt,100)
RandomBlock(-6,34,5,minecraft:wooden_slab:5,95,BED_BLOCK:8,../AllScraperData/skyscraper_2x2_05/57-bedC0R0.nbt,100)
Block(-6,34,6,CONCRETE:7)
RandomBlock(-6,34,7,minecraft:wooden_slab:5,95,BED_BLOCK:10,../AllScraperData/skyscraper_2x2_05/58-bedC0R0.nbt,100)
RandomBlock(-6,34,8,minecraft:wooden_slab:5,95,BED_BLOCK:2,../AllScraperData/skyscraper_2x2_05/59-bedC0R0.nbt,100)
Block(-6,35,0,CONCRETE:7)
Block(-6,35,6,CONCRETE:7)
Block(-6,36,0,CONCRETE:7)
RandomBlock(-6,36,2,AIR,95,WALL_BANNER:5,../AllScraperData/skyscraper_2x2_05/62-bannerC0R0.nbt,100)
RandomBlock(-6,36,4,AIR,95,WALL_BANNER:5,../AllScraperData/skyscraper_2x2_05/63-bannerC0R0.nbt,100)
RandomBlock(-6,36,5,AIR,95,WALL_BANNER:5,../AllScraperData/skyscraper_2x2_05/64-bannerC0R0.nbt,100)
Block(-6,36,6,CONCRETE:7)
RandomBlock(-6,36,7,AIR,95,WALL_BANNER:5,../AllScraperData/skyscraper_2x2_05/65-bannerC0R0.nbt,100)
Block(-6,37,0,CONCRETE:7)
Block(-6,37,1,STEP:8)
Block(-6,37,2,STEP:8)
Block(-6,37,3,STEP:8)
Block(-6,37,4,STEP:8)
Block(-6,37,5,STEP:8)
Block(-6,37,6,CONCRETE:7)
Block(-6,37,7,STEP:8)
Block(-6,37,8,STEP:8)
Block(-6,38,0,CONCRETE:8)
Block(-6,38,1,CARPET:10)
Block(-6,38,2,CARPET:10)
RandomBlock(-6,38,3,AIR,90,WALL_SIGN:2,../AllScraperData/skyscraper_2x2_05/68-signC0R0.nbt,100)
RandomBlock(-6,38,4,minecraft:wooden_slab:5,95,BED_BLOCK:0,../AllScraperData/skyscraper_2x2_05/69-bedC0R0.nbt,100)
RandomBlock(-6,38,5,minecraft:wooden_slab:5,95,BED_BLOCK:8,../AllScraperData/skyscraper_2x2_05/70-bedC0R0.nbt,100)
Block(-6,38,6,CONCRETE:8)
RandomBlock(-6,38,7,minecraft:wooden_slab:5,95,BED_BLOCK:10,../AllScraperData/skyscraper_2x2_05/71-bedC0R0.nbt,100)
RandomBlock(-6,38,8,minecraft:wooden_slab:5,95,BED_BLOCK:2,../AllScraperData/skyscraper_2x2_05/72-bedC0R0.nbt,100)
Block(-6,39,0,CONCRETE:8)
Block(-6,39,6,CONCRETE:8)
Block(-6,40,0,CONCRETE:8)
RandomBlock(-6,40,2,AIR,95,WALL_BANNER:5,../AllScraperData/skyscraper_2x2_05/75-bannerC0R0.nbt,100)
RandomBlock(-6,40,4,AIR,95,WALL_BANNER:5,../AllScraperData/skyscraper_2x2_05/76-bannerC0R0.nbt,100)
RandomBlock(-6,40,5,AIR,95,WALL_BANNER:5,../AllScraperData/skyscraper_2x2_05/77-bannerC0R0.nbt,100)
Block(-6,40,6,CONCRETE:8)
RandomBlock(-6,40,7,AIR,95,WALL_BANNER:5,../AllScraperData/skyscraper_2x2_05/78-bannerC0R0.nbt,100)
Block(-6,41,0,CONCRETE:8)
Block(-6,41,1,STEP:8)
Block(-6,41,2,STEP:8)
Block(-6,41,3,STEP:8)
Block(-6,41,4,STEP:8)
Block(-6,41,5,STEP:8)
Block(-6,41,6,CONCRETE:8)
Block(-6,41,7,STEP:8)
Block(-6,41,8,STEP:8)
Block(-6,42,0,CONCRETE:8)
Block(-6,42,1,CARPET:10)
Block(-6,42,2,CARPET:10)
RandomBlock(-6,42,3,AIR,90,WALL_SIGN:2,../AllScraperData/skyscraper_2x2_05/81-signC0R0.nbt,100)
RandomBlock(-6,42,4,minecraft:wooden_slab:5,95,BED_BLOCK:0,../AllScraperData/skyscraper_2x2_05/82-bedC0R0.nbt,100)
RandomBlock(-6,42,5,minecraft:wooden_slab:5,95,BED_BLOCK:8,../AllScraperData/skyscraper_2x2_05/83-bedC0R0.nbt,100)
Block(-6,42,6,CONCRETE:8)
RandomBlock(-6,42,7,minecraft:wooden_slab:5,95,BED_BLOCK:10,../AllScraperData/skyscraper_2x2_05/84-bedC0R0.nbt,100)
RandomBlock(-6,42,8,minecraft:wooden_slab:5,95,BED_BLOCK:2,../AllScraperData/skyscraper_2x2_05/85-bedC0R0.nbt,100)
Block(-6,43,0,CONCRETE:8)
Block(-6,43,6,CONCRETE:8)
Block(-6,44,0,CONCRETE:8)
RandomBlock(-6,44,2,AIR,95,WALL_BANNER:5,../AllScraperData/skyscraper_2x2_05/88-bannerC0R0.nbt,100)
RandomBlock(-6,44,4,AIR,95,WALL_BANNER:5,../AllScraperData/skyscraper_2x2_05/89-bannerC0R0.nbt,100)
RandomBlock(-6,44,5,AIR,95,WALL_BANNER:5,../AllScraperData/skyscraper_2x2_05/90-bannerC0R0.nbt,100)
Block(-6,44,6,CONCRETE:8)
RandomBlock(-6,44,7,AIR,95,WALL_BANNER:5,../AllScraperData/skyscraper_2x2_05/91-bannerC0R0.nbt,100)
Block(-6,45,0,CONCRETE:8)
Block(-6,45,1,STEP:8)
Block(-6,45,2,STEP:8)
Block(-6,45,3,STEP:8)
Block(-6,45,4,STEP:8)
Block(-6,45,5,STEP:8)
Block(-6,45,6,CONCRETE:8)
Block(-6,45,7,STEP:8)
Block(-6,45,8,STEP:8)
Block(-6,46,0,CONCRETE:8)
Block(-6,46,1,CARPET:10)
Block(-6,46,2,CARPET:10)
RandomBlock(-6,46,3,AIR,90,WALL_SIGN:2,../AllScraperData/skyscraper_2x2_05/94-signC0R0.nbt,100)
RandomBlock(-6,46,4,minecraft:wooden_slab:5,95,BED_BLOCK:0,../AllScraperData/skyscraper_2x2_05/95-bedC0R0.nbt,100)
RandomBlock(-6,46,5,minecraft:wooden_slab:5,95,BED_BLOCK:8,../AllScraperData/skyscraper_2x2_05/96-bedC0R0.nbt,100)
Block(-6,46,6,CONCRETE:8)
RandomBlock(-6,46,7,minecraft:wooden_slab:5,95,BED_BLOCK:10,../AllScraperData/skyscraper_2x2_05/97-bedC0R0.nbt,100)
RandomBlock(-6,46,8,minecraft:wooden_slab:5,95,BED_BLOCK:2,../AllScraperData/skyscraper_2x2_05/98-bedC0R0.nbt,100)
Block(-6,47,0,CONCRETE:8)
Block(-6,47,6,CONCRETE:8)
Block(-6,48,0,CONCRETE:8)
RandomBlock(-6,48,2,AIR,95,WALL_BANNER:5,../AllScraperData/skyscraper_2x2_05/101-bannerC0R0.nbt,100)
RandomBlock(-6,48,4,AIR,95,WALL_BANNER:5,../AllScraperData/skyscraper_2x2_05/102-bannerC0R0.nbt,100)
RandomBlock(-6,48,5,AIR,95,WALL_BANNER:5,../AllScraperData/skyscraper_2x2_05/103-bannerC0R0.nbt,100)
Block(-6,48,6,CONCRETE:8)
RandomBlock(-6,48,7,AIR,95,WALL_BANNER:5,../AllScraperData/skyscraper_2x2_05/104-bannerC0R0.nbt,100)
Block(-6,49,0,CONCRETE:7)
Block(-6,49,1,STEP:8)
Block(-6,49,2,STEP:8)
Block(-6,49,3,STEP:8)
Block(-6,49,4,STEP:8)
Block(-6,49,5,STEP:8)
Block(-6,49,6,CONCRETE:7)
Block(-6,49,7,STEP:8)
Block(-6,49,8,STEP:8)
Block(-6,50,0,CONCRETE:8)
Block(-6,50,1,CARPET:10)
Block(-6,50,2,CARPET:10)
RandomBlock(-6,50,3,AIR,90,WALL_SIGN:2,../AllScraperData/skyscraper_2x2_05/107-signC0R0.nbt,100)
RandomBlock(-6,50,4,minecraft:wooden_slab:5,95,BED_BLOCK:0,../AllScraperData/skyscraper_2x2_05/108-bedC0R0.nbt,100)
RandomBlock(-6,50,5,minecraft:wooden_slab:5,95,BED_BLOCK:8,../AllScraperData/skyscraper_2x2_05/109-bedC0R0.nbt,100)
Block(-6,50,6,CONCRETE:8)
RandomBlock(-6,50,7,minecraft:wooden_slab:5,95,BED_BLOCK:10,../AllScraperData/skyscraper_2x2_05/110-bedC0R0.nbt,100)
RandomBlock(-6,50,8,minecraft:wooden_slab:5,95,BED_BLOCK:2,../AllScraperData/skyscraper_2x2_05/111-bedC0R0.nbt,100)
Block(-6,51,0,CONCRETE:8)
Block(-6,51,6,CONCRETE:8)
Block(-6,52,0,CONCRETE:8)
RandomBlock(-6,52,2,AIR,95,WALL_BANNER:5,../AllScraperData/skyscraper_2x2_05/114-bannerC0R0.nbt,100)
RandomBlock(-6,52,4,AIR,95,WALL_BANNER:5,../AllScraperData/skyscraper_2x2_05/115-bannerC0R0.nbt,100)
RandomBlock(-6,52,5,AIR,95,WALL_BANNER:5,../AllScraperData/skyscraper_2x2_05/116-bannerC0R0.nbt,100)
Block(-6,52,6,CONCRETE:8)
RandomBlock(-6,52,7,AIR,95,WALL_BANNER:5,../AllScraperData/skyscraper_2x2_05/117-bannerC0R0.nbt,100)
Block(-6,53,0,CONCRETE:7)
Block(-6,53,1,STEP:8)
Block(-6,53,2,STEP:8)
Block(-6,53,3,STEP:8)
Block(-6,53,4,STEP:8)
Block(-6,53,5,STEP:8)
Block(-6,53,6,CONCRETE:7)
Block(-6,53,7,STEP:8)
Block(-6,53,8,STEP:8)
Block(-6,54,0,CONCRETE:8)
Block(-6,54,1,CARPET:10)
Block(-6,54,2,CARPET:10)
RandomBlock(-6,54,3,AIR,90,WALL_SIGN:2,../AllScraperData/skyscraper_2x2_05/120-signC0R0.nbt,100)
RandomBlock(-6,54,4,minecraft:wooden_slab:5,95,BED_BLOCK:0,../AllScraperData/skyscraper_2x2_05/121-bedC0R0.nbt,100)
RandomBlock(-6,54,5,minecraft:wooden_slab:5,95,BED_BLOCK:8,../AllScraperData/skyscraper_2x2_05/122-bedC0R0.nbt,100)
Block(-6,54,6,CONCRETE:8)
RandomBlock(-6,54,7,minecraft:wooden_slab:5,95,BED_BLOCK:10,../AllScraperData/skyscraper_2x2_05/123-bedC0R0.nbt,100)
RandomBlock(-6,54,8,minecraft:wooden_slab:5,95,BED_BLOCK:2,../AllScraperData/skyscraper_2x2_05/124-bedC0R0.nbt,100)
Block(-6,55,0,CONCRETE:8)
Block(-6,55,6,CONCRETE:8)
Block(-6,56,0,CONCRETE:8)
RandomBlock(-6,56,2,AIR,95,WALL_BANNER:5,../AllScraperData/skyscraper_2x2_05/127-bannerC0R0.nbt,100)
RandomBlock(-6,56,4,AIR,95,WALL_BANNER:5,../AllScraperData/skyscraper_2x2_05/128-bannerC0R0.nbt,100)
RandomBlock(-6,56,5,AIR,95,WALL_BANNER:5,../AllScraperData/skyscraper_2x2_05/129-bannerC0R0.nbt,100)
Block(-6,56,6,CONCRETE:8)
RandomBlock(-6,56,7,AIR,95,WALL_BANNER:5,../AllScraperData/skyscraper_2x2_05/130-bannerC0R0.nbt,100)
Block(-6,57,0,CONCRETE:8)
Block(-6,57,1,STEP:8)
Block(-6,57,2,STEP:8)
Block(-6,57,3,STEP:8)
Block(-6,57,4,STEP:8)
Block(-6,57,5,STEP:8)
Block(-6,57,6,CONCRETE:8)
Block(-6,57,7,STEP:8)
Block(-6,57,8,STEP:8)
Block(-6,58,0,CONCRETE:8)
Block(-6,58,1,CARPET:10)
Block(-6,58,2,CARPET:10)
RandomBlock(-6,58,3,AIR,90,WALL_SIGN:2,../AllScraperData/skyscraper_2x2_05/133-signC0R0.nbt,100)
RandomBlock(-6,58,4,minecraft:wooden_slab:5,95,BED_BLOCK:0,../AllScraperData/skyscraper_2x2_05/134-bedC0R0.nbt,100)
RandomBlock(-6,58,5,minecraft:wooden_slab:5,95,BED_BLOCK:8,../AllScraperData/skyscraper_2x2_05/135-bedC0R0.nbt,100)
Block(-6,58,6,CONCRETE:8)
RandomBlock(-6,58,7,minecraft:wooden_slab:5,95,BED_BLOCK:10,../AllScraperData/skyscraper_2x2_05/136-bedC0R0.nbt,100)
RandomBlock(-6,58,8,minecraft:wooden_slab:5,95,BED_BLOCK:2,../AllScraperData/skyscraper_2x2_05/137-bedC0R0.nbt,100)
Block(-6,59,0,CONCRETE:8)
Block(-6,59,6,CONCRETE:8)
Block(-6,60,0,CONCRETE:8)
RandomBlock(-6,60,2,AIR,95,WALL_BANNER:5,../AllScraperData/skyscraper_2x2_05/140-bannerC0R0.nbt,100)
RandomBlock(-6,60,4,AIR,95,WALL_BANNER:5,../AllScraperData/skyscraper_2x2_05/141-bannerC0R0.nbt,100)
RandomBlock(-6,60,5,AIR,95,WALL_BANNER:5,../AllScraperData/skyscraper_2x2_05/142-bannerC0R0.nbt,100)
Block(-6,60,6,CONCRETE:8)
RandomBlock(-6,60,7,AIR,95,WALL_BANNER:5,../AllScraperData/skyscraper_2x2_05/143-bannerC0R0.nbt,100)
Block(-6,61,0,CONCRETE:8)
Block(-6,61,1,STEP:8)
Block(-6,61,2,STEP:8)
Block(-6,61,3,STEP:8)
Block(-6,61,4,STEP:8)
Block(-6,61,5,STEP:8)
Block(-6,61,6,CONCRETE:8)
Block(-6,61,7,STEP:8)
Block(-6,61,8,STEP:8)
Block(-6,62,0,CONCRETE:8)
Block(-6,62,1,CARPET:10)
Block(-6,62,2,CARPET:10)
RandomBlock(-6,62,3,AIR,90,WALL_SIGN:2,../AllScraperData/skyscraper_2x2_05/146-signC0R0.nbt,100)
RandomBlock(-6,62,4,minecraft:wooden_slab:5,95,BED_BLOCK:0,../AllScraperData/skyscraper_2x2_05/147-bedC0R0.nbt,100)
RandomBlock(-6,62,5,minecraft:wooden_slab:5,95,BED_BLOCK:8,../AllScraperData/skyscraper_2x2_05/148-bedC0R0.nbt,100)
Block(-6,62,6,CONCRETE:8)
RandomBlock(-6,62,7,minecraft:wooden_slab:5,95,BED_BLOCK:10,../AllScraperData/skyscraper_2x2_05/149-bedC0R0.nbt,100)
RandomBlock(-6,62,8,minecraft:wooden_slab:5,95,BED_BLOCK:2,../AllScraperData/skyscraper_2x2_05/150-bedC0R0.nbt,100)
Block(-6,63,0,CONCRETE:8)
Block(-6,63,6,CONCRETE:8)
Block(-6,64,0,CONCRETE:8)
RandomBlock(-6,64,2,AIR,95,WALL_BANNER:5,../AllScraperData/skyscraper_2x2_05/153-bannerC0R0.nbt,100)
RandomBlock(-6,64,4,AIR,95,WALL_BANNER:5,../AllScraperData/skyscraper_2x2_05/154-bannerC0R0.nbt,100)
RandomBlock(-6,64,5,AIR,95,WALL_BANNER:5,../AllScraperData/skyscraper_2x2_05/155-bannerC0R0.nbt,100)
Block(-6,64,6,CONCRETE:8)
RandomBlock(-6,64,7,AIR,95,WALL_BANNER:5,../AllScraperData/skyscraper_2x2_05/156-bannerC0R0.nbt,100)
Block(-6,65,0,CONCRETE:8)
Block(-6,65,1,STEP:8)
Block(-6,65,2,STEP:8)
Block(-6,65,3,STEP:8)
Block(-6,65,4,STEP:8)
Block(-6,65,5,STEP:8)
Block(-6,65,6,CONCRETE:8)
Block(-6,65,7,STEP:8)
Block(-6,65,8,STEP:8)
Block(-6,66,0,CONCRETE:8)
Block(-6,66,1,CARPET:10)
Block(-6,66,2,CARPET:10)
RandomBlock(-6,66,3,AIR,90,WALL_SIGN:2,../AllScraperData/skyscraper_2x2_05/159-signC0R0.nbt,100)
RandomBlock(-6,66,4,minecraft:wooden_slab:5,95,BED_BLOCK:0,../AllScraperData/skyscraper_2x2_05/160-bedC0R0.nbt,100)
RandomBlock(-6,66,5,minecraft:wooden_slab:5,95,BED_BLOCK:8,../AllScraperData/skyscraper_2x2_05/161-bedC0R0.nbt,100)
Block(-6,66,6,CONCRETE:8)
RandomBlock(-6,66,7,minecraft:wooden_slab:5,95,BED_BLOCK:10,../AllScraperData/skyscraper_2x2_05/162-bedC0R0.nbt,100)
RandomBlock(-6,66,8,minecraft:wooden_slab:5,95,BED_BLOCK:2,../AllScraperData/skyscraper_2x2_05/163-bedC0R0.nbt,100)
Block(-6,67,0,CONCRETE:8)
Block(-6,67,6,CONCRETE:8)
Block(-6,68,0,CONCRETE:8)
RandomBlock(-6,68,2,AIR,95,WALL_BANNER:5,../AllScraperData/skyscraper_2x2_05/166-bannerC0R0.nbt,100)
RandomBlock(-6,68,4,AIR,95,WALL_BANNER:5,../AllScraperData/skyscraper_2x2_05/167-bannerC0R0.nbt,100)
RandomBlock(-6,68,5,AIR,95,WALL_BANNER:5,../AllScraperData/skyscraper_2x2_05/168-bannerC0R0.nbt,100)
Block(-6,68,6,CONCRETE:8)
RandomBlock(-6,68,7,AIR,95,WALL_BANNER:5,../AllScraperData/skyscraper_2x2_05/169-bannerC0R0.nbt,100)
Block(-6,69,0,CONCRETE:8)
Block(-6,69,1,STEP:8)
Block(-6,69,2,STEP:8)
Block(-6,69,3,STEP:8)
Block(-6,69,4,STEP:8)
Block(-6,69,5,STEP:8)
Block(-6,69,6,CONCRETE:8)
Block(-6,69,7,STEP:8)
Block(-6,69,8,STEP:8)
Block(-6,70,0,CONCRETE:8)
Block(-6,70,1,CARPET:10)
Block(-6,70,2,CARPET:10)
RandomBlock(-6,70,3,AIR,90,WALL_SIGN:2,../AllScraperData/skyscraper_2x2_05/172-signC0R0.nbt,100)
RandomBlock(-6,70,4,minecraft:wooden_slab:5,95,BED_BLOCK:0,../AllScraperData/skyscraper_2x2_05/173-bedC0R0.nbt,100)
RandomBlock(-6,70,5,minecraft:wooden_slab:5,95,BED_BLOCK:8,../AllScraperData/skyscraper_2x2_05/174-bedC0R0.nbt,100)
Block(-6,70,6,CONCRETE:8)
RandomBlock(-6,70,7,minecraft:wooden_slab:5,95,BED_BLOCK:10,../AllScraperData/skyscraper_2x2_05/175-bedC0R0.nbt,100)
RandomBlock(-6,70,8,minecraft:wooden_slab:5,95,BED_BLOCK:2,../AllScraperData/skyscraper_2x2_05/176-bedC0R0.nbt,100)
Block(-6,71,0,CONCRETE:8)
Block(-6,71,6,CONCRETE:8)
Block(-6,72,0,CONCRETE:8)
RandomBlock(-6,72,2,AIR,95,WALL_BANNER:5,../AllScraperData/skyscraper_2x2_05/179-bannerC0R0.nbt,100)
RandomBlock(-6,72,4,AIR,95,WALL_BANNER:5,../AllScraperData/skyscraper_2x2_05/180-bannerC0R0.nbt,100)
RandomBlock(-6,72,5,AIR,95,WALL_BANNER:5,../AllScraperData/skyscraper_2x2_05/181-bannerC0R0.nbt,100)
Block(-6,72,6,CONCRETE:8)
RandomBlock(-6,72,7,AIR,95,WALL_BANNER:5,../AllScraperData/skyscraper_2x2_05/182-bannerC0R0.nbt,100)
Block(-6,73,0,CONCRETE:8)
Block(-6,73,1,STEP:8)
Block(-6,73,2,STEP:8)
Block(-6,73,3,STEP:8)
Block(-6,73,4,STEP:8)
Block(-6,73,5,STEP:8)
Block(-6,73,6,CONCRETE:8)
Block(-6,73,7,STEP:8)
Block(-6,73,8,STEP:8)
Block(-6,74,0,CONCRETE:8)
Block(-6,74,1,CARPET:10)
Block(-6,74,2,CARPET:10)
RandomBlock(-6,74,3,AIR,90,WALL_SIGN:2,../AllScraperData/skyscraper_2x2_05/185-signC0R0.nbt,100)
RandomBlock(-6,74,4,minecraft:wooden_slab:5,95,BED_BLOCK:0,../AllScraperData/skyscraper_2x2_05/186-bedC0R0.nbt,100)
RandomBlock(-6,74,5,minecraft:wooden_slab:5,95,BED_BLOCK:8,../AllScraperData/skyscraper_2x2_05/187-bedC0R0.nbt,100)
Block(-6,74,6,CONCRETE:8)
RandomBlock(-6,74,7,minecraft:wooden_slab:5,95,BED_BLOCK:10,../AllScraperData/skyscraper_2x2_05/188-bedC0R0.nbt,100)
RandomBlock(-6,74,8,minecraft:wooden_slab:5,95,BED_BLOCK:2,../AllScraperData/skyscraper_2x2_05/189-bedC0R0.nbt,100)
Block(-6,75,0,CONCRETE:8)
Block(-6,75,6,CONCRETE:8)
Block(-6,76,0,CONCRETE:8)
RandomBlock(-6,76,2,AIR,95,WALL_BANNER:5,../AllScraperData/skyscraper_2x2_05/192-bannerC0R0.nbt,100)
RandomBlock(-6,76,4,AIR,95,WALL_BANNER:5,../AllScraperData/skyscraper_2x2_05/193-bannerC0R0.nbt,100)
RandomBlock(-6,76,5,AIR,95,WALL_BANNER:5,../AllScraperData/skyscraper_2x2_05/194-bannerC0R0.nbt,100)
Block(-6,76,6,CONCRETE:8)
RandomBlock(-6,76,7,AIR,95,WALL_BANNER:5,../AllScraperData/skyscraper_2x2_05/195-bannerC0R0.nbt,100)
Block(-6,77,0,CONCRETE:8)
Block(-6,77,1,STEP:8)
Block(-6,77,2,STEP:8)
Block(-6,77,3,STEP:8)
Block(-6,77,4,STEP:8)
Block(-6,77,5,STEP:8)
Block(-6,77,6,CONCRETE:8)
Block(-6,77,7,STEP:8)
Block(-6,77,8,STEP:8)
Block(-6,78,0,CONCRETE:8)
Block(-6,78,1,CARPET:10)
Block(-6,78,2,CARPET:10)
RandomBlock(-6,78,3,AIR,90,WALL_SIGN:2,../AllScraperData/skyscraper_2x2_05/198-signC0R0.nbt,100)
RandomBlock(-6,78,4,minecraft:wooden_slab:5,95,BED_BLOCK:0,../AllScraperData/skyscraper_2x2_05/199-bedC0R0.nbt,100)
RandomBlock(-6,78,5,minecraft:wooden_slab:5,95,BED_BLOCK:8,../AllScraperData/skyscraper_2x2_05/200-bedC0R0.nbt,100)
Block(-6,78,6,CONCRETE:8)
RandomBlock(-6,78,7,minecraft:wooden_slab:5,95,BED_BLOCK:10,../AllScraperData/skyscraper_2x2_05/201-bedC0R0.nbt,100)
RandomBlock(-6,78,8,minecraft:wooden_slab:5,95,BED_BLOCK:2,../AllScraperData/skyscraper_2x2_05/202-bedC0R0.nbt,100)
Block(-6,79,0,CONCRETE:8)
Block(-6,79,6,CONCRETE:8)
Block(-6,80,0,CONCRETE:8)
RandomBlock(-6,80,2,AIR,95,WALL_BANNER:5,../AllScraperData/skyscraper_2x2_05/205-bannerC0R0.nbt,100)
RandomBlock(-6,80,4,AIR,95,WALL_BANNER:5,../AllScraperData/skyscraper_2x2_05/206-bannerC0R0.nbt,100)
RandomBlock(-6,80,5,AIR,95,WALL_BANNER:5,../AllScraperData/skyscraper_2x2_05/207-bannerC0R0.nbt,100)
Block(-6,80,6,CONCRETE:8)
RandomBlock(-6,80,7,AIR,95,WALL_BANNER:5,../AllScraperData/skyscraper_2x2_05/208-bannerC0R0.nbt,100)
Block(-6,81,0,CONCRETE:7)
Block(-6,81,1,STEP:8)
Block(-6,81,2,STEP:8)
Block(-6,81,3,STEP:8)
Block(-6,81,4,STEP:8)
Block(-6,81,5,STEP:8)
Block(-6,81,6,CONCRETE:7)
Block(-6,81,7,STEP:8)
Block(-6,81,8,STEP:8)
Block(-6,82,0,CONCRETE:8)
RandomBlock(-6,82,1,AIR,95,STANDING_BANNER:0,../AllScraperData/skyscraper_2x2_05/211-bannerC0R0.nbt,100)
RandomBlock(-6,82,2,minecraft:wooden_slab:5,95,BED_BLOCK:0,../AllScraperData/skyscraper_2x2_05/212-bedC0R0.nbt,100)
RandomBlock(-6,82,3,minecraft:wooden_slab:5,95,BED_BLOCK:8,../AllScraperData/skyscraper_2x2_05/213-bedC0R0.nbt,100)
RandomBlock(-6,82,4,AIR,90,TRAP_DOOR:5,100)
RandomBlock(-6,82,5,AIR,95,STANDING_BANNER:10,../AllScraperData/skyscraper_2x2_05/214-bannerC0R0.nbt,100)
Block(-6,82,6,CONCRETE:7)
Block(-6,82,7,BOOKSHELF:0)
Block(-6,82,8,BIRCH_DOOR:1)
Block(-6,83,0,CONCRETE:8)
RandomBlock(-6,83,1,AIR,90,IRON_TRAPDOOR:1,100)
RandomBlock(-6,83,3,AIR,95,WALL_BANNER:2,../AllScraperData/skyscraper_2x2_05/219-bannerC0R0.nbt,100)
RandomBlock(-6,83,4,AIR,90,TRAP_DOOR:5,100)
RandomBlock(-6,83,5,AIR,90,IRON_TRAPDOOR:0,100)
Block(-6,83,6,CONCRETE:7)
RandomBlock(-6,83,7,WOOD:5,65,WORKBENCH:0,100)
Block(-6,83,8,BIRCH_DOOR:10)
Block(-6,84,0,CONCRETE:8)
RandomBlock(-6,84,2,AIR,95,WALL_BANNER:5,../AllScraperData/skyscraper_2x2_05/220-bannerC0R0.nbt,100)
RandomBlock(-6,84,4,AIR,95,WALL_BANNER:5,../AllScraperData/skyscraper_2x2_05/221-bannerC0R0.nbt,100)
RandomBlock(-6,84,5,AIR,95,WALL_BANNER:5,../AllScraperData/skyscraper_2x2_05/222-bannerC0R0.nbt,100)
Block(-6,84,6,CONCRETE:7)
Block(-6,84,7,WOOD_STEP:5)
Block(-6,85,0,CONCRETE:8)
Block(-6,85,1,STEP:8)
Block(-6,85,2,STEP:8)
Block(-6,85,3,STEP:8)
Block(-6,85,4,STEP:8)
Block(-6,85,5,STEP:8)
Block(-6,85,6,CONCRETE:8)
Block(-6,85,7,STEP:8)
Block(-6,85,8,STEP:8)
Block(-6,86,0,CONCRETE:8)
RandomBlock(-6,86,1,AIR,95,STANDING_BANNER:0,../AllScraperData/skyscraper_2x2_05/226-bannerC0R0.nbt,100)
RandomBlock(-6,86,2,minecraft:wooden_slab:5,95,BED_BLOCK:0,../AllScraperData/skyscraper_2x2_05/227-bedC0R0.nbt,100)
RandomBlock(-6,86,3,minecraft:wooden_slab:5,95,BED_BLOCK:8,../AllScraperData/skyscraper_2x2_05/228-bedC0R0.nbt,100)
RandomBlock(-6,86,4,AIR,90,TRAP_DOOR:5,100)
RandomBlock(-6,86,5,AIR,95,STANDING_BANNER:10,../AllScraperData/skyscraper_2x2_05/229-bannerC0R0.nbt,100)
Block(-6,86,6,CONCRETE:7)
Block(-6,86,7,BOOKSHELF:0)
Block(-6,86,8,BIRCH_DOOR:1)
Block(-6,87,0,CONCRETE:8)
RandomBlock(-6,87,1,AIR,90,IRON_TRAPDOOR:1,100)
RandomBlock(-6,87,3,AIR,95,WALL_BANNER:2,../AllScraperData/skyscraper_2x2_05/234-bannerC0R0.nbt,100)
RandomBlock(-6,87,4,AIR,90,TRAP_DOOR:5,100)
RandomBlock(-6,87,5,AIR,90,IRON_TRAPDOOR:0,100)
Block(-6,87,6,CONCRETE:7)
RandomBlock(-6,87,7,WOOD:5,65,WORKBENCH:0,100)
Block(-6,87,8,BIRCH_DOOR:10)
Block(-6,88,0,CONCRETE:8)
RandomBlock(-6,88,2,AIR,95,WALL_BANNER:5,../AllScraperData/skyscraper_2x2_05/235-bannerC0R0.nbt,100)
RandomBlock(-6,88,4,AIR,95,WALL_BANNER:5,../AllScraperData/skyscraper_2x2_05/236-bannerC0R0.nbt,100)
RandomBlock(-6,88,5,AIR,95,WALL_BANNER:5,../AllScraperData/skyscraper_2x2_05/237-bannerC0R0.nbt,100)
Block(-6,88,6,CONCRETE:7)
Block(-6,88,7,WOOD_STEP:5)
Block(-6,89,0,CONCRETE:8)
Block(-6,89,1,STEP:8)
Block(-6,89,2,STEP:8)
Block(-6,89,3,STEP:8)
Block(-6,89,4,STEP:8)
Block(-6,89,5,STEP:8)
Block(-6,89,6,CONCRETE:8)
Block(-6,89,7,STEP:8)
Block(-6,89,8,STEP:8)
Block(-6,90,0,IRON_FENCE:0)
Block(-6,90,1,CONCRETE:8)
Block(-6,90,2,STAINED_GLASS_PANE:15)
Block(-6,90,3,CONCRETE:8)
Block(-6,90,4,STAINED_GLASS_PANE:15)
Block(-6,90,5,STAINED_GLASS_PANE:15)
Block(-6,90,6,CONCRETE:8)
Block(-6,90,7,STAINED_GLASS_PANE:15)
Block(-6,90,8,CONCRETE:8)
Block(-6,91,1,CONCRETE:8)
Block(-6,91,2,STAINED_GLASS_PANE:15)
Block(-6,91,3,CONCRETE:8)
Block(-6,91,4,STAINED_GLASS_PANE:15)
Block(-6,91,5,STAINED_GLASS_PANE:15)
Block(-6,91,6,CONCRETE:8)
Block(-6,91,7,STAINED_GLASS_PANE:15)
Block(-6,91,8,CONCRETE:8)
Block(-6,92,1,CONCRETE:8)
Block(-6,92,2,STAINED_GLASS_PANE:15)
Block(-6,92,3,CONCRETE:8)
Block(-6,92,4,STAINED_GLASS_PANE:15)
Block(-6,92,5,STAINED_GLASS_PANE:15)
Block(-6,92,6,CONCRETE:8)
Block(-6,92,7,STAINED_GLASS_PANE:15)
Block(-6,92,8,CONCRETE:8)
Block(-6,93,1,CONCRETE:8)
Block(-6,93,2,CONCRETE:8)
Block(-6,93,3,CONCRETE:8)
Block(-6,93,4,CONCRETE:8)
Block(-6,93,5,CONCRETE:8)
Block(-6,93,6,CONCRETE:8)
Block(-6,93,7,CONCRETE:8)
Block(-6,93,8,CONCRETE:8)
Block(-6,94,1,CONCRETE:8)
Block(-6,94,2,CONCRETE:8)
Block(-6,94,3,CONCRETE:8)
Block(-6,94,4,CONCRETE:8)
Block(-6,94,5,CONCRETE:8)
Block(-6,94,6,CONCRETE:8)
Block(-6,94,7,CONCRETE:8)
Block(-6,94,8,CONCRETE:8)
Block(-6,95,1,CONCRETE:8)
Block(-6,95,2,STAINED_GLASS_PANE:15)
Block(-6,95,3,CONCRETE:8)
Block(-6,95,4,STAINED_GLASS_PANE:15)
Block(-6,95,5,STAINED_GLASS_PANE:15)
Block(-6,95,6,CONCRETE:8)
Block(-6,95,7,STAINED_GLASS_PANE:15)
Block(-6,95,8,CONCRETE:8)
Block(-6,96,1,CONCRETE:8)
Block(-6,96,2,STAINED_GLASS_PANE:15)
Block(-6,96,3,CONCRETE:8)
Block(-6,96,4,STAINED_GLASS_PANE:15)
Block(-6,96,5,STAINED_GLASS_PANE:15)
Block(-6,96,6,CONCRETE:8)
Block(-6,96,7,STAINED_GLASS_PANE:15)
Block(-6,96,8,CONCRETE:8)
Block(-6,97,1,CONCRETE:8)
Block(-6,97,2,CONCRETE:8)
Block(-6,97,3,CONCRETE:8)
Block(-6,97,4,CONCRETE:8)
Block(-6,97,5,CONCRETE:8)
Block(-6,97,6,CONCRETE:8)
Block(-6,97,7,CONCRETE:8)
Block(-6,97,8,CONCRETE:8)
Block(-6,98,1,CONCRETE:8)
Block(-6,98,2,CONCRETE:8)
Block(-6,98,3,CONCRETE:8)
Block(-6,98,4,CONCRETE:8)
Block(-6,98,5,CONCRETE:8)
Block(-6,98,6,CONCRETE:8)
Block(-6,98,7,CONCRETE:8)
Block(-6,98,8,CONCRETE:8)
Block(-6,99,1,CONCRETE:8)
Block(-6,99,2,STAINED_GLASS_PANE:15)
Block(-6,99,3,CONCRETE:8)
Block(-6,99,4,STAINED_GLASS_PANE:15)
Block(-6,99,5,STAINED_GLASS_PANE:15)
Block(-6,99,6,CONCRETE:8)
Block(-6,99,7,STAINED_GLASS_PANE:15)
Block(-6,99,8,CONCRETE:8)
Block(-6,100,1,CONCRETE:8)
Block(-6,100,2,STAINED_GLASS_PANE:15)
Block(-6,100,3,CONCRETE:8)
Block(-6,100,4,STAINED_GLASS_PANE:15)
Block(-6,100,5,STAINED_GLASS_PANE:15)
Block(-6,100,6,CONCRETE:8)
Block(-6,100,7,STAINED_GLASS_PANE:15)
Block(-6,100,8,CONCRETE:8)
Block(-6,101,1,CONCRETE:8)
Block(-6,101,2,CONCRETE:8)
Block(-6,101,3,CONCRETE:8)
Block(-6,101,4,CONCRETE:8)
Block(-6,101,5,CONCRETE:8)
Block(-6,101,6,CONCRETE:8)
Block(-6,101,7,CONCRETE:8)
Block(-6,101,8,CONCRETE:8)
Block(-6,102,1,CONCRETE:7)
Block(-6,102,2,IRON_FENCE:0)
Block(-6,102,3,IRON_FENCE:0)
Block(-6,102,4,IRON_FENCE:0)
Block(-6,102,5,IRON_FENCE:0)
Block(-6,102,6,IRON_FENCE:0)
Block(-6,102,7,IRON_FENCE:0)
Block(-6,102,8,CONCRETE:7)
Block(-5,0,-7,CONCRETE:7)
Block(-5,0,-6,CONCRETE:7)
Block(-5,0,-5,CONCRETE:7)
Block(-5,0,-4,CONCRETE:7)
Block(-5,0,-3,CONCRETE:7)
Block(-5,0,-2,CONCRETE:7)
Block(-5,0,-1,CONCRETE:7)
Block(-5,0,0,CONCRETE:7)
Block(-5,0,1,CONCRETE:7)
Block(-5,0,2,CONCRETE:7)
Block(-5,0,3,CONCRETE:7)
Block(-5,0,4,CONCRETE:7)
Block(-5,0,5,CONCRETE:7)
Block(-5,0,6,CONCRETE:7)
Block(-5,0,7,CONCRETE:7)
Block(-5,0,8,CONCRETE:7)
Block(-5,1,-7,CONCRETE:7)
Block(-5,1,-6,CONCRETE:7)
Block(-5,1,-5,CONCRETE:7)
Block(-5,1,-4,CONCRETE:7)
Block(-5,1,-3,CONCRETE:7)
Block(-5,1,-2,CONCRETE:7)
Block(-5,1,-1,CONCRETE:7)
Block(-5,1,0,CONCRETE:7)
Block(-5,1,1,CONCRETE:7)
Block(-5,1,2,CONCRETE:7)
Block(-5,1,3,CONCRETE:7)
Block(-5,1,4,CONCRETE:7)
Block(-5,1,5,CONCRETE:7)
Block(-5,1,6,CONCRETE:7)
Block(-5,1,7,CONCRETE:7)
Block(-5,1,8,CONCRETE:7)
Block(-5,2,-7,CONCRETE:7)
Block(-5,2,-6,CONCRETE:7)
Block(-5,2,-5,CONCRETE:7)
Block(-5,2,-4,CONCRETE:7)
Block(-5,2,-3,CONCRETE:7)
Block(-5,2,-2,CONCRETE:7)
Block(-5,2,-1,CONCRETE:7)
Block(-5,2,0,CONCRETE:7)
Block(-5,2,1,CONCRETE:7)
Block(-5,2,2,CONCRETE:7)
Block(-5,2,3,CONCRETE:7)
Block(-5,2,4,CONCRETE:7)
Block(-5,2,5,CONCRETE:7)
Block(-5,2,6,CONCRETE:7)
Block(-5,2,7,CONCRETE:7)
Block(-5,2,8,CONCRETE:7)
Block(-5,3,-7,CONCRETE:7)
Block(-5,3,-6,CONCRETE:7)
Block(-5,3,-5,CONCRETE:7)
Block(-5,3,-4,CONCRETE:7)
Block(-5,3,-3,CONCRETE:7)
Block(-5,3,-2,CONCRETE:7)
Block(-5,3,-1,CONCRETE:7)
Block(-5,3,0,CONCRETE:7)
Block(-5,3,1,CONCRETE:7)
Block(-5,3,2,CONCRETE:7)
Block(-5,3,3,CONCRETE:7)
Block(-5,3,4,CONCRETE:7)
Block(-5,3,5,CONCRETE:7)
Block(-5,3,6,CONCRETE:7)
Block(-5,3,7,SMOOTH_STAIRS:1)
Block(-5,3,8,SMOOTH_STAIRS:1)
Block(-5,4,-7,CONCRETE:7)
Block(-5,4,-6,CONCRETE:7)
Block(-5,4,-5,CONCRETE:7)
Block(-5,4,-4,CONCRETE:7)
Block(-5,4,-3,CONCRETE:7)
Block(-5,4,-2,CONCRETE:7)
Block(-5,4,-1,CONCRETE:7)
Block(-5,4,0,CONCRETE:7)
Block(-5,4,1,CONCRETE:7)
Block(-5,4,2,CONCRETE:7)
Block(-5,4,3,CONCRETE:7)
Block(-5,4,4,CONCRETE:7)
Block(-5,4,5,CONCRETE:7)
Block(-5,4,6,CONCRETE:7)
Block(-5,4,7,COBBLE_WALL:0)
Block(-5,4,8,COBBLE_WALL:0)
Block(-5,5,-7,CONCRETE:7)
Block(-5,5,-6,CONCRETE:7)
Block(-5,5,-5,CONCRETE:7)
Block(-5,5,-4,CONCRETE:7)
Block(-5,5,-3,CONCRETE:7)
Block(-5,5,-2,CONCRETE:7)
Block(-5,5,-1,CONCRETE:7)
Block(-5,5,0,CONCRETE:7)
Block(-5,5,1,CONCRETE:7)
Block(-5,5,2,CONCRETE:7)
Block(-5,5,3,CONCRETE:7)
Block(-5,5,4,CONCRETE:7)
Block(-5,5,5,CONCRETE:7)
Block(-5,5,6,CONCRETE:7)
Block(-5,5,7,SMOOTH_STAIRS:5)
Block(-5,5,8,SMOOTH_STAIRS:5)
Block(-5,6,-7,CONCRETE:7)
Block(-5,6,-6,CONCRETE:7)
Block(-5,6,-5,CONCRETE:7)
Block(-5,6,-4,CONCRETE:7)
Block(-5,6,-3,CONCRETE:7)
Block(-5,6,-2,CONCRETE:7)
Block(-5,6,-1,CONCRETE:7)
Block(-5,6,0,CONCRETE:7)
Block(-5,6,1,CONCRETE:7)
Block(-5,6,2,CONCRETE:7)
Block(-5,6,3,CONCRETE:7)
Block(-5,6,4,CONCRETE:7)
Block(-5,6,5,CONCRETE:7)
Block(-5,6,6,CONCRETE:7)
Block(-5,6,7,CONCRETE:7)
Block(-5,6,8,CONCRETE:7)
Block(-5,7,-7,CONCRETE:7)
Block(-5,7,-6,CONCRETE:7)
Block(-5,7,-5,CONCRETE:7)
Block(-5,7,-4,CONCRETE:7)
Block(-5,7,-3,CONCRETE:7)
Block(-5,7,-2,CONCRETE:7)
Block(-5,7,-1,CONCRETE:7)
Block(-5,7,0,CONCRETE:7)
Block(-5,7,1,CONCRETE:7)
Block(-5,7,2,CONCRETE:7)
Block(-5,7,3,CONCRETE:7)
Block(-5,7,4,CONCRETE:7)
Block(-5,7,5,CONCRETE:7)
Block(-5,7,6,CONCRETE:7)
Block(-5,7,7,CONCRETE:7)
Block(-5,7,8,CONCRETE:7)
Block(-5,8,-7,CONCRETE:7)
Block(-5,8,-6,CONCRETE:7)
Block(-5,8,-5,CONCRETE:7)
Block(-5,8,-4,CONCRETE:7)
Block(-5,8,-3,CONCRETE:7)
Block(-5,8,-2,CONCRETE:7)
Block(-5,8,-1,CONCRETE:7)
Block(-5,8,0,CONCRETE:7)
Block(-5,8,1,CONCRETE:7)
Block(-5,8,2,CONCRETE:7)
Block(-5,8,3,CONCRETE:7)
Block(-5,8,4,CONCRETE:7)
Block(-5,8,5,CONCRETE:7)
Block(-5,8,6,CONCRETE:7)
Block(-5,8,7,CONCRETE:7)
Block(-5,8,8,CONCRETE:7)
Block(-5,9,-7,CONCRETE:7)
Block(-5,9,-6,CONCRETE:7)
Block(-5,9,-5,CONCRETE:7)
Block(-5,9,-4,CONCRETE:7)
Block(-5,9,-3,CONCRETE:7)
Block(-5,9,-2,CONCRETE:7)
Block(-5,9,-1,CONCRETE:7)
Block(-5,9,0,CONCRETE:7)
Block(-5,9,1,CONCRETE:7)
Block(-5,9,2,CONCRETE:7)
Block(-5,9,3,CONCRETE:7)
Block(-5,9,4,CONCRETE:7)
Block(-5,9,5,CONCRETE:7)
Block(-5,9,6,CONCRETE:7)
Block(-5,9,7,CONCRETE:7)
Block(-5,9,8,CONCRETE:7)
Block(-5,10,-7,CONCRETE:7)
Block(-5,10,-6,CONCRETE:7)
Block(-5,10,-5,CONCRETE:7)
Block(-5,10,-4,CONCRETE:7)
Block(-5,10,-3,CONCRETE:7)
Block(-5,10,-2,CONCRETE:7)
Block(-5,10,-1,CONCRETE:7)
Block(-5,10,0,CONCRETE:7)
Block(-5,10,1,CONCRETE:7)
Block(-5,10,2,CONCRETE:7)
Block(-5,10,3,CONCRETE:7)
Block(-5,10,4,CONCRETE:7)
Block(-5,10,5,CONCRETE:7)
Block(-5,10,6,CONCRETE:7)
Block(-5,10,7,CONCRETE:7)
Block(-5,10,8,CONCRETE:7)
Block(-5,11,-7,CONCRETE:7)
Block(-5,11,-6,CONCRETE:7)
Block(-5,11,-5,CONCRETE:7)
Block(-5,11,-4,CONCRETE:7)
Block(-5,11,-3,CONCRETE:7)
Block(-5,11,-2,CONCRETE:7)
Block(-5,11,-1,CONCRETE:7)
Block(-5,11,0,CONCRETE:7)
Block(-5,11,1,CONCRETE:7)
Block(-5,11,2,CONCRETE:7)
Block(-5,11,3,CONCRETE:7)
Block(-5,11,4,CONCRETE:7)
Block(-5,11,5,CONCRETE:7)
Block(-5,11,6,CONCRETE:7)
Block(-5,11,7,CONCRETE:7)
Block(-5,11,8,CONCRETE:7)
Block(-5,12,-7,CONCRETE:7)
Block(-5,12,-6,CONCRETE:7)
Block(-5,12,-5,CONCRETE:7)
Block(-5,12,-4,CONCRETE:7)
Block(-5,12,-3,CONCRETE:7)
Block(-5,12,-2,CONCRETE:7)
Block(-5,12,-1,CONCRETE:7)
Block(-5,12,0,CONCRETE:7)
Block(-5,12,1,CONCRETE:7)
Block(-5,12,2,CONCRETE:7)
Block(-5,12,3,CONCRETE:7)
Block(-5,12,4,CONCRETE:7)
Block(-5,12,5,CONCRETE:7)
Block(-5,12,6,CONCRETE:7)
Block(-5,12,7,CONCRETE:7)
Block(-5,12,8,CONCRETE:7)
Block(-5,13,-7,CONCRETE:7)
Block(-5,13,-6,CONCRETE:7)
Block(-5,13,-5,CONCRETE:7)
Block(-5,13,-4,CONCRETE:7)
Block(-5,13,-3,CONCRETE:7)
Block(-5,13,-2,CONCRETE:7)
Block(-5,13,-1,CONCRETE:7)
Block(-5,13,0,CONCRETE:7)
Block(-5,13,1,CONCRETE:7)
Block(-5,13,2,CONCRETE:7)
Block(-5,13,3,CONCRETE:7)
Block(-5,13,4,CONCRETE:7)
Block(-5,13,5,CONCRETE:7)
Block(-5,13,6,CONCRETE:7)
Block(-5,13,7,CONCRETE:7)
Block(-5,13,8,CONCRETE:7)
Block(-5,14,-7,CONCRETE:7)
Block(-5,14,-6,CONCRETE:7)
Block(-5,14,-5,CONCRETE:7)
Block(-5,14,-4,CONCRETE:7)
Block(-5,14,-3,CONCRETE:7)
Block(-5,14,-2,CONCRETE:7)
Block(-5,14,-1,CONCRETE:7)
Block(-5,14,0,CONCRETE:7)
Block(-5,14,1,CONCRETE:7)
Block(-5,14,2,CONCRETE:7)
RandomBlock(-5,14,3,AIR,90,IRON_TRAPDOOR:9,100)
Block(-5,14,4,AIR:0)
RandomBlock(-5,14,5,AIR,90,IRON_TRAPDOOR:8,100)
Block(-5,14,6,CONCRETE:7)
Block(-5,14,7,QUARTZ_STAIRS:7)
Block(-5,14,8,AIR:0)
Block(-5,15,-7,CONCRETE:7)
Block(-5,15,-6,CONCRETE:7)
Block(-5,15,-5,CONCRETE:7)
Block(-5,15,-4,CONCRETE:7)
Block(-5,15,-3,CONCRETE:7)
Block(-5,15,-2,CONCRETE:7)
Block(-5,15,-1,CONCRETE:7)
Block(-5,15,0,CONCRETE:7)
Block(-5,15,1,CONCRETE:7)
Block(-5,15,2,CONCRETE:7)
RandomBlock(-5,15,3,AIR,90,IRON_TRAPDOOR:9,100)
Block(-5,15,4,AIR:0)
Block(-5,15,5,BOOKSHELF:0)
Block(-5,15,6,CONCRETE:7)
Block(-5,15,7,QUARTZ_STAIRS:7)
Block(-5,15,8,AIR:0)
Block(-5,16,-7,CONCRETE:7)
Block(-5,16,-6,CONCRETE:7)
Block(-5,16,-5,CONCRETE:7)
Block(-5,16,-4,CONCRETE:7)
Block(-5,16,-3,CONCRETE:7)
Block(-5,16,-2,CONCRETE:7)
Block(-5,16,-1,CONCRETE:7)
Block(-5,16,0,CONCRETE:7)
Block(-5,16,1,CONCRETE:7)
Block(-5,16,2,CONCRETE:7)
Block(-5,16,3,STEP:8)
Block(-5,16,4,STEP:8)
Block(-5,16,5,STEP:8)
Block(-5,16,6,CONCRETE:7)
Block(-5,16,7,STEP:8)
Block(-5,16,8,STEP:8)
Block(-5,17,-7,DOUBLE_STEP:0)
Block(-5,17,-6,STAINED_CLAY:9)
Block(-5,17,-5,SMOOTH_BRICK:2)
Block(-5,17,-4,STAINED_CLAY:9)
Block(-5,17,-3,STAINED_CLAY:9)
Block(-5,17,-2,CONCRETE:7)
Block(-5,17,-1,CONCRETE:7)
Block(-5,17,0,CONCRETE:7)
Block(-5,17,1,CONCRETE:7)
Block(-5,17,2,CONCRETE:7)
Block(-5,17,3,CONCRETE:7)
Block(-5,17,4,CONCRETE:7)
Block(-5,17,5,CONCRETE:7)
Block(-5,17,6,CONCRETE:7)
Block(-5,17,7,CONCRETE:7)
Block(-5,17,8,CONCRETE:7)
Block(-5,18,-6,COBBLE_WALL:0)
Block(-5,18,0,CONCRETE:7)
Block(-5,18,1,CARPET:3)
Block(-5,18,2,BOOKSHELF:0)
RandomBlock(-5,18,3,AIR,90,WALL_SIGN:2,../AllScraperData/skyscraper_2x2_05/242-signC0R0.nbt,100)
RandomBlock(-5,18,4,minecraft:wooden_slab:5,95,BED_BLOCK:0,../AllScraperData/skyscraper_2x2_05/243-bedC0R0.nbt,100)
RandomBlock(-5,18,5,minecraft:wooden_slab:5,95,BED_BLOCK:8,../AllScraperData/skyscraper_2x2_05/244-bedC0R0.nbt,100)
Block(-5,18,6,CONCRETE:7)
RandomBlock(-5,18,7,AIR,95,STANDING_BANNER:0,../AllScraperData/skyscraper_2x2_05/245-bannerC0R0.nbt,100)
RandomBlock(-5,18,8,AIR,90,WALL_SIGN:5,../AllScraperData/skyscraper_2x2_05/246-signC0R0.nbt,100)
Block(-5,19,0,STAINED_GLASS_PANE:15)
Block(-5,19,2,BOOKSHELF:0)
RandomBlock(-5,19,3,AIR,90,TRAP_DOOR:8,100)
RandomBlock(-5,19,4,AIR,90,TRAP_DOOR:8,100)
RandomBlock(-5,19,5,AIR,90,TRAP_DOOR:8,100)
Block(-5,19,6,CONCRETE:7)
RandomBlock(-5,19,7,AIR,90,IRON_TRAPDOOR:1,100)
Block(-5,20,0,STAINED_GLASS_PANE:15)
RandomBlock(-5,20,1,AIR,95,WALL_BANNER:3,../AllScraperData/skyscraper_2x2_05/250-bannerC0R0.nbt,100)
Block(-5,20,2,WOOD_STEP:5)
Block(-5,20,6,CONCRETE:7)
Block(-5,21,0,CONCRETE:7)
Block(-5,21,1,STEP:8)
Block(-5,21,2,STEP:8)
Block(-5,21,3,STEP:8)
Block(-5,21,4,STEP:8)
Block(-5,21,5,STEP:8)
Block(-5,21,6,CONCRETE:7)
Block(-5,21,7,STEP:8)
Block(-5,21,8,STEP:8)
Block(-5,22,0,CONCRETE:7)
Block(-5,22,1,CARPET:10)
Block(-5,22,2,BOOKSHELF:0)
RandomBlock(-5,22,3,AIR,90,WALL_SIGN:2,../AllScraperData/skyscraper_2x2_05/254-signC0R0.nbt,100)
RandomBlock(-5,22,4,minecraft:wooden_slab:5,95,BED_BLOCK:0,../AllScraperData/skyscraper_2x2_05/255-bedC0R0.nbt,100)
RandomBlock(-5,22,5,minecraft:wooden_slab:5,95,BED_BLOCK:8,../AllScraperData/skyscraper_2x2_05/256-bedC0R0.nbt,100)
Block(-5,22,6,CONCRETE:7)
RandomBlock(-5,22,7,minecraft:wooden_slab:5,95,BED_BLOCK:10,../AllScraperData/skyscraper_2x2_05/257-bedC0R0.nbt,100)
RandomBlock(-5,22,8,minecraft:wooden_slab:5,95,BED_BLOCK:2,../AllScraperData/skyscraper_2x2_05/258-bedC0R0.nbt,100)
Block(-5,23,0,STAINED_GLASS_PANE:15)
Block(-5,23,2,BOOKSHELF:0)
RandomBlock(-5,23,3,AIR,90,TRAP_DOOR:8,100)
RandomBlock(-5,23,4,AIR,90,TRAP_DOOR:8,100)
RandomBlock(-5,23,5,AIR,90,TRAP_DOOR:8,100)
Block(-5,23,6,CONCRETE:7)
Block(-5,24,0,STAINED_GLASS_PANE:15)
RandomBlock(-5,24,1,AIR,95,WALL_BANNER:3,../AllScraperData/skyscraper_2x2_05/260-bannerC0R0.nbt,100)
Block(-5,24,2,WOOD_STEP:5)
Block(-5,24,6,CONCRETE:7)
RandomBlock(-5,24,7,AIR,95,WALL_BANNER:3,../AllScraperData/skyscraper_2x2_05/263-bannerC0R0.nbt,100)
Block(-5,25,0,CONCRETE:7)
Block(-5,25,1,STEP:8)
Block(-5,25,2,STEP:8)
Block(-5,25,3,STEP:8)
Block(-5,25,4,STEP:8)
Block(-5,25,5,STEP:8)
Block(-5,25,6,CONCRETE:7)
Block(-5,25,7,STEP:8)
Block(-5,25,8,STEP:8)
Block(-5,26,0,CONCRETE:7)
Block(-5,26,1,CARPET:10)
Block(-5,26,2,BOOKSHELF:0)
RandomBlock(-5,26,3,AIR,90,WALL_SIGN:2,../AllScraperData/skyscraper_2x2_05/265-signC0R0.nbt,100)
RandomBlock(-5,26,4,minecraft:wooden_slab:5,95,BED_BLOCK:0,../AllScraperData/skyscraper_2x2_05/266-bedC0R0.nbt,100)
RandomBlock(-5,26,5,minecraft:wooden_slab:5,95,BED_BLOCK:8,../AllScraperData/skyscraper_2x2_05/267-bedC0R0.nbt,100)
Block(-5,26,6,CONCRETE:7)
RandomBlock(-5,26,7,minecraft:wooden_slab:5,95,BED_BLOCK:10,../AllScraperData/skyscraper_2x2_05/268-bedC0R0.nbt,100)
RandomBlock(-5,26,8,minecraft:wooden_slab:5,95,BED_BLOCK:2,../AllScraperData/skyscraper_2x2_05/269-bedC0R0.nbt,100)
Block(-5,27,0,STAINED_GLASS_PANE:15)
Block(-5,27,2,BOOKSHELF:0)
RandomBlock(-5,27,3,AIR,90,TRAP_DOOR:8,100)
RandomBlock(-5,27,4,AIR,90,TRAP_DOOR:8,100)
RandomBlock(-5,27,5,AIR,90,TRAP_DOOR:8,100)
Block(-5,27,6,CONCRETE:7)
Block(-5,28,0,STAINED_GLASS_PANE:15)
RandomBlock(-5,28,1,AIR,95,WALL_BANNER:3,../AllScraperData/skyscraper_2x2_05/271-bannerC0R0.nbt,100)
Block(-5,28,2,WOOD_STEP:5)
Block(-5,28,6,CONCRETE:7)
RandomBlock(-5,28,7,AIR,95,WALL_BANNER:3,../AllScraperData/skyscraper_2x2_05/274-bannerC0R0.nbt,100)
Block(-5,29,0,CONCRETE:7)
Block(-5,29,1,STEP:8)
Block(-5,29,2,STEP:8)
Block(-5,29,3,STEP:8)
Block(-5,29,4,STEP:8)
Block(-5,29,5,STEP:8)
Block(-5,29,6,CONCRETE:7)
Block(-5,29,7,STEP:8)
Block(-5,29,8,STEP:8)
Block(-5,30,0,CONCRETE:7)
Block(-5,30,1,CARPET:10)
Block(-5,30,2,BOOKSHELF:0)
RandomBlock(-5,30,3,AIR,90,WALL_SIGN:2,../AllScraperData/skyscraper_2x2_05/276-signC0R0.nbt,100)
RandomBlock(-5,30,4,minecraft:wooden_slab:5,95,BED_BLOCK:0,../AllScraperData/skyscraper_2x2_05/277-bedC0R0.nbt,100)
RandomBlock(-5,30,5,minecraft:wooden_slab:5,95,BED_BLOCK:8,../AllScraperData/skyscraper_2x2_05/278-bedC0R0.nbt,100)
Block(-5,30,6,CONCRETE:7)
RandomBlock(-5,30,7,minecraft:wooden_slab:5,95,BED_BLOCK:10,../AllScraperData/skyscraper_2x2_05/279-bedC0R0.nbt,100)
RandomBlock(-5,30,8,minecraft:wooden_slab:5,95,BED_BLOCK:2,../AllScraperData/skyscraper_2x2_05/280-bedC0R0.nbt,100)
Block(-5,31,0,STAINED_GLASS_PANE:15)
Block(-5,31,2,BOOKSHELF:0)
RandomBlock(-5,31,3,AIR,90,TRAP_DOOR:8,100)
RandomBlock(-5,31,4,AIR,90,TRAP_DOOR:8,100)
RandomBlock(-5,31,5,AIR,90,TRAP_DOOR:8,100)
Block(-5,31,6,CONCRETE:7)
Block(-5,32,0,STAINED_GLASS_PANE:15)
RandomBlock(-5,32,1,AIR,95,WALL_BANNER:3,../AllScraperData/skyscraper_2x2_05/282-bannerC0R0.nbt,100)
Block(-5,32,2,WOOD_STEP:5)
Block(-5,32,6,CONCRETE:7)
RandomBlock(-5,32,7,AIR,95,WALL_BANNER:3,../AllScraperData/skyscraper_2x2_05/285-bannerC0R0.nbt,100)
Block(-5,33,0,CONCRETE:7)
Block(-5,33,1,STEP:8)
Block(-5,33,2,STEP:8)
Block(-5,33,3,STEP:8)
Block(-5,33,4,STEP:8)
Block(-5,33,5,STEP:8)
Block(-5,33,6,CONCRETE:7)
Block(-5,33,7,STEP:8)
Block(-5,33,8,STEP:8)
Block(-5,34,0,CONCRETE:7)
Block(-5,34,1,CARPET:10)
Block(-5,34,2,BOOKSHELF:0)
RandomBlock(-5,34,3,AIR,90,WALL_SIGN:2,../AllScraperData/skyscraper_2x2_05/287-signC0R0.nbt,100)
RandomBlock(-5,34,4,minecraft:wooden_slab:5,95,BED_BLOCK:0,../AllScraperData/skyscraper_2x2_05/288-bedC0R0.nbt,100)
RandomBlock(-5,34,5,minecraft:wooden_slab:5,95,BED_BLOCK:8,../AllScraperData/skyscraper_2x2_05/289-bedC0R0.nbt,100)
Block(-5,34,6,CONCRETE:7)
RandomBlock(-5,34,7,minecraft:wooden_slab:5,95,BED_BLOCK:10,../AllScraperData/skyscraper_2x2_05/290-bedC0R0.nbt,100)
RandomBlock(-5,34,8,minecraft:wooden_slab:5,95,BED_BLOCK:2,../AllScraperData/skyscraper_2x2_05/291-bedC0R0.nbt,100)
Block(-5,35,0,STAINED_GLASS_PANE:15)
Block(-5,35,2,BOOKSHELF:0)
RandomBlock(-5,35,3,AIR,90,TRAP_DOOR:8,100)
RandomBlock(-5,35,4,AIR,90,TRAP_DOOR:8,100)
RandomBlock(-5,35,5,AIR,90,TRAP_DOOR:8,100)
Block(-5,35,6,CONCRETE:7)
Block(-5,36,0,STAINED_GLASS_PANE:15)
RandomBlock(-5,36,1,AIR,95,WALL_BANNER:3,../AllScraperData/skyscraper_2x2_05/293-bannerC0R0.nbt,100)
Block(-5,36,2,WOOD_STEP:5)
Block(-5,36,6,CONCRETE:7)
RandomBlock(-5,36,7,AIR,95,WALL_BANNER:3,../AllScraperData/skyscraper_2x2_05/296-bannerC0R0.nbt,100)
Block(-5,37,0,CONCRETE:7)
Block(-5,37,1,STEP:8)
Block(-5,37,2,STEP:8)
Block(-5,37,3,STEP:8)
Block(-5,37,4,STEP:8)
Block(-5,37,5,STEP:8)
Block(-5,37,6,CONCRETE:7)
Block(-5,37,7,STEP:8)
Block(-5,37,8,STEP:8)
Block(-5,38,0,CONCRETE:8)
Block(-5,38,1,CARPET:10)
Block(-5,38,2,BOOKSHELF:0)
RandomBlock(-5,38,3,AIR,90,WALL_SIGN:2,../AllScraperData/skyscraper_2x2_05/298-signC0R0.nbt,100)
RandomBlock(-5,38,4,minecraft:wooden_slab:5,95,BED_BLOCK:0,../AllScraperData/skyscraper_2x2_05/299-bedC0R0.nbt,100)
RandomBlock(-5,38,5,minecraft:wooden_slab:5,95,BED_BLOCK:8,../AllScraperData/skyscraper_2x2_05/300-bedC0R0.nbt,100)
Block(-5,38,6,CONCRETE:8)
RandomBlock(-5,38,7,minecraft:wooden_slab:5,95,BED_BLOCK:10,../AllScraperData/skyscraper_2x2_05/301-bedC0R0.nbt,100)
RandomBlock(-5,38,8,minecraft:wooden_slab:5,95,BED_BLOCK:2,../AllScraperData/skyscraper_2x2_05/302-bedC0R0.nbt,100)
Block(-5,39,0,STAINED_GLASS_PANE:15)
Block(-5,39,2,BOOKSHELF:0)
RandomBlock(-5,39,3,AIR,90,TRAP_DOOR:8,100)
RandomBlock(-5,39,4,AIR,90,TRAP_DOOR:8,100)
RandomBlock(-5,39,5,AIR,90,TRAP_DOOR:8,100)
Block(-5,39,6,CONCRETE:8)
Block(-5,40,0,STAINED_GLASS_PANE:15)
RandomBlock(-5,40,1,AIR,95,WALL_BANNER:3,../AllScraperData/skyscraper_2x2_05/304-bannerC0R0.nbt,100)
Block(-5,40,2,WOOD_STEP:5)
Block(-5,40,6,CONCRETE:8)
RandomBlock(-5,40,7,AIR,95,WALL_BANNER:3,../AllScraperData/skyscraper_2x2_05/307-bannerC0R0.nbt,100)
Block(-5,41,0,CONCRETE:8)
Block(-5,41,1,STEP:8)
Block(-5,41,2,STEP:8)
Block(-5,41,3,STEP:8)
Block(-5,41,4,STEP:8)
Block(-5,41,5,STEP:8)
Block(-5,41,6,CONCRETE:8)
Block(-5,41,7,STEP:8)
Block(-5,41,8,STEP:8)
Block(-5,42,0,CONCRETE:8)
Block(-5,42,1,CARPET:10)
Block(-5,42,2,BOOKSHELF:0)
RandomBlock(-5,42,3,AIR,90,WALL_SIGN:2,../AllScraperData/skyscraper_2x2_05/309-signC0R0.nbt,100)
RandomBlock(-5,42,4,minecraft:wooden_slab:5,95,BED_BLOCK:0,../AllScraperData/skyscraper_2x2_05/310-bedC0R0.nbt,100)
RandomBlock(-5,42,5,minecraft:wooden_slab:5,95,BED_BLOCK:8,../AllScraperData/skyscraper_2x2_05/311-bedC0R0.nbt,100)
Block(-5,42,6,CONCRETE:8)
RandomBlock(-5,42,7,minecraft:wooden_slab:5,95,BED_BLOCK:10,../AllScraperData/skyscraper_2x2_05/312-bedC0R0.nbt,100)
RandomBlock(-5,42,8,minecraft:wooden_slab:5,95,BED_BLOCK:2,../AllScraperData/skyscraper_2x2_05/313-bedC0R0.nbt,100)
Block(-5,43,0,STAINED_GLASS_PANE:15)
Block(-5,43,2,BOOKSHELF:0)
RandomBlock(-5,43,3,AIR,90,TRAP_DOOR:8,100)
RandomBlock(-5,43,4,AIR,90,TRAP_DOOR:8,100)
RandomBlock(-5,43,5,AIR,90,TRAP_DOOR:8,100)
Block(-5,43,6,CONCRETE:8)
Block(-5,44,0,STAINED_GLASS_PANE:15)
RandomBlock(-5,44,1,AIR,95,WALL_BANNER:3,../AllScraperData/skyscraper_2x2_05/315-bannerC0R0.nbt,100)
Block(-5,44,2,WOOD_STEP:5)
Block(-5,44,6,CONCRETE:8)
RandomBlock(-5,44,7,AIR,95,WALL_BANNER:3,../AllScraperData/skyscraper_2x2_05/318-bannerC0R0.nbt,100)
Block(-5,45,0,CONCRETE:8)
Block(-5,45,1,STEP:8)
Block(-5,45,2,STEP:8)
Block(-5,45,3,STEP:8)
Block(-5,45,4,STEP:8)
Block(-5,45,5,STEP:8)
Block(-5,45,6,CONCRETE:8)
Block(-5,45,7,STEP:8)
Block(-5,45,8,STEP:8)
Block(-5,46,0,CONCRETE:8)
