
#######################################################################
# +-----------------------------------------------------------------+ #
# |                            BO4 object                           | #
# +-----------------------------------------------------------------+ #
#######################################################################

Author: NLBlackEagle

Description: No description given

SettingsMode: WriteWithoutComments


#######################################################################
# +-----------------------------------------------------------------+ #
# |                          Main settings                          | #
# +-----------------------------------------------------------------+ #
#######################################################################

FixedRotation: 

Frequency: 0

SpawnHeight: highestBlock

UseCenterForHighestBlock: true

##############################
# Height Limits for the BO4. #
##############################

MinHeight: 0

MaxHeight: 255

InheritBO3: 

InheritBO3Rotation: NORTH

OverrideChildSettings: true

OverrideParentHeight: false

CanOverride: true

BranchFrequency: 0

BranchFrequencyGroup: 

MustBeBelowOther: false

MustBeInside: 

CannotBeInside: 

ReplacesBO3: 

MustBeInsideWorldBorders: false

CanSpawnOnWater: true

SpawnOnWaterOnly: false

SpawnUnderWater: false

SpawnAtWaterLevel: false

HeightOffset: 0

RemoveAir: false

ReplaceAbove: 

ReplaceBelow: 

ReplaceWithBiomeBlocks: false

ReplaceWithSurfaceBlock: GRASS

ReplaceWithGroundBlock: DIRT

ReplaceWithStoneBlock: STONE

SmoothRadius: 0

SmoothHeightOffset: 0

SmoothStartTop: false

SmoothStartWood: false

SmoothingSurfaceBlock: 

SmoothingGroundBlock: 

BO3Group: 

IsSpawnPoint: false

DoReplaceBlocks: true


#######################################################################
# +-----------------------------------------------------------------+ #
# |                              Blocks                             | #
# +-----------------------------------------------------------------+ #
#######################################################################

RandomBlock(-8,0,-5,SMOOTH_BRICK:0,40,SMOOTH_BRICK:1,30,SMOOTH_BRICK:2,30,MOSSY_COBBLESTONE:0,30,COBBLESTONE:0,20,SMOOTH_BRICK:0,100)
RandomBlock(-8,1,-5,SMOOTH_BRICK:0,40,SMOOTH_BRICK:1,30,SMOOTH_BRICK:2,30,MOSSY_COBBLESTONE:0,30,COBBLESTONE:0,20,SMOOTH_BRICK:0,100)
RandomBlock(-8,2,-5,SMOOTH_BRICK:0,40,SMOOTH_BRICK:1,30,SMOOTH_BRICK:2,30,MOSSY_COBBLESTONE:0,30,COBBLESTONE:0,20,SMOOTH_BRICK:0,100)
RandomBlock(-8,3,-5,SMOOTH_BRICK:0,40,SMOOTH_BRICK:1,30,SMOOTH_BRICK:2,30,MOSSY_COBBLESTONE:0,30,COBBLESTONE:0,20,SMOOTH_BRICK:0,100)
RandomBlock(-8,4,-5,SMOOTH_BRICK:0,40,SMOOTH_BRICK:1,30,SMOOTH_BRICK:2,30,MOSSY_COBBLESTONE:0,30,COBBLESTONE:0,20,SMOOTH_BRICK:0,100)
RandomBlock(-8,5,-5,SMOOTH_BRICK:0,40,SMOOTH_BRICK:1,30,SMOOTH_BRICK:2,30,MOSSY_COBBLESTONE:0,30,COBBLESTONE:0,20,SMOOTH_BRICK:0,100)
RandomBlock(-8,6,-5,SMOOTH_BRICK:0,40,SMOOTH_BRICK:1,30,SMOOTH_BRICK:2,30,MOSSY_COBBLESTONE:0,30,COBBLESTONE:0,20,SMOOTH_BRICK:0,100)
RandomBlock(-8,7,-5,SMOOTH_BRICK:0,40,SMOOTH_BRICK:1,30,SMOOTH_BRICK:2,30,MOSSY_COBBLESTONE:0,30,COBBLESTONE:0,20,SMOOTH_BRICK:0,100)
RandomBlock(-8,8,-5,SMOOTH_BRICK:0,40,SMOOTH_BRICK:1,30,SMOOTH_BRICK:2,30,MOSSY_COBBLESTONE:0,30,COBBLESTONE:0,20,SMOOTH_BRICK:0,100)
RandomBlock(-8,9,-5,SMOOTH_BRICK:0,40,SMOOTH_BRICK:1,30,SMOOTH_BRICK:2,30,MOSSY_COBBLESTONE:0,30,COBBLESTONE:0,20,SMOOTH_BRICK:0,100)
RandomBlock(-8,10,-5,SMOOTH_BRICK:0,40,SMOOTH_BRICK:1,30,SMOOTH_BRICK:2,30,MOSSY_COBBLESTONE:0,30,COBBLESTONE:0,20,SMOOTH_BRICK:0,100)
Block(-8,11,-5,SMOOTH_STAIRS:0)
Block(-8,13,-5,SMOOTH_STAIRS:0)
Block(-8,14,-7,STEP:0)
Block(-8,14,-6,STEP:0)
Block(-8,14,-5,STEP:0)
Block(-8,14,-4,STEP:0)
Block(-8,14,-3,STEP:0)
Block(-8,14,-2,STEP:0)
Block(-8,14,-1,STEP:0)
Block(-8,14,0,STEP:0)
Block(-7,0,-7,quark:world_stone_pavement:5)
Block(-7,0,-6,quark:world_stone_pavement:2)
Block(-7,0,-5,quark:world_stone_pavement:5)
Block(-7,0,-4,quark:limestone:1)
Block(-7,0,-3,quark:world_stone_pavement:5)
RandomBlock(-7,0,-2,SMOOTH_BRICK:0,40,SMOOTH_BRICK:1,30,SMOOTH_BRICK:2,30,MOSSY_COBBLESTONE:0,30,COBBLESTONE:0,20,SMOOTH_BRICK:0,100)
RandomBlock(-7,0,-1,SMOOTH_BRICK:0,40,SMOOTH_BRICK:1,30,SMOOTH_BRICK:2,30,MOSSY_COBBLESTONE:0,30,COBBLESTONE:0,20,SMOOTH_BRICK:0,100)
RandomBlock(-7,0,0,SMOOTH_BRICK:0,40,SMOOTH_BRICK:1,30,SMOOTH_BRICK:2,30,MOSSY_COBBLESTONE:0,30,COBBLESTONE:0,20,SMOOTH_BRICK:0,100)
RandomBlock(-7,0,1,SMOOTH_BRICK:0,40,SMOOTH_BRICK:1,30,SMOOTH_BRICK:2,30,MOSSY_COBBLESTONE:0,30,COBBLESTONE:0,20,SMOOTH_BRICK:0,100)
Block(-7,1,-7,quark:world_stone_pavement:2)
Block(-7,1,-6,quark:world_stone_pavement:2)
Block(-7,1,-5,quark:world_stone_pavement:5)
Block(-7,1,-4,quark:world_stone_pavement:2)
Block(-7,1,-3,quark:world_stone_pavement:5)
RandomBlock(-7,1,-2,SMOOTH_BRICK:0,40,SMOOTH_BRICK:1,30,SMOOTH_BRICK:2,30,MOSSY_COBBLESTONE:0,30,COBBLESTONE:0,20,SMOOTH_BRICK:0,100)
RandomBlock(-7,1,-1,SMOOTH_BRICK:0,40,SMOOTH_BRICK:1,30,SMOOTH_BRICK:2,30,MOSSY_COBBLESTONE:0,30,COBBLESTONE:0,20,SMOOTH_BRICK:0,100)
RandomBlock(-7,1,0,SMOOTH_BRICK:0,40,SMOOTH_BRICK:1,30,SMOOTH_BRICK:2,30,MOSSY_COBBLESTONE:0,30,COBBLESTONE:0,20,SMOOTH_BRICK:0,100)
RandomBlock(-7,1,1,SMOOTH_BRICK:0,40,SMOOTH_BRICK:1,30,SMOOTH_BRICK:2,30,MOSSY_COBBLESTONE:0,30,COBBLESTONE:0,20,SMOOTH_BRICK:0,100)
Block(-7,2,-7,quark:limestone:1)
Block(-7,2,-6,quark:world_stone_pavement:2)
Block(-7,2,-5,quark:world_stone_pavement:5)
Block(-7,2,-4,quark:limestone:1)
Block(-7,2,-3,quark:limestone:1)
RandomBlock(-7,2,-2,SMOOTH_BRICK:0,40,SMOOTH_BRICK:1,30,SMOOTH_BRICK:2,30,MOSSY_COBBLESTONE:0,30,COBBLESTONE:0,20,SMOOTH_BRICK:0,100)
RandomBlock(-7,2,-1,SMOOTH_BRICK:0,40,SMOOTH_BRICK:1,30,SMOOTH_BRICK:2,30,MOSSY_COBBLESTONE:0,30,COBBLESTONE:0,20,SMOOTH_BRICK:0,100)
RandomBlock(-7,2,0,SMOOTH_BRICK:0,40,SMOOTH_BRICK:1,30,SMOOTH_BRICK:2,30,MOSSY_COBBLESTONE:0,30,COBBLESTONE:0,20,SMOOTH_BRICK:0,100)
RandomBlock(-7,2,1,SMOOTH_BRICK:0,40,SMOOTH_BRICK:1,30,SMOOTH_BRICK:2,30,MOSSY_COBBLESTONE:0,30,COBBLESTONE:0,20,SMOOTH_BRICK:0,100)
Block(-7,3,-7,quark:world_stone_pavement:2)
Block(-7,3,-6,quark:world_stone_pavement:5)
Block(-7,3,-5,quark:world_stone_pavement:5)
Block(-7,3,-4,quark:world_stone_pavement:2)
Block(-7,3,-3,quark:world_stone_pavement:2)
RandomBlock(-7,3,-2,SMOOTH_BRICK:0,40,SMOOTH_BRICK:1,30,SMOOTH_BRICK:2,30,MOSSY_COBBLESTONE:0,30,COBBLESTONE:0,20,SMOOTH_BRICK:0,100)
RandomBlock(-7,3,-1,SMOOTH_BRICK:0,40,SMOOTH_BRICK:1,30,SMOOTH_BRICK:2,30,MOSSY_COBBLESTONE:0,30,COBBLESTONE:0,20,SMOOTH_BRICK:0,100)
RandomBlock(-7,3,0,SMOOTH_BRICK:0,40,SMOOTH_BRICK:1,30,SMOOTH_BRICK:2,30,MOSSY_COBBLESTONE:0,30,COBBLESTONE:0,20,SMOOTH_BRICK:0,100)
RandomBlock(-7,3,1,SMOOTH_BRICK:0,40,SMOOTH_BRICK:1,30,SMOOTH_BRICK:2,30,MOSSY_COBBLESTONE:0,30,COBBLESTONE:0,20,SMOOTH_BRICK:0,100)
Block(-7,4,-7,quark:limestone:1)
Block(-7,4,-6,quark:world_stone_pavement:2)
Block(-7,4,-5,quark:world_stone_pavement:2)
Block(-7,4,-4,quark:world_stone_pavement:5)
Block(-7,4,-3,quark:world_stone_pavement:2)
RandomBlock(-7,4,-2,SMOOTH_BRICK:0,40,SMOOTH_BRICK:1,30,SMOOTH_BRICK:2,30,MOSSY_COBBLESTONE:0,30,COBBLESTONE:0,20,SMOOTH_BRICK:0,100)
RandomBlock(-7,4,-1,SMOOTH_BRICK:0,40,SMOOTH_BRICK:1,30,SMOOTH_BRICK:2,30,MOSSY_COBBLESTONE:0,30,COBBLESTONE:0,20,SMOOTH_BRICK:0,100)
RandomBlock(-7,4,0,SMOOTH_BRICK:0,40,SMOOTH_BRICK:1,30,SMOOTH_BRICK:2,30,MOSSY_COBBLESTONE:0,30,COBBLESTONE:0,20,SMOOTH_BRICK:0,100)
RandomBlock(-7,4,1,SMOOTH_BRICK:0,40,SMOOTH_BRICK:1,30,SMOOTH_BRICK:2,30,MOSSY_COBBLESTONE:0,30,COBBLESTONE:0,20,SMOOTH_BRICK:0,100)
Block(-7,5,-7,quark:world_stone_pavement:5)
Block(-7,5,-6,quark:limestone:1)
Block(-7,5,-5,quark:limestone:1)
Block(-7,5,-4,quark:world_stone_pavement:2)
Block(-7,5,-3,quark:world_stone_pavement:2)
RandomBlock(-7,5,-2,SMOOTH_BRICK:0,40,SMOOTH_BRICK:1,30,SMOOTH_BRICK:2,30,MOSSY_COBBLESTONE:0,30,COBBLESTONE:0,20,SMOOTH_BRICK:0,100)
RandomBlock(-7,5,-1,SMOOTH_BRICK:0,40,SMOOTH_BRICK:1,30,SMOOTH_BRICK:2,30,MOSSY_COBBLESTONE:0,30,COBBLESTONE:0,20,SMOOTH_BRICK:0,100)
RandomBlock(-7,5,0,SMOOTH_BRICK:0,40,SMOOTH_BRICK:1,30,SMOOTH_BRICK:2,30,MOSSY_COBBLESTONE:0,30,COBBLESTONE:0,20,SMOOTH_BRICK:0,100)
RandomBlock(-7,5,1,SMOOTH_BRICK:0,40,SMOOTH_BRICK:1,30,SMOOTH_BRICK:2,30,MOSSY_COBBLESTONE:0,30,COBBLESTONE:0,20,SMOOTH_BRICK:0,100)
Block(-7,6,-7,quark:world_stone_pavement:5)
Block(-7,6,-6,quark:limestone:1)
Block(-7,6,-5,quark:world_stone_pavement:2)
Block(-7,6,-4,quark:world_stone_pavement:2)
Block(-7,6,-3,quark:world_stone_pavement:5)
RandomBlock(-7,6,-2,SMOOTH_BRICK:0,40,SMOOTH_BRICK:1,30,SMOOTH_BRICK:2,30,MOSSY_COBBLESTONE:0,30,COBBLESTONE:0,20,SMOOTH_BRICK:0,100)
RandomBlock(-7,6,-1,SMOOTH_BRICK:0,40,SMOOTH_BRICK:1,30,SMOOTH_BRICK:2,30,MOSSY_COBBLESTONE:0,30,COBBLESTONE:0,20,SMOOTH_BRICK:0,100)
RandomBlock(-7,6,0,SMOOTH_BRICK:0,40,SMOOTH_BRICK:1,30,SMOOTH_BRICK:2,30,MOSSY_COBBLESTONE:0,30,COBBLESTONE:0,20,SMOOTH_BRICK:0,100)
RandomBlock(-7,6,1,SMOOTH_BRICK:0,40,SMOOTH_BRICK:1,30,SMOOTH_BRICK:2,30,MOSSY_COBBLESTONE:0,30,COBBLESTONE:0,20,SMOOTH_BRICK:0,100)
Block(-7,7,-7,quark:limestone:1)
Block(-7,7,-6,quark:world_stone_pavement:2)
Block(-7,7,-5,quark:world_stone_pavement:5)
Block(-7,7,-4,quark:limestone:1)
Block(-7,7,-3,quark:world_stone_pavement:5)
RandomBlock(-7,7,-2,SMOOTH_BRICK:0,40,SMOOTH_BRICK:1,30,SMOOTH_BRICK:2,30,MOSSY_COBBLESTONE:0,30,COBBLESTONE:0,20,SMOOTH_BRICK:0,100)
RandomBlock(-7,7,-1,SMOOTH_BRICK:0,40,SMOOTH_BRICK:1,30,SMOOTH_BRICK:2,30,MOSSY_COBBLESTONE:0,30,COBBLESTONE:0,20,SMOOTH_BRICK:0,100)
RandomBlock(-7,7,0,SMOOTH_BRICK:0,40,SMOOTH_BRICK:1,30,SMOOTH_BRICK:2,30,MOSSY_COBBLESTONE:0,30,COBBLESTONE:0,20,SMOOTH_BRICK:0,100)
RandomBlock(-7,7,1,SMOOTH_BRICK:0,40,SMOOTH_BRICK:1,30,SMOOTH_BRICK:2,30,MOSSY_COBBLESTONE:0,30,COBBLESTONE:0,20,SMOOTH_BRICK:0,100)
Block(-7,8,-7,quark:world_stone_pavement:5)
Block(-7,8,-6,quark:limestone:1)
Block(-7,8,-5,quark:world_stone_pavement:5)
Block(-7,8,-4,quark:world_stone_pavement:5)
Block(-7,8,-3,quark:world_stone_pavement:2)
RandomBlock(-7,8,-2,SMOOTH_BRICK:0,40,SMOOTH_BRICK:1,30,SMOOTH_BRICK:2,30,MOSSY_COBBLESTONE:0,30,COBBLESTONE:0,20,SMOOTH_BRICK:0,100)
RandomBlock(-7,8,-1,SMOOTH_BRICK:0,40,SMOOTH_BRICK:1,30,SMOOTH_BRICK:2,30,MOSSY_COBBLESTONE:0,30,COBBLESTONE:0,20,SMOOTH_BRICK:0,100)
RandomBlock(-7,8,0,SMOOTH_BRICK:0,40,SMOOTH_BRICK:1,30,SMOOTH_BRICK:2,30,MOSSY_COBBLESTONE:0,30,COBBLESTONE:0,20,SMOOTH_BRICK:0,100)
RandomBlock(-7,8,1,SMOOTH_BRICK:0,40,SMOOTH_BRICK:1,30,SMOOTH_BRICK:2,30,MOSSY_COBBLESTONE:0,30,COBBLESTONE:0,20,SMOOTH_BRICK:0,100)
Block(-7,9,-7,quark:world_stone_pavement:2)
Block(-7,9,-6,quark:world_stone_pavement:2)
Block(-7,9,-5,quark:limestone:1)
Block(-7,9,-4,quark:limestone:1)
Block(-7,9,-3,quark:world_stone_pavement:5)
RandomBlock(-7,9,-2,SMOOTH_BRICK:0,40,SMOOTH_BRICK:1,30,SMOOTH_BRICK:2,30,MOSSY_COBBLESTONE:0,30,COBBLESTONE:0,20,SMOOTH_BRICK:0,100)
RandomBlock(-7,9,-1,SMOOTH_BRICK:0,40,SMOOTH_BRICK:1,30,SMOOTH_BRICK:2,30,MOSSY_COBBLESTONE:0,30,COBBLESTONE:0,20,SMOOTH_BRICK:0,100)
RandomBlock(-7,9,0,SMOOTH_BRICK:0,40,SMOOTH_BRICK:1,30,SMOOTH_BRICK:2,30,MOSSY_COBBLESTONE:0,30,COBBLESTONE:0,20,SMOOTH_BRICK:0,100)
RandomBlock(-7,9,1,SMOOTH_BRICK:0,40,SMOOTH_BRICK:1,30,SMOOTH_BRICK:2,30,MOSSY_COBBLESTONE:0,30,COBBLESTONE:0,20,SMOOTH_BRICK:0,100)
Block(-7,10,-7,quark:world_stone_pavement:5)
Block(-7,10,-6,quark:world_stone_pavement:2)
Block(-7,10,-5,quark:world_stone_pavement:2)
Block(-7,10,-4,quark:world_stone_pavement:5)
Block(-7,10,-3,quark:world_stone_pavement:5)
RandomBlock(-7,10,-2,SMOOTH_BRICK:0,40,SMOOTH_BRICK:1,30,SMOOTH_BRICK:2,30,MOSSY_COBBLESTONE:0,30,COBBLESTONE:0,20,SMOOTH_BRICK:0,100)
RandomBlock(-7,10,-1,SMOOTH_BRICK:0,40,SMOOTH_BRICK:1,30,SMOOTH_BRICK:2,30,MOSSY_COBBLESTONE:0,30,COBBLESTONE:0,20,SMOOTH_BRICK:0,100)
RandomBlock(-7,10,0,SMOOTH_BRICK:0,40,SMOOTH_BRICK:1,30,SMOOTH_BRICK:2,30,MOSSY_COBBLESTONE:0,30,COBBLESTONE:0,20,SMOOTH_BRICK:0,100)
RandomBlock(-7,10,1,SMOOTH_BRICK:0,40,SMOOTH_BRICK:1,30,SMOOTH_BRICK:2,30,MOSSY_COBBLESTONE:0,30,COBBLESTONE:0,20,SMOOTH_BRICK:0,100)
Block(-7,11,-7,biomesoplenty:fir_door_block:6)
Block(-7,11,-6,biomesoplenty:fir_door_block:6)
Block(-7,11,-5,quark:world_stone_pavement:2)
Block(-7,11,-4,quark:world_stone_pavement:2)
Block(-7,11,-3,quark:world_stone_pavement:5)
Block(-7,11,-2,STEP:0)
Block(-7,11,-1,STEP:0)
Block(-7,11,0,DOUBLE_STEP:0)
Block(-7,11,1,STEP:0)
Block(-7,12,-7,biomesoplenty:fir_door_block:9)
Block(-7,12,-6,biomesoplenty:fir_door_block:8)
Block(-7,12,-5,quark:iron_plate:1)
Block(-7,12,-4,quark:iron_plate:1)
Block(-7,12,-3,quark:iron_plate:1)
Block(-7,12,-2,STEP:0)
Block(-7,12,-1,STEP:0)
Block(-7,12,0,DOUBLE_STEP:0)
Block(-7,12,1,STEP:0)
RandomBlock(-7,13,-7,SMOOTH_BRICK:0,40,SMOOTH_BRICK:1,30,SMOOTH_BRICK:2,30,MOSSY_COBBLESTONE:0,30,COBBLESTONE:0,20,SMOOTH_BRICK:0,100)
RandomBlock(-7,13,-6,SMOOTH_BRICK:0,40,SMOOTH_BRICK:1,30,SMOOTH_BRICK:2,30,MOSSY_COBBLESTONE:0,30,COBBLESTONE:0,20,SMOOTH_BRICK:0,100)
Block(-7,13,-5,quark:iron_plate:1)
Block(-7,13,-4,quark:iron_plate:1)
Block(-7,13,-3,quark:iron_plate:1)
Block(-7,13,-2,STEP:0)
Block(-7,13,-1,STEP:0)
Block(-7,13,0,DOUBLE_STEP:0)
Block(-7,13,1,STEP:0)
RandomBlock(-7,14,-7,SMOOTH_BRICK:0,40,SMOOTH_BRICK:1,30,SMOOTH_BRICK:2,30,MOSSY_COBBLESTONE:0,30,COBBLESTONE:0,20,SMOOTH_BRICK:0,100)
RandomBlock(-7,14,-6,SMOOTH_BRICK:0,40,SMOOTH_BRICK:1,30,SMOOTH_BRICK:2,30,MOSSY_COBBLESTONE:0,30,COBBLESTONE:0,20,SMOOTH_BRICK:0,100)
RandomBlock(-7,14,-5,SMOOTH_BRICK:0,40,SMOOTH_BRICK:1,30,SMOOTH_BRICK:2,30,MOSSY_COBBLESTONE:0,30,COBBLESTONE:0,20,SMOOTH_BRICK:0,100)
RandomBlock(-7,14,-4,SMOOTH_BRICK:0,40,SMOOTH_BRICK:1,30,SMOOTH_BRICK:2,30,MOSSY_COBBLESTONE:0,30,COBBLESTONE:0,20,SMOOTH_BRICK:0,100)
RandomBlock(-7,14,-3,SMOOTH_BRICK:0,40,SMOOTH_BRICK:1,30,SMOOTH_BRICK:2,30,MOSSY_COBBLESTONE:0,30,COBBLESTONE:0,20,SMOOTH_BRICK:0,100)
Block(-7,14,-2,STEP:0)
Block(-7,14,-1,DOUBLE_STEP:0)
Block(-7,14,0,STEP:0)
Block(-7,14,1,STEP:0)
RandomBlock(-7,15,-7,SMOOTH_BRICK:0,40,SMOOTH_BRICK:1,30,SMOOTH_BRICK:2,30,MOSSY_COBBLESTONE:0,30,COBBLESTONE:0,20,SMOOTH_BRICK:0,100)
RandomBlock(-7,15,-6,SMOOTH_BRICK:0,40,SMOOTH_BRICK:1,30,SMOOTH_BRICK:2,30,MOSSY_COBBLESTONE:0,30,COBBLESTONE:0,20,SMOOTH_BRICK:0,100)
Block(-7,15,-5,DOUBLE_STEP:0)
Block(-7,15,-4,DOUBLE_STEP:0)
Block(-7,15,-3,DOUBLE_STEP:0)
Block(-7,15,-2,DOUBLE_STEP:0)
Block(-6,0,-7,quark:world_stone_pavement:5)
Block(-6,0,-6,quark:world_stone_pavement:5)
Block(-6,0,-5,quark:world_stone_pavement:2)
Block(-6,0,-4,quark:world_stone_pavement:2)
Block(-6,0,-3,quark:world_stone_pavement:2)
Block(-6,0,-2,quark:world_stone_pavement:2)
Block(-6,0,-1,quark:world_stone_pavement:2)
Block(-6,0,0,quark:world_stone_pavement:5)
Block(-6,0,1,quark:world_stone_pavement:5)
RandomBlock(-6,0,2,SMOOTH_BRICK:0,40,SMOOTH_BRICK:1,30,SMOOTH_BRICK:2,30,MOSSY_COBBLESTONE:0,30,COBBLESTONE:0,20,SMOOTH_BRICK:0,100)
Block(-6,0,3,quark:iron_plate:1)
Block(-6,1,-7,quark:world_stone_pavement:5)
Block(-6,1,-6,quark:limestone:1)
Block(-6,1,-5,quark:world_stone_pavement:2)
Block(-6,1,-4,quark:limestone:1)
Block(-6,1,-3,quark:world_stone_pavement:2)
Block(-6,1,-2,quark:world_stone_pavement:2)
Block(-6,1,-1,quark:world_stone_pavement:2)
Block(-6,1,0,quark:limestone:1)
Block(-6,1,1,quark:world_stone_pavement:2)
RandomBlock(-6,1,2,SMOOTH_BRICK:0,40,SMOOTH_BRICK:1,30,SMOOTH_BRICK:2,30,MOSSY_COBBLESTONE:0,30,COBBLESTONE:0,20,SMOOTH_BRICK:0,100)
Block(-6,1,3,quark:iron_plate:1)
Block(-6,2,-7,quark:limestone:1)
Block(-6,2,-6,quark:world_stone_pavement:5)
Block(-6,2,-5,quark:world_stone_pavement:2)
Block(-6,2,-4,quark:limestone:1)
Block(-6,2,-3,quark:world_stone_pavement:2)
Block(-6,2,-2,quark:world_stone_pavement:2)
Block(-6,2,-1,quark:world_stone_pavement:2)
Block(-6,2,0,quark:world_stone_pavement:5)
Block(-6,2,1,quark:world_stone_pavement:5)
RandomBlock(-6,2,2,SMOOTH_BRICK:0,40,SMOOTH_BRICK:1,30,SMOOTH_BRICK:2,30,MOSSY_COBBLESTONE:0,30,COBBLESTONE:0,20,SMOOTH_BRICK:0,100)
Block(-6,2,3,quark:iron_plate:1)
Block(-6,3,-7,quark:limestone:1)
Block(-6,3,-6,quark:world_stone_pavement:5)
Block(-6,3,-5,quark:world_stone_pavement:2)
Block(-6,3,-4,quark:world_stone_pavement:5)
Block(-6,3,-3,quark:world_stone_pavement:2)
Block(-6,3,-2,quark:world_stone_pavement:2)
Block(-6,3,-1,quark:world_stone_pavement:2)
Block(-6,3,0,quark:limestone:1)
Block(-6,3,1,quark:world_stone_pavement:5)
RandomBlock(-6,3,2,SMOOTH_BRICK:0,40,SMOOTH_BRICK:1,30,SMOOTH_BRICK:2,30,MOSSY_COBBLESTONE:0,30,COBBLESTONE:0,20,SMOOTH_BRICK:0,100)
Block(-6,3,3,quark:iron_plate:1)
Block(-6,4,-7,quark:world_stone_pavement:2)
Block(-6,4,-6,quark:world_stone_pavement:5)
Block(-6,4,-5,quark:world_stone_pavement:2)
Block(-6,4,-4,quark:world_stone_pavement:5)
Block(-6,4,-3,quark:world_stone_pavement:2)
Block(-6,4,-2,quark:world_stone_pavement:2)
Block(-6,4,-1,quark:world_stone_pavement:2)
Block(-6,4,0,quark:world_stone_pavement:2)
Block(-6,4,1,quark:world_stone_pavement:2)
RandomBlock(-6,4,2,SMOOTH_BRICK:0,40,SMOOTH_BRICK:1,30,SMOOTH_BRICK:2,30,MOSSY_COBBLESTONE:0,30,COBBLESTONE:0,20,SMOOTH_BRICK:0,100)
Block(-6,4,3,quark:iron_plate:1)
Block(-6,5,-7,quark:limestone:1)
Block(-6,5,-6,quark:limestone:1)
Block(-6,5,-5,quark:world_stone_pavement:2)
Block(-6,5,-4,quark:world_stone_pavement:5)
Block(-6,5,-3,quark:world_stone_pavement:2)
Block(-6,5,-2,quark:world_stone_pavement:2)
Block(-6,5,-1,quark:world_stone_pavement:2)
Block(-6,5,0,quark:world_stone_pavement:2)
Block(-6,5,1,quark:world_stone_pavement:2)
RandomBlock(-6,5,2,SMOOTH_BRICK:0,40,SMOOTH_BRICK:1,30,SMOOTH_BRICK:2,30,MOSSY_COBBLESTONE:0,30,COBBLESTONE:0,20,SMOOTH_BRICK:0,100)
Block(-6,5,3,quark:iron_plate:1)
Block(-6,6,-7,quark:world_stone_pavement:5)
Block(-6,6,-6,quark:world_stone_pavement:2)
Block(-6,6,-5,quark:world_stone_pavement:2)
Block(-6,6,-4,quark:world_stone_pavement:2)
Block(-6,6,-3,quark:world_stone_pavement:2)
Block(-6,6,-2,quark:world_stone_pavement:2)
Block(-6,6,-1,quark:world_stone_pavement:2)
Block(-6,6,0,quark:limestone:1)
Block(-6,6,1,quark:world_stone_pavement:2)
RandomBlock(-6,6,2,SMOOTH_BRICK:0,40,SMOOTH_BRICK:1,30,SMOOTH_BRICK:2,30,MOSSY_COBBLESTONE:0,30,COBBLESTONE:0,20,SMOOTH_BRICK:0,100)
Block(-6,6,3,quark:iron_plate:1)
Block(-6,7,-7,quark:world_stone_pavement:2)
Block(-6,7,-6,quark:limestone:1)
Block(-6,7,-5,quark:world_stone_pavement:2)
Block(-6,7,-4,quark:world_stone_pavement:2)
Block(-6,7,-3,quark:world_stone_pavement:5)
Block(-6,7,-2,quark:world_stone_pavement:5)
Block(-6,7,-1,quark:limestone:1)
Block(-6,7,0,quark:world_stone_pavement:2)
Block(-6,7,1,quark:limestone:1)
RandomBlock(-6,7,2,SMOOTH_BRICK:0,40,SMOOTH_BRICK:1,30,SMOOTH_BRICK:2,30,MOSSY_COBBLESTONE:0,30,COBBLESTONE:0,20,SMOOTH_BRICK:0,100)
Block(-6,7,3,quark:iron_plate:1)
Block(-6,8,-7,quark:world_stone_pavement:5)
Block(-6,8,-6,quark:limestone:1)
Block(-6,8,-5,quark:world_stone_pavement:2)
Block(-6,8,-4,quark:world_stone_pavement:2)
Block(-6,8,-3,quark:world_stone_pavement:5)
Block(-6,8,-2,quark:limestone:1)
Block(-6,8,-1,quark:world_stone_pavement:2)
Block(-6,8,0,quark:world_stone_pavement:2)
Block(-6,8,1,quark:world_stone_pavement:2)
RandomBlock(-6,8,2,SMOOTH_BRICK:0,40,SMOOTH_BRICK:1,30,SMOOTH_BRICK:2,30,MOSSY_COBBLESTONE:0,30,COBBLESTONE:0,20,SMOOTH_BRICK:0,100)
Block(-6,8,3,quark:iron_plate:1)
Block(-6,9,-7,quark:polished_stone)
Block(-6,9,-6,quark:limestone:1)
Block(-6,9,-5,quark:limestone:1)
Block(-6,9,-4,quark:limestone:1)
Block(-6,9,-3,quark:world_stone_pavement:2)
Block(-6,9,-2,quark:world_stone_pavement:5)
Block(-6,9,-1,quark:limestone:1)
Block(-6,9,0,quark:world_stone_pavement:2)
Block(-6,9,1,quark:polished_stone)
RandomBlock(-6,9,2,SMOOTH_BRICK:0,40,SMOOTH_BRICK:1,30,SMOOTH_BRICK:2,30,MOSSY_COBBLESTONE:0,30,COBBLESTONE:0,20,SMOOTH_BRICK:0,100)
Block(-6,9,3,quark:iron_plate:1)
Block(-6,10,-7,quark:polished_stone)
Block(-6,10,-6,quark:polished_stone)
Block(-6,10,-5,quark:polished_stone)
Block(-6,10,-4,quark:limestone:1)
Block(-6,10,-3,quark:world_stone_pavement:2)
Block(-6,10,-2,quark:world_stone_pavement:2)
Block(-6,10,-1,quark:world_stone_pavement:2)
Block(-6,10,0,quark:polished_stone)
Block(-6,10,1,quark:world_stone_pavement:2)
RandomBlock(-6,10,2,SMOOTH_BRICK:0,40,SMOOTH_BRICK:1,30,SMOOTH_BRICK:2,30,MOSSY_COBBLESTONE:0,30,COBBLESTONE:0,20,SMOOTH_BRICK:0,100)
Block(-6,10,3,quark:iron_plate:1)
Block(-6,11,-3,quark:iron_plate:1)
Block(-6,11,-2,quark:polished_stone)
Block(-6,11,-1,quark:world_stone_pavement:2)
Block(-6,11,0,quark:polished_stone)
Block(-6,11,1,quark:polished_stone)
Block(-6,11,2,STEP:0)
Block(-6,11,3,quark:iron_plate:1)
Block(-6,11,4,quark:iron_plate:1)
Block(-6,11,5,quark:iron_plate:1)
Block(-6,11,6,quark:iron_plate:1)
Block(-6,11,7,quark:iron_plate:1)
Block(-6,11,8,quark:iron_plate:1)
Block(-6,12,-3,quark:iron_plate:1)
Block(-6,12,-2,quark:iron_plate:1)
Block(-6,12,-1,quark:iron_plate:1)
Block(-6,12,0,quark:iron_plate:1)
Block(-6,12,1,quark:iron_plate:1)
Block(-6,12,2,STEP:0)
Block(-6,12,3,quark:iron_plate:1)
Block(-6,12,4,quark:basalt_wall)
Block(-6,12,5,quark:basalt_wall)
Block(-6,12,6,quark:basalt_wall)
Block(-6,12,7,quark:basalt_wall)
Block(-6,12,8,quark:basalt_wall)
Block(-6,13,-3,quark:iron_plate:1)
Block(-6,13,-2,quark:iron_plate:1)
Block(-6,13,-1,quark:iron_plate:1)
Block(-6,13,0,quark:iron_plate:1)
Block(-6,13,1,quark:iron_plate:1)
Block(-6,13,2,STEP:0)
Block(-6,13,3,quark:iron_plate:1)
Block(-6,14,-7,quark:iron_plate:1)
Block(-6,14,-6,quark:iron_plate:1)
Block(-6,14,-5,quark:iron_plate:1)
Block(-6,14,-4,quark:iron_plate:1)
Block(-6,14,-3,quark:iron_plate:1)
RandomBlock(-6,14,-2,SMOOTH_BRICK:0,40,SMOOTH_BRICK:1,30,SMOOTH_BRICK:2,30,MOSSY_COBBLESTONE:0,30,COBBLESTONE:0,20,SMOOTH_BRICK:0,100)
RandomBlock(-6,14,-1,SMOOTH_BRICK:0,40,SMOOTH_BRICK:1,30,SMOOTH_BRICK:2,30,MOSSY_COBBLESTONE:0,30,COBBLESTONE:0,20,SMOOTH_BRICK:0,100)
RandomBlock(-6,14,0,SMOOTH_BRICK:0,40,SMOOTH_BRICK:1,30,SMOOTH_BRICK:2,30,MOSSY_COBBLESTONE:0,30,COBBLESTONE:0,20,SMOOTH_BRICK:0,100)
RandomBlock(-6,14,1,SMOOTH_BRICK:0,40,SMOOTH_BRICK:1,30,SMOOTH_BRICK:2,30,MOSSY_COBBLESTONE:0,30,COBBLESTONE:0,20,SMOOTH_BRICK:0,100)
Block(-6,14,2,STEP:0)
Block(-6,14,3,quark:iron_plate:1)
RandomBlock(-6,15,-7,SMOOTH_BRICK:0,40,SMOOTH_BRICK:1,30,SMOOTH_BRICK:2,30,MOSSY_COBBLESTONE:0,30,COBBLESTONE:0,20,SMOOTH_BRICK:0,100)
RandomBlock(-6,15,-6,SMOOTH_BRICK:0,40,SMOOTH_BRICK:1,30,SMOOTH_BRICK:2,30,MOSSY_COBBLESTONE:0,30,COBBLESTONE:0,20,SMOOTH_BRICK:0,100)
RandomBlock(-6,15,-5,SMOOTH_BRICK:0,40,SMOOTH_BRICK:1,30,SMOOTH_BRICK:2,30,MOSSY_COBBLESTONE:0,30,COBBLESTONE:0,20,SMOOTH_BRICK:0,100)
RandomBlock(-6,15,-4,SMOOTH_BRICK:0,40,SMOOTH_BRICK:1,30,SMOOTH_BRICK:2,30,MOSSY_COBBLESTONE:0,30,COBBLESTONE:0,20,SMOOTH_BRICK:0,100)
RandomBlock(-6,15,-3,SMOOTH_BRICK:0,40,SMOOTH_BRICK:1,30,SMOOTH_BRICK:2,30,MOSSY_COBBLESTONE:0,30,COBBLESTONE:0,20,SMOOTH_BRICK:0,100)
Block(-6,15,-2,DOUBLE_STEP:0)
Block(-6,15,-1,DOUBLE_STEP:0)
Block(-6,15,0,DOUBLE_STEP:0)
Block(-6,15,1,DOUBLE_STEP:0)
RandomBlock(-6,15,2,SMOOTH_BRICK:0,40,SMOOTH_BRICK:1,30,SMOOTH_BRICK:2,30,MOSSY_COBBLESTONE:0,30,COBBLESTONE:0,20,SMOOTH_BRICK:0,100)
Block(-6,15,3,quark:iron_plate:1)
Block(-6,16,-7,DOUBLE_STEP:0)
Block(-6,16,-6,DOUBLE_STEP:0)
Block(-6,16,-5,DOUBLE_STEP:0)
Block(-6,16,-4,DOUBLE_STEP:0)
Block(-6,16,-3,DOUBLE_STEP:0)
Block(-6,16,-2,DOUBLE_STEP:0)
Block(-6,16,-1,DOUBLE_STEP:0)
Block(-6,16,0,DOUBLE_STEP:0)
Block(-6,16,1,DOUBLE_STEP:0)
RandomBlock(-6,16,2,SMOOTH_BRICK:0,40,SMOOTH_BRICK:1,30,SMOOTH_BRICK:2,30,MOSSY_COBBLESTONE:0,30,COBBLESTONE:0,20,SMOOTH_BRICK:0,100)
Block(-6,16,3,quark:iron_plate:1)
Block(-6,17,-7,quark:sturdy_stone)
Block(-6,17,-6,quark:sturdy_stone)
Block(-6,17,-5,quark:sturdy_stone)
Block(-6,17,-4,quark:sturdy_stone)
Block(-6,17,-3,quark:sturdy_stone)
Block(-6,17,-2,quark:sturdy_stone)
Block(-6,17,-1,quark:sturdy_stone)
Block(-6,17,0,quark:sturdy_stone)
Block(-6,17,1,quark:sturdy_stone)
Block(-6,17,2,quark:sturdy_stone)
Block(-6,17,3,quark:iron_plate:1)
Block(-6,18,-7,DOUBLE_STEP:0)
Block(-6,18,-6,DOUBLE_STEP:0)
Block(-6,18,-5,DOUBLE_STEP:0)
Block(-6,18,-4,DOUBLE_STEP:0)
Block(-6,18,-3,DOUBLE_STEP:0)
RandomBlock(-6,18,-2,SMOOTH_BRICK:0,40,SMOOTH_BRICK:1,30,SMOOTH_BRICK:2,30,MOSSY_COBBLESTONE:0,30,COBBLESTONE:0,20,SMOOTH_BRICK:0,100)
RandomBlock(-6,18,-1,SMOOTH_BRICK:0,40,SMOOTH_BRICK:1,30,SMOOTH_BRICK:2,30,MOSSY_COBBLESTONE:0,30,COBBLESTONE:0,20,SMOOTH_BRICK:0,100)
RandomBlock(-6,18,0,SMOOTH_BRICK:0,40,SMOOTH_BRICK:1,30,SMOOTH_BRICK:2,30,MOSSY_COBBLESTONE:0,30,COBBLESTONE:0,20,SMOOTH_BRICK:0,100)
RandomBlock(-6,18,1,SMOOTH_BRICK:0,40,SMOOTH_BRICK:1,30,SMOOTH_BRICK:2,30,MOSSY_COBBLESTONE:0,30,COBBLESTONE:0,20,SMOOTH_BRICK:0,100)
Block(-6,18,2,STEP:0)
Block(-6,18,3,quark:iron_plate:1)
Block(-6,19,-7,quark:sturdy_stone)
Block(-6,19,-6,quark:sturdy_stone)
Block(-6,19,-5,quark:sturdy_stone)
Block(-6,19,-4,quark:sturdy_stone)
Block(-6,19,-3,quark:sturdy_stone)
Block(-6,19,-2,quark:sturdy_stone)
Block(-6,19,-1,quark:sturdy_stone)
Block(-6,19,0,quark:sturdy_stone)
Block(-6,19,1,quark:sturdy_stone)
Block(-6,19,2,quark:sturdy_stone)
Block(-6,19,3,DOUBLE_STEP:0)
Block(-6,20,-7,DOUBLE_STEP:0)
Block(-6,20,-6,DOUBLE_STEP:0)
Block(-6,20,-5,DOUBLE_STEP:0)
Block(-6,20,-4,DOUBLE_STEP:0)
Block(-6,20,-3,DOUBLE_STEP:0)
Block(-6,20,-2,DOUBLE_STEP:0)
Block(-6,20,-1,DOUBLE_STEP:0)
Block(-6,20,0,DOUBLE_STEP:0)
Block(-6,20,1,DOUBLE_STEP:0)
Block(-6,21,-7,quark:sturdy_stone)
Block(-6,21,-6,quark:sturdy_stone)
Block(-6,21,-5,quark:sturdy_stone)
Block(-6,21,-4,quark:sturdy_stone)
Block(-6,21,-3,quark:sturdy_stone)
RandomBlock(-6,21,-2,SMOOTH_BRICK:0,40,SMOOTH_BRICK:1,30,SMOOTH_BRICK:2,30,MOSSY_COBBLESTONE:0,30,COBBLESTONE:0,20,SMOOTH_BRICK:0,100)
RandomBlock(-6,21,-1,SMOOTH_BRICK:0,40,SMOOTH_BRICK:1,30,SMOOTH_BRICK:2,30,MOSSY_COBBLESTONE:0,30,COBBLESTONE:0,20,SMOOTH_BRICK:0,100)
RandomBlock(-6,21,0,SMOOTH_BRICK:0,40,SMOOTH_BRICK:1,30,SMOOTH_BRICK:2,30,MOSSY_COBBLESTONE:0,30,COBBLESTONE:0,20,SMOOTH_BRICK:0,100)
RandomBlock(-6,21,1,SMOOTH_BRICK:0,40,SMOOTH_BRICK:1,30,SMOOTH_BRICK:2,30,MOSSY_COBBLESTONE:0,30,COBBLESTONE:0,20,SMOOTH_BRICK:0,100)
Block(-6,22,-7,DOUBLE_STEP:0)
Block(-6,22,-6,DOUBLE_STEP:0)
Block(-6,22,-5,DOUBLE_STEP:0)
Block(-6,22,-4,DOUBLE_STEP:0)
Block(-6,22,-3,DOUBLE_STEP:0)
Block(-6,22,-2,DOUBLE_STEP:0)
Block(-6,22,-1,DOUBLE_STEP:0)
Block(-6,22,0,DOUBLE_STEP:0)
Block(-6,22,1,DOUBLE_STEP:0)
Block(-6,23,-7,SMOOTH_STAIRS:0)
Block(-6,23,-6,SMOOTH_STAIRS:0)
Block(-6,23,-5,SMOOTH_STAIRS:0)
Block(-6,23,-4,SMOOTH_STAIRS:0)
Block(-6,23,-3,SMOOTH_STAIRS:0)
Block(-6,23,-2,SMOOTH_STAIRS:0)
Block(-5,0,-7,quark:world_stone_pavement:2)
Block(-5,0,-6,quark:world_stone_pavement:2)
Block(-5,0,-5,quark:world_stone_pavement:2)
Block(-5,0,-4,quark:world_stone_pavement:2)
Block(-5,0,-3,quark:world_stone_pavement:2)
Block(-5,0,-2,quark:world_stone_pavement:2)
Block(-5,0,-1,quark:world_stone_pavement:2)
Block(-5,0,0,quark:world_stone_pavement:5)
Block(-5,0,1,quark:world_stone_pavement:2)
Block(-5,0,2,quark:world_stone_pavement:2)
Block(-5,0,3,quark:world_stone_pavement:2)
Block(-5,0,4,quark:world_stone_pavement:2)
RandomBlock(-5,0,5,SMOOTH_BRICK:0,40,SMOOTH_BRICK:1,30,SMOOTH_BRICK:2,30,MOSSY_COBBLESTONE:0,30,COBBLESTONE:0,20,SMOOTH_BRICK:0,100)
RandomBlock(-5,0,6,SMOOTH_BRICK:0,40,SMOOTH_BRICK:1,30,SMOOTH_BRICK:2,30,MOSSY_COBBLESTONE:0,30,COBBLESTONE:0,20,SMOOTH_BRICK:0,100)
Block(-5,1,-7,quark:world_stone_pavement:2)
Block(-5,1,-6,quark:world_stone_pavement:2)
Block(-5,1,-5,quark:limestone:1)
Block(-5,1,-4,quark:world_stone_pavement:5)
Block(-5,1,-3,quark:world_stone_pavement:2)
Block(-5,1,-2,quark:limestone:1)
Block(-5,1,-1,quark:world_stone_pavement:5)
Block(-5,1,0,quark:world_stone_pavement:5)
Block(-5,1,1,quark:world_stone_pavement:2)
Block(-5,1,2,quark:world_stone_pavement:2)
Block(-5,1,3,quark:world_stone_pavement:5)
Block(-5,1,4,quark:world_stone_pavement:5)
RandomBlock(-5,1,5,SMOOTH_BRICK:0,40,SMOOTH_BRICK:1,30,SMOOTH_BRICK:2,30,MOSSY_COBBLESTONE:0,30,COBBLESTONE:0,20,SMOOTH_BRICK:0,100)
RandomBlock(-5,1,6,SMOOTH_BRICK:0,40,SMOOTH_BRICK:1,30,SMOOTH_BRICK:2,30,MOSSY_COBBLESTONE:0,30,COBBLESTONE:0,20,SMOOTH_BRICK:0,100)
Block(-5,2,-7,quark:world_stone_pavement:2)
Block(-5,2,-6,quark:world_stone_pavement:2)
Block(-5,2,-5,quark:world_stone_pavement:2)
Block(-5,2,-4,quark:limestone:1)
Block(-5,2,-3,quark:world_stone_pavement:2)
Block(-5,2,-2,quark:world_stone_pavement:2)
Block(-5,2,-1,quark:world_stone_pavement:2)
Block(-5,2,0,quark:limestone:1)
Block(-5,2,1,quark:world_stone_pavement:2)
Block(-5,2,2,quark:world_stone_pavement:2)
Block(-5,2,3,quark:limestone:1)
Block(-5,2,4,quark:limestone:1)
RandomBlock(-5,2,5,SMOOTH_BRICK:0,40,SMOOTH_BRICK:1,30,SMOOTH_BRICK:2,30,MOSSY_COBBLESTONE:0,30,COBBLESTONE:0,20,SMOOTH_BRICK:0,100)
RandomBlock(-5,2,6,SMOOTH_BRICK:0,40,SMOOTH_BRICK:1,30,SMOOTH_BRICK:2,30,MOSSY_COBBLESTONE:0,30,COBBLESTONE:0,20,SMOOTH_BRICK:0,100)
Block(-5,3,-7,quark:world_stone_pavement:2)
Block(-5,3,-6,quark:world_stone_pavement:2)
Block(-5,3,-5,quark:limestone:1)
Block(-5,3,-4,quark:world_stone_pavement:5)
Block(-5,3,-3,quark:world_stone_pavement:2)
Block(-5,3,-2,quark:limestone:1)
Block(-5,3,-1,quark:world_stone_pavement:2)
Block(-5,3,0,quark:world_stone_pavement:2)
Block(-5,3,1,quark:world_stone_pavement:2)
Block(-5,3,2,quark:world_stone_pavement:2)
Block(-5,3,3,quark:limestone:1)
Block(-5,3,4,quark:world_stone_pavement:5)
RandomBlock(-5,3,5,SMOOTH_BRICK:0,40,SMOOTH_BRICK:1,30,SMOOTH_BRICK:2,30,MOSSY_COBBLESTONE:0,30,COBBLESTONE:0,20,SMOOTH_BRICK:0,100)
RandomBlock(-5,3,6,SMOOTH_BRICK:0,40,SMOOTH_BRICK:1,30,SMOOTH_BRICK:2,30,MOSSY_COBBLESTONE:0,30,COBBLESTONE:0,20,SMOOTH_BRICK:0,100)
Block(-5,4,-7,quark:world_stone_pavement:2)
Block(-5,4,-6,quark:world_stone_pavement:2)
Block(-5,4,-5,quark:world_stone_pavement:2)
Block(-5,4,-4,quark:world_stone_pavement:5)
Block(-5,4,-3,quark:world_stone_pavement:2)
Block(-5,4,-2,quark:limestone:1)
Block(-5,4,-1,quark:world_stone_pavement:5)
Block(-5,4,0,quark:world_stone_pavement:5)
Block(-5,4,1,quark:world_stone_pavement:2)
Block(-5,4,2,quark:world_stone_pavement:2)
Block(-5,4,3,quark:world_stone_pavement:2)
Block(-5,4,4,quark:limestone:1)
RandomBlock(-5,4,5,SMOOTH_BRICK:0,40,SMOOTH_BRICK:1,30,SMOOTH_BRICK:2,30,MOSSY_COBBLESTONE:0,30,COBBLESTONE:0,20,SMOOTH_BRICK:0,100)
RandomBlock(-5,4,6,SMOOTH_BRICK:0,40,SMOOTH_BRICK:1,30,SMOOTH_BRICK:2,30,MOSSY_COBBLESTONE:0,30,COBBLESTONE:0,20,SMOOTH_BRICK:0,100)
Block(-5,5,-7,quark:world_stone_pavement:2)
Block(-5,5,-6,quark:world_stone_pavement:2)
Block(-5,5,-5,quark:world_stone_pavement:2)
Block(-5,5,-4,quark:limestone:1)
Block(-5,5,-3,quark:world_stone_pavement:2)
Block(-5,5,-2,quark:world_stone_pavement:5)
Block(-5,5,-1,quark:world_stone_pavement:2)
Block(-5,5,0,quark:world_stone_pavement:2)
Block(-5,5,1,quark:world_stone_pavement:2)
Block(-5,5,2,quark:world_stone_pavement:2)
Block(-5,5,3,quark:limestone:1)
Block(-5,5,4,quark:world_stone_pavement:2)
RandomBlock(-5,5,5,SMOOTH_BRICK:0,40,SMOOTH_BRICK:1,30,SMOOTH_BRICK:2,30,MOSSY_COBBLESTONE:0,30,COBBLESTONE:0,20,SMOOTH_BRICK:0,100)
RandomBlock(-5,5,6,SMOOTH_BRICK:0,40,SMOOTH_BRICK:1,30,SMOOTH_BRICK:2,30,MOSSY_COBBLESTONE:0,30,COBBLESTONE:0,20,SMOOTH_BRICK:0,100)
Block(-5,6,-7,quark:world_stone_pavement:2)
Block(-5,6,-6,quark:world_stone_pavement:2)
Block(-5,6,-5,quark:limestone:1)
Block(-5,6,-4,quark:limestone:1)
Block(-5,6,-3,quark:world_stone_pavement:2)
Block(-5,6,-2,quark:world_stone_pavement:2)
Block(-5,6,-1,quark:world_stone_pavement:5)
Block(-5,6,0,quark:limestone:1)
Block(-5,6,1,quark:world_stone_pavement:2)
Block(-5,6,2,quark:world_stone_pavement:2)
Block(-5,6,3,quark:limestone:1)
Block(-5,6,4,quark:limestone:1)
RandomBlock(-5,6,5,SMOOTH_BRICK:0,40,SMOOTH_BRICK:1,30,SMOOTH_BRICK:2,30,MOSSY_COBBLESTONE:0,30,COBBLESTONE:0,20,SMOOTH_BRICK:0,100)
RandomBlock(-5,6,6,SMOOTH_BRICK:0,40,SMOOTH_BRICK:1,30,SMOOTH_BRICK:2,30,MOSSY_COBBLESTONE:0,30,COBBLESTONE:0,20,SMOOTH_BRICK:0,100)
Block(-5,7,-7,quark:world_stone_pavement:2)
Block(-5,7,-6,quark:world_stone_pavement:2)
Block(-5,7,-5,quark:world_stone_pavement:2)
Block(-5,7,-4,quark:world_stone_pavement:5)
Block(-5,7,-3,quark:limestone:1)
Block(-5,7,-2,quark:world_stone_pavement:2)
Block(-5,7,-1,quark:limestone:1)
Block(-5,7,0,quark:world_stone_pavement:5)
Block(-5,7,1,quark:world_stone_pavement:5)
Block(-5,7,2,quark:world_stone_pavement:2)
Block(-5,7,3,quark:limestone:1)
Block(-5,7,4,quark:world_stone_pavement:5)
RandomBlock(-5,7,5,SMOOTH_BRICK:0,40,SMOOTH_BRICK:1,30,SMOOTH_BRICK:2,30,MOSSY_COBBLESTONE:0,30,COBBLESTONE:0,20,SMOOTH_BRICK:0,100)
RandomBlock(-5,7,6,SMOOTH_BRICK:0,40,SMOOTH_BRICK:1,30,SMOOTH_BRICK:2,30,MOSSY_COBBLESTONE:0,30,COBBLESTONE:0,20,SMOOTH_BRICK:0,100)
Block(-5,8,-7,quark:limestone:1)
Block(-5,8,-6,quark:world_stone_pavement:5)
Block(-5,8,-5,quark:world_stone_pavement:5)
Block(-5,8,-4,quark:world_stone_pavement:2)
Block(-5,8,-3,quark:world_stone_pavement:2)
Block(-5,8,-2,quark:world_stone_pavement:5)
Block(-5,8,-1,quark:world_stone_pavement:2)
Block(-5,8,0,quark:world_stone_pavement:2)
Block(-5,8,1,quark:world_stone_pavement:5)
Block(-5,8,2,quark:limestone:1)
Block(-5,8,3,quark:world_stone_pavement:5)
Block(-5,8,4,quark:world_stone_pavement:5)
RandomBlock(-5,8,5,SMOOTH_BRICK:0,40,SMOOTH_BRICK:1,30,SMOOTH_BRICK:2,30,MOSSY_COBBLESTONE:0,30,COBBLESTONE:0,20,SMOOTH_BRICK:0,100)
RandomBlock(-5,8,6,SMOOTH_BRICK:0,40,SMOOTH_BRICK:1,30,SMOOTH_BRICK:2,30,MOSSY_COBBLESTONE:0,30,COBBLESTONE:0,20,SMOOTH_BRICK:0,100)
Block(-5,9,-7,quark:limestone:1)
Block(-5,9,-6,quark:limestone:1)
Block(-5,9,-5,quark:world_stone_pavement:2)
Block(-5,9,-4,quark:world_stone_pavement:5)
Block(-5,9,-3,quark:world_stone_pavement:5)
Block(-5,9,-2,quark:world_stone_pavement:2)
Block(-5,9,-1,quark:limestone:1)
Block(-5,9,0,quark:world_stone_pavement:5)
Block(-5,9,1,quark:polished_stone)
Block(-5,9,2,quark:world_stone_pavement:2)
Block(-5,9,3,quark:world_stone_pavement:5)
Block(-5,9,4,quark:limestone:1)
RandomBlock(-5,9,5,SMOOTH_BRICK:0,40,SMOOTH_BRICK:1,30,SMOOTH_BRICK:2,30,MOSSY_COBBLESTONE:0,30,COBBLESTONE:0,20,SMOOTH_BRICK:0,100)
RandomBlock(-5,9,6,SMOOTH_BRICK:0,40,SMOOTH_BRICK:1,30,SMOOTH_BRICK:2,30,MOSSY_COBBLESTONE:0,30,COBBLESTONE:0,20,SMOOTH_BRICK:0,100)
Block(-5,10,-7,quark:world_stone_pavement:2)
Block(-5,10,-6,quark:world_stone_pavement:2)
Block(-5,10,-5,quark:world_stone_pavement:2)
Block(-5,10,-4,quark:polished_stone)
Block(-5,10,-3,quark:polished_stone)
Block(-5,10,-2,quark:polished_stone)
Block(-5,10,-1,quark:world_stone_pavement:2)
Block(-5,10,0,quark:polished_stone)
Block(-5,10,1,quark:world_stone_pavement:2)
Block(-5,10,2,quark:polished_stone)
Block(-5,10,3,quark:world_stone_pavement:2)
Block(-5,10,4,quark:polished_stone)
RandomBlock(-5,10,5,SMOOTH_BRICK:0,40,SMOOTH_BRICK:1,30,SMOOTH_BRICK:2,30,MOSSY_COBBLESTONE:0,30,COBBLESTONE:0,20,SMOOTH_BRICK:0,100)
RandomBlock(-5,10,6,SMOOTH_BRICK:0,40,SMOOTH_BRICK:1,30,SMOOTH_BRICK:2,30,MOSSY_COBBLESTONE:0,30,COBBLESTONE:0,20,SMOOTH_BRICK:0,100)
Block(-5,11,-3,quark:iron_plate:1)
RandomBlock(-5,11,-2,variedcommodities:crate:5,5,charm:crate_sealed:5,../../../../Chests/RLCraft/Containers/charm_crate.nbt,10,charm:crate_sealed:5,../../../../Chests/RLCraft/Containers/charm_crate.nbt,100)
Block(-5,11,-1,CAULDRON:3)
RandomBlock(-5,11,0,variedcommodities:crate:5,5,charm:crate_sealed:5,../../../../Chests/RLCraft/Containers/charm_crate.nbt,10,charm:crate_sealed:5,../../../../Chests/RLCraft/Containers/charm_crate.nbt,100)
Block(-5,11,1,CAULDRON:3)
Block(-5,11,2,quark:polished_stone)
Block(-5,11,3,quark:polished_stone)
Block(-5,11,4,quark:world_stone_pavement:2)
Block(-5,11,5,SMOOTH_STAIRS:0)
Block(-5,11,6,SMOOTH_STAIRS:3)
Block(-5,12,-3,quark:iron_plate:1)
Block(-5,12,-1,IRON_TRAPDOOR:3)
RandomBlock(-5,12,0,variedcommodities:crate:5,5,charm:crate_sealed:5,../../../../Chests/RLCraft/Containers/charm_crate.nbt,10,charm:crate_sealed:5,../../../../Chests/RLCraft/Containers/charm_crate.nbt,100)
Block(-5,12,1,IRON_TRAPDOOR:3)
Block(-5,12,2,quark:iron_plate:1)
Block(-5,12,3,quark:iron_plate:1)
Block(-5,12,4,quark:iron_plate:1)
Block(-5,13,-3,quark:iron_plate:1)
Block(-5,13,2,quark:iron_plate:1)
Block(-5,13,3,quark:iron_plate:1)
Block(-5,13,4,quark:iron_plate:1)
Block(-5,14,-3,quark:iron_plate:1)
Block(-5,14,-2,quark:limestone:1)
Block(-5,14,-1,quark:world_stone_pavement:5)
Block(-5,14,0,quark:limestone:1)
Block(-5,14,1,quark:world_stone_pavement:2)
RandomBlock(-5,14,2,SMOOTH_BRICK:0,40,SMOOTH_BRICK:1,30,SMOOTH_BRICK:2,30,MOSSY_COBBLESTONE:0,30,COBBLESTONE:0,20,SMOOTH_BRICK:0,100)
RandomBlock(-5,14,3,SMOOTH_BRICK:0,40,SMOOTH_BRICK:1,30,SMOOTH_BRICK:2,30,MOSSY_COBBLESTONE:0,30,COBBLESTONE:0,20,SMOOTH_BRICK:0,100)
RandomBlock(-5,14,4,SMOOTH_BRICK:0,40,SMOOTH_BRICK:1,30,SMOOTH_BRICK:2,30,MOSSY_COBBLESTONE:0,30,COBBLESTONE:0,20,SMOOTH_BRICK:0,100)
Block(-5,15,-7,DOUBLE_STEP:0)
RandomBlock(-5,15,-6,SMOOTH_BRICK:0,40,SMOOTH_BRICK:1,30,SMOOTH_BRICK:2,30,MOSSY_COBBLESTONE:0,30,COBBLESTONE:0,20,SMOOTH_BRICK:0,100)
Block(-5,15,-5,DOUBLE_STEP:0)
RandomBlock(-5,15,-4,SMOOTH_BRICK:0,40,SMOOTH_BRICK:1,30,SMOOTH_BRICK:2,30,MOSSY_COBBLESTONE:0,30,COBBLESTONE:0,20,SMOOTH_BRICK:0,100)
Block(-5,15,-3,DOUBLE_STEP:0)
RandomBlock(-5,15,-2,SMOOTH_BRICK:0,40,SMOOTH_BRICK:1,30,SMOOTH_BRICK:2,30,MOSSY_COBBLESTONE:0,30,COBBLESTONE:0,20,SMOOTH_BRICK:0,100)
Block(-5,15,-1,DOUBLE_STEP:0)
RandomBlock(-5,15,0,SMOOTH_BRICK:0,40,SMOOTH_BRICK:1,30,SMOOTH_BRICK:2,30,MOSSY_COBBLESTONE:0,30,COBBLESTONE:0,20,SMOOTH_BRICK:0,100)
Block(-5,15,1,DOUBLE_STEP:0)
Block(-5,15,2,DOUBLE_STEP:0)
Block(-5,15,3,DOUBLE_STEP:0)
Block(-5,15,4,DOUBLE_STEP:0)
Block(-5,16,-7,quark:basalt_wall)
Block(-5,16,-3,quark:basalt_wall)
Block(-5,16,-2,quark:basalt_wall)
Block(-5,16,-1,quark:basalt_wall)
Block(-5,16,1,quark:iron_plate:1)
Block(-5,16,2,DOUBLE_STEP:0)
Block(-5,16,3,DOUBLE_STEP:0)
Block(-5,16,4,DOUBLE_STEP:0)
Block(-5,17,-7,quark:basalt_wall)
Block(-5,17,-4,quark:basalt_wall)
Block(-5,17,-1,quark:basalt_wall)
Block(-5,17,1,quark:iron_plate:1)
Block(-5,17,2,DOUBLE_STEP:0)
Block(-5,17,3,DOUBLE_STEP:0)
Block(-5,17,4,DOUBLE_STEP:0)
Block(-5,18,-7,quark:iron_plate:1)
Block(-5,18,-6,quark:iron_plate:1)
Block(-5,18,-5,quark:iron_plate:1)
Block(-5,18,-4,quark:iron_plate:1)
Block(-5,18,-3,quark:iron_plate:1)
Block(-5,18,-2,quark:iron_plate:1)
Block(-5,18,-1,quark:iron_plate:1)
Block(-5,18,0,quark:iron_plate:1)
Block(-5,18,1,quark:iron_plate:1)
RandomBlock(-5,18,2,SMOOTH_BRICK:0,40,SMOOTH_BRICK:1,30,SMOOTH_BRICK:2,30,MOSSY_COBBLESTONE:0,30,COBBLESTONE:0,20,SMOOTH_BRICK:0,100)
RandomBlock(-5,18,3,SMOOTH_BRICK:0,40,SMOOTH_BRICK:1,30,SMOOTH_BRICK:2,30,MOSSY_COBBLESTONE:0,30,COBBLESTONE:0,20,SMOOTH_BRICK:0,100)
RandomBlock(-5,18,4,SMOOTH_BRICK:0,40,SMOOTH_BRICK:1,30,SMOOTH_BRICK:2,30,MOSSY_COBBLESTONE:0,30,COBBLESTONE:0,20,SMOOTH_BRICK:0,100)
Block(-5,19,-7,STEP:0)
Block(-5,19,-6,STEP:0)
Block(-5,19,-5,STEP:0)
Block(-5,19,-4,DOUBLE_STEP:0)
RandomBlock(-5,19,1,variedcommodities:crate,5,charm:crate_sealed,../../../../Chests/RLCraft/Containers/charm_crate.nbt,100)
Block(-5,19,2,DOUBLE_STEP:0)
Block(-5,19,3,DOUBLE_STEP:0)
Block(-5,19,4,DOUBLE_STEP:0)
Block(-5,20,-7,STEP:0)
Block(-5,20,-6,STEP:0)
Block(-5,20,-5,STEP:0)
Block(-5,20,-4,STEP:0)
Block(-5,20,2,DOUBLE_STEP:0)
Block(-5,20,3,DOUBLE_STEP:0)
Block(-5,20,4,DOUBLE_STEP:0)
Block(-5,21,-7,STEP:0)
Block(-5,21,-6,STEP:0)
Block(-5,21,-5,STEP:0)
Block(-5,21,-4,DOUBLE_STEP:0)
RandomBlock(-5,21,2,SMOOTH_BRICK:0,40,SMOOTH_BRICK:1,30,SMOOTH_BRICK:2,30,MOSSY_COBBLESTONE:0,30,COBBLESTONE:0,20,SMOOTH_BRICK:0,100)
RandomBlock(-5,21,3,SMOOTH_BRICK:0,40,SMOOTH_BRICK:1,30,SMOOTH_BRICK:2,30,MOSSY_COBBLESTONE:0,30,COBBLESTONE:0,20,SMOOTH_BRICK:0,100)
RandomBlock(-5,21,4,SMOOTH_BRICK:0,40,SMOOTH_BRICK:1,30,SMOOTH_BRICK:2,30,MOSSY_COBBLESTONE:0,30,COBBLESTONE:0,20,SMOOTH_BRICK:0,100)
Block(-5,22,-4,DOUBLE_STEP:0)
Block(-5,22,2,DOUBLE_STEP:0)
RandomBlock(-5,22,3,SMOOTH_BRICK:0,40,SMOOTH_BRICK:1,30,SMOOTH_BRICK:2,30,MOSSY_COBBLESTONE:0,30,COBBLESTONE:0,20,SMOOTH_BRICK:0,100)
RandomBlock(-5,22,4,SMOOTH_BRICK:0,40,SMOOTH_BRICK:1,30,SMOOTH_BRICK:2,30,MOSSY_COBBLESTONE:0,30,COBBLESTONE:0,20,SMOOTH_BRICK:0,100)
Block(-5,23,-7,DOUBLE_STEP:0)
Block(-5,23,-6,DOUBLE_STEP:0)
Block(-5,23,-5,DOUBLE_STEP:0)
Block(-5,23,-4,DOUBLE_STEP:0)
Block(-5,23,-3,DOUBLE_STEP:0)
Block(-5,23,-2,DOUBLE_STEP:0)
RandomBlock(-5,23,-1,SMOOTH_BRICK:0,40,SMOOTH_BRICK:1,30,SMOOTH_BRICK:2,30,MOSSY_COBBLESTONE:0,30,COBBLESTONE:0,20,SMOOTH_BRICK:0,100)
RandomBlock(-5,23,0,SMOOTH_BRICK:0,40,SMOOTH_BRICK:1,30,SMOOTH_BRICK:2,30,MOSSY_COBBLESTONE:0,30,COBBLESTONE:0,20,SMOOTH_BRICK:0,100)
RandomBlock(-5,23,1,SMOOTH_BRICK:0,40,SMOOTH_BRICK:1,30,SMOOTH_BRICK:2,30,MOSSY_COBBLESTONE:0,30,COBBLESTONE:0,20,SMOOTH_BRICK:0,100)
Block(-5,24,-7,DOUBLE_STEP:0)
Block(-5,24,-6,DOUBLE_STEP:0)
Block(-5,24,-5,DOUBLE_STEP:0)
Block(-5,24,-4,DOUBLE_STEP:0)
Block(-5,24,-3,DOUBLE_STEP:0)
Block(-5,24,-2,DOUBLE_STEP:0)
RandomBlock(-5,24,-1,SMOOTH_BRICK:0,40,SMOOTH_BRICK:1,30,SMOOTH_BRICK:2,30,MOSSY_COBBLESTONE:0,30,COBBLESTONE:0,20,SMOOTH_BRICK:0,100)
RandomBlock(-5,24,0,SMOOTH_BRICK:0,40,SMOOTH_BRICK:1,30,SMOOTH_BRICK:2,30,MOSSY_COBBLESTONE:0,30,COBBLESTONE:0,20,SMOOTH_BRICK:0,100)
RandomBlock(-5,24,1,SMOOTH_BRICK:0,40,SMOOTH_BRICK:1,30,SMOOTH_BRICK:2,30,MOSSY_COBBLESTONE:0,30,COBBLESTONE:0,20,SMOOTH_BRICK:0,100)
Block(-4,0,-7,quark:world_stone_pavement:2)
Block(-4,0,-6,quark:limestone:1)
Block(-4,0,-5,quark:world_stone_pavement:2)
Block(-4,0,-4,quark:world_stone_pavement:5)
Block(-4,0,-3,quark:world_stone_pavement:2)
Block(-4,0,-2,quark:world_stone_pavement:2)
Block(-4,0,-1,quark:limestone:1)
Block(-4,0,0,quark:limestone:1)
Block(-4,0,1,quark:world_stone_pavement:2)
Block(-4,0,2,quark:world_stone_pavement:2)
Block(-4,0,3,quark:world_stone_pavement:5)
Block(-4,0,4,quark:world_stone_pavement:5)
Block(-4,0,5,quark:world_stone_pavement:5)
RandomBlock(-4,0,6,SMOOTH_BRICK:0,40,SMOOTH_BRICK:1,30,SMOOTH_BRICK:2,30,MOSSY_COBBLESTONE:0,30,COBBLESTONE:0,20,SMOOTH_BRICK:0,100)
Block(-4,1,-7,quark:limestone:1)
Block(-4,1,-6,quark:world_stone_pavement:2)
Block(-4,1,-5,quark:world_stone_pavement:2)
Block(-4,1,-4,quark:limestone:1)
Block(-4,1,-3,quark:world_stone_pavement:2)
Block(-4,1,-2,quark:world_stone_pavement:2)
Block(-4,1,-1,quark:limestone:1)
Block(-4,1,0,quark:world_stone_pavement:2)
Block(-4,1,1,quark:world_stone_pavement:2)
Block(-4,1,2,quark:world_stone_pavement:2)
Block(-4,1,3,quark:limestone:1)
Block(-4,1,4,quark:world_stone_pavement:5)
Block(-4,1,5,quark:world_stone_pavement:5)
RandomBlock(-4,1,6,SMOOTH_BRICK:0,40,SMOOTH_BRICK:1,30,SMOOTH_BRICK:2,30,MOSSY_COBBLESTONE:0,30,COBBLESTONE:0,20,SMOOTH_BRICK:0,100)
Block(-4,2,-7,quark:limestone:1)
Block(-4,2,-6,quark:world_stone_pavement:2)
Block(-4,2,-5,quark:world_stone_pavement:2)
Block(-4,2,-4,quark:world_stone_pavement:5)
Block(-4,2,-3,quark:world_stone_pavement:2)
Block(-4,2,-2,quark:world_stone_pavement:2)
Block(-4,2,-1,quark:limestone:1)
Block(-4,2,0,quark:world_stone_pavement:2)
Block(-4,2,1,quark:world_stone_pavement:2)
Block(-4,2,2,quark:world_stone_pavement:2)
Block(-4,2,3,quark:limestone:1)
Block(-4,2,4,quark:world_stone_pavement:2)
Block(-4,2,5,quark:world_stone_pavement:5)
RandomBlock(-4,2,6,SMOOTH_BRICK:0,40,SMOOTH_BRICK:1,30,SMOOTH_BRICK:2,30,MOSSY_COBBLESTONE:0,30,COBBLESTONE:0,20,SMOOTH_BRICK:0,100)
Block(-4,3,-7,quark:limestone:1)
Block(-4,3,-6,quark:limestone:1)
Block(-4,3,-5,quark:world_stone_pavement:2)
Block(-4,3,-4,quark:world_stone_pavement:2)
Block(-4,3,-3,quark:world_stone_pavement:2)
Block(-4,3,-2,quark:world_stone_pavement:2)
Block(-4,3,-1,quark:world_stone_pavement:2)
Block(-4,3,0,quark:world_stone_pavement:2)
Block(-4,3,1,quark:world_stone_pavement:2)
Block(-4,3,2,quark:world_stone_pavement:2)
Block(-4,3,3,quark:limestone:1)
Block(-4,3,4,quark:world_stone_pavement:5)
Block(-4,3,5,quark:limestone:1)
RandomBlock(-4,3,6,SMOOTH_BRICK:0,40,SMOOTH_BRICK:1,30,SMOOTH_BRICK:2,30,MOSSY_COBBLESTONE:0,30,COBBLESTONE:0,20,SMOOTH_BRICK:0,100)
Block(-4,4,-7,quark:world_stone_pavement:2)
Block(-4,4,-6,quark:world_stone_pavement:5)
Block(-4,4,-5,quark:world_stone_pavement:2)
Block(-4,4,-4,quark:limestone:1)
Block(-4,4,-3,quark:world_stone_pavement:2)
Block(-4,4,-2,quark:world_stone_pavement:2)
Block(-4,4,-1,quark:limestone:1)
Block(-4,4,0,quark:limestone:1)
Block(-4,4,1,quark:world_stone_pavement:2)
Block(-4,4,2,quark:world_stone_pavement:2)
Block(-4,4,3,quark:world_stone_pavement:2)
Block(-4,4,4,quark:world_stone_pavement:2)
Block(-4,4,5,quark:world_stone_pavement:5)
RandomBlock(-4,4,6,SMOOTH_BRICK:0,40,SMOOTH_BRICK:1,30,SMOOTH_BRICK:2,30,MOSSY_COBBLESTONE:0,30,COBBLESTONE:0,20,SMOOTH_BRICK:0,100)
Block(-4,5,-7,quark:limestone:1)
Block(-4,5,-6,quark:limestone:1)
Block(-4,5,-5,quark:world_stone_pavement:2)
Block(-4,5,-4,quark:limestone:1)
Block(-4,5,-3,quark:world_stone_pavement:2)
Block(-4,5,-2,quark:world_stone_pavement:2)
Block(-4,5,-1,quark:limestone:1)
Block(-4,5,0,quark:limestone:1)
Block(-4,5,1,quark:world_stone_pavement:2)
Block(-4,5,2,quark:world_stone_pavement:2)
Block(-4,5,3,quark:world_stone_pavement:5)
Block(-4,5,4,quark:world_stone_pavement:5)
Block(-4,5,5,quark:limestone:1)
RandomBlock(-4,5,6,SMOOTH_BRICK:0,40,SMOOTH_BRICK:1,30,SMOOTH_BRICK:2,30,MOSSY_COBBLESTONE:0,30,COBBLESTONE:0,20,SMOOTH_BRICK:0,100)
Block(-4,6,-7,quark:limestone:1)
Block(-4,6,-6,quark:world_stone_pavement:5)
Block(-4,6,-5,quark:world_stone_pavement:2)
Block(-4,6,-4,quark:world_stone_pavement:5)
Block(-4,6,-3,quark:world_stone_pavement:2)
Block(-4,6,-2,quark:world_stone_pavement:2)
Block(-4,6,-1,quark:world_stone_pavement:2)
Block(-4,6,0,quark:world_stone_pavement:5)
Block(-4,6,1,quark:world_stone_pavement:2)
Block(-4,6,2,quark:world_stone_pavement:2)
Block(-4,6,3,quark:world_stone_pavement:5)
Block(-4,6,4,quark:world_stone_pavement:5)
Block(-4,6,5,quark:world_stone_pavement:5)
RandomBlock(-4,6,6,SMOOTH_BRICK:0,40,SMOOTH_BRICK:1,30,SMOOTH_BRICK:2,30,MOSSY_COBBLESTONE:0,30,COBBLESTONE:0,20,SMOOTH_BRICK:0,100)
Block(-4,7,-7,quark:limestone:1)
Block(-4,7,-6,quark:limestone:1)
Block(-4,7,-5,quark:world_stone_pavement:5)
Block(-4,7,-4,quark:limestone:1)
Block(-4,7,-3,quark:world_stone_pavement:5)
Block(-4,7,-2,quark:world_stone_pavement:5)
Block(-4,7,-1,quark:world_stone_pavement:2)
Block(-4,7,0,quark:world_stone_pavement:5)
Block(-4,7,1,quark:world_stone_pavement:5)
Block(-4,7,2,quark:world_stone_pavement:2)
Block(-4,7,3,quark:world_stone_pavement:2)
Block(-4,7,4,quark:world_stone_pavement:5)
Block(-4,7,5,quark:limestone:1)
RandomBlock(-4,7,6,SMOOTH_BRICK:0,40,SMOOTH_BRICK:1,30,SMOOTH_BRICK:2,30,MOSSY_COBBLESTONE:0,30,COBBLESTONE:0,20,SMOOTH_BRICK:0,100)
Block(-4,8,-7,quark:world_stone_pavement:2)
Block(-4,8,-6,quark:world_stone_pavement:2)
Block(-4,8,-5,quark:world_stone_pavement:2)
Block(-4,8,-4,quark:limestone:1)
Block(-4,8,-3,quark:world_stone_pavement:5)
Block(-4,8,-2,quark:world_stone_pavement:2)
Block(-4,8,-1,quark:world_stone_pavement:5)
Block(-4,8,0,quark:limestone:1)
Block(-4,8,1,quark:world_stone_pavement:2)
Block(-4,8,2,quark:world_stone_pavement:2)
Block(-4,8,3,quark:world_stone_pavement:2)
Block(-4,8,4,quark:limestone:1)
Block(-4,8,5,quark:world_stone_pavement:5)
RandomBlock(-4,8,6,SMOOTH_BRICK:0,40,SMOOTH_BRICK:1,30,SMOOTH_BRICK:2,30,MOSSY_COBBLESTONE:0,30,COBBLESTONE:0,20,SMOOTH_BRICK:0,100)
Block(-4,9,-7,quark:world_stone_pavement:2)
Block(-4,9,-6,quark:world_stone_pavement:2)
Block(-4,9,-5,quark:limestone:1)
Block(-4,9,-4,quark:world_stone_pavement:5)
Block(-4,9,-3,quark:world_stone_pavement:2)
Block(-4,9,-2,quark:world_stone_pavement:2)
Block(-4,9,-1,quark:world_stone_pavement:2)
Block(-4,9,0,quark:world_stone_pavement:2)
Block(-4,9,1,quark:world_stone_pavement:2)
Block(-4,9,2,quark:world_stone_pavement:2)
Block(-4,9,3,quark:limestone:1)
Block(-4,9,4,quark:limestone:1)
Block(-4,9,5,quark:world_stone_pavement:5)
RandomBlock(-4,9,6,SMOOTH_BRICK:0,40,SMOOTH_BRICK:1,30,SMOOTH_BRICK:2,30,MOSSY_COBBLESTONE:0,30,COBBLESTONE:0,20,SMOOTH_BRICK:0,100)
Block(-4,10,-7,quark:limestone:1)
Block(-4,10,-6,quark:world_stone_pavement:5)
Block(-4,10,-5,quark:polished_stone)
Block(-4,10,-4,quark:limestone:1)
Block(-4,10,-3,quark:polished_stone)
Block(-4,10,-2,quark:world_stone_pavement:2)
Block(-4,10,-1,quark:world_stone_pavement:2)
Block(-4,10,0,quark:world_stone_pavement:5)
Block(-4,10,1,quark:world_stone_pavement:5)
Block(-4,10,2,quark:polished_stone)
Block(-4,10,3,quark:world_stone_pavement:2)
Block(-4,10,4,quark:polished_stone)
Block(-4,10,5,quark:polished_stone)
RandomBlock(-4,10,6,SMOOTH_BRICK:0,40,SMOOTH_BRICK:1,30,SMOOTH_BRICK:2,30,MOSSY_COBBLESTONE:0,30,COBBLESTONE:0,20,SMOOTH_BRICK:0,100)
RandomBlock(-4,11,-2,variedcommodities:crate:5,5,charm:crate_sealed:5,../../../../Chests/RLCraft/Containers/charm_crate.nbt,10,charm:crate_sealed:5,../../../../Chests/RLCraft/Containers/charm_crate.nbt,100)
Block(-4,11,2,CAULDRON:3)
RandomBlock(-4,11,3,variedcommodities:crate,5,charm:crate_sealed,../../../../Chests/RLCraft/Containers/charm_crate.nbt,100)
RandomBlock(-4,11,4,variedcommodities:crate:5,5,charm:crate_sealed:5,../../../../Chests/RLCraft/Containers/charm_crate.nbt,10,charm:crate_sealed:5,../../../../Chests/RLCraft/Containers/charm_crate.nbt,100)
Block(-4,11,5,quark:world_stone_pavement:2)
Block(-4,11,6,SMOOTH_STAIRS:3)
RandomBlock(-4,12,3,variedcommodities:crate,5,charm:crate_sealed,../../../../Chests/RLCraft/Containers/charm_crate.nbt,100)
RandomBlock(-4,12,4,variedcommodities:crate:5,5,charm:crate_sealed:5,../../../../Chests/RLCraft/Containers/charm_crate.nbt,10,charm:crate_sealed:5,../../../../Chests/RLCraft/Containers/charm_crate.nbt,100)
Block(-4,12,5,quark:iron_plate:1)
RandomBlock(-4,13,4,variedcommodities:crate:5,5,charm:crate_sealed:5,../../../../Chests/RLCraft/Containers/charm_crate.nbt,10,charm:crate_sealed:5,../../../../Chests/RLCraft/Containers/charm_crate.nbt,100)
Block(-4,13,5,quark:iron_plate:1)
RandomBlock(-4,14,5,SMOOTH_BRICK:0,40,SMOOTH_BRICK:1,30,SMOOTH_BRICK:2,30,MOSSY_COBBLESTONE:0,30,COBBLESTONE:0,20,SMOOTH_BRICK:0,100)
RandomBlock(-4,15,-7,SMOOTH_BRICK:0,40,SMOOTH_BRICK:1,30,SMOOTH_BRICK:2,30,MOSSY_COBBLESTONE:0,30,COBBLESTONE:0,20,SMOOTH_BRICK:0,100)
RandomBlock(-4,15,-6,SMOOTH_BRICK:0,40,SMOOTH_BRICK:1,30,SMOOTH_BRICK:2,30,MOSSY_COBBLESTONE:0,30,COBBLESTONE:0,20,SMOOTH_BRICK:0,100)
RandomBlock(-4,15,-5,SMOOTH_BRICK:0,40,SMOOTH_BRICK:1,30,SMOOTH_BRICK:2,30,MOSSY_COBBLESTONE:0,30,COBBLESTONE:0,20,SMOOTH_BRICK:0,100)
RandomBlock(-4,15,-4,SMOOTH_BRICK:0,40,SMOOTH_BRICK:1,30,SMOOTH_BRICK:2,30,MOSSY_COBBLESTONE:0,30,COBBLESTONE:0,20,SMOOTH_BRICK:0,100)
RandomBlock(-4,15,-3,SMOOTH_BRICK:0,40,SMOOTH_BRICK:1,30,SMOOTH_BRICK:2,30,MOSSY_COBBLESTONE:0,30,COBBLESTONE:0,20,SMOOTH_BRICK:0,100)
RandomBlock(-4,15,-2,SMOOTH_BRICK:0,40,SMOOTH_BRICK:1,30,SMOOTH_BRICK:2,30,MOSSY_COBBLESTONE:0,30,COBBLESTONE:0,20,SMOOTH_BRICK:0,100)
RandomBlock(-4,15,-1,SMOOTH_BRICK:0,40,SMOOTH_BRICK:1,30,SMOOTH_BRICK:2,30,MOSSY_COBBLESTONE:0,30,COBBLESTONE:0,20,SMOOTH_BRICK:0,100)
RandomBlock(-4,15,0,SMOOTH_BRICK:0,40,SMOOTH_BRICK:1,30,SMOOTH_BRICK:2,30,MOSSY_COBBLESTONE:0,30,COBBLESTONE:0,20,SMOOTH_BRICK:0,100)
RandomBlock(-4,15,1,SMOOTH_BRICK:0,40,SMOOTH_BRICK:1,30,SMOOTH_BRICK:2,30,MOSSY_COBBLESTONE:0,30,COBBLESTONE:0,20,SMOOTH_BRICK:0,100)
RandomBlock(-4,15,2,SMOOTH_BRICK:0,40,SMOOTH_BRICK:1,30,SMOOTH_BRICK:2,30,MOSSY_COBBLESTONE:0,30,COBBLESTONE:0,20,SMOOTH_BRICK:0,100)
RandomBlock(-4,15,3,SMOOTH_BRICK:0,40,SMOOTH_BRICK:1,30,SMOOTH_BRICK:2,30,MOSSY_COBBLESTONE:0,30,COBBLESTONE:0,20,SMOOTH_BRICK:0,100)
RandomBlock(-4,15,4,SMOOTH_BRICK:0,40,SMOOTH_BRICK:1,30,SMOOTH_BRICK:2,30,MOSSY_COBBLESTONE:0,30,COBBLESTONE:0,20,SMOOTH_BRICK:0,100)
Block(-4,15,5,DOUBLE_STEP:0)
Block(-4,16,1,DOUBLE_STEP:0)
Block(-4,16,4,DOUBLE_STEP:0)
Block(-4,16,5,DOUBLE_STEP:0)
Block(-4,17,1,DOUBLE_STEP:0)
Block(-4,17,4,DOUBLE_STEP:0)
Block(-4,17,5,DOUBLE_STEP:0)
Block(-4,18,-7,quark:iron_plate:1)
Block(-4,18,-6,quark:iron_plate:1)
Block(-4,18,-5,quark:iron_plate:1)
Block(-4,18,-4,quark:iron_plate:1)
Block(-4,18,-3,quark:iron_plate:1)
Block(-4,18,-2,quark:iron_plate:1)
Block(-4,18,-1,quark:iron_plate:1)
Block(-4,18,0,quark:iron_plate:1)
Block(-4,18,1,quark:iron_plate:1)
Block(-4,18,2,quark:iron_plate:1)
Block(-4,18,3,quark:iron_plate:1)
Block(-4,18,4,DOUBLE_STEP:0)
RandomBlock(-4,18,5,SMOOTH_BRICK:0,40,SMOOTH_BRICK:1,30,SMOOTH_BRICK:2,30,MOSSY_COBBLESTONE:0,30,COBBLESTONE:0,20,SMOOTH_BRICK:0,100)
RandomBlock(-4,19,2,variedcommodities:crate,5,charm:crate_sealed,../../../../Chests/RLCraft/Containers/charm_crate.nbt,100)
RandomBlock(-4,19,3,variedcommodities:crate:5,5,charm:crate_sealed:5,../../../../Chests/RLCraft/Containers/charm_crate.nbt,10,charm:crate_sealed:5,../../../../Chests/RLCraft/Containers/charm_crate.nbt,100)
Block(-4,19,4,DOUBLE_STEP:0)
Block(-4,19,5,DOUBLE_STEP:0)
RandomBlock(-4,20,3,variedcommodities:crate:5,5,charm:crate_sealed:5,../../../../Chests/RLCraft/Containers/charm_crate.nbt,10,charm:crate_sealed:5,../../../../Chests/RLCraft/Containers/charm_crate.nbt,100)
Block(-4,20,4,DOUBLE_STEP:0)
Block(-4,20,5,DOUBLE_STEP:0)
RandomBlock(-4,21,3,SMOOTH_BRICK:0,40,SMOOTH_BRICK:1,30,SMOOTH_BRICK:2,30,MOSSY_COBBLESTONE:0,30,COBBLESTONE:0,20,SMOOTH_BRICK:0,100)
RandomBlock(-4,21,4,SMOOTH_BRICK:0,40,SMOOTH_BRICK:1,30,SMOOTH_BRICK:2,30,MOSSY_COBBLESTONE:0,30,COBBLESTONE:0,20,SMOOTH_BRICK:0,100)
RandomBlock(-4,21,5,SMOOTH_BRICK:0,40,SMOOTH_BRICK:1,30,SMOOTH_BRICK:2,30,MOSSY_COBBLESTONE:0,30,COBBLESTONE:0,20,SMOOTH_BRICK:0,100)
Block(-4,22,3,DOUBLE_STEP:0)
Block(-4,22,4,DOUBLE_STEP:0)
RandomBlock(-4,23,2,SMOOTH_BRICK:0,40,SMOOTH_BRICK:1,30,SMOOTH_BRICK:2,30,MOSSY_COBBLESTONE:0,30,COBBLESTONE:0,20,SMOOTH_BRICK:0,100)
Block(-4,24,-2,DOUBLE_STEP:0)
Block(-4,24,-1,DOUBLE_STEP:0)
Block(-4,24,0,DOUBLE_STEP:0)
Block(-4,24,1,DOUBLE_STEP:0)
Block(-4,24,2,DOUBLE_STEP:0)
RandomBlock(-4,25,-7,SMOOTH_BRICK:0,40,SMOOTH_BRICK:1,30,SMOOTH_BRICK:2,30,MOSSY_COBBLESTONE:0,30,COBBLESTONE:0,20,SMOOTH_BRICK:0,100)
RandomBlock(-4,25,-6,SMOOTH_BRICK:0,40,SMOOTH_BRICK:1,30,SMOOTH_BRICK:2,30,MOSSY_COBBLESTONE:0,30,COBBLESTONE:0,20,SMOOTH_BRICK:0,100)
RandomBlock(-4,25,-5,SMOOTH_BRICK:0,40,SMOOTH_BRICK:1,30,SMOOTH_BRICK:2,30,MOSSY_COBBLESTONE:0,30,COBBLESTONE:0,20,SMOOTH_BRICK:0,100)
RandomBlock(-4,25,-4,SMOOTH_BRICK:0,40,SMOOTH_BRICK:1,30,SMOOTH_BRICK:2,30,MOSSY_COBBLESTONE:0,30,COBBLESTONE:0,20,SMOOTH_BRICK:0,100)
RandomBlock(-4,25,-3,SMOOTH_BRICK:0,40,SMOOTH_BRICK:1,30,SMOOTH_BRICK:2,30,MOSSY_COBBLESTONE:0,30,COBBLESTONE:0,20,SMOOTH_BRICK:0,100)
Block(-4,25,-2,DOUBLE_STEP:0)
Block(-4,25,-1,DOUBLE_STEP:0)
Block(-4,25,0,DOUBLE_STEP:0)
Block(-4,25,1,DOUBLE_STEP:0)
Block(-4,25,2,DOUBLE_STEP:0)
Block(-4,26,-7,SMOOTH_STAIRS:0)
Block(-4,26,-6,SMOOTH_STAIRS:0)
Block(-4,26,-5,SMOOTH_STAIRS:0)
Block(-4,26,-4,SMOOTH_STAIRS:0)
Block(-4,26,-3,SMOOTH_STAIRS:0)
Block(-4,26,-2,SMOOTH_STAIRS:0)
Block(-4,26,-1,DOUBLE_STEP:0)
Block(-4,26,0,DOUBLE_STEP:0)
Block(-4,26,1,DOUBLE_STEP:0)
Block(-4,26,2,DOUBLE_STEP:0)
Block(-3,0,-7,quark:world_stone_pavement:2)
Block(-3,0,-6,quark:world_stone_pavement:2)
Block(-3,0,-5,quark:world_stone_pavement:2)
Block(-3,0,-4,quark:world_stone_pavement:5)
Block(-3,0,-3,quark:world_stone_pavement:5)
Block(-3,0,-2,quark:world_stone_pavement:2)
Block(-3,0,-1,quark:limestone:1)
Block(-3,0,0,quark:world_stone_pavement:5)
Block(-3,0,1,quark:world_stone_pavement:2)
Block(-3,0,2,quark:world_stone_pavement:2)
Block(-3,0,3,quark:world_stone_pavement:2)
Block(-3,0,4,quark:world_stone_pavement:2)
Block(-3,0,5,quark:world_stone_pavement:5)
RandomBlock(-3,0,6,SMOOTH_BRICK:0,40,SMOOTH_BRICK:1,30,SMOOTH_BRICK:2,30,MOSSY_COBBLESTONE:0,30,COBBLESTONE:0,20,SMOOTH_BRICK:0,100)
Block(-3,1,-7,quark:world_stone_pavement:2)
Block(-3,1,-6,quark:world_stone_pavement:2)
Block(-3,1,-5,quark:world_stone_pavement:2)
Block(-3,1,-4,quark:limestone:1)
Block(-3,1,-3,quark:limestone:1)
Block(-3,1,-2,quark:world_stone_pavement:2)
Block(-3,1,-1,quark:limestone:1)
Block(-3,1,0,quark:world_stone_pavement:2)
Block(-3,1,1,quark:world_stone_pavement:2)
Block(-3,1,2,quark:limestone:1)
Block(-3,1,3,quark:world_stone_pavement:2)
Block(-3,1,4,quark:world_stone_pavement:2)
Block(-3,1,5,quark:limestone:1)
RandomBlock(-3,1,6,SMOOTH_BRICK:0,40,SMOOTH_BRICK:1,30,SMOOTH_BRICK:2,30,MOSSY_COBBLESTONE:0,30,COBBLESTONE:0,20,SMOOTH_BRICK:0,100)
Block(-3,2,-7,quark:world_stone_pavement:2)
Block(-3,2,-6,quark:world_stone_pavement:2)
Block(-3,2,-5,quark:world_stone_pavement:2)
Block(-3,2,-4,quark:world_stone_pavement:5)
Block(-3,2,-3,quark:world_stone_pavement:2)
Block(-3,2,-2,quark:world_stone_pavement:2)
Block(-3,2,-1,quark:world_stone_pavement:2)
Block(-3,2,0,quark:world_stone_pavement:2)
Block(-3,2,1,quark:limestone:1)
Block(-3,2,2,quark:world_stone_pavement:2)
Block(-3,2,3,quark:world_stone_pavement:2)
Block(-3,2,4,quark:limestone:1)
Block(-3,2,5,quark:world_stone_pavement:5)
RandomBlock(-3,2,6,SMOOTH_BRICK:0,40,SMOOTH_BRICK:1,30,SMOOTH_BRICK:2,30,MOSSY_COBBLESTONE:0,30,COBBLESTONE:0,20,SMOOTH_BRICK:0,100)
Block(-3,3,-7,quark:world_stone_pavement:2)
Block(-3,3,-6,quark:world_stone_pavement:2)
Block(-3,3,-5,quark:world_stone_pavement:2)
Block(-3,3,-4,quark:world_stone_pavement:2)
Block(-3,3,-3,quark:world_stone_pavement:2)
Block(-3,3,-2,quark:world_stone_pavement:2)
Block(-3,3,-1,quark:world_stone_pavement:5)
Block(-3,3,0,quark:limestone:1)
Block(-3,3,1,quark:world_stone_pavement:5)
Block(-3,3,2,quark:world_stone_pavement:5)
Block(-3,3,3,quark:world_stone_pavement:2)
Block(-3,3,4,quark:world_stone_pavement:2)
Block(-3,3,5,quark:world_stone_pavement:5)
RandomBlock(-3,3,6,SMOOTH_BRICK:0,40,SMOOTH_BRICK:1,30,SMOOTH_BRICK:2,30,MOSSY_COBBLESTONE:0,30,COBBLESTONE:0,20,SMOOTH_BRICK:0,100)
Block(-3,4,-7,quark:world_stone_pavement:2)
Block(-3,4,-6,quark:world_stone_pavement:2)
Block(-3,4,-5,quark:world_stone_pavement:2)
Block(-3,4,-4,quark:limestone:1)
Block(-3,4,-3,quark:world_stone_pavement:2)
Block(-3,4,-2,quark:world_stone_pavement:2)
Block(-3,4,-1,quark:limestone:1)
Block(-3,4,0,quark:world_stone_pavement:2)
Block(-3,4,1,quark:limestone:1)
Block(-3,4,2,quark:world_stone_pavement:5)
Block(-3,4,3,quark:world_stone_pavement:2)
Block(-3,4,4,quark:limestone:1)
Block(-3,4,5,quark:world_stone_pavement:2)
RandomBlock(-3,4,6,SMOOTH_BRICK:0,40,SMOOTH_BRICK:1,30,SMOOTH_BRICK:2,30,MOSSY_COBBLESTONE:0,30,COBBLESTONE:0,20,SMOOTH_BRICK:0,100)
Block(-3,5,-7,quark:world_stone_pavement:2)
Block(-3,5,-6,quark:world_stone_pavement:2)
Block(-3,5,-5,quark:world_stone_pavement:2)
Block(-3,5,-4,quark:limestone:1)
Block(-3,5,-3,quark:limestone:1)
Block(-3,5,-2,quark:world_stone_pavement:2)
Block(-3,5,-1,quark:world_stone_pavement:2)
Block(-3,5,0,quark:world_stone_pavement:5)
Block(-3,5,1,quark:world_stone_pavement:5)
Block(-3,5,2,quark:world_stone_pavement:5)
Block(-3,5,3,quark:world_stone_pavement:2)
Block(-3,5,4,quark:limestone:1)
Block(-3,5,5,quark:limestone:1)
RandomBlock(-3,5,6,SMOOTH_BRICK:0,40,SMOOTH_BRICK:1,30,SMOOTH_BRICK:2,30,MOSSY_COBBLESTONE:0,30,COBBLESTONE:0,20,SMOOTH_BRICK:0,100)
Block(-3,6,-7,quark:world_stone_pavement:2)
Block(-3,6,-6,quark:world_stone_pavement:2)
Block(-3,6,-5,quark:world_stone_pavement:2)
Block(-3,6,-4,quark:world_stone_pavement:5)
Block(-3,6,-3,quark:world_stone_pavement:5)
Block(-3,6,-2,quark:world_stone_pavement:2)
Block(-3,6,-1,quark:world_stone_pavement:2)
Block(-3,6,0,quark:world_stone_pavement:2)
Block(-3,6,1,quark:world_stone_pavement:2)
Block(-3,6,2,quark:world_stone_pavement:5)
Block(-3,6,3,quark:world_stone_pavement:2)
Block(-3,6,4,quark:limestone:1)
Block(-3,6,5,quark:world_stone_pavement:5)
RandomBlock(-3,6,6,SMOOTH_BRICK:0,40,SMOOTH_BRICK:1,30,SMOOTH_BRICK:2,30,MOSSY_COBBLESTONE:0,30,COBBLESTONE:0,20,SMOOTH_BRICK:0,100)
Block(-3,7,-7,quark:world_stone_pavement:5)
Block(-3,7,-6,quark:world_stone_pavement:5)
Block(-3,7,-5,quark:limestone:1)
Block(-3,7,-4,quark:world_stone_pavement:5)
Block(-3,7,-3,quark:world_stone_pavement:2)
Block(-3,7,-2,quark:world_stone_pavement:2)
Block(-3,7,-1,quark:world_stone_pavement:2)
Block(-3,7,0,quark:world_stone_pavement:2)
Block(-3,7,1,quark:world_stone_pavement:2)
Block(-3,7,2,quark:world_stone_pavement:2)
Block(-3,7,3,quark:world_stone_pavement:2)
Block(-3,7,4,quark:limestone:1)
Block(-3,7,5,quark:world_stone_pavement:5)
RandomBlock(-3,7,6,SMOOTH_BRICK:0,40,SMOOTH_BRICK:1,30,SMOOTH_BRICK:2,30,MOSSY_COBBLESTONE:0,30,COBBLESTONE:0,20,SMOOTH_BRICK:0,100)
Block(-3,8,-7,quark:limestone:1)
Block(-3,8,-6,quark:world_stone_pavement:2)
Block(-3,8,-5,quark:world_stone_pavement:2)
Block(-3,8,-4,quark:world_stone_pavement:5)
Block(-3,8,-3,quark:world_stone_pavement:5)
Block(-3,8,-2,quark:world_stone_pavement:2)
Block(-3,8,-1,quark:world_stone_pavement:5)
Block(-3,8,0,quark:world_stone_pavement:2)
Block(-3,8,1,quark:limestone:1)
Block(-3,8,2,quark:world_stone_pavement:2)
Block(-3,8,3,quark:limestone:1)
Block(-3,8,4,quark:world_stone_pavement:5)
Block(-3,8,5,quark:world_stone_pavement:2)
RandomBlock(-3,8,6,SMOOTH_BRICK:0,40,SMOOTH_BRICK:1,30,SMOOTH_BRICK:2,30,MOSSY_COBBLESTONE:0,30,COBBLESTONE:0,20,SMOOTH_BRICK:0,100)
Block(-3,9,-7,quark:limestone:1)
Block(-3,9,-6,quark:world_stone_pavement:5)
Block(-3,9,-5,quark:world_stone_pavement:5)
Block(-3,9,-4,quark:limestone:1)
Block(-3,9,-3,quark:world_stone_pavement:5)
Block(-3,9,-2,quark:world_stone_pavement:5)
Block(-3,9,-1,quark:world_stone_pavement:2)
Block(-3,9,0,quark:world_stone_pavement:5)
Block(-3,9,1,quark:world_stone_pavement:2)
Block(-3,9,2,quark:limestone:1)
Block(-3,9,3,quark:limestone:1)
Block(-3,9,4,quark:world_stone_pavement:5)
Block(-3,9,5,quark:world_stone_pavement:2)
RandomBlock(-3,9,6,SMOOTH_BRICK:0,40,SMOOTH_BRICK:1,30,SMOOTH_BRICK:2,30,MOSSY_COBBLESTONE:0,30,COBBLESTONE:0,20,SMOOTH_BRICK:0,100)
Block(-3,10,-7,quark:world_stone_pavement:2)
Block(-3,10,-6,quark:world_stone_pavement:5)
Block(-3,10,-5,quark:limestone:1)
Block(-3,10,-4,quark:world_stone_pavement:2)
Block(-3,10,-3,quark:world_stone_pavement:2)
Block(-3,10,-2,quark:world_stone_pavement:2)
Block(-3,10,-1,quark:limestone:1)
Block(-3,10,0,quark:world_stone_pavement:5)
Block(-3,10,1,quark:limestone:1)
Block(-3,10,2,quark:world_stone_pavement:5)
Block(-3,10,3,quark:limestone:1)
Block(-3,10,4,quark:world_stone_pavement:5)
Block(-3,10,5,quark:world_stone_pavement:2)
RandomBlock(-3,10,6,SMOOTH_BRICK:0,40,SMOOTH_BRICK:1,30,SMOOTH_BRICK:2,30,MOSSY_COBBLESTONE:0,30,COBBLESTONE:0,20,SMOOTH_BRICK:0,100)
Block(-3,11,1,IRON_TRAPDOOR:3)
RandomBlock(-3,11,4,variedcommodities:crate,5,charm:crate_sealed,../../../../Chests/RLCraft/Containers/charm_crate.nbt,100)
Block(-3,11,5,quark:world_stone_pavement:2)
Block(-3,11,6,SMOOTH_STAIRS:3)
Block(-3,12,5,quark:iron_plate:1)
Block(-3,13,5,quark:iron_plate:1)
RandomBlock(-3,14,5,SMOOTH_BRICK:0,40,SMOOTH_BRICK:1,30,SMOOTH_BRICK:2,30,MOSSY_COBBLESTONE:0,30,COBBLESTONE:0,20,SMOOTH_BRICK:0,100)
Block(-3,15,-7,DOUBLE_STEP:0)
RandomBlock(-3,15,-6,SMOOTH_BRICK:0,40,SMOOTH_BRICK:1,30,SMOOTH_BRICK:2,30,MOSSY_COBBLESTONE:0,30,COBBLESTONE:0,20,SMOOTH_BRICK:0,100)
Block(-3,15,-5,DOUBLE_STEP:0)
RandomBlock(-3,15,-4,SMOOTH_BRICK:0,40,SMOOTH_BRICK:1,30,SMOOTH_BRICK:2,30,MOSSY_COBBLESTONE:0,30,COBBLESTONE:0,20,SMOOTH_BRICK:0,100)
Block(-3,15,-3,DOUBLE_STEP:0)
RandomBlock(-3,15,-2,SMOOTH_BRICK:0,40,SMOOTH_BRICK:1,30,SMOOTH_BRICK:2,30,MOSSY_COBBLESTONE:0,30,COBBLESTONE:0,20,SMOOTH_BRICK:0,100)
Block(-3,15,-1,DOUBLE_STEP:0)
RandomBlock(-3,15,0,SMOOTH_BRICK:0,40,SMOOTH_BRICK:1,30,SMOOTH_BRICK:2,30,MOSSY_COBBLESTONE:0,30,COBBLESTONE:0,20,SMOOTH_BRICK:0,100)
Block(-3,15,1,DOUBLE_STEP:0)
RandomBlock(-3,15,2,SMOOTH_BRICK:0,40,SMOOTH_BRICK:1,30,SMOOTH_BRICK:2,30,MOSSY_COBBLESTONE:0,30,COBBLESTONE:0,20,SMOOTH_BRICK:0,100)
Block(-3,15,3,DOUBLE_STEP:0)
RandomBlock(-3,15,4,SMOOTH_BRICK:0,40,SMOOTH_BRICK:1,30,SMOOTH_BRICK:2,30,MOSSY_COBBLESTONE:0,30,COBBLESTONE:0,20,SMOOTH_BRICK:0,100)
Block(-3,15,5,DOUBLE_STEP:0)
Block(-3,16,-7,quark:basalt_wall)
Block(-3,16,-1,quark:basalt_wall)
Block(-3,16,1,DOUBLE_STEP:0)
Block(-3,16,4,DOUBLE_STEP:0)
Block(-3,16,5,DOUBLE_STEP:0)
Block(-3,17,-7,quark:basalt_wall)
Block(-3,17,-4,quark:basalt_wall)
Block(-3,17,-3,quark:basalt_wall)
Block(-3,17,-2,quark:basalt_wall)
Block(-3,17,-1,quark:basalt_wall)
Block(-3,17,1,DOUBLE_STEP:0)
Block(-3,17,4,DOUBLE_STEP:0)
Block(-3,17,5,DOUBLE_STEP:0)
Block(-3,18,-7,quark:iron_plate:1)
Block(-3,18,-6,quark:iron_plate:1)
Block(-3,18,-5,quark:iron_plate:1)
Block(-3,18,-4,quark:iron_plate:1)
Block(-3,18,-3,quark:iron_plate:1)
Block(-3,18,-2,quark:iron_plate:1)
Block(-3,18,-1,quark:iron_plate:1)
Block(-3,18,0,quark:iron_plate:1)
Block(-3,18,1,quark:iron_plate:1)
Block(-3,18,2,quark:iron_plate:1)
Block(-3,18,3,quark:iron_plate:1)
Block(-3,18,4,DOUBLE_STEP:0)
RandomBlock(-3,18,5,SMOOTH_BRICK:0,40,SMOOTH_BRICK:1,30,SMOOTH_BRICK:2,30,MOSSY_COBBLESTONE:0,30,COBBLESTONE:0,20,SMOOTH_BRICK:0,100)
RandomBlock(-3,19,3,variedcommodities:crate:5,5,charm:crate_sealed:5,../../../../Chests/RLCraft/Containers/charm_crate.nbt,10,charm:crate_sealed:5,../../../../Chests/RLCraft/Containers/charm_crate.nbt,100)
Block(-3,19,4,DOUBLE_STEP:0)
Block(-3,19,5,DOUBLE_STEP:0)
Block(-3,20,4,DOUBLE_STEP:0)
Block(-3,20,5,DOUBLE_STEP:0)
RandomBlock(-3,21,3,SMOOTH_BRICK:0,40,SMOOTH_BRICK:1,30,SMOOTH_BRICK:2,30,MOSSY_COBBLESTONE:0,30,COBBLESTONE:0,20,SMOOTH_BRICK:0,100)
RandomBlock(-3,21,4,SMOOTH_BRICK:0,40,SMOOTH_BRICK:1,30,SMOOTH_BRICK:2,30,MOSSY_COBBLESTONE:0,30,COBBLESTONE:0,20,SMOOTH_BRICK:0,100)
RandomBlock(-3,21,5,SMOOTH_BRICK:0,40,SMOOTH_BRICK:1,30,SMOOTH_BRICK:2,30,MOSSY_COBBLESTONE:0,30,COBBLESTONE:0,20,SMOOTH_BRICK:0,100)
Block(-3,22,3,DOUBLE_STEP:0)
Block(-3,22,4,DOUBLE_STEP:0)
RandomBlock(-3,23,2,SMOOTH_BRICK:0,40,SMOOTH_BRICK:1,30,SMOOTH_BRICK:2,30,MOSSY_COBBLESTONE:0,30,COBBLESTONE:0,20,SMOOTH_BRICK:0,100)
Block(-3,23,3,DOUBLE_STEP:0)
Block(-3,24,2,DOUBLE_STEP:0)
Block(-3,25,2,DOUBLE_STEP:0)
RandomBlock(-3,26,-7,SMOOTH_BRICK:0,40,SMOOTH_BRICK:1,30,SMOOTH_BRICK:2,30,MOSSY_COBBLESTONE:0,30,COBBLESTONE:0,20,SMOOTH_BRICK:0,100)
RandomBlock(-3,26,-6,SMOOTH_BRICK:0,40,SMOOTH_BRICK:1,30,SMOOTH_BRICK:2,30,MOSSY_COBBLESTONE:0,30,COBBLESTONE:0,20,SMOOTH_BRICK:0,100)
RandomBlock(-3,26,-5,SMOOTH_BRICK:0,40,SMOOTH_BRICK:1,30,SMOOTH_BRICK:2,30,MOSSY_COBBLESTONE:0,30,COBBLESTONE:0,20,SMOOTH_BRICK:0,100)
RandomBlock(-3,26,-4,SMOOTH_BRICK:0,40,SMOOTH_BRICK:1,30,SMOOTH_BRICK:2,30,MOSSY_COBBLESTONE:0,30,COBBLESTONE:0,20,SMOOTH_BRICK:0,100)
RandomBlock(-3,26,-3,SMOOTH_BRICK:0,40,SMOOTH_BRICK:1,30,SMOOTH_BRICK:2,30,MOSSY_COBBLESTONE:0,30,COBBLESTONE:0,20,SMOOTH_BRICK:0,100)
RandomBlock(-3,26,-2,SMOOTH_BRICK:0,40,SMOOTH_BRICK:1,30,SMOOTH_BRICK:2,30,MOSSY_COBBLESTONE:0,30,COBBLESTONE:0,20,SMOOTH_BRICK:0,100)
RandomBlock(-3,26,-1,SMOOTH_BRICK:0,40,SMOOTH_BRICK:1,30,SMOOTH_BRICK:2,30,MOSSY_COBBLESTONE:0,30,COBBLESTONE:0,20,SMOOTH_BRICK:0,100)
RandomBlock(-3,26,0,SMOOTH_BRICK:0,40,SMOOTH_BRICK:1,30,SMOOTH_BRICK:2,30,MOSSY_COBBLESTONE:0,30,COBBLESTONE:0,20,SMOOTH_BRICK:0,100)
RandomBlock(-3,26,1,SMOOTH_BRICK:0,40,SMOOTH_BRICK:1,30,SMOOTH_BRICK:2,30,MOSSY_COBBLESTONE:0,30,COBBLESTONE:0,20,SMOOTH_BRICK:0,100)
Block(-3,26,2,DOUBLE_STEP:0)
Block(-3,27,-5,quark:iron_plate:1)
Block(-3,27,-3,quark:iron_plate:1)
Block(-3,27,-1,quark:iron_plate:1)
Block(-3,27,1,quark:iron_plate:1)
Block(-3,28,-5,quark:iron_plate:1)
Block(-3,28,-3,quark:iron_plate:1)
Block(-3,28,-1,quark:iron_plate:1)
Block(-3,28,1,quark:iron_plate:1)
Block(-3,29,-5,quark:iron_plate:1)
Block(-3,29,-3,quark:iron_plate:1)
Block(-3,29,-1,quark:iron_plate:1)
Block(-3,29,1,quark:iron_plate:1)
Block(-3,30,-5,SMOOTH_STAIRS:0)
Block(-3,30,-3,SMOOTH_STAIRS:0)
Block(-3,30,-1,SMOOTH_STAIRS:0)
Block(-3,30,1,SMOOTH_STAIRS:0)
Block(-2,0,-7,quark:world_stone_pavement:2)
Block(-2,0,-6,quark:world_stone_pavement:5)
Block(-2,0,-5,quark:world_stone_pavement:2)
Block(-2,0,-4,quark:world_stone_pavement:2)
Block(-2,0,-3,quark:world_stone_pavement:2)
Block(-2,0,-2,quark:world_stone_pavement:2)
Block(-2,0,-1,quark:world_stone_pavement:2)
Block(-2,0,0,quark:world_stone_pavement:2)
Block(-2,0,1,quark:world_stone_pavement:5)
Block(-2,0,2,quark:limestone:1)
Block(-2,0,3,quark:limestone:1)
Block(-2,0,4,quark:limestone:1)
Block(-2,0,5,quark:world_stone_pavement:2)
Block(-2,0,6,quark:limestone:1)
Block(-2,0,7,quark:iron_plate:1)
Block(-2,1,-7,quark:world_stone_pavement:2)
Block(-2,1,-6,quark:limestone:1)
Block(-2,1,-5,quark:world_stone_pavement:2)
Block(-2,1,-4,quark:world_stone_pavement:2)
Block(-2,1,-3,quark:world_stone_pavement:2)
Block(-2,1,-2,quark:world_stone_pavement:2)
Block(-2,1,-1,quark:world_stone_pavement:2)
Block(-2,1,0,quark:world_stone_pavement:2)
Block(-2,1,1,quark:world_stone_pavement:2)
Block(-2,1,2,quark:limestone:1)
Block(-2,1,3,quark:world_stone_pavement:5)
Block(-2,1,4,quark:world_stone_pavement:5)
Block(-2,1,5,quark:world_stone_pavement:2)
Block(-2,1,6,quark:limestone:1)
Block(-2,1,7,quark:iron_plate:1)
Block(-2,2,-7,quark:world_stone_pavement:2)
Block(-2,2,-6,quark:world_stone_pavement:2)
Block(-2,2,-5,quark:world_stone_pavement:2)
Block(-2,2,-4,quark:world_stone_pavement:2)
Block(-2,2,-3,quark:world_stone_pavement:2)
Block(-2,2,-2,quark:world_stone_pavement:2)
Block(-2,2,-1,quark:world_stone_pavement:2)
Block(-2,2,0,quark:world_stone_pavement:2)
Block(-2,2,1,quark:world_stone_pavement:5)
Block(-2,2,2,quark:world_stone_pavement:2)
Block(-2,2,3,quark:world_stone_pavement:2)
Block(-2,2,4,quark:world_stone_pavement:5)
Block(-2,2,5,quark:world_stone_pavement:2)
Block(-2,2,6,quark:world_stone_pavement:2)
Block(-2,2,7,quark:iron_plate:1)
Block(-2,3,-7,quark:world_stone_pavement:2)
Block(-2,3,-6,quark:limestone:1)
Block(-2,3,-5,quark:world_stone_pavement:2)
Block(-2,3,-4,quark:world_stone_pavement:2)
Block(-2,3,-3,quark:world_stone_pavement:2)
Block(-2,3,-2,quark:world_stone_pavement:2)
Block(-2,3,-1,quark:world_stone_pavement:2)
Block(-2,3,0,quark:world_stone_pavement:2)
Block(-2,3,1,quark:world_stone_pavement:5)
Block(-2,3,2,quark:world_stone_pavement:5)
Block(-2,3,3,quark:limestone:1)
Block(-2,3,4,quark:limestone:1)
Block(-2,3,5,quark:world_stone_pavement:2)
Block(-2,3,6,quark:limestone:1)
Block(-2,3,7,quark:iron_plate:1)
Block(-2,4,-7,quark:world_stone_pavement:2)
Block(-2,4,-6,quark:limestone:1)
Block(-2,4,-5,quark:world_stone_pavement:2)
Block(-2,4,-4,quark:world_stone_pavement:2)
Block(-2,4,-3,quark:world_stone_pavement:2)
Block(-2,4,-2,quark:world_stone_pavement:2)
Block(-2,4,-1,quark:world_stone_pavement:2)
Block(-2,4,0,quark:world_stone_pavement:5)
Block(-2,4,1,quark:world_stone_pavement:2)
Block(-2,4,2,quark:world_stone_pavement:2)
Block(-2,4,3,quark:world_stone_pavement:2)
Block(-2,4,4,quark:world_stone_pavement:5)
Block(-2,4,5,quark:world_stone_pavement:2)
Block(-2,4,6,quark:world_stone_pavement:5)
Block(-2,4,7,quark:iron_plate:1)
Block(-2,5,-7,quark:world_stone_pavement:2)
Block(-2,5,-6,quark:world_stone_pavement:5)
Block(-2,5,-5,quark:world_stone_pavement:2)
Block(-2,5,-4,quark:world_stone_pavement:2)
Block(-2,5,-3,quark:world_stone_pavement:2)
Block(-2,5,-2,quark:world_stone_pavement:2)
Block(-2,5,-1,quark:world_stone_pavement:2)
Block(-2,5,0,quark:world_stone_pavement:5)
Block(-2,5,1,quark:limestone:1)
Block(-2,5,2,quark:limestone:1)
Block(-2,5,3,quark:limestone:1)
Block(-2,5,4,quark:world_stone_pavement:2)
Block(-2,5,5,quark:world_stone_pavement:2)
Block(-2,5,6,quark:world_stone_pavement:2)
Block(-2,5,7,quark:iron_plate:1)
Block(-2,6,-7,quark:world_stone_pavement:2)
Block(-2,6,-6,quark:world_stone_pavement:5)
Block(-2,6,-5,quark:world_stone_pavement:2)
Block(-2,6,-4,quark:world_stone_pavement:2)
Block(-2,6,-3,quark:world_stone_pavement:2)
Block(-2,6,-2,quark:world_stone_pavement:2)
Block(-2,6,-1,quark:world_stone_pavement:2)
Block(-2,6,0,quark:world_stone_pavement:2)
Block(-2,6,1,quark:world_stone_pavement:2)
Block(-2,6,2,quark:world_stone_pavement:5)
Block(-2,6,3,quark:limestone:1)
Block(-2,6,4,quark:limestone:1)
Block(-2,6,5,quark:world_stone_pavement:2)
Block(-2,6,6,quark:limestone:1)
Block(-2,6,7,quark:iron_plate:1)
Block(-2,7,-7,quark:limestone:1)
Block(-2,7,-6,quark:limestone:1)
Block(-2,7,-5,quark:limestone:1)
Block(-2,7,-4,quark:world_stone_pavement:2)
Block(-2,7,-3,quark:world_stone_pavement:2)
Block(-2,7,-2,quark:world_stone_pavement:5)
Block(-2,7,-1,quark:limestone:1)
Block(-2,7,0,quark:limestone:1)
Block(-2,7,1,quark:world_stone_pavement:2)
Block(-2,7,2,quark:world_stone_pavement:2)
Block(-2,7,3,quark:world_stone_pavement:5)
Block(-2,7,4,quark:limestone:1)
Block(-2,7,5,quark:limestone:1)
Block(-2,7,6,quark:world_stone_pavement:5)
Block(-2,7,7,quark:iron_plate:1)
Block(-2,8,-7,quark:world_stone_pavement:5)
Block(-2,8,-6,quark:limestone:1)
Block(-2,8,-5,quark:world_stone_pavement:2)
Block(-2,8,-4,quark:world_stone_pavement:2)
Block(-2,8,-3,quark:limestone:1)
Block(-2,8,-2,quark:world_stone_pavement:5)
Block(-2,8,-1,quark:world_stone_pavement:2)
Block(-2,8,0,quark:world_stone_pavement:5)
Block(-2,8,1,quark:limestone:1)
Block(-2,8,2,quark:limestone:1)
Block(-2,8,3,quark:world_stone_pavement:2)
Block(-2,8,4,quark:world_stone_pavement:5)
Block(-2,8,5,quark:limestone:1)
Block(-2,8,6,quark:world_stone_pavement:5)
Block(-2,8,7,quark:iron_plate:1)
Block(-2,9,-7,quark:world_stone_pavement:2)
Block(-2,9,-6,quark:world_stone_pavement:2)
Block(-2,9,-5,quark:world_stone_pavement:5)
Block(-2,9,-4,quark:limestone:1)
Block(-2,9,-3,quark:limestone:1)
Block(-2,9,-2,quark:world_stone_pavement:2)
Block(-2,9,-1,quark:world_stone_pavement:2)
Block(-2,9,0,quark:world_stone_pavement:5)
Block(-2,9,1,quark:limestone:1)
Block(-2,9,2,quark:world_stone_pavement:2)
Block(-2,9,3,quark:world_stone_pavement:5)
Block(-2,9,4,quark:world_stone_pavement:2)
Block(-2,9,5,quark:polished_stone)
Block(-2,9,6,quark:world_stone_pavement:5)
Block(-2,9,7,quark:iron_plate:1)
Block(-2,10,-7,quark:world_stone_pavement:2)
Block(-2,10,-6,quark:world_stone_pavement:5)
Block(-2,10,-5,quark:world_stone_pavement:5)
Block(-2,10,-4,quark:world_stone_pavement:2)
Block(-2,10,-3,quark:world_stone_pavement:2)
Block(-2,10,-2,quark:limestone:1)
Block(-2,10,-1,quark:world_stone_pavement:2)
Block(-2,10,0,quark:world_stone_pavement:2)
Block(-2,10,1,quark:world_stone_pavement:2)
Block(-2,10,2,quark:world_stone_pavement:2)
Block(-2,10,3,quark:polished_stone)
Block(-2,10,4,quark:world_stone_pavement:2)
Block(-2,10,5,quark:polished_stone)
Block(-2,10,6,quark:polished_stone)
Block(-2,10,7,quark:iron_plate:1)
Block(-2,11,4,CAULDRON:3)
Block(-2,11,5,quark:iron_plate:1)
Block(-2,11,6,quark:world_stone_pavement:2)
Block(-2,11,7,quark:basalt_wall)
Block(-2,12,4,IRON_TRAPDOOR:0)
Block(-2,12,5,quark:iron_plate:1)
Block(-2,12,6,DOUBLE_STEP:0)
Block(-2,12,7,quark:iron_plate:1)
Block(-2,13,5,quark:iron_plate:1)
Block(-2,13,6,DOUBLE_STEP:0)
Block(-2,13,7,quark:basalt_wall)
Block(-2,14,5,quark:iron_plate:1)
Block(-2,14,6,DOUBLE_STEP:0)
RandomBlock(-2,15,-7,SMOOTH_BRICK:0,40,SMOOTH_BRICK:1,30,SMOOTH_BRICK:2,30,MOSSY_COBBLESTONE:0,30,COBBLESTONE:0,20,SMOOTH_BRICK:0,100)
RandomBlock(-2,15,-6,SMOOTH_BRICK:0,40,SMOOTH_BRICK:1,30,SMOOTH_BRICK:2,30,MOSSY_COBBLESTONE:0,30,COBBLESTONE:0,20,SMOOTH_BRICK:0,100)
RandomBlock(-2,15,-5,SMOOTH_BRICK:0,40,SMOOTH_BRICK:1,30,SMOOTH_BRICK:2,30,MOSSY_COBBLESTONE:0,30,COBBLESTONE:0,20,SMOOTH_BRICK:0,100)
RandomBlock(-2,15,-4,SMOOTH_BRICK:0,40,SMOOTH_BRICK:1,30,SMOOTH_BRICK:2,30,MOSSY_COBBLESTONE:0,30,COBBLESTONE:0,20,SMOOTH_BRICK:0,100)
RandomBlock(-2,15,-3,SMOOTH_BRICK:0,40,SMOOTH_BRICK:1,30,SMOOTH_BRICK:2,30,MOSSY_COBBLESTONE:0,30,COBBLESTONE:0,20,SMOOTH_BRICK:0,100)
RandomBlock(-2,15,-2,SMOOTH_BRICK:0,40,SMOOTH_BRICK:1,30,SMOOTH_BRICK:2,30,MOSSY_COBBLESTONE:0,30,COBBLESTONE:0,20,SMOOTH_BRICK:0,100)
RandomBlock(-2,15,-1,SMOOTH_BRICK:0,40,SMOOTH_BRICK:1,30,SMOOTH_BRICK:2,30,MOSSY_COBBLESTONE:0,30,COBBLESTONE:0,20,SMOOTH_BRICK:0,100)
RandomBlock(-2,15,0,SMOOTH_BRICK:0,40,SMOOTH_BRICK:1,30,SMOOTH_BRICK:2,30,MOSSY_COBBLESTONE:0,30,COBBLESTONE:0,20,SMOOTH_BRICK:0,100)
RandomBlock(-2,15,1,SMOOTH_BRICK:0,40,SMOOTH_BRICK:1,30,SMOOTH_BRICK:2,30,MOSSY_COBBLESTONE:0,30,COBBLESTONE:0,20,SMOOTH_BRICK:0,100)
RandomBlock(-2,15,2,SMOOTH_BRICK:0,40,SMOOTH_BRICK:1,30,SMOOTH_BRICK:2,30,MOSSY_COBBLESTONE:0,30,COBBLESTONE:0,20,SMOOTH_BRICK:0,100)
RandomBlock(-2,15,3,SMOOTH_BRICK:0,40,SMOOTH_BRICK:1,30,SMOOTH_BRICK:2,30,MOSSY_COBBLESTONE:0,30,COBBLESTONE:0,20,SMOOTH_BRICK:0,100)
RandomBlock(-2,15,4,SMOOTH_BRICK:0,40,SMOOTH_BRICK:1,30,SMOOTH_BRICK:2,30,MOSSY_COBBLESTONE:0,30,COBBLESTONE:0,20,SMOOTH_BRICK:0,100)
RandomBlock(-2,15,5,SMOOTH_BRICK:0,40,SMOOTH_BRICK:1,30,SMOOTH_BRICK:2,30,MOSSY_COBBLESTONE:0,30,COBBLESTONE:0,20,SMOOTH_BRICK:0,100)
Block(-2,15,6,DOUBLE_STEP:0)
Block(-2,16,1,DOUBLE_STEP:0)
Block(-2,16,4,DOUBLE_STEP:0)
Block(-2,16,5,DOUBLE_STEP:0)
Block(-2,16,6,DOUBLE_STEP:0)
Block(-2,17,-4,quark:basalt_wall)
Block(-2,17,1,DOUBLE_STEP:0)
Block(-2,17,4,DOUBLE_STEP:0)
Block(-2,17,5,DOUBLE_STEP:0)
Block(-2,17,6,DOUBLE_STEP:0)
Block(-2,18,-7,quark:iron_plate:1)
Block(-2,18,-6,quark:iron_plate:1)
Block(-2,18,-5,quark:iron_plate:1)
Block(-2,18,-4,quark:iron_plate:1)
Block(-2,18,-3,quark:iron_plate:1)
Block(-2,18,-2,quark:iron_plate:1)
Block(-2,18,-1,quark:iron_plate:1)
Block(-2,18,0,quark:iron_plate:1)
Block(-2,18,1,quark:iron_plate:1)
Block(-2,18,2,quark:iron_plate:1)
Block(-2,18,3,quark:iron_plate:1)
Block(-2,18,4,DOUBLE_STEP:0)
Block(-2,18,6,DOUBLE_STEP:0)
Block(-2,19,4,DOUBLE_STEP:0)
Block(-2,19,6,quark:iron_plate:1)
Block(-2,20,4,DOUBLE_STEP:0)
RandomBlock(-2,20,5,SMOOTH_BRICK:0,40,SMOOTH_BRICK:1,30,SMOOTH_BRICK:2,30,MOSSY_COBBLESTONE:0,30,COBBLESTONE:0,20,SMOOTH_BRICK:0,100)
Block(-2,20,6,STEP:0)
RandomBlock(-2,21,3,SMOOTH_BRICK:0,40,SMOOTH_BRICK:1,30,SMOOTH_BRICK:2,30,MOSSY_COBBLESTONE:0,30,COBBLESTONE:0,20,SMOOTH_BRICK:0,100)
Block(-2,21,4,quark:iron_plate:1)
Block(-2,21,5,STEP:0)
RandomBlock(-2,22,3,SMOOTH_BRICK:0,40,SMOOTH_BRICK:1,30,SMOOTH_BRICK:2,30,MOSSY_COBBLESTONE:0,30,COBBLESTONE:0,20,SMOOTH_BRICK:0,100)
RandomBlock(-2,23,3,SMOOTH_BRICK:0,40,SMOOTH_BRICK:1,30,SMOOTH_BRICK:2,30,MOSSY_COBBLESTONE:0,30,COBBLESTONE:0,20,SMOOTH_BRICK:0,100)
RandomBlock(-2,24,3,SMOOTH_BRICK:0,40,SMOOTH_BRICK:1,30,SMOOTH_BRICK:2,30,MOSSY_COBBLESTONE:0,30,COBBLESTONE:0,20,SMOOTH_BRICK:0,100)
RandomBlock(-2,25,3,SMOOTH_BRICK:0,40,SMOOTH_BRICK:1,30,SMOOTH_BRICK:2,30,MOSSY_COBBLESTONE:0,30,COBBLESTONE:0,20,SMOOTH_BRICK:0,100)
Block(-2,26,-5,quark:iron_plate:1)
Block(-2,26,-3,quark:iron_plate:1)
RandomBlock(-2,26,3,SMOOTH_BRICK:0,40,SMOOTH_BRICK:1,30,SMOOTH_BRICK:2,30,MOSSY_COBBLESTONE:0,30,COBBLESTONE:0,20,SMOOTH_BRICK:0,100)
Block(-2,27,-7,quark:limestone:1)
Block(-2,27,-6,quark:world_stone_pavement:2)
Block(-2,27,-5,quark:world_stone_pavement:2)
Block(-2,27,-4,quark:limestone:1)
Block(-2,27,-3,quark:world_stone_pavement:2)
Block(-2,27,-2,quark:world_stone_pavement:5)
Block(-2,27,-1,quark:world_stone_pavement:2)
Block(-2,27,0,quark:world_stone_pavement:5)
Block(-2,27,1,quark:world_stone_pavement:2)
Block(-2,27,2,quark:world_stone_pavement:2)
RandomBlock(-2,27,3,SMOOTH_BRICK:0,40,SMOOTH_BRICK:1,30,SMOOTH_BRICK:2,30,MOSSY_COBBLESTONE:0,30,COBBLESTONE:0,20,SMOOTH_BRICK:0,100)
Block(-2,28,-7,quark:world_stone_pavement:5)
Block(-2,28,-6,quark:world_stone_pavement:2)
Block(-2,28,-5,quark:world_stone_pavement:2)
Block(-2,28,-4,quark:world_stone_pavement:2)
Block(-2,28,-3,quark:world_stone_pavement:5)
Block(-2,28,-2,quark:limestone:1)
Block(-2,28,-1,quark:world_stone_pavement:2)
Block(-2,28,0,quark:world_stone_pavement:5)
Block(-2,28,1,quark:world_stone_pavement:5)
Block(-2,28,2,quark:world_stone_pavement:2)
Block(-2,28,3,SMOOTH_STAIRS:3)
RandomBlock(-2,29,-7,SMOOTH_BRICK:0,40,SMOOTH_BRICK:1,30,SMOOTH_BRICK:2,30,MOSSY_COBBLESTONE:0,30,COBBLESTONE:0,20,SMOOTH_BRICK:0,100)
RandomBlock(-2,29,-6,SMOOTH_BRICK:0,40,SMOOTH_BRICK:1,30,SMOOTH_BRICK:2,30,MOSSY_COBBLESTONE:0,30,COBBLESTONE:0,20,SMOOTH_BRICK:0,100)
RandomBlock(-2,29,-5,SMOOTH_BRICK:0,40,SMOOTH_BRICK:1,30,SMOOTH_BRICK:2,30,MOSSY_COBBLESTONE:0,30,COBBLESTONE:0,20,SMOOTH_BRICK:0,100)
RandomBlock(-2,29,-4,SMOOTH_BRICK:0,40,SMOOTH_BRICK:1,30,SMOOTH_BRICK:2,30,MOSSY_COBBLESTONE:0,30,COBBLESTONE:0,20,SMOOTH_BRICK:0,100)
RandomBlock(-2,29,-3,SMOOTH_BRICK:0,40,SMOOTH_BRICK:1,30,SMOOTH_BRICK:2,30,MOSSY_COBBLESTONE:0,30,COBBLESTONE:0,20,SMOOTH_BRICK:0,100)
RandomBlock(-2,29,-2,SMOOTH_BRICK:0,40,SMOOTH_BRICK:1,30,SMOOTH_BRICK:2,30,MOSSY_COBBLESTONE:0,30,COBBLESTONE:0,20,SMOOTH_BRICK:0,100)
RandomBlock(-2,29,-1,SMOOTH_BRICK:0,40,SMOOTH_BRICK:1,30,SMOOTH_BRICK:2,30,MOSSY_COBBLESTONE:0,30,COBBLESTONE:0,20,SMOOTH_BRICK:0,100)
RandomBlock(-2,29,0,SMOOTH_BRICK:0,40,SMOOTH_BRICK:1,30,SMOOTH_BRICK:2,30,MOSSY_COBBLESTONE:0,30,COBBLESTONE:0,20,SMOOTH_BRICK:0,100)
RandomBlock(-2,29,1,SMOOTH_BRICK:0,40,SMOOTH_BRICK:1,30,SMOOTH_BRICK:2,30,MOSSY_COBBLESTONE:0,30,COBBLESTONE:0,20,SMOOTH_BRICK:0,100)
Block(-2,29,2,SMOOTH_STAIRS:3)
Block(-2,30,-5,quark:iron_plate:1)
Block(-2,30,-3,quark:iron_plate:1)
Block(-2,30,-1,quark:iron_plate:1)
Block(-2,30,1,quark:iron_plate:1)
Block(-1,0,-7,quark:world_stone_pavement:2)
Block(-1,0,-6,quark:world_stone_pavement:2)
Block(-1,0,-5,quark:world_stone_pavement:2)
Block(-1,0,-4,quark:world_stone_pavement:2)
Block(-1,0,-3,quark:world_stone_pavement:2)
Block(-1,0,-2,quark:world_stone_pavement:2)
Block(-1,0,-1,quark:limestone:1)
Block(-1,0,0,quark:limestone:1)
Block(-1,0,1,quark:world_stone_pavement:2)
Block(-1,0,2,quark:world_stone_pavement:5)
Block(-1,0,3,quark:limestone:1)
Block(-1,0,4,quark:world_stone_pavement:5)
Block(-1,0,5,quark:world_stone_pavement:2)
Block(-1,0,6,quark:world_stone_pavement:2)
Block(-1,1,-7,quark:world_stone_pavement:2)
Block(-1,1,-6,quark:limestone:1)
Block(-1,1,-5,quark:world_stone_pavement:2)
Block(-1,1,-4,quark:world_stone_pavement:5)
Block(-1,1,-3,quark:world_stone_pavement:2)
Block(-1,1,-2,quark:world_stone_pavement:2)
Block(-1,1,-1,quark:world_stone_pavement:5)
Block(-1,1,0,quark:limestone:1)
Block(-1,1,1,quark:world_stone_pavement:2)
Block(-1,1,2,quark:world_stone_pavement:2)
Block(-1,1,3,quark:limestone:1)
Block(-1,1,4,quark:world_stone_pavement:2)
Block(-1,1,5,quark:world_stone_pavement:5)
Block(-1,1,6,quark:world_stone_pavement:2)
Block(-1,2,-7,quark:world_stone_pavement:2)
Block(-1,2,-6,quark:world_stone_pavement:2)
Block(-1,2,-5,quark:world_stone_pavement:2)
Block(-1,2,-4,quark:world_stone_pavement:5)
Block(-1,2,-3,quark:world_stone_pavement:2)
Block(-1,2,-2,quark:world_stone_pavement:2)
Block(-1,2,-1,quark:world_stone_pavement:5)
Block(-1,2,0,quark:limestone:1)
Block(-1,2,1,quark:world_stone_pavement:2)
Block(-1,2,2,quark:limestone:1)
Block(-1,2,3,quark:limestone:1)
Block(-1,2,4,quark:limestone:1)
Block(-1,2,5,quark:world_stone_pavement:2)
Block(-1,2,6,quark:world_stone_pavement:2)
Block(-1,3,-7,quark:world_stone_pavement:2)
Block(-1,3,-6,quark:world_stone_pavement:2)
Block(-1,3,-5,quark:world_stone_pavement:2)
Block(-1,3,-4,quark:world_stone_pavement:5)
Block(-1,3,-3,quark:world_stone_pavement:2)
Block(-1,3,-2,quark:world_stone_pavement:2)
Block(-1,3,-1,quark:world_stone_pavement:5)
Block(-1,3,0,quark:world_stone_pavement:2)
Block(-1,3,1,quark:world_stone_pavement:2)
Block(-1,3,2,quark:limestone:1)
Block(-1,3,3,quark:world_stone_pavement:5)
Block(-1,3,4,quark:limestone:1)
Block(-1,3,5,quark:limestone:1)
Block(-1,3,6,quark:world_stone_pavement:2)
Block(-1,4,-7,quark:world_stone_pavement:2)
Block(-1,4,-6,quark:world_stone_pavement:5)
Block(-1,4,-5,quark:world_stone_pavement:2)
Block(-1,4,-4,quark:limestone:1)
Block(-1,4,-3,quark:world_stone_pavement:2)
Block(-1,4,-2,quark:world_stone_pavement:2)
Block(-1,4,-1,quark:limestone:1)
Block(-1,4,0,quark:limestone:1)
Block(-1,4,1,quark:world_stone_pavement:2)
Block(-1,4,2,quark:world_stone_pavement:2)
Block(-1,4,3,quark:limestone:1)
Block(-1,4,4,quark:world_stone_pavement:2)
Block(-1,4,5,quark:limestone:1)
Block(-1,4,6,quark:world_stone_pavement:2)
Block(-1,5,-7,quark:world_stone_pavement:2)
Block(-1,5,-6,quark:limestone:1)
Block(-1,5,-5,quark:world_stone_pavement:2)
Block(-1,5,-4,quark:world_stone_pavement:2)
Block(-1,5,-3,quark:world_stone_pavement:2)
Block(-1,5,-2,quark:world_stone_pavement:2)
Block(-1,5,-1,quark:world_stone_pavement:5)
Block(-1,5,0,quark:world_stone_pavement:2)
Block(-1,5,1,quark:world_stone_pavement:2)
Block(-1,5,2,quark:world_stone_pavement:5)
Block(-1,5,3,quark:limestone:1)
Block(-1,5,4,quark:world_stone_pavement:5)
Block(-1,5,5,quark:world_stone_pavement:5)
Block(-1,5,6,quark:world_stone_pavement:2)
Block(-1,6,-7,quark:world_stone_pavement:2)
Block(-1,6,-6,quark:world_stone_pavement:5)
Block(-1,6,-5,quark:world_stone_pavement:2)
Block(-1,6,-4,quark:world_stone_pavement:2)
Block(-1,6,-3,quark:world_stone_pavement:2)
Block(-1,6,-2,quark:world_stone_pavement:2)
Block(-1,6,-1,quark:world_stone_pavement:5)
Block(-1,6,0,quark:limestone:1)
Block(-1,6,1,quark:world_stone_pavement:2)
Block(-1,6,2,quark:limestone:1)
Block(-1,6,3,quark:limestone:1)
Block(-1,6,4,quark:world_stone_pavement:5)
Block(-1,6,5,quark:world_stone_pavement:5)
Block(-1,6,6,quark:world_stone_pavement:2)
Block(-1,7,-7,quark:world_stone_pavement:2)
Block(-1,7,-6,quark:world_stone_pavement:5)
Block(-1,7,-5,quark:world_stone_pavement:2)
Block(-1,7,-4,quark:world_stone_pavement:2)
Block(-1,7,-3,quark:world_stone_pavement:2)
Block(-1,7,-2,quark:world_stone_pavement:5)
Block(-1,7,-1,quark:world_stone_pavement:2)
Block(-1,7,0,quark:world_stone_pavement:5)
Block(-1,7,1,quark:world_stone_pavement:2)
Block(-1,7,2,quark:world_stone_pavement:2)
Block(-1,7,3,quark:world_stone_pavement:2)
Block(-1,7,4,quark:world_stone_pavement:5)
Block(-1,7,5,quark:world_stone_pavement:2)
Block(-1,7,6,quark:world_stone_pavement:2)
Block(-1,8,-7,quark:world_stone_pavement:2)
Block(-1,8,-6,quark:limestone:1)
Block(-1,8,-5,quark:limestone:1)
Block(-1,8,-4,quark:limestone:1)
Block(-1,8,-3,quark:world_stone_pavement:2)
Block(-1,8,-2,quark:world_stone_pavement:5)
Block(-1,8,-1,quark:world_stone_pavement:5)
Block(-1,8,0,quark:limestone:1)
Block(-1,8,1,quark:world_stone_pavement:5)
Block(-1,8,2,quark:limestone:1)
Block(-1,8,3,quark:world_stone_pavement:5)
Block(-1,8,4,quark:world_stone_pavement:5)
Block(-1,8,5,quark:limestone:1)
Block(-1,8,6,quark:limestone:1)
Block(-1,9,-7,quark:world_stone_pavement:5)
Block(-1,9,-6,quark:world_stone_pavement:5)
Block(-1,9,-5,quark:world_stone_pavement:2)
Block(-1,9,-4,quark:world_stone_pavement:2)
Block(-1,9,-3,quark:polished_stone)
Block(-1,9,-2,quark:limestone:1)
Block(-1,9,-1,quark:world_stone_pavement:2)
Block(-1,9,0,quark:polished_stone)
Block(-1,9,1,quark:limestone:1)
Block(-1,9,2,quark:world_stone_pavement:5)
Block(-1,9,3,quark:polished_stone)
Block(-1,9,4,quark:world_stone_pavement:2)
Block(-1,9,5,quark:world_stone_pavement:2)
Block(-1,9,6,quark:polished_stone)
Block(-1,10,-7,quark:limestone:1)
Block(-1,10,-6,quark:world_stone_pavement:2)
Block(-1,10,-5,quark:world_stone_pavement:2)
Block(-1,10,-4,quark:polished_stone)
Block(-1,10,-3,quark:polished_stone)
Block(-1,10,-2,quark:polished_stone)
Block(-1,10,-1,quark:polished_stone)
Block(-1,10,0,quark:polished_stone)
Block(-1,10,1,quark:polished_stone)
Block(-1,10,2,quark:world_stone_pavement:5)
Block(-1,10,3,quark:polished_stone)
Block(-1,10,4,quark:world_stone_pavement:2)
Block(-1,10,5,quark:world_stone_pavement:2)
Block(-1,10,6,quark:polished_stone)
RandomBlock(-1,11,-7,variedcommodities:crate:5,5,charm:crate_sealed:5,../../../../Chests/RLCraft/Containers/charm_crate.nbt,10,charm:crate_sealed:5,../../../../Chests/RLCraft/Containers/charm_crate.nbt,100)
RandomBlock(-1,11,-6,variedcommodities:crate:5,5,charm:crate_sealed:5,../../../../Chests/RLCraft/Containers/charm_crate.nbt,10,charm:crate_sealed:5,../../../../Chests/RLCraft/Containers/charm_crate.nbt,100)
RandomBlock(-1,11,-5,variedcommodities:crate:5,5,charm:crate_sealed:5,../../../../Chests/RLCraft/Containers/charm_crate.nbt,10,charm:crate_sealed:5,../../../../Chests/RLCraft/Containers/charm_crate.nbt,100)
RandomBlock(-1,11,3,variedcommodities:crate,5,charm:crate_sealed,../../../../Chests/RLCraft/Containers/charm_crate.nbt,100)
RandomBlock(-1,11,4,variedcommodities:crate:5,5,charm:crate_sealed:5,../../../../Chests/RLCraft/Containers/charm_crate.nbt,10,charm:crate_sealed:5,../../../../Chests/RLCraft/Containers/charm_crate.nbt,100)
Block(-1,11,5,quark:iron_plate:1)
Block(-1,11,6,quark:polished_stone)
RandomBlock(-1,12,-7,variedcommodities:crate:5,5,charm:crate_sealed:5,../../../../Chests/RLCraft/Containers/charm_crate.nbt,10,charm:crate_sealed:5,../../../../Chests/RLCraft/Containers/charm_crate.nbt,100)
RandomBlock(-1,12,-6,variedcommodities:crate:5,5,charm:crate_sealed:5,../../../../Chests/RLCraft/Containers/charm_crate.nbt,10,charm:crate_sealed:5,../../../../Chests/RLCraft/Containers/charm_crate.nbt,100)
RandomBlock(-1,12,4,variedcommodities:crate,5,charm:crate_sealed,../../../../Chests/RLCraft/Containers/charm_crate.nbt,100)
Block(-1,12,5,quark:iron_plate:1)
RandomBlock(-1,12,6,SMOOTH_BRICK:0,40,SMOOTH_BRICK:1,30,SMOOTH_BRICK:2,30,MOSSY_COBBLESTONE:0,30,COBBLESTONE:0,20,SMOOTH_BRICK:0,100)
Block(-1,13,5,quark:iron_plate:1)
RandomBlock(-1,13,6,SMOOTH_BRICK:0,40,SMOOTH_BRICK:1,30,SMOOTH_BRICK:2,30,MOSSY_COBBLESTONE:0,30,COBBLESTONE:0,20,SMOOTH_BRICK:0,100)
Block(-1,13,7,quark:basalt_wall)
Block(-1,14,5,quark:iron_plate:1)
RandomBlock(-1,14,6,SMOOTH_BRICK:0,40,SMOOTH_BRICK:1,30,SMOOTH_BRICK:2,30,MOSSY_COBBLESTONE:0,30,COBBLESTONE:0,20,SMOOTH_BRICK:0,100)
Block(-1,15,-7,DOUBLE_STEP:0)
RandomBlock(-1,15,-6,SMOOTH_BRICK:0,40,SMOOTH_BRICK:1,30,SMOOTH_BRICK:2,30,MOSSY_COBBLESTONE:0,30,COBBLESTONE:0,20,SMOOTH_BRICK:0,100)
Block(-1,15,-5,DOUBLE_STEP:0)
RandomBlock(-1,15,-4,SMOOTH_BRICK:0,40,SMOOTH_BRICK:1,30,SMOOTH_BRICK:2,30,MOSSY_COBBLESTONE:0,30,COBBLESTONE:0,20,SMOOTH_BRICK:0,100)
Block(-1,15,-3,DOUBLE_STEP:0)
RandomBlock(-1,15,-2,SMOOTH_BRICK:0,40,SMOOTH_BRICK:1,30,SMOOTH_BRICK:2,30,MOSSY_COBBLESTONE:0,30,COBBLESTONE:0,20,SMOOTH_BRICK:0,100)
Block(-1,15,-1,DOUBLE_STEP:0)
RandomBlock(-1,15,0,SMOOTH_BRICK:0,40,SMOOTH_BRICK:1,30,SMOOTH_BRICK:2,30,MOSSY_COBBLESTONE:0,30,COBBLESTONE:0,20,SMOOTH_BRICK:0,100)
Block(-1,15,1,DOUBLE_STEP:0)
RandomBlock(-1,15,2,SMOOTH_BRICK:0,40,SMOOTH_BRICK:1,30,SMOOTH_BRICK:2,30,MOSSY_COBBLESTONE:0,30,COBBLESTONE:0,20,SMOOTH_BRICK:0,100)
Block(-1,15,3,DOUBLE_STEP:0)
RandomBlock(-1,15,4,SMOOTH_BRICK:0,40,SMOOTH_BRICK:1,30,SMOOTH_BRICK:2,30,MOSSY_COBBLESTONE:0,30,COBBLESTONE:0,20,SMOOTH_BRICK:0,100)
Block(-1,15,5,DOUBLE_STEP:0)
RandomBlock(-1,15,6,SMOOTH_BRICK:0,40,SMOOTH_BRICK:1,30,SMOOTH_BRICK:2,30,MOSSY_COBBLESTONE:0,30,COBBLESTONE:0,20,SMOOTH_BRICK:0,100)
Block(-1,16,-5,quark:basalt_wall)
Block(-1,16,-4,quark:basalt_wall)
Block(-1,16,1,DOUBLE_STEP:0)
Block(-1,16,4,DOUBLE_STEP:0)
Block(-1,16,5,DOUBLE_STEP:0)
RandomBlock(-1,16,6,SMOOTH_BRICK:0,40,SMOOTH_BRICK:1,30,SMOOTH_BRICK:2,30,MOSSY_COBBLESTONE:0,30,COBBLESTONE:0,20,SMOOTH_BRICK:0,100)
Block(-1,17,-4,quark:basalt_wall)
Block(-1,17,1,DOUBLE_STEP:0)
Block(-1,17,4,DOUBLE_STEP:0)
Block(-1,17,5,DOUBLE_STEP:0)
RandomBlock(-1,17,6,SMOOTH_BRICK:0,40,SMOOTH_BRICK:1,30,SMOOTH_BRICK:2,30,MOSSY_COBBLESTONE:0,30,COBBLESTONE:0,20,SMOOTH_BRICK:0,100)
Block(-1,18,-7,quark:iron_plate:1)
Block(-1,18,-6,quark:iron_plate:1)
Block(-1,18,-5,quark:iron_plate:1)
Block(-1,18,-4,quark:iron_plate:1)
Block(-1,18,-3,quark:iron_plate:1)
Block(-1,18,-2,quark:iron_plate:1)
Block(-1,18,-1,quark:iron_plate:1)
Block(-1,18,0,quark:iron_plate:1)
Block(-1,18,1,quark:iron_plate:1)
Block(-1,18,2,quark:iron_plate:1)
Block(-1,18,3,quark:iron_plate:1)
Block(-1,18,4,DOUBLE_STEP:0)
RandomBlock(-1,18,6,SMOOTH_BRICK:0,40,SMOOTH_BRICK:1,30,SMOOTH_BRICK:2,30,MOSSY_COBBLESTONE:0,30,COBBLESTONE:0,20,SMOOTH_BRICK:0,100)
Block(-1,19,4,DOUBLE_STEP:0)
Block(-1,19,6,quark:iron_plate:1)
Block(-1,20,4,DOUBLE_STEP:0)
RandomBlock(-1,20,5,SMOOTH_BRICK:0,40,SMOOTH_BRICK:1,30,SMOOTH_BRICK:2,30,MOSSY_COBBLESTONE:0,30,COBBLESTONE:0,20,SMOOTH_BRICK:0,100)
Block(-1,20,6,STEP:0)
RandomBlock(-1,21,3,SMOOTH_BRICK:0,40,SMOOTH_BRICK:1,30,SMOOTH_BRICK:2,30,MOSSY_COBBLESTONE:0,30,COBBLESTONE:0,20,SMOOTH_BRICK:0,100)
Block(-1,21,4,quark:iron_plate:1)
Block(-1,21,5,DOUBLE_STEP:0)
Block(-1,22,3,DOUBLE_STEP:0)
Block(-1,22,4,STEP:0)
Block(-1,22,5,quark:iron_plate:1)
Block(-1,23,3,DOUBLE_STEP:0)
Block(-1,23,4,STEP:0)
Block(-1,23,5,DOUBLE_STEP:0)
Block(-1,24,3,DOUBLE_STEP:0)
Block(-1,24,4,STEP:0)
Block(-1,24,5,DOUBLE_STEP:0)
RandomBlock(-1,25,3,SMOOTH_BRICK:0,40,SMOOTH_BRICK:1,30,SMOOTH_BRICK:2,30,MOSSY_COBBLESTONE:0,30,COBBLESTONE:0,20,SMOOTH_BRICK:0,100)
Block(-1,25,4,DOUBLE_STEP:0)
Block(-1,25,5,STEP:0)
Block(-1,26,-5,quark:iron_plate:1)
Block(-1,26,-3,quark:iron_plate:1)
Block(-1,26,3,quark:sturdy_stone)
Block(-1,26,4,STEP:0)
Block(-1,27,-6,quark:iron_plate:1)
Block(-1,27,-2,quark:iron_plate:1)
RandomBlock(-1,27,3,SMOOTH_BRICK:0,40,SMOOTH_BRICK:1,30,SMOOTH_BRICK:2,30,MOSSY_COBBLESTONE:0,30,COBBLESTONE:0,20,SMOOTH_BRICK:0,100)
Block(-1,28,-7,quark:polished_stone)
Block(-1,28,-6,quark:polished_stone)
Block(-1,28,-5,quark:polished_stone)
Block(-1,28,-4,quark:world_stone_pavement:5)
Block(-1,28,-3,quark:world_stone_pavement:2)
Block(-1,28,-2,quark:polished_stone)
Block(-1,28,-1,quark:polished_stone)
Block(-1,28,0,quark:world_stone_pavement:2)
Block(-1,28,1,quark:world_stone_pavement:5)
RandomBlock(-1,28,2,SMOOTH_BRICK:0,40,SMOOTH_BRICK:1,30,SMOOTH_BRICK:2,30,MOSSY_COBBLESTONE:0,30,COBBLESTONE:0,20,SMOOTH_BRICK:0,100)
Block(-1,28,3,SMOOTH_STAIRS:3)
Block(-1,29,1,quark:iron_plate:1)
Block(-1,29,2,SMOOTH_STAIRS:3)
Block(-1,30,1,quark:stone_diorite_bricks_wall)
Block(0,0,-7,quark:world_stone_pavement:5)
Block(0,0,-6,quark:world_stone_pavement:2)
Block(0,0,-5,quark:limestone:1)
Block(0,0,-4,quark:world_stone_pavement:2)
Block(0,0,-3,quark:world_stone_pavement:2)
Block(0,0,-2,quark:limestone:1)
Block(0,0,-1,quark:limestone:1)
Block(0,0,0,quark:limestone:1)
Block(0,0,1,quark:limestone:1)
Block(0,0,2,quark:world_stone_pavement:5)
Block(0,0,3,quark:world_stone_pavement:5)
Block(0,0,4,quark:world_stone_pavement:2)
Block(0,0,5,quark:world_stone_pavement:2)
Block(0,0,6,quark:limestone:1)
Block(0,1,-7,quark:world_stone_pavement:2)
Block(0,1,-6,quark:world_stone_pavement:2)
Block(0,1,-5,quark:world_stone_pavement:5)
Block(0,1,-4,quark:world_stone_pavement:2)
Block(0,1,-3,quark:world_stone_pavement:2)
Block(0,1,-2,quark:world_stone_pavement:5)
Block(0,1,-1,quark:world_stone_pavement:5)
Block(0,1,0,quark:world_stone_pavement:5)
Block(0,1,1,quark:limestone:1)
Block(0,1,2,quark:world_stone_pavement:2)
Block(0,1,3,quark:world_stone_pavement:5)
Block(0,1,4,quark:world_stone_pavement:2)
Block(0,1,5,quark:world_stone_pavement:5)
Block(0,1,6,quark:world_stone_pavement:5)
Block(0,2,-7,quark:world_stone_pavement:5)
Block(0,2,-6,quark:world_stone_pavement:5)
Block(0,2,-5,quark:limestone:1)
Block(0,2,-4,quark:limestone:1)
Block(0,2,-3,quark:world_stone_pavement:2)
Block(0,2,-2,quark:world_stone_pavement:2)
Block(0,2,-1,quark:world_stone_pavement:5)
Block(0,2,0,quark:world_stone_pavement:2)
Block(0,2,1,quark:world_stone_pavement:5)
Block(0,2,2,quark:world_stone_pavement:5)
Block(0,2,3,quark:limestone:1)
Block(0,2,4,quark:world_stone_pavement:2)
Block(0,2,5,quark:world_stone_pavement:5)
Block(0,2,6,quark:world_stone_pavement:5)
Block(0,3,-7,quark:world_stone_pavement:5)
Block(0,3,-6,quark:world_stone_pavement:2)
Block(0,3,-5,quark:world_stone_pavement:2)
Block(0,3,-4,quark:limestone:1)
Block(0,3,-3,quark:world_stone_pavement:2)
Block(0,3,-2,quark:world_stone_pavement:5)
Block(0,3,-1,quark:world_stone_pavement:5)
Block(0,3,0,quark:world_stone_pavement:2)
Block(0,3,1,quark:limestone:1)
Block(0,3,2,quark:world_stone_pavement:2)
Block(0,3,3,quark:world_stone_pavement:5)
Block(0,3,4,quark:world_stone_pavement:2)
Block(0,3,5,quark:limestone:1)
Block(0,3,6,quark:world_stone_pavement:2)
Block(0,4,-7,quark:world_stone_pavement:5)
Block(0,4,-6,quark:limestone:1)
Block(0,4,-5,quark:world_stone_pavement:5)
Block(0,4,-4,quark:world_stone_pavement:2)
Block(0,4,-3,quark:world_stone_pavement:2)
Block(0,4,-2,quark:world_stone_pavement:5)
Block(0,4,-1,quark:world_stone_pavement:2)
Block(0,4,0,quark:world_stone_pavement:5)
Block(0,4,1,quark:world_stone_pavement:2)
Block(0,4,2,quark:limestone:1)
Block(0,4,3,quark:limestone:1)
Block(0,4,4,quark:world_stone_pavement:2)
Block(0,4,5,quark:limestone:1)
Block(0,4,6,quark:world_stone_pavement:2)
Block(0,5,-7,quark:world_stone_pavement:5)
Block(0,5,-6,quark:limestone:1)
Block(0,5,-5,quark:limestone:1)
Block(0,5,-4,quark:limestone:1)
Block(0,5,-3,quark:world_stone_pavement:2)
Block(0,5,-2,quark:world_stone_pavement:5)
Block(0,5,-1,quark:limestone:1)
Block(0,5,0,quark:limestone:1)
Block(0,5,1,quark:world_stone_pavement:5)
Block(0,5,2,quark:world_stone_pavement:5)
Block(0,5,3,quark:world_stone_pavement:5)
Block(0,5,4,quark:world_stone_pavement:2)
Block(0,5,5,quark:limestone:1)
Block(0,5,6,quark:limestone:1)
Block(0,6,-7,quark:world_stone_pavement:5)
Block(0,6,-6,quark:limestone:1)
Block(0,6,-5,quark:world_stone_pavement:2)
Block(0,6,-4,quark:world_stone_pavement:2)
Block(0,6,-3,quark:world_stone_pavement:2)
Block(0,6,-2,quark:world_stone_pavement:5)
Block(0,6,-1,quark:world_stone_pavement:2)
Block(0,6,0,quark:world_stone_pavement:5)
Block(0,6,1,quark:world_stone_pavement:5)
Block(0,6,2,quark:limestone:1)
Block(0,6,3,quark:world_stone_pavement:2)
Block(0,6,4,quark:world_stone_pavement:2)
Block(0,6,5,quark:world_stone_pavement:5)
Block(0,6,6,quark:world_stone_pavement:5)
Block(0,7,-7,quark:world_stone_pavement:2)
Block(0,7,-6,quark:world_stone_pavement:2)
Block(0,7,-5,quark:world_stone_pavement:5)
Block(0,7,-4,quark:world_stone_pavement:2)
Block(0,7,-3,quark:world_stone_pavement:5)
Block(0,7,-2,quark:world_stone_pavement:2)
Block(0,7,-1,quark:limestone:1)
Block(0,7,0,quark:world_stone_pavement:2)
Block(0,7,1,quark:limestone:1)
Block(0,7,2,quark:limestone:1)
Block(0,7,3,quark:world_stone_pavement:5)
Block(0,7,4,quark:world_stone_pavement:2)
Block(0,7,5,quark:world_stone_pavement:2)
Block(0,7,6,quark:world_stone_pavement:2)
Block(0,8,-7,quark:world_stone_pavement:5)
Block(0,8,-6,quark:world_stone_pavement:2)
Block(0,8,-5,quark:world_stone_pavement:2)
Block(0,8,-4,quark:world_stone_pavement:5)
Block(0,8,-3,quark:world_stone_pavement:2)
Block(0,8,-2,quark:limestone:1)
Block(0,8,-1,quark:world_stone_pavement:2)
Block(0,8,0,quark:limestone:1)
Block(0,8,1,quark:world_stone_pavement:5)
Block(0,8,2,quark:world_stone_pavement:5)
Block(0,8,3,quark:world_stone_pavement:5)
Block(0,8,4,quark:world_stone_pavement:5)
Block(0,8,5,quark:world_stone_pavement:2)
Block(0,8,6,quark:world_stone_pavement:2)
Block(0,9,-7,quark:limestone:1)
Block(0,9,-6,quark:limestone:1)
Block(0,9,-5,quark:world_stone_pavement:5)
Block(0,9,-4,quark:world_stone_pavement:2)
Block(0,9,-3,quark:polished_stone)
Block(0,9,-2,quark:polished_stone)
Block(0,9,-1,quark:world_stone_pavement:2)
Block(0,9,0,quark:polished_stone)
Block(0,9,1,quark:polished_stone)
Block(0,9,2,quark:world_stone_pavement:5)
Block(0,9,3,quark:world_stone_pavement:5)
Block(0,9,4,quark:world_stone_pavement:2)
Block(0,9,5,quark:world_stone_pavement:2)
Block(0,9,6,quark:world_stone_pavement:2)
Block(0,10,-7,quark:world_stone_pavement:5)
Block(0,10,-6,quark:world_stone_pavement:2)
Block(0,10,-5,quark:world_stone_pavement:2)
Block(0,10,-4,quark:polished_stone)
Block(0,10,-3,quark:polished_stone)
Block(0,10,-2,quark:polished_stone)
Block(0,10,-1,quark:polished_stone)
Block(0,10,0,quark:polished_stone)
Block(0,10,1,quark:world_stone_pavement:2)
Block(0,10,2,quark:polished_stone)
Block(0,10,3,quark:polished_stone)
Block(0,10,4,quark:polished_stone)
Block(0,10,5,quark:polished_stone)
Block(0,10,6,quark:world_stone_pavement:2)
Block(0,11,-7,quark:world_stone_pavement:5)
Block(0,11,-6,quark:world_stone_pavement:5)
Block(0,11,-5,quark:polished_stone)
Block(0,11,-4,quark:polished_stone)
Block(0,11,-3,biomesoplenty:fir_door_block:0)
Block(0,11,-2,biomesoplenty:fir_door_block:0)
Block(0,11,-1,quark:world_stone_pavement:2)
Block(0,11,0,biomesoplenty:fir_door_block:0)
Block(0,11,1,biomesoplenty:fir_door_block:0)
Block(0,11,2,quark:polished_stone)
Block(0,11,3,quark:polished_stone)
Block(0,11,4,quark:polished_stone)
Block(0,11,5,quark:polished_stone)
Block(0,11,6,quark:limestone:1)
RandomBlock(0,12,-7,SMOOTH_BRICK:0,40,SMOOTH_BRICK:1,30,SMOOTH_BRICK:2,30,MOSSY_COBBLESTONE:0,30,COBBLESTONE:0,20,SMOOTH_BRICK:0,100)
RandomBlock(0,12,-6,SMOOTH_BRICK:0,40,SMOOTH_BRICK:1,30,SMOOTH_BRICK:2,30,MOSSY_COBBLESTONE:0,30,COBBLESTONE:0,20,SMOOTH_BRICK:0,100)
Block(0,12,-5,DOUBLE_STEP:0)
Block(0,12,-4,DOUBLE_STEP:0)
Block(0,12,-3,biomesoplenty:fir_door_block:8)
Block(0,12,-2,biomesoplenty:fir_door_block:9)
Block(0,12,-1,DOUBLE_STEP:0)
Block(0,12,0,biomesoplenty:fir_door_block:8)
Block(0,12,1,biomesoplenty:fir_door_block:9)
Block(0,12,2,DOUBLE_STEP:0)
Block(0,12,3,quark:iron_plate:1)
RandomBlock(0,12,4,SMOOTH_BRICK:0,40,SMOOTH_BRICK:1,30,SMOOTH_BRICK:2,30,MOSSY_COBBLESTONE:0,30,COBBLESTONE:0,20,SMOOTH_BRICK:0,100)
