
#######################################################################
# +-----------------------------------------------------------------+ #
# |                            BO4 object                           | #
# +-----------------------------------------------------------------+ #
#######################################################################

Author: NLBlackEagle

Description: No description given

SettingsMode: WriteDisable


#######################################################################
# +-----------------------------------------------------------------+ #
# |                          Main settings                          | #
# +-----------------------------------------------------------------+ #
#######################################################################

FixedRotation: 

Frequency: 0

SpawnHeight: highestBlock

UseCenterForHighestBlock: true

##############################
# Height Limits for the BO4. #
##############################

MinHeight: 0

MaxHeight: 255

InheritBO3: 

InheritBO3Rotation: NORTH

OverrideChildSettings: true

OverrideParentHeight: false

CanOverride: true

BranchFrequency: 0

BranchFrequencyGroup: 

MustBeBelowOther: false

MustBeInside: 

CannotBeInside: 

ReplacesBO3: 

MustBeInsideWorldBorders: false

CanSpawnOnWater: true

SpawnOnWaterOnly: false

SpawnUnderWater: false

SpawnAtWaterLevel: false

HeightOffset: 0

RemoveAir: false

ReplaceAbove: 

ReplaceBelow: 

ReplaceWithBiomeBlocks: false

ReplaceWithSurfaceBlock: GRASS

ReplaceWithGroundBlock: DIRT

ReplaceWithStoneBlock: STONE

SmoothRadius: 0

SmoothHeightOffset: 0

SmoothStartTop: false

SmoothStartWood: false

SmoothingSurfaceBlock: 

SmoothingGroundBlock: 

BO3Group: 

IsSpawnPoint: false

DoReplaceBlocks: true


#######################################################################
# +-----------------------------------------------------------------+ #
# |                              Blocks                             | #
# +-----------------------------------------------------------------+ #
#######################################################################

RandomBlock(-8,0,-7,SMOOTH_BRICK:0,40,SMOOTH_BRICK:1,30,SMOOTH_BRICK:2,30,SMOOTH_STAIRS:0,15,SMOOTH_STAIRS:1,15,SMOOTH_STAIRS:2,15,SMOOTH_STAIRS:3,15,STEP:5,15,STEP:13,15,COBBLE_WALL:0,10,COBBLESTONE_STAIRS:0,10,STEP:3,10,COBBLE_WALL:1,20,COBBLESTONE_STAIRS:2,20,COBBLESTONE_STAIRS:3,20,MOSSY_COBBLESTONE:0,60,COBBLESTONE_STAIRS:1,20,STEP:11,20,COBBLESTONE:0,100)
RandomBlock(-8,0,-6,SMOOTH_BRICK:0,40,SMOOTH_BRICK:1,30,SMOOTH_BRICK:2,30,SMOOTH_STAIRS:0,15,SMOOTH_STAIRS:1,15,SMOOTH_STAIRS:2,15,SMOOTH_STAIRS:3,15,STEP:5,15,STEP:13,15,COBBLE_WALL:0,10,COBBLESTONE_STAIRS:0,10,STEP:3,10,COBBLE_WALL:1,20,COBBLESTONE_STAIRS:2,20,COBBLESTONE_STAIRS:3,20,MOSSY_COBBLESTONE:0,60,COBBLESTONE_STAIRS:1,20,STEP:11,20,COBBLESTONE:0,100)
RandomBlock(-8,0,-5,SMOOTH_BRICK:0,40,SMOOTH_BRICK:1,30,SMOOTH_BRICK:2,30,SMOOTH_STAIRS:0,15,SMOOTH_STAIRS:1,15,SMOOTH_STAIRS:2,15,SMOOTH_STAIRS:3,15,STEP:5,15,STEP:13,15,COBBLE_WALL:0,10,COBBLESTONE_STAIRS:0,10,STEP:3,10,COBBLE_WALL:1,20,COBBLESTONE_STAIRS:2,20,COBBLESTONE_STAIRS:3,20,MOSSY_COBBLESTONE:0,60,COBBLESTONE_STAIRS:1,20,STEP:11,20,COBBLESTONE:0,100)
RandomBlock(-8,0,-4,SMOOTH_BRICK:0,40,SMOOTH_BRICK:1,30,SMOOTH_BRICK:2,30,SMOOTH_STAIRS:0,15,SMOOTH_STAIRS:1,15,SMOOTH_STAIRS:2,15,SMOOTH_STAIRS:3,15,STEP:5,15,STEP:13,15,COBBLE_WALL:0,10,COBBLESTONE_STAIRS:0,10,STEP:3,10,COBBLE_WALL:1,20,COBBLESTONE_STAIRS:2,20,COBBLESTONE_STAIRS:3,20,MOSSY_COBBLESTONE:0,60,COBBLESTONE_STAIRS:1,20,STEP:11,20,COBBLESTONE:0,100)
RandomBlock(-8,0,-3,SMOOTH_BRICK:0,40,SMOOTH_BRICK:1,30,SMOOTH_BRICK:2,30,SMOOTH_STAIRS:0,15,SMOOTH_STAIRS:1,15,SMOOTH_STAIRS:2,15,SMOOTH_STAIRS:3,15,STEP:5,15,STEP:13,15,COBBLE_WALL:0,10,COBBLESTONE_STAIRS:0,10,STEP:3,10,COBBLE_WALL:1,20,COBBLESTONE_STAIRS:2,20,COBBLESTONE_STAIRS:3,20,MOSSY_COBBLESTONE:0,60,COBBLESTONE_STAIRS:1,20,STEP:11,20,COBBLESTONE:0,100)
RandomBlock(-8,0,-2,SMOOTH_BRICK:0,40,SMOOTH_BRICK:1,30,SMOOTH_BRICK:2,30,SMOOTH_STAIRS:0,15,SMOOTH_STAIRS:1,15,SMOOTH_STAIRS:2,15,SMOOTH_STAIRS:3,15,STEP:5,15,STEP:13,15,COBBLE_WALL:0,10,COBBLESTONE_STAIRS:0,10,STEP:3,10,COBBLE_WALL:1,20,COBBLESTONE_STAIRS:2,20,COBBLESTONE_STAIRS:3,20,MOSSY_COBBLESTONE:0,60,COBBLESTONE_STAIRS:1,20,STEP:11,20,COBBLESTONE:0,100)
RandomBlock(-8,1,-7,SMOOTH_BRICK:0,40,SMOOTH_BRICK:1,30,SMOOTH_BRICK:2,30,SMOOTH_STAIRS:0,15,SMOOTH_STAIRS:1,15,SMOOTH_STAIRS:2,15,SMOOTH_STAIRS:3,15,STEP:5,15,STEP:13,15,COBBLE_WALL:0,10,COBBLESTONE_STAIRS:0,10,STEP:3,10,COBBLE_WALL:1,20,COBBLESTONE_STAIRS:2,20,COBBLESTONE_STAIRS:3,20,MOSSY_COBBLESTONE:0,60,COBBLESTONE_STAIRS:1,20,STEP:11,20,COBBLESTONE:0,100)
RandomBlock(-8,1,-6,SMOOTH_BRICK:0,40,SMOOTH_BRICK:1,30,SMOOTH_BRICK:2,30,SMOOTH_STAIRS:0,15,SMOOTH_STAIRS:1,15,SMOOTH_STAIRS:2,15,SMOOTH_STAIRS:3,15,STEP:5,15,STEP:13,15,COBBLE_WALL:0,10,COBBLESTONE_STAIRS:0,10,STEP:3,10,COBBLE_WALL:1,20,COBBLESTONE_STAIRS:2,20,COBBLESTONE_STAIRS:3,20,MOSSY_COBBLESTONE:0,60,COBBLESTONE_STAIRS:1,20,STEP:11,20,COBBLESTONE:0,100)
RandomBlock(-8,1,-5,SMOOTH_BRICK:0,40,SMOOTH_BRICK:1,30,SMOOTH_BRICK:2,30,SMOOTH_STAIRS:0,15,SMOOTH_STAIRS:1,15,SMOOTH_STAIRS:2,15,SMOOTH_STAIRS:3,15,STEP:5,15,STEP:13,15,COBBLE_WALL:0,10,COBBLESTONE_STAIRS:0,10,STEP:3,10,COBBLE_WALL:1,20,COBBLESTONE_STAIRS:2,20,COBBLESTONE_STAIRS:3,20,MOSSY_COBBLESTONE:0,60,COBBLESTONE_STAIRS:1,20,STEP:11,20,COBBLESTONE:0,100)
RandomBlock(-8,1,-4,SMOOTH_BRICK:0,40,SMOOTH_BRICK:1,30,SMOOTH_BRICK:2,30,SMOOTH_STAIRS:0,15,SMOOTH_STAIRS:1,15,SMOOTH_STAIRS:2,15,SMOOTH_STAIRS:3,15,STEP:5,15,STEP:13,15,COBBLE_WALL:0,10,COBBLESTONE_STAIRS:0,10,STEP:3,10,COBBLE_WALL:1,20,COBBLESTONE_STAIRS:2,20,COBBLESTONE_STAIRS:3,20,MOSSY_COBBLESTONE:0,60,COBBLESTONE_STAIRS:1,20,STEP:11,20,COBBLESTONE:0,100)
RandomBlock(-8,1,-3,SMOOTH_BRICK:0,40,SMOOTH_BRICK:1,30,SMOOTH_BRICK:2,30,SMOOTH_STAIRS:0,15,SMOOTH_STAIRS:1,15,SMOOTH_STAIRS:2,15,SMOOTH_STAIRS:3,15,STEP:5,15,STEP:13,15,COBBLE_WALL:0,10,COBBLESTONE_STAIRS:0,10,STEP:3,10,COBBLE_WALL:1,20,COBBLESTONE_STAIRS:2,20,COBBLESTONE_STAIRS:3,20,MOSSY_COBBLESTONE:0,60,COBBLESTONE_STAIRS:1,20,STEP:11,20,COBBLESTONE:0,100)
RandomBlock(-8,1,-2,SMOOTH_BRICK:0,40,SMOOTH_BRICK:1,30,SMOOTH_BRICK:2,30,SMOOTH_STAIRS:0,15,SMOOTH_STAIRS:1,15,SMOOTH_STAIRS:2,15,SMOOTH_STAIRS:3,15,STEP:5,15,STEP:13,15,COBBLE_WALL:0,10,COBBLESTONE_STAIRS:0,10,STEP:3,10,COBBLE_WALL:1,20,COBBLESTONE_STAIRS:2,20,COBBLESTONE_STAIRS:3,20,MOSSY_COBBLESTONE:0,60,COBBLESTONE_STAIRS:1,20,STEP:11,20,COBBLESTONE:0,100)
RandomBlock(-8,2,-7,SMOOTH_BRICK:0,40,SMOOTH_BRICK:1,30,SMOOTH_BRICK:2,30,SMOOTH_STAIRS:0,15,SMOOTH_STAIRS:1,15,SMOOTH_STAIRS:2,15,SMOOTH_STAIRS:3,15,STEP:5,15,STEP:13,15,COBBLE_WALL:0,10,COBBLESTONE_STAIRS:0,10,STEP:3,10,COBBLE_WALL:1,20,COBBLESTONE_STAIRS:2,20,COBBLESTONE_STAIRS:3,20,MOSSY_COBBLESTONE:0,60,COBBLESTONE_STAIRS:1,20,STEP:11,20,COBBLESTONE:0,100)
RandomBlock(-8,2,-6,SMOOTH_BRICK:0,40,SMOOTH_BRICK:1,30,SMOOTH_BRICK:2,30,SMOOTH_STAIRS:0,15,SMOOTH_STAIRS:1,15,SMOOTH_STAIRS:2,15,SMOOTH_STAIRS:3,15,STEP:5,15,STEP:13,15,COBBLE_WALL:0,10,COBBLESTONE_STAIRS:0,10,STEP:3,10,COBBLE_WALL:1,20,COBBLESTONE_STAIRS:2,20,COBBLESTONE_STAIRS:3,20,MOSSY_COBBLESTONE:0,60,COBBLESTONE_STAIRS:1,20,STEP:11,20,COBBLESTONE:0,100)
RandomBlock(-8,2,-5,SMOOTH_BRICK:0,40,SMOOTH_BRICK:1,30,SMOOTH_BRICK:2,30,SMOOTH_STAIRS:0,15,SMOOTH_STAIRS:1,15,SMOOTH_STAIRS:2,15,SMOOTH_STAIRS:3,15,STEP:5,15,STEP:13,15,COBBLE_WALL:0,10,COBBLESTONE_STAIRS:0,10,STEP:3,10,COBBLE_WALL:1,20,COBBLESTONE_STAIRS:2,20,COBBLESTONE_STAIRS:3,20,MOSSY_COBBLESTONE:0,60,COBBLESTONE_STAIRS:1,20,STEP:11,20,COBBLESTONE:0,100)
RandomBlock(-8,2,-4,SMOOTH_BRICK:0,40,SMOOTH_BRICK:1,30,SMOOTH_BRICK:2,30,SMOOTH_STAIRS:0,15,SMOOTH_STAIRS:1,15,SMOOTH_STAIRS:2,15,SMOOTH_STAIRS:3,15,STEP:5,15,STEP:13,15,COBBLE_WALL:0,10,COBBLESTONE_STAIRS:0,10,STEP:3,10,COBBLE_WALL:1,20,COBBLESTONE_STAIRS:2,20,COBBLESTONE_STAIRS:3,20,MOSSY_COBBLESTONE:0,60,COBBLESTONE_STAIRS:1,20,STEP:11,20,COBBLESTONE:0,100)
RandomBlock(-8,2,-3,SMOOTH_BRICK:0,40,SMOOTH_BRICK:1,30,SMOOTH_BRICK:2,30,SMOOTH_STAIRS:0,15,SMOOTH_STAIRS:1,15,SMOOTH_STAIRS:2,15,SMOOTH_STAIRS:3,15,STEP:5,15,STEP:13,15,COBBLE_WALL:0,10,COBBLESTONE_STAIRS:0,10,STEP:3,10,COBBLE_WALL:1,20,COBBLESTONE_STAIRS:2,20,COBBLESTONE_STAIRS:3,20,MOSSY_COBBLESTONE:0,60,COBBLESTONE_STAIRS:1,20,STEP:11,20,COBBLESTONE:0,100)
RandomBlock(-8,2,-2,SMOOTH_BRICK:0,40,SMOOTH_BRICK:1,30,SMOOTH_BRICK:2,30,SMOOTH_STAIRS:0,15,SMOOTH_STAIRS:1,15,SMOOTH_STAIRS:2,15,SMOOTH_STAIRS:3,15,STEP:5,15,STEP:13,15,COBBLE_WALL:0,10,COBBLESTONE_STAIRS:0,10,STEP:3,10,COBBLE_WALL:1,20,COBBLESTONE_STAIRS:2,20,COBBLESTONE_STAIRS:3,20,MOSSY_COBBLESTONE:0,60,COBBLESTONE_STAIRS:1,20,STEP:11,20,COBBLESTONE:0,100)
RandomBlock(-8,3,-7,SMOOTH_BRICK:0,40,SMOOTH_BRICK:1,30,SMOOTH_BRICK:2,30,SMOOTH_STAIRS:0,15,SMOOTH_STAIRS:1,15,SMOOTH_STAIRS:2,15,SMOOTH_STAIRS:3,15,STEP:5,15,STEP:13,15,COBBLE_WALL:0,10,COBBLESTONE_STAIRS:0,10,STEP:3,10,COBBLE_WALL:1,20,COBBLESTONE_STAIRS:2,20,COBBLESTONE_STAIRS:3,20,MOSSY_COBBLESTONE:0,60,COBBLESTONE_STAIRS:1,20,STEP:11,20,COBBLESTONE:0,100)
RandomBlock(-8,3,-6,SMOOTH_BRICK:0,40,SMOOTH_BRICK:1,30,SMOOTH_BRICK:2,30,SMOOTH_STAIRS:0,15,SMOOTH_STAIRS:1,15,SMOOTH_STAIRS:2,15,SMOOTH_STAIRS:3,15,STEP:5,15,STEP:13,15,COBBLE_WALL:0,10,COBBLESTONE_STAIRS:0,10,STEP:3,10,COBBLE_WALL:1,20,COBBLESTONE_STAIRS:2,20,COBBLESTONE_STAIRS:3,20,MOSSY_COBBLESTONE:0,60,COBBLESTONE_STAIRS:1,20,STEP:11,20,COBBLESTONE:0,100)
RandomBlock(-8,3,-5,SMOOTH_BRICK:0,40,SMOOTH_BRICK:1,30,SMOOTH_BRICK:2,30,SMOOTH_STAIRS:0,15,SMOOTH_STAIRS:1,15,SMOOTH_STAIRS:2,15,SMOOTH_STAIRS:3,15,STEP:5,15,STEP:13,15,COBBLE_WALL:0,10,COBBLESTONE_STAIRS:0,10,STEP:3,10,COBBLE_WALL:1,20,COBBLESTONE_STAIRS:2,20,COBBLESTONE_STAIRS:3,20,MOSSY_COBBLESTONE:0,60,COBBLESTONE_STAIRS:1,20,STEP:11,20,COBBLESTONE:0,100)
RandomBlock(-8,3,-4,SMOOTH_BRICK:0,40,SMOOTH_BRICK:1,30,SMOOTH_BRICK:2,30,SMOOTH_STAIRS:0,15,SMOOTH_STAIRS:1,15,SMOOTH_STAIRS:2,15,SMOOTH_STAIRS:3,15,STEP:5,15,STEP:13,15,COBBLE_WALL:0,10,COBBLESTONE_STAIRS:0,10,STEP:3,10,COBBLE_WALL:1,20,COBBLESTONE_STAIRS:2,20,COBBLESTONE_STAIRS:3,20,MOSSY_COBBLESTONE:0,60,COBBLESTONE_STAIRS:1,20,STEP:11,20,COBBLESTONE:0,100)
RandomBlock(-8,3,-3,SMOOTH_BRICK:0,40,SMOOTH_BRICK:1,30,SMOOTH_BRICK:2,30,SMOOTH_STAIRS:0,15,SMOOTH_STAIRS:1,15,SMOOTH_STAIRS:2,15,SMOOTH_STAIRS:3,15,STEP:5,15,STEP:13,15,COBBLE_WALL:0,10,COBBLESTONE_STAIRS:0,10,STEP:3,10,COBBLE_WALL:1,20,COBBLESTONE_STAIRS:2,20,COBBLESTONE_STAIRS:3,20,MOSSY_COBBLESTONE:0,60,COBBLESTONE_STAIRS:1,20,STEP:11,20,COBBLESTONE:0,100)
RandomBlock(-8,3,-2,SMOOTH_BRICK:0,40,SMOOTH_BRICK:1,30,SMOOTH_BRICK:2,30,SMOOTH_STAIRS:0,15,SMOOTH_STAIRS:1,15,SMOOTH_STAIRS:2,15,SMOOTH_STAIRS:3,15,STEP:5,15,STEP:13,15,COBBLE_WALL:0,10,COBBLESTONE_STAIRS:0,10,STEP:3,10,COBBLE_WALL:1,20,COBBLESTONE_STAIRS:2,20,COBBLESTONE_STAIRS:3,20,MOSSY_COBBLESTONE:0,60,COBBLESTONE_STAIRS:1,20,STEP:11,20,COBBLESTONE:0,100)
RandomBlock(-8,4,-7,SMOOTH_BRICK:0,40,SMOOTH_BRICK:1,30,SMOOTH_BRICK:2,30,SMOOTH_STAIRS:0,15,SMOOTH_STAIRS:1,15,SMOOTH_STAIRS:2,15,SMOOTH_STAIRS:3,15,STEP:5,15,STEP:13,15,COBBLE_WALL:0,10,COBBLESTONE_STAIRS:0,10,STEP:3,10,COBBLE_WALL:1,20,COBBLESTONE_STAIRS:2,20,COBBLESTONE_STAIRS:3,20,MOSSY_COBBLESTONE:0,60,COBBLESTONE_STAIRS:1,20,STEP:11,20,COBBLESTONE:0,100)
RandomBlock(-8,4,-6,SMOOTH_BRICK:0,40,SMOOTH_BRICK:1,30,SMOOTH_BRICK:2,30,SMOOTH_STAIRS:0,15,SMOOTH_STAIRS:1,15,SMOOTH_STAIRS:2,15,SMOOTH_STAIRS:3,15,STEP:5,15,STEP:13,15,COBBLE_WALL:0,10,COBBLESTONE_STAIRS:0,10,STEP:3,10,COBBLE_WALL:1,20,COBBLESTONE_STAIRS:2,20,COBBLESTONE_STAIRS:3,20,MOSSY_COBBLESTONE:0,60,COBBLESTONE_STAIRS:1,20,STEP:11,20,COBBLESTONE:0,100)
RandomBlock(-8,4,-5,SMOOTH_BRICK:0,40,SMOOTH_BRICK:1,30,SMOOTH_BRICK:2,30,SMOOTH_STAIRS:0,15,SMOOTH_STAIRS:1,15,SMOOTH_STAIRS:2,15,SMOOTH_STAIRS:3,15,STEP:5,15,STEP:13,15,COBBLE_WALL:0,10,COBBLESTONE_STAIRS:0,10,STEP:3,10,COBBLE_WALL:1,20,COBBLESTONE_STAIRS:2,20,COBBLESTONE_STAIRS:3,20,MOSSY_COBBLESTONE:0,60,COBBLESTONE_STAIRS:1,20,STEP:11,20,COBBLESTONE:0,100)
RandomBlock(-8,4,-4,SMOOTH_BRICK:0,40,SMOOTH_BRICK:1,30,SMOOTH_BRICK:2,30,SMOOTH_STAIRS:0,15,SMOOTH_STAIRS:1,15,SMOOTH_STAIRS:2,15,SMOOTH_STAIRS:3,15,STEP:5,15,STEP:13,15,COBBLE_WALL:0,10,COBBLESTONE_STAIRS:0,10,STEP:3,10,COBBLE_WALL:1,20,COBBLESTONE_STAIRS:2,20,COBBLESTONE_STAIRS:3,20,MOSSY_COBBLESTONE:0,60,COBBLESTONE_STAIRS:1,20,STEP:11,20,COBBLESTONE:0,100)
RandomBlock(-8,4,-3,SMOOTH_BRICK:0,40,SMOOTH_BRICK:1,30,SMOOTH_BRICK:2,30,SMOOTH_STAIRS:0,15,SMOOTH_STAIRS:1,15,SMOOTH_STAIRS:2,15,SMOOTH_STAIRS:3,15,STEP:5,15,STEP:13,15,COBBLE_WALL:0,10,COBBLESTONE_STAIRS:0,10,STEP:3,10,COBBLE_WALL:1,20,COBBLESTONE_STAIRS:2,20,COBBLESTONE_STAIRS:3,20,MOSSY_COBBLESTONE:0,60,COBBLESTONE_STAIRS:1,20,STEP:11,20,COBBLESTONE:0,100)
RandomBlock(-8,4,-2,SMOOTH_BRICK:0,40,SMOOTH_BRICK:1,30,SMOOTH_BRICK:2,30,SMOOTH_STAIRS:0,15,SMOOTH_STAIRS:1,15,SMOOTH_STAIRS:2,15,SMOOTH_STAIRS:3,15,STEP:5,15,STEP:13,15,COBBLE_WALL:0,10,COBBLESTONE_STAIRS:0,10,STEP:3,10,COBBLE_WALL:1,20,COBBLESTONE_STAIRS:2,20,COBBLESTONE_STAIRS:3,20,MOSSY_COBBLESTONE:0,60,COBBLESTONE_STAIRS:1,20,STEP:11,20,COBBLESTONE:0,100)
RandomBlock(-8,5,-7,SMOOTH_BRICK:0,40,SMOOTH_BRICK:1,30,SMOOTH_BRICK:2,30,SMOOTH_STAIRS:0,15,SMOOTH_STAIRS:1,15,SMOOTH_STAIRS:2,15,SMOOTH_STAIRS:3,15,STEP:5,15,STEP:13,15,COBBLE_WALL:0,10,COBBLESTONE_STAIRS:0,10,STEP:3,10,COBBLE_WALL:1,20,COBBLESTONE_STAIRS:2,20,COBBLESTONE_STAIRS:3,20,MOSSY_COBBLESTONE:0,60,COBBLESTONE_STAIRS:1,20,STEP:11,20,COBBLESTONE:0,100)
RandomBlock(-8,5,-6,SMOOTH_BRICK:0,40,SMOOTH_BRICK:1,30,SMOOTH_BRICK:2,30,SMOOTH_STAIRS:0,15,SMOOTH_STAIRS:1,15,SMOOTH_STAIRS:2,15,SMOOTH_STAIRS:3,15,STEP:5,15,STEP:13,15,COBBLE_WALL:0,10,COBBLESTONE_STAIRS:0,10,STEP:3,10,COBBLE_WALL:1,20,COBBLESTONE_STAIRS:2,20,COBBLESTONE_STAIRS:3,20,MOSSY_COBBLESTONE:0,60,COBBLESTONE_STAIRS:1,20,STEP:11,20,COBBLESTONE:0,100)
RandomBlock(-8,5,-5,SMOOTH_BRICK:0,40,SMOOTH_BRICK:1,30,SMOOTH_BRICK:2,30,SMOOTH_STAIRS:0,15,SMOOTH_STAIRS:1,15,SMOOTH_STAIRS:2,15,SMOOTH_STAIRS:3,15,STEP:5,15,STEP:13,15,COBBLE_WALL:0,10,COBBLESTONE_STAIRS:0,10,STEP:3,10,COBBLE_WALL:1,20,COBBLESTONE_STAIRS:2,20,COBBLESTONE_STAIRS:3,20,MOSSY_COBBLESTONE:0,60,COBBLESTONE_STAIRS:1,20,STEP:11,20,COBBLESTONE:0,100)
RandomBlock(-8,5,-4,SMOOTH_BRICK:0,40,SMOOTH_BRICK:1,30,SMOOTH_BRICK:2,30,SMOOTH_STAIRS:0,15,SMOOTH_STAIRS:1,15,SMOOTH_STAIRS:2,15,SMOOTH_STAIRS:3,15,STEP:5,15,STEP:13,15,COBBLE_WALL:0,10,COBBLESTONE_STAIRS:0,10,STEP:3,10,COBBLE_WALL:1,20,COBBLESTONE_STAIRS:2,20,COBBLESTONE_STAIRS:3,20,MOSSY_COBBLESTONE:0,60,COBBLESTONE_STAIRS:1,20,STEP:11,20,COBBLESTONE:0,100)
RandomBlock(-8,5,-3,SMOOTH_BRICK:0,40,SMOOTH_BRICK:1,30,SMOOTH_BRICK:2,30,SMOOTH_STAIRS:0,15,SMOOTH_STAIRS:1,15,SMOOTH_STAIRS:2,15,SMOOTH_STAIRS:3,15,STEP:5,15,STEP:13,15,COBBLE_WALL:0,10,COBBLESTONE_STAIRS:0,10,STEP:3,10,COBBLE_WALL:1,20,COBBLESTONE_STAIRS:2,20,COBBLESTONE_STAIRS:3,20,MOSSY_COBBLESTONE:0,60,COBBLESTONE_STAIRS:1,20,STEP:11,20,COBBLESTONE:0,100)
RandomBlock(-8,5,-2,quark:limestone:1,30,quark:limestone_wall,10,quark:limestone,100)
RandomBlock(-8,6,-7,SMOOTH_BRICK:0,40,SMOOTH_BRICK:1,30,SMOOTH_BRICK:2,30,SMOOTH_STAIRS:0,15,SMOOTH_STAIRS:1,15,SMOOTH_STAIRS:2,15,SMOOTH_STAIRS:3,15,STEP:5,15,STEP:13,15,COBBLE_WALL:0,10,COBBLESTONE_STAIRS:0,10,STEP:3,10,COBBLE_WALL:1,20,COBBLESTONE_STAIRS:2,20,COBBLESTONE_STAIRS:3,20,MOSSY_COBBLESTONE:0,60,COBBLESTONE_STAIRS:1,20,STEP:11,20,COBBLESTONE:0,100)
RandomBlock(-8,6,-6,SMOOTH_BRICK:0,40,SMOOTH_BRICK:1,30,SMOOTH_BRICK:2,30,SMOOTH_STAIRS:0,15,SMOOTH_STAIRS:1,15,SMOOTH_STAIRS:2,15,SMOOTH_STAIRS:3,15,STEP:5,15,STEP:13,15,COBBLE_WALL:0,10,COBBLESTONE_STAIRS:0,10,STEP:3,10,COBBLE_WALL:1,20,COBBLESTONE_STAIRS:2,20,COBBLESTONE_STAIRS:3,20,MOSSY_COBBLESTONE:0,60,COBBLESTONE_STAIRS:1,20,STEP:11,20,COBBLESTONE:0,100)
RandomBlock(-8,6,-5,SMOOTH_BRICK:0,40,SMOOTH_BRICK:1,30,SMOOTH_BRICK:2,30,SMOOTH_STAIRS:0,15,SMOOTH_STAIRS:1,15,SMOOTH_STAIRS:2,15,SMOOTH_STAIRS:3,15,STEP:5,15,STEP:13,15,COBBLE_WALL:0,10,COBBLESTONE_STAIRS:0,10,STEP:3,10,COBBLE_WALL:1,20,COBBLESTONE_STAIRS:2,20,COBBLESTONE_STAIRS:3,20,MOSSY_COBBLESTONE:0,60,COBBLESTONE_STAIRS:1,20,STEP:11,20,COBBLESTONE:0,100)
RandomBlock(-8,6,-4,SMOOTH_BRICK:0,40,SMOOTH_BRICK:1,30,SMOOTH_BRICK:2,30,SMOOTH_STAIRS:0,15,SMOOTH_STAIRS:1,15,SMOOTH_STAIRS:2,15,SMOOTH_STAIRS:3,15,STEP:5,15,STEP:13,15,COBBLE_WALL:0,10,COBBLESTONE_STAIRS:0,10,STEP:3,10,COBBLE_WALL:1,20,COBBLESTONE_STAIRS:2,20,COBBLESTONE_STAIRS:3,20,MOSSY_COBBLESTONE:0,60,COBBLESTONE_STAIRS:1,20,STEP:11,20,COBBLESTONE:0,100)
RandomBlock(-8,6,-3,SMOOTH_BRICK:0,40,SMOOTH_BRICK:1,30,SMOOTH_BRICK:2,30,SMOOTH_STAIRS:0,15,SMOOTH_STAIRS:1,15,SMOOTH_STAIRS:2,15,SMOOTH_STAIRS:3,15,STEP:5,15,STEP:13,15,COBBLE_WALL:0,10,COBBLESTONE_STAIRS:0,10,STEP:3,10,COBBLE_WALL:1,20,COBBLESTONE_STAIRS:2,20,COBBLESTONE_STAIRS:3,20,MOSSY_COBBLESTONE:0,60,COBBLESTONE_STAIRS:1,20,STEP:11,20,COBBLESTONE:0,100)
RandomBlock(-8,6,-2,quark:limestone:1,30,quark:limestone_wall,10,quark:limestone,100)
RandomBlock(-8,7,-7,SMOOTH_BRICK:0,40,SMOOTH_BRICK:1,30,SMOOTH_BRICK:2,30,SMOOTH_STAIRS:0,15,SMOOTH_STAIRS:1,15,SMOOTH_STAIRS:2,15,SMOOTH_STAIRS:3,15,STEP:5,15,STEP:13,15,COBBLE_WALL:0,10,COBBLESTONE_STAIRS:0,10,STEP:3,10,COBBLE_WALL:1,20,COBBLESTONE_STAIRS:2,20,COBBLESTONE_STAIRS:3,20,MOSSY_COBBLESTONE:0,60,COBBLESTONE_STAIRS:1,20,STEP:11,20,COBBLESTONE:0,100)
RandomBlock(-8,7,-6,SMOOTH_BRICK:0,40,SMOOTH_BRICK:1,30,SMOOTH_BRICK:2,30,SMOOTH_STAIRS:0,15,SMOOTH_STAIRS:1,15,SMOOTH_STAIRS:2,15,SMOOTH_STAIRS:3,15,STEP:5,15,STEP:13,15,COBBLE_WALL:0,10,COBBLESTONE_STAIRS:0,10,STEP:3,10,COBBLE_WALL:1,20,COBBLESTONE_STAIRS:2,20,COBBLESTONE_STAIRS:3,20,MOSSY_COBBLESTONE:0,60,COBBLESTONE_STAIRS:1,20,STEP:11,20,COBBLESTONE:0,100)
RandomBlock(-8,7,-5,SMOOTH_BRICK:0,40,SMOOTH_BRICK:1,30,SMOOTH_BRICK:2,30,SMOOTH_STAIRS:0,15,SMOOTH_STAIRS:1,15,SMOOTH_STAIRS:2,15,SMOOTH_STAIRS:3,15,STEP:5,15,STEP:13,15,COBBLE_WALL:0,10,COBBLESTONE_STAIRS:0,10,STEP:3,10,COBBLE_WALL:1,20,COBBLESTONE_STAIRS:2,20,COBBLESTONE_STAIRS:3,20,MOSSY_COBBLESTONE:0,60,COBBLESTONE_STAIRS:1,20,STEP:11,20,COBBLESTONE:0,100)
RandomBlock(-8,7,-4,SMOOTH_BRICK:0,40,SMOOTH_BRICK:1,30,SMOOTH_BRICK:2,30,SMOOTH_STAIRS:0,15,SMOOTH_STAIRS:1,15,SMOOTH_STAIRS:2,15,SMOOTH_STAIRS:3,15,STEP:5,15,STEP:13,15,COBBLE_WALL:0,10,COBBLESTONE_STAIRS:0,10,STEP:3,10,COBBLE_WALL:1,20,COBBLESTONE_STAIRS:2,20,COBBLESTONE_STAIRS:3,20,MOSSY_COBBLESTONE:0,60,COBBLESTONE_STAIRS:1,20,STEP:11,20,COBBLESTONE:0,100)
RandomBlock(-8,7,-3,SMOOTH_BRICK:0,40,SMOOTH_BRICK:1,30,SMOOTH_BRICK:2,30,SMOOTH_STAIRS:0,15,SMOOTH_STAIRS:1,15,SMOOTH_STAIRS:2,15,SMOOTH_STAIRS:3,15,STEP:5,15,STEP:13,15,COBBLE_WALL:0,10,COBBLESTONE_STAIRS:0,10,STEP:3,10,COBBLE_WALL:1,20,COBBLESTONE_STAIRS:2,20,COBBLESTONE_STAIRS:3,20,MOSSY_COBBLESTONE:0,60,COBBLESTONE_STAIRS:1,20,STEP:11,20,COBBLESTONE:0,100)
RandomBlock(-8,7,-2,quark:limestone:1,30,quark:limestone_wall,10,quark:limestone,100)
RandomBlock(-8,8,-4,RUSTIC:IRON_LATTICE:0,30,RUSTIC:IRON_LATTICE:1,100)
RandomBlock(-8,8,-3,RUSTIC:IRON_LATTICE:0,30,RUSTIC:IRON_LATTICE:1,100)
Block(-8,8,-2,inspirations:redstone_barrel)
RandomBlock(-8,9,-4,RUSTIC:IRON_LATTICE:0,30,RUSTIC:IRON_LATTICE:1,100)
RandomBlock(-8,9,-3,RUSTIC:IRON_LATTICE:0,30,RUSTIC:IRON_LATTICE:1,100)
Block(-8,9,-2,inspirations:redstone_barrel)
RandomBlock(-8,10,-4,RUSTIC:IRON_LATTICE:0,30,RUSTIC:IRON_LATTICE:1,100)
RandomBlock(-8,10,-3,RUSTIC:IRON_LATTICE:0,30,RUSTIC:IRON_LATTICE:1,100)
RandomBlock(-8,10,-2,quark:limestone:1,30,quark:limestone_wall,10,quark:limestone,100)
RandomBlock(-8,11,-2,quark:limestone:1,30,quark:limestone_wall,10,quark:limestone,100)
RandomBlock(-8,12,-3,quark:limestone:1,30,quark:limestone_wall,10,quark:limestone,100)
RandomBlock(-8,13,-3,quark:limestone:1,30,quark:limestone_wall,10,quark:limestone,100)
RandomBlock(-8,14,-4,quark:limestone:1,30,quark:limestone_wall,10,quark:limestone,100)
Block(-8,14,-3,VINE:6)
RandomBlock(-8,15,-4,quark:limestone:1,30,quark:limestone_wall,10,quark:limestone,100)
Block(-8,15,-3,VINE:2)
RandomBlock(-8,16,-5,quark:limestone:1,30,quark:limestone_wall,10,quark:limestone,100)
Block(-8,16,-4,VINE:2)
RandomBlock(-8,17,-5,quark:limestone:1,30,quark:limestone_wall,10,quark:limestone,100)
Block(-8,17,-4,VINE:6)
RandomBlock(-8,18,-5,quark:limestone:1,30,quark:limestone_wall,10,quark:limestone,100)
Block(-8,18,-4,VINE:6)
RandomBlock(-8,19,-5,quark:limestone:1,30,quark:limestone_wall,10,quark:limestone,100)
Block(-8,19,-4,VINE:4)
RandomBlock(-8,20,-6,quark:limestone:1,30,quark:limestone_wall,10,quark:limestone,100)
RandomBlock(-8,21,-6,quark:limestone:1,30,quark:limestone_wall,10,quark:limestone,100)
RandomBlock(-8,22,-6,quark:limestone:1,30,quark:limestone_wall,10,quark:limestone,100)
RandomBlock(-8,23,-6,quark:limestone:1,30,quark:limestone_wall,10,quark:limestone,100)
Block(-8,23,-3,VINE:2)
RandomBlock(-8,24,-5,quark:limestone:1,30,quark:limestone_wall,10,quark:limestone,100)
Block(-8,24,-3,VINE:2)
RandomBlock(-8,25,-5,quark:limestone:1,30,quark:limestone_wall,10,quark:limestone,100)
Block(-8,25,-3,VINE:6)
RandomBlock(-8,26,-4,quark:limestone:1,30,quark:limestone_wall,10,quark:limestone,100)
Block(-8,26,-3,VINE:6)
RandomBlock(-8,27,-4,quark:limestone:1,30,quark:limestone_wall,10,quark:limestone,100)
Block(-8,27,-3,VINE:6)
RandomBlock(-8,28,-3,quark:limestone:1,30,quark:limestone_wall,10,quark:limestone,100)
RandomBlock(-7,0,-7,SMOOTH_BRICK:0,40,SMOOTH_BRICK:1,30,SMOOTH_BRICK:2,30,SMOOTH_STAIRS:0,15,SMOOTH_STAIRS:1,15,SMOOTH_STAIRS:2,15,SMOOTH_STAIRS:3,15,STEP:5,15,STEP:13,15,COBBLE_WALL:0,10,COBBLESTONE_STAIRS:0,10,STEP:3,10,COBBLE_WALL:1,20,COBBLESTONE_STAIRS:2,20,COBBLESTONE_STAIRS:3,20,MOSSY_COBBLESTONE:0,60,COBBLESTONE_STAIRS:1,20,STEP:11,20,COBBLESTONE:0,100)
RandomBlock(-7,0,-6,SMOOTH_BRICK:0,40,SMOOTH_BRICK:1,30,SMOOTH_BRICK:2,30,SMOOTH_STAIRS:0,15,SMOOTH_STAIRS:1,15,SMOOTH_STAIRS:2,15,SMOOTH_STAIRS:3,15,STEP:5,15,STEP:13,15,COBBLE_WALL:0,10,COBBLESTONE_STAIRS:0,10,STEP:3,10,COBBLE_WALL:1,20,COBBLESTONE_STAIRS:2,20,COBBLESTONE_STAIRS:3,20,MOSSY_COBBLESTONE:0,60,COBBLESTONE_STAIRS:1,20,STEP:11,20,COBBLESTONE:0,100)
RandomBlock(-7,0,-5,SMOOTH_BRICK:0,40,SMOOTH_BRICK:1,30,SMOOTH_BRICK:2,30,SMOOTH_STAIRS:0,15,SMOOTH_STAIRS:1,15,SMOOTH_STAIRS:2,15,SMOOTH_STAIRS:3,15,STEP:5,15,STEP:13,15,COBBLE_WALL:0,10,COBBLESTONE_STAIRS:0,10,STEP:3,10,COBBLE_WALL:1,20,COBBLESTONE_STAIRS:2,20,COBBLESTONE_STAIRS:3,20,MOSSY_COBBLESTONE:0,60,COBBLESTONE_STAIRS:1,20,STEP:11,20,COBBLESTONE:0,100)
RandomBlock(-7,0,-4,SMOOTH_BRICK:0,40,SMOOTH_BRICK:1,30,SMOOTH_BRICK:2,30,SMOOTH_STAIRS:0,15,SMOOTH_STAIRS:1,15,SMOOTH_STAIRS:2,15,SMOOTH_STAIRS:3,15,STEP:5,15,STEP:13,15,COBBLE_WALL:0,10,COBBLESTONE_STAIRS:0,10,STEP:3,10,COBBLE_WALL:1,20,COBBLESTONE_STAIRS:2,20,COBBLESTONE_STAIRS:3,20,MOSSY_COBBLESTONE:0,60,COBBLESTONE_STAIRS:1,20,STEP:11,20,COBBLESTONE:0,100)
RandomBlock(-7,0,-3,SMOOTH_BRICK:0,40,SMOOTH_BRICK:1,30,SMOOTH_BRICK:2,30,SMOOTH_STAIRS:0,15,SMOOTH_STAIRS:1,15,SMOOTH_STAIRS:2,15,SMOOTH_STAIRS:3,15,STEP:5,15,STEP:13,15,COBBLE_WALL:0,10,COBBLESTONE_STAIRS:0,10,STEP:3,10,COBBLE_WALL:1,20,COBBLESTONE_STAIRS:2,20,COBBLESTONE_STAIRS:3,20,MOSSY_COBBLESTONE:0,60,COBBLESTONE_STAIRS:1,20,STEP:11,20,COBBLESTONE:0,100)
RandomBlock(-7,1,-7,SMOOTH_BRICK:0,40,SMOOTH_BRICK:1,30,SMOOTH_BRICK:2,30,SMOOTH_STAIRS:0,15,SMOOTH_STAIRS:1,15,SMOOTH_STAIRS:2,15,SMOOTH_STAIRS:3,15,STEP:5,15,STEP:13,15,COBBLE_WALL:0,10,COBBLESTONE_STAIRS:0,10,STEP:3,10,COBBLE_WALL:1,20,COBBLESTONE_STAIRS:2,20,COBBLESTONE_STAIRS:3,20,MOSSY_COBBLESTONE:0,60,COBBLESTONE_STAIRS:1,20,STEP:11,20,COBBLESTONE:0,100)
RandomBlock(-7,1,-6,SMOOTH_BRICK:0,40,SMOOTH_BRICK:1,30,SMOOTH_BRICK:2,30,SMOOTH_STAIRS:0,15,SMOOTH_STAIRS:1,15,SMOOTH_STAIRS:2,15,SMOOTH_STAIRS:3,15,STEP:5,15,STEP:13,15,COBBLE_WALL:0,10,COBBLESTONE_STAIRS:0,10,STEP:3,10,COBBLE_WALL:1,20,COBBLESTONE_STAIRS:2,20,COBBLESTONE_STAIRS:3,20,MOSSY_COBBLESTONE:0,60,COBBLESTONE_STAIRS:1,20,STEP:11,20,COBBLESTONE:0,100)
RandomBlock(-7,1,-5,SMOOTH_BRICK:0,40,SMOOTH_BRICK:1,30,SMOOTH_BRICK:2,30,SMOOTH_STAIRS:0,15,SMOOTH_STAIRS:1,15,SMOOTH_STAIRS:2,15,SMOOTH_STAIRS:3,15,STEP:5,15,STEP:13,15,COBBLE_WALL:0,10,COBBLESTONE_STAIRS:0,10,STEP:3,10,COBBLE_WALL:1,20,COBBLESTONE_STAIRS:2,20,COBBLESTONE_STAIRS:3,20,MOSSY_COBBLESTONE:0,60,COBBLESTONE_STAIRS:1,20,STEP:11,20,COBBLESTONE:0,100)
RandomBlock(-7,1,-4,SMOOTH_BRICK:0,40,SMOOTH_BRICK:1,30,SMOOTH_BRICK:2,30,SMOOTH_STAIRS:0,15,SMOOTH_STAIRS:1,15,SMOOTH_STAIRS:2,15,SMOOTH_STAIRS:3,15,STEP:5,15,STEP:13,15,COBBLE_WALL:0,10,COBBLESTONE_STAIRS:0,10,STEP:3,10,COBBLE_WALL:1,20,COBBLESTONE_STAIRS:2,20,COBBLESTONE_STAIRS:3,20,MOSSY_COBBLESTONE:0,60,COBBLESTONE_STAIRS:1,20,STEP:11,20,COBBLESTONE:0,100)
RandomBlock(-7,1,-3,SMOOTH_BRICK:0,40,SMOOTH_BRICK:1,30,SMOOTH_BRICK:2,30,SMOOTH_STAIRS:0,15,SMOOTH_STAIRS:1,15,SMOOTH_STAIRS:2,15,SMOOTH_STAIRS:3,15,STEP:5,15,STEP:13,15,COBBLE_WALL:0,10,COBBLESTONE_STAIRS:0,10,STEP:3,10,COBBLE_WALL:1,20,COBBLESTONE_STAIRS:2,20,COBBLESTONE_STAIRS:3,20,MOSSY_COBBLESTONE:0,60,COBBLESTONE_STAIRS:1,20,STEP:11,20,COBBLESTONE:0,100)
RandomBlock(-7,2,-7,SMOOTH_BRICK:0,40,SMOOTH_BRICK:1,30,SMOOTH_BRICK:2,30,SMOOTH_STAIRS:0,15,SMOOTH_STAIRS:1,15,SMOOTH_STAIRS:2,15,SMOOTH_STAIRS:3,15,STEP:5,15,STEP:13,15,COBBLE_WALL:0,10,COBBLESTONE_STAIRS:0,10,STEP:3,10,COBBLE_WALL:1,20,COBBLESTONE_STAIRS:2,20,COBBLESTONE_STAIRS:3,20,MOSSY_COBBLESTONE:0,60,COBBLESTONE_STAIRS:1,20,STEP:11,20,COBBLESTONE:0,100)
RandomBlock(-7,2,-6,SMOOTH_BRICK:0,40,SMOOTH_BRICK:1,30,SMOOTH_BRICK:2,30,SMOOTH_STAIRS:0,15,SMOOTH_STAIRS:1,15,SMOOTH_STAIRS:2,15,SMOOTH_STAIRS:3,15,STEP:5,15,STEP:13,15,COBBLE_WALL:0,10,COBBLESTONE_STAIRS:0,10,STEP:3,10,COBBLE_WALL:1,20,COBBLESTONE_STAIRS:2,20,COBBLESTONE_STAIRS:3,20,MOSSY_COBBLESTONE:0,60,COBBLESTONE_STAIRS:1,20,STEP:11,20,COBBLESTONE:0,100)
RandomBlock(-7,2,-5,SMOOTH_BRICK:0,40,SMOOTH_BRICK:1,30,SMOOTH_BRICK:2,30,SMOOTH_STAIRS:0,15,SMOOTH_STAIRS:1,15,SMOOTH_STAIRS:2,15,SMOOTH_STAIRS:3,15,STEP:5,15,STEP:13,15,COBBLE_WALL:0,10,COBBLESTONE_STAIRS:0,10,STEP:3,10,COBBLE_WALL:1,20,COBBLESTONE_STAIRS:2,20,COBBLESTONE_STAIRS:3,20,MOSSY_COBBLESTONE:0,60,COBBLESTONE_STAIRS:1,20,STEP:11,20,COBBLESTONE:0,100)
RandomBlock(-7,2,-4,SMOOTH_BRICK:0,40,SMOOTH_BRICK:1,30,SMOOTH_BRICK:2,30,SMOOTH_STAIRS:0,15,SMOOTH_STAIRS:1,15,SMOOTH_STAIRS:2,15,SMOOTH_STAIRS:3,15,STEP:5,15,STEP:13,15,COBBLE_WALL:0,10,COBBLESTONE_STAIRS:0,10,STEP:3,10,COBBLE_WALL:1,20,COBBLESTONE_STAIRS:2,20,COBBLESTONE_STAIRS:3,20,MOSSY_COBBLESTONE:0,60,COBBLESTONE_STAIRS:1,20,STEP:11,20,COBBLESTONE:0,100)
RandomBlock(-7,2,-3,SMOOTH_BRICK:0,40,SMOOTH_BRICK:1,30,SMOOTH_BRICK:2,30,SMOOTH_STAIRS:0,15,SMOOTH_STAIRS:1,15,SMOOTH_STAIRS:2,15,SMOOTH_STAIRS:3,15,STEP:5,15,STEP:13,15,COBBLE_WALL:0,10,COBBLESTONE_STAIRS:0,10,STEP:3,10,COBBLE_WALL:1,20,COBBLESTONE_STAIRS:2,20,COBBLESTONE_STAIRS:3,20,MOSSY_COBBLESTONE:0,60,COBBLESTONE_STAIRS:1,20,STEP:11,20,COBBLESTONE:0,100)
RandomBlock(-7,3,-7,SMOOTH_BRICK:0,40,SMOOTH_BRICK:1,30,SMOOTH_BRICK:2,30,SMOOTH_STAIRS:0,15,SMOOTH_STAIRS:1,15,SMOOTH_STAIRS:2,15,SMOOTH_STAIRS:3,15,STEP:5,15,STEP:13,15,COBBLE_WALL:0,10,COBBLESTONE_STAIRS:0,10,STEP:3,10,COBBLE_WALL:1,20,COBBLESTONE_STAIRS:2,20,COBBLESTONE_STAIRS:3,20,MOSSY_COBBLESTONE:0,60,COBBLESTONE_STAIRS:1,20,STEP:11,20,COBBLESTONE:0,100)
RandomBlock(-7,3,-6,SMOOTH_BRICK:0,40,SMOOTH_BRICK:1,30,SMOOTH_BRICK:2,30,SMOOTH_STAIRS:0,15,SMOOTH_STAIRS:1,15,SMOOTH_STAIRS:2,15,SMOOTH_STAIRS:3,15,STEP:5,15,STEP:13,15,COBBLE_WALL:0,10,COBBLESTONE_STAIRS:0,10,STEP:3,10,COBBLE_WALL:1,20,COBBLESTONE_STAIRS:2,20,COBBLESTONE_STAIRS:3,20,MOSSY_COBBLESTONE:0,60,COBBLESTONE_STAIRS:1,20,STEP:11,20,COBBLESTONE:0,100)
RandomBlock(-7,3,-5,SMOOTH_BRICK:0,40,SMOOTH_BRICK:1,30,SMOOTH_BRICK:2,30,SMOOTH_STAIRS:0,15,SMOOTH_STAIRS:1,15,SMOOTH_STAIRS:2,15,SMOOTH_STAIRS:3,15,STEP:5,15,STEP:13,15,COBBLE_WALL:0,10,COBBLESTONE_STAIRS:0,10,STEP:3,10,COBBLE_WALL:1,20,COBBLESTONE_STAIRS:2,20,COBBLESTONE_STAIRS:3,20,MOSSY_COBBLESTONE:0,60,COBBLESTONE_STAIRS:1,20,STEP:11,20,COBBLESTONE:0,100)
RandomBlock(-7,3,-4,SMOOTH_BRICK:0,40,SMOOTH_BRICK:1,30,SMOOTH_BRICK:2,30,SMOOTH_STAIRS:0,15,SMOOTH_STAIRS:1,15,SMOOTH_STAIRS:2,15,SMOOTH_STAIRS:3,15,STEP:5,15,STEP:13,15,COBBLE_WALL:0,10,COBBLESTONE_STAIRS:0,10,STEP:3,10,COBBLE_WALL:1,20,COBBLESTONE_STAIRS:2,20,COBBLESTONE_STAIRS:3,20,MOSSY_COBBLESTONE:0,60,COBBLESTONE_STAIRS:1,20,STEP:11,20,COBBLESTONE:0,100)
RandomBlock(-7,3,-3,SMOOTH_BRICK:0,40,SMOOTH_BRICK:1,30,SMOOTH_BRICK:2,30,SMOOTH_STAIRS:0,15,SMOOTH_STAIRS:1,15,SMOOTH_STAIRS:2,15,SMOOTH_STAIRS:3,15,STEP:5,15,STEP:13,15,COBBLE_WALL:0,10,COBBLESTONE_STAIRS:0,10,STEP:3,10,COBBLE_WALL:1,20,COBBLESTONE_STAIRS:2,20,COBBLESTONE_STAIRS:3,20,MOSSY_COBBLESTONE:0,60,COBBLESTONE_STAIRS:1,20,STEP:11,20,COBBLESTONE:0,100)
RandomBlock(-7,4,-7,SMOOTH_BRICK:0,40,SMOOTH_BRICK:1,30,SMOOTH_BRICK:2,30,SMOOTH_STAIRS:0,15,SMOOTH_STAIRS:1,15,SMOOTH_STAIRS:2,15,SMOOTH_STAIRS:3,15,STEP:5,15,STEP:13,15,COBBLE_WALL:0,10,COBBLESTONE_STAIRS:0,10,STEP:3,10,COBBLE_WALL:1,20,COBBLESTONE_STAIRS:2,20,COBBLESTONE_STAIRS:3,20,MOSSY_COBBLESTONE:0,60,COBBLESTONE_STAIRS:1,20,STEP:11,20,COBBLESTONE:0,100)
RandomBlock(-7,4,-6,SMOOTH_BRICK:0,40,SMOOTH_BRICK:1,30,SMOOTH_BRICK:2,30,SMOOTH_STAIRS:0,15,SMOOTH_STAIRS:1,15,SMOOTH_STAIRS:2,15,SMOOTH_STAIRS:3,15,STEP:5,15,STEP:13,15,COBBLE_WALL:0,10,COBBLESTONE_STAIRS:0,10,STEP:3,10,COBBLE_WALL:1,20,COBBLESTONE_STAIRS:2,20,COBBLESTONE_STAIRS:3,20,MOSSY_COBBLESTONE:0,60,COBBLESTONE_STAIRS:1,20,STEP:11,20,COBBLESTONE:0,100)
RandomBlock(-7,4,-5,SMOOTH_BRICK:0,40,SMOOTH_BRICK:1,30,SMOOTH_BRICK:2,30,SMOOTH_STAIRS:0,15,SMOOTH_STAIRS:1,15,SMOOTH_STAIRS:2,15,SMOOTH_STAIRS:3,15,STEP:5,15,STEP:13,15,COBBLE_WALL:0,10,COBBLESTONE_STAIRS:0,10,STEP:3,10,COBBLE_WALL:1,20,COBBLESTONE_STAIRS:2,20,COBBLESTONE_STAIRS:3,20,MOSSY_COBBLESTONE:0,60,COBBLESTONE_STAIRS:1,20,STEP:11,20,COBBLESTONE:0,100)
RandomBlock(-7,4,-4,SMOOTH_BRICK:0,40,SMOOTH_BRICK:1,30,SMOOTH_BRICK:2,30,SMOOTH_STAIRS:0,15,SMOOTH_STAIRS:1,15,SMOOTH_STAIRS:2,15,SMOOTH_STAIRS:3,15,STEP:5,15,STEP:13,15,COBBLE_WALL:0,10,COBBLESTONE_STAIRS:0,10,STEP:3,10,COBBLE_WALL:1,20,COBBLESTONE_STAIRS:2,20,COBBLESTONE_STAIRS:3,20,MOSSY_COBBLESTONE:0,60,COBBLESTONE_STAIRS:1,20,STEP:11,20,COBBLESTONE:0,100)
RandomBlock(-7,4,-3,SMOOTH_BRICK:0,40,SMOOTH_BRICK:1,30,SMOOTH_BRICK:2,30,SMOOTH_STAIRS:0,15,SMOOTH_STAIRS:1,15,SMOOTH_STAIRS:2,15,SMOOTH_STAIRS:3,15,STEP:5,15,STEP:13,15,COBBLE_WALL:0,10,COBBLESTONE_STAIRS:0,10,STEP:3,10,COBBLE_WALL:1,20,COBBLESTONE_STAIRS:2,20,COBBLESTONE_STAIRS:3,20,MOSSY_COBBLESTONE:0,60,COBBLESTONE_STAIRS:1,20,STEP:11,20,COBBLESTONE:0,100)
RandomBlock(-7,5,-7,SMOOTH_BRICK:0,40,SMOOTH_BRICK:1,30,SMOOTH_BRICK:2,30,SMOOTH_STAIRS:0,15,SMOOTH_STAIRS:1,15,SMOOTH_STAIRS:2,15,SMOOTH_STAIRS:3,15,STEP:5,15,STEP:13,15,COBBLE_WALL:0,10,COBBLESTONE_STAIRS:0,10,STEP:3,10,COBBLE_WALL:1,20,COBBLESTONE_STAIRS:2,20,COBBLESTONE_STAIRS:3,20,MOSSY_COBBLESTONE:0,60,COBBLESTONE_STAIRS:1,20,STEP:11,20,COBBLESTONE:0,100)
RandomBlock(-7,5,-6,SMOOTH_BRICK:0,40,SMOOTH_BRICK:1,30,SMOOTH_BRICK:2,30,SMOOTH_STAIRS:0,15,SMOOTH_STAIRS:1,15,SMOOTH_STAIRS:2,15,SMOOTH_STAIRS:3,15,STEP:5,15,STEP:13,15,COBBLE_WALL:0,10,COBBLESTONE_STAIRS:0,10,STEP:3,10,COBBLE_WALL:1,20,COBBLESTONE_STAIRS:2,20,COBBLESTONE_STAIRS:3,20,MOSSY_COBBLESTONE:0,60,COBBLESTONE_STAIRS:1,20,STEP:11,20,COBBLESTONE:0,100)
RandomBlock(-7,5,-5,SMOOTH_BRICK:0,40,SMOOTH_BRICK:1,30,SMOOTH_BRICK:2,30,SMOOTH_STAIRS:0,15,SMOOTH_STAIRS:1,15,SMOOTH_STAIRS:2,15,SMOOTH_STAIRS:3,15,STEP:5,15,STEP:13,15,COBBLE_WALL:0,10,COBBLESTONE_STAIRS:0,10,STEP:3,10,COBBLE_WALL:1,20,COBBLESTONE_STAIRS:2,20,COBBLESTONE_STAIRS:3,20,MOSSY_COBBLESTONE:0,60,COBBLESTONE_STAIRS:1,20,STEP:11,20,COBBLESTONE:0,100)
RandomBlock(-7,5,-4,SMOOTH_BRICK:0,40,SMOOTH_BRICK:1,30,SMOOTH_BRICK:2,30,SMOOTH_STAIRS:0,15,SMOOTH_STAIRS:1,15,SMOOTH_STAIRS:2,15,SMOOTH_STAIRS:3,15,STEP:5,15,STEP:13,15,COBBLE_WALL:0,10,COBBLESTONE_STAIRS:0,10,STEP:3,10,COBBLE_WALL:1,20,COBBLESTONE_STAIRS:2,20,COBBLESTONE_STAIRS:3,20,MOSSY_COBBLESTONE:0,60,COBBLESTONE_STAIRS:1,20,STEP:11,20,COBBLESTONE:0,100)
RandomBlock(-7,5,-3,quark:limestone:1,30,quark:limestone_wall,10,quark:limestone,100)
RandomBlock(-7,6,-7,SMOOTH_BRICK:0,40,SMOOTH_BRICK:1,30,SMOOTH_BRICK:2,30,SMOOTH_STAIRS:0,15,SMOOTH_STAIRS:1,15,SMOOTH_STAIRS:2,15,SMOOTH_STAIRS:3,15,STEP:5,15,STEP:13,15,COBBLE_WALL:0,10,COBBLESTONE_STAIRS:0,10,STEP:3,10,COBBLE_WALL:1,20,COBBLESTONE_STAIRS:2,20,COBBLESTONE_STAIRS:3,20,MOSSY_COBBLESTONE:0,60,COBBLESTONE_STAIRS:1,20,STEP:11,20,COBBLESTONE:0,100)
RandomBlock(-7,6,-6,SMOOTH_BRICK:0,40,SMOOTH_BRICK:1,30,SMOOTH_BRICK:2,30,SMOOTH_STAIRS:0,15,SMOOTH_STAIRS:1,15,SMOOTH_STAIRS:2,15,SMOOTH_STAIRS:3,15,STEP:5,15,STEP:13,15,COBBLE_WALL:0,10,COBBLESTONE_STAIRS:0,10,STEP:3,10,COBBLE_WALL:1,20,COBBLESTONE_STAIRS:2,20,COBBLESTONE_STAIRS:3,20,MOSSY_COBBLESTONE:0,60,COBBLESTONE_STAIRS:1,20,STEP:11,20,COBBLESTONE:0,100)
RandomBlock(-7,6,-5,SMOOTH_BRICK:0,40,SMOOTH_BRICK:1,30,SMOOTH_BRICK:2,30,SMOOTH_STAIRS:0,15,SMOOTH_STAIRS:1,15,SMOOTH_STAIRS:2,15,SMOOTH_STAIRS:3,15,STEP:5,15,STEP:13,15,COBBLE_WALL:0,10,COBBLESTONE_STAIRS:0,10,STEP:3,10,COBBLE_WALL:1,20,COBBLESTONE_STAIRS:2,20,COBBLESTONE_STAIRS:3,20,MOSSY_COBBLESTONE:0,60,COBBLESTONE_STAIRS:1,20,STEP:11,20,COBBLESTONE:0,100)
RandomBlock(-7,6,-4,SMOOTH_BRICK:0,40,SMOOTH_BRICK:1,30,SMOOTH_BRICK:2,30,SMOOTH_STAIRS:0,15,SMOOTH_STAIRS:1,15,SMOOTH_STAIRS:2,15,SMOOTH_STAIRS:3,15,STEP:5,15,STEP:13,15,COBBLE_WALL:0,10,COBBLESTONE_STAIRS:0,10,STEP:3,10,COBBLE_WALL:1,20,COBBLESTONE_STAIRS:2,20,COBBLESTONE_STAIRS:3,20,MOSSY_COBBLESTONE:0,60,COBBLESTONE_STAIRS:1,20,STEP:11,20,COBBLESTONE:0,100)
RandomBlock(-7,6,-3,quark:limestone:1,30,quark:limestone_wall,10,quark:limestone,100)
RandomBlock(-7,7,-7,SMOOTH_BRICK:0,40,SMOOTH_BRICK:1,30,SMOOTH_BRICK:2,30,SMOOTH_STAIRS:0,15,SMOOTH_STAIRS:1,15,SMOOTH_STAIRS:2,15,SMOOTH_STAIRS:3,15,STEP:5,15,STEP:13,15,COBBLE_WALL:0,10,COBBLESTONE_STAIRS:0,10,STEP:3,10,COBBLE_WALL:1,20,COBBLESTONE_STAIRS:2,20,COBBLESTONE_STAIRS:3,20,MOSSY_COBBLESTONE:0,60,COBBLESTONE_STAIRS:1,20,STEP:11,20,COBBLESTONE:0,100)
RandomBlock(-7,7,-6,SMOOTH_BRICK:0,40,SMOOTH_BRICK:1,30,SMOOTH_BRICK:2,30,SMOOTH_STAIRS:0,15,SMOOTH_STAIRS:1,15,SMOOTH_STAIRS:2,15,SMOOTH_STAIRS:3,15,STEP:5,15,STEP:13,15,COBBLE_WALL:0,10,COBBLESTONE_STAIRS:0,10,STEP:3,10,COBBLE_WALL:1,20,COBBLESTONE_STAIRS:2,20,COBBLESTONE_STAIRS:3,20,MOSSY_COBBLESTONE:0,60,COBBLESTONE_STAIRS:1,20,STEP:11,20,COBBLESTONE:0,100)
RandomBlock(-7,7,-5,SMOOTH_BRICK:0,40,SMOOTH_BRICK:1,30,SMOOTH_BRICK:2,30,SMOOTH_STAIRS:0,15,SMOOTH_STAIRS:1,15,SMOOTH_STAIRS:2,15,SMOOTH_STAIRS:3,15,STEP:5,15,STEP:13,15,COBBLE_WALL:0,10,COBBLESTONE_STAIRS:0,10,STEP:3,10,COBBLE_WALL:1,20,COBBLESTONE_STAIRS:2,20,COBBLESTONE_STAIRS:3,20,MOSSY_COBBLESTONE:0,60,COBBLESTONE_STAIRS:1,20,STEP:11,20,COBBLESTONE:0,100)
RandomBlock(-7,7,-4,SMOOTH_BRICK:0,40,SMOOTH_BRICK:1,30,SMOOTH_BRICK:2,30,SMOOTH_STAIRS:0,15,SMOOTH_STAIRS:1,15,SMOOTH_STAIRS:2,15,SMOOTH_STAIRS:3,15,STEP:5,15,STEP:13,15,COBBLE_WALL:0,10,COBBLESTONE_STAIRS:0,10,STEP:3,10,COBBLE_WALL:1,20,COBBLESTONE_STAIRS:2,20,COBBLESTONE_STAIRS:3,20,MOSSY_COBBLESTONE:0,60,COBBLESTONE_STAIRS:1,20,STEP:11,20,COBBLESTONE:0,100)
RandomBlock(-7,7,-3,quark:limestone:1,30,quark:limestone_wall,10,quark:limestone,100)
RandomBlock(-7,8,-4,RUSTIC:IRON_LATTICE:0,30,RUSTIC:IRON_LATTICE:1,100)
RandomBlock(-7,9,-4,RUSTIC:IRON_LATTICE:0,30,RUSTIC:IRON_LATTICE:1,100)
RandomBlock(-7,10,-4,RUSTIC:IRON_LATTICE:0,30,RUSTIC:IRON_LATTICE:1,100)
RandomBlock(-7,10,-3,quark:limestone:1,30,quark:limestone_wall,10,quark:limestone,100)
Block(-7,11,-5,VINE:1)
RandomBlock(-7,11,-3,quark:limestone:1,30,quark:limestone_wall,10,quark:limestone,100)
Block(-7,12,-5,VINE:1)
RandomBlock(-7,12,-4,quark:limestone:1,30,quark:limestone_wall,10,quark:limestone,100)
Block(-7,13,-5,VINE:1)
RandomBlock(-7,13,-4,quark:limestone:1,30,quark:limestone_wall,10,quark:limestone,100)
Block(-7,14,-6,VINE:1)
RandomBlock(-7,14,-5,quark:limestone:1,30,quark:limestone_wall,10,quark:limestone,100)
Block(-7,15,-6,VINE:1)
RandomBlock(-7,15,-5,quark:limestone:1,30,quark:limestone_wall,10,quark:limestone,100)
RandomBlock(-7,16,-6,quark:limestone:1,30,quark:limestone_wall,10,quark:limestone,100)
RandomBlock(-7,17,-6,quark:limestone:1,30,quark:limestone_wall,10,quark:limestone,100)
RandomBlock(-7,18,-6,quark:limestone:1,30,quark:limestone_wall,10,quark:limestone,100)
RandomBlock(-7,19,-6,quark:limestone:1,30,quark:limestone_wall,10,quark:limestone,100)
RandomBlock(-7,20,-7,quark:limestone:1,30,quark:limestone_wall,10,quark:limestone,100)
RandomBlock(-7,21,-7,quark:limestone:1,30,quark:limestone_wall,10,quark:limestone,100)
RandomBlock(-7,22,-7,quark:limestone:1,30,quark:limestone_wall,10,quark:limestone,100)
RandomBlock(-7,23,-7,quark:limestone:1,30,quark:limestone_wall,10,quark:limestone,100)
RandomBlock(-7,24,-6,quark:limestone:1,30,quark:limestone_wall,10,quark:limestone,100)
Block(-7,24,-3,VINE:2)
RandomBlock(-7,25,-6,quark:limestone:1,30,quark:limestone_wall,10,quark:limestone,100)
Block(-7,25,-3,VINE:2)
RandomBlock(-7,26,-5,quark:limestone:1,30,quark:limestone_wall,10,quark:limestone,100)
Block(-7,26,-3,VINE:2)
RandomBlock(-7,27,-5,quark:limestone:1,30,quark:limestone_wall,10,quark:limestone,100)
Block(-7,27,-3,VINE:2)
RandomBlock(-7,28,-4,quark:limestone:1,30,quark:limestone_wall,10,quark:limestone,100)
Block(-7,28,-3,VINE:2)
RandomBlock(-6,0,-7,SMOOTH_BRICK:0,40,SMOOTH_BRICK:1,30,SMOOTH_BRICK:2,30,SMOOTH_STAIRS:0,15,SMOOTH_STAIRS:1,15,SMOOTH_STAIRS:2,15,SMOOTH_STAIRS:3,15,STEP:5,15,STEP:13,15,COBBLE_WALL:0,10,COBBLESTONE_STAIRS:0,10,STEP:3,10,COBBLE_WALL:1,20,COBBLESTONE_STAIRS:2,20,COBBLESTONE_STAIRS:3,20,MOSSY_COBBLESTONE:0,60,COBBLESTONE_STAIRS:1,20,STEP:11,20,COBBLESTONE:0,100)
RandomBlock(-6,0,-6,SMOOTH_BRICK:0,40,SMOOTH_BRICK:1,30,SMOOTH_BRICK:2,30,SMOOTH_STAIRS:0,15,SMOOTH_STAIRS:1,15,SMOOTH_STAIRS:2,15,SMOOTH_STAIRS:3,15,STEP:5,15,STEP:13,15,COBBLE_WALL:0,10,COBBLESTONE_STAIRS:0,10,STEP:3,10,COBBLE_WALL:1,20,COBBLESTONE_STAIRS:2,20,COBBLESTONE_STAIRS:3,20,MOSSY_COBBLESTONE:0,60,COBBLESTONE_STAIRS:1,20,STEP:11,20,COBBLESTONE:0,100)
RandomBlock(-6,0,-5,SMOOTH_BRICK:0,40,SMOOTH_BRICK:1,30,SMOOTH_BRICK:2,30,SMOOTH_STAIRS:0,15,SMOOTH_STAIRS:1,15,SMOOTH_STAIRS:2,15,SMOOTH_STAIRS:3,15,STEP:5,15,STEP:13,15,COBBLE_WALL:0,10,COBBLESTONE_STAIRS:0,10,STEP:3,10,COBBLE_WALL:1,20,COBBLESTONE_STAIRS:2,20,COBBLESTONE_STAIRS:3,20,MOSSY_COBBLESTONE:0,60,COBBLESTONE_STAIRS:1,20,STEP:11,20,COBBLESTONE:0,100)
RandomBlock(-6,0,-4,SMOOTH_BRICK:0,40,SMOOTH_BRICK:1,30,SMOOTH_BRICK:2,30,SMOOTH_STAIRS:0,15,SMOOTH_STAIRS:1,15,SMOOTH_STAIRS:2,15,SMOOTH_STAIRS:3,15,STEP:5,15,STEP:13,15,COBBLE_WALL:0,10,COBBLESTONE_STAIRS:0,10,STEP:3,10,COBBLE_WALL:1,20,COBBLESTONE_STAIRS:2,20,COBBLESTONE_STAIRS:3,20,MOSSY_COBBLESTONE:0,60,COBBLESTONE_STAIRS:1,20,STEP:11,20,COBBLESTONE:0,100)
RandomBlock(-6,0,-3,SMOOTH_BRICK:0,40,SMOOTH_BRICK:1,30,SMOOTH_BRICK:2,30,SMOOTH_STAIRS:0,15,SMOOTH_STAIRS:1,15,SMOOTH_STAIRS:2,15,SMOOTH_STAIRS:3,15,STEP:5,15,STEP:13,15,COBBLE_WALL:0,10,COBBLESTONE_STAIRS:0,10,STEP:3,10,COBBLE_WALL:1,20,COBBLESTONE_STAIRS:2,20,COBBLESTONE_STAIRS:3,20,MOSSY_COBBLESTONE:0,60,COBBLESTONE_STAIRS:1,20,STEP:11,20,COBBLESTONE:0,100)
RandomBlock(-6,1,-7,SMOOTH_BRICK:0,40,SMOOTH_BRICK:1,30,SMOOTH_BRICK:2,30,SMOOTH_STAIRS:0,15,SMOOTH_STAIRS:1,15,SMOOTH_STAIRS:2,15,SMOOTH_STAIRS:3,15,STEP:5,15,STEP:13,15,COBBLE_WALL:0,10,COBBLESTONE_STAIRS:0,10,STEP:3,10,COBBLE_WALL:1,20,COBBLESTONE_STAIRS:2,20,COBBLESTONE_STAIRS:3,20,MOSSY_COBBLESTONE:0,60,COBBLESTONE_STAIRS:1,20,STEP:11,20,COBBLESTONE:0,100)
RandomBlock(-6,1,-6,SMOOTH_BRICK:0,40,SMOOTH_BRICK:1,30,SMOOTH_BRICK:2,30,SMOOTH_STAIRS:0,15,SMOOTH_STAIRS:1,15,SMOOTH_STAIRS:2,15,SMOOTH_STAIRS:3,15,STEP:5,15,STEP:13,15,COBBLE_WALL:0,10,COBBLESTONE_STAIRS:0,10,STEP:3,10,COBBLE_WALL:1,20,COBBLESTONE_STAIRS:2,20,COBBLESTONE_STAIRS:3,20,MOSSY_COBBLESTONE:0,60,COBBLESTONE_STAIRS:1,20,STEP:11,20,COBBLESTONE:0,100)
RandomBlock(-6,1,-5,SMOOTH_BRICK:0,40,SMOOTH_BRICK:1,30,SMOOTH_BRICK:2,30,SMOOTH_STAIRS:0,15,SMOOTH_STAIRS:1,15,SMOOTH_STAIRS:2,15,SMOOTH_STAIRS:3,15,STEP:5,15,STEP:13,15,COBBLE_WALL:0,10,COBBLESTONE_STAIRS:0,10,STEP:3,10,COBBLE_WALL:1,20,COBBLESTONE_STAIRS:2,20,COBBLESTONE_STAIRS:3,20,MOSSY_COBBLESTONE:0,60,COBBLESTONE_STAIRS:1,20,STEP:11,20,COBBLESTONE:0,100)
RandomBlock(-6,1,-4,SMOOTH_BRICK:0,40,SMOOTH_BRICK:1,30,SMOOTH_BRICK:2,30,SMOOTH_STAIRS:0,15,SMOOTH_STAIRS:1,15,SMOOTH_STAIRS:2,15,SMOOTH_STAIRS:3,15,STEP:5,15,STEP:13,15,COBBLE_WALL:0,10,COBBLESTONE_STAIRS:0,10,STEP:3,10,COBBLE_WALL:1,20,COBBLESTONE_STAIRS:2,20,COBBLESTONE_STAIRS:3,20,MOSSY_COBBLESTONE:0,60,COBBLESTONE_STAIRS:1,20,STEP:11,20,COBBLESTONE:0,100)
RandomBlock(-6,1,-3,SMOOTH_BRICK:0,40,SMOOTH_BRICK:1,30,SMOOTH_BRICK:2,30,SMOOTH_STAIRS:0,15,SMOOTH_STAIRS:1,15,SMOOTH_STAIRS:2,15,SMOOTH_STAIRS:3,15,STEP:5,15,STEP:13,15,COBBLE_WALL:0,10,COBBLESTONE_STAIRS:0,10,STEP:3,10,COBBLE_WALL:1,20,COBBLESTONE_STAIRS:2,20,COBBLESTONE_STAIRS:3,20,MOSSY_COBBLESTONE:0,60,COBBLESTONE_STAIRS:1,20,STEP:11,20,COBBLESTONE:0,100)
RandomBlock(-6,2,-7,SMOOTH_BRICK:0,40,SMOOTH_BRICK:1,30,SMOOTH_BRICK:2,30,SMOOTH_STAIRS:0,15,SMOOTH_STAIRS:1,15,SMOOTH_STAIRS:2,15,SMOOTH_STAIRS:3,15,STEP:5,15,STEP:13,15,COBBLE_WALL:0,10,COBBLESTONE_STAIRS:0,10,STEP:3,10,COBBLE_WALL:1,20,COBBLESTONE_STAIRS:2,20,COBBLESTONE_STAIRS:3,20,MOSSY_COBBLESTONE:0,60,COBBLESTONE_STAIRS:1,20,STEP:11,20,COBBLESTONE:0,100)
RandomBlock(-6,2,-6,SMOOTH_BRICK:0,40,SMOOTH_BRICK:1,30,SMOOTH_BRICK:2,30,SMOOTH_STAIRS:0,15,SMOOTH_STAIRS:1,15,SMOOTH_STAIRS:2,15,SMOOTH_STAIRS:3,15,STEP:5,15,STEP:13,15,COBBLE_WALL:0,10,COBBLESTONE_STAIRS:0,10,STEP:3,10,COBBLE_WALL:1,20,COBBLESTONE_STAIRS:2,20,COBBLESTONE_STAIRS:3,20,MOSSY_COBBLESTONE:0,60,COBBLESTONE_STAIRS:1,20,STEP:11,20,COBBLESTONE:0,100)
RandomBlock(-6,2,-5,SMOOTH_BRICK:0,40,SMOOTH_BRICK:1,30,SMOOTH_BRICK:2,30,SMOOTH_STAIRS:0,15,SMOOTH_STAIRS:1,15,SMOOTH_STAIRS:2,15,SMOOTH_STAIRS:3,15,STEP:5,15,STEP:13,15,COBBLE_WALL:0,10,COBBLESTONE_STAIRS:0,10,STEP:3,10,COBBLE_WALL:1,20,COBBLESTONE_STAIRS:2,20,COBBLESTONE_STAIRS:3,20,MOSSY_COBBLESTONE:0,60,COBBLESTONE_STAIRS:1,20,STEP:11,20,COBBLESTONE:0,100)
RandomBlock(-6,2,-4,SMOOTH_BRICK:0,40,SMOOTH_BRICK:1,30,SMOOTH_BRICK:2,30,SMOOTH_STAIRS:0,15,SMOOTH_STAIRS:1,15,SMOOTH_STAIRS:2,15,SMOOTH_STAIRS:3,15,STEP:5,15,STEP:13,15,COBBLE_WALL:0,10,COBBLESTONE_STAIRS:0,10,STEP:3,10,COBBLE_WALL:1,20,COBBLESTONE_STAIRS:2,20,COBBLESTONE_STAIRS:3,20,MOSSY_COBBLESTONE:0,60,COBBLESTONE_STAIRS:1,20,STEP:11,20,COBBLESTONE:0,100)
RandomBlock(-6,2,-3,SMOOTH_BRICK:0,40,SMOOTH_BRICK:1,30,SMOOTH_BRICK:2,30,SMOOTH_STAIRS:0,15,SMOOTH_STAIRS:1,15,SMOOTH_STAIRS:2,15,SMOOTH_STAIRS:3,15,STEP:5,15,STEP:13,15,COBBLE_WALL:0,10,COBBLESTONE_STAIRS:0,10,STEP:3,10,COBBLE_WALL:1,20,COBBLESTONE_STAIRS:2,20,COBBLESTONE_STAIRS:3,20,MOSSY_COBBLESTONE:0,60,COBBLESTONE_STAIRS:1,20,STEP:11,20,COBBLESTONE:0,100)
RandomBlock(-6,3,-7,SMOOTH_BRICK:0,40,SMOOTH_BRICK:1,30,SMOOTH_BRICK:2,30,SMOOTH_STAIRS:0,15,SMOOTH_STAIRS:1,15,SMOOTH_STAIRS:2,15,SMOOTH_STAIRS:3,15,STEP:5,15,STEP:13,15,COBBLE_WALL:0,10,COBBLESTONE_STAIRS:0,10,STEP:3,10,COBBLE_WALL:1,20,COBBLESTONE_STAIRS:2,20,COBBLESTONE_STAIRS:3,20,MOSSY_COBBLESTONE:0,60,COBBLESTONE_STAIRS:1,20,STEP:11,20,COBBLESTONE:0,100)
RandomBlock(-6,3,-6,SMOOTH_BRICK:0,40,SMOOTH_BRICK:1,30,SMOOTH_BRICK:2,30,SMOOTH_STAIRS:0,15,SMOOTH_STAIRS:1,15,SMOOTH_STAIRS:2,15,SMOOTH_STAIRS:3,15,STEP:5,15,STEP:13,15,COBBLE_WALL:0,10,COBBLESTONE_STAIRS:0,10,STEP:3,10,COBBLE_WALL:1,20,COBBLESTONE_STAIRS:2,20,COBBLESTONE_STAIRS:3,20,MOSSY_COBBLESTONE:0,60,COBBLESTONE_STAIRS:1,20,STEP:11,20,COBBLESTONE:0,100)
RandomBlock(-6,3,-5,SMOOTH_BRICK:0,40,SMOOTH_BRICK:1,30,SMOOTH_BRICK:2,30,SMOOTH_STAIRS:0,15,SMOOTH_STAIRS:1,15,SMOOTH_STAIRS:2,15,SMOOTH_STAIRS:3,15,STEP:5,15,STEP:13,15,COBBLE_WALL:0,10,COBBLESTONE_STAIRS:0,10,STEP:3,10,COBBLE_WALL:1,20,COBBLESTONE_STAIRS:2,20,COBBLESTONE_STAIRS:3,20,MOSSY_COBBLESTONE:0,60,COBBLESTONE_STAIRS:1,20,STEP:11,20,COBBLESTONE:0,100)
RandomBlock(-6,3,-4,SMOOTH_BRICK:0,40,SMOOTH_BRICK:1,30,SMOOTH_BRICK:2,30,SMOOTH_STAIRS:0,15,SMOOTH_STAIRS:1,15,SMOOTH_STAIRS:2,15,SMOOTH_STAIRS:3,15,STEP:5,15,STEP:13,15,COBBLE_WALL:0,10,COBBLESTONE_STAIRS:0,10,STEP:3,10,COBBLE_WALL:1,20,COBBLESTONE_STAIRS:2,20,COBBLESTONE_STAIRS:3,20,MOSSY_COBBLESTONE:0,60,COBBLESTONE_STAIRS:1,20,STEP:11,20,COBBLESTONE:0,100)
RandomBlock(-6,3,-3,SMOOTH_BRICK:0,40,SMOOTH_BRICK:1,30,SMOOTH_BRICK:2,30,SMOOTH_STAIRS:0,15,SMOOTH_STAIRS:1,15,SMOOTH_STAIRS:2,15,SMOOTH_STAIRS:3,15,STEP:5,15,STEP:13,15,COBBLE_WALL:0,10,COBBLESTONE_STAIRS:0,10,STEP:3,10,COBBLE_WALL:1,20,COBBLESTONE_STAIRS:2,20,COBBLESTONE_STAIRS:3,20,MOSSY_COBBLESTONE:0,60,COBBLESTONE_STAIRS:1,20,STEP:11,20,COBBLESTONE:0,100)
RandomBlock(-6,4,-7,SMOOTH_BRICK:0,40,SMOOTH_BRICK:1,30,SMOOTH_BRICK:2,30,SMOOTH_STAIRS:0,15,SMOOTH_STAIRS:1,15,SMOOTH_STAIRS:2,15,SMOOTH_STAIRS:3,15,STEP:5,15,STEP:13,15,COBBLE_WALL:0,10,COBBLESTONE_STAIRS:0,10,STEP:3,10,COBBLE_WALL:1,20,COBBLESTONE_STAIRS:2,20,COBBLESTONE_STAIRS:3,20,MOSSY_COBBLESTONE:0,60,COBBLESTONE_STAIRS:1,20,STEP:11,20,COBBLESTONE:0,100)
RandomBlock(-6,4,-6,SMOOTH_BRICK:0,40,SMOOTH_BRICK:1,30,SMOOTH_BRICK:2,30,SMOOTH_STAIRS:0,15,SMOOTH_STAIRS:1,15,SMOOTH_STAIRS:2,15,SMOOTH_STAIRS:3,15,STEP:5,15,STEP:13,15,COBBLE_WALL:0,10,COBBLESTONE_STAIRS:0,10,STEP:3,10,COBBLE_WALL:1,20,COBBLESTONE_STAIRS:2,20,COBBLESTONE_STAIRS:3,20,MOSSY_COBBLESTONE:0,60,COBBLESTONE_STAIRS:1,20,STEP:11,20,COBBLESTONE:0,100)
RandomBlock(-6,4,-5,SMOOTH_BRICK:0,40,SMOOTH_BRICK:1,30,SMOOTH_BRICK:2,30,SMOOTH_STAIRS:0,15,SMOOTH_STAIRS:1,15,SMOOTH_STAIRS:2,15,SMOOTH_STAIRS:3,15,STEP:5,15,STEP:13,15,COBBLE_WALL:0,10,COBBLESTONE_STAIRS:0,10,STEP:3,10,COBBLE_WALL:1,20,COBBLESTONE_STAIRS:2,20,COBBLESTONE_STAIRS:3,20,MOSSY_COBBLESTONE:0,60,COBBLESTONE_STAIRS:1,20,STEP:11,20,COBBLESTONE:0,100)
RandomBlock(-6,4,-4,SMOOTH_BRICK:0,40,SMOOTH_BRICK:1,30,SMOOTH_BRICK:2,30,SMOOTH_STAIRS:0,15,SMOOTH_STAIRS:1,15,SMOOTH_STAIRS:2,15,SMOOTH_STAIRS:3,15,STEP:5,15,STEP:13,15,COBBLE_WALL:0,10,COBBLESTONE_STAIRS:0,10,STEP:3,10,COBBLE_WALL:1,20,COBBLESTONE_STAIRS:2,20,COBBLESTONE_STAIRS:3,20,MOSSY_COBBLESTONE:0,60,COBBLESTONE_STAIRS:1,20,STEP:11,20,COBBLESTONE:0,100)
RandomBlock(-6,4,-3,SMOOTH_BRICK:0,40,SMOOTH_BRICK:1,30,SMOOTH_BRICK:2,30,SMOOTH_STAIRS:0,15,SMOOTH_STAIRS:1,15,SMOOTH_STAIRS:2,15,SMOOTH_STAIRS:3,15,STEP:5,15,STEP:13,15,COBBLE_WALL:0,10,COBBLESTONE_STAIRS:0,10,STEP:3,10,COBBLE_WALL:1,20,COBBLESTONE_STAIRS:2,20,COBBLESTONE_STAIRS:3,20,MOSSY_COBBLESTONE:0,60,COBBLESTONE_STAIRS:1,20,STEP:11,20,COBBLESTONE:0,100)
RandomBlock(-6,5,-7,SMOOTH_BRICK:0,40,SMOOTH_BRICK:1,30,SMOOTH_BRICK:2,30,SMOOTH_STAIRS:0,15,SMOOTH_STAIRS:1,15,SMOOTH_STAIRS:2,15,SMOOTH_STAIRS:3,15,STEP:5,15,STEP:13,15,COBBLE_WALL:0,10,COBBLESTONE_STAIRS:0,10,STEP:3,10,COBBLE_WALL:1,20,COBBLESTONE_STAIRS:2,20,COBBLESTONE_STAIRS:3,20,MOSSY_COBBLESTONE:0,60,COBBLESTONE_STAIRS:1,20,STEP:11,20,COBBLESTONE:0,100)
RandomBlock(-6,5,-6,SMOOTH_BRICK:0,40,SMOOTH_BRICK:1,30,SMOOTH_BRICK:2,30,SMOOTH_STAIRS:0,15,SMOOTH_STAIRS:1,15,SMOOTH_STAIRS:2,15,SMOOTH_STAIRS:3,15,STEP:5,15,STEP:13,15,COBBLE_WALL:0,10,COBBLESTONE_STAIRS:0,10,STEP:3,10,COBBLE_WALL:1,20,COBBLESTONE_STAIRS:2,20,COBBLESTONE_STAIRS:3,20,MOSSY_COBBLESTONE:0,60,COBBLESTONE_STAIRS:1,20,STEP:11,20,COBBLESTONE:0,100)
RandomBlock(-6,5,-5,SMOOTH_BRICK:0,40,SMOOTH_BRICK:1,30,SMOOTH_BRICK:2,30,SMOOTH_STAIRS:0,15,SMOOTH_STAIRS:1,15,SMOOTH_STAIRS:2,15,SMOOTH_STAIRS:3,15,STEP:5,15,STEP:13,15,COBBLE_WALL:0,10,COBBLESTONE_STAIRS:0,10,STEP:3,10,COBBLE_WALL:1,20,COBBLESTONE_STAIRS:2,20,COBBLESTONE_STAIRS:3,20,MOSSY_COBBLESTONE:0,60,COBBLESTONE_STAIRS:1,20,STEP:11,20,COBBLESTONE:0,100)
RandomBlock(-6,5,-4,SMOOTH_BRICK:0,40,SMOOTH_BRICK:1,30,SMOOTH_BRICK:2,30,SMOOTH_STAIRS:0,15,SMOOTH_STAIRS:1,15,SMOOTH_STAIRS:2,15,SMOOTH_STAIRS:3,15,STEP:5,15,STEP:13,15,COBBLE_WALL:0,10,COBBLESTONE_STAIRS:0,10,STEP:3,10,COBBLE_WALL:1,20,COBBLESTONE_STAIRS:2,20,COBBLESTONE_STAIRS:3,20,MOSSY_COBBLESTONE:0,60,COBBLESTONE_STAIRS:1,20,STEP:11,20,COBBLESTONE:0,100)
RandomBlock(-6,5,-3,quark:limestone:1,30,quark:limestone_wall,10,quark:limestone,100)
RandomBlock(-6,6,-7,SMOOTH_BRICK:0,40,SMOOTH_BRICK:1,30,SMOOTH_BRICK:2,30,SMOOTH_STAIRS:0,15,SMOOTH_STAIRS:1,15,SMOOTH_STAIRS:2,15,SMOOTH_STAIRS:3,15,STEP:5,15,STEP:13,15,COBBLE_WALL:0,10,COBBLESTONE_STAIRS:0,10,STEP:3,10,COBBLE_WALL:1,20,COBBLESTONE_STAIRS:2,20,COBBLESTONE_STAIRS:3,20,MOSSY_COBBLESTONE:0,60,COBBLESTONE_STAIRS:1,20,STEP:11,20,COBBLESTONE:0,100)
RandomBlock(-6,6,-6,SMOOTH_BRICK:0,40,SMOOTH_BRICK:1,30,SMOOTH_BRICK:2,30,SMOOTH_STAIRS:0,15,SMOOTH_STAIRS:1,15,SMOOTH_STAIRS:2,15,SMOOTH_STAIRS:3,15,STEP:5,15,STEP:13,15,COBBLE_WALL:0,10,COBBLESTONE_STAIRS:0,10,STEP:3,10,COBBLE_WALL:1,20,COBBLESTONE_STAIRS:2,20,COBBLESTONE_STAIRS:3,20,MOSSY_COBBLESTONE:0,60,COBBLESTONE_STAIRS:1,20,STEP:11,20,COBBLESTONE:0,100)
RandomBlock(-6,6,-5,SMOOTH_BRICK:0,40,SMOOTH_BRICK:1,30,SMOOTH_BRICK:2,30,SMOOTH_STAIRS:0,15,SMOOTH_STAIRS:1,15,SMOOTH_STAIRS:2,15,SMOOTH_STAIRS:3,15,STEP:5,15,STEP:13,15,COBBLE_WALL:0,10,COBBLESTONE_STAIRS:0,10,STEP:3,10,COBBLE_WALL:1,20,COBBLESTONE_STAIRS:2,20,COBBLESTONE_STAIRS:3,20,MOSSY_COBBLESTONE:0,60,COBBLESTONE_STAIRS:1,20,STEP:11,20,COBBLESTONE:0,100)
RandomBlock(-6,6,-4,SMOOTH_BRICK:0,40,SMOOTH_BRICK:1,30,SMOOTH_BRICK:2,30,SMOOTH_STAIRS:0,15,SMOOTH_STAIRS:1,15,SMOOTH_STAIRS:2,15,SMOOTH_STAIRS:3,15,STEP:5,15,STEP:13,15,COBBLE_WALL:0,10,COBBLESTONE_STAIRS:0,10,STEP:3,10,COBBLE_WALL:1,20,COBBLESTONE_STAIRS:2,20,COBBLESTONE_STAIRS:3,20,MOSSY_COBBLESTONE:0,60,COBBLESTONE_STAIRS:1,20,STEP:11,20,COBBLESTONE:0,100)
RandomBlock(-6,6,-3,quark:limestone:1,30,quark:limestone_wall,10,quark:limestone,100)
RandomBlock(-6,7,-7,SMOOTH_BRICK:0,40,SMOOTH_BRICK:1,30,SMOOTH_BRICK:2,30,SMOOTH_STAIRS:0,15,SMOOTH_STAIRS:1,15,SMOOTH_STAIRS:2,15,SMOOTH_STAIRS:3,15,STEP:5,15,STEP:13,15,COBBLE_WALL:0,10,COBBLESTONE_STAIRS:0,10,STEP:3,10,COBBLE_WALL:1,20,COBBLESTONE_STAIRS:2,20,COBBLESTONE_STAIRS:3,20,MOSSY_COBBLESTONE:0,60,COBBLESTONE_STAIRS:1,20,STEP:11,20,COBBLESTONE:0,100)
RandomBlock(-6,7,-6,SMOOTH_BRICK:0,40,SMOOTH_BRICK:1,30,SMOOTH_BRICK:2,30,SMOOTH_STAIRS:0,15,SMOOTH_STAIRS:1,15,SMOOTH_STAIRS:2,15,SMOOTH_STAIRS:3,15,STEP:5,15,STEP:13,15,COBBLE_WALL:0,10,COBBLESTONE_STAIRS:0,10,STEP:3,10,COBBLE_WALL:1,20,COBBLESTONE_STAIRS:2,20,COBBLESTONE_STAIRS:3,20,MOSSY_COBBLESTONE:0,60,COBBLESTONE_STAIRS:1,20,STEP:11,20,COBBLESTONE:0,100)
RandomBlock(-6,7,-5,SMOOTH_BRICK:0,40,SMOOTH_BRICK:1,30,SMOOTH_BRICK:2,30,SMOOTH_STAIRS:0,15,SMOOTH_STAIRS:1,15,SMOOTH_STAIRS:2,15,SMOOTH_STAIRS:3,15,STEP:5,15,STEP:13,15,COBBLE_WALL:0,10,COBBLESTONE_STAIRS:0,10,STEP:3,10,COBBLE_WALL:1,20,COBBLESTONE_STAIRS:2,20,COBBLESTONE_STAIRS:3,20,MOSSY_COBBLESTONE:0,60,COBBLESTONE_STAIRS:1,20,STEP:11,20,COBBLESTONE:0,100)
RandomBlock(-6,7,-4,SMOOTH_BRICK:0,40,SMOOTH_BRICK:1,30,SMOOTH_BRICK:2,30,SMOOTH_STAIRS:0,15,SMOOTH_STAIRS:1,15,SMOOTH_STAIRS:2,15,SMOOTH_STAIRS:3,15,STEP:5,15,STEP:13,15,COBBLE_WALL:0,10,COBBLESTONE_STAIRS:0,10,STEP:3,10,COBBLE_WALL:1,20,COBBLESTONE_STAIRS:2,20,COBBLESTONE_STAIRS:3,20,MOSSY_COBBLESTONE:0,60,COBBLESTONE_STAIRS:1,20,STEP:11,20,COBBLESTONE:0,100)
RandomBlock(-6,7,-3,quark:limestone:1,30,quark:limestone_wall,10,quark:limestone,100)
RandomBlock(-6,8,-5,RUSTIC:IRON_LATTICE:0,30,RUSTIC:IRON_LATTICE:1,100)
RandomBlock(-6,8,-4,RUSTIC:IRON_LATTICE:0,30,RUSTIC:IRON_LATTICE:1,100)
Block(-6,8,-3,inspirations:redstone_barrel)
RandomBlock(-6,9,-5,RUSTIC:IRON_LATTICE:0,30,RUSTIC:IRON_LATTICE:1,100)
RandomBlock(-6,9,-4,RUSTIC:IRON_LATTICE:0,30,RUSTIC:IRON_LATTICE:1,100)
Block(-6,9,-3,inspirations:redstone_barrel)
RandomBlock(-6,10,-5,RUSTIC:IRON_LATTICE:0,30,RUSTIC:IRON_LATTICE:1,100)
RandomBlock(-6,10,-4,RUSTIC:IRON_LATTICE:0,30,RUSTIC:IRON_LATTICE:1,100)
RandomBlock(-6,10,-3,quark:limestone:1,30,quark:limestone_wall,10,quark:limestone,100)
Block(-6,11,-5,VINE:9)
RandomBlock(-6,11,-3,quark:limestone:1,30,quark:limestone_wall,10,quark:limestone,100)
Block(-6,12,-5,VINE:9)
RandomBlock(-6,12,-4,quark:limestone:1,30,quark:limestone_wall,10,quark:limestone,100)
Block(-6,13,-5,VINE:1)
RandomBlock(-6,13,-4,quark:limestone:1,30,quark:limestone_wall,10,quark:limestone,100)
RandomBlock(-6,14,-6,quark:limestone:1,30,quark:limestone_wall,10,quark:limestone,100)
RandomBlock(-6,14,-5,quark:limestone:1,30,quark:limestone_wall,10,quark:limestone,100)
RandomBlock(-6,15,-6,quark:limestone:1,30,quark:limestone_wall,10,quark:limestone,100)
RandomBlock(-6,15,-5,quark:limestone:1,30,quark:limestone_wall,10,quark:limestone,100)
RandomBlock(-6,16,-7,quark:limestone:1,30,quark:limestone_wall,10,quark:limestone,100)
RandomBlock(-6,17,-7,quark:limestone:1,30,quark:limestone_wall,10,quark:limestone,100)
RandomBlock(-6,18,-7,quark:limestone:1,30,quark:limestone_wall,10,quark:limestone,100)
RandomBlock(-6,19,-7,quark:limestone:1,30,quark:limestone_wall,10,quark:limestone,100)
Block(-6,22,-6,VINE:4)
Block(-6,23,-6,VINE:4)
RandomBlock(-6,24,-7,quark:limestone:1,30,quark:limestone_wall,10,quark:limestone,100)
Block(-6,24,-6,VINE:4)
RandomBlock(-6,25,-7,quark:limestone:1,30,quark:limestone_wall,10,quark:limestone,100)
RandomBlock(-6,26,-6,quark:limestone:1,30,quark:limestone_wall,10,quark:limestone,100)
Block(-6,26,-4,VINE:6)
RandomBlock(-6,27,-6,quark:limestone:1,30,quark:limestone_wall,10,quark:limestone,100)
Block(-6,27,-4,VINE:6)
RandomBlock(-6,28,-5,quark:limestone:1,30,quark:limestone_wall,10,quark:limestone,100)
Block(-6,28,-4,VINE:6)
RandomBlock(-5,0,-7,SMOOTH_BRICK:0,40,SMOOTH_BRICK:1,30,SMOOTH_BRICK:2,30,SMOOTH_STAIRS:0,15,SMOOTH_STAIRS:1,15,SMOOTH_STAIRS:2,15,SMOOTH_STAIRS:3,15,STEP:5,15,STEP:13,15,COBBLE_WALL:0,10,COBBLESTONE_STAIRS:0,10,STEP:3,10,COBBLE_WALL:1,20,COBBLESTONE_STAIRS:2,20,COBBLESTONE_STAIRS:3,20,MOSSY_COBBLESTONE:0,60,COBBLESTONE_STAIRS:1,20,STEP:11,20,COBBLESTONE:0,100)
RandomBlock(-5,0,-6,SMOOTH_BRICK:0,40,SMOOTH_BRICK:1,30,SMOOTH_BRICK:2,30,SMOOTH_STAIRS:0,15,SMOOTH_STAIRS:1,15,SMOOTH_STAIRS:2,15,SMOOTH_STAIRS:3,15,STEP:5,15,STEP:13,15,COBBLE_WALL:0,10,COBBLESTONE_STAIRS:0,10,STEP:3,10,COBBLE_WALL:1,20,COBBLESTONE_STAIRS:2,20,COBBLESTONE_STAIRS:3,20,MOSSY_COBBLESTONE:0,60,COBBLESTONE_STAIRS:1,20,STEP:11,20,COBBLESTONE:0,100)
RandomBlock(-5,0,-5,SMOOTH_BRICK:0,40,SMOOTH_BRICK:1,30,SMOOTH_BRICK:2,30,SMOOTH_STAIRS:0,15,SMOOTH_STAIRS:1,15,SMOOTH_STAIRS:2,15,SMOOTH_STAIRS:3,15,STEP:5,15,STEP:13,15,COBBLE_WALL:0,10,COBBLESTONE_STAIRS:0,10,STEP:3,10,COBBLE_WALL:1,20,COBBLESTONE_STAIRS:2,20,COBBLESTONE_STAIRS:3,20,MOSSY_COBBLESTONE:0,60,COBBLESTONE_STAIRS:1,20,STEP:11,20,COBBLESTONE:0,100)
RandomBlock(-5,0,-4,SMOOTH_BRICK:0,40,SMOOTH_BRICK:1,30,SMOOTH_BRICK:2,30,SMOOTH_STAIRS:0,15,SMOOTH_STAIRS:1,15,SMOOTH_STAIRS:2,15,SMOOTH_STAIRS:3,15,STEP:5,15,STEP:13,15,COBBLE_WALL:0,10,COBBLESTONE_STAIRS:0,10,STEP:3,10,COBBLE_WALL:1,20,COBBLESTONE_STAIRS:2,20,COBBLESTONE_STAIRS:3,20,MOSSY_COBBLESTONE:0,60,COBBLESTONE_STAIRS:1,20,STEP:11,20,COBBLESTONE:0,100)
RandomBlock(-5,1,-7,SMOOTH_BRICK:0,40,SMOOTH_BRICK:1,30,SMOOTH_BRICK:2,30,SMOOTH_STAIRS:0,15,SMOOTH_STAIRS:1,15,SMOOTH_STAIRS:2,15,SMOOTH_STAIRS:3,15,STEP:5,15,STEP:13,15,COBBLE_WALL:0,10,COBBLESTONE_STAIRS:0,10,STEP:3,10,COBBLE_WALL:1,20,COBBLESTONE_STAIRS:2,20,COBBLESTONE_STAIRS:3,20,MOSSY_COBBLESTONE:0,60,COBBLESTONE_STAIRS:1,20,STEP:11,20,COBBLESTONE:0,100)
RandomBlock(-5,1,-6,SMOOTH_BRICK:0,40,SMOOTH_BRICK:1,30,SMOOTH_BRICK:2,30,SMOOTH_STAIRS:0,15,SMOOTH_STAIRS:1,15,SMOOTH_STAIRS:2,15,SMOOTH_STAIRS:3,15,STEP:5,15,STEP:13,15,COBBLE_WALL:0,10,COBBLESTONE_STAIRS:0,10,STEP:3,10,COBBLE_WALL:1,20,COBBLESTONE_STAIRS:2,20,COBBLESTONE_STAIRS:3,20,MOSSY_COBBLESTONE:0,60,COBBLESTONE_STAIRS:1,20,STEP:11,20,COBBLESTONE:0,100)
RandomBlock(-5,1,-5,SMOOTH_BRICK:0,40,SMOOTH_BRICK:1,30,SMOOTH_BRICK:2,30,SMOOTH_STAIRS:0,15,SMOOTH_STAIRS:1,15,SMOOTH_STAIRS:2,15,SMOOTH_STAIRS:3,15,STEP:5,15,STEP:13,15,COBBLE_WALL:0,10,COBBLESTONE_STAIRS:0,10,STEP:3,10,COBBLE_WALL:1,20,COBBLESTONE_STAIRS:2,20,COBBLESTONE_STAIRS:3,20,MOSSY_COBBLESTONE:0,60,COBBLESTONE_STAIRS:1,20,STEP:11,20,COBBLESTONE:0,100)
RandomBlock(-5,1,-4,SMOOTH_BRICK:0,40,SMOOTH_BRICK:1,30,SMOOTH_BRICK:2,30,SMOOTH_STAIRS:0,15,SMOOTH_STAIRS:1,15,SMOOTH_STAIRS:2,15,SMOOTH_STAIRS:3,15,STEP:5,15,STEP:13,15,COBBLE_WALL:0,10,COBBLESTONE_STAIRS:0,10,STEP:3,10,COBBLE_WALL:1,20,COBBLESTONE_STAIRS:2,20,COBBLESTONE_STAIRS:3,20,MOSSY_COBBLESTONE:0,60,COBBLESTONE_STAIRS:1,20,STEP:11,20,COBBLESTONE:0,100)
RandomBlock(-5,2,-7,SMOOTH_BRICK:0,40,SMOOTH_BRICK:1,30,SMOOTH_BRICK:2,30,SMOOTH_STAIRS:0,15,SMOOTH_STAIRS:1,15,SMOOTH_STAIRS:2,15,SMOOTH_STAIRS:3,15,STEP:5,15,STEP:13,15,COBBLE_WALL:0,10,COBBLESTONE_STAIRS:0,10,STEP:3,10,COBBLE_WALL:1,20,COBBLESTONE_STAIRS:2,20,COBBLESTONE_STAIRS:3,20,MOSSY_COBBLESTONE:0,60,COBBLESTONE_STAIRS:1,20,STEP:11,20,COBBLESTONE:0,100)
RandomBlock(-5,2,-6,SMOOTH_BRICK:0,40,SMOOTH_BRICK:1,30,SMOOTH_BRICK:2,30,SMOOTH_STAIRS:0,15,SMOOTH_STAIRS:1,15,SMOOTH_STAIRS:2,15,SMOOTH_STAIRS:3,15,STEP:5,15,STEP:13,15,COBBLE_WALL:0,10,COBBLESTONE_STAIRS:0,10,STEP:3,10,COBBLE_WALL:1,20,COBBLESTONE_STAIRS:2,20,COBBLESTONE_STAIRS:3,20,MOSSY_COBBLESTONE:0,60,COBBLESTONE_STAIRS:1,20,STEP:11,20,COBBLESTONE:0,100)
RandomBlock(-5,2,-5,SMOOTH_BRICK:0,40,SMOOTH_BRICK:1,30,SMOOTH_BRICK:2,30,SMOOTH_STAIRS:0,15,SMOOTH_STAIRS:1,15,SMOOTH_STAIRS:2,15,SMOOTH_STAIRS:3,15,STEP:5,15,STEP:13,15,COBBLE_WALL:0,10,COBBLESTONE_STAIRS:0,10,STEP:3,10,COBBLE_WALL:1,20,COBBLESTONE_STAIRS:2,20,COBBLESTONE_STAIRS:3,20,MOSSY_COBBLESTONE:0,60,COBBLESTONE_STAIRS:1,20,STEP:11,20,COBBLESTONE:0,100)
RandomBlock(-5,2,-4,SMOOTH_BRICK:0,40,SMOOTH_BRICK:1,30,SMOOTH_BRICK:2,30,SMOOTH_STAIRS:0,15,SMOOTH_STAIRS:1,15,SMOOTH_STAIRS:2,15,SMOOTH_STAIRS:3,15,STEP:5,15,STEP:13,15,COBBLE_WALL:0,10,COBBLESTONE_STAIRS:0,10,STEP:3,10,COBBLE_WALL:1,20,COBBLESTONE_STAIRS:2,20,COBBLESTONE_STAIRS:3,20,MOSSY_COBBLESTONE:0,60,COBBLESTONE_STAIRS:1,20,STEP:11,20,COBBLESTONE:0,100)
RandomBlock(-5,3,-7,SMOOTH_BRICK:0,40,SMOOTH_BRICK:1,30,SMOOTH_BRICK:2,30,SMOOTH_STAIRS:0,15,SMOOTH_STAIRS:1,15,SMOOTH_STAIRS:2,15,SMOOTH_STAIRS:3,15,STEP:5,15,STEP:13,15,COBBLE_WALL:0,10,COBBLESTONE_STAIRS:0,10,STEP:3,10,COBBLE_WALL:1,20,COBBLESTONE_STAIRS:2,20,COBBLESTONE_STAIRS:3,20,MOSSY_COBBLESTONE:0,60,COBBLESTONE_STAIRS:1,20,STEP:11,20,COBBLESTONE:0,100)
RandomBlock(-5,3,-6,SMOOTH_BRICK:0,40,SMOOTH_BRICK:1,30,SMOOTH_BRICK:2,30,SMOOTH_STAIRS:0,15,SMOOTH_STAIRS:1,15,SMOOTH_STAIRS:2,15,SMOOTH_STAIRS:3,15,STEP:5,15,STEP:13,15,COBBLE_WALL:0,10,COBBLESTONE_STAIRS:0,10,STEP:3,10,COBBLE_WALL:1,20,COBBLESTONE_STAIRS:2,20,COBBLESTONE_STAIRS:3,20,MOSSY_COBBLESTONE:0,60,COBBLESTONE_STAIRS:1,20,STEP:11,20,COBBLESTONE:0,100)
RandomBlock(-5,3,-5,SMOOTH_BRICK:0,40,SMOOTH_BRICK:1,30,SMOOTH_BRICK:2,30,SMOOTH_STAIRS:0,15,SMOOTH_STAIRS:1,15,SMOOTH_STAIRS:2,15,SMOOTH_STAIRS:3,15,STEP:5,15,STEP:13,15,COBBLE_WALL:0,10,COBBLESTONE_STAIRS:0,10,STEP:3,10,COBBLE_WALL:1,20,COBBLESTONE_STAIRS:2,20,COBBLESTONE_STAIRS:3,20,MOSSY_COBBLESTONE:0,60,COBBLESTONE_STAIRS:1,20,STEP:11,20,COBBLESTONE:0,100)
RandomBlock(-5,3,-4,SMOOTH_BRICK:0,40,SMOOTH_BRICK:1,30,SMOOTH_BRICK:2,30,SMOOTH_STAIRS:0,15,SMOOTH_STAIRS:1,15,SMOOTH_STAIRS:2,15,SMOOTH_STAIRS:3,15,STEP:5,15,STEP:13,15,COBBLE_WALL:0,10,COBBLESTONE_STAIRS:0,10,STEP:3,10,COBBLE_WALL:1,20,COBBLESTONE_STAIRS:2,20,COBBLESTONE_STAIRS:3,20,MOSSY_COBBLESTONE:0,60,COBBLESTONE_STAIRS:1,20,STEP:11,20,COBBLESTONE:0,100)
RandomBlock(-5,4,-7,SMOOTH_BRICK:0,40,SMOOTH_BRICK:1,30,SMOOTH_BRICK:2,30,SMOOTH_STAIRS:0,15,SMOOTH_STAIRS:1,15,SMOOTH_STAIRS:2,15,SMOOTH_STAIRS:3,15,STEP:5,15,STEP:13,15,COBBLE_WALL:0,10,COBBLESTONE_STAIRS:0,10,STEP:3,10,COBBLE_WALL:1,20,COBBLESTONE_STAIRS:2,20,COBBLESTONE_STAIRS:3,20,MOSSY_COBBLESTONE:0,60,COBBLESTONE_STAIRS:1,20,STEP:11,20,COBBLESTONE:0,100)
RandomBlock(-5,4,-6,SMOOTH_BRICK:0,40,SMOOTH_BRICK:1,30,SMOOTH_BRICK:2,30,SMOOTH_STAIRS:0,15,SMOOTH_STAIRS:1,15,SMOOTH_STAIRS:2,15,SMOOTH_STAIRS:3,15,STEP:5,15,STEP:13,15,COBBLE_WALL:0,10,COBBLESTONE_STAIRS:0,10,STEP:3,10,COBBLE_WALL:1,20,COBBLESTONE_STAIRS:2,20,COBBLESTONE_STAIRS:3,20,MOSSY_COBBLESTONE:0,60,COBBLESTONE_STAIRS:1,20,STEP:11,20,COBBLESTONE:0,100)
RandomBlock(-5,4,-5,SMOOTH_BRICK:0,40,SMOOTH_BRICK:1,30,SMOOTH_BRICK:2,30,SMOOTH_STAIRS:0,15,SMOOTH_STAIRS:1,15,SMOOTH_STAIRS:2,15,SMOOTH_STAIRS:3,15,STEP:5,15,STEP:13,15,COBBLE_WALL:0,10,COBBLESTONE_STAIRS:0,10,STEP:3,10,COBBLE_WALL:1,20,COBBLESTONE_STAIRS:2,20,COBBLESTONE_STAIRS:3,20,MOSSY_COBBLESTONE:0,60,COBBLESTONE_STAIRS:1,20,STEP:11,20,COBBLESTONE:0,100)
RandomBlock(-5,4,-4,SMOOTH_BRICK:0,40,SMOOTH_BRICK:1,30,SMOOTH_BRICK:2,30,SMOOTH_STAIRS:0,15,SMOOTH_STAIRS:1,15,SMOOTH_STAIRS:2,15,SMOOTH_STAIRS:3,15,STEP:5,15,STEP:13,15,COBBLE_WALL:0,10,COBBLESTONE_STAIRS:0,10,STEP:3,10,COBBLE_WALL:1,20,COBBLESTONE_STAIRS:2,20,COBBLESTONE_STAIRS:3,20,MOSSY_COBBLESTONE:0,60,COBBLESTONE_STAIRS:1,20,STEP:11,20,COBBLESTONE:0,100)
RandomBlock(-5,5,-7,SMOOTH_BRICK:0,40,SMOOTH_BRICK:1,30,SMOOTH_BRICK:2,30,SMOOTH_STAIRS:0,15,SMOOTH_STAIRS:1,15,SMOOTH_STAIRS:2,15,SMOOTH_STAIRS:3,15,STEP:5,15,STEP:13,15,COBBLE_WALL:0,10,COBBLESTONE_STAIRS:0,10,STEP:3,10,COBBLE_WALL:1,20,COBBLESTONE_STAIRS:2,20,COBBLESTONE_STAIRS:3,20,MOSSY_COBBLESTONE:0,60,COBBLESTONE_STAIRS:1,20,STEP:11,20,COBBLESTONE:0,100)
RandomBlock(-5,5,-6,SMOOTH_BRICK:0,40,SMOOTH_BRICK:1,30,SMOOTH_BRICK:2,30,SMOOTH_STAIRS:0,15,SMOOTH_STAIRS:1,15,SMOOTH_STAIRS:2,15,SMOOTH_STAIRS:3,15,STEP:5,15,STEP:13,15,COBBLE_WALL:0,10,COBBLESTONE_STAIRS:0,10,STEP:3,10,COBBLE_WALL:1,20,COBBLESTONE_STAIRS:2,20,COBBLESTONE_STAIRS:3,20,MOSSY_COBBLESTONE:0,60,COBBLESTONE_STAIRS:1,20,STEP:11,20,COBBLESTONE:0,100)
RandomBlock(-5,5,-5,SMOOTH_BRICK:0,40,SMOOTH_BRICK:1,30,SMOOTH_BRICK:2,30,SMOOTH_STAIRS:0,15,SMOOTH_STAIRS:1,15,SMOOTH_STAIRS:2,15,SMOOTH_STAIRS:3,15,STEP:5,15,STEP:13,15,COBBLE_WALL:0,10,COBBLESTONE_STAIRS:0,10,STEP:3,10,COBBLE_WALL:1,20,COBBLESTONE_STAIRS:2,20,COBBLESTONE_STAIRS:3,20,MOSSY_COBBLESTONE:0,60,COBBLESTONE_STAIRS:1,20,STEP:11,20,COBBLESTONE:0,100)
RandomBlock(-5,5,-4,quark:limestone:1,30,quark:limestone_wall,10,quark:limestone,100)
RandomBlock(-5,6,-7,SMOOTH_BRICK:0,40,SMOOTH_BRICK:1,30,SMOOTH_BRICK:2,30,SMOOTH_STAIRS:0,15,SMOOTH_STAIRS:1,15,SMOOTH_STAIRS:2,15,SMOOTH_STAIRS:3,15,STEP:5,15,STEP:13,15,COBBLE_WALL:0,10,COBBLESTONE_STAIRS:0,10,STEP:3,10,COBBLE_WALL:1,20,COBBLESTONE_STAIRS:2,20,COBBLESTONE_STAIRS:3,20,MOSSY_COBBLESTONE:0,60,COBBLESTONE_STAIRS:1,20,STEP:11,20,COBBLESTONE:0,100)
RandomBlock(-5,6,-6,SMOOTH_BRICK:0,40,SMOOTH_BRICK:1,30,SMOOTH_BRICK:2,30,SMOOTH_STAIRS:0,15,SMOOTH_STAIRS:1,15,SMOOTH_STAIRS:2,15,SMOOTH_STAIRS:3,15,STEP:5,15,STEP:13,15,COBBLE_WALL:0,10,COBBLESTONE_STAIRS:0,10,STEP:3,10,COBBLE_WALL:1,20,COBBLESTONE_STAIRS:2,20,COBBLESTONE_STAIRS:3,20,MOSSY_COBBLESTONE:0,60,COBBLESTONE_STAIRS:1,20,STEP:11,20,COBBLESTONE:0,100)
RandomBlock(-5,6,-5,SMOOTH_BRICK:0,40,SMOOTH_BRICK:1,30,SMOOTH_BRICK:2,30,SMOOTH_STAIRS:0,15,SMOOTH_STAIRS:1,15,SMOOTH_STAIRS:2,15,SMOOTH_STAIRS:3,15,STEP:5,15,STEP:13,15,COBBLE_WALL:0,10,COBBLESTONE_STAIRS:0,10,STEP:3,10,COBBLE_WALL:1,20,COBBLESTONE_STAIRS:2,20,COBBLESTONE_STAIRS:3,20,MOSSY_COBBLESTONE:0,60,COBBLESTONE_STAIRS:1,20,STEP:11,20,COBBLESTONE:0,100)
RandomBlock(-5,6,-4,quark:limestone:1,30,quark:limestone_wall,10,quark:limestone,100)
RandomBlock(-5,7,-7,SMOOTH_BRICK:0,40,SMOOTH_BRICK:1,30,SMOOTH_BRICK:2,30,SMOOTH_STAIRS:0,15,SMOOTH_STAIRS:1,15,SMOOTH_STAIRS:2,15,SMOOTH_STAIRS:3,15,STEP:5,15,STEP:13,15,COBBLE_WALL:0,10,COBBLESTONE_STAIRS:0,10,STEP:3,10,COBBLE_WALL:1,20,COBBLESTONE_STAIRS:2,20,COBBLESTONE_STAIRS:3,20,MOSSY_COBBLESTONE:0,60,COBBLESTONE_STAIRS:1,20,STEP:11,20,COBBLESTONE:0,100)
RandomBlock(-5,7,-6,SMOOTH_BRICK:0,40,SMOOTH_BRICK:1,30,SMOOTH_BRICK:2,30,SMOOTH_STAIRS:0,15,SMOOTH_STAIRS:1,15,SMOOTH_STAIRS:2,15,SMOOTH_STAIRS:3,15,STEP:5,15,STEP:13,15,COBBLE_WALL:0,10,COBBLESTONE_STAIRS:0,10,STEP:3,10,COBBLE_WALL:1,20,COBBLESTONE_STAIRS:2,20,COBBLESTONE_STAIRS:3,20,MOSSY_COBBLESTONE:0,60,COBBLESTONE_STAIRS:1,20,STEP:11,20,COBBLESTONE:0,100)
RandomBlock(-5,7,-5,SMOOTH_BRICK:0,40,SMOOTH_BRICK:1,30,SMOOTH_BRICK:2,30,SMOOTH_STAIRS:0,15,SMOOTH_STAIRS:1,15,SMOOTH_STAIRS:2,15,SMOOTH_STAIRS:3,15,STEP:5,15,STEP:13,15,COBBLE_WALL:0,10,COBBLESTONE_STAIRS:0,10,STEP:3,10,COBBLE_WALL:1,20,COBBLESTONE_STAIRS:2,20,COBBLESTONE_STAIRS:3,20,MOSSY_COBBLESTONE:0,60,COBBLESTONE_STAIRS:1,20,STEP:11,20,COBBLESTONE:0,100)
RandomBlock(-5,7,-4,quark:limestone:1,30,quark:limestone_wall,10,quark:limestone,100)
RandomBlock(-5,8,-7,RUSTIC:IRON_LATTICE:0,30,RUSTIC:IRON_LATTICE:1,100)
RandomBlock(-5,8,-6,RUSTIC:IRON_LATTICE:0,30,RUSTIC:IRON_LATTICE:1,100)
RandomBlock(-5,8,-5,RUSTIC:IRON_LATTICE:0,30,RUSTIC:IRON_LATTICE:1,100)
RandomBlock(-5,9,-7,RUSTIC:IRON_LATTICE:0,30,RUSTIC:IRON_LATTICE:1,100)
RandomBlock(-5,9,-6,RUSTIC:IRON_LATTICE:0,30,RUSTIC:IRON_LATTICE:1,100)
RandomBlock(-5,9,-5,RUSTIC:IRON_LATTICE:0,30,RUSTIC:IRON_LATTICE:1,100)
RandomBlock(-5,10,-7,RUSTIC:IRON_LATTICE:0,30,RUSTIC:IRON_LATTICE:1,100)
RandomBlock(-5,10,-6,RUSTIC:IRON_LATTICE:0,30,RUSTIC:IRON_LATTICE:1,100)
RandomBlock(-5,10,-5,RUSTIC:IRON_LATTICE:0,30,RUSTIC:IRON_LATTICE:1,100)
RandomBlock(-5,10,-4,quark:limestone:1,30,quark:limestone_wall,10,quark:limestone,100)
RandomBlock(-5,11,-4,quark:limestone:1,30,quark:limestone_wall,10,quark:limestone,100)
RandomBlock(-5,12,-6,quark:limestone:1,30,quark:limestone_wall,10,quark:limestone,100)
RandomBlock(-5,12,-5,quark:limestone:1,30,quark:limestone_wall,10,quark:limestone,100)
RandomBlock(-5,13,-6,quark:limestone:1,30,quark:limestone_wall,10,quark:limestone,100)
RandomBlock(-5,13,-5,quark:limestone:1,30,quark:limestone_wall,10,quark:limestone,100)
RandomBlock(-5,14,-7,quark:limestone:1,30,quark:limestone_wall,10,quark:limestone,100)
Block(-5,14,-6,VINE:4)
RandomBlock(-5,15,-7,quark:limestone:1,30,quark:limestone_wall,10,quark:limestone,100)
Block(-5,15,-6,VINE:4)
Block(-5,17,-7,VINE:6)
Block(-5,18,-7,VINE:6)
Block(-5,19,-7,VINE:6)
RandomBlock(-5,26,-7,quark:limestone:1,30,quark:limestone_wall,10,quark:limestone,100)
RandomBlock(-5,27,-7,quark:limestone:1,30,quark:limestone_wall,10,quark:limestone,100)
RandomBlock(-5,28,-6,quark:limestone:1,30,quark:limestone_wall,10,quark:limestone,100)
RandomBlock(-4,0,-7,SMOOTH_BRICK:0,40,SMOOTH_BRICK:1,30,SMOOTH_BRICK:2,30,SMOOTH_STAIRS:0,15,SMOOTH_STAIRS:1,15,SMOOTH_STAIRS:2,15,SMOOTH_STAIRS:3,15,STEP:5,15,STEP:13,15,COBBLE_WALL:0,10,COBBLESTONE_STAIRS:0,10,STEP:3,10,COBBLE_WALL:1,20,COBBLESTONE_STAIRS:2,20,COBBLESTONE_STAIRS:3,20,MOSSY_COBBLESTONE:0,60,COBBLESTONE_STAIRS:1,20,STEP:11,20,COBBLESTONE:0,100)
RandomBlock(-4,0,-6,SMOOTH_BRICK:0,40,SMOOTH_BRICK:1,30,SMOOTH_BRICK:2,30,SMOOTH_STAIRS:0,15,SMOOTH_STAIRS:1,15,SMOOTH_STAIRS:2,15,SMOOTH_STAIRS:3,15,STEP:5,15,STEP:13,15,COBBLE_WALL:0,10,COBBLESTONE_STAIRS:0,10,STEP:3,10,COBBLE_WALL:1,20,COBBLESTONE_STAIRS:2,20,COBBLESTONE_STAIRS:3,20,MOSSY_COBBLESTONE:0,60,COBBLESTONE_STAIRS:1,20,STEP:11,20,COBBLESTONE:0,100)
RandomBlock(-4,0,-5,SMOOTH_BRICK:0,40,SMOOTH_BRICK:1,30,SMOOTH_BRICK:2,30,SMOOTH_STAIRS:0,15,SMOOTH_STAIRS:1,15,SMOOTH_STAIRS:2,15,SMOOTH_STAIRS:3,15,STEP:5,15,STEP:13,15,COBBLE_WALL:0,10,COBBLESTONE_STAIRS:0,10,STEP:3,10,COBBLE_WALL:1,20,COBBLESTONE_STAIRS:2,20,COBBLESTONE_STAIRS:3,20,MOSSY_COBBLESTONE:0,60,COBBLESTONE_STAIRS:1,20,STEP:11,20,COBBLESTONE:0,100)
RandomBlock(-4,1,-7,SMOOTH_BRICK:0,40,SMOOTH_BRICK:1,30,SMOOTH_BRICK:2,30,SMOOTH_STAIRS:0,15,SMOOTH_STAIRS:1,15,SMOOTH_STAIRS:2,15,SMOOTH_STAIRS:3,15,STEP:5,15,STEP:13,15,COBBLE_WALL:0,10,COBBLESTONE_STAIRS:0,10,STEP:3,10,COBBLE_WALL:1,20,COBBLESTONE_STAIRS:2,20,COBBLESTONE_STAIRS:3,20,MOSSY_COBBLESTONE:0,60,COBBLESTONE_STAIRS:1,20,STEP:11,20,COBBLESTONE:0,100)
RandomBlock(-4,1,-6,SMOOTH_BRICK:0,40,SMOOTH_BRICK:1,30,SMOOTH_BRICK:2,30,SMOOTH_STAIRS:0,15,SMOOTH_STAIRS:1,15,SMOOTH_STAIRS:2,15,SMOOTH_STAIRS:3,15,STEP:5,15,STEP:13,15,COBBLE_WALL:0,10,COBBLESTONE_STAIRS:0,10,STEP:3,10,COBBLE_WALL:1,20,COBBLESTONE_STAIRS:2,20,COBBLESTONE_STAIRS:3,20,MOSSY_COBBLESTONE:0,60,COBBLESTONE_STAIRS:1,20,STEP:11,20,COBBLESTONE:0,100)
RandomBlock(-4,1,-5,SMOOTH_BRICK:0,40,SMOOTH_BRICK:1,30,SMOOTH_BRICK:2,30,SMOOTH_STAIRS:0,15,SMOOTH_STAIRS:1,15,SMOOTH_STAIRS:2,15,SMOOTH_STAIRS:3,15,STEP:5,15,STEP:13,15,COBBLE_WALL:0,10,COBBLESTONE_STAIRS:0,10,STEP:3,10,COBBLE_WALL:1,20,COBBLESTONE_STAIRS:2,20,COBBLESTONE_STAIRS:3,20,MOSSY_COBBLESTONE:0,60,COBBLESTONE_STAIRS:1,20,STEP:11,20,COBBLESTONE:0,100)
RandomBlock(-4,2,-7,SMOOTH_BRICK:0,40,SMOOTH_BRICK:1,30,SMOOTH_BRICK:2,30,SMOOTH_STAIRS:0,15,SMOOTH_STAIRS:1,15,SMOOTH_STAIRS:2,15,SMOOTH_STAIRS:3,15,STEP:5,15,STEP:13,15,COBBLE_WALL:0,10,COBBLESTONE_STAIRS:0,10,STEP:3,10,COBBLE_WALL:1,20,COBBLESTONE_STAIRS:2,20,COBBLESTONE_STAIRS:3,20,MOSSY_COBBLESTONE:0,60,COBBLESTONE_STAIRS:1,20,STEP:11,20,COBBLESTONE:0,100)
RandomBlock(-4,2,-6,SMOOTH_BRICK:0,40,SMOOTH_BRICK:1,30,SMOOTH_BRICK:2,30,SMOOTH_STAIRS:0,15,SMOOTH_STAIRS:1,15,SMOOTH_STAIRS:2,15,SMOOTH_STAIRS:3,15,STEP:5,15,STEP:13,15,COBBLE_WALL:0,10,COBBLESTONE_STAIRS:0,10,STEP:3,10,COBBLE_WALL:1,20,COBBLESTONE_STAIRS:2,20,COBBLESTONE_STAIRS:3,20,MOSSY_COBBLESTONE:0,60,COBBLESTONE_STAIRS:1,20,STEP:11,20,COBBLESTONE:0,100)
RandomBlock(-4,2,-5,SMOOTH_BRICK:0,40,SMOOTH_BRICK:1,30,SMOOTH_BRICK:2,30,SMOOTH_STAIRS:0,15,SMOOTH_STAIRS:1,15,SMOOTH_STAIRS:2,15,SMOOTH_STAIRS:3,15,STEP:5,15,STEP:13,15,COBBLE_WALL:0,10,COBBLESTONE_STAIRS:0,10,STEP:3,10,COBBLE_WALL:1,20,COBBLESTONE_STAIRS:2,20,COBBLESTONE_STAIRS:3,20,MOSSY_COBBLESTONE:0,60,COBBLESTONE_STAIRS:1,20,STEP:11,20,COBBLESTONE:0,100)
RandomBlock(-4,3,-7,SMOOTH_BRICK:0,40,SMOOTH_BRICK:1,30,SMOOTH_BRICK:2,30,SMOOTH_STAIRS:0,15,SMOOTH_STAIRS:1,15,SMOOTH_STAIRS:2,15,SMOOTH_STAIRS:3,15,STEP:5,15,STEP:13,15,COBBLE_WALL:0,10,COBBLESTONE_STAIRS:0,10,STEP:3,10,COBBLE_WALL:1,20,COBBLESTONE_STAIRS:2,20,COBBLESTONE_STAIRS:3,20,MOSSY_COBBLESTONE:0,60,COBBLESTONE_STAIRS:1,20,STEP:11,20,COBBLESTONE:0,100)
RandomBlock(-4,3,-6,SMOOTH_BRICK:0,40,SMOOTH_BRICK:1,30,SMOOTH_BRICK:2,30,SMOOTH_STAIRS:0,15,SMOOTH_STAIRS:1,15,SMOOTH_STAIRS:2,15,SMOOTH_STAIRS:3,15,STEP:5,15,STEP:13,15,COBBLE_WALL:0,10,COBBLESTONE_STAIRS:0,10,STEP:3,10,COBBLE_WALL:1,20,COBBLESTONE_STAIRS:2,20,COBBLESTONE_STAIRS:3,20,MOSSY_COBBLESTONE:0,60,COBBLESTONE_STAIRS:1,20,STEP:11,20,COBBLESTONE:0,100)
RandomBlock(-4,3,-5,SMOOTH_BRICK:0,40,SMOOTH_BRICK:1,30,SMOOTH_BRICK:2,30,SMOOTH_STAIRS:0,15,SMOOTH_STAIRS:1,15,SMOOTH_STAIRS:2,15,SMOOTH_STAIRS:3,15,STEP:5,15,STEP:13,15,COBBLE_WALL:0,10,COBBLESTONE_STAIRS:0,10,STEP:3,10,COBBLE_WALL:1,20,COBBLESTONE_STAIRS:2,20,COBBLESTONE_STAIRS:3,20,MOSSY_COBBLESTONE:0,60,COBBLESTONE_STAIRS:1,20,STEP:11,20,COBBLESTONE:0,100)
RandomBlock(-4,4,-7,SMOOTH_BRICK:0,40,SMOOTH_BRICK:1,30,SMOOTH_BRICK:2,30,SMOOTH_STAIRS:0,15,SMOOTH_STAIRS:1,15,SMOOTH_STAIRS:2,15,SMOOTH_STAIRS:3,15,STEP:5,15,STEP:13,15,COBBLE_WALL:0,10,COBBLESTONE_STAIRS:0,10,STEP:3,10,COBBLE_WALL:1,20,COBBLESTONE_STAIRS:2,20,COBBLESTONE_STAIRS:3,20,MOSSY_COBBLESTONE:0,60,COBBLESTONE_STAIRS:1,20,STEP:11,20,COBBLESTONE:0,100)
RandomBlock(-4,4,-6,SMOOTH_BRICK:0,40,SMOOTH_BRICK:1,30,SMOOTH_BRICK:2,30,SMOOTH_STAIRS:0,15,SMOOTH_STAIRS:1,15,SMOOTH_STAIRS:2,15,SMOOTH_STAIRS:3,15,STEP:5,15,STEP:13,15,COBBLE_WALL:0,10,COBBLESTONE_STAIRS:0,10,STEP:3,10,COBBLE_WALL:1,20,COBBLESTONE_STAIRS:2,20,COBBLESTONE_STAIRS:3,20,MOSSY_COBBLESTONE:0,60,COBBLESTONE_STAIRS:1,20,STEP:11,20,COBBLESTONE:0,100)
RandomBlock(-4,4,-5,SMOOTH_BRICK:0,40,SMOOTH_BRICK:1,30,SMOOTH_BRICK:2,30,SMOOTH_STAIRS:0,15,SMOOTH_STAIRS:1,15,SMOOTH_STAIRS:2,15,SMOOTH_STAIRS:3,15,STEP:5,15,STEP:13,15,COBBLE_WALL:0,10,COBBLESTONE_STAIRS:0,10,STEP:3,10,COBBLE_WALL:1,20,COBBLESTONE_STAIRS:2,20,COBBLESTONE_STAIRS:3,20,MOSSY_COBBLESTONE:0,60,COBBLESTONE_STAIRS:1,20,STEP:11,20,COBBLESTONE:0,100)
RandomBlock(-4,5,-7,SMOOTH_BRICK:0,40,SMOOTH_BRICK:1,30,SMOOTH_BRICK:2,30,SMOOTH_STAIRS:0,15,SMOOTH_STAIRS:1,15,SMOOTH_STAIRS:2,15,SMOOTH_STAIRS:3,15,STEP:5,15,STEP:13,15,COBBLE_WALL:0,10,COBBLESTONE_STAIRS:0,10,STEP:3,10,COBBLE_WALL:1,20,COBBLESTONE_STAIRS:2,20,COBBLESTONE_STAIRS:3,20,MOSSY_COBBLESTONE:0,60,COBBLESTONE_STAIRS:1,20,STEP:11,20,COBBLESTONE:0,100)
RandomBlock(-4,5,-6,quark:limestone:1,30,quark:limestone_wall,10,quark:limestone,100)
RandomBlock(-4,5,-5,quark:limestone:1,30,quark:limestone_wall,10,quark:limestone,100)
RandomBlock(-4,6,-7,SMOOTH_BRICK:0,40,SMOOTH_BRICK:1,30,SMOOTH_BRICK:2,30,SMOOTH_STAIRS:0,15,SMOOTH_STAIRS:1,15,SMOOTH_STAIRS:2,15,SMOOTH_STAIRS:3,15,STEP:5,15,STEP:13,15,COBBLE_WALL:0,10,COBBLESTONE_STAIRS:0,10,STEP:3,10,COBBLE_WALL:1,20,COBBLESTONE_STAIRS:2,20,COBBLESTONE_STAIRS:3,20,MOSSY_COBBLESTONE:0,60,COBBLESTONE_STAIRS:1,20,STEP:11,20,COBBLESTONE:0,100)
RandomBlock(-4,6,-6,quark:limestone:1,30,quark:limestone_wall,10,quark:limestone,100)
RandomBlock(-4,6,-5,quark:limestone:1,30,quark:limestone_wall,10,quark:limestone,100)
RandomBlock(-4,7,-7,SMOOTH_BRICK:0,40,SMOOTH_BRICK:1,30,SMOOTH_BRICK:2,30,SMOOTH_STAIRS:0,15,SMOOTH_STAIRS:1,15,SMOOTH_STAIRS:2,15,SMOOTH_STAIRS:3,15,STEP:5,15,STEP:13,15,COBBLE_WALL:0,10,COBBLESTONE_STAIRS:0,10,STEP:3,10,COBBLE_WALL:1,20,COBBLESTONE_STAIRS:2,20,COBBLESTONE_STAIRS:3,20,MOSSY_COBBLESTONE:0,60,COBBLESTONE_STAIRS:1,20,STEP:11,20,COBBLESTONE:0,100)
RandomBlock(-4,7,-6,quark:limestone:1,30,quark:limestone_wall,10,quark:limestone,100)
RandomBlock(-4,7,-5,quark:limestone:1,30,quark:limestone_wall,10,quark:limestone,100)
RandomBlock(-4,8,-7,RUSTIC:IRON_LATTICE:0,30,RUSTIC:IRON_LATTICE:1,100)
Block(-4,8,-5,inspirations:redstone_barrel)
RandomBlock(-4,9,-7,RUSTIC:IRON_LATTICE:0,30,RUSTIC:IRON_LATTICE:1,100)
Block(-4,9,-5,inspirations:redstone_barrel)
RandomBlock(-4,10,-7,RUSTIC:IRON_LATTICE:0,30,RUSTIC:IRON_LATTICE:1,100)
RandomBlock(-4,10,-6,quark:limestone:1,30,quark:limestone_wall,10,quark:limestone,100)
RandomBlock(-4,10,-5,quark:limestone:1,30,quark:limestone_wall,10,quark:limestone,100)
RandomBlock(-4,11,-6,quark:limestone:1,30,quark:limestone_wall,10,quark:limestone,100)
RandomBlock(-4,11,-5,quark:limestone:1,30,quark:limestone_wall,10,quark:limestone,100)
RandomBlock(-4,12,-7,quark:limestone:1,30,quark:limestone_wall,10,quark:limestone,100)
RandomBlock(-4,13,-7,quark:limestone:1,30,quark:limestone_wall,10,quark:limestone,100)
Block(-4,23,-7,VINE:2)
Block(-4,24,-7,VINE:2)
Block(-4,25,-7,VINE:6)
Block(-4,26,-7,VINE:6)
Block(-4,27,-7,VINE:6)
Block(-4,27,-6,VINE:2)
RandomBlock(-4,28,-7,quark:limestone:1,30,quark:limestone_wall,10,quark:limestone,100)
Block(-4,28,-6,VINE:2)
RandomBlock(-3,0,-7,SMOOTH_BRICK:0,40,SMOOTH_BRICK:1,30,SMOOTH_BRICK:2,30,SMOOTH_STAIRS:0,15,SMOOTH_STAIRS:1,15,SMOOTH_STAIRS:2,15,SMOOTH_STAIRS:3,15,STEP:5,15,STEP:13,15,COBBLE_WALL:0,10,COBBLESTONE_STAIRS:0,10,STEP:3,10,COBBLE_WALL:1,20,COBBLESTONE_STAIRS:2,20,COBBLESTONE_STAIRS:3,20,MOSSY_COBBLESTONE:0,60,COBBLESTONE_STAIRS:1,20,STEP:11,20,COBBLESTONE:0,100)
RandomBlock(-3,1,-7,SMOOTH_BRICK:0,40,SMOOTH_BRICK:1,30,SMOOTH_BRICK:2,30,SMOOTH_STAIRS:0,15,SMOOTH_STAIRS:1,15,SMOOTH_STAIRS:2,15,SMOOTH_STAIRS:3,15,STEP:5,15,STEP:13,15,COBBLE_WALL:0,10,COBBLESTONE_STAIRS:0,10,STEP:3,10,COBBLE_WALL:1,20,COBBLESTONE_STAIRS:2,20,COBBLESTONE_STAIRS:3,20,MOSSY_COBBLESTONE:0,60,COBBLESTONE_STAIRS:1,20,STEP:11,20,COBBLESTONE:0,100)
RandomBlock(-3,2,-7,SMOOTH_BRICK:0,40,SMOOTH_BRICK:1,30,SMOOTH_BRICK:2,30,SMOOTH_STAIRS:0,15,SMOOTH_STAIRS:1,15,SMOOTH_STAIRS:2,15,SMOOTH_STAIRS:3,15,STEP:5,15,STEP:13,15,COBBLE_WALL:0,10,COBBLESTONE_STAIRS:0,10,STEP:3,10,COBBLE_WALL:1,20,COBBLESTONE_STAIRS:2,20,COBBLESTONE_STAIRS:3,20,MOSSY_COBBLESTONE:0,60,COBBLESTONE_STAIRS:1,20,STEP:11,20,COBBLESTONE:0,100)
RandomBlock(-3,3,-7,SMOOTH_BRICK:0,40,SMOOTH_BRICK:1,30,SMOOTH_BRICK:2,30,SMOOTH_STAIRS:0,15,SMOOTH_STAIRS:1,15,SMOOTH_STAIRS:2,15,SMOOTH_STAIRS:3,15,STEP:5,15,STEP:13,15,COBBLE_WALL:0,10,COBBLESTONE_STAIRS:0,10,STEP:3,10,COBBLE_WALL:1,20,COBBLESTONE_STAIRS:2,20,COBBLESTONE_STAIRS:3,20,MOSSY_COBBLESTONE:0,60,COBBLESTONE_STAIRS:1,20,STEP:11,20,COBBLESTONE:0,100)
RandomBlock(-3,4,-7,SMOOTH_BRICK:0,40,SMOOTH_BRICK:1,30,SMOOTH_BRICK:2,30,SMOOTH_STAIRS:0,15,SMOOTH_STAIRS:1,15,SMOOTH_STAIRS:2,15,SMOOTH_STAIRS:3,15,STEP:5,15,STEP:13,15,COBBLE_WALL:0,10,COBBLESTONE_STAIRS:0,10,STEP:3,10,COBBLE_WALL:1,20,COBBLESTONE_STAIRS:2,20,COBBLESTONE_STAIRS:3,20,MOSSY_COBBLESTONE:0,60,COBBLESTONE_STAIRS:1,20,STEP:11,20,COBBLESTONE:0,100)
RandomBlock(-3,5,-7,quark:limestone:1,30,quark:limestone_wall,10,quark:limestone,100)
RandomBlock(-3,6,-7,quark:limestone:1,30,quark:limestone_wall,10,quark:limestone,100)
RandomBlock(-3,7,-7,quark:limestone:1,30,quark:limestone_wall,10,quark:limestone,100)
Block(-3,8,-7,inspirations:redstone_barrel)
Block(-3,9,-7,inspirations:redstone_barrel)
RandomBlock(-3,10,-7,quark:limestone:1,30,quark:limestone_wall,10,quark:limestone,100)
RandomBlock(-3,11,-7,quark:limestone:1,30,quark:limestone_wall,10,quark:limestone,100)
Block(-3,28,-7,VINE:2)

#######################################################################
# +-----------------------------------------------------------------+ #
# |                             Branches                            | #
# +-----------------------------------------------------------------+ #
#######################################################################

Branch(-16,0,0,true,CoolingTowerC0R1,NORTH,100.0,0)

#######################################################################
# +-----------------------------------------------------------------+ #
# |                             Entities                            | #
# +-----------------------------------------------------------------+ #
#######################################################################


#######################################################################
# +-----------------------------------------------------------------+ #
# |                            Particles                            | #
# +-----------------------------------------------------------------+ #
#######################################################################


#######################################################################
# +-----------------------------------------------------------------+ #
# |                             Spawners                            | #
# +-----------------------------------------------------------------+ #
#######################################################################


#######################################################################
# +-----------------------------------------------------------------+ #
# |                             ModData                             | #
# +-----------------------------------------------------------------+ #
#######################################################################

