
#######################################################################
# +-----------------------------------------------------------------+ #
# |                            BO4 object                           | #
# +-----------------------------------------------------------------+ #
#######################################################################

Author: NLBlackEagle

Description: No description given

SettingsMode: WriteDisable


#######################################################################
# +-----------------------------------------------------------------+ #
# |                          Main settings                          | #
# +-----------------------------------------------------------------+ #
#######################################################################

Frequency: 0

SpawnHeight: highestBlock

UseCenterForHighestBlock: true

##############################
# Height Limits for the BO4. #
##############################

MinHeight: 0

MaxHeight: 255

InheritBO3: 

InheritBO3Rotation: NORTH

OverrideChildSettings: true

OverrideParentHeight: false

CanOverride: true

BranchFrequency: 0

BranchFrequencyGroup: 

MustBeBelowOther: false

MustBeInside: 

CannotBeInside: 

ReplacesBO3: L4-M-CrossC0R0, L4-M-CrossC0R1, L4-M-CrossC0R2, L4-M-CrossC0R3, L4-M-CrossC1R0, L4-M-CrossC1R1, L4-M-CrossC1R2, L4-M-CrossC1R3, L4-M-CrossC2R0, L4-M-CrossC2R1, L4-M-CrossC2R2, L4-M-CrossC2R3, L4-M-CrossC3R0, L4-M-CrossC3R1, L4-M-CrossC3R2, L4-M-CrossC3R3, L4-M-Straigth-START_01-C0R0, L4-M-Straigth-START_01-C0R1, L4-M-Straigth-START_01-C1R0, L4-M-Straigth-START_01-C1R1, L4-M-Straigth-START_01-C2R0, L4-M-Straigth-START_01-C2R1, L4-M-Straigth-START_01-C3R0, L4-M-Straigth-START_01-C3R1, L4-M-Straigth-3CC0R0, L4-M-Straigth-3CC0R1, L4-M-Straigth-3CC0R2, L4-M-Straigth-3CC1R0, L4-M-Straigth-3CC1R1, L4-M-Straigth-3CC1R2, L4-M-Straigth-3CC2R0, L4-M-Straigth-3CC2R1, L4-M-Straigth-3CC2R2, L4-M-Straigth-3CC3R0, L4-M-Straigth-3CC3R1, L4-M-Straigth-3CC3R2, L4-M-Cross, skyscraper_2x2_01, skyscraper_2x2_02, skyscraper_2x2_03, skyscraper_2x2_04, skyscraper_2x2_05, skyscraper_3x3_01, skyscraper_3x3_02, skyscraper_3x3_03, L3-M-Straigth-2CC0R0, L3-M-Straigth-2CC0R1, L3-M-Straigth-2CC1R0, L3-M-Straigth-2CC1R1, L3-M-Straigth-2CC2R0, L3-M-Straigth-2CC2R1, L3-M-Straigth-2CC3R0, L3-M-Straigth-2CC3R1, L3-M-Straigth-3CC0R0, L3-M-Straigth-3CC0R1, L3-M-Straigth-3CC0R2, L3-M-Straigth-3CC1R0, L3-M-Straigth-3CC1R1, L3-M-Straigth-3CC1R2, L3-M-Straigth-3CC2R0, L3-M-Straigth-3CC2R1, L3-M-Straigth-3CC2R2, L3-M-Straigth-3CC3R0, L3-M-Straigth-3CC3R1, L3-M-Straigth-3CC3R2L4-M-CrossC0R0, L4-M-CrossC0R1, L4-M-CrossC0R2, L4-M-CrossC0R3, L4-M-CrossC1R0, L4-M-CrossC1R1, L4-M-CrossC1R2, L4-M-CrossC1R3, L4-M-CrossC2R0, L4-M-CrossC2R1, L4-M-CrossC2R2, L4-M-CrossC2R3, L4-M-CrossC3R0, L4-M-CrossC3R1, L4-M-CrossC3R2, L4-M-CrossC3R3, L4-M-Straigth-START_01-C0R0, L4-M-Straigth-START_01-C0R1, L4-M-Straigth-START_01-C1R0, L4-M-Straigth-START_01-C1R1, L4-M-Straigth-START_01-C2R0, L4-M-Straigth-START_01-C2R1, L4-M-Straigth-START_01-C3R0, L4-M-Straigth-START_01-C3R1, L4-M-Straigth-3CC0R0, L4-M-Straigth-3CC0R1, L4-M-Straigth-3CC0R2, L4-M-Straigth-3CC1R0, L4-M-Straigth-3CC1R1, L4-M-Straigth-3CC1R2, L4-M-Straigth-3CC2R0, L4-M-Straigth-3CC2R1, L4-M-Straigth-3CC2R2, L4-M-Straigth-3CC3R0, L4-M-Straigth-3CC3R1, L4-M-Straigth-3CC3R2, L4-M-Cross, skyscraper_2x2_01, skyscraper_2x2_02, skyscraper_2x2_03, skyscraper_2x2_04, skyscraper_2x2_05, skyscraper_3x3_01, skyscraper_3x3_02, skyscraper_3x3_03

MustBeInsideWorldBorders: false

CanSpawnOnWater: true

SpawnOnWaterOnly: false

SpawnUnderWater: false

SpawnAtWaterLevel: false

HeightOffset: 0

RemoveAir: false

ReplaceAbove: 

ReplaceBelow: 

ReplaceWithBiomeBlocks: false

ReplaceWithSurfaceBlock: GRASS

ReplaceWithGroundBlock: DIRT

ReplaceWithStoneBlock: STONE

SmoothRadius: 0

SmoothHeightOffset: 0

SmoothStartTop: false

SmoothStartWood: false

SmoothingSurfaceBlock: 

SmoothingGroundBlock: 

BO3Group: 

IsSpawnPoint: false

DoReplaceBlocks: false


#######################################################################
# +-----------------------------------------------------------------+ #
# |                              Blocks                             | #
# +-----------------------------------------------------------------+ #
#######################################################################

Block(-8,0,-7,CONCRETE:7)
Block(-8,0,-6,CONCRETE:7)
Block(-8,0,-5,CONCRETE:7)
Block(-8,0,-4,CONCRETE:7)
Block(-8,0,-3,CONCRETE:7)
Block(-8,0,-2,CONCRETE:7)
Block(-8,0,-1,CONCRETE:7)
Block(-8,0,0,CONCRETE:7)
Block(-8,0,1,CONCRETE:7)
Block(-8,0,2,CONCRETE:7)
Block(-8,0,3,CONCRETE:7)
Block(-8,0,4,CONCRETE:7)
Block(-8,0,5,CONCRETE:7)
Block(-8,0,6,CONCRETE:7)
Block(-8,0,7,CONCRETE:7)
Block(-8,0,8,CONCRETE:7)
Block(-8,1,-7,OBSIDIAN:0)
Block(-8,1,-6,OBSIDIAN:0)
Block(-8,1,-5,OBSIDIAN:0)
Block(-8,1,-4,OBSIDIAN:0)
Block(-8,1,-3,OBSIDIAN:0)
Block(-8,1,-2,OBSIDIAN:0)
Block(-8,1,-1,OBSIDIAN:0)
Block(-8,1,0,OBSIDIAN:0)
Block(-8,1,1,OBSIDIAN:0)
Block(-8,1,2,OBSIDIAN:0)
Block(-8,1,3,OBSIDIAN:0)
Block(-8,1,4,OBSIDIAN:0)
Block(-8,1,5,OBSIDIAN:0)
Block(-8,1,6,OBSIDIAN:0)
Block(-8,1,7,OBSIDIAN:0)
Block(-8,1,8,OBSIDIAN:0)
Block(-8,2,-7,OBSIDIAN:0)
Block(-8,2,-6,OBSIDIAN:0)
Block(-8,2,-5,OBSIDIAN:0)
Block(-8,2,-4,OBSIDIAN:0)
Block(-8,2,-3,OBSIDIAN:0)
Block(-8,2,-2,OBSIDIAN:0)
Block(-8,2,-1,OBSIDIAN:0)
Block(-8,2,0,OBSIDIAN:0)
Block(-8,2,1,OBSIDIAN:0)
Block(-8,2,2,OBSIDIAN:0)
Block(-8,2,3,OBSIDIAN:0)
Block(-8,2,4,OBSIDIAN:0)
Block(-8,2,5,OBSIDIAN:0)
Block(-8,2,6,OBSIDIAN:0)
Block(-8,2,7,OBSIDIAN:0)
Block(-8,2,8,OBSIDIAN:0)
Block(-8,3,-7,STATIONARY_LAVA:0)
Block(-8,3,-6,STATIONARY_LAVA:0)
Block(-8,3,-5,STATIONARY_LAVA:0)
Block(-8,3,-4,STATIONARY_LAVA:0)
Block(-8,3,-3,STATIONARY_LAVA:0)
Block(-8,3,-2,STATIONARY_LAVA:0)
Block(-8,3,-1,STATIONARY_LAVA:0)
Block(-8,3,0,STATIONARY_LAVA:0)
Block(-8,3,1,STATIONARY_LAVA:0)
Block(-8,3,2,STATIONARY_LAVA:0)
Block(-8,3,3,STATIONARY_LAVA:0)
Block(-8,3,4,STATIONARY_LAVA:0)
Block(-8,3,5,STATIONARY_LAVA:0)
Block(-8,3,6,STATIONARY_LAVA:0)
Block(-8,3,7,STATIONARY_LAVA:0)
Block(-8,3,8,STATIONARY_LAVA:0)
Block(-8,4,-7,OBSIDIAN:0)
Block(-8,4,-6,OBSIDIAN:0)
Block(-8,4,-5,OBSIDIAN:0)
Block(-8,4,-4,OBSIDIAN:0)
Block(-8,4,-3,OBSIDIAN:0)
Block(-8,4,-2,OBSIDIAN:0)
Block(-8,4,-1,OBSIDIAN:0)
Block(-8,4,0,OBSIDIAN:0)
Block(-8,4,1,OBSIDIAN:0)
Block(-8,4,2,OBSIDIAN:0)
Block(-8,4,3,OBSIDIAN:0)
Block(-8,4,4,OBSIDIAN:0)
Block(-8,4,5,OBSIDIAN:0)
Block(-8,4,6,OBSIDIAN:0)
Block(-8,4,7,OBSIDIAN:0)
Block(-8,4,8,OBSIDIAN:0)
Block(-8,5,-7,COBBLE_WALL:0)
Block(-8,5,-6,minecraft:yellow_glazed_terracotta:0)
Block(-8,5,-5,GOLD_PLATE:0)
Block(-8,5,-4,COBBLE_WALL:0)
Block(-8,5,-3,IRON_PLATE:0)
Block(-8,5,-2,OBSIDIAN:0)
Block(-8,5,-1,IRON_PLATE:0)
Block(-8,5,0,IRON_PLATE:0)
Block(-8,5,1,IRON_PLATE:0)
Block(-8,5,2,IRON_PLATE:0)
Block(-8,5,3,IRON_PLATE:0)
Block(-8,5,4,IRON_PLATE:0)
Block(-8,5,5,IRON_PLATE:0)
Block(-8,5,6,IRON_PLATE:0)
Block(-8,5,7,IRON_PLATE:0)
Block(-8,5,8,IRON_PLATE:0)
Block(-8,6,-7,DOUBLE_STEP:0)
Block(-8,6,-6,STEP:8)
Block(-8,6,-5,STEP:8)
Block(-8,6,-4,DOUBLE_STEP:0)
Block(-8,6,-3,STONE_BUTTON:3)
Block(-8,6,-2,OBSIDIAN:0)
Block(-8,7,-7,COBBLE_WALL:0)
Block(-8,7,-6,GOLD_PLATE:0)
Block(-8,7,-5,GOLD_BLOCK:0)
Block(-8,7,-4,COBBLE_WALL:0)
Block(-8,7,-2,OBSIDIAN:0)
Block(-8,8,-7,DOUBLE_STEP:0)
Block(-8,8,-6,STEP:8)
Block(-8,8,-5,STEP:8)
Block(-8,8,-4,DOUBLE_STEP:0)
Block(-8,8,-3,STONE_BUTTON:3)
Block(-8,8,-2,OBSIDIAN:0)
Block(-8,8,6,STEP:8)
Block(-8,8,7,STEP:8)
Block(-8,9,-7,GOLD_PLATE:0)
Block(-8,9,-6,minecraft:yellow_glazed_terracotta:0)
RandomBlock(-8,9,-5,emerald_ore,50,gold_ore,35,iron_ore,100)
Block(-8,9,-4,GOLD_PLATE:0)
Block(-8,9,-2,OBSIDIAN:0)
Block(-8,9,6,DIODE_BLOCK_OFF:1)
Block(-8,9,7,DIODE_BLOCK_OFF:1)
Block(-7,9,6,REDSTONE_WIRE:0)
Block(-7,9,7,REDSTONE_WIRE:0)
Block(6,9,6,DIODE_BLOCK_OFF:1)
Block(6,9,7,DIODE_BLOCK_OFF:1)
Block(-8,10,-7,STEP:8)
Block(-8,10,-6,STEP:8)
Block(-8,10,-5,STEP:8)
Block(-8,10,-4,STEP:8)
Block(-8,10,-3,STEP:8)
Block(-8,10,-2,OBSIDIAN:0)
Block(-8,10,-1,STEP:8)
Block(-8,10,0,STEP:8)
Block(-8,10,1,STEP:8)
Block(-8,10,2,STEP:8)
Block(-8,10,3,STEP:8)
Block(-8,10,4,STEP:8)
Block(-8,10,5,STEP:8)
Block(-8,10,6,STEP:8)
Block(-8,10,7,STEP:8)
Block(-8,10,8,STEP:8)
Block(-8,11,-7,OBSIDIAN:0)
Block(-8,11,-6,OBSIDIAN:0)
Block(-8,11,-5,OBSIDIAN:0)
Block(-8,11,-4,OBSIDIAN:0)
Block(-8,11,-3,OBSIDIAN:0)
Block(-8,11,-2,OBSIDIAN:0)
Block(-8,11,-1,OBSIDIAN:0)
Block(-8,11,0,OBSIDIAN:0)
Block(-8,11,1,OBSIDIAN:0)
Block(-8,11,2,OBSIDIAN:0)
Block(-8,11,3,OBSIDIAN:0)
Block(-8,11,4,OBSIDIAN:0)
Block(-8,11,5,OBSIDIAN:0)
Block(-8,11,6,OBSIDIAN:0)
Block(-8,11,7,OBSIDIAN:0)
Block(-8,11,8,OBSIDIAN:0)
Block(-8,12,-7,STATIONARY_LAVA:0)
Block(-8,12,-6,STATIONARY_LAVA:0)
Block(-8,12,-5,STATIONARY_LAVA:0)
Block(-8,12,-4,STATIONARY_LAVA:0)
Block(-8,12,-3,STATIONARY_LAVA:0)
Block(-8,12,-2,STATIONARY_LAVA:0)
Block(-8,12,-1,STATIONARY_LAVA:0)
Block(-8,12,0,STATIONARY_LAVA:0)
Block(-8,12,1,STATIONARY_LAVA:0)
Block(-8,12,2,STATIONARY_LAVA:0)
Block(-8,12,3,STATIONARY_LAVA:0)
Block(-8,12,4,STATIONARY_LAVA:0)
Block(-8,12,5,STATIONARY_LAVA:0)
Block(-8,12,6,STATIONARY_LAVA:0)
Block(-8,12,7,STATIONARY_LAVA:0)
Block(-8,12,8,STATIONARY_LAVA:0)
Block(-8,13,-7,OBSIDIAN:0)
Block(-8,13,-6,OBSIDIAN:0)
Block(-8,13,-5,OBSIDIAN:0)
Block(-8,13,-4,OBSIDIAN:0)
Block(-8,13,-3,OBSIDIAN:0)
Block(-8,13,-2,OBSIDIAN:0)
Block(-8,13,-1,OBSIDIAN:0)
Block(-8,13,0,OBSIDIAN:0)
Block(-8,13,1,OBSIDIAN:0)
Block(-8,13,2,OBSIDIAN:0)
Block(-8,13,3,OBSIDIAN:0)
Block(-8,13,4,OBSIDIAN:0)
Block(-8,13,5,OBSIDIAN:0)
Block(-8,13,6,OBSIDIAN:0)
Block(-8,13,7,OBSIDIAN:0)
Block(-8,13,8,OBSIDIAN:0)
Block(-8,14,-7,OBSIDIAN:0)
Block(-8,14,-6,OBSIDIAN:0)
Block(-8,14,-5,OBSIDIAN:0)
Block(-8,14,-4,OBSIDIAN:0)
Block(-8,14,-3,OBSIDIAN:0)
Block(-8,14,-2,OBSIDIAN:0)
Block(-8,14,-1,OBSIDIAN:0)
Block(-8,14,0,OBSIDIAN:0)
Block(-8,14,1,OBSIDIAN:0)
Block(-8,14,2,OBSIDIAN:0)
Block(-8,14,3,OBSIDIAN:0)
Block(-8,14,4,OBSIDIAN:0)
Block(-8,14,5,OBSIDIAN:0)
Block(-8,14,6,OBSIDIAN:0)
Block(-8,14,7,OBSIDIAN:0)
Block(-8,14,8,OBSIDIAN:0)
Block(-8,15,-7,OBSIDIAN:0)
Block(-8,15,-6,OBSIDIAN:0)
Block(-8,15,-5,OBSIDIAN:0)
Block(-8,15,-4,OBSIDIAN:0)
Block(-8,15,-3,OBSIDIAN:0)
Block(-8,15,-2,OBSIDIAN:0)
Block(-8,15,-1,OBSIDIAN:0)
Block(-8,15,0,OBSIDIAN:0)
Block(-8,15,1,OBSIDIAN:0)
Block(-8,15,2,OBSIDIAN:0)
Block(-8,15,3,OBSIDIAN:0)
Block(-8,15,4,OBSIDIAN:0)
Block(-8,15,5,OBSIDIAN:0)
Block(-8,15,6,OBSIDIAN:0)
Block(-8,15,7,OBSIDIAN:0)
Block(-8,15,8,OBSIDIAN:0)
Block(-8,16,-7,OBSIDIAN:0)
Block(-8,16,-6,OBSIDIAN:0)
Block(-8,16,-5,OBSIDIAN:0)
Block(-8,16,-4,OBSIDIAN:0)
Block(-8,16,-3,OBSIDIAN:0)
Block(-8,16,-2,OBSIDIAN:0)
Block(-8,16,-1,OBSIDIAN:0)
Block(-8,16,0,OBSIDIAN:0)
Block(-8,16,1,OBSIDIAN:0)
Block(-8,16,2,OBSIDIAN:0)
Block(-8,16,3,OBSIDIAN:0)
Block(-8,16,4,OBSIDIAN:0)
Block(-8,16,5,OBSIDIAN:0)
Block(-8,16,6,OBSIDIAN:0)
Block(-8,16,7,OBSIDIAN:0)
Block(-8,16,8,OBSIDIAN:0)
Block(-8,17,-7,CONCRETE:7)
Block(-8,17,-6,CONCRETE:7)
Block(-8,17,-5,CONCRETE:7)
Block(-8,17,-4,CONCRETE:7)
Block(-8,17,-3,CONCRETE:7)
Block(-8,17,-2,CONCRETE:7)
Block(-8,17,-1,CONCRETE:7)
Block(-8,17,0,CONCRETE:7)
Block(-8,17,1,CONCRETE:7)
Block(-8,17,2,CONCRETE:7)
Block(-8,17,3,CONCRETE:7)
Block(-8,17,4,CONCRETE:7)
Block(-8,17,5,CONCRETE:7)
Block(-8,17,6,CONCRETE:7)
Block(-8,17,7,CONCRETE:7)
Block(-8,17,8,CONCRETE:7)
Block(-8,18,-7,STEP:8)
Block(-8,18,-6,OBSIDIAN:0)
Block(-8,18,-3,CONCRETE:7)
Block(-8,18,-2,OBSIDIAN:0)
Block(-8,18,-1,CONCRETE:7)
#RandomBlock(-8,18,0,AIR:0,30,CHEST:5,../../../../../Chests/Loot/junk_loot.nbt,10,CHEST:5,../../../../../Chests/Loot/simple_dungeon.nbt,5,CHEST:5,../../../../../Chests/Loot/moderncity_junk_loot.nbt,65,CHEST:3,../../../../../Chests/Loot/moderncity_junk_loot.nbt,20,CHEST:3,../../../../../Chests/Loot/moderncity_common_loot.nbt,5,CHEST:3,../../../../../Chests/Loot/moderncity_rare_loot.nbt,3,CHEST:3,../../../../../Chests/Loot/moderncity_epic_loot.nbt,1,CHEST:3,../../../../../Chests/Loot/moderncity_junk_loot.nbt,100)
RandomBlock(-8,18,1,AIR,90,IRON_TRAPDOOR:13,100)
Block(-8,18,3,IRON_FENCE:0)
Block(-8,18,7,IRON_DOOR_BLOCK:3)
Block(-8,19,-6,STEP:8)
Block(-8,19,-3,CONCRETE:7)
Block(-8,19,-2,OBSIDIAN:0)
Block(-8,19,-1,CONCRETE:7)
Block(-8,19,0,STEP:8)
Block(-8,19,1,QUARTZ_STAIRS:7)
Block(-8,19,3,IRON_FENCE:0)
Block(-8,19,7,IRON_DOOR_BLOCK:9)
Block(-8,20,-7,STEP:8)
Block(-8,20,-6,OBSIDIAN:0)
Block(-8,20,-5,STEP:8)
Block(-8,20,-4,STEP:8)
Block(-8,20,-3,CONCRETE:7)
Block(-8,20,-2,OBSIDIAN:0)
Block(-8,20,-1,CONCRETE:7)
#RandomBlock(-8,20,0,AIR:0,30,CHEST:5,../../../../../Chests/Loot/junk_loot.nbt,10,CHEST:5,../../../../../Chests/Loot/simple_dungeon.nbt,5,CHEST:5,../../../../../Chests/Loot/moderncity_junk_loot.nbt,65,CHEST:3,../../../../../Chests/Loot/moderncity_junk_loot.nbt,20,CHEST:3,../../../../../Chests/Loot/moderncity_common_loot.nbt,5,CHEST:3,../../../../../Chests/Loot/moderncity_rare_loot.nbt,3,CHEST:3,../../../../../Chests/Loot/moderncity_epic_loot.nbt,1,CHEST:3,../../../../../Chests/Loot/moderncity_junk_loot.nbt,100)
RandomBlock(-8,20,1,AIR,90,IRON_TRAPDOOR:13,100)
Block(-8,20,3,IRON_FENCE:0)
Block(-8,20,7,OBSIDIAN:0)
Block(-8,21,-7,CONCRETE:7)
Block(-8,21,-6,CONCRETE:7)
Block(-8,21,-5,CONCRETE:7)
Block(-8,21,-4,CONCRETE:7)
Block(-8,21,-3,CONCRETE:7)
Block(-8,21,-2,OBSIDIAN:0)
Block(-8,21,-1,CONCRETE:7)
Block(-8,21,0,STEP:0)
Block(-8,21,1,QUARTZ_STAIRS:7)
Block(-8,21,2,STEP:8)
Block(-8,21,3,STEP:8)
Block(-8,21,4,STEP:8)
Block(-8,21,5,STEP:8)
Block(-8,21,6,STEP:8)
Block(-8,21,7,CONCRETE:7)
Block(-8,21,8,STEP:8)
Block(-8,22,-7,OBSIDIAN:0)
Block(-8,22,-6,OBSIDIAN:0)
Block(-8,22,-5,OBSIDIAN:0)
Block(-8,22,-4,OBSIDIAN:0)
Block(-8,22,-3,OBSIDIAN:0)
Block(-8,22,-2,OBSIDIAN:0)
Block(-8,22,-1,CONCRETE:7)
Block(-8,22,0,CONCRETE:7)
Block(-8,22,1,CONCRETE:7)
Block(-8,22,2,CONCRETE:7)
Block(-8,22,3,CONCRETE:7)
Block(-8,22,4,CONCRETE:7)
Block(-8,22,5,CONCRETE:7)
Block(-8,22,6,CONCRETE:7)
Block(-8,22,7,CONCRETE:7)
Block(-8,22,8,CONCRETE:7)
Block(-8,23,-7,CONCRETE:0)
Block(-8,23,-6,CONCRETE:0)
Block(-8,23,-5,CONCRETE:0)
Block(-8,23,-4,CONCRETE:0)
Block(-8,23,-3,CONCRETE:0)
Block(-8,23,-2,OBSIDIAN:0)
Block(-8,23,-1,OBSIDIAN:0)
Block(-8,23,0,OBSIDIAN:0)
Block(-8,23,1,OBSIDIAN:0)
Block(-8,23,2,OBSIDIAN:0)
Block(-8,23,3,OBSIDIAN:0)
Block(-8,23,4,OBSIDIAN:0)
Block(-8,23,5,OBSIDIAN:0)
Block(-8,23,6,OBSIDIAN:0)
Block(-8,23,7,OBSIDIAN:0)
Block(-8,23,8,OBSIDIAN:0)
Block(-8,24,-5,QUARTZ_STAIRS:2)
Block(-8,24,-4,CONCRETE:0)
Block(-8,24,-3,CONCRETE:0)
Block(-8,24,-2,CONCRETE:0)
Block(-8,24,-1,CONCRETE:7)
Block(-8,24,0,CONCRETE:0)
Block(-8,24,1,CONCRETE:0)
Block(-8,24,2,CONCRETE:0)
Block(-8,24,3,CONCRETE:15)
Block(-8,24,4,STONE:6)
Block(-8,24,5,CONCRETE:0)
Block(-8,24,6,STONE:4)
Block(-8,24,7,STONE:4)
Block(-8,24,8,CONCRETE:0)
Block(-8,25,5,DARK_OAK_STAIRS:5)
Block(-8,25,6,DARK_OAK_STAIRS:5)
Block(-8,25,7,DARK_OAK_STAIRS:5)
Block(-8,25,8,DARK_OAK_STAIRS:5)
Block(-8,27,-1,QUARTZ_STAIRS:0)
Block(-8,27,0,STAINED_GLASS:15)
Block(-8,28,-1,STEP:8)
Block(-8,28,0,STAINED_GLASS:15)
Block(-8,29,-3,STEP:15)
Block(-8,29,-2,CONCRETE:0)
Block(-8,29,-1,CONCRETE:0)
Block(-8,29,0,STEP:7)
Block(-8,30,-1,CONCRETE:7)
Block(-8,31,-1,STAINED_GLASS_PANE:15)
Block(-8,32,-1,STAINED_GLASS_PANE:14)
Block(-8,33,-1,STAINED_GLASS_PANE:15)
Block(-8,34,-1,STAINED_GLASS_PANE:14)
Block(-8,35,-1,STAINED_GLASS_PANE:15)
Block(-8,36,-1,CONCRETE:7)
Block(-8,36,0,QUARTZ_STAIRS:7)
Block(-8,37,-1,STEP:7)
Block(-8,37,0,CONCRETE:0)
Block(-8,38,-5,STEP:15)
Block(-8,38,-4,STEP:15)
Block(-8,38,-3,STEP:15)
Block(-8,38,-2,STEP:15)
Block(-8,38,-1,QUARTZ_STAIRS:6)
Block(-8,38,0,CONCRETE:0)
Block(-8,38,1,QUARTZ_STAIRS:7)
Block(-8,39,-6,QUARTZ_STAIRS:6)
Block(-8,39,-5,CONCRETE:0)
Block(-8,39,-4,CONCRETE:0)
Block(-8,39,-3,CONCRETE:0)
Block(-8,39,-2,CONCRETE:0)
Block(-8,39,-1,CONCRETE:0)
Block(-8,39,0,CONCRETE:8)
Block(-8,39,1,CONCRETE:0)
Block(-8,39,3,QUARTZ_STAIRS:4)
Block(-8,39,5,CONCRETE:0)
Block(-8,39,8,CONCRETE:0)
Block(-8,40,-6,STEP:7)
Block(-8,40,-5,STEP:7)
Block(-8,40,-4,STEP:7)
Block(-8,40,-3,DOUBLE_STEP:7)
Block(-8,40,-2,DOUBLE_STEP:7)
Block(-8,40,-1,STEP:8)
Block(-8,40,0,STEP:15)
Block(-8,40,1,DOUBLE_STEP:7)
Block(-8,40,2,STEP:15)
Block(-8,40,3,DOUBLE_STEP:7)
Block(-8,40,4,STEP:15)
Block(-8,40,5,DOUBLE_STEP:0)
Block(-8,40,6,STEP:15)
Block(-8,40,7,STEP:15)
Block(-8,40,8,DOUBLE_STEP:0)
Block(-8,41,-3,STAINED_GLASS_PANE:15)
Block(-8,44,8,CONCRETE:7)
Block(-8,45,8,STAINED_GLASS_PANE:15)
Block(-8,46,8,STAINED_GLASS_PANE:15)
Block(-8,47,8,STAINED_GLASS_PANE:15)
Block(-8,48,8,STAINED_GLASS_PANE:15)
Block(-8,49,8,CONCRETE:7)
Block(-8,50,8,CONCRETE:0)
Block(-8,51,8,CONCRETE:7)
Block(-7,0,-7,CONCRETE:7)
Block(-7,0,-6,CONCRETE:7)
Block(-7,0,-5,CONCRETE:7)
Block(-7,0,-4,CONCRETE:7)
Block(-7,0,-3,CONCRETE:7)
Block(-7,0,-2,CONCRETE:7)
Block(-7,0,-1,CONCRETE:7)
Block(-7,0,0,CONCRETE:7)
Block(-7,0,1,CONCRETE:7)
Block(-7,0,2,CONCRETE:7)
Block(-7,0,3,CONCRETE:7)
Block(-7,0,4,CONCRETE:7)
Block(-7,0,5,CONCRETE:7)
Block(-7,0,6,CONCRETE:7)
Block(-7,0,7,CONCRETE:7)
Block(-7,0,8,CONCRETE:7)
Block(-7,1,-7,OBSIDIAN:0)
Block(-7,1,-6,OBSIDIAN:0)
Block(-7,1,-5,OBSIDIAN:0)
Block(-7,1,-4,OBSIDIAN:0)
Block(-7,1,-3,OBSIDIAN:0)
Block(-7,1,-2,OBSIDIAN:0)
Block(-7,1,-1,OBSIDIAN:0)
Block(-7,1,0,OBSIDIAN:0)
Block(-7,1,1,OBSIDIAN:0)
Block(-7,1,2,OBSIDIAN:0)
Block(-7,1,3,OBSIDIAN:0)
Block(-7,1,4,OBSIDIAN:0)
Block(-7,1,5,OBSIDIAN:0)
Block(-7,1,6,OBSIDIAN:0)
Block(-7,1,7,OBSIDIAN:0)
Block(-7,1,8,OBSIDIAN:0)
Block(-7,2,-7,OBSIDIAN:0)
Block(-7,2,-6,OBSIDIAN:0)
Block(-7,2,-5,OBSIDIAN:0)
Block(-7,2,-4,OBSIDIAN:0)
Block(-7,2,-3,OBSIDIAN:0)
Block(-7,2,-2,OBSIDIAN:0)
Block(-7,2,-1,OBSIDIAN:0)
Block(-7,2,0,OBSIDIAN:0)
Block(-7,2,1,OBSIDIAN:0)
Block(-7,2,2,OBSIDIAN:0)
Block(-7,2,3,OBSIDIAN:0)
Block(-7,2,4,OBSIDIAN:0)
Block(-7,2,5,OBSIDIAN:0)
Block(-7,2,6,OBSIDIAN:0)
Block(-7,2,7,OBSIDIAN:0)
Block(-7,2,8,OBSIDIAN:0)
Block(-7,3,-7,STATIONARY_LAVA:0)
Block(-7,3,-6,STATIONARY_LAVA:0)
Block(-7,3,-5,STATIONARY_LAVA:0)
Block(-7,3,-4,STATIONARY_LAVA:0)
Block(-7,3,-3,STATIONARY_LAVA:0)
Block(-7,3,-2,STATIONARY_LAVA:0)
Block(-7,3,-1,STATIONARY_LAVA:0)
Block(-7,3,0,STATIONARY_LAVA:0)
Block(-7,3,1,STATIONARY_LAVA:0)
Block(-7,3,2,STATIONARY_LAVA:0)
Block(-7,3,3,STATIONARY_LAVA:0)
Block(-7,3,4,STATIONARY_LAVA:0)
Block(-7,3,5,STATIONARY_LAVA:0)
Block(-7,3,6,STATIONARY_LAVA:0)
Block(-7,3,7,STATIONARY_LAVA:0)
Block(-7,3,8,STATIONARY_LAVA:0)
Block(-7,4,-7,OBSIDIAN:0)
Block(-7,4,-6,OBSIDIAN:0)
Block(-7,4,-5,OBSIDIAN:0)
Block(-7,4,-4,OBSIDIAN:0)
Block(-7,4,-3,OBSIDIAN:0)
Block(-7,4,-2,OBSIDIAN:0)
Block(-7,4,-1,OBSIDIAN:0)
Block(-7,4,0,OBSIDIAN:0)
Block(-7,4,1,OBSIDIAN:0)
Block(-7,4,2,OBSIDIAN:0)
Block(-7,4,3,OBSIDIAN:0)
Block(-7,4,4,OBSIDIAN:0)
Block(-7,4,5,OBSIDIAN:0)
Block(-7,4,6,OBSIDIAN:0)
Block(-7,4,7,OBSIDIAN:0)
Block(-7,4,8,OBSIDIAN:0)
Block(-7,5,-7,IRON_PLATE:0)
Block(-7,5,-6,IRON_PLATE:0)
Block(-7,5,-5,IRON_PLATE:0)
Block(-7,5,-4,IRON_PLATE:0)
Block(-7,5,-3,IRON_PLATE:0)
Block(-7,5,-2,OBSIDIAN:0)
Block(-7,5,-1,IRON_PLATE:0)
Block(-7,5,0,IRON_PLATE:0)
Block(-7,5,1,IRON_PLATE:0)
Block(-7,5,2,IRON_PLATE:0)
Block(-7,5,3,IRON_PLATE:0)
Block(-7,5,4,IRON_PLATE:0)
Block(-7,5,5,IRON_PLATE:0)
Block(-7,5,6,IRON_PLATE:0)
Block(-7,5,7,IRON_PLATE:0)
Block(-7,5,8,IRON_PLATE:0)
Block(-7,6,-7,STONE_BUTTON:1)
Block(-7,6,-4,STONE_BUTTON:1)
Block(-7,6,-2,OBSIDIAN:0)
Block(-7,6,-1,STONE_BUTTON:3)
Block(-7,7,-2,OBSIDIAN:0)
Block(-7,8,-7,STONE_BUTTON:1)
Block(-7,8,-4,STONE_BUTTON:1)
Block(-7,8,-2,OBSIDIAN:0)
Block(-7,8,6,STEP:8)
Block(-7,8,7,STEP:8)
Block(-7,9,-2,OBSIDIAN:0)
Block(-7,10,-7,STEP:8)
Block(-7,10,-6,STEP:8)
Block(-7,10,-5,STEP:8)
Block(-7,10,-4,STEP:8)
Block(-7,10,-3,STEP:8)
Block(-7,10,-2,OBSIDIAN:0)
Block(-7,10,-1,STEP:8)
Block(-7,10,0,STEP:8)
Block(-7,10,1,STEP:8)
Block(-7,10,2,STEP:8)
Block(-7,10,3,STEP:8)
Block(-7,10,4,STEP:8)
Block(-7,10,5,STEP:8)
Block(-7,10,6,STEP:8)
Block(-7,10,7,STEP:8)
Block(-7,10,8,STEP:8)
Block(-7,11,-7,OBSIDIAN:0)
Block(-7,11,-6,OBSIDIAN:0)
Block(-7,11,-5,OBSIDIAN:0)
Block(-7,11,-4,OBSIDIAN:0)
Block(-7,11,-3,OBSIDIAN:0)
Block(-7,11,-2,OBSIDIAN:0)
Block(-7,11,-1,OBSIDIAN:0)
Block(-7,11,0,OBSIDIAN:0)
Block(-7,11,1,OBSIDIAN:0)
Block(-7,11,2,OBSIDIAN:0)
Block(-7,11,3,OBSIDIAN:0)
Block(-7,11,4,OBSIDIAN:0)
Block(-7,11,5,OBSIDIAN:0)
Block(-7,11,6,OBSIDIAN:0)
Block(-7,11,7,OBSIDIAN:0)
Block(-7,11,8,OBSIDIAN:0)
Block(-7,12,-7,STATIONARY_LAVA:0)
Block(-7,12,-6,STATIONARY_LAVA:0)
Block(-7,12,-5,STATIONARY_LAVA:0)
Block(-7,12,-4,STATIONARY_LAVA:0)
Block(-7,12,-3,STATIONARY_LAVA:0)
Block(-7,12,-2,STATIONARY_LAVA:0)
Block(-7,12,-1,STATIONARY_LAVA:0)
Block(-7,12,0,STATIONARY_LAVA:0)
Block(-7,12,1,STATIONARY_LAVA:0)
Block(-7,12,2,STATIONARY_LAVA:0)
Block(-7,12,3,STATIONARY_LAVA:0)
Block(-7,12,4,STATIONARY_LAVA:0)
Block(-7,12,5,STATIONARY_LAVA:0)
Block(-7,12,6,STATIONARY_LAVA:0)
Block(-7,12,7,STATIONARY_LAVA:0)
Block(-7,12,8,STATIONARY_LAVA:0)
Block(-7,13,-7,OBSIDIAN:0)
Block(-7,13,-6,OBSIDIAN:0)
Block(-7,13,-5,OBSIDIAN:0)
Block(-7,13,-4,OBSIDIAN:0)
Block(-7,13,-3,OBSIDIAN:0)
Block(-7,13,-2,OBSIDIAN:0)
Block(-7,13,-1,OBSIDIAN:0)
Block(-7,13,0,OBSIDIAN:0)
Block(-7,13,1,OBSIDIAN:0)
Block(-7,13,2,OBSIDIAN:0)
Block(-7,13,3,OBSIDIAN:0)
Block(-7,13,4,OBSIDIAN:0)
Block(-7,13,5,OBSIDIAN:0)
Block(-7,13,6,OBSIDIAN:0)
Block(-7,13,7,OBSIDIAN:0)
Block(-7,13,8,OBSIDIAN:0)
Block(-7,14,-7,OBSIDIAN:0)
Block(-7,14,-6,OBSIDIAN:0)
Block(-7,14,-5,OBSIDIAN:0)
Block(-7,14,-4,OBSIDIAN:0)
Block(-7,14,-3,OBSIDIAN:0)
Block(-7,14,-2,OBSIDIAN:0)
Block(-7,14,-1,OBSIDIAN:0)
Block(-7,14,0,OBSIDIAN:0)
Block(-7,14,1,OBSIDIAN:0)
Block(-7,14,2,OBSIDIAN:0)
Block(-7,14,3,OBSIDIAN:0)
Block(-7,14,4,OBSIDIAN:0)
Block(-7,14,5,OBSIDIAN:0)
Block(-7,14,6,OBSIDIAN:0)
Block(-7,14,7,OBSIDIAN:0)
Block(-7,14,8,OBSIDIAN:0)
Block(-7,15,-7,OBSIDIAN:0)
Block(-7,15,-6,OBSIDIAN:0)
Block(-7,15,-5,OBSIDIAN:0)
Block(-7,15,-4,OBSIDIAN:0)
Block(-7,15,-3,OBSIDIAN:0)
Block(-7,15,-2,OBSIDIAN:0)
Block(-7,15,-1,OBSIDIAN:0)
Block(-7,15,0,OBSIDIAN:0)
Block(-7,15,1,OBSIDIAN:0)
Block(-7,15,2,OBSIDIAN:0)
Block(-7,15,3,OBSIDIAN:0)
Block(-7,15,4,OBSIDIAN:0)
Block(-7,15,5,OBSIDIAN:0)
Block(-7,15,6,OBSIDIAN:0)
Block(-7,15,7,OBSIDIAN:0)
Block(-7,15,8,OBSIDIAN:0)
Block(-7,16,-7,OBSIDIAN:0)
Block(-7,16,-6,OBSIDIAN:0)
Block(-7,16,-5,OBSIDIAN:0)
Block(-7,16,-4,OBSIDIAN:0)
Block(-7,16,-3,OBSIDIAN:0)
Block(-7,16,-2,OBSIDIAN:0)
Block(-7,16,-1,OBSIDIAN:0)
Block(-7,16,0,OBSIDIAN:0)
Block(-7,16,1,OBSIDIAN:0)
Block(-7,16,2,OBSIDIAN:0)
Block(-7,16,3,OBSIDIAN:0)
Block(-7,16,4,OBSIDIAN:0)
Block(-7,16,5,OBSIDIAN:0)
Block(-7,16,6,OBSIDIAN:0)
Block(-7,16,7,OBSIDIAN:0)
Block(-7,16,8,OBSIDIAN:0)
Block(-7,17,-7,CONCRETE:7)
Block(-7,17,-6,CONCRETE:7)
Block(-7,17,-5,CONCRETE:7)
Block(-7,17,-4,CONCRETE:7)
Block(-7,17,-3,CONCRETE:7)
Block(-7,17,-2,CONCRETE:7)
Block(-7,17,-1,CONCRETE:7)
Block(-7,17,0,CONCRETE:7)
Block(-7,17,1,CONCRETE:7)
Block(-7,17,2,CONCRETE:7)
Block(-7,17,3,CONCRETE:7)
Block(-7,17,4,CONCRETE:7)
Block(-7,17,5,CONCRETE:7)
Block(-7,17,6,CONCRETE:7)
Block(-7,17,7,CONCRETE:7)
Block(-7,17,8,CONCRETE:7)
RandomBlock(-7,18,-7,AIR,95,STANDING_BANNER:8,../AllScraperData/skyscraper_8x6_01/474-bannerC64R16.nbt,100)
Block(-7,18,-6,OBSIDIAN:0)
Block(-7,18,-3,CONCRETE:7)
Block(-7,18,-2,OBSIDIAN:0)
Block(-7,18,-1,CONCRETE:7)
Block(-7,18,0,STONE:4)
Block(-7,18,1,STONE:4)
Block(-7,18,2,LEVER:11)
Block(-7,18,3,OBSIDIAN:0)
Block(-7,18,4,IRON_DOOR_BLOCK:0)
Block(-7,18,5,STONE:4)
Block(-7,18,6,STONE:4)
Block(-7,18,7,OBSIDIAN:0)
RandomBlock(-7,19,-7,AIR,90,IRON_TRAPDOOR:0,100)
Block(-7,19,-6,IRON_FENCE:0)
Block(-7,19,-3,CONCRETE:7)
Block(-7,19,-2,OBSIDIAN:0)
Block(-7,19,-1,CONCRETE:7)
Block(-7,19,0,STONE:4)
Block(-7,19,1,STONE:4)
Block(-7,19,3,OBSIDIAN:0)
Block(-7,19,4,IRON_DOOR_BLOCK:8)
Block(-7,19,5,STONE:4)
Block(-7,19,6,STONE:4)
Block(-7,19,7,OBSIDIAN:0)
Block(-7,20,-7,STEP:8)
Block(-7,20,-6,OBSIDIAN:0)
Block(-7,20,-5,STEP:8)
Block(-7,20,-4,STEP:8)
Block(-7,20,-3,CONCRETE:7)
Block(-7,20,-2,OBSIDIAN:0)
Block(-7,20,-1,CONCRETE:7)
Block(-7,20,0,STONE:4)
Block(-7,20,1,STONE:4)
Block(-7,20,2,LEVER:11)
Block(-7,20,3,OBSIDIAN:0)
Block(-7,20,4,IRON_FENCE:0)
Block(-7,20,5,STONE:4)
Block(-7,20,6,STONE:4)
Block(-7,20,7,OBSIDIAN:0)
Block(-7,21,-7,CONCRETE:7)
Block(-7,21,-6,CONCRETE:7)
Block(-7,21,-5,CONCRETE:7)
Block(-7,21,-4,CONCRETE:7)
Block(-7,21,-3,CONCRETE:7)
Block(-7,21,-2,OBSIDIAN:0)
Block(-7,21,-1,CONCRETE:7)
Block(-7,21,0,STONE:4)
Block(-7,21,1,STONE:4)
Block(-7,21,2,STEP:8)
Block(-7,21,3,OBSIDIAN:0)
Block(-7,21,4,STEP:8)
Block(-7,21,5,STONE:4)
Block(-7,21,6,STONE:4)
Block(-7,21,7,CONCRETE:7)
Block(-7,21,8,STEP:8)
Block(-7,22,-7,OBSIDIAN:0)
Block(-7,22,-6,OBSIDIAN:0)
Block(-7,22,-5,OBSIDIAN:0)
Block(-7,22,-4,OBSIDIAN:0)
Block(-7,22,-3,OBSIDIAN:0)
Block(-7,22,-2,OBSIDIAN:0)
Block(-7,22,-1,CONCRETE:7)
Block(-7,22,0,CONCRETE:7)
Block(-7,22,1,CONCRETE:7)
Block(-7,22,2,CONCRETE:7)
Block(-7,22,3,CONCRETE:7)
Block(-7,22,4,CONCRETE:7)
Block(-7,22,5,CONCRETE:7)
Block(-7,22,6,CONCRETE:7)
Block(-7,22,7,CONCRETE:7)
Block(-7,22,8,CONCRETE:7)
Block(-7,23,-7,CONCRETE:0)
Block(-7,23,-6,CONCRETE:0)
Block(-7,23,-5,CONCRETE:0)
Block(-7,23,-4,CONCRETE:0)
Block(-7,23,-3,CONCRETE:0)
Block(-7,23,-2,OBSIDIAN:0)
Block(-7,23,-1,OBSIDIAN:0)
Block(-7,23,0,OBSIDIAN:0)
Block(-7,23,1,OBSIDIAN:0)
Block(-7,23,2,OBSIDIAN:0)
Block(-7,23,3,OBSIDIAN:0)
Block(-7,23,4,OBSIDIAN:0)
Block(-7,23,5,OBSIDIAN:0)
Block(-7,23,6,OBSIDIAN:0)
Block(-7,23,7,OBSIDIAN:0)
Block(-7,23,8,OBSIDIAN:0)
Block(-7,24,-5,QUARTZ_STAIRS:2)
Block(-7,24,-4,CONCRETE:0)
Block(-7,24,-3,CONCRETE:0)
Block(-7,24,-2,CONCRETE:0)
Block(-7,24,-1,CONCRETE:7)
Block(-7,24,0,CONCRETE:0)
Block(-7,24,1,STONE:4)
Block(-7,24,2,CONCRETE:0)
Block(-7,24,3,CONCRETE:0)
Block(-7,24,4,CONCRETE:15)
Block(-7,24,5,STONE:6)
Block(-7,24,6,CONCRETE:0)
Block(-7,24,7,CONCRETE:0)
Block(-7,24,8,STONE:6)
Block(-7,25,-2,IRON_DOOR_BLOCK:0)
Block(-7,25,-1,QUARTZ_STAIRS:0)
Block(-7,25,0,STAINED_GLASS:15)
Block(-7,25,5,DARK_OAK_STAIRS:0)
Block(-7,25,7,DARK_OAK_STAIRS:0)
Block(-7,26,-2,IRON_DOOR_BLOCK:9)
Block(-7,26,-1,QUARTZ_STAIRS:1)
Block(-7,26,0,STAINED_GLASS:15)
Block(-7,27,-1,QUARTZ_STAIRS:5)
Block(-7,27,0,STAINED_GLASS:15)
Block(-7,28,-1,QUARTZ_STAIRS:4)
Block(-7,28,0,STAINED_GLASS:15)
Block(-7,29,-3,STEP:15)
Block(-7,29,-2,CONCRETE:0)
Block(-7,29,-1,CONCRETE:0)
Block(-7,29,0,QUARTZ_STAIRS:0)
Block(-7,30,-2,STEP:7)
Block(-7,30,-1,CONCRETE:7)
Block(-7,31,-1,STAINED_GLASS_PANE:14)
Block(-7,32,-1,STAINED_GLASS_PANE:15)
Block(-7,33,-1,STAINED_GLASS_PANE:14)
Block(-7,34,-1,STAINED_GLASS_PANE:15)
Block(-7,35,-1,STAINED_GLASS_PANE:14)
Block(-7,36,-2,STEP:15)
Block(-7,36,-1,CONCRETE:7)
Block(-7,37,-2,QUARTZ_STAIRS:6)
Block(-7,37,-1,STEP:7)
Block(-7,37,0,CONCRETE:8)
Block(-7,38,-6,QUARTZ_STAIRS:6)
Block(-7,38,-5,CONCRETE:0)
Block(-7,38,-4,CONCRETE:0)
Block(-7,38,-3,CONCRETE:0)
Block(-7,38,-2,CONCRETE:0)
Block(-7,38,-1,CONCRETE:0)
Block(-7,38,0,CONCRETE:8)
Block(-7,39,-6,QUARTZ_STAIRS:1)
Block(-7,39,-5,QUARTZ_STAIRS:1)
Block(-7,39,-4,QUARTZ_STAIRS:1)
Block(-7,39,-3,COBBLE_WALL:0)
Block(-7,39,-2,CONCRETE:0)
Block(-7,39,-1,CONCRETE:8)
Block(-7,39,0,CONCRETE:8)
Block(-7,39,3,CONCRETE:0)
Block(-7,39,5,CONCRETE:0)
Block(-7,39,8,CONCRETE:0)
Block(-7,40,-3,QUARTZ_STAIRS:6)
Block(-7,40,-2,CONCRETE:0)
Block(-7,40,-1,STEP:8)
Block(-7,40,0,STEP:15)
Block(-7,40,1,DOUBLE_STEP:0)
Block(-7,40,2,STEP:15)
Block(-7,40,3,DOUBLE_STEP:7)
Block(-7,40,4,STEP:8)
Block(-7,40,5,DOUBLE_STEP:7)
Block(-7,40,6,STEP:8)
Block(-7,40,7,STEP:8)
Block(-7,40,8,DOUBLE_STEP:7)
Block(-7,41,-3,CONCRETE:0)
Block(-7,41,-2,STAINED_GLASS_PANE:15)
Block(-7,41,6,STAINED_GLASS_PANE:0)
Block(-7,41,7,STAINED_GLASS_PANE:15)
Block(-7,41,8,CONCRETE:7)
Block(-7,42,-3,COBBLE_WALL:0)
Block(-7,42,6,STAINED_GLASS_PANE:0)
Block(-7,42,7,STAINED_GLASS_PANE:15)
Block(-7,42,8,CONCRETE:7)
Block(-7,43,6,STAINED_GLASS_PANE:0)
Block(-7,43,7,STAINED_GLASS_PANE:15)
Block(-7,43,8,CONCRETE:7)
Block(-7,44,8,CONCRETE:7)
Block(-7,45,8,CONCRETE:7)
Block(-7,46,8,CONCRETE:0)
Block(-7,47,8,CONCRETE:7)
Block(-7,48,8,CONCRETE:7)
Block(-7,49,8,CONCRETE:7)
Block(-7,50,8,CONCRETE:0)
Block(-6,0,-7,CONCRETE:7)
Block(-6,0,-6,CONCRETE:7)
Block(-6,0,-5,CONCRETE:7)
Block(-6,0,-4,CONCRETE:7)
Block(-6,0,-3,CONCRETE:7)
Block(-6,0,-2,CONCRETE:7)
Block(-6,0,-1,CONCRETE:7)
Block(-6,0,0,CONCRETE:7)
Block(-6,0,1,CONCRETE:7)
Block(-6,0,2,CONCRETE:7)
Block(-6,0,3,CONCRETE:7)
Block(-6,0,4,CONCRETE:7)
Block(-6,0,5,CONCRETE:7)
Block(-6,0,6,CONCRETE:7)
Block(-6,0,7,CONCRETE:7)
Block(-6,0,8,CONCRETE:7)
Block(-6,1,-7,OBSIDIAN:0)
Block(-6,1,-6,OBSIDIAN:0)
Block(-6,1,-5,OBSIDIAN:0)
Block(-6,1,-4,OBSIDIAN:0)
Block(-6,1,-3,OBSIDIAN:0)
Block(-6,1,-2,OBSIDIAN:0)
Block(-6,1,-1,OBSIDIAN:0)
Block(-6,1,0,OBSIDIAN:0)
Block(-6,1,1,OBSIDIAN:0)
Block(-6,1,2,OBSIDIAN:0)
Block(-6,1,3,OBSIDIAN:0)
Block(-6,1,4,OBSIDIAN:0)
Block(-6,1,5,OBSIDIAN:0)
Block(-6,1,6,OBSIDIAN:0)
Block(-6,1,7,OBSIDIAN:0)
Block(-6,1,8,OBSIDIAN:0)
Block(-6,2,-7,OBSIDIAN:0)
Block(-6,2,-6,OBSIDIAN:0)
Block(-6,2,-5,OBSIDIAN:0)
Block(-6,2,-4,OBSIDIAN:0)
Block(-6,2,-3,OBSIDIAN:0)
Block(-6,2,-2,OBSIDIAN:0)
Block(-6,2,-1,OBSIDIAN:0)
Block(-6,2,0,OBSIDIAN:0)
Block(-6,2,1,OBSIDIAN:0)
Block(-6,2,2,OBSIDIAN:0)
Block(-6,2,3,OBSIDIAN:0)
Block(-6,2,4,OBSIDIAN:0)
Block(-6,2,5,OBSIDIAN:0)
Block(-6,2,6,OBSIDIAN:0)
Block(-6,2,7,OBSIDIAN:0)
Block(-6,2,8,OBSIDIAN:0)
Block(-6,3,-7,STATIONARY_LAVA:0)
Block(-6,3,-6,STATIONARY_LAVA:0)
Block(-6,3,-5,STATIONARY_LAVA:0)
Block(-6,3,-4,STATIONARY_LAVA:0)
Block(-6,3,-3,STATIONARY_LAVA:0)
Block(-6,3,-2,STATIONARY_LAVA:0)
Block(-6,3,-1,STATIONARY_LAVA:0)
Block(-6,3,0,STATIONARY_LAVA:0)
Block(-6,3,1,STATIONARY_LAVA:0)
Block(-6,3,2,STATIONARY_LAVA:0)
Block(-6,3,3,STATIONARY_LAVA:0)
Block(-6,3,4,STATIONARY_LAVA:0)
Block(-6,3,5,STATIONARY_LAVA:0)
Block(-6,3,6,STATIONARY_LAVA:0)
Block(-6,3,7,STATIONARY_LAVA:0)
Block(-6,3,8,STATIONARY_LAVA:0)
Block(-6,4,-7,OBSIDIAN:0)
Block(-6,4,-6,OBSIDIAN:0)
Block(-6,4,-5,OBSIDIAN:0)
Block(-6,4,-4,OBSIDIAN:0)
Block(-6,4,-3,OBSIDIAN:0)
Block(-6,4,-2,OBSIDIAN:0)
Block(-6,4,-1,OBSIDIAN:0)
Block(-6,4,0,OBSIDIAN:0)
Block(-6,4,1,OBSIDIAN:0)
Block(-6,4,2,OBSIDIAN:0)
Block(-6,4,3,OBSIDIAN:0)
Block(-6,4,4,OBSIDIAN:0)
Block(-6,4,5,OBSIDIAN:0)
Block(-6,4,6,OBSIDIAN:0)
Block(-6,4,7,OBSIDIAN:0)
Block(-6,4,8,OBSIDIAN:0)
Block(-6,5,-7,IRON_PLATE:0)
Block(-6,5,-6,IRON_PLATE:0)
Block(-6,5,-5,IRON_PLATE:0)
Block(-6,5,-4,IRON_PLATE:0)
Block(-6,5,-2,IRON_DOOR_BLOCK:1)
Block(-6,5,0,IRON_PLATE:0)
Block(-6,5,1,IRON_PLATE:0)
Block(-6,5,2,IRON_PLATE:0)
Block(-6,5,3,IRON_PLATE:0)
Block(-6,5,4,IRON_PLATE:0)
Block(-6,5,5,IRON_PLATE:0)
Block(-6,5,6,IRON_PLATE:0)
Block(-6,5,7,IRON_PLATE:0)
Block(-6,5,8,IRON_PLATE:0)
Block(-6,6,-2,IRON_DOOR_BLOCK:8)
Block(-6,7,-3,STONE_BUTTON:4)
Block(-6,7,-2,OBSIDIAN:0)
Block(-6,8,-4,STEP:8)
Block(-6,8,-3,STEP:8)
Block(-6,8,-2,OBSIDIAN:0)
Block(-6,8,-1,STEP:8)
Block(-6,8,0,STEP:8)
Block(-6,8,1,STEP:8)
Block(-6,8,2,STEP:8)
Block(-6,8,3,STEP:8)
Block(-6,8,4,STEP:8)
Block(-6,8,5,STEP:8)
Block(-6,8,6,STEP:8)
Block(-6,8,7,STEP:8)
Block(-6,8,8,STEP:8)
RandomBlock(-6,9,-4,AIR:0,20,TNT:0,100)
Block(-6,9,-3,DIODE_BLOCK_OFF:0)
Block(-6,9,-2,OBSIDIAN:0)
Block(-6,9,-1,REDSTONE_WIRE:0)
Block(-6,9,0,REDSTONE_WIRE:0)
Block(-6,9,1,REDSTONE_WIRE:0)
Block(-6,9,2,REDSTONE_WIRE:0)
Block(-6,9,3,REDSTONE_WIRE:0)
Block(-6,9,4,REDSTONE_WIRE:0)
Block(-6,9,5,REDSTONE_WIRE:0)
Block(-6,9,6,REDSTONE_WIRE:0)
Block(-6,9,7,REDSTONE_WIRE:0)
Block(-6,9,8,REDSTONE_WIRE:0)
Block(-6,10,-7,STEP:8)
Block(-6,10,-6,STEP:8)
Block(-6,10,-5,STEP:8)
Block(-6,10,-4,STEP:8)
Block(-6,10,-3,STEP:8)
Block(-6,10,-2,OBSIDIAN:0)
Block(-6,10,-1,STEP:8)
Block(-6,10,0,STEP:8)
Block(-6,10,1,STEP:8)
Block(-6,10,2,STEP:8)
Block(-6,10,3,STEP:8)
Block(-6,10,4,STEP:8)
Block(-6,10,5,STEP:8)
Block(-6,10,6,STEP:8)
Block(-6,10,7,STEP:8)
Block(-6,10,8,STEP:8)
Block(-6,11,-7,OBSIDIAN:0)
Block(-6,11,-6,OBSIDIAN:0)
Block(-6,11,-5,OBSIDIAN:0)
Block(-6,11,-4,OBSIDIAN:0)
Block(-6,11,-3,OBSIDIAN:0)
Block(-6,11,-2,OBSIDIAN:0)
Block(-6,11,-1,OBSIDIAN:0)
Block(-6,11,0,OBSIDIAN:0)
Block(-6,11,1,OBSIDIAN:0)
Block(-6,11,2,OBSIDIAN:0)
Block(-6,11,3,OBSIDIAN:0)
Block(-6,11,4,OBSIDIAN:0)
Block(-6,11,5,OBSIDIAN:0)
Block(-6,11,6,OBSIDIAN:0)
Block(-6,11,7,OBSIDIAN:0)
Block(-6,11,8,OBSIDIAN:0)
Block(-6,12,-7,STATIONARY_LAVA:0)
Block(-6,12,-6,STATIONARY_LAVA:0)
Block(-6,12,-5,STATIONARY_LAVA:0)
Block(-6,12,-4,STATIONARY_LAVA:0)
Block(-6,12,-3,STATIONARY_LAVA:0)
Block(-6,12,-2,STATIONARY_LAVA:0)
Block(-6,12,-1,STATIONARY_LAVA:0)
Block(-6,12,0,STATIONARY_LAVA:0)
Block(-6,12,1,STATIONARY_LAVA:0)
Block(-6,12,2,STATIONARY_LAVA:0)
Block(-6,12,3,STATIONARY_LAVA:0)
Block(-6,12,4,STATIONARY_LAVA:0)
Block(-6,12,5,STATIONARY_LAVA:0)
Block(-6,12,6,STATIONARY_LAVA:0)
Block(-6,12,7,STATIONARY_LAVA:0)
Block(-6,12,8,STATIONARY_LAVA:0)
Block(-6,13,-7,OBSIDIAN:0)
Block(-6,13,-6,OBSIDIAN:0)
Block(-6,13,-5,OBSIDIAN:0)
Block(-6,13,-4,OBSIDIAN:0)
Block(-6,13,-3,OBSIDIAN:0)
Block(-6,13,-2,OBSIDIAN:0)
Block(-6,13,-1,OBSIDIAN:0)
Block(-6,13,0,OBSIDIAN:0)
Block(-6,13,1,OBSIDIAN:0)
Block(-6,13,2,OBSIDIAN:0)
Block(-6,13,3,OBSIDIAN:0)
Block(-6,13,4,OBSIDIAN:0)
Block(-6,13,5,OBSIDIAN:0)
Block(-6,13,6,OBSIDIAN:0)
Block(-6,13,7,OBSIDIAN:0)
Block(-6,13,8,OBSIDIAN:0)
Block(-6,14,-7,OBSIDIAN:0)
Block(-6,14,-6,OBSIDIAN:0)
Block(-6,14,-5,OBSIDIAN:0)
Block(-6,14,-4,OBSIDIAN:0)
Block(-6,14,-3,OBSIDIAN:0)
Block(-6,14,-2,OBSIDIAN:0)
Block(-6,14,-1,OBSIDIAN:0)
Block(-6,14,0,OBSIDIAN:0)
Block(-6,14,1,OBSIDIAN:0)
Block(-6,14,2,OBSIDIAN:0)
Block(-6,14,3,OBSIDIAN:0)
Block(-6,14,4,OBSIDIAN:0)
Block(-6,14,5,OBSIDIAN:0)
Block(-6,14,6,OBSIDIAN:0)
Block(-6,14,7,OBSIDIAN:0)
Block(-6,14,8,OBSIDIAN:0)
Block(-6,15,-7,OBSIDIAN:0)
Block(-6,15,-6,OBSIDIAN:0)
Block(-6,15,-5,OBSIDIAN:0)
Block(-6,15,-4,OBSIDIAN:0)
Block(-6,15,-3,OBSIDIAN:0)
Block(-6,15,-2,OBSIDIAN:0)
Block(-6,15,-1,OBSIDIAN:0)
Block(-6,15,0,OBSIDIAN:0)
Block(-6,15,1,OBSIDIAN:0)
Block(-6,15,2,OBSIDIAN:0)
Block(-6,15,3,OBSIDIAN:0)
Block(-6,15,4,OBSIDIAN:0)
Block(-6,15,5,OBSIDIAN:0)
Block(-6,15,6,OBSIDIAN:0)
Block(-6,15,7,OBSIDIAN:0)
Block(-6,15,8,OBSIDIAN:0)
Block(-6,16,-7,OBSIDIAN:0)
Block(-6,16,-6,OBSIDIAN:0)
Block(-6,16,-5,OBSIDIAN:0)
Block(-6,16,-4,OBSIDIAN:0)
Block(-6,16,-3,OBSIDIAN:0)
Block(-6,16,-2,OBSIDIAN:0)
Block(-6,16,-1,OBSIDIAN:0)
Block(-6,16,0,OBSIDIAN:0)
Block(-6,16,1,OBSIDIAN:0)
Block(-6,16,2,OBSIDIAN:0)
Block(-6,16,3,OBSIDIAN:0)
Block(-6,16,4,OBSIDIAN:0)
Block(-6,16,5,OBSIDIAN:0)
Block(-6,16,6,OBSIDIAN:0)
Block(-6,16,7,OBSIDIAN:0)
Block(-6,16,8,OBSIDIAN:0)
Block(-6,17,-7,CONCRETE:7)
Block(-6,17,-6,CONCRETE:7)
Block(-6,17,-5,CONCRETE:7)
Block(-6,17,-4,CONCRETE:7)
Block(-6,17,-3,CONCRETE:7)
Block(-6,17,-2,CONCRETE:7)
Block(-6,17,-1,CONCRETE:7)
Block(-6,17,0,CONCRETE:7)
Block(-6,17,1,CONCRETE:7)
Block(-6,17,2,CONCRETE:7)
Block(-6,17,3,CONCRETE:7)
Block(-6,17,4,CONCRETE:7)
Block(-6,17,5,CONCRETE:7)
Block(-6,17,6,CONCRETE:7)
Block(-6,17,7,CONCRETE:7)
Block(-6,17,8,CONCRETE:7)
RandomBlock(-6,18,-7,AIR,95,STANDING_BANNER:8,../AllScraperData/skyscraper_8x6_01/481-bannerC64R16.nbt,100)
Block(-6,18,-6,OBSIDIAN:0)
Block(-6,18,-3,CONCRETE:7)
Block(-6,18,-2,OBSIDIAN:0)
Block(-6,18,-1,CONCRETE:7)
#RandomBlock(-6,18,0,AIR:0,30,CHEST:5,../../../../../Chests/Loot/junk_loot.nbt,10,CHEST:5,../../../../../Chests/Loot/simple_dungeon.nbt,5,CHEST:5,../../../../../Chests/Loot/moderncity_junk_loot.nbt,65,CHEST:3,../../../../../Chests/Loot/moderncity_junk_loot.nbt,20,CHEST:3,../../../../../Chests/Loot/moderncity_common_loot.nbt,5,CHEST:3,../../../../../Chests/Loot/moderncity_rare_loot.nbt,3,CHEST:3,../../../../../Chests/Loot/moderncity_epic_loot.nbt,1,CHEST:3,../../../../../Chests/Loot/moderncity_junk_loot.nbt,100)
RandomBlock(-6,18,1,AIR,90,IRON_TRAPDOOR:5,100)
RandomBlock(-6,18,5,AIR,90,IRON_TRAPDOOR:4,100)
#RandomBlock(-6,18,6,AIR:0,30,CHEST:5,../../../../../Chests/Loot/junk_loot.nbt,10,CHEST:5,../../../../../Chests/Loot/simple_dungeon.nbt,5,CHEST:5,../../../../../Chests/Loot/moderncity_junk_loot.nbt,65,CHEST:2,../../../../../Chests/Loot/moderncity_junk_loot.nbt,20,CHEST:2,../../../../../Chests/Loot/moderncity_common_loot.nbt,5,CHEST:2,../../../../../Chests/Loot/moderncity_rare_loot.nbt,3,CHEST:2,../../../../../Chests/Loot/moderncity_epic_loot.nbt,1,CHEST:2,../../../../../Chests/Loot/moderncity_junk_loot.nbt,100)
Block(-6,18,7,CONCRETE:7)
RandomBlock(-6,19,-7,AIR,90,IRON_TRAPDOOR:3,100)
Block(-6,19,-6,STAINED_GLASS_PANE:0)
Block(-6,19,-3,CONCRETE:7)
Block(-6,19,-2,OBSIDIAN:0)
Block(-6,19,-1,CONCRETE:7)
Block(-6,19,0,STEP:8)
Block(-6,19,1,QUARTZ_STAIRS:7)
RandomBlock(-6,19,5,AIR,90,IRON_TRAPDOOR:4,100)
#RandomBlock(-6,19,6,AIR:0,30,CHEST:5,../../../../../Chests/Loot/junk_loot.nbt,10,CHEST:5,../../../../../Chests/Loot/simple_dungeon.nbt,5,CHEST:5,../../../../../Chests/Loot/moderncity_junk_loot.nbt,65,CHEST:2,../../../../../Chests/Loot/moderncity_junk_loot.nbt,20,CHEST:2,../../../../../Chests/Loot/moderncity_common_loot.nbt,5,CHEST:2,../../../../../Chests/Loot/moderncity_rare_loot.nbt,3,CHEST:2,../../../../../Chests/Loot/moderncity_epic_loot.nbt,1,CHEST:2,../../../../../Chests/Loot/moderncity_junk_loot.nbt,100)
Block(-6,19,7,CONCRETE:7)
Block(-6,20,-7,STEP:8)
Block(-6,20,-6,OBSIDIAN:0)
Block(-6,20,-5,STEP:8)
Block(-6,20,-4,STEP:8)
Block(-6,20,-3,CONCRETE:7)
Block(-6,20,-2,OBSIDIAN:0)
Block(-6,20,-1,CONCRETE:7)
#RandomBlock(-6,20,0,AIR:0,30,CHEST:5,../../../../../Chests/Loot/junk_loot.nbt,10,CHEST:5,../../../../../Chests/Loot/simple_dungeon.nbt,5,CHEST:5,../../../../../Chests/Loot/moderncity_junk_loot.nbt,65,CHEST:3,../../../../../Chests/Loot/moderncity_junk_loot.nbt,20,CHEST:3,../../../../../Chests/Loot/moderncity_common_loot.nbt,5,CHEST:3,../../../../../Chests/Loot/moderncity_rare_loot.nbt,3,CHEST:3,../../../../../Chests/Loot/moderncity_epic_loot.nbt,1,CHEST:3,../../../../../Chests/Loot/moderncity_junk_loot.nbt,100)
RandomBlock(-6,20,1,AIR,90,IRON_TRAPDOOR:5,100)
RandomBlock(-6,20,5,AIR,90,IRON_TRAPDOOR:4,100)
#RandomBlock(-6,20,6,AIR:0,30,CHEST:5,../../../../../Chests/Loot/junk_loot.nbt,10,CHEST:5,../../../../../Chests/Loot/simple_dungeon.nbt,5,CHEST:5,../../../../../Chests/Loot/moderncity_junk_loot.nbt,65,CHEST:2,../../../../../Chests/Loot/moderncity_junk_loot.nbt,20,CHEST:2,../../../../../Chests/Loot/moderncity_common_loot.nbt,5,CHEST:2,../../../../../Chests/Loot/moderncity_rare_loot.nbt,3,CHEST:2,../../../../../Chests/Loot/moderncity_epic_loot.nbt,1,CHEST:2,../../../../../Chests/Loot/moderncity_junk_loot.nbt,100)
Block(-6,20,7,CONCRETE:7)
Block(-6,21,-7,CONCRETE:7)
Block(-6,21,-6,CONCRETE:7)
Block(-6,21,-5,CONCRETE:7)
Block(-6,21,-4,CONCRETE:7)
Block(-6,21,-3,CONCRETE:7)
Block(-6,21,-2,OBSIDIAN:0)
Block(-6,21,-1,CONCRETE:7)
Block(-6,21,0,STEP:0)
Block(-6,21,1,QUARTZ_STAIRS:7)
Block(-6,21,2,STEP:8)
Block(-6,21,3,STEP:8)
Block(-6,21,4,STEP:8)
Block(-6,21,5,QUARTZ_STAIRS:6)
Block(-6,21,6,STEP:0)
Block(-6,21,7,CONCRETE:7)
Block(-6,21,8,STEP:8)
Block(-6,22,-7,OBSIDIAN:0)
Block(-6,22,-6,OBSIDIAN:0)
Block(-6,22,-5,OBSIDIAN:0)
Block(-6,22,-4,OBSIDIAN:0)
Block(-6,22,-3,OBSIDIAN:0)
Block(-6,22,-2,OBSIDIAN:0)
Block(-6,22,-1,CONCRETE:7)
Block(-6,22,0,CONCRETE:7)
Block(-6,22,1,CONCRETE:7)
Block(-6,22,2,CONCRETE:7)
Block(-6,22,3,CONCRETE:7)
Block(-6,22,4,CONCRETE:7)
Block(-6,22,5,CONCRETE:7)
Block(-6,22,6,CONCRETE:7)
Block(-6,22,7,CONCRETE:7)
Block(-6,22,8,CONCRETE:7)
Block(-6,23,-7,CONCRETE:0)
Block(-6,23,-6,CONCRETE:0)
Block(-6,23,-5,CONCRETE:0)
Block(-6,23,-4,CONCRETE:0)
Block(-6,23,-3,CONCRETE:0)
Block(-6,23,-2,OBSIDIAN:0)
Block(-6,23,-1,OBSIDIAN:0)
Block(-6,23,0,OBSIDIAN:0)
Block(-6,23,1,OBSIDIAN:0)
Block(-6,23,2,OBSIDIAN:0)
Block(-6,23,3,OBSIDIAN:0)
Block(-6,23,4,OBSIDIAN:0)
Block(-6,23,5,OBSIDIAN:0)
Block(-6,23,6,OBSIDIAN:0)
Block(-6,23,7,OBSIDIAN:0)
Block(-6,23,8,OBSIDIAN:0)
Block(-6,24,-5,QUARTZ_STAIRS:2)
Block(-6,24,-4,CONCRETE:0)
Block(-6,24,-3,CONCRETE:0)
Block(-6,24,-2,CONCRETE:0)
Block(-6,24,-1,CONCRETE:0)
Block(-6,24,0,CONCRETE:0)
Block(-6,24,1,CONCRETE:0)
Block(-6,24,2,STONE:4)
Block(-6,24,3,STONE:4)
Block(-6,24,4,SMOOTH_BRICK:3)
Block(-6,24,5,CONCRETE:15)
Block(-6,24,6,STONE:6)
Block(-6,24,7,STONE:6)
Block(-6,24,8,CONCRETE:15)
Block(-6,25,-2,QUARTZ_STAIRS:2)
Block(-6,25,-1,CONCRETE:0)
Block(-6,25,0,CONCRETE:0)
Block(-6,26,-1,CONCRETE:0)
Block(-6,26,0,QUARTZ_STAIRS:3)
Block(-6,27,-1,CONCRETE:0)
Block(-6,28,-2,QUARTZ_STAIRS:6)
Block(-6,28,-1,CONCRETE:0)
Block(-6,28,0,QUARTZ_STAIRS:7)
Block(-6,29,-3,QUARTZ_STAIRS:4)
Block(-6,29,-2,CONCRETE:0)
Block(-6,29,-1,CONCRETE:0)
Block(-6,29,0,CONCRETE:8)
Block(-6,30,-2,COBBLE_WALL:0)
Block(-6,30,-1,STEP:15)
Block(-6,30,0,CONCRETE:8)
Block(-6,31,-1,CONCRETE:7)
Block(-6,31,0,QUARTZ_STAIRS:3)
Block(-6,32,-1,STAINED_GLASS_PANE:14)
Block(-6,33,-1,STAINED_GLASS_PANE:15)
Block(-6,34,-1,STAINED_GLASS_PANE:14)
Block(-6,35,-1,CONCRETE:7)
Block(-6,35,0,QUARTZ_STAIRS:7)
Block(-6,36,-2,COBBLE_WALL:0)
Block(-6,36,-1,STEP:7)
Block(-6,36,0,CONCRETE:0)
Block(-6,37,-5,STEP:15)
Block(-6,37,-4,STEP:15)
Block(-6,37,-3,STEP:15)
Block(-6,37,-2,STEP:15)
Block(-6,37,-1,STEP:15)
Block(-6,37,0,CONCRETE:8)
Block(-6,37,1,QUARTZ_STAIRS:7)
Block(-6,38,-6,QUARTZ_STAIRS:6)
Block(-6,38,-5,CONCRETE:0)
Block(-6,38,-4,CONCRETE:0)
Block(-6,38,-3,CONCRETE:0)
Block(-6,38,-2,CONCRETE:0)
Block(-6,38,-1,CONCRETE:0)
Block(-6,38,0,CONCRETE:8)
Block(-6,38,1,CONCRETE:0)
Block(-6,38,5,QUARTZ_STAIRS:4)
Block(-6,38,8,QUARTZ_STAIRS:4)
Block(-6,39,-5,STEP:7)
Block(-6,39,-4,STEP:7)
Block(-6,39,-3,STEP:7)
Block(-6,39,-2,STEP:7)
Block(-6,39,-1,STEP:7)
Block(-6,39,0,CONCRETE:8)
Block(-6,39,1,CONCRETE:0)
Block(-6,39,3,CONCRETE:0)
Block(-6,39,5,CONCRETE:0)
Block(-6,39,8,CONCRETE:0)
Block(-6,40,-2,QUARTZ_STAIRS:6)
Block(-6,40,-1,QUARTZ_STAIRS:7)
Block(-6,40,0,STEP:8)
Block(-6,40,1,DOUBLE_STEP:7)
Block(-6,40,2,STEP:15)
Block(-6,40,3,DOUBLE_STEP:0)
Block(-6,40,4,STEP:15)
Block(-6,40,5,STEP:15)
Block(-6,40,6,STEP:15)
Block(-6,40,7,STEP:15)
Block(-6,40,8,STEP:15)
Block(-6,41,-2,STAINED_GLASS_PANE:15)
Block(-6,41,8,STAINED_GLASS_PANE:15)
Block(-6,42,8,STAINED_GLASS_PANE:15)
Block(-6,43,8,STAINED_GLASS_PANE:15)
Block(-6,44,8,CONCRETE:7)
Block(-6,45,8,STAINED_GLASS_PANE:15)
Block(-6,46,8,STAINED_GLASS_PANE:15)
Block(-6,47,8,STAINED_GLASS_PANE:15)
Block(-6,48,8,CONCRETE:7)
Block(-6,49,8,CONCRETE:7)
Block(-6,50,8,CONCRETE:0)
Block(-5,0,-7,CONCRETE:7)
Block(-5,0,-6,CONCRETE:7)
Block(-5,0,-5,CONCRETE:7)
Block(-5,0,-4,CONCRETE:7)
Block(-5,0,-3,CONCRETE:7)
Block(-5,0,-2,CONCRETE:7)
Block(-5,0,-1,CONCRETE:7)
Block(-5,0,0,CONCRETE:7)
Block(-5,0,1,CONCRETE:7)
Block(-5,0,2,CONCRETE:7)
Block(-5,0,3,CONCRETE:7)
Block(-5,0,4,CONCRETE:7)
Block(-5,0,5,CONCRETE:7)
Block(-5,0,6,CONCRETE:7)
Block(-5,0,7,CONCRETE:7)
Block(-5,0,8,CONCRETE:7)
Block(-5,1,-7,OBSIDIAN:0)
Block(-5,1,-6,OBSIDIAN:0)
Block(-5,1,-5,OBSIDIAN:0)
Block(-5,1,-4,OBSIDIAN:0)
Block(-5,1,-3,OBSIDIAN:0)
Block(-5,1,-2,OBSIDIAN:0)
Block(-5,1,-1,OBSIDIAN:0)
Block(-5,1,0,OBSIDIAN:0)
Block(-5,1,1,OBSIDIAN:0)
Block(-5,1,2,OBSIDIAN:0)
Block(-5,1,3,OBSIDIAN:0)
Block(-5,1,4,OBSIDIAN:0)
Block(-5,1,5,OBSIDIAN:0)
Block(-5,1,6,OBSIDIAN:0)
Block(-5,1,7,OBSIDIAN:0)
Block(-5,1,8,OBSIDIAN:0)
Block(-5,2,-7,OBSIDIAN:0)
Block(-5,2,-6,OBSIDIAN:0)
Block(-5,2,-5,OBSIDIAN:0)
Block(-5,2,-4,OBSIDIAN:0)
Block(-5,2,-3,OBSIDIAN:0)
Block(-5,2,-2,OBSIDIAN:0)
Block(-5,2,-1,OBSIDIAN:0)
Block(-5,2,0,OBSIDIAN:0)
Block(-5,2,1,OBSIDIAN:0)
Block(-5,2,2,OBSIDIAN:0)
Block(-5,2,3,OBSIDIAN:0)
Block(-5,2,4,OBSIDIAN:0)
Block(-5,2,5,OBSIDIAN:0)
Block(-5,2,6,OBSIDIAN:0)
Block(-5,2,7,OBSIDIAN:0)
Block(-5,2,8,OBSIDIAN:0)
Block(-5,3,-7,STATIONARY_LAVA:0)
Block(-5,3,-6,STATIONARY_LAVA:0)
Block(-5,3,-5,STATIONARY_LAVA:0)
Block(-5,3,-4,STATIONARY_LAVA:0)
Block(-5,3,-3,STATIONARY_LAVA:0)
Block(-5,3,-2,STATIONARY_LAVA:0)
Block(-5,3,-1,STATIONARY_LAVA:0)
Block(-5,3,0,STATIONARY_LAVA:0)
Block(-5,3,1,STATIONARY_LAVA:0)
Block(-5,3,2,STATIONARY_LAVA:0)
Block(-5,3,3,STATIONARY_LAVA:0)
Block(-5,3,4,STATIONARY_LAVA:0)
Block(-5,3,5,STATIONARY_LAVA:0)
Block(-5,3,6,STATIONARY_LAVA:0)
Block(-5,3,7,STATIONARY_LAVA:0)
Block(-5,3,8,STATIONARY_LAVA:0)
Block(-5,4,-7,OBSIDIAN:0)
Block(-5,4,-6,OBSIDIAN:0)
Block(-5,4,-5,OBSIDIAN:0)
Block(-5,4,-4,OBSIDIAN:0)
Block(-5,4,-3,OBSIDIAN:0)
Block(-5,4,-2,OBSIDIAN:0)
Block(-5,4,-1,OBSIDIAN:0)
Block(-5,4,0,OBSIDIAN:0)
Block(-5,4,1,OBSIDIAN:0)
Block(-5,4,2,OBSIDIAN:0)
Block(-5,4,3,OBSIDIAN:0)
Block(-5,4,4,OBSIDIAN:0)
Block(-5,4,5,OBSIDIAN:0)
Block(-5,4,6,OBSIDIAN:0)
Block(-5,4,7,OBSIDIAN:0)
Block(-5,4,8,OBSIDIAN:0)
Block(-5,5,-7,IRON_PLATE:0)
Block(-5,5,-6,IRON_PLATE:0)
Block(-5,5,-5,IRON_PLATE:0)
Block(-5,5,-4,IRON_PLATE:0)
Block(-5,5,-3,IRON_PLATE:0)
Block(-5,5,-2,OBSIDIAN:0)
Block(-5,5,-1,IRON_PLATE:0)
Block(-5,5,0,IRON_PLATE:0)
Block(-5,5,1,IRON_PLATE:0)
Block(-5,5,2,IRON_PLATE:0)
Block(-5,5,3,IRON_PLATE:0)
Block(-5,5,4,IRON_PLATE:0)
Block(-5,5,5,IRON_PLATE:0)
Block(-5,5,6,IRON_PLATE:0)
Block(-5,5,7,IRON_PLATE:0)
Block(-5,5,8,IRON_PLATE:0)
Block(-5,6,-7,STONE_BUTTON:2)
Block(-5,6,-4,STONE_BUTTON:2)
Block(-5,6,-2,OBSIDIAN:0)
Block(-5,7,-2,OBSIDIAN:0)
Block(-5,8,-7,STONE_BUTTON:2)
Block(-5,8,-4,STONE_BUTTON:2)
Block(-5,8,-2,OBSIDIAN:0)
Block(-5,8,6,STEP:8)
Block(-5,8,7,STEP:8)
Block(-5,9,-2,OBSIDIAN:0)
Block(-5,9,6,REDSTONE_WIRE:0)
Block(-5,9,7,REDSTONE_WIRE:0)
Block(-5,10,-7,STEP:8)
Block(-5,10,-6,STEP:8)
Block(-5,10,-5,STEP:8)
Block(-5,10,-4,STEP:8)
Block(-5,10,-3,STEP:8)
Block(-5,10,-2,OBSIDIAN:0)
Block(-5,10,-1,STEP:8)
Block(-5,10,0,STEP:8)
Block(-5,10,1,STEP:8)
Block(-5,10,2,STEP:8)
Block(-5,10,3,STEP:8)
Block(-5,10,4,STEP:8)
Block(-5,10,5,STEP:8)
Block(-5,10,6,STEP:8)
Block(-5,10,7,STEP:8)
Block(-5,10,8,STEP:8)
Block(-5,11,-7,OBSIDIAN:0)
Block(-5,11,-6,OBSIDIAN:0)
Block(-5,11,-5,OBSIDIAN:0)
Block(-5,11,-4,OBSIDIAN:0)
Block(-5,11,-3,OBSIDIAN:0)
Block(-5,11,-2,OBSIDIAN:0)
Block(-5,11,-1,OBSIDIAN:0)
Block(-5,11,0,OBSIDIAN:0)
Block(-5,11,1,OBSIDIAN:0)
Block(-5,11,2,OBSIDIAN:0)
Block(-5,11,3,OBSIDIAN:0)
Block(-5,11,4,OBSIDIAN:0)
Block(-5,11,5,OBSIDIAN:0)
Block(-5,11,6,OBSIDIAN:0)
Block(-5,11,7,OBSIDIAN:0)
Block(-5,11,8,OBSIDIAN:0)
Block(-5,12,-7,STATIONARY_LAVA:0)
Block(-5,12,-6,STATIONARY_LAVA:0)
Block(-5,12,-5,STATIONARY_LAVA:0)
Block(-5,12,-4,STATIONARY_LAVA:0)
Block(-5,12,-3,STATIONARY_LAVA:0)
Block(-5,12,-2,STATIONARY_LAVA:0)
Block(-5,12,-1,STATIONARY_LAVA:0)
Block(-5,12,0,STATIONARY_LAVA:0)
Block(-5,12,1,STATIONARY_LAVA:0)
Block(-5,12,2,STATIONARY_LAVA:0)
Block(-5,12,3,STATIONARY_LAVA:0)
Block(-5,12,4,STATIONARY_LAVA:0)
Block(-5,12,5,STATIONARY_LAVA:0)
Block(-5,12,6,STATIONARY_LAVA:0)
Block(-5,12,7,STATIONARY_LAVA:0)
Block(-5,12,8,STATIONARY_LAVA:0)
Block(-5,13,-7,OBSIDIAN:0)
Block(-5,13,-6,OBSIDIAN:0)
Block(-5,13,-5,OBSIDIAN:0)
Block(-5,13,-4,OBSIDIAN:0)
Block(-5,13,-3,OBSIDIAN:0)
Block(-5,13,-2,OBSIDIAN:0)
Block(-5,13,-1,OBSIDIAN:0)
Block(-5,13,0,OBSIDIAN:0)
Block(-5,13,1,OBSIDIAN:0)
Block(-5,13,2,OBSIDIAN:0)
Block(-5,13,3,OBSIDIAN:0)
Block(-5,13,4,OBSIDIAN:0)
Block(-5,13,5,OBSIDIAN:0)
Block(-5,13,6,OBSIDIAN:0)
Block(-5,13,7,OBSIDIAN:0)
Block(-5,13,8,OBSIDIAN:0)
Block(-5,14,-7,OBSIDIAN:0)
Block(-5,14,-6,OBSIDIAN:0)
Block(-5,14,-5,OBSIDIAN:0)
Block(-5,14,-4,OBSIDIAN:0)
Block(-5,14,-3,OBSIDIAN:0)
Block(-5,14,-2,OBSIDIAN:0)
Block(-5,14,-1,OBSIDIAN:0)
Block(-5,14,0,OBSIDIAN:0)
Block(-5,14,1,OBSIDIAN:0)
Block(-5,14,2,OBSIDIAN:0)
Block(-5,14,3,OBSIDIAN:0)
Block(-5,14,4,OBSIDIAN:0)
Block(-5,14,5,OBSIDIAN:0)
Block(-5,14,6,OBSIDIAN:0)
Block(-5,14,7,OBSIDIAN:0)
Block(-5,14,8,OBSIDIAN:0)
Block(-5,15,-7,OBSIDIAN:0)
Block(-5,15,-6,OBSIDIAN:0)
Block(-5,15,-5,OBSIDIAN:0)
Block(-5,15,-4,OBSIDIAN:0)
Block(-5,15,-3,OBSIDIAN:0)
Block(-5,15,-2,OBSIDIAN:0)
Block(-5,15,-1,OBSIDIAN:0)
Block(-5,15,0,OBSIDIAN:0)
Block(-5,15,1,OBSIDIAN:0)
Block(-5,15,2,OBSIDIAN:0)
Block(-5,15,3,OBSIDIAN:0)
Block(-5,15,4,OBSIDIAN:0)
Block(-5,15,5,OBSIDIAN:0)
Block(-5,15,6,OBSIDIAN:0)
Block(-5,15,7,OBSIDIAN:0)
Block(-5,15,8,OBSIDIAN:0)
Block(-5,16,-7,OBSIDIAN:0)
Block(-5,16,-6,OBSIDIAN:0)
Block(-5,16,-5,OBSIDIAN:0)
Block(-5,16,-4,OBSIDIAN:0)
Block(-5,16,-3,OBSIDIAN:0)
Block(-5,16,-2,OBSIDIAN:0)
Block(-5,16,-1,OBSIDIAN:0)
Block(-5,16,0,OBSIDIAN:0)
Block(-5,16,1,OBSIDIAN:0)
Block(-5,16,2,OBSIDIAN:0)
Block(-5,16,3,OBSIDIAN:0)
Block(-5,16,4,OBSIDIAN:0)
Block(-5,16,5,OBSIDIAN:0)
Block(-5,16,6,OBSIDIAN:0)
Block(-5,16,7,OBSIDIAN:0)
Block(-5,16,8,OBSIDIAN:0)
Block(-5,17,-7,CONCRETE:7)
Block(-5,17,-6,CONCRETE:7)
Block(-5,17,-5,CONCRETE:7)
Block(-5,17,-4,CONCRETE:7)
Block(-5,17,-3,CONCRETE:7)
Block(-5,17,-2,CONCRETE:7)
Block(-5,17,-1,CONCRETE:7)
Block(-5,17,0,CONCRETE:7)
Block(-5,17,1,CONCRETE:7)
Block(-5,17,2,CONCRETE:7)
Block(-5,17,3,CONCRETE:7)
Block(-5,17,4,CONCRETE:7)
Block(-5,17,5,CONCRETE:7)
Block(-5,17,6,CONCRETE:7)
Block(-5,17,7,CONCRETE:7)
Block(-5,17,8,CONCRETE:7)
RandomBlock(-5,18,-7,AIR,90,TRAP_DOOR:7,100)
Block(-5,18,-6,OBSIDIAN:0)
Block(-5,18,-3,CONCRETE:7)
Block(-5,18,-2,OBSIDIAN:0)
Block(-5,18,-1,CONCRETE:7)
Block(-5,18,0,STONE:4)
Block(-5,18,1,STONE:4)
Block(-5,18,4,LEVER:12)
Block(-5,18,5,STONE:4)
Block(-5,18,6,STONE:4)
Block(-5,18,7,OBSIDIAN:0)
Block(-5,19,-6,STAINED_GLASS_PANE:0)
Block(-5,19,-3,CONCRETE:7)
Block(-5,19,-2,OBSIDIAN:0)
Block(-5,19,-1,CONCRETE:7)
Block(-5,19,0,STONE:4)
Block(-5,19,1,STONE:4)
Block(-5,19,4,LEVER:12)
Block(-5,19,5,STONE:4)
Block(-5,19,6,STONE:4)
Block(-5,19,7,OBSIDIAN:0)
Block(-5,20,-7,STEP:8)
Block(-5,20,-6,OBSIDIAN:0)
Block(-5,20,-5,STEP:8)
Block(-5,20,-4,STEP:8)
Block(-5,20,-3,CONCRETE:7)
Block(-5,20,-2,OBSIDIAN:0)
Block(-5,20,-1,CONCRETE:7)
Block(-5,20,0,STONE:4)
Block(-5,20,1,STONE:4)
Block(-5,20,4,LEVER:12)
Block(-5,20,5,STONE:4)
Block(-5,20,6,STONE:4)
Block(-5,20,7,OBSIDIAN:0)
Block(-5,21,-7,CONCRETE:7)
Block(-5,21,-6,CONCRETE:7)
Block(-5,21,-5,CONCRETE:7)
Block(-5,21,-4,CONCRETE:7)
Block(-5,21,-3,CONCRETE:7)
Block(-5,21,-2,OBSIDIAN:0)
Block(-5,21,-1,CONCRETE:7)
Block(-5,21,0,STONE:4)
Block(-5,21,1,STONE:4)
Block(-5,21,2,STEP:8)
Block(-5,21,3,STEP:8)
Block(-5,21,4,STEP:8)
Block(-5,21,5,STONE:4)
Block(-5,21,6,STONE:4)
Block(-5,21,7,CONCRETE:7)
Block(-5,21,8,STEP:8)
Block(-5,22,-7,OBSIDIAN:0)
Block(-5,22,-6,OBSIDIAN:0)
Block(-5,22,-5,OBSIDIAN:0)
Block(-5,22,-4,OBSIDIAN:0)
Block(-5,22,-3,OBSIDIAN:0)
Block(-5,22,-2,OBSIDIAN:0)
Block(-5,22,-1,CONCRETE:7)
Block(-5,22,0,CONCRETE:7)
Block(-5,22,1,CONCRETE:7)
Block(-5,22,2,CONCRETE:7)
Block(-5,22,3,CONCRETE:7)
Block(-5,22,4,CONCRETE:7)
Block(-5,22,5,CONCRETE:7)
Block(-5,22,6,CONCRETE:7)
Block(-5,22,7,CONCRETE:7)
Block(-5,22,8,CONCRETE:7)
Block(-5,23,-7,CONCRETE:0)
Block(-5,23,-6,CONCRETE:0)
Block(-5,23,-5,CONCRETE:0)
Block(-5,23,-4,CONCRETE:0)
Block(-5,23,-3,CONCRETE:0)
Block(-5,23,-2,OBSIDIAN:0)
Block(-5,23,-1,OBSIDIAN:0)
Block(-5,23,0,OBSIDIAN:0)
Block(-5,23,1,OBSIDIAN:0)
Block(-5,23,2,OBSIDIAN:0)
Block(-5,23,3,OBSIDIAN:0)
Block(-5,23,4,OBSIDIAN:0)
Block(-5,23,5,OBSIDIAN:0)
Block(-5,23,6,OBSIDIAN:0)
Block(-5,23,7,OBSIDIAN:0)
Block(-5,23,8,OBSIDIAN:0)
Block(-5,24,-5,QUARTZ_STAIRS:2)
Block(-5,24,-4,CONCRETE:0)
Block(-5,24,-3,CONCRETE:0)
Block(-5,24,-2,CONCRETE:0)
Block(-5,24,-1,CONCRETE:7)
Block(-5,24,0,CONCRETE:15)
Block(-5,24,1,CONCRETE:0)
Block(-5,24,2,CONCRETE:0)
Block(-5,24,3,CONCRETE:0)
Block(-5,24,4,STONE:4)
Block(-5,24,5,CONCRETE:0)
Block(-5,24,6,CONCRETE:15)
Block(-5,24,7,CONCRETE:15)
Block(-5,24,8,CONCRETE:0)
Block(-5,25,-1,STAINED_GLASS_PANE:15)
Block(-5,26,-1,STAINED_GLASS_PANE:15)
Block(-5,27,-1,STAINED_GLASS_PANE:15)
Block(-5,28,-1,STEP:8)
Block(-5,29,-3,QUARTZ_STAIRS:6)
Block(-5,29,-2,CONCRETE:0)
Block(-5,29,-1,CONCRETE:0)
Block(-5,29,0,QUARTZ_STAIRS:7)
Block(-5,30,-2,STEP:0)
Block(-5,30,-1,QUARTZ_STAIRS:0)
Block(-5,30,0,CONCRETE:0)
Block(-5,31,-1,STEP:15)
Block(-5,31,0,CONCRETE:8)
Block(-5,32,-1,CONCRETE:7)
Block(-5,32,0,STEP:7)
Block(-5,33,-1,CONCRETE:7)
Block(-5,33,0,COBBLE_WALL:0)
Block(-5,34,-1,CONCRETE:7)
Block(-5,34,0,STEP:15)
Block(-5,35,-1,STEP:7)
Block(-5,35,0,CONCRETE:8)
Block(-5,36,-4,QUARTZ_STAIRS:4)
Block(-5,36,-1,QUARTZ_STAIRS:4)
Block(-5,36,0,CONCRETE:8)
Block(-5,37,-6,QUARTZ_STAIRS:6)
Block(-5,37,-5,CONCRETE:0)
Block(-5,37,-4,CONCRETE:0)
Block(-5,37,-3,CONCRETE:0)
Block(-5,37,-2,CONCRETE:0)
Block(-5,37,-1,CONCRETE:0)
Block(-5,37,0,CONCRETE:8)
Block(-5,38,-6,QUARTZ_STAIRS:1)
Block(-5,38,-5,QUARTZ_STAIRS:1)
Block(-5,38,-4,QUARTZ_STAIRS:1)
Block(-5,38,-2,CONCRETE:0)
Block(-5,38,-1,CONCRETE:8)
Block(-5,38,0,CONCRETE:8)
Block(-5,38,3,QUARTZ_STAIRS:4)
Block(-5,38,5,CONCRETE:0)
Block(-5,38,8,CONCRETE:0)
Block(-5,39,-2,CONCRETE:0)
Block(-5,39,-1,CONCRETE:8)
Block(-5,39,0,CONCRETE:8)
Block(-5,39,3,CONCRETE:0)
Block(-5,39,5,QUARTZ_STAIRS:1)
Block(-5,39,8,QUARTZ_STAIRS:1)
Block(-5,40,-2,CONCRETE:0)
Block(-5,40,-1,QUARTZ_STAIRS:7)
Block(-5,40,0,STEP:8)
Block(-5,40,1,DOUBLE_STEP:7)
Block(-5,40,2,STEP:8)
Block(-5,40,3,STEP:8)
Block(-5,40,4,STEP:8)
Block(-5,40,5,STEP:15)
Block(-5,40,6,STEP:15)
Block(-5,40,7,STEP:15)
Block(-5,40,8,STEP:15)
Block(-5,41,-2,CONCRETE:0)
Block(-5,41,-1,STAINED_GLASS_PANE:15)
Block(-5,41,8,STAINED_GLASS_PANE:15)
Block(-5,42,-2,COBBLE_WALL:0)
Block(-5,42,8,STAINED_GLASS_PANE:15)
Block(-5,43,8,STAINED_GLASS_PANE:15)
Block(-5,44,8,CONCRETE:7)
Block(-5,45,8,STAINED_GLASS_PANE:15)
Block(-5,46,8,STAINED_GLASS_PANE:15)
Block(-5,47,8,CONCRETE:7)
Block(-5,48,8,CONCRETE:7)
Block(-5,49,8,CONCRETE:7)
Block(-4,0,-7,CONCRETE:7)
Block(-4,0,-6,CONCRETE:7)
Block(-4,0,-5,CONCRETE:7)
Block(-4,0,-4,CONCRETE:7)
Block(-4,0,-3,CONCRETE:7)
Block(-4,0,-2,CONCRETE:7)
Block(-4,0,-1,CONCRETE:7)
Block(-4,0,0,CONCRETE:7)
Block(-4,0,1,CONCRETE:7)
Block(-4,0,2,CONCRETE:7)
Block(-4,0,3,CONCRETE:7)
Block(-4,0,4,CONCRETE:7)
Block(-4,0,5,CONCRETE:7)
Block(-4,0,6,CONCRETE:7)
Block(-4,0,7,CONCRETE:7)
Block(-4,0,8,CONCRETE:7)
Block(-4,1,-7,OBSIDIAN:0)
Block(-4,1,-6,OBSIDIAN:0)
Block(-4,1,-5,OBSIDIAN:0)
Block(-4,1,-4,OBSIDIAN:0)
Block(-4,1,-3,OBSIDIAN:0)
Block(-4,1,-2,OBSIDIAN:0)
Block(-4,1,-1,OBSIDIAN:0)
Block(-4,1,0,OBSIDIAN:0)
Block(-4,1,1,OBSIDIAN:0)
Block(-4,1,2,OBSIDIAN:0)
Block(-4,1,3,OBSIDIAN:0)
Block(-4,1,4,OBSIDIAN:0)
Block(-4,1,5,OBSIDIAN:0)
Block(-4,1,6,OBSIDIAN:0)
Block(-4,1,7,OBSIDIAN:0)
Block(-4,1,8,OBSIDIAN:0)
Block(-4,2,-7,OBSIDIAN:0)
Block(-4,2,-6,OBSIDIAN:0)
Block(-4,2,-5,OBSIDIAN:0)
Block(-4,2,-4,OBSIDIAN:0)
Block(-4,2,-3,OBSIDIAN:0)
Block(-4,2,-2,OBSIDIAN:0)
Block(-4,2,-1,OBSIDIAN:0)
Block(-4,2,0,OBSIDIAN:0)
Block(-4,2,1,OBSIDIAN:0)
Block(-4,2,2,OBSIDIAN:0)
Block(-4,2,3,OBSIDIAN:0)
Block(-4,2,4,OBSIDIAN:0)
Block(-4,2,5,OBSIDIAN:0)
Block(-4,2,6,OBSIDIAN:0)
Block(-4,2,7,OBSIDIAN:0)
Block(-4,2,8,OBSIDIAN:0)
Block(-4,3,-7,STATIONARY_LAVA:0)
Block(-4,3,-6,STATIONARY_LAVA:0)
Block(-4,3,-5,STATIONARY_LAVA:0)
Block(-4,3,-4,STATIONARY_LAVA:0)
Block(-4,3,-3,STATIONARY_LAVA:0)
Block(-4,3,-2,STATIONARY_LAVA:0)
Block(-4,3,-1,STATIONARY_LAVA:0)
Block(-4,3,0,STATIONARY_LAVA:0)
Block(-4,3,1,STATIONARY_LAVA:0)
Block(-4,3,2,STATIONARY_LAVA:0)
Block(-4,3,3,STATIONARY_LAVA:0)
Block(-4,3,4,STATIONARY_LAVA:0)
Block(-4,3,5,STATIONARY_LAVA:0)
Block(-4,3,6,STATIONARY_LAVA:0)
Block(-4,3,7,STATIONARY_LAVA:0)
Block(-4,3,8,STATIONARY_LAVA:0)
Block(-4,4,-7,OBSIDIAN:0)
Block(-4,4,-6,OBSIDIAN:0)
Block(-4,4,-5,OBSIDIAN:0)
Block(-4,4,-4,OBSIDIAN:0)
Block(-4,4,-3,OBSIDIAN:0)
Block(-4,4,-2,OBSIDIAN:0)
Block(-4,4,-1,OBSIDIAN:0)
Block(-4,4,0,OBSIDIAN:0)
Block(-4,4,1,OBSIDIAN:0)
Block(-4,4,2,OBSIDIAN:0)
Block(-4,4,3,OBSIDIAN:0)
Block(-4,4,4,OBSIDIAN:0)
Block(-4,4,5,OBSIDIAN:0)
Block(-4,4,6,OBSIDIAN:0)
Block(-4,4,7,OBSIDIAN:0)
Block(-4,4,8,OBSIDIAN:0)
Block(-4,5,-7,COBBLE_WALL:0)
#RandomBlock(-4,5,-6,AIR:0,30,CHEST:5,../../../../../Chests/Loot/junk_loot.nbt,10,CHEST:5,../../../../../Chests/Loot/simple_dungeon.nbt,5,CHEST:5,../../../../../Chests/Loot/moderncity_junk_loot.nbt,65,CHEST:4,../../../../../Chests/Loot/moderncity_junk_loot.nbt,20,CHEST:4,../../../../../Chests/Loot/moderncity_common_loot.nbt,5,CHEST:4,../../../../../Chests/Loot/moderncity_rare_loot.nbt,3,CHEST:4,../../../../../Chests/Loot/moderncity_epic_loot.nbt,1,CHEST:4,../../../../../Chests/Loot/moderncity_junk_loot.nbt,100)
RandomBlock(-4,5,-5,GOLD_BLOCK,40,MOB_SPAWNER:0,../../DestructionLayers/Parasites/parasite_multi.nbt,20,CHEST:2,../../../../../Chests/Loot/simple_dungeon.nbt,10,CHEST:2,../../../../../Chests/Loot/gem_loot.nbt,10,CHEST:2,../../../../../Chests/Loot/desert_pyramid.nbt,5,CHEST:2,../../../../../Chests/Loot/jungle_temple.nbt,5,CHEST:2,../../../../../Chests/Loot/stronghold_library.nbt,10,CHEST:2,../../../../../Chests/Loot/woodland_mansion.nbt,10,CHEST:2,../../../../../Chests/Loot/end_city_treasure.nbt,10,CHEST:2,../../../../../Chests/RLCraft/IceAndFire/fire_dragon_roost_chest.nbt,5,CHEST:2,../../../../../Chests/lore/moderncity.nbt,5,chest:2,../../../../../Chests/RLCraft/IceAndFire/ice_dragon_roost_chest.nbt,5,chest:2,../../../../../Chests/lore/moderncity.nbt,2,chest:2,../../../../../Chests/RLCraft/IceAndFire/lightning_dragon_roost_chest.nbt,5,chest:2,../../../../../Chests/loot/moderncity_epic_loot.nbt,100)
Block(-4,5,-4,COBBLE_WALL:0)
Block(-4,5,-3,IRON_PLATE:0)
Block(-4,5,-2,OBSIDIAN:0)
Block(-4,5,-1,IRON_PLATE:0)
Block(-4,5,0,IRON_PLATE:0)
Block(-4,5,1,IRON_PLATE:0)
Block(-4,5,2,IRON_PLATE:0)
Block(-4,5,3,IRON_PLATE:0)
Block(-4,5,4,IRON_PLATE:0)
Block(-4,5,5,IRON_PLATE:0)
Block(-4,5,6,IRON_PLATE:0)
Block(-4,5,7,IRON_PLATE:0)
Block(-4,5,8,IRON_PLATE:0)
Block(-4,6,-7,DOUBLE_STEP:0)
Block(-4,6,-6,STEP:8)
Block(-4,6,-5,STEP:8)
Block(-4,6,-4,DOUBLE_STEP:0)
Block(-4,6,-3,STONE_BUTTON:3)
Block(-4,6,-2,OBSIDIAN:0)
Block(-4,7,-7,COBBLE_WALL:0)
Block(-4,7,-6,GOLD_PLATE:0)
#RandomBlock(-4,7,-5,AIR:0,30,CHEST:5,../../../../../Chests/Loot/junk_loot.nbt,10,CHEST:5,../../../../../Chests/Loot/simple_dungeon.nbt,5,CHEST:5,../../../../../Chests/Loot/moderncity_junk_loot.nbt,65,CHEST:4,../../../../../Chests/Loot/moderncity_junk_loot.nbt,20,CHEST:4,../../../../../Chests/Loot/moderncity_common_loot.nbt,5,CHEST:4,../../../../../Chests/Loot/moderncity_rare_loot.nbt,3,CHEST:4,../../../../../Chests/Loot/moderncity_epic_loot.nbt,1,CHEST:4,../../../../../Chests/Loot/moderncity_junk_loot.nbt,100)
Block(-4,7,-4,COBBLE_WALL:0)
Block(-4,7,-2,OBSIDIAN:0)
Block(-4,8,-7,DOUBLE_STEP:0)
Block(-4,8,-6,STEP:8)
Block(-4,8,-5,STEP:8)
Block(-4,8,-4,DOUBLE_STEP:0)
Block(-4,8,-3,STONE_BUTTON:3)
Block(-4,8,-2,OBSIDIAN:0)
Block(-4,8,6,STEP:8)
Block(-4,8,7,STEP:8)
Block(-4,9,-7,minecraft:yellow_glazed_terracotta:0)
Block(-4,9,-6,GOLD_PLATE:0)
Block(-4,9,-5,GOLD_PLATE:0)
RandomBlock(-4,9,-4,GOLD_BLOCK,40,MOB_SPAWNER:0,../../DestructionLayers/Parasites/parasite_multi.nbt,20,CHEST:2,../../../../../Chests/Loot/simple_dungeon.nbt,10,CHEST:2,../../../../../Chests/Loot/gem_loot.nbt,10,CHEST:2,../../../../../Chests/Loot/desert_pyramid.nbt,5,CHEST:2,../../../../../Chests/Loot/jungle_temple.nbt,5,CHEST:2,../../../../../Chests/Loot/stronghold_library.nbt,10,CHEST:2,../../../../../Chests/Loot/woodland_mansion.nbt,10,CHEST:2,../../../../../Chests/Loot/end_city_treasure.nbt,10,CHEST:2,../../../../../Chests/RLCraft/IceAndFire/fire_dragon_roost_chest.nbt,5,CHEST:2,../../../../../Chests/lore/moderncity.nbt,5,chest:2,../../../../../Chests/RLCraft/IceAndFire/ice_dragon_roost_chest.nbt,5,chest:2,../../../../../Chests/lore/moderncity.nbt,2,chest:2,../../../../../Chests/RLCraft/IceAndFire/lightning_dragon_roost_chest.nbt,5,chest:2,../../../../../Chests/loot/moderncity_epic_loot.nbt,100)
Block(-4,9,-2,OBSIDIAN:0)
Block(-4,9,6,REDSTONE_WIRE:0)
Block(-4,9,7,REDSTONE_WIRE:0)
Block(-4,10,-7,STEP:8)
Block(-4,10,-6,STEP:8)
Block(-4,10,-5,STEP:8)
Block(-4,10,-4,STEP:8)
Block(-4,10,-3,STEP:8)
Block(-4,10,-2,OBSIDIAN:0)
Block(-4,10,-1,STEP:8)
Block(-4,10,0,STEP:8)
Block(-4,10,1,STEP:8)
Block(-4,10,2,STEP:8)
Block(-4,10,3,STEP:8)
Block(-4,10,4,STEP:8)
Block(-4,10,5,STEP:8)
Block(-4,10,6,STEP:8)
Block(-4,10,7,STEP:8)
Block(-4,10,8,STEP:8)
Block(-4,11,-7,OBSIDIAN:0)
Block(-4,11,-6,OBSIDIAN:0)
Block(-4,11,-5,OBSIDIAN:0)
Block(-4,11,-4,OBSIDIAN:0)
Block(-4,11,-3,OBSIDIAN:0)
Block(-4,11,-2,OBSIDIAN:0)
Block(-4,11,-1,OBSIDIAN:0)
Block(-4,11,0,OBSIDIAN:0)
Block(-4,11,1,OBSIDIAN:0)
Block(-4,11,2,OBSIDIAN:0)
Block(-4,11,3,OBSIDIAN:0)
Block(-4,11,4,OBSIDIAN:0)
Block(-4,11,5,OBSIDIAN:0)
Block(-4,11,6,OBSIDIAN:0)
Block(-4,11,7,OBSIDIAN:0)
Block(-4,11,8,OBSIDIAN:0)
Block(-4,12,-7,STATIONARY_LAVA:0)
Block(-4,12,-6,STATIONARY_LAVA:0)
Block(-4,12,-5,STATIONARY_LAVA:0)
Block(-4,12,-4,STATIONARY_LAVA:0)
Block(-4,12,-3,STATIONARY_LAVA:0)
Block(-4,12,-2,STATIONARY_LAVA:0)
Block(-4,12,-1,STATIONARY_LAVA:0)
Block(-4,12,0,STATIONARY_LAVA:0)
Block(-4,12,1,STATIONARY_LAVA:0)
Block(-4,12,2,STATIONARY_LAVA:0)
Block(-4,12,3,STATIONARY_LAVA:0)
Block(-4,12,4,STATIONARY_LAVA:0)
Block(-4,12,5,STATIONARY_LAVA:0)
Block(-4,12,6,STATIONARY_LAVA:0)
Block(-4,12,7,STATIONARY_LAVA:0)
Block(-4,12,8,STATIONARY_LAVA:0)
Block(-4,13,-7,OBSIDIAN:0)
Block(-4,13,-6,OBSIDIAN:0)
Block(-4,13,-5,OBSIDIAN:0)
Block(-4,13,-4,OBSIDIAN:0)
Block(-4,13,-3,OBSIDIAN:0)
Block(-4,13,-2,OBSIDIAN:0)
Block(-4,13,-1,OBSIDIAN:0)
Block(-4,13,0,OBSIDIAN:0)
Block(-4,13,1,OBSIDIAN:0)
Block(-4,13,2,OBSIDIAN:0)
Block(-4,13,3,OBSIDIAN:0)
Block(-4,13,4,OBSIDIAN:0)
Block(-4,13,5,OBSIDIAN:0)
Block(-4,13,6,OBSIDIAN:0)
Block(-4,13,7,OBSIDIAN:0)
Block(-4,13,8,OBSIDIAN:0)
Block(-4,14,-7,OBSIDIAN:0)
Block(-4,14,-6,OBSIDIAN:0)
Block(-4,14,-5,OBSIDIAN:0)
Block(-4,14,-4,OBSIDIAN:0)
Block(-4,14,-3,OBSIDIAN:0)
Block(-4,14,-2,OBSIDIAN:0)
Block(-4,14,-1,OBSIDIAN:0)
Block(-4,14,0,OBSIDIAN:0)
Block(-4,14,1,OBSIDIAN:0)
Block(-4,14,2,OBSIDIAN:0)
Block(-4,14,3,OBSIDIAN:0)
Block(-4,14,4,OBSIDIAN:0)
Block(-4,14,5,OBSIDIAN:0)
Block(-4,14,6,OBSIDIAN:0)
Block(-4,14,7,OBSIDIAN:0)
Block(-4,14,8,OBSIDIAN:0)
Block(-4,15,-7,OBSIDIAN:0)
Block(-4,15,-6,OBSIDIAN:0)
Block(-4,15,-5,OBSIDIAN:0)
Block(-4,15,-4,OBSIDIAN:0)
Block(-4,15,-3,OBSIDIAN:0)
Block(-4,15,-2,OBSIDIAN:0)
Block(-4,15,-1,OBSIDIAN:0)
Block(-4,15,0,OBSIDIAN:0)
Block(-4,15,1,OBSIDIAN:0)
Block(-4,15,2,OBSIDIAN:0)
Block(-4,15,3,OBSIDIAN:0)
Block(-4,15,4,OBSIDIAN:0)
Block(-4,15,5,OBSIDIAN:0)
Block(-4,15,6,OBSIDIAN:0)
Block(-4,15,7,OBSIDIAN:0)
Block(-4,15,8,OBSIDIAN:0)
Block(-4,16,-7,OBSIDIAN:0)
Block(-4,16,-6,OBSIDIAN:0)
Block(-4,16,-5,OBSIDIAN:0)
Block(-4,16,-4,OBSIDIAN:0)
Block(-4,16,-3,OBSIDIAN:0)
Block(-4,16,-2,OBSIDIAN:0)
Block(-4,16,-1,OBSIDIAN:0)
Block(-4,16,0,OBSIDIAN:0)
Block(-4,16,1,OBSIDIAN:0)
Block(-4,16,2,OBSIDIAN:0)
Block(-4,16,3,OBSIDIAN:0)
Block(-4,16,4,OBSIDIAN:0)
Block(-4,16,5,OBSIDIAN:0)
Block(-4,16,6,OBSIDIAN:0)
Block(-4,16,7,OBSIDIAN:0)
Block(-4,16,8,OBSIDIAN:0)
Block(-4,17,-7,CONCRETE:7)
Block(-4,17,-6,CONCRETE:7)
Block(-4,17,-5,CONCRETE:7)
Block(-4,17,-4,CONCRETE:7)
Block(-4,17,-3,CONCRETE:7)
Block(-4,17,-2,CONCRETE:7)
Block(-4,17,-1,CONCRETE:7)
Block(-4,17,0,CONCRETE:7)
Block(-4,17,1,CONCRETE:7)
Block(-4,17,2,CONCRETE:7)
Block(-4,17,3,CONCRETE:7)
Block(-4,17,4,CONCRETE:7)
Block(-4,17,5,CONCRETE:7)
Block(-4,17,6,CONCRETE:7)
Block(-4,17,7,CONCRETE:7)
Block(-4,17,8,CONCRETE:7)
Block(-4,18,-6,OBSIDIAN:0)
Block(-4,18,-3,CONCRETE:7)
Block(-4,18,-2,OBSIDIAN:0)
Block(-4,18,-1,CONCRETE:7)
#RandomBlock(-4,18,0,AIR:0,30,CHEST:5,../../../../../Chests/Loot/junk_loot.nbt,10,CHEST:5,../../../../../Chests/Loot/simple_dungeon.nbt,5,CHEST:5,../../../../../Chests/Loot/moderncity_junk_loot.nbt,65,CHEST:3,../../../../../Chests/Loot/moderncity_junk_loot.nbt,20,CHEST:3,../../../../../Chests/Loot/moderncity_common_loot.nbt,5,CHEST:3,../../../../../Chests/Loot/moderncity_rare_loot.nbt,3,CHEST:3,../../../../../Chests/Loot/moderncity_epic_loot.nbt,1,CHEST:3,../../../../../Chests/Loot/moderncity_junk_loot.nbt,100)
RandomBlock(-4,18,1,AIR,90,IRON_TRAPDOOR:5,100)
RandomBlock(-4,18,5,AIR,90,IRON_TRAPDOOR:4,100)
#RandomBlock(-4,18,6,AIR:0,30,CHEST:5,../../../../../Chests/Loot/junk_loot.nbt,10,CHEST:5,../../../../../Chests/Loot/simple_dungeon.nbt,5,CHEST:5,../../../../../Chests/Loot/moderncity_junk_loot.nbt,65,CHEST:2,../../../../../Chests/Loot/moderncity_junk_loot.nbt,20,CHEST:2,../../../../../Chests/Loot/moderncity_common_loot.nbt,5,CHEST:2,../../../../../Chests/Loot/moderncity_rare_loot.nbt,3,CHEST:2,../../../../../Chests/Loot/moderncity_epic_loot.nbt,1,CHEST:2,../../../../../Chests/Loot/moderncity_junk_loot.nbt,100)
Block(-4,18,7,OBSIDIAN:0)
Block(-4,19,-6,STAINED_GLASS_PANE:0)
Block(-4,19,-3,CONCRETE:7)
Block(-4,19,-2,OBSIDIAN:0)
Block(-4,19,-1,CONCRETE:7)
Block(-4,19,0,STEP:8)
Block(-4,19,1,QUARTZ_STAIRS:7)
RandomBlock(-4,19,5,AIR,90,IRON_TRAPDOOR:4,100)
#RandomBlock(-4,19,6,AIR:0,30,CHEST:5,../../../../../Chests/Loot/junk_loot.nbt,10,CHEST:5,../../../../../Chests/Loot/simple_dungeon.nbt,5,CHEST:5,../../../../../Chests/Loot/moderncity_junk_loot.nbt,65,CHEST:2,../../../../../Chests/Loot/moderncity_junk_loot.nbt,20,CHEST:2,../../../../../Chests/Loot/moderncity_common_loot.nbt,5,CHEST:2,../../../../../Chests/Loot/moderncity_rare_loot.nbt,3,CHEST:2,../../../../../Chests/Loot/moderncity_epic_loot.nbt,1,CHEST:2,../../../../../Chests/Loot/moderncity_junk_loot.nbt,100)
Block(-4,19,7,OBSIDIAN:0)
Block(-4,20,-7,STEP:8)
Block(-4,20,-6,OBSIDIAN:0)
Block(-4,20,-5,STEP:8)
Block(-4,20,-4,STEP:8)
Block(-4,20,-3,CONCRETE:7)
Block(-4,20,-2,OBSIDIAN:0)
Block(-4,20,-1,CONCRETE:7)
#RandomBlock(-4,20,0,AIR:0,30,CHEST:5,../../../../../Chests/Loot/junk_loot.nbt,10,CHEST:5,../../../../../Chests/Loot/simple_dungeon.nbt,5,CHEST:5,../../../../../Chests/Loot/moderncity_junk_loot.nbt,65,CHEST:3,../../../../../Chests/Loot/moderncity_junk_loot.nbt,20,CHEST:3,../../../../../Chests/Loot/moderncity_common_loot.nbt,5,CHEST:3,../../../../../Chests/Loot/moderncity_rare_loot.nbt,3,CHEST:3,../../../../../Chests/Loot/moderncity_epic_loot.nbt,1,CHEST:3,../../../../../Chests/Loot/moderncity_junk_loot.nbt,100)
RandomBlock(-4,20,1,AIR,90,IRON_TRAPDOOR:5,100)
RandomBlock(-4,20,5,AIR,90,IRON_TRAPDOOR:4,100)
#RandomBlock(-4,20,6,AIR:0,30,CHEST:5,../../../../../Chests/Loot/junk_loot.nbt,10,CHEST:5,../../../../../Chests/Loot/simple_dungeon.nbt,5,CHEST:5,../../../../../Chests/Loot/moderncity_junk_loot.nbt,65,CHEST:2,../../../../../Chests/Loot/moderncity_junk_loot.nbt,20,CHEST:2,../../../../../Chests/Loot/moderncity_common_loot.nbt,5,CHEST:2,../../../../../Chests/Loot/moderncity_rare_loot.nbt,3,CHEST:2,../../../../../Chests/Loot/moderncity_epic_loot.nbt,1,CHEST:2,../../../../../Chests/Loot/moderncity_junk_loot.nbt,100)
Block(-4,20,7,OBSIDIAN:0)
Block(-4,21,-7,CONCRETE:7)
Block(-4,21,-6,CONCRETE:7)
Block(-4,21,-5,CONCRETE:7)
Block(-4,21,-4,CONCRETE:7)
Block(-4,21,-3,CONCRETE:7)
Block(-4,21,-2,OBSIDIAN:0)
Block(-4,21,-1,CONCRETE:7)
Block(-4,21,0,STEP:0)
Block(-4,21,1,QUARTZ_STAIRS:7)
Block(-4,21,2,STEP:8)
Block(-4,21,3,STEP:8)
Block(-4,21,4,STEP:8)
Block(-4,21,5,QUARTZ_STAIRS:6)
Block(-4,21,6,STEP:0)
Block(-4,21,7,CONCRETE:7)
Block(-4,21,8,STEP:8)
Block(-4,22,-7,OBSIDIAN:0)
Block(-4,22,-6,OBSIDIAN:0)
Block(-4,22,-5,OBSIDIAN:0)
Block(-4,22,-4,OBSIDIAN:0)
Block(-4,22,-3,OBSIDIAN:0)
Block(-4,22,-2,OBSIDIAN:0)
Block(-4,22,-1,CONCRETE:7)
Block(-4,22,0,CONCRETE:7)
Block(-4,22,1,CONCRETE:7)
Block(-4,22,2,CONCRETE:7)
Block(-4,22,3,CONCRETE:7)
Block(-4,22,4,CONCRETE:7)
Block(-4,22,5,CONCRETE:7)
Block(-4,22,6,CONCRETE:7)
Block(-4,22,7,CONCRETE:7)
Block(-4,22,8,CONCRETE:7)
Block(-4,23,-7,CONCRETE:0)
Block(-4,23,-6,CONCRETE:0)
Block(-4,23,-5,CONCRETE:0)
Block(-4,23,-4,CONCRETE:0)
Block(-4,23,-3,CONCRETE:0)
Block(-4,23,-2,OBSIDIAN:0)
Block(-4,23,-1,OBSIDIAN:0)
Block(-4,23,0,OBSIDIAN:0)
Block(-4,23,1,OBSIDIAN:0)
Block(-4,23,2,OBSIDIAN:0)
Block(-4,23,3,OBSIDIAN:0)
Block(-4,23,4,OBSIDIAN:0)
Block(-4,23,5,OBSIDIAN:0)
Block(-4,23,6,OBSIDIAN:0)
Block(-4,23,7,OBSIDIAN:0)
Block(-4,23,8,OBSIDIAN:0)
Block(-4,24,-5,CONCRETE:0)
Block(-4,24,-4,CONCRETE:0)
Block(-4,24,-3,CONCRETE:0)
Block(-4,24,-2,CONCRETE:0)
Block(-4,24,-1,CONCRETE:0)
Block(-4,24,0,STONE:4)
Block(-4,24,1,STONE:4)
Block(-4,24,2,STONE:4)
Block(-4,24,3,CONCRETE:0)
Block(-4,24,4,CONCRETE:0)
Block(-4,24,5,STONE:4)
Block(-4,24,6,CONCRETE:0)
Block(-4,24,7,CONCRETE:0)
Block(-4,24,8,STONE:4)
Block(-4,25,-5,CONCRETE:0)
Block(-4,25,-4,STONE:4)
Block(-4,25,-3,CONCRETE:0)
Block(-4,25,-2,QUARTZ_STAIRS:2)
Block(-4,25,-1,CONCRETE:0)
Block(-4,25,5,DARK_OAK_STAIRS:1)
Block(-4,25,7,DARK_OAK_STAIRS:1)
Block(-4,26,-5,SMOOTH_BRICK:3)
Block(-4,26,-4,STONE:4)
Block(-4,26,-3,CONCRETE:0)
Block(-4,26,-1,CONCRETE:0)
Block(-4,27,-5,CONCRETE:0)
Block(-4,27,-4,STONE:4)
Block(-4,27,-3,CONCRETE:0)
Block(-4,27,-1,CONCRETE:0)
Block(-4,28,-5,QUARTZ_STAIRS:2)
Block(-4,28,-4,STONE:4)
Block(-4,28,-3,CONCRETE:0)
Block(-4,28,-2,QUARTZ_STAIRS:6)
Block(-4,28,-1,CONCRETE:0)
Block(-4,29,-4,STONE:4)
Block(-4,29,-3,CONCRETE:0)
Block(-4,29,-2,CONCRETE:0)
Block(-4,29,-1,CONCRETE:0)
Block(-4,30,-4,SMOOTH_BRICK:3)
Block(-4,30,-3,QUARTZ_STAIRS:3)
Block(-4,30,-2,STEP:7)
Block(-4,30,-1,CONCRETE:7)
Block(-4,30,0,QUARTZ_STAIRS:7)
Block(-4,31,-4,STONE:4)
Block(-4,31,-1,COBBLE_WALL:0)
Block(-4,31,0,CONCRETE:0)
Block(-4,32,-5,QUARTZ_STAIRS:6)
Block(-4,32,-4,STONE:4)
Block(-4,32,-1,COBBLE_WALL:0)
Block(-4,32,0,CONCRETE:8)
Block(-4,33,-5,CONCRETE:0)
Block(-4,33,-4,STONE:4)
Block(-4,33,-1,COBBLE_WALL:0)
Block(-4,33,0,QUARTZ_STAIRS:7)
Block(-4,34,-5,SMOOTH_BRICK:3)
Block(-4,34,-4,STONE:4)
Block(-4,34,-3,QUARTZ_STAIRS:7)
Block(-4,34,-1,COBBLE_WALL:0)
Block(-4,34,0,CONCRETE:0)
Block(-4,35,-5,CONCRETE:0)
Block(-4,35,-4,STONE:4)
Block(-4,35,-3,CONCRETE:0)
Block(-4,35,-1,COBBLE_WALL:0)
Block(-4,35,0,CONCRETE:0)
Block(-4,36,-5,CONCRETE:0)
Block(-4,36,-4,STONE:4)
Block(-4,36,-3,CONCRETE:0)
Block(-4,36,-2,STEP:15)
Block(-4,36,-1,QUARTZ_STAIRS:6)
Block(-4,36,0,CONCRETE:0)
Block(-4,36,1,QUARTZ_STAIRS:7)
Block(-4,37,-6,QUARTZ_STAIRS:6)
Block(-4,37,-5,CONCRETE:0)
Block(-4,37,-4,CONCRETE:0)
Block(-4,37,-3,CONCRETE:0)
Block(-4,37,-2,CONCRETE:0)
Block(-4,37,-1,CONCRETE:0)
Block(-4,37,0,CONCRETE:0)
Block(-4,37,1,CONCRETE:0)
Block(-4,38,-5,STEP:7)
Block(-4,38,-4,STEP:7)
Block(-4,38,-3,STEP:7)
Block(-4,38,-2,STEP:7)
Block(-4,38,-1,STEP:7)
Block(-4,38,0,CONCRETE:0)
Block(-4,38,1,CONCRETE:0)
Block(-4,38,3,CONCRETE:0)
Block(-4,38,5,CONCRETE:0)
Block(-4,38,8,CONCRETE:0)
Block(-4,39,-1,QUARTZ_STAIRS:6)
Block(-4,39,0,CONCRETE:0)
Block(-4,39,1,CONCRETE:0)
Block(-4,39,3,QUARTZ_STAIRS:1)
Block(-4,40,-1,CONCRETE:0)
Block(-4,40,0,QUARTZ_STAIRS:7)
Block(-4,40,1,DOUBLE_STEP:0)
Block(-4,40,2,STEP:15)
Block(-4,40,3,STEP:8)
Block(-4,40,4,STEP:15)
Block(-4,40,5,STEP:15)
Block(-4,40,6,STEP:15)
Block(-4,40,7,STEP:15)
Block(-4,40,8,STEP:15)
Block(-4,41,-1,STAINED_GLASS_PANE:15)
Block(-4,41,8,CONCRETE:7)
Block(-4,42,8,CONCRETE:7)
Block(-4,43,8,CONCRETE:7)
Block(-4,44,8,CONCRETE:7)
Block(-4,45,8,CONCRETE:7)
Block(-4,46,8,CONCRETE:0)
Block(-4,47,8,CONCRETE:7)
Block(-3,0,-7,CONCRETE:7)
Block(-3,0,-6,CONCRETE:7)
Block(-3,0,-5,CONCRETE:7)
Block(-3,0,-4,CONCRETE:7)
Block(-3,0,-3,CONCRETE:7)
Block(-3,0,-2,CONCRETE:7)
Block(-3,0,-1,CONCRETE:7)
Block(-3,0,0,CONCRETE:7)
Block(-3,0,1,CONCRETE:7)
Block(-3,0,2,CONCRETE:7)
Block(-3,0,3,CONCRETE:7)
Block(-3,0,4,CONCRETE:7)
Block(-3,0,5,CONCRETE:7)
Block(-3,0,6,CONCRETE:7)
Block(-3,0,7,CONCRETE:7)
Block(-3,0,8,CONCRETE:7)
Block(-3,1,-7,OBSIDIAN:0)
Block(-3,1,-6,OBSIDIAN:0)
Block(-3,1,-5,OBSIDIAN:0)
Block(-3,1,-4,OBSIDIAN:0)
Block(-3,1,-3,OBSIDIAN:0)
Block(-3,1,-2,OBSIDIAN:0)
Block(-3,1,-1,OBSIDIAN:0)
Block(-3,1,0,OBSIDIAN:0)
Block(-3,1,1,OBSIDIAN:0)
Block(-3,1,2,OBSIDIAN:0)
Block(-3,1,3,OBSIDIAN:0)
Block(-3,1,4,OBSIDIAN:0)
Block(-3,1,5,OBSIDIAN:0)
Block(-3,1,6,OBSIDIAN:0)
Block(-3,1,7,OBSIDIAN:0)
Block(-3,1,8,OBSIDIAN:0)
Block(-3,2,-7,OBSIDIAN:0)
Block(-3,2,-6,OBSIDIAN:0)
Block(-3,2,-5,OBSIDIAN:0)
Block(-3,2,-4,OBSIDIAN:0)
Block(-3,2,-3,OBSIDIAN:0)
Block(-3,2,-2,OBSIDIAN:0)
Block(-3,2,-1,OBSIDIAN:0)
Block(-3,2,0,OBSIDIAN:0)
Block(-3,2,1,OBSIDIAN:0)
Block(-3,2,2,OBSIDIAN:0)
Block(-3,2,3,OBSIDIAN:0)
Block(-3,2,4,OBSIDIAN:0)
Block(-3,2,5,OBSIDIAN:0)
Block(-3,2,6,OBSIDIAN:0)
Block(-3,2,7,OBSIDIAN:0)
Block(-3,2,8,OBSIDIAN:0)
Block(-3,3,-7,STATIONARY_LAVA:0)
Block(-3,3,-6,STATIONARY_LAVA:0)
Block(-3,3,-5,STATIONARY_LAVA:0)
Block(-3,3,-4,STATIONARY_LAVA:0)
Block(-3,3,-3,STATIONARY_LAVA:0)
Block(-3,3,-2,STATIONARY_LAVA:0)
Block(-3,3,-1,STATIONARY_LAVA:0)
Block(-3,3,0,STATIONARY_LAVA:0)
Block(-3,3,1,STATIONARY_LAVA:0)
Block(-3,3,2,STATIONARY_LAVA:0)
Block(-3,3,3,STATIONARY_LAVA:0)
Block(-3,3,4,STATIONARY_LAVA:0)
Block(-3,3,5,STATIONARY_LAVA:0)
Block(-3,3,6,STATIONARY_LAVA:0)
Block(-3,3,7,STATIONARY_LAVA:0)
Block(-3,3,8,STATIONARY_LAVA:0)
Block(-3,4,-7,OBSIDIAN:0)
Block(-3,4,-6,OBSIDIAN:0)
Block(-3,4,-5,OBSIDIAN:0)
Block(-3,4,-4,OBSIDIAN:0)
Block(-3,4,-3,OBSIDIAN:0)
Block(-3,4,-2,OBSIDIAN:0)
Block(-3,4,-1,OBSIDIAN:0)
Block(-3,4,0,OBSIDIAN:0)
Block(-3,4,1,OBSIDIAN:0)
Block(-3,4,2,OBSIDIAN:0)
Block(-3,4,3,OBSIDIAN:0)
Block(-3,4,4,OBSIDIAN:0)
Block(-3,4,5,OBSIDIAN:0)
Block(-3,4,6,OBSIDIAN:0)
Block(-3,4,7,OBSIDIAN:0)
Block(-3,4,8,OBSIDIAN:0)
Block(-3,5,-7,minecraft:yellow_glazed_terracotta:0)
Block(-3,5,-6,GOLD_PLATE:0)
RandomBlock(-3,5,-5,emerald_ore,50,gold_ore,35,iron_ore,100)
RandomBlock(-3,5,-4,GOLD_BLOCK,40,MOB_SPAWNER:0,../../DestructionLayers/Parasites/parasite_multi.nbt,20,CHEST:2,../../../../../Chests/Loot/simple_dungeon.nbt,10,CHEST:2,../../../../../Chests/Loot/gem_loot.nbt,10,CHEST:2,../../../../../Chests/Loot/desert_pyramid.nbt,5,CHEST:2,../../../../../Chests/Loot/jungle_temple.nbt,5,CHEST:2,../../../../../Chests/Loot/stronghold_library.nbt,10,CHEST:2,../../../../../Chests/Loot/woodland_mansion.nbt,10,CHEST:2,../../../../../Chests/Loot/end_city_treasure.nbt,10,CHEST:2,../../../../../Chests/RLCraft/IceAndFire/fire_dragon_roost_chest.nbt,5,CHEST:2,../../../../../Chests/lore/moderncity.nbt,5,chest:2,../../../../../Chests/RLCraft/IceAndFire/ice_dragon_roost_chest.nbt,5,chest:2,../../../../../Chests/lore/moderncity.nbt,2,chest:2,../../../../../Chests/RLCraft/IceAndFire/lightning_dragon_roost_chest.nbt,5,chest:2,../../../../../Chests/loot/moderncity_epic_loot.nbt,100)
Block(-3,5,-3,IRON_PLATE:0)
Block(-3,5,-2,OBSIDIAN:0)
Block(-3,5,-1,IRON_PLATE:0)
Block(-3,5,0,STEP:0)
Block(-3,5,1,STEP:0)
Block(-3,5,2,DOUBLE_STEP:0)
Block(-3,5,3,STEP:0)
Block(-3,5,4,STEP:0)
Block(-3,5,5,IRON_PLATE:0)
Block(-3,5,6,IRON_PLATE:0)
Block(-3,5,7,IRON_PLATE:0)
Block(-3,5,8,IRON_PLATE:0)
Block(-3,6,-7,STEP:8)
Block(-3,6,-6,STEP:8)
Block(-3,6,-5,STEP:8)
Block(-3,6,-4,STEP:8)
Block(-3,6,-2,OBSIDIAN:0)
Block(-3,6,2,SMOOTH_STAIRS:0)
Block(-3,7,-7,GOLD_PLATE:0)
Block(-3,7,-6,minecraft:yellow_glazed_terracotta:0)
Block(-3,7,-5,GOLD_BLOCK:0)
Block(-3,7,-4,GOLD_PLATE:0)
Block(-3,7,-2,OBSIDIAN:0)
Block(-3,8,-7,STEP:8)
Block(-3,8,-6,STEP:8)
Block(-3,8,-5,STEP:8)
Block(-3,8,-4,STEP:8)
Block(-3,8,-2,OBSIDIAN:0)
Block(-3,8,6,STEP:8)
Block(-3,8,7,STEP:8)
RandomBlock(-3,9,-7,GOLD_BLOCK,40,MOB_SPAWNER:0,../../DestructionLayers/Parasites/parasite_multi.nbt,20,CHEST:2,../../../../../Chests/Loot/simple_dungeon.nbt,10,CHEST:2,../../../../../Chests/Loot/gem_loot.nbt,10,CHEST:2,../../../../../Chests/Loot/desert_pyramid.nbt,5,CHEST:2,../../../../../Chests/Loot/jungle_temple.nbt,5,CHEST:2,../../../../../Chests/Loot/stronghold_library.nbt,10,CHEST:2,../../../../../Chests/Loot/woodland_mansion.nbt,10,CHEST:2,../../../../../Chests/Loot/end_city_treasure.nbt,10,CHEST:2,../../../../../Chests/RLCraft/IceAndFire/fire_dragon_roost_chest.nbt,5,CHEST:2,../../../../../Chests/lore/moderncity.nbt,5,chest:2,../../../../../Chests/RLCraft/IceAndFire/ice_dragon_roost_chest.nbt,5,chest:2,../../../../../Chests/lore/moderncity.nbt,2,chest:2,../../../../../Chests/RLCraft/IceAndFire/lightning_dragon_roost_chest.nbt,5,chest:2,../../../../../Chests/loot/moderncity_epic_loot.nbt,100)
RandomBlock(-3,9,-6,AIR:0,20,TNT:0,100)
Block(-3,9,-4,minecraft:yellow_glazed_terracotta:0)
Block(-3,9,-2,OBSIDIAN:0)
Block(-3,9,2,SMOOTH_STAIRS:4)
Block(-3,9,6,REDSTONE_WIRE:0)
Block(-3,9,7,REDSTONE_WIRE:0)
Block(-3,10,-7,STEP:8)
Block(-3,10,-6,STEP:8)
Block(-3,10,-5,STEP:8)
Block(-3,10,-4,STEP:8)
Block(-3,10,-3,STEP:8)
Block(-3,10,-2,OBSIDIAN:0)
Block(-3,10,0,STEP:8)
Block(-3,10,1,STEP:8)
Block(-3,10,2,DOUBLE_STEP:0)
Block(-3,10,3,STEP:8)
Block(-3,10,4,STEP:8)
Block(-3,10,5,STEP:8)
Block(-3,10,6,STEP:8)
Block(-3,10,7,STEP:8)
Block(-3,10,8,STEP:8)
Block(-3,11,-7,OBSIDIAN:0)
Block(-3,11,-6,OBSIDIAN:0)
Block(-3,11,-5,OBSIDIAN:0)
Block(-3,11,-4,OBSIDIAN:0)
Block(-3,11,-3,OBSIDIAN:0)
Block(-3,11,-2,OBSIDIAN:0)
Block(-3,11,-1,OBSIDIAN:0)
Block(-3,11,0,OBSIDIAN:0)
Block(-3,11,1,OBSIDIAN:0)
Block(-3,11,2,OBSIDIAN:0)
Block(-3,11,3,OBSIDIAN:0)
Block(-3,11,4,OBSIDIAN:0)
Block(-3,11,5,OBSIDIAN:0)
Block(-3,11,6,OBSIDIAN:0)
Block(-3,11,7,OBSIDIAN:0)
Block(-3,11,8,OBSIDIAN:0)
Block(-3,12,-7,STATIONARY_LAVA:0)
Block(-3,12,-6,STATIONARY_LAVA:0)
Block(-3,12,-5,STATIONARY_LAVA:0)
Block(-3,12,-4,STATIONARY_LAVA:0)
Block(-3,12,-3,STATIONARY_LAVA:0)
Block(-3,12,-2,STATIONARY_LAVA:0)
Block(-3,12,-1,STATIONARY_LAVA:0)
Block(-3,12,0,STATIONARY_LAVA:0)
Block(-3,12,1,STATIONARY_LAVA:0)
Block(-3,12,2,STATIONARY_LAVA:0)
Block(-3,12,3,STATIONARY_LAVA:0)
Block(-3,12,4,STATIONARY_LAVA:0)
Block(-3,12,5,STATIONARY_LAVA:0)
Block(-3,12,6,STATIONARY_LAVA:0)
Block(-3,12,7,STATIONARY_LAVA:0)
Block(-3,12,8,STATIONARY_LAVA:0)
Block(-3,13,-7,OBSIDIAN:0)
Block(-3,13,-6,OBSIDIAN:0)
Block(-3,13,-5,OBSIDIAN:0)
Block(-3,13,-4,OBSIDIAN:0)
Block(-3,13,-3,OBSIDIAN:0)
Block(-3,13,-2,OBSIDIAN:0)
Block(-3,13,-1,OBSIDIAN:0)
Block(-3,13,0,OBSIDIAN:0)
Block(-3,13,1,OBSIDIAN:0)
Block(-3,13,2,OBSIDIAN:0)
Block(-3,13,3,OBSIDIAN:0)
Block(-3,13,4,OBSIDIAN:0)
Block(-3,13,5,OBSIDIAN:0)
Block(-3,13,6,OBSIDIAN:0)
Block(-3,13,7,OBSIDIAN:0)
Block(-3,13,8,OBSIDIAN:0)
Block(-3,14,-7,OBSIDIAN:0)
Block(-3,14,-6,OBSIDIAN:0)
Block(-3,14,-5,OBSIDIAN:0)
Block(-3,14,-4,OBSIDIAN:0)
Block(-3,14,-3,OBSIDIAN:0)
Block(-3,14,-2,OBSIDIAN:0)
Block(-3,14,-1,OBSIDIAN:0)
Block(-3,14,0,OBSIDIAN:0)
Block(-3,14,1,OBSIDIAN:0)
Block(-3,14,2,OBSIDIAN:0)
Block(-3,14,3,OBSIDIAN:0)
Block(-3,14,4,OBSIDIAN:0)
Block(-3,14,5,OBSIDIAN:0)
Block(-3,14,6,OBSIDIAN:0)
Block(-3,14,7,OBSIDIAN:0)
Block(-3,14,8,OBSIDIAN:0)
Block(-3,15,-7,OBSIDIAN:0)
Block(-3,15,-6,OBSIDIAN:0)
Block(-3,15,-5,OBSIDIAN:0)
Block(-3,15,-4,OBSIDIAN:0)
Block(-3,15,-3,OBSIDIAN:0)
Block(-3,15,-2,OBSIDIAN:0)
Block(-3,15,-1,OBSIDIAN:0)
Block(-3,15,0,OBSIDIAN:0)
Block(-3,15,1,OBSIDIAN:0)
Block(-3,15,2,OBSIDIAN:0)
Block(-3,15,3,OBSIDIAN:0)
Block(-3,15,4,OBSIDIAN:0)
Block(-3,15,5,OBSIDIAN:0)
Block(-3,15,6,OBSIDIAN:0)
Block(-3,15,7,OBSIDIAN:0)
Block(-3,15,8,OBSIDIAN:0)
Block(-3,16,-7,OBSIDIAN:0)
Block(-3,16,-6,OBSIDIAN:0)
Block(-3,16,-5,OBSIDIAN:0)
Block(-3,16,-4,OBSIDIAN:0)
Block(-3,16,-3,OBSIDIAN:0)
Block(-3,16,-2,OBSIDIAN:0)
Block(-3,16,-1,OBSIDIAN:0)
Block(-3,16,0,OBSIDIAN:0)
Block(-3,16,1,OBSIDIAN:0)
Block(-3,16,2,OBSIDIAN:0)
Block(-3,16,3,OBSIDIAN:0)
Block(-3,16,4,OBSIDIAN:0)
Block(-3,16,5,OBSIDIAN:0)
Block(-3,16,6,OBSIDIAN:0)
Block(-3,16,7,OBSIDIAN:0)
Block(-3,16,8,OBSIDIAN:0)
Block(-3,17,-7,CONCRETE:7)
Block(-3,17,-6,CONCRETE:7)
Block(-3,17,-5,CONCRETE:7)
Block(-3,17,-4,CONCRETE:7)
Block(-3,17,-3,CONCRETE:7)
Block(-3,17,-2,CONCRETE:7)
Block(-3,17,-1,CONCRETE:7)
Block(-3,17,0,CONCRETE:7)
Block(-3,17,1,CONCRETE:7)
Block(-3,17,2,CONCRETE:7)
Block(-3,17,3,CONCRETE:7)
Block(-3,17,4,CONCRETE:7)
Block(-3,17,5,CONCRETE:7)
Block(-3,17,6,CONCRETE:7)
Block(-3,17,7,CONCRETE:7)
Block(-3,17,8,CONCRETE:7)
Block(-3,18,-6,OBSIDIAN:0)
Block(-3,18,-3,CONCRETE:7)
Block(-3,18,-2,OBSIDIAN:0)
Block(-3,18,-1,CONCRETE:7)
Block(-3,18,0,STONE:4)
Block(-3,18,1,STONE:4)
Block(-3,18,2,LEVER:11)
Block(-3,18,4,LEVER:12)
Block(-3,18,5,STONE:4)
Block(-3,18,6,STONE:4)
Block(-3,18,7,CONCRETE:7)
Block(-3,19,-6,STAINED_GLASS_PANE:0)
Block(-3,19,-3,CONCRETE:7)
Block(-3,19,-2,OBSIDIAN:0)
Block(-3,19,-1,CONCRETE:7)
Block(-3,19,0,STONE:4)
Block(-3,19,1,STONE:4)
Block(-3,19,4,LEVER:12)
Block(-3,19,5,STONE:4)
Block(-3,19,6,STONE:4)
Block(-3,19,7,CONCRETE:7)
Block(-3,20,-7,STEP:8)
Block(-3,20,-6,OBSIDIAN:0)
Block(-3,20,-5,STEP:8)
Block(-3,20,-4,STEP:8)
Block(-3,20,-3,CONCRETE:7)
Block(-3,20,-2,OBSIDIAN:0)
Block(-3,20,-1,CONCRETE:7)
Block(-3,20,0,STONE:4)
Block(-3,20,1,STONE:4)
Block(-3,20,2,LEVER:11)
Block(-3,20,4,LEVER:12)
Block(-3,20,5,STONE:4)
Block(-3,20,6,STONE:4)
Block(-3,20,7,CONCRETE:7)
Block(-3,21,-7,CONCRETE:7)
Block(-3,21,-6,CONCRETE:7)
Block(-3,21,-5,CONCRETE:7)
Block(-3,21,-4,CONCRETE:7)
Block(-3,21,-3,CONCRETE:7)
Block(-3,21,-2,OBSIDIAN:0)
Block(-3,21,-1,CONCRETE:7)
Block(-3,21,0,STONE:4)
Block(-3,21,1,STONE:4)
Block(-3,21,2,STEP:8)
Block(-3,21,3,STEP:8)
Block(-3,21,4,STEP:8)
Block(-3,21,5,STONE:4)
Block(-3,21,6,STONE:4)
Block(-3,21,7,CONCRETE:7)
Block(-3,21,8,STEP:8)
Block(-3,22,-7,OBSIDIAN:0)
Block(-3,22,-6,OBSIDIAN:0)
Block(-3,22,-5,OBSIDIAN:0)
Block(-3,22,-4,OBSIDIAN:0)
Block(-3,22,-3,OBSIDIAN:0)
Block(-3,22,-2,OBSIDIAN:0)
Block(-3,22,-1,CONCRETE:7)
Block(-3,22,0,CONCRETE:7)
Block(-3,22,1,CONCRETE:7)
Block(-3,22,2,CONCRETE:7)
Block(-3,22,3,CONCRETE:7)
Block(-3,22,4,CONCRETE:7)
Block(-3,22,5,CONCRETE:7)
Block(-3,22,6,CONCRETE:7)
Block(-3,22,7,CONCRETE:7)
Block(-3,22,8,CONCRETE:7)
Block(-3,23,-7,CONCRETE:0)
Block(-3,23,-6,CONCRETE:0)
Block(-3,23,-5,CONCRETE:0)
Block(-3,23,-4,CONCRETE:0)
Block(-3,23,-3,CONCRETE:0)
Block(-3,23,-2,OBSIDIAN:0)
Block(-3,23,-1,OBSIDIAN:0)
Block(-3,23,0,OBSIDIAN:0)
Block(-3,23,1,OBSIDIAN:0)
Block(-3,23,2,OBSIDIAN:0)
Block(-3,23,3,OBSIDIAN:0)
Block(-3,23,4,OBSIDIAN:0)
Block(-3,23,5,OBSIDIAN:0)
Block(-3,23,6,OBSIDIAN:0)
Block(-3,23,7,OBSIDIAN:0)
Block(-3,23,8,OBSIDIAN:0)
Block(-3,24,-5,QUARTZ_STAIRS:2)
Block(-3,24,-4,QUARTZ_STAIRS:1)
Block(-3,24,-3,CONCRETE:0)
Block(-3,24,-2,CONCRETE:0)
Block(-3,24,-1,CONCRETE:7)
Block(-3,24,0,CONCRETE:0)
Block(-3,24,1,CONCRETE:0)
Block(-3,24,2,CONCRETE:15)
Block(-3,24,3,STONE:4)
Block(-3,24,4,CONCRETE:0)
Block(-3,24,5,STONE:4)
Block(-3,24,6,CONCRETE:0)
Block(-3,24,7,CONCRETE:0)
Block(-3,24,8,STONE:4)
Block(-3,25,-1,STAINED_GLASS_PANE:15)
Block(-3,25,5,DARK_OAK_STAIRS:6)
Block(-3,25,6,DARK_OAK_STAIRS:4)
Block(-3,25,7,DARK_OAK_STAIRS:4)
Block(-3,25,8,DARK_OAK_STAIRS:4)
Block(-3,26,-1,STAINED_GLASS_PANE:15)
Block(-3,27,-1,STAINED_GLASS_PANE:15)
Block(-3,28,-1,STEP:8)
Block(-3,29,-3,QUARTZ_STAIRS:6)
Block(-3,29,-2,CONCRETE:0)
Block(-3,29,-1,CONCRETE:0)
Block(-3,30,-2,STEP:7)
Block(-3,30,-1,CONCRETE:7)
Block(-3,30,0,STEP:8)
Block(-3,31,0,CONCRETE:8)
Block(-3,32,0,CONCRETE:8)
Block(-3,33,0,CONCRETE:8)
Block(-3,34,0,CONCRETE:8)
Block(-3,35,-4,QUARTZ_STAIRS:5)
Block(-3,35,0,CONCRETE:8)
Block(-3,36,-6,QUARTZ_STAIRS:6)
Block(-3,36,-5,CONCRETE:0)
Block(-3,36,-4,CONCRETE:0)
Block(-3,36,-3,CONCRETE:0)
Block(-3,36,-2,CONCRETE:0)
Block(-3,36,-1,CONCRETE:0)
Block(-3,36,0,CONCRETE:8)
Block(-3,37,-6,QUARTZ_STAIRS:1)
Block(-3,37,-5,QUARTZ_STAIRS:1)
Block(-3,37,-4,QUARTZ_STAIRS:1)
Block(-3,37,-3,COBBLE_WALL:0)
Block(-3,37,-2,CONCRETE:0)
Block(-3,37,-1,CONCRETE:0)
Block(-3,37,0,CONCRETE:8)
Block(-3,37,5,QUARTZ_STAIRS:4)
Block(-3,37,8,QUARTZ_STAIRS:4)
Block(-3,38,-2,CONCRETE:0)
Block(-3,38,-1,CONCRETE:0)
Block(-3,38,0,CONCRETE:8)
Block(-3,38,3,CONCRETE:0)
Block(-3,38,5,CONCRETE:0)
Block(-3,38,8,CONCRETE:0)
Block(-3,39,-2,QUARTZ_STAIRS:2)
Block(-3,39,-1,CONCRETE:0)
Block(-3,39,0,CONCRETE:8)
Block(-3,40,-1,CONCRETE:0)
Block(-3,40,0,QUARTZ_STAIRS:7)
Block(-3,40,1,DOUBLE_STEP:0)
Block(-3,40,2,STEP:8)
Block(-3,40,3,STEP:15)
Block(-3,40,4,STEP:15)
Block(-3,40,5,STEP:8)
Block(-3,40,6,STEP:15)
Block(-3,40,7,STEP:15)
Block(-3,40,8,STEP:8)
Block(-3,41,-1,CONCRETE:0)
Block(-3,41,0,STAINED_GLASS_PANE:15)
Block(-3,41,8,CONCRETE:7)
Block(-3,42,-1,COBBLE_WALL:0)
Block(-3,42,8,CONCRETE:7)
Block(-3,43,8,CONCRETE:7)
Block(-2,0,-7,CONCRETE:7)
Block(-2,0,-6,CONCRETE:7)
Block(-2,0,-5,CONCRETE:7)
Block(-2,0,-4,CONCRETE:7)
Block(-2,0,-3,CONCRETE:7)
Block(-2,0,-2,CONCRETE:7)
Block(-2,0,-1,CONCRETE:7)
Block(-2,0,0,CONCRETE:7)
Block(-2,0,1,CONCRETE:7)
Block(-2,0,2,CONCRETE:7)
Block(-2,0,3,CONCRETE:7)
Block(-2,0,4,CONCRETE:7)
Block(-2,0,5,CONCRETE:7)
Block(-2,0,6,CONCRETE:7)
Block(-2,0,7,CONCRETE:7)
Block(-2,0,8,CONCRETE:7)
Block(-2,1,-7,OBSIDIAN:0)
Block(-2,1,-6,OBSIDIAN:0)
Block(-2,1,-5,OBSIDIAN:0)
Block(-2,1,-4,OBSIDIAN:0)
Block(-2,1,-3,OBSIDIAN:0)
Block(-2,1,-2,OBSIDIAN:0)
Block(-2,1,-1,OBSIDIAN:0)
Block(-2,1,0,OBSIDIAN:0)
Block(-2,1,1,OBSIDIAN:0)
Block(-2,1,2,OBSIDIAN:0)
Block(-2,1,3,OBSIDIAN:0)
Block(-2,1,4,OBSIDIAN:0)
Block(-2,1,5,OBSIDIAN:0)
Block(-2,1,6,OBSIDIAN:0)
Block(-2,1,7,OBSIDIAN:0)
Block(-2,1,8,OBSIDIAN:0)
Block(-2,2,-7,OBSIDIAN:0)
Block(-2,2,-6,OBSIDIAN:0)
Block(-2,2,-5,OBSIDIAN:0)
Block(-2,2,-4,OBSIDIAN:0)
Block(-2,2,-3,OBSIDIAN:0)
Block(-2,2,-2,OBSIDIAN:0)
Block(-2,2,-1,OBSIDIAN:0)
Block(-2,2,0,OBSIDIAN:0)
Block(-2,2,1,OBSIDIAN:0)
Block(-2,2,2,OBSIDIAN:0)
Block(-2,2,3,OBSIDIAN:0)
Block(-2,2,4,OBSIDIAN:0)
Block(-2,2,5,OBSIDIAN:0)
Block(-2,2,6,OBSIDIAN:0)
Block(-2,2,7,OBSIDIAN:0)
Block(-2,2,8,OBSIDIAN:0)
Block(-2,3,-7,STATIONARY_LAVA:0)
Block(-2,3,-6,STATIONARY_LAVA:0)
Block(-2,3,-5,STATIONARY_LAVA:0)
Block(-2,3,-4,STATIONARY_LAVA:0)
Block(-2,3,-3,STATIONARY_LAVA:0)
Block(-2,3,-2,STATIONARY_LAVA:0)
Block(-2,3,-1,STATIONARY_LAVA:0)
Block(-2,3,0,STATIONARY_LAVA:0)
Block(-2,3,1,STATIONARY_LAVA:0)
Block(-2,3,2,STATIONARY_LAVA:0)
Block(-2,3,3,STATIONARY_LAVA:0)
Block(-2,3,4,STATIONARY_LAVA:0)
Block(-2,3,5,STATIONARY_LAVA:0)
Block(-2,3,6,STATIONARY_LAVA:0)
Block(-2,3,7,STATIONARY_LAVA:0)
Block(-2,3,8,STATIONARY_LAVA:0)
Block(-2,4,-7,OBSIDIAN:0)
Block(-2,4,-6,OBSIDIAN:0)
Block(-2,4,-5,OBSIDIAN:0)
Block(-2,4,-4,OBSIDIAN:0)
Block(-2,4,-3,OBSIDIAN:0)
Block(-2,4,-2,OBSIDIAN:0)
Block(-2,4,-1,OBSIDIAN:0)
Block(-2,4,0,OBSIDIAN:0)
Block(-2,4,1,OBSIDIAN:0)
Block(-2,4,2,OBSIDIAN:0)
Block(-2,4,3,OBSIDIAN:0)
Block(-2,4,4,OBSIDIAN:0)
Block(-2,4,5,OBSIDIAN:0)
Block(-2,4,6,OBSIDIAN:0)
Block(-2,4,7,OBSIDIAN:0)
Block(-2,4,8,OBSIDIAN:0)
RandomBlock(-2,5,-7,emerald_ore,50,gold_ore,35,iron_ore,100)
Block(-2,5,-6,minecraft:yellow_glazed_terracotta:0)
RandomBlock(-2,5,-5,GOLD_BLOCK,40,MOB_SPAWNER:0,../../DestructionLayers/Parasites/parasite_multi.nbt,20,CHEST:2,../../../../../Chests/Loot/simple_dungeon.nbt,10,CHEST:2,../../../../../Chests/Loot/gem_loot.nbt,10,CHEST:2,../../../../../Chests/Loot/desert_pyramid.nbt,5,CHEST:2,../../../../../Chests/Loot/jungle_temple.nbt,5,CHEST:2,../../../../../Chests/Loot/stronghold_library.nbt,10,CHEST:2,../../../../../Chests/Loot/woodland_mansion.nbt,10,CHEST:2,../../../../../Chests/Loot/end_city_treasure.nbt,10,CHEST:2,../../../../../Chests/RLCraft/IceAndFire/fire_dragon_roost_chest.nbt,5,CHEST:2,../../../../../Chests/lore/moderncity.nbt,5,chest:2,../../../../../Chests/RLCraft/IceAndFire/ice_dragon_roost_chest.nbt,5,chest:2,../../../../../Chests/lore/moderncity.nbt,2,chest:2,../../../../../Chests/RLCraft/IceAndFire/lightning_dragon_roost_chest.nbt,5,chest:2,../../../../../Chests/loot/moderncity_epic_loot.nbt,100)
Block(-2,5,-4,GOLD_BLOCK:0)
Block(-2,5,-3,IRON_PLATE:0)
Block(-2,5,-2,OBSIDIAN:0)
Block(-2,5,-1,IRON_PLATE:0)
Block(-2,5,0,STEP:0)
Block(-2,5,1,COBBLE_WALL:0)
Block(-2,5,2,CONCRETE:7)
Block(-2,5,3,COBBLE_WALL:0)
Block(-2,5,4,STEP:0)
Block(-2,5,5,IRON_PLATE:0)
Block(-2,5,6,IRON_PLATE:0)
Block(-2,5,7,IRON_PLATE:0)
Block(-2,5,8,IRON_PLATE:0)
Block(-2,6,-7,STEP:8)
Block(-2,6,-6,STEP:8)
Block(-2,6,-5,STEP:8)
Block(-2,6,-4,STEP:8)
Block(-2,6,-2,OBSIDIAN:0)
Block(-2,6,1,STEP:0)
Block(-2,6,2,CONCRETE:7)
Block(-2,6,3,STEP:0)
Block(-2,7,-7,GOLD_PLATE:0)
RandomBlock(-2,7,-6,GOLD_BLOCK,40,MOB_SPAWNER:0,../../DestructionLayers/Parasites/parasite_multi.nbt,20,CHEST:2,../../../../../Chests/Loot/simple_dungeon.nbt,10,CHEST:2,../../../../../Chests/Loot/gem_loot.nbt,10,CHEST:2,../../../../../Chests/Loot/desert_pyramid.nbt,5,CHEST:2,../../../../../Chests/Loot/jungle_temple.nbt,5,CHEST:2,../../../../../Chests/Loot/stronghold_library.nbt,10,CHEST:2,../../../../../Chests/Loot/woodland_mansion.nbt,10,CHEST:2,../../../../../Chests/Loot/end_city_treasure.nbt,10,CHEST:2,../../../../../Chests/RLCraft/IceAndFire/fire_dragon_roost_chest.nbt,5,CHEST:2,../../../../../Chests/lore/moderncity.nbt,5,chest:2,../../../../../Chests/RLCraft/IceAndFire/ice_dragon_roost_chest.nbt,5,chest:2,../../../../../Chests/lore/moderncity.nbt,2,chest:2,../../../../../Chests/RLCraft/IceAndFire/lightning_dragon_roost_chest.nbt,5,chest:2,../../../../../Chests/loot/moderncity_epic_loot.nbt,100)
Block(-2,7,-5,GOLD_PLATE:0)
RandomBlock(-2,7,-4,GOLD_BLOCK,40,MOB_SPAWNER:0,../../DestructionLayers/Parasites/parasite_multi.nbt,20,CHEST:2,../../../../../Chests/Loot/simple_dungeon.nbt,10,CHEST:2,../../../../../Chests/Loot/gem_loot.nbt,10,CHEST:2,../../../../../Chests/Loot/desert_pyramid.nbt,5,CHEST:2,../../../../../Chests/Loot/jungle_temple.nbt,5,CHEST:2,../../../../../Chests/Loot/stronghold_library.nbt,10,CHEST:2,../../../../../Chests/Loot/woodland_mansion.nbt,10,CHEST:2,../../../../../Chests/Loot/end_city_treasure.nbt,10,CHEST:2,../../../../../Chests/RLCraft/IceAndFire/fire_dragon_roost_chest.nbt,5,CHEST:2,../../../../../Chests/lore/moderncity.nbt,5,chest:2,../../../../../Chests/RLCraft/IceAndFire/ice_dragon_roost_chest.nbt,5,chest:2,../../../../../Chests/lore/moderncity.nbt,2,chest:2,../../../../../Chests/RLCraft/IceAndFire/lightning_dragon_roost_chest.nbt,5,chest:2,../../../../../Chests/loot/moderncity_epic_loot.nbt,100)
Block(-2,7,-2,OBSIDIAN:0)
Block(-2,7,1,COBBLE_WALL:0)
Block(-2,7,2,CONCRETE:7)
Block(-2,7,3,COBBLE_WALL:0)
Block(-2,8,-7,STEP:8)
Block(-2,8,-6,STEP:8)
Block(-2,8,-5,STEP:8)
Block(-2,8,-4,STEP:8)
Block(-2,8,-2,OBSIDIAN:0)
Block(-2,8,1,COBBLE_WALL:0)
Block(-2,8,2,CONCRETE:7)
Block(-2,8,3,COBBLE_WALL:0)
Block(-2,8,6,STEP:8)
Block(-2,8,7,STEP:8)
Block(-2,9,-7,minecraft:yellow_glazed_terracotta:0)
RandomBlock(-2,9,-6,AIR:0,20,TNT:0,100)
RandomBlock(-2,9,-5,AIR:0,20,TNT:0,100)
Block(-2,9,-4,GOLD_BLOCK:0)
Block(-2,9,-2,OBSIDIAN:0)
Block(-2,9,1,STEP:8)
Block(-2,9,2,CONCRETE:7)
Block(-2,9,3,STEP:8)
Block(-2,9,6,REDSTONE_WIRE:0)
Block(-2,9,7,REDSTONE_WIRE:0)
Block(-2,10,-7,STEP:8)
Block(-2,10,-6,STEP:8)
Block(-2,10,-5,STEP:8)
Block(-2,10,-4,STEP:8)
Block(-2,10,-3,STEP:8)
Block(-2,10,-2,OBSIDIAN:0)
Block(-2,10,-1,STEP:8)
Block(-2,10,0,STEP:8)
Block(-2,10,1,COBBLE_WALL:0)
Block(-2,10,2,OBSIDIAN:0)
Block(-2,10,3,COBBLE_WALL:0)
Block(-2,10,4,STEP:8)
Block(-2,10,5,STEP:8)
Block(-2,10,6,STEP:8)
Block(-2,10,7,STEP:8)
Block(-2,10,8,STEP:8)
Block(-2,11,-7,OBSIDIAN:0)
Block(-2,11,-6,OBSIDIAN:0)
Block(-2,11,-5,OBSIDIAN:0)
Block(-2,11,-4,OBSIDIAN:0)
Block(-2,11,-3,OBSIDIAN:0)
Block(-2,11,-2,OBSIDIAN:0)
Block(-2,11,-1,OBSIDIAN:0)
Block(-2,11,0,OBSIDIAN:0)
Block(-2,11,1,OBSIDIAN:0)
Block(-2,11,2,OBSIDIAN:0)
Block(-2,11,3,OBSIDIAN:0)
Block(-2,11,4,OBSIDIAN:0)
Block(-2,11,5,OBSIDIAN:0)
Block(-2,11,6,OBSIDIAN:0)
Block(-2,11,7,OBSIDIAN:0)
Block(-2,11,8,OBSIDIAN:0)
Block(-2,12,-7,STATIONARY_LAVA:0)
Block(-2,12,-6,STATIONARY_LAVA:0)
Block(-2,12,-5,STATIONARY_LAVA:0)
Block(-2,12,-4,STATIONARY_LAVA:0)
Block(-2,12,-3,STATIONARY_LAVA:0)
Block(-2,12,-2,STATIONARY_LAVA:0)
Block(-2,12,-1,STATIONARY_LAVA:0)
Block(-2,12,0,STATIONARY_LAVA:0)
Block(-2,12,1,STATIONARY_LAVA:0)
Block(-2,12,2,STATIONARY_LAVA:0)
Block(-2,12,3,STATIONARY_LAVA:0)
Block(-2,12,4,STATIONARY_LAVA:0)
Block(-2,12,5,STATIONARY_LAVA:0)
Block(-2,12,6,STATIONARY_LAVA:0)
Block(-2,12,7,STATIONARY_LAVA:0)
Block(-2,12,8,STATIONARY_LAVA:0)
Block(-2,13,-7,OBSIDIAN:0)
Block(-2,13,-6,OBSIDIAN:0)
Block(-2,13,-5,OBSIDIAN:0)
Block(-2,13,-4,OBSIDIAN:0)
Block(-2,13,-3,OBSIDIAN:0)
Block(-2,13,-2,OBSIDIAN:0)
Block(-2,13,-1,OBSIDIAN:0)
Block(-2,13,0,OBSIDIAN:0)
Block(-2,13,1,OBSIDIAN:0)
Block(-2,13,2,OBSIDIAN:0)
Block(-2,13,3,OBSIDIAN:0)
Block(-2,13,4,OBSIDIAN:0)
Block(-2,13,5,OBSIDIAN:0)
Block(-2,13,6,OBSIDIAN:0)
Block(-2,13,7,OBSIDIAN:0)
Block(-2,13,8,OBSIDIAN:0)
Block(-2,14,-7,OBSIDIAN:0)
Block(-2,14,-6,OBSIDIAN:0)
Block(-2,14,-5,OBSIDIAN:0)
Block(-2,14,-4,OBSIDIAN:0)
Block(-2,14,-3,OBSIDIAN:0)
Block(-2,14,-2,OBSIDIAN:0)
Block(-2,14,-1,OBSIDIAN:0)
Block(-2,14,0,OBSIDIAN:0)
Block(-2,14,1,OBSIDIAN:0)
Block(-2,14,2,OBSIDIAN:0)
Block(-2,14,3,OBSIDIAN:0)
Block(-2,14,4,OBSIDIAN:0)
Block(-2,14,5,OBSIDIAN:0)
Block(-2,14,6,OBSIDIAN:0)
Block(-2,14,7,OBSIDIAN:0)
Block(-2,14,8,OBSIDIAN:0)
Block(-2,15,-7,OBSIDIAN:0)
Block(-2,15,-6,OBSIDIAN:0)
Block(-2,15,-5,OBSIDIAN:0)
Block(-2,15,-4,OBSIDIAN:0)
Block(-2,15,-3,OBSIDIAN:0)
Block(-2,15,-2,OBSIDIAN:0)
Block(-2,15,-1,OBSIDIAN:0)
Block(-2,15,0,OBSIDIAN:0)
Block(-2,15,1,OBSIDIAN:0)
Block(-2,15,2,OBSIDIAN:0)
Block(-2,15,3,OBSIDIAN:0)
Block(-2,15,4,OBSIDIAN:0)
Block(-2,15,5,OBSIDIAN:0)
Block(-2,15,6,OBSIDIAN:0)
Block(-2,15,7,OBSIDIAN:0)
Block(-2,15,8,OBSIDIAN:0)
Block(-2,16,-7,OBSIDIAN:0)
Block(-2,16,-6,OBSIDIAN:0)
Block(-2,16,-5,OBSIDIAN:0)
Block(-2,16,-4,OBSIDIAN:0)
Block(-2,16,-3,OBSIDIAN:0)
Block(-2,16,-2,OBSIDIAN:0)
Block(-2,16,-1,OBSIDIAN:0)
Block(-2,16,0,OBSIDIAN:0)
Block(-2,16,1,OBSIDIAN:0)
Block(-2,16,2,OBSIDIAN:0)
Block(-2,16,3,OBSIDIAN:0)
Block(-2,16,4,OBSIDIAN:0)
Block(-2,16,5,OBSIDIAN:0)
Block(-2,16,6,OBSIDIAN:0)
Block(-2,16,7,OBSIDIAN:0)
Block(-2,16,8,OBSIDIAN:0)
Block(-2,17,-7,CONCRETE:7)
Block(-2,17,-6,CONCRETE:7)
Block(-2,17,-5,CONCRETE:7)
Block(-2,17,-4,CONCRETE:7)
Block(-2,17,-3,CONCRETE:7)
Block(-2,17,-2,CONCRETE:7)
Block(-2,17,-1,CONCRETE:7)
Block(-2,17,0,CONCRETE:7)
Block(-2,17,1,CONCRETE:7)
Block(-2,17,2,CONCRETE:7)
Block(-2,17,3,CONCRETE:7)
Block(-2,17,4,CONCRETE:7)
Block(-2,17,5,CONCRETE:7)
Block(-2,17,6,CONCRETE:7)
Block(-2,17,7,CONCRETE:7)
Block(-2,17,8,CONCRETE:7)
Block(-2,18,-6,OBSIDIAN:0)
Block(-2,18,-3,CONCRETE:7)
Block(-2,18,-2,OBSIDIAN:0)
Block(-2,18,-1,CONCRETE:7)
#RandomBlock(-2,18,0,AIR:0,30,CHEST:5,../../../../../Chests/Loot/junk_loot.nbt,10,CHEST:5,../../../../../Chests/Loot/simple_dungeon.nbt,5,CHEST:5,../../../../../Chests/Loot/moderncity_junk_loot.nbt,65,CHEST:3,../../../../../Chests/Loot/moderncity_junk_loot.nbt,20,CHEST:3,../../../../../Chests/Loot/moderncity_common_loot.nbt,5,CHEST:3,../../../../../Chests/Loot/moderncity_rare_loot.nbt,3,CHEST:3,../../../../../Chests/Loot/moderncity_epic_loot.nbt,1,CHEST:3,../../../../../Chests/Loot/moderncity_junk_loot.nbt,100)
RandomBlock(-2,18,1,AIR,90,IRON_TRAPDOOR:5,100)
RandomBlock(-2,18,5,AIR,90,IRON_TRAPDOOR:4,100)
#RandomBlock(-2,18,6,AIR:0,30,CHEST:5,../../../../../Chests/Loot/junk_loot.nbt,10,CHEST:5,../../../../../Chests/Loot/simple_dungeon.nbt,5,CHEST:5,../../../../../Chests/Loot/moderncity_junk_loot.nbt,65,CHEST:2,../../../../../Chests/Loot/moderncity_junk_loot.nbt,20,CHEST:2,../../../../../Chests/Loot/moderncity_common_loot.nbt,5,CHEST:2,../../../../../Chests/Loot/moderncity_rare_loot.nbt,3,CHEST:2,../../../../../Chests/Loot/moderncity_epic_loot.nbt,1,CHEST:2,../../../../../Chests/Loot/moderncity_junk_loot.nbt,100)
Block(-2,18,7,OBSIDIAN:0)
Block(-2,19,-7,STONE_BUTTON:4)
Block(-2,19,-6,OBSIDIAN:0)
Block(-2,19,-3,CONCRETE:7)
Block(-2,19,-2,OBSIDIAN:0)
Block(-2,19,-1,CONCRETE:7)
Block(-2,19,0,STEP:8)
Block(-2,19,1,QUARTZ_STAIRS:7)
RandomBlock(-2,19,5,AIR,90,IRON_TRAPDOOR:4,100)
#RandomBlock(-2,19,6,AIR:0,30,CHEST:5,../../../../../Chests/Loot/junk_loot.nbt,10,CHEST:5,../../../../../Chests/Loot/simple_dungeon.nbt,5,CHEST:5,../../../../../Chests/Loot/moderncity_junk_loot.nbt,65,CHEST:2,../../../../../Chests/Loot/moderncity_junk_loot.nbt,20,CHEST:2,../../../../../Chests/Loot/moderncity_common_loot.nbt,5,CHEST:2,../../../../../Chests/Loot/moderncity_rare_loot.nbt,3,CHEST:2,../../../../../Chests/Loot/moderncity_epic_loot.nbt,1,CHEST:2,../../../../../Chests/Loot/moderncity_junk_loot.nbt,100)
Block(-2,19,7,OBSIDIAN:0)
Block(-2,20,-7,STEP:8)
Block(-2,20,-6,OBSIDIAN:0)
Block(-2,20,-5,STEP:8)
Block(-2,20,-4,STEP:8)
Block(-2,20,-3,CONCRETE:7)
Block(-2,20,-2,OBSIDIAN:0)
Block(-2,20,-1,CONCRETE:7)
#RandomBlock(-2,20,0,AIR:0,30,CHEST:5,../../../../../Chests/Loot/junk_loot.nbt,10,CHEST:5,../../../../../Chests/Loot/simple_dungeon.nbt,5,CHEST:5,../../../../../Chests/Loot/moderncity_junk_loot.nbt,65,CHEST:3,../../../../../Chests/Loot/moderncity_junk_loot.nbt,20,CHEST:3,../../../../../Chests/Loot/moderncity_common_loot.nbt,5,CHEST:3,../../../../../Chests/Loot/moderncity_rare_loot.nbt,3,CHEST:3,../../../../../Chests/Loot/moderncity_epic_loot.nbt,1,CHEST:3,../../../../../Chests/Loot/moderncity_junk_loot.nbt,100)
RandomBlock(-2,20,1,AIR,90,IRON_TRAPDOOR:13,100)
RandomBlock(-2,20,5,AIR,90,IRON_TRAPDOOR:4,100)
#RandomBlock(-2,20,6,AIR:0,30,CHEST:5,../../../../../Chests/Loot/junk_loot.nbt,10,CHEST:5,../../../../../Chests/Loot/simple_dungeon.nbt,5,CHEST:5,../../../../../Chests/Loot/moderncity_junk_loot.nbt,65,CHEST:2,../../../../../Chests/Loot/moderncity_junk_loot.nbt,20,CHEST:2,../../../../../Chests/Loot/moderncity_common_loot.nbt,5,CHEST:2,../../../../../Chests/Loot/moderncity_rare_loot.nbt,3,CHEST:2,../../../../../Chests/Loot/moderncity_epic_loot.nbt,1,CHEST:2,../../../../../Chests/Loot/moderncity_junk_loot.nbt,100)
Block(-2,20,7,OBSIDIAN:0)
Block(-2,21,-7,CONCRETE:7)
Block(-2,21,-6,CONCRETE:7)
Block(-2,21,-5,CONCRETE:7)
Block(-2,21,-4,CONCRETE:7)
Block(-2,21,-3,CONCRETE:7)
Block(-2,21,-2,OBSIDIAN:0)
Block(-2,21,-1,CONCRETE:7)
Block(-2,21,0,STEP:0)
Block(-2,21,1,QUARTZ_STAIRS:7)
Block(-2,21,2,STEP:8)
Block(-2,21,3,STEP:8)
Block(-2,21,4,STEP:8)
Block(-2,21,5,QUARTZ_STAIRS:6)
Block(-2,21,6,STEP:0)
Block(-2,21,7,CONCRETE:7)
Block(-2,21,8,STEP:8)
Block(-2,22,-7,OBSIDIAN:0)
Block(-2,22,-6,OBSIDIAN:0)
Block(-2,22,-5,OBSIDIAN:0)
Block(-2,22,-4,OBSIDIAN:0)
Block(-2,22,-3,OBSIDIAN:0)
Block(-2,22,-2,OBSIDIAN:0)
Block(-2,22,-1,CONCRETE:7)
Block(-2,22,0,CONCRETE:7)
Block(-2,22,1,CONCRETE:7)
Block(-2,22,2,CONCRETE:7)
Block(-2,22,3,CONCRETE:7)
Block(-2,22,4,CONCRETE:7)
Block(-2,22,5,CONCRETE:7)
Block(-2,22,6,CONCRETE:7)
Block(-2,22,7,CONCRETE:7)
Block(-2,22,8,CONCRETE:7)
Block(-2,23,-7,CONCRETE:0)
Block(-2,23,-6,CONCRETE:0)
Block(-2,23,-5,CONCRETE:0)
Block(-2,23,-4,CONCRETE:0)
Block(-2,23,-3,CONCRETE:0)
Block(-2,23,-2,OBSIDIAN:0)
Block(-2,23,-1,OBSIDIAN:0)
Block(-2,23,0,OBSIDIAN:0)
Block(-2,23,1,OBSIDIAN:0)
Block(-2,23,2,OBSIDIAN:0)
Block(-2,23,3,OBSIDIAN:0)
Block(-2,23,4,OBSIDIAN:0)
Block(-2,23,5,OBSIDIAN:0)
Block(-2,23,6,OBSIDIAN:0)
Block(-2,23,7,OBSIDIAN:0)
Block(-2,23,8,OBSIDIAN:0)
Block(-2,24,-4,QUARTZ_STAIRS:2)
Block(-2,24,-3,CONCRETE:0)
Block(-2,24,-2,CONCRETE:0)
Block(-2,24,-1,CONCRETE:0)
Block(-2,24,0,CONCRETE:0)
Block(-2,24,1,CONCRETE:0)
Block(-2,24,2,CONCRETE:0)
Block(-2,24,3,CONCRETE:15)
Block(-2,24,4,STONE:4)
Block(-2,24,5,STONE:4)
Block(-2,24,6,CONCRETE:0)
Block(-2,24,7,CONCRETE:0)
Block(-2,24,8,STONE:4)
